package mod.fossil.common.gens;

import java.util.Random;

import net.minecraft.block.Block;
import net.minecraft.world.World;
import net.minecraft.world.gen.feature.WorldGenerator;

public class WorldGeneratorShipWreck180 extends WorldGenerator
{
	
	public boolean generate(World world, Random rand, int i, int j, int k)
	{
		
		world.setBlockAndMetadata(i + 0, j + 8, k + 31, Block.stoneSingleSlab.blockID, 2);
		world.setBlock(i + 0, j + 9, k + 43, Block.planks.blockID);
		world.setBlock(i + 0, j + 9, k + 44, Block.planks.blockID);
		world.setBlock(i + 0, j + 9, k + 45, Block.planks.blockID);
		world.setBlock(i + 0, j + 9, k + 46, Block.planks.blockID);
		world.setBlock(i + 0, j + 9, k + 47, Block.planks.blockID);
		world.setBlock(i + 0, j + 9, k + 48, Block.planks.blockID);
		world.setBlock(i + 0, j + 9, k + 49, Block.planks.blockID);
		world.setBlock(i + 0, j + 10, k + 43, Block.planks.blockID);
		world.setBlock(i + 0, j + 10, k + 44, Block.planks.blockID);
		world.setBlock(i + 0, j + 10, k + 45, Block.glass.blockID);
		world.setBlock(i + 0, j + 10, k + 46, Block.glass.blockID);
		world.setBlock(i + 0, j + 10, k + 47, Block.glass.blockID);
		world.setBlock(i + 0, j + 10, k + 48, Block.glass.blockID);
		world.setBlock(i + 0, j + 10, k + 49, Block.planks.blockID);
		world.setBlock(i + 0, j + 11, k + 44, Block.planks.blockID);
		world.setBlock(i + 0, j + 11, k + 45, Block.planks.blockID);
		world.setBlock(i + 0, j + 11, k + 46, Block.planks.blockID);
		world.setBlock(i + 0, j + 11, k + 47, Block.planks.blockID);
		world.setBlock(i + 0, j + 11, k + 48, Block.planks.blockID);
		world.setBlock(i + 0, j + 11, k + 49, Block.planks.blockID);
		world.setBlock(i + 0, j + 12, k + 43, Block.planks.blockID);
		world.setBlock(i + 0, j + 12, k + 44, Block.planks.blockID);
		world.setBlock(i + 0, j + 12, k + 45, Block.planks.blockID);
		world.setBlock(i + 0, j + 12, k + 46, Block.planks.blockID);
		world.setBlock(i + 0, j + 12, k + 47, Block.planks.blockID);
		world.setBlock(i + 0, j + 12, k + 48, Block.planks.blockID);
		world.setBlock(i + 0, j + 12, k + 49, Block.planks.blockID);
		world.setBlock(i + 0, j + 13, k + 43, Block.fence.blockID);
		world.setBlock(i + 0, j + 13, k + 44, Block.fence.blockID);
		world.setBlock(i + 0, j + 13, k + 45, Block.fence.blockID);
		world.setBlock(i + 0, j + 13, k + 46, Block.fence.blockID);
		world.setBlock(i + 0, j + 13, k + 47, Block.fence.blockID);
		world.setBlock(i + 0, j + 13, k + 48, Block.fence.blockID);
		world.setBlock(i + 0, j + 13, k + 49, Block.fence.blockID);
		world.setBlock(i + 1, j + 3, k + 13, Block.planks.blockID);
		world.setBlock(i + 1, j + 3, k + 14, Block.planks.blockID);
		world.setBlock(i + 1, j + 3, k + 15, Block.planks.blockID);
		world.setBlock(i + 1, j + 3, k + 16, Block.planks.blockID);
		world.setBlock(i + 1, j + 3, k + 17, Block.planks.blockID);
		world.setBlock(i + 1, j + 3, k + 18, Block.planks.blockID);
		world.setBlock(i + 1, j + 3, k + 19, Block.planks.blockID);
		world.setBlock(i + 1, j + 3, k + 20, Block.planks.blockID);
		world.setBlock(i + 1, j + 3, k + 21, Block.planks.blockID);
		world.setBlock(i + 1, j + 3, k + 22, Block.planks.blockID);
		world.setBlock(i + 1, j + 3, k + 23, Block.planks.blockID);
		world.setBlock(i + 1, j + 3, k + 24, Block.planks.blockID);
		world.setBlock(i + 1, j + 3, k + 25, Block.planks.blockID);
		world.setBlock(i + 1, j + 3, k + 26, Block.planks.blockID);
		world.setBlock(i + 1, j + 3, k + 27, Block.planks.blockID);
		world.setBlock(i + 1, j + 3, k + 28, Block.planks.blockID);
		world.setBlock(i + 1, j + 3, k + 29, Block.planks.blockID);
		world.setBlock(i + 1, j + 3, k + 30, Block.planks.blockID);
		world.setBlock(i + 1, j + 3, k + 31, Block.planks.blockID);
		world.setBlock(i + 1, j + 3, k + 32, Block.planks.blockID);
		world.setBlock(i + 1, j + 3, k + 33, Block.planks.blockID);
		world.setBlock(i + 1, j + 3, k + 34, Block.planks.blockID);
		world.setBlock(i + 1, j + 3, k + 35, Block.planks.blockID);
		world.setBlock(i + 1, j + 3, k + 36, Block.planks.blockID);
		world.setBlock(i + 1, j + 3, k + 37, Block.planks.blockID);
		world.setBlock(i + 1, j + 3, k + 38, Block.planks.blockID);
		world.setBlock(i + 1, j + 3, k + 39, Block.planks.blockID);
		world.setBlock(i + 1, j + 3, k + 40, Block.planks.blockID);
		world.setBlock(i + 1, j + 3, k + 41, Block.planks.blockID);
		world.setBlock(i + 1, j + 3, k + 42, Block.planks.blockID);
		world.setBlock(i + 1, j + 3, k + 43, Block.planks.blockID);
		world.setBlock(i + 1, j + 3, k + 44, Block.planks.blockID);
		world.setBlock(i + 1, j + 3, k + 45, Block.planks.blockID);
		world.setBlock(i + 1, j + 3, k + 46, Block.planks.blockID);
		world.setBlock(i + 1, j + 3, k + 47, Block.planks.blockID);
		world.setBlock(i + 1, j + 3, k + 48, Block.planks.blockID);
		world.setBlock(i + 1, j + 3, k + 49, Block.planks.blockID);
		world.setBlock(i + 1, j + 4, k + 13, Block.planks.blockID);
		world.setBlock(i + 1, j + 4, k + 14, Block.planks.blockID);
		world.setBlock(i + 1, j + 4, k + 15, Block.planks.blockID);
		world.setBlock(i + 1, j + 4, k + 16, Block.planks.blockID);
		world.setBlock(i + 1, j + 4, k + 17, Block.glass.blockID);
		world.setBlock(i + 1, j + 4, k + 18, Block.planks.blockID);
		world.setBlock(i + 1, j + 4, k + 19, Block.planks.blockID);
		world.setBlock(i + 1, j + 4, k + 20, Block.planks.blockID);
		world.setBlock(i + 1, j + 4, k + 21, Block.planks.blockID);
		world.setBlock(i + 1, j + 4, k + 22, Block.planks.blockID);
		world.setBlock(i + 1, j + 4, k + 23, Block.glass.blockID);
		world.setBlock(i + 1, j + 4, k + 24, Block.planks.blockID);
		world.setBlock(i + 1, j + 4, k + 25, Block.planks.blockID);
		world.setBlock(i + 1, j + 4, k + 26, Block.planks.blockID);
		world.setBlock(i + 1, j + 4, k + 27, Block.planks.blockID);
		world.setBlock(i + 1, j + 4, k + 28, Block.planks.blockID);
		world.setBlock(i + 1, j + 4, k + 29, Block.glass.blockID);
		world.setBlock(i + 1, j + 4, k + 30, Block.planks.blockID);
		world.setBlock(i + 1, j + 4, k + 31, Block.planks.blockID);
		world.setBlock(i + 1, j + 4, k + 32, Block.planks.blockID);
		world.setBlock(i + 1, j + 4, k + 33, Block.planks.blockID);
		world.setBlock(i + 1, j + 4, k + 34, Block.planks.blockID);
		world.setBlock(i + 1, j + 4, k + 35, Block.glass.blockID);
		world.setBlock(i + 1, j + 4, k + 36, Block.planks.blockID);
		world.setBlock(i + 1, j + 4, k + 37, Block.planks.blockID);
		world.setBlock(i + 1, j + 4, k + 38, Block.planks.blockID);
		world.setBlock(i + 1, j + 4, k + 39, Block.planks.blockID);
		world.setBlock(i + 1, j + 4, k + 40, Block.planks.blockID);
		world.setBlock(i + 1, j + 4, k + 41, Block.glass.blockID);
		world.setBlock(i + 1, j + 4, k + 42, Block.planks.blockID);
		world.setBlock(i + 1, j + 4, k + 43, Block.planks.blockID);
		world.setBlock(i + 1, j + 4, k + 44, Block.planks.blockID);
		world.setBlock(i + 1, j + 4, k + 45, Block.planks.blockID);
		world.setBlock(i + 1, j + 4, k + 46, Block.planks.blockID);
		world.setBlock(i + 1, j + 4, k + 47, Block.planks.blockID);
		world.setBlock(i + 1, j + 4, k + 48, Block.planks.blockID);
		world.setBlock(i + 1, j + 4, k + 49, Block.planks.blockID);
		world.setBlock(i + 1, j + 5, k + 13, Block.planks.blockID);
		world.setBlock(i + 1, j + 5, k + 14, Block.planks.blockID);
		world.setBlock(i + 1, j + 5, k + 15, Block.planks.blockID);
		world.setBlock(i + 1, j + 5, k + 16, Block.planks.blockID);
		world.setBlock(i + 1, j + 5, k + 17, Block.planks.blockID);
		world.setBlock(i + 1, j + 5, k + 18, Block.planks.blockID);
		world.setBlock(i + 1, j + 5, k + 19, Block.planks.blockID);
		world.setBlock(i + 1, j + 5, k + 20, Block.planks.blockID);
		world.setBlock(i + 1, j + 5, k + 21, Block.planks.blockID);
		world.setBlock(i + 1, j + 5, k + 22, Block.planks.blockID);
		world.setBlock(i + 1, j + 5, k + 23, Block.planks.blockID);
		world.setBlock(i + 1, j + 5, k + 24, Block.planks.blockID);
		world.setBlock(i + 1, j + 5, k + 25, Block.planks.blockID);
		world.setBlock(i + 1, j + 5, k + 26, Block.planks.blockID);
		world.setBlock(i + 1, j + 5, k + 27, Block.planks.blockID);
		world.setBlock(i + 1, j + 5, k + 28, Block.planks.blockID);
		world.setBlock(i + 1, j + 5, k + 29, Block.planks.blockID);
		world.setBlock(i + 1, j + 5, k + 30, Block.planks.blockID);
		world.setBlock(i + 1, j + 5, k + 31, Block.planks.blockID);
		world.setBlock(i + 1, j + 5, k + 32, Block.planks.blockID);
		world.setBlock(i + 1, j + 5, k + 33, Block.planks.blockID);
		world.setBlock(i + 1, j + 5, k + 34, Block.planks.blockID);
		world.setBlock(i + 1, j + 5, k + 35, Block.planks.blockID);
		world.setBlock(i + 1, j + 5, k + 36, Block.planks.blockID);
		world.setBlock(i + 1, j + 5, k + 37, Block.planks.blockID);
		world.setBlock(i + 1, j + 5, k + 38, Block.planks.blockID);
		world.setBlock(i + 1, j + 5, k + 39, Block.planks.blockID);
		world.setBlock(i + 1, j + 5, k + 40, Block.planks.blockID);
		world.setBlock(i + 1, j + 5, k + 41, Block.planks.blockID);
		world.setBlock(i + 1, j + 5, k + 42, Block.planks.blockID);
		world.setBlock(i + 1, j + 5, k + 43, Block.planks.blockID);
		world.setBlock(i + 1, j + 5, k + 44, Block.planks.blockID);
		world.setBlock(i + 1, j + 5, k + 45, Block.planks.blockID);
		world.setBlock(i + 1, j + 5, k + 46, Block.planks.blockID);
		world.setBlock(i + 1, j + 5, k + 47, Block.planks.blockID);
		world.setBlock(i + 1, j + 5, k + 48, Block.planks.blockID);
		world.setBlock(i + 1, j + 5, k + 49, Block.planks.blockID);
		world.setBlock(i + 1, j + 6, k + 12, Block.planks.blockID);
		world.setBlock(i + 1, j + 6, k + 13, Block.planks.blockID);
		world.setBlock(i + 1, j + 6, k + 14, Block.planks.blockID);
		world.setBlock(i + 1, j + 6, k + 16, Block.planks.blockID);
		world.setBlock(i + 1, j + 6, k + 17, Block.planks.blockID);
		world.setBlock(i + 1, j + 6, k + 19, Block.planks.blockID);
		world.setBlock(i + 1, j + 6, k + 20, Block.planks.blockID);
		world.setBlock(i + 1, j + 6, k + 22, Block.planks.blockID);
		world.setBlock(i + 1, j + 6, k + 23, Block.planks.blockID);
		world.setBlock(i + 1, j + 6, k + 25, Block.planks.blockID);
		world.setBlock(i + 1, j + 6, k + 26, Block.planks.blockID);
		world.setBlock(i + 1, j + 6, k + 28, Block.planks.blockID);
		world.setBlock(i + 1, j + 6, k + 29, Block.planks.blockID);
		world.setBlock(i + 1, j + 6, k + 30, Block.planks.blockID);
		world.setBlock(i + 1, j + 6, k + 31, Block.planks.blockID);
		world.setBlock(i + 1, j + 6, k + 32, Block.planks.blockID);
		world.setBlock(i + 1, j + 6, k + 33, Block.planks.blockID);
		world.setBlock(i + 1, j + 6, k + 34, Block.planks.blockID);
		world.setBlock(i + 1, j + 6, k + 36, Block.planks.blockID);
		world.setBlock(i + 1, j + 6, k + 37, Block.planks.blockID);
		world.setBlock(i + 1, j + 6, k + 39, Block.planks.blockID);
		world.setBlock(i + 1, j + 6, k + 40, Block.planks.blockID);
		world.setBlock(i + 1, j + 6, k + 42, Block.planks.blockID);
		world.setBlock(i + 1, j + 6, k + 43, Block.planks.blockID);
		world.setBlock(i + 1, j + 6, k + 45, Block.planks.blockID);
		world.setBlock(i + 1, j + 6, k + 46, Block.planks.blockID);
		world.setBlock(i + 1, j + 6, k + 48, Block.planks.blockID);
		world.setBlock(i + 1, j + 6, k + 49, Block.planks.blockID);
		world.setBlock(i + 1, j + 7, k + 7, Block.planks.blockID);
		world.setBlock(i + 1, j + 7, k + 8, Block.planks.blockID);
		world.setBlock(i + 1, j + 7, k + 9, Block.planks.blockID);
		world.setBlock(i + 1, j + 7, k + 10, Block.planks.blockID);
		world.setBlock(i + 1, j + 7, k + 11, Block.planks.blockID);
		world.setBlock(i + 1, j + 7, k + 12, Block.planks.blockID);
		world.setBlock(i + 1, j + 7, k + 13, Block.planks.blockID);
		world.setBlock(i + 1, j + 7, k + 14, Block.planks.blockID);
		world.setBlock(i + 1, j + 7, k + 16, Block.planks.blockID);
		world.setBlock(i + 1, j + 7, k + 17, Block.planks.blockID);
		world.setBlock(i + 1, j + 7, k + 19, Block.planks.blockID);
		world.setBlock(i + 1, j + 7, k + 20, Block.planks.blockID);
		world.setBlock(i + 1, j + 7, k + 22, Block.planks.blockID);
		world.setBlock(i + 1, j + 7, k + 23, Block.planks.blockID);
		world.setBlock(i + 1, j + 7, k + 25, Block.planks.blockID);
		world.setBlock(i + 1, j + 7, k + 26, Block.planks.blockID);
		world.setBlock(i + 1, j + 7, k + 28, Block.planks.blockID);
		world.setBlock(i + 1, j + 7, k + 29, Block.planks.blockID);
		world.setBlock(i + 1, j + 7, k + 30, Block.planks.blockID);
		world.setBlock(i + 1, j + 7, k + 31, Block.planks.blockID);
		world.setBlock(i + 1, j + 7, k + 32, Block.planks.blockID);
		world.setBlock(i + 1, j + 7, k + 33, Block.planks.blockID);
		world.setBlock(i + 1, j + 7, k + 34, Block.planks.blockID);
		world.setBlock(i + 1, j + 7, k + 36, Block.planks.blockID);
		world.setBlock(i + 1, j + 7, k + 37, Block.planks.blockID);
		world.setBlock(i + 1, j + 7, k + 39, Block.planks.blockID);
		world.setBlock(i + 1, j + 7, k + 40, Block.planks.blockID);
		world.setBlock(i + 1, j + 7, k + 42, Block.planks.blockID);
		world.setBlock(i + 1, j + 7, k + 43, Block.planks.blockID);
		world.setBlock(i + 1, j + 7, k + 45, Block.planks.blockID);
		world.setBlock(i + 1, j + 7, k + 46, Block.planks.blockID);
		world.setBlock(i + 1, j + 7, k + 48, Block.planks.blockID);
		world.setBlock(i + 1, j + 7, k + 49, Block.planks.blockID);
		world.setBlock(i + 1, j + 8, k + 7, Block.planks.blockID);
		world.setBlock(i + 1, j + 8, k + 8, Block.planks.blockID);
		world.setBlock(i + 1, j + 8, k + 9, Block.planks.blockID);
		world.setBlock(i + 1, j + 8, k + 10, Block.planks.blockID);
		world.setBlock(i + 1, j + 8, k + 11, Block.planks.blockID);
		world.setBlock(i + 1, j + 8, k + 12, Block.planks.blockID);
		world.setBlock(i + 1, j + 8, k + 13, Block.planks.blockID);
		world.setBlock(i + 1, j + 8, k + 14, Block.planks.blockID);
		world.setBlock(i + 1, j + 8, k + 15, Block.planks.blockID);
		world.setBlock(i + 1, j + 8, k + 16, Block.planks.blockID);
		world.setBlock(i + 1, j + 8, k + 17, Block.planks.blockID);
		world.setBlock(i + 1, j + 8, k + 18, Block.planks.blockID);
		world.setBlock(i + 1, j + 8, k + 19, Block.planks.blockID);
		world.setBlock(i + 1, j + 8, k + 20, Block.planks.blockID);
		world.setBlock(i + 1, j + 8, k + 21, Block.planks.blockID);
		world.setBlock(i + 1, j + 8, k + 22, Block.planks.blockID);
		world.setBlock(i + 1, j + 8, k + 23, Block.planks.blockID);
		world.setBlock(i + 1, j + 8, k + 24, Block.planks.blockID);
		world.setBlock(i + 1, j + 8, k + 25, Block.planks.blockID);
		world.setBlock(i + 1, j + 8, k + 26, Block.planks.blockID);
		world.setBlock(i + 1, j + 8, k + 27, Block.planks.blockID);
		world.setBlock(i + 1, j + 8, k + 28, Block.planks.blockID);
		world.setBlock(i + 1, j + 8, k + 29, Block.planks.blockID);
		world.setBlock(i + 1, j + 8, k + 30, Block.planks.blockID);
		world.setBlock(i + 1, j + 8, k + 31, Block.planks.blockID);
		world.setBlock(i + 1, j + 8, k + 32, Block.planks.blockID);
		world.setBlock(i + 1, j + 8, k + 33, Block.planks.blockID);
		world.setBlock(i + 1, j + 8, k + 34, Block.planks.blockID);
		world.setBlock(i + 1, j + 8, k + 35, Block.planks.blockID);
		world.setBlock(i + 1, j + 8, k + 36, Block.planks.blockID);
		world.setBlock(i + 1, j + 8, k + 37, Block.planks.blockID);
		world.setBlock(i + 1, j + 8, k + 38, Block.planks.blockID);
		world.setBlock(i + 1, j + 8, k + 39, Block.planks.blockID);
		world.setBlock(i + 1, j + 8, k + 40, Block.planks.blockID);
		world.setBlock(i + 1, j + 8, k + 41, Block.planks.blockID);
		world.setBlock(i + 1, j + 8, k + 42, Block.planks.blockID);
		world.setBlock(i + 1, j + 8, k + 43, Block.planks.blockID);
		world.setBlockAndMetadata(i + 1, j + 8, k + 44, Block.cloth.blockID, 14);
		world.setBlockAndMetadata(i + 1, j + 8, k + 45, Block.cloth.blockID, 14);
		world.setBlockAndMetadata(i + 1, j + 8, k + 46, Block.cloth.blockID, 14);
		world.setBlockAndMetadata(i + 1, j + 8, k + 47, Block.cloth.blockID, 14);
		world.setBlockAndMetadata(i + 1, j + 8, k + 48, Block.cloth.blockID, 14);
		world.setBlockAndMetadata(i + 1, j + 8, k + 49, Block.cloth.blockID, 14);
		world.setBlock(i + 1, j + 9, k + 7, Block.planks.blockID);
		world.setBlock(i + 1, j + 9, k + 8, Block.planks.blockID);
		world.setBlock(i + 1, j + 9, k + 9, Block.planks.blockID);
		world.setBlock(i + 1, j + 9, k + 10, Block.planks.blockID);
		world.setBlock(i + 1, j + 9, k + 11, Block.planks.blockID);
		world.setBlock(i + 1, j + 9, k + 12, Block.planks.blockID);
		world.setBlock(i + 1, j + 9, k + 13, Block.planks.blockID);
		world.setBlock(i + 1, j + 9, k + 14, Block.planks.blockID);
		world.setBlock(i + 1, j + 9, k + 15, Block.planks.blockID);
		world.setBlock(i + 1, j + 9, k + 17, Block.fence.blockID);
		world.setBlock(i + 1, j + 9, k + 18, Block.fence.blockID);
		world.setBlock(i + 1, j + 9, k + 19, Block.fence.blockID);
		world.setBlock(i + 1, j + 9, k + 20, Block.fence.blockID);
		world.setBlock(i + 1, j + 9, k + 21, Block.fence.blockID);
		world.setBlock(i + 1, j + 9, k + 22, Block.fence.blockID);
		world.setBlock(i + 1, j + 9, k + 23, Block.fence.blockID);
		world.setBlock(i + 1, j + 9, k + 24, Block.fence.blockID);
		world.setBlock(i + 1, j + 9, k + 25, Block.fence.blockID);
		world.setBlock(i + 1, j + 9, k + 26, Block.fence.blockID);
		world.setBlock(i + 1, j + 9, k + 27, Block.fence.blockID);
		world.setBlock(i + 1, j + 9, k + 28, Block.fence.blockID);
		world.setBlock(i + 1, j + 9, k + 29, Block.fence.blockID);
		world.setBlock(i + 1, j + 9, k + 30, Block.fence.blockID);
		world.setBlock(i + 1, j + 9, k + 32, Block.fence.blockID);
		world.setBlock(i + 1, j + 9, k + 33, Block.fence.blockID);
		world.setBlock(i + 1, j + 9, k + 34, Block.fence.blockID);
		world.setBlock(i + 1, j + 9, k + 35, Block.fence.blockID);
		world.setBlock(i + 1, j + 9, k + 36, Block.fence.blockID);
		world.setBlock(i + 1, j + 9, k + 37, Block.fence.blockID);
		world.setBlock(i + 1, j + 9, k + 38, Block.fence.blockID);
		world.setBlock(i + 1, j + 9, k + 39, Block.fence.blockID);
		world.setBlock(i + 1, j + 9, k + 40, Block.fence.blockID);
		world.setBlock(i + 1, j + 9, k + 41, Block.fence.blockID);
		world.setBlock(i + 1, j + 9, k + 43, Block.planks.blockID);
		world.setBlock(i + 1, j + 9, k + 50, Block.planks.blockID);
		world.setBlock(i + 1, j + 10, k + 7, Block.fence.blockID);
		world.setBlock(i + 1, j + 10, k + 8, Block.fence.blockID);
		world.setBlock(i + 1, j + 10, k + 9, Block.fence.blockID);
		world.setBlock(i + 1, j + 10, k + 10, Block.fence.blockID);
		world.setBlock(i + 1, j + 10, k + 11, Block.fence.blockID);
		world.setBlock(i + 1, j + 10, k + 12, Block.fence.blockID);
		world.setBlock(i + 1, j + 10, k + 13, Block.fence.blockID);
		world.setBlock(i + 1, j + 10, k + 14, Block.fence.blockID);
		world.setBlock(i + 1, j + 10, k + 15, Block.fence.blockID);
		world.setBlock(i + 1, j + 10, k + 43, Block.planks.blockID);
		world.setBlock(i + 1, j + 10, k + 50, Block.planks.blockID);
		world.setBlock(i + 1, j + 11, k + 43, Block.planks.blockID);
		world.setBlock(i + 1, j + 11, k + 50, Block.planks.blockID);
		world.setBlock(i + 1, j + 12, k + 43, Block.planks.blockID);
		world.setBlock(i + 1, j + 12, k + 44, Block.planks.blockID);
		world.setBlock(i + 1, j + 12, k + 45, Block.planks.blockID);
		world.setBlock(i + 1, j + 12, k + 46, Block.planks.blockID);
		world.setBlock(i + 1, j + 12, k + 47, Block.planks.blockID);
		world.setBlock(i + 1, j + 12, k + 48, Block.planks.blockID);
		world.setBlock(i + 1, j + 12, k + 49, Block.planks.blockID);
		world.setBlock(i + 1, j + 12, k + 50, Block.planks.blockID);
		world.setBlock(i + 1, j + 13, k + 49, Block.fence.blockID);
		world.setBlock(i + 1, j + 13, k + 50, Block.fence.blockID);
		world.setBlock(i + 2, j + 2, k + 13, Block.planks.blockID);
		world.setBlock(i + 2, j + 2, k + 14, Block.planks.blockID);
		world.setBlock(i + 2, j + 2, k + 15, Block.planks.blockID);
		world.setBlock(i + 2, j + 2, k + 16, Block.planks.blockID);
		world.setBlock(i + 2, j + 2, k + 17, Block.planks.blockID);
		world.setBlock(i + 2, j + 2, k + 18, Block.planks.blockID);
		world.setBlock(i + 2, j + 2, k + 19, Block.planks.blockID);
		world.setBlock(i + 2, j + 2, k + 20, Block.planks.blockID);
		world.setBlock(i + 2, j + 2, k + 21, Block.planks.blockID);
		world.setBlock(i + 2, j + 2, k + 22, Block.planks.blockID);
		world.setBlock(i + 2, j + 2, k + 23, Block.planks.blockID);
		world.setBlock(i + 2, j + 2, k + 24, Block.planks.blockID);
		world.setBlock(i + 2, j + 2, k + 25, Block.planks.blockID);
		world.setBlock(i + 2, j + 2, k + 26, Block.planks.blockID);
		world.setBlock(i + 2, j + 2, k + 27, Block.planks.blockID);
		world.setBlock(i + 2, j + 2, k + 28, Block.planks.blockID);
		world.setBlock(i + 2, j + 2, k + 29, Block.planks.blockID);
		world.setBlock(i + 2, j + 2, k + 30, Block.planks.blockID);
		world.setBlock(i + 2, j + 2, k + 31, Block.planks.blockID);
		world.setBlock(i + 2, j + 2, k + 32, Block.planks.blockID);
		world.setBlock(i + 2, j + 2, k + 33, Block.planks.blockID);
		world.setBlock(i + 2, j + 2, k + 34, Block.planks.blockID);
		world.setBlock(i + 2, j + 2, k + 35, Block.planks.blockID);
		world.setBlock(i + 2, j + 2, k + 36, Block.planks.blockID);
		world.setBlock(i + 2, j + 2, k + 37, Block.planks.blockID);
		world.setBlock(i + 2, j + 2, k + 38, Block.planks.blockID);
		world.setBlock(i + 2, j + 2, k + 39, Block.planks.blockID);
		world.setBlock(i + 2, j + 2, k + 40, Block.planks.blockID);
		world.setBlock(i + 2, j + 2, k + 41, Block.planks.blockID);
		world.setBlock(i + 2, j + 2, k + 42, Block.planks.blockID);
		world.setBlock(i + 2, j + 2, k + 43, Block.planks.blockID);
		world.setBlock(i + 2, j + 2, k + 44, Block.planks.blockID);
		world.setBlock(i + 2, j + 2, k + 45, Block.planks.blockID);
		world.setBlock(i + 2, j + 2, k + 46, Block.planks.blockID);
		world.setBlock(i + 2, j + 2, k + 47, Block.planks.blockID);
		world.setBlock(i + 2, j + 2, k + 48, Block.planks.blockID);
		world.setBlock(i + 2, j + 3, k + 11, Block.planks.blockID);
		world.setBlock(i + 2, j + 3, k + 12, Block.planks.blockID);
		world.setBlock(i + 2, j + 3, k + 13, Block.planks.blockID);
		world.setBlockAndMetadata(i + 2, j + 3, k + 14, Block.bed.blockID, 8);
		world.setBlock(i + 2, j + 3, k + 19, Block.planks.blockID);
		world.setBlockAndMetadata(i + 2, j + 3, k + 20, Block.bed.blockID, 8);
		world.setBlock(i + 2, j + 3, k + 25, Block.planks.blockID);
		world.setBlockAndMetadata(i + 2, j + 3, k + 26, Block.bed.blockID, 8);
		world.setBlock(i + 2, j + 3, k + 31, Block.planks.blockID);
		world.setBlockAndMetadata(i + 2, j + 3, k + 32, Block.bed.blockID, 8);
		world.setBlock(i + 2, j + 3, k + 37, Block.planks.blockID);
		world.setBlockAndMetadata(i + 2, j + 3, k + 38, Block.bed.blockID, 8);
		world.setBlock(i + 2, j + 3, k + 43, Block.planks.blockID);
		world.setBlock(i + 2, j + 3, k + 49, Block.planks.blockID);
		world.setBlock(i + 2, j + 3, k + 50, Block.planks.blockID);
		world.setBlock(i + 2, j + 4, k + 11, Block.planks.blockID);
		world.setBlock(i + 2, j + 4, k + 12, Block.planks.blockID);
		world.setBlock(i + 2, j + 4, k + 13, Block.planks.blockID);
		world.setBlock(i + 2, j + 4, k + 19, Block.planks.blockID);
		world.setBlock(i + 2, j + 4, k + 25, Block.planks.blockID);
		world.setBlock(i + 2, j + 4, k + 31, Block.planks.blockID);
		world.setBlock(i + 2, j + 4, k + 37, Block.planks.blockID);
		world.setBlock(i + 2, j + 4, k + 43, Block.planks.blockID);
		world.setBlock(i + 2, j + 4, k + 49, Block.planks.blockID);
		world.setBlock(i + 2, j + 4, k + 50, Block.planks.blockID);
		world.setBlock(i + 2, j + 5, k + 11, Block.planks.blockID);
		world.setBlock(i + 2, j + 5, k + 12, Block.planks.blockID);
		world.setBlock(i + 2, j + 5, k + 13, Block.planks.blockID);
		world.setBlock(i + 2, j + 5, k + 14, Block.planks.blockID);
		world.setBlock(i + 2, j + 5, k + 15, Block.planks.blockID);
		world.setBlock(i + 2, j + 5, k + 16, Block.planks.blockID);
		world.setBlock(i + 2, j + 5, k + 17, Block.planks.blockID);
		world.setBlock(i + 2, j + 5, k + 18, Block.planks.blockID);
		world.setBlock(i + 2, j + 5, k + 19, Block.planks.blockID);
		world.setBlock(i + 2, j + 5, k + 20, Block.planks.blockID);
		world.setBlock(i + 2, j + 5, k + 21, Block.planks.blockID);
		world.setBlock(i + 2, j + 5, k + 22, Block.planks.blockID);
		world.setBlock(i + 2, j + 5, k + 23, Block.planks.blockID);
		world.setBlock(i + 2, j + 5, k + 24, Block.planks.blockID);
		world.setBlock(i + 2, j + 5, k + 25, Block.planks.blockID);
		world.setBlock(i + 2, j + 5, k + 26, Block.planks.blockID);
		world.setBlock(i + 2, j + 5, k + 27, Block.planks.blockID);
		world.setBlock(i + 2, j + 5, k + 28, Block.planks.blockID);
		world.setBlock(i + 2, j + 5, k + 29, Block.planks.blockID);
		world.setBlock(i + 2, j + 5, k + 30, Block.planks.blockID);
		world.setBlock(i + 2, j + 5, k + 31, Block.planks.blockID);
		world.setBlock(i + 2, j + 5, k + 32, Block.planks.blockID);
		world.setBlock(i + 2, j + 5, k + 33, Block.planks.blockID);
		world.setBlock(i + 2, j + 5, k + 34, Block.planks.blockID);
		world.setBlock(i + 2, j + 5, k + 35, Block.planks.blockID);
		world.setBlock(i + 2, j + 5, k + 36, Block.planks.blockID);
		world.setBlock(i + 2, j + 5, k + 37, Block.planks.blockID);
		world.setBlock(i + 2, j + 5, k + 38, Block.planks.blockID);
		world.setBlock(i + 2, j + 5, k + 39, Block.planks.blockID);
		world.setBlock(i + 2, j + 5, k + 40, Block.planks.blockID);
		world.setBlock(i + 2, j + 5, k + 41, Block.planks.blockID);
		world.setBlock(i + 2, j + 5, k + 42, Block.planks.blockID);
		world.setBlock(i + 2, j + 5, k + 43, Block.planks.blockID);
		world.setBlock(i + 2, j + 5, k + 44, Block.planks.blockID);
		world.setBlock(i + 2, j + 5, k + 45, Block.planks.blockID);
		world.setBlock(i + 2, j + 5, k + 46, Block.planks.blockID);
		world.setBlock(i + 2, j + 5, k + 47, Block.planks.blockID);
		world.setBlock(i + 2, j + 5, k + 48, Block.planks.blockID);
		world.setBlock(i + 2, j + 5, k + 49, Block.planks.blockID);
		world.setBlock(i + 2, j + 5, k + 50, Block.planks.blockID);
		world.setBlock(i + 2, j + 6, k + 8, Block.planks.blockID);
		world.setBlock(i + 2, j + 6, k + 9, Block.planks.blockID);
		world.setBlock(i + 2, j + 6, k + 10, Block.planks.blockID);
		world.setBlock(i + 2, j + 6, k + 11, Block.planks.blockID);
		world.setBlock(i + 2, j + 6, k + 12, Block.planks.blockID);
		world.setBlock(i + 2, j + 6, k + 49, Block.planks.blockID);
		world.setBlock(i + 2, j + 6, k + 50, Block.planks.blockID);
		world.setBlock(i + 2, j + 7, k + 6, Block.planks.blockID);
		world.setBlock(i + 2, j + 7, k + 7, Block.planks.blockID);
		world.setBlockAndMetadata(i + 2, j + 7, k + 8, Block.chest.blockID, 5);
		world.setBlockAndMetadata(i + 2, j + 7, k + 9, Block.chest.blockID, 5);
		world.setBlockAndMetadata(i + 2, j + 7, k + 10, Block.chest.blockID, 5);
		world.setBlockAndMetadata(i + 2, j + 7, k + 11, Block.chest.blockID, 5);
		world.setBlock(i + 2, j + 7, k + 12, Block.planks.blockID);
		world.setBlock(i + 2, j + 7, k + 49, Block.planks.blockID);
		world.setBlock(i + 2, j + 7, k + 50, Block.planks.blockID);
		world.setBlock(i + 2, j + 8, k + 6, Block.planks.blockID);
		world.setBlock(i + 2, j + 8, k + 7, Block.planks.blockID);
		world.setBlock(i + 2, j + 8, k + 8, Block.planks.blockID);
		world.setBlock(i + 2, j + 8, k + 9, Block.planks.blockID);
		world.setBlock(i + 2, j + 8, k + 10, Block.planks.blockID);
		world.setBlock(i + 2, j + 8, k + 11, Block.planks.blockID);
		world.setBlock(i + 2, j + 8, k + 12, Block.planks.blockID);
		world.setBlock(i + 2, j + 8, k + 13, Block.planks.blockID);
		world.setBlock(i + 2, j + 8, k + 14, Block.planks.blockID);
		world.setBlock(i + 2, j + 8, k + 15, Block.planks.blockID);
		world.setBlock(i + 2, j + 8, k + 16, Block.planks.blockID);
		world.setBlock(i + 2, j + 8, k + 17, Block.planks.blockID);
		world.setBlock(i + 2, j + 8, k + 18, Block.planks.blockID);
		world.setBlock(i + 2, j + 8, k + 19, Block.planks.blockID);
		world.setBlock(i + 2, j + 8, k + 20, Block.planks.blockID);
		world.setBlock(i + 2, j + 8, k + 21, Block.planks.blockID);
		world.setBlock(i + 2, j + 8, k + 22, Block.planks.blockID);
		world.setBlock(i + 2, j + 8, k + 23, Block.planks.blockID);
		world.setBlock(i + 2, j + 8, k + 24, Block.planks.blockID);
		world.setBlock(i + 2, j + 8, k + 25, Block.planks.blockID);
		world.setBlock(i + 2, j + 8, k + 26, Block.planks.blockID);
		world.setBlock(i + 2, j + 8, k + 27, Block.planks.blockID);
		world.setBlock(i + 2, j + 8, k + 28, Block.planks.blockID);
		world.setBlock(i + 2, j + 8, k + 29, Block.planks.blockID);
		world.setBlock(i + 2, j + 8, k + 30, Block.planks.blockID);
		world.setBlock(i + 2, j + 8, k + 31, Block.planks.blockID);
		world.setBlock(i + 2, j + 8, k + 32, Block.planks.blockID);
		world.setBlock(i + 2, j + 8, k + 33, Block.planks.blockID);
		world.setBlock(i + 2, j + 8, k + 34, Block.planks.blockID);
		world.setBlock(i + 2, j + 8, k + 35, Block.planks.blockID);
		world.setBlock(i + 2, j + 8, k + 36, Block.planks.blockID);
		world.setBlock(i + 2, j + 8, k + 37, Block.planks.blockID);
		world.setBlock(i + 2, j + 8, k + 38, Block.planks.blockID);
		world.setBlock(i + 2, j + 8, k + 39, Block.planks.blockID);
		world.setBlock(i + 2, j + 8, k + 40, Block.planks.blockID);
		world.setBlock(i + 2, j + 8, k + 41, Block.planks.blockID);
		world.setBlock(i + 2, j + 8, k + 42, Block.planks.blockID);
		world.setBlock(i + 2, j + 8, k + 43, Block.planks.blockID);
		world.setBlockAndMetadata(i + 2, j + 8, k + 44, Block.cloth.blockID, 14);
		world.setBlockAndMetadata(i + 2, j + 8, k + 45, Block.cloth.blockID, 14);
		world.setBlockAndMetadata(i + 2, j + 8, k + 46, Block.cloth.blockID, 14);
		world.setBlockAndMetadata(i + 2, j + 8, k + 47, Block.cloth.blockID, 14);
		world.setBlockAndMetadata(i + 2, j + 8, k + 48, Block.cloth.blockID, 14);
		world.setBlockAndMetadata(i + 2, j + 8, k + 49, Block.cloth.blockID, 14);
		world.setBlockAndMetadata(i + 2, j + 8, k + 50, Block.cloth.blockID, 14);
		world.setBlock(i + 2, j + 9, k + 6, Block.planks.blockID);
		world.setBlockAndMetadata(i + 2, j + 9, k + 39, Block.stairCompactPlanks.blockID, 2);
		world.setBlock(i + 2, j + 9, k + 40, Block.planks.blockID);
		world.setBlock(i + 2, j + 9, k + 41, Block.planks.blockID);
		world.setBlock(i + 2, j + 9, k + 42, Block.planks.blockID);
		world.setBlock(i + 2, j + 9, k + 43, Block.planks.blockID);
		world.setBlock(i + 2, j + 9, k + 51, Block.planks.blockID);
		world.setBlock(i + 2, j + 10, k + 5, Block.planks.blockID);
		world.setBlock(i + 2, j + 10, k + 6, Block.planks.blockID);
		world.setBlockAndMetadata(i + 2, j + 10, k + 40, Block.stairCompactPlanks.blockID, 2);
		world.setBlock(i + 2, j + 10, k + 41, Block.planks.blockID);
		world.setBlock(i + 2, j + 10, k + 42, Block.planks.blockID);
		world.setBlock(i + 2, j + 10, k + 43, Block.planks.blockID);
		world.setBlock(i + 2, j + 10, k + 51, Block.planks.blockID);
		world.setBlock(i + 2, j + 11, k + 5, Block.planks.blockID);
		world.setBlock(i + 2, j + 11, k + 6, Block.planks.blockID);
		world.setBlockAndMetadata(i + 2, j + 11, k + 41, Block.stairCompactPlanks.blockID, 2);
		world.setBlock(i + 2, j + 11, k + 42, Block.planks.blockID);
		world.setBlock(i + 2, j + 11, k + 43, Block.planks.blockID);
		world.setBlock(i + 2, j + 11, k + 51, Block.planks.blockID);
		world.setBlock(i + 2, j + 12, k + 5, Block.fence.blockID);
		world.setBlock(i + 2, j + 12, k + 6, Block.fence.blockID);
		world.setBlockAndMetadata(i + 2, j + 12, k + 42, Block.stairCompactPlanks.blockID, 2);
		world.setBlock(i + 2, j + 12, k + 43, Block.planks.blockID);
		world.setBlock(i + 2, j + 12, k + 44, Block.planks.blockID);
		world.setBlock(i + 2, j + 12, k + 45, Block.planks.blockID);
		world.setBlock(i + 2, j + 12, k + 46, Block.planks.blockID);
		world.setBlock(i + 2, j + 12, k + 47, Block.planks.blockID);
		world.setBlock(i + 2, j + 12, k + 48, Block.planks.blockID);
		world.setBlock(i + 2, j + 12, k + 49, Block.planks.blockID);
		world.setBlock(i + 2, j + 12, k + 50, Block.planks.blockID);
		world.setBlock(i + 2, j + 12, k + 51, Block.planks.blockID);
		world.setBlock(i + 2, j + 13, k + 50, Block.fence.blockID);
		world.setBlock(i + 2, j + 13, k + 51, Block.fence.blockID);
		world.setBlock(i + 3, j + 1, k + 14, Block.planks.blockID);
		world.setBlock(i + 3, j + 1, k + 15, Block.planks.blockID);
		world.setBlock(i + 3, j + 1, k + 16, Block.planks.blockID);
		world.setBlock(i + 3, j + 1, k + 17, Block.planks.blockID);
		world.setBlock(i + 3, j + 1, k + 18, Block.planks.blockID);
		world.setBlock(i + 3, j + 1, k + 19, Block.planks.blockID);
		world.setBlock(i + 3, j + 1, k + 20, Block.planks.blockID);
		world.setBlock(i + 3, j + 1, k + 21, Block.planks.blockID);
		world.setBlock(i + 3, j + 1, k + 22, Block.planks.blockID);
		world.setBlock(i + 3, j + 1, k + 23, Block.planks.blockID);
		world.setBlock(i + 3, j + 1, k + 24, Block.planks.blockID);
		world.setBlock(i + 3, j + 1, k + 25, Block.planks.blockID);
		world.setBlock(i + 3, j + 1, k + 26, Block.planks.blockID);
		world.setBlock(i + 3, j + 1, k + 27, Block.planks.blockID);
		world.setBlock(i + 3, j + 1, k + 28, Block.planks.blockID);
		world.setBlock(i + 3, j + 1, k + 29, Block.planks.blockID);
		world.setBlock(i + 3, j + 1, k + 30, Block.planks.blockID);
		world.setBlock(i + 3, j + 1, k + 31, Block.planks.blockID);
		world.setBlock(i + 3, j + 1, k + 32, Block.planks.blockID);
		world.setBlock(i + 3, j + 1, k + 33, Block.planks.blockID);
		world.setBlock(i + 3, j + 1, k + 34, Block.planks.blockID);
		world.setBlock(i + 3, j + 1, k + 35, Block.planks.blockID);
		world.setBlock(i + 3, j + 1, k + 36, Block.planks.blockID);
		world.setBlock(i + 3, j + 1, k + 37, Block.planks.blockID);
		world.setBlock(i + 3, j + 1, k + 38, Block.planks.blockID);
		world.setBlock(i + 3, j + 1, k + 39, Block.planks.blockID);
		world.setBlock(i + 3, j + 1, k + 40, Block.planks.blockID);
		world.setBlock(i + 3, j + 1, k + 41, Block.planks.blockID);
		world.setBlock(i + 3, j + 1, k + 42, Block.planks.blockID);
		world.setBlock(i + 3, j + 1, k + 43, Block.planks.blockID);
		world.setBlock(i + 3, j + 1, k + 44, Block.planks.blockID);
		world.setBlock(i + 3, j + 1, k + 45, Block.planks.blockID);
		world.setBlock(i + 3, j + 1, k + 46, Block.planks.blockID);
		world.setBlock(i + 3, j + 1, k + 47, Block.planks.blockID);
		world.setBlock(i + 3, j + 2, k + 12, Block.planks.blockID);
		world.setBlock(i + 3, j + 2, k + 13, Block.planks.blockID);
		world.setBlock(i + 3, j + 2, k + 14, Block.planks.blockID);
		world.setBlock(i + 3, j + 2, k + 15, Block.planks.blockID);
		world.setBlock(i + 3, j + 2, k + 16, Block.planks.blockID);
		world.setBlock(i + 3, j + 2, k + 17, Block.planks.blockID);
		world.setBlock(i + 3, j + 2, k + 18, Block.planks.blockID);
		world.setBlock(i + 3, j + 2, k + 19, Block.planks.blockID);
		world.setBlock(i + 3, j + 2, k + 20, Block.planks.blockID);
		world.setBlock(i + 3, j + 2, k + 21, Block.planks.blockID);
		world.setBlock(i + 3, j + 2, k + 22, Block.planks.blockID);
		world.setBlock(i + 3, j + 2, k + 23, Block.planks.blockID);
		world.setBlock(i + 3, j + 2, k + 24, Block.planks.blockID);
		world.setBlock(i + 3, j + 2, k + 25, Block.planks.blockID);
		world.setBlock(i + 3, j + 2, k + 26, Block.planks.blockID);
		world.setBlock(i + 3, j + 2, k + 27, Block.planks.blockID);
		world.setBlock(i + 3, j + 2, k + 28, Block.planks.blockID);
		world.setBlock(i + 3, j + 2, k + 29, Block.planks.blockID);
		world.setBlock(i + 3, j + 2, k + 30, Block.planks.blockID);
		world.setBlock(i + 3, j + 2, k + 31, Block.planks.blockID);
		world.setBlock(i + 3, j + 2, k + 32, Block.planks.blockID);
		world.setBlock(i + 3, j + 2, k + 33, Block.planks.blockID);
		world.setBlock(i + 3, j + 2, k + 34, Block.planks.blockID);
		world.setBlock(i + 3, j + 2, k + 35, Block.planks.blockID);
		world.setBlock(i + 3, j + 2, k + 36, Block.planks.blockID);
		world.setBlock(i + 3, j + 2, k + 37, Block.planks.blockID);
		world.setBlock(i + 3, j + 2, k + 38, Block.planks.blockID);
		world.setBlock(i + 3, j + 2, k + 39, Block.planks.blockID);
		world.setBlock(i + 3, j + 2, k + 40, Block.planks.blockID);
		world.setBlock(i + 3, j + 2, k + 41, Block.planks.blockID);
		world.setBlock(i + 3, j + 2, k + 42, Block.planks.blockID);
		world.setBlock(i + 3, j + 2, k + 43, Block.planks.blockID);
		world.setBlock(i + 3, j + 2, k + 44, Block.planks.blockID);
		world.setBlock(i + 3, j + 2, k + 45, Block.planks.blockID);
		world.setBlock(i + 3, j + 2, k + 46, Block.planks.blockID);
		world.setBlock(i + 3, j + 2, k + 47, Block.planks.blockID);
		world.setBlock(i + 3, j + 2, k + 48, Block.planks.blockID);
		world.setBlock(i + 3, j + 2, k + 49, Block.planks.blockID);
		world.setBlock(i + 3, j + 3, k + 9, Block.planks.blockID);
		world.setBlock(i + 3, j + 3, k + 10, Block.planks.blockID);
		world.setBlock(i + 3, j + 3, k + 11, Block.planks.blockID);
		world.setBlock(i + 3, j + 3, k + 13, Block.planks.blockID);
		world.setBlock(i + 3, j + 3, k + 14, Block.bed.blockID);
		world.setBlock(i + 3, j + 3, k + 19, Block.planks.blockID);
		world.setBlock(i + 3, j + 3, k + 20, Block.bed.blockID);
		world.setBlock(i + 3, j + 3, k + 25, Block.planks.blockID);
		world.setBlock(i + 3, j + 3, k + 26, Block.bed.blockID);
		world.setBlock(i + 3, j + 3, k + 31, Block.planks.blockID);
		world.setBlock(i + 3, j + 3, k + 32, Block.bed.blockID);
		world.setBlock(i + 3, j + 3, k + 37, Block.planks.blockID);
		world.setBlock(i + 3, j + 3, k + 38, Block.bed.blockID);
		world.setBlock(i + 3, j + 3, k + 43, Block.planks.blockID);
		world.setBlock(i + 3, j + 3, k + 50, Block.planks.blockID);
		world.setBlock(i + 3, j + 3, k + 51, Block.planks.blockID);
		world.setBlock(i + 3, j + 4, k + 9, Block.planks.blockID);
		world.setBlock(i + 3, j + 4, k + 10, Block.planks.blockID);
		world.setBlock(i + 3, j + 4, k + 11, Block.planks.blockID);
		world.setBlock(i + 3, j + 4, k + 13, Block.planks.blockID);
		world.setBlock(i + 3, j + 4, k + 19, Block.planks.blockID);
		world.setBlock(i + 3, j + 4, k + 25, Block.planks.blockID);
		world.setBlock(i + 3, j + 4, k + 31, Block.planks.blockID);
		world.setBlock(i + 3, j + 4, k + 37, Block.planks.blockID);
		world.setBlock(i + 3, j + 4, k + 43, Block.planks.blockID);
		world.setBlock(i + 3, j + 4, k + 50, Block.planks.blockID);
		world.setBlock(i + 3, j + 4, k + 51, Block.planks.blockID);
		world.setBlock(i + 3, j + 5, k + 9, Block.planks.blockID);
		world.setBlock(i + 3, j + 5, k + 10, Block.planks.blockID);
		world.setBlock(i + 3, j + 5, k + 11, Block.planks.blockID);
		world.setBlock(i + 3, j + 5, k + 12, Block.planks.blockID);
		world.setBlock(i + 3, j + 5, k + 13, Block.planks.blockID);
		world.setBlock(i + 3, j + 5, k + 14, Block.planks.blockID);
		world.setBlock(i + 3, j + 5, k + 15, Block.planks.blockID);
		world.setBlock(i + 3, j + 5, k + 16, Block.planks.blockID);
		world.setBlock(i + 3, j + 5, k + 17, Block.planks.blockID);
		world.setBlock(i + 3, j + 5, k + 18, Block.planks.blockID);
		world.setBlock(i + 3, j + 5, k + 19, Block.planks.blockID);
		world.setBlock(i + 3, j + 5, k + 20, Block.planks.blockID);
		world.setBlock(i + 3, j + 5, k + 21, Block.planks.blockID);
		world.setBlock(i + 3, j + 5, k + 22, Block.planks.blockID);
		world.setBlock(i + 3, j + 5, k + 23, Block.planks.blockID);
		world.setBlock(i + 3, j + 5, k + 24, Block.planks.blockID);
		world.setBlock(i + 3, j + 5, k + 25, Block.planks.blockID);
		world.setBlock(i + 3, j + 5, k + 26, Block.planks.blockID);
		world.setBlock(i + 3, j + 5, k + 27, Block.planks.blockID);
		world.setBlock(i + 3, j + 5, k + 28, Block.planks.blockID);
		world.setBlock(i + 3, j + 5, k + 29, Block.planks.blockID);
		world.setBlock(i + 3, j + 5, k + 30, Block.planks.blockID);
		world.setBlock(i + 3, j + 5, k + 31, Block.planks.blockID);
		world.setBlock(i + 3, j + 5, k + 32, Block.planks.blockID);
		world.setBlock(i + 3, j + 5, k + 33, Block.planks.blockID);
		world.setBlock(i + 3, j + 5, k + 34, Block.planks.blockID);
		world.setBlock(i + 3, j + 5, k + 35, Block.planks.blockID);
		world.setBlock(i + 3, j + 5, k + 36, Block.planks.blockID);
		world.setBlock(i + 3, j + 5, k + 37, Block.planks.blockID);
		world.setBlock(i + 3, j + 5, k + 38, Block.planks.blockID);
		world.setBlock(i + 3, j + 5, k + 39, Block.planks.blockID);
		world.setBlock(i + 3, j + 5, k + 40, Block.planks.blockID);
		world.setBlock(i + 3, j + 5, k + 41, Block.planks.blockID);
		world.setBlock(i + 3, j + 5, k + 42, Block.planks.blockID);
		world.setBlock(i + 3, j + 5, k + 43, Block.planks.blockID);
		world.setBlock(i + 3, j + 5, k + 44, Block.planks.blockID);
		world.setBlock(i + 3, j + 5, k + 45, Block.planks.blockID);
		world.setBlock(i + 3, j + 5, k + 46, Block.planks.blockID);
		world.setBlock(i + 3, j + 5, k + 47, Block.planks.blockID);
		world.setBlock(i + 3, j + 5, k + 48, Block.planks.blockID);
		world.setBlock(i + 3, j + 5, k + 49, Block.planks.blockID);
		world.setBlock(i + 3, j + 5, k + 50, Block.planks.blockID);
		world.setBlock(i + 3, j + 5, k + 51, Block.planks.blockID);
		world.setBlock(i + 3, j + 6, k + 7, Block.planks.blockID);
		world.setBlock(i + 3, j + 6, k + 8, Block.planks.blockID);
		world.setBlockAndMetadata(i + 3, j + 6, k + 9, Block.chest.blockID, 5);
		world.setBlockAndMetadata(i + 3, j + 6, k + 10, Block.chest.blockID, 5);
		world.setBlock(i + 3, j + 6, k + 33, Block.cloth.blockID);
		world.setBlock(i + 3, j + 6, k + 34, Block.cloth.blockID);
		world.setBlock(i + 3, j + 6, k + 35, Block.cloth.blockID);
		world.setBlock(i + 3, j + 6, k + 36, Block.cloth.blockID);
		world.setBlock(i + 3, j + 6, k + 37, Block.cloth.blockID);
		world.setBlock(i + 3, j + 6, k + 38, Block.cloth.blockID);
		world.setBlock(i + 3, j + 6, k + 39, Block.cloth.blockID);
		world.setBlock(i + 3, j + 6, k + 40, Block.cloth.blockID);
		world.setBlock(i + 3, j + 6, k + 50, Block.planks.blockID);
		world.setBlock(i + 3, j + 6, k + 51, Block.planks.blockID);
		world.setBlock(i + 3, j + 7, k + 6, Block.planks.blockID);
		world.setBlock(i + 3, j + 7, k + 34, Block.cloth.blockID);
		world.setBlock(i + 3, j + 7, k + 35, Block.cloth.blockID);
		world.setBlock(i + 3, j + 7, k + 36, Block.cloth.blockID);
		world.setBlock(i + 3, j + 7, k + 37, Block.cloth.blockID);
		world.setBlock(i + 3, j + 7, k + 38, Block.cloth.blockID);
		world.setBlock(i + 3, j + 7, k + 39, Block.cloth.blockID);
		world.setBlock(i + 3, j + 7, k + 50, Block.planks.blockID);
		world.setBlock(i + 3, j + 7, k + 51, Block.planks.blockID);
		world.setBlock(i + 3, j + 8, k + 6, Block.planks.blockID);
		world.setBlock(i + 3, j + 8, k + 7, Block.planks.blockID);
		world.setBlock(i + 3, j + 8, k + 8, Block.planks.blockID);
		world.setBlock(i + 3, j + 8, k + 9, Block.planks.blockID);
		world.setBlock(i + 3, j + 8, k + 10, Block.planks.blockID);
		world.setBlock(i + 3, j + 8, k + 11, Block.planks.blockID);
		world.setBlock(i + 3, j + 8, k + 12, Block.planks.blockID);
		world.setBlock(i + 3, j + 8, k + 13, Block.planks.blockID);
		world.setBlock(i + 3, j + 8, k + 14, Block.planks.blockID);
		world.setBlock(i + 3, j + 8, k + 15, Block.planks.blockID);
		world.setBlock(i + 3, j + 8, k + 16, Block.planks.blockID);
		world.setBlock(i + 3, j + 8, k + 17, Block.planks.blockID);
		world.setBlock(i + 3, j + 8, k + 18, Block.planks.blockID);
		world.setBlock(i + 3, j + 8, k + 19, Block.planks.blockID);
		world.setBlock(i + 3, j + 8, k + 20, Block.planks.blockID);
		world.setBlock(i + 3, j + 8, k + 21, Block.planks.blockID);
		world.setBlock(i + 3, j + 8, k + 22, Block.planks.blockID);
		world.setBlock(i + 3, j + 8, k + 23, Block.planks.blockID);
		world.setBlock(i + 3, j + 8, k + 24, Block.planks.blockID);
		world.setBlock(i + 3, j + 8, k + 25, Block.planks.blockID);
		world.setBlock(i + 3, j + 8, k + 26, Block.planks.blockID);
		world.setBlock(i + 3, j + 8, k + 27, Block.planks.blockID);
		world.setBlock(i + 3, j + 8, k + 28, Block.planks.blockID);
		world.setBlock(i + 3, j + 8, k + 29, Block.planks.blockID);
		world.setBlock(i + 3, j + 8, k + 30, Block.planks.blockID);
		world.setBlock(i + 3, j + 8, k + 31, Block.planks.blockID);
		world.setBlock(i + 3, j + 8, k + 32, Block.planks.blockID);
		world.setBlock(i + 3, j + 8, k + 33, Block.planks.blockID);
		world.setBlock(i + 3, j + 8, k + 34, Block.planks.blockID);
		world.setBlock(i + 3, j + 8, k + 35, Block.planks.blockID);
		world.setBlock(i + 3, j + 8, k + 36, Block.planks.blockID);
		world.setBlock(i + 3, j + 8, k + 37, Block.planks.blockID);
		world.setBlock(i + 3, j + 8, k + 38, Block.planks.blockID);
		world.setBlock(i + 3, j + 8, k + 39, Block.planks.blockID);
		world.setBlock(i + 3, j + 8, k + 40, Block.planks.blockID);
		world.setBlock(i + 3, j + 8, k + 41, Block.planks.blockID);
		world.setBlock(i + 3, j + 8, k + 42, Block.planks.blockID);
		world.setBlock(i + 3, j + 8, k + 43, Block.planks.blockID);
		world.setBlockAndMetadata(i + 3, j + 8, k + 44, Block.cloth.blockID, 14);
		world.setBlockAndMetadata(i + 3, j + 8, k + 45, Block.cloth.blockID, 14);
		world.setBlockAndMetadata(i + 3, j + 8, k + 46, Block.cloth.blockID, 14);
		world.setBlockAndMetadata(i + 3, j + 8, k + 47, Block.cloth.blockID, 14);
		world.setBlockAndMetadata(i + 3, j + 8, k + 48, Block.cloth.blockID, 14);
		world.setBlockAndMetadata(i + 3, j + 8, k + 49, Block.cloth.blockID, 14);
		world.setBlockAndMetadata(i + 3, j + 8, k + 50, Block.cloth.blockID, 14);
		world.setBlockAndMetadata(i + 3, j + 8, k + 51, Block.cloth.blockID, 14);
		world.setBlock(i + 3, j + 9, k + 5, Block.planks.blockID);
		world.setBlock(i + 3, j + 9, k + 6, Block.planks.blockID);
		world.setBlockAndMetadata(i + 3, j + 9, k + 39, Block.stairCompactPlanks.blockID, 2);
		world.setBlock(i + 3, j + 9, k + 40, Block.planks.blockID);
		world.setBlock(i + 3, j + 9, k + 41, Block.planks.blockID);
		world.setBlock(i + 3, j + 9, k + 42, Block.planks.blockID);
		world.setBlock(i + 3, j + 9, k + 43, Block.planks.blockID);
		world.setBlock(i + 3, j + 9, k + 52, Block.planks.blockID);
		world.setBlock(i + 3, j + 10, k + 4, Block.planks.blockID);
		world.setBlock(i + 3, j + 10, k + 5, Block.planks.blockID);
		world.setBlock(i + 3, j + 10, k + 6, Block.planks.blockID);
		world.setBlockAndMetadata(i + 3, j + 10, k + 40, Block.stairCompactPlanks.blockID, 2);
		world.setBlock(i + 3, j + 10, k + 41, Block.planks.blockID);
		world.setBlock(i + 3, j + 10, k + 42, Block.planks.blockID);
		world.setBlock(i + 3, j + 10, k + 43, Block.planks.blockID);
		world.setBlock(i + 3, j + 10, k + 52, Block.planks.blockID);
		world.setBlock(i + 3, j + 11, k + 4, Block.planks.blockID);
		world.setBlock(i + 3, j + 11, k + 5, Block.planks.blockID);
		world.setBlock(i + 3, j + 11, k + 6, Block.planks.blockID);
		world.setBlockAndMetadata(i + 3, j + 11, k + 41, Block.stairCompactPlanks.blockID, 2);
		world.setBlock(i + 3, j + 11, k + 42, Block.planks.blockID);
		world.setBlock(i + 3, j + 11, k + 43, Block.planks.blockID);
		world.setBlock(i + 3, j + 11, k + 52, Block.planks.blockID);
		world.setBlock(i + 3, j + 12, k + 4, Block.fence.blockID);
		world.setBlock(i + 3, j + 12, k + 5, Block.fence.blockID);
		world.setBlockAndMetadata(i + 3, j + 12, k + 42, Block.stairCompactPlanks.blockID, 2);
		world.setBlock(i + 3, j + 12, k + 43, Block.planks.blockID);
		world.setBlock(i + 3, j + 12, k + 44, Block.planks.blockID);
		world.setBlock(i + 3, j + 12, k + 45, Block.planks.blockID);
		world.setBlock(i + 3, j + 12, k + 46, Block.planks.blockID);
		world.setBlock(i + 3, j + 12, k + 47, Block.planks.blockID);
		world.setBlock(i + 3, j + 12, k + 48, Block.planks.blockID);
		world.setBlock(i + 3, j + 12, k + 49, Block.planks.blockID);
		world.setBlock(i + 3, j + 12, k + 50, Block.planks.blockID);
		world.setBlock(i + 3, j + 12, k + 51, Block.planks.blockID);
		world.setBlock(i + 3, j + 12, k + 52, Block.planks.blockID);
		world.setBlock(i + 3, j + 13, k + 51, Block.fence.blockID);
		world.setBlock(i + 3, j + 13, k + 52, Block.fence.blockID);
		world.setBlock(i + 4, j + 0, k + 14, Block.planks.blockID);
		world.setBlock(i + 4, j + 0, k + 15, Block.planks.blockID);
		world.setBlock(i + 4, j + 0, k + 16, Block.planks.blockID);
		world.setBlock(i + 4, j + 0, k + 17, Block.planks.blockID);
		world.setBlock(i + 4, j + 0, k + 18, Block.planks.blockID);
		world.setBlock(i + 4, j + 0, k + 19, Block.planks.blockID);
		world.setBlock(i + 4, j + 0, k + 20, Block.planks.blockID);
		world.setBlock(i + 4, j + 0, k + 21, Block.planks.blockID);
		world.setBlock(i + 4, j + 0, k + 22, Block.planks.blockID);
		world.setBlock(i + 4, j + 0, k + 23, Block.planks.blockID);
		world.setBlock(i + 4, j + 0, k + 24, Block.planks.blockID);
		world.setBlock(i + 4, j + 0, k + 25, Block.planks.blockID);
		world.setBlock(i + 4, j + 0, k + 26, Block.planks.blockID);
		world.setBlock(i + 4, j + 0, k + 27, Block.planks.blockID);
		world.setBlock(i + 4, j + 0, k + 28, Block.planks.blockID);
		world.setBlock(i + 4, j + 0, k + 29, Block.planks.blockID);
		world.setBlock(i + 4, j + 0, k + 30, Block.planks.blockID);
		world.setBlock(i + 4, j + 0, k + 31, Block.planks.blockID);
		world.setBlock(i + 4, j + 0, k + 32, Block.planks.blockID);
		world.setBlock(i + 4, j + 0, k + 33, Block.planks.blockID);
		world.setBlock(i + 4, j + 0, k + 34, Block.planks.blockID);
		world.setBlock(i + 4, j + 0, k + 35, Block.planks.blockID);
		world.setBlock(i + 4, j + 0, k + 36, Block.planks.blockID);
		world.setBlock(i + 4, j + 0, k + 37, Block.planks.blockID);
		world.setBlock(i + 4, j + 0, k + 38, Block.planks.blockID);
		world.setBlock(i + 4, j + 0, k + 39, Block.planks.blockID);
		world.setBlock(i + 4, j + 0, k + 40, Block.planks.blockID);
		world.setBlock(i + 4, j + 0, k + 41, Block.planks.blockID);
		world.setBlock(i + 4, j + 0, k + 42, Block.planks.blockID);
		world.setBlock(i + 4, j + 0, k + 43, Block.planks.blockID);
		world.setBlock(i + 4, j + 0, k + 44, Block.planks.blockID);
		world.setBlock(i + 4, j + 0, k + 45, Block.planks.blockID);
		world.setBlock(i + 4, j + 0, k + 46, Block.planks.blockID);
		world.setBlock(i + 4, j + 1, k + 12, Block.planks.blockID);
		world.setBlock(i + 4, j + 1, k + 13, Block.planks.blockID);
		world.setBlock(i + 4, j + 1, k + 14, Block.planks.blockID);
		world.setBlock(i + 4, j + 1, k + 47, Block.planks.blockID);
		world.setBlock(i + 4, j + 1, k + 48, Block.planks.blockID);
		world.setBlock(i + 4, j + 2, k + 10, Block.planks.blockID);
		world.setBlock(i + 4, j + 2, k + 11, Block.planks.blockID);
		world.setBlock(i + 4, j + 2, k + 12, Block.planks.blockID);
		world.setBlock(i + 4, j + 2, k + 13, Block.planks.blockID);
		world.setBlock(i + 4, j + 2, k + 14, Block.planks.blockID);
		world.setBlock(i + 4, j + 2, k + 15, Block.planks.blockID);
		world.setBlock(i + 4, j + 2, k + 16, Block.planks.blockID);
		world.setBlock(i + 4, j + 2, k + 17, Block.planks.blockID);
		world.setBlock(i + 4, j + 2, k + 18, Block.planks.blockID);
		world.setBlock(i + 4, j + 2, k + 19, Block.planks.blockID);
		world.setBlock(i + 4, j + 2, k + 20, Block.planks.blockID);
		world.setBlock(i + 4, j + 2, k + 21, Block.planks.blockID);
		world.setBlock(i + 4, j + 2, k + 22, Block.planks.blockID);
		world.setBlock(i + 4, j + 2, k + 23, Block.planks.blockID);
		world.setBlock(i + 4, j + 2, k + 24, Block.planks.blockID);
		world.setBlock(i + 4, j + 2, k + 25, Block.planks.blockID);
		world.setBlock(i + 4, j + 2, k + 26, Block.planks.blockID);
		world.setBlock(i + 4, j + 2, k + 27, Block.planks.blockID);
		world.setBlock(i + 4, j + 2, k + 28, Block.planks.blockID);
		world.setBlock(i + 4, j + 2, k + 29, Block.planks.blockID);
		world.setBlock(i + 4, j + 2, k + 30, Block.planks.blockID);
		world.setBlock(i + 4, j + 2, k + 31, Block.planks.blockID);
		world.setBlock(i + 4, j + 2, k + 32, Block.planks.blockID);
		world.setBlock(i + 4, j + 2, k + 33, Block.planks.blockID);
		world.setBlock(i + 4, j + 2, k + 34, Block.planks.blockID);
		world.setBlock(i + 4, j + 2, k + 35, Block.planks.blockID);
		world.setBlock(i + 4, j + 2, k + 36, Block.planks.blockID);
		world.setBlock(i + 4, j + 2, k + 37, Block.planks.blockID);
		world.setBlock(i + 4, j + 2, k + 38, Block.planks.blockID);
		world.setBlock(i + 4, j + 2, k + 39, Block.planks.blockID);
		world.setBlock(i + 4, j + 2, k + 40, Block.planks.blockID);
		world.setBlock(i + 4, j + 2, k + 41, Block.planks.blockID);
		world.setBlock(i + 4, j + 2, k + 42, Block.planks.blockID);
		world.setBlock(i + 4, j + 2, k + 43, Block.planks.blockID);
		world.setBlock(i + 4, j + 2, k + 44, Block.planks.blockID);
		world.setBlock(i + 4, j + 2, k + 45, Block.planks.blockID);
		world.setBlock(i + 4, j + 2, k + 46, Block.planks.blockID);
		world.setBlock(i + 4, j + 2, k + 47, Block.planks.blockID);
		world.setBlock(i + 4, j + 2, k + 48, Block.planks.blockID);
		world.setBlock(i + 4, j + 2, k + 49, Block.planks.blockID);
		world.setBlock(i + 4, j + 2, k + 50, Block.planks.blockID);
		world.setBlock(i + 4, j + 3, k + 7, Block.planks.blockID);
		world.setBlock(i + 4, j + 3, k + 8, Block.planks.blockID);
		world.setBlock(i + 4, j + 3, k + 9, Block.planks.blockID);
		world.setBlockAndMetadata(i + 4, j + 3, k + 10, Block.chest.blockID, 5);
		world.setBlock(i + 4, j + 3, k + 13, Block.planks.blockID);
		world.setBlock(i + 4, j + 3, k + 19, Block.planks.blockID);
		world.setBlock(i + 4, j + 3, k + 25, Block.planks.blockID);
		world.setBlock(i + 4, j + 3, k + 31, Block.planks.blockID);
		world.setBlock(i + 4, j + 3, k + 37, Block.planks.blockID);
		world.setBlock(i + 4, j + 3, k + 43, Block.planks.blockID);
		world.setBlock(i + 4, j + 3, k + 51, Block.planks.blockID);
		world.setBlock(i + 4, j + 4, k + 7, Block.planks.blockID);
		world.setBlock(i + 4, j + 4, k + 8, Block.planks.blockID);
		world.setBlock(i + 4, j + 4, k + 9, Block.planks.blockID);
		world.setBlock(i + 4, j + 4, k + 13, Block.planks.blockID);
		world.setBlock(i + 4, j + 4, k + 19, Block.planks.blockID);
		world.setBlock(i + 4, j + 4, k + 25, Block.planks.blockID);
		world.setBlock(i + 4, j + 4, k + 31, Block.planks.blockID);
		world.setBlock(i + 4, j + 4, k + 37, Block.planks.blockID);
		world.setBlock(i + 4, j + 4, k + 43, Block.planks.blockID);
		world.setBlock(i + 4, j + 4, k + 51, Block.planks.blockID);
		world.setBlock(i + 4, j + 5, k + 7, Block.planks.blockID);
		world.setBlock(i + 4, j + 5, k + 8, Block.planks.blockID);
		world.setBlock(i + 4, j + 5, k + 9, Block.planks.blockID);
		world.setBlock(i + 4, j + 5, k + 10, Block.planks.blockID);
		world.setBlock(i + 4, j + 5, k + 11, Block.planks.blockID);
		world.setBlock(i + 4, j + 5, k + 12, Block.planks.blockID);
		world.setBlock(i + 4, j + 5, k + 13, Block.planks.blockID);
		world.setBlock(i + 4, j + 5, k + 14, Block.planks.blockID);
		world.setBlock(i + 4, j + 5, k + 15, Block.planks.blockID);
		world.setBlock(i + 4, j + 5, k + 16, Block.planks.blockID);
		world.setBlock(i + 4, j + 5, k + 17, Block.planks.blockID);
		world.setBlock(i + 4, j + 5, k + 18, Block.planks.blockID);
		world.setBlock(i + 4, j + 5, k + 19, Block.planks.blockID);
		world.setBlock(i + 4, j + 5, k + 20, Block.planks.blockID);
		world.setBlock(i + 4, j + 5, k + 21, Block.planks.blockID);
		world.setBlock(i + 4, j + 5, k + 22, Block.planks.blockID);
		world.setBlock(i + 4, j + 5, k + 23, Block.planks.blockID);
		world.setBlock(i + 4, j + 5, k + 24, Block.planks.blockID);
		world.setBlock(i + 4, j + 5, k + 25, Block.planks.blockID);
		world.setBlock(i + 4, j + 5, k + 26, Block.planks.blockID);
		world.setBlock(i + 4, j + 5, k + 27, Block.planks.blockID);
		world.setBlock(i + 4, j + 5, k + 28, Block.planks.blockID);
		world.setBlock(i + 4, j + 5, k + 29, Block.planks.blockID);
		world.setBlock(i + 4, j + 5, k + 30, Block.planks.blockID);
		world.setBlock(i + 4, j + 5, k + 31, Block.planks.blockID);
		world.setBlock(i + 4, j + 5, k + 32, Block.planks.blockID);
		world.setBlock(i + 4, j + 5, k + 33, Block.planks.blockID);
		world.setBlock(i + 4, j + 5, k + 34, Block.planks.blockID);
		world.setBlock(i + 4, j + 5, k + 35, Block.planks.blockID);
		world.setBlock(i + 4, j + 5, k + 36, Block.planks.blockID);
		world.setBlock(i + 4, j + 5, k + 37, Block.planks.blockID);
		world.setBlock(i + 4, j + 5, k + 38, Block.planks.blockID);
		world.setBlock(i + 4, j + 5, k + 39, Block.planks.blockID);
		world.setBlock(i + 4, j + 5, k + 40, Block.planks.blockID);
		world.setBlock(i + 4, j + 5, k + 41, Block.planks.blockID);
		world.setBlock(i + 4, j + 5, k + 42, Block.planks.blockID);
		world.setBlock(i + 4, j + 5, k + 43, Block.planks.blockID);
		world.setBlock(i + 4, j + 5, k + 44, Block.planks.blockID);
		world.setBlock(i + 4, j + 5, k + 45, Block.planks.blockID);
		world.setBlock(i + 4, j + 5, k + 46, Block.planks.blockID);
		world.setBlock(i + 4, j + 5, k + 47, Block.planks.blockID);
		world.setBlock(i + 4, j + 5, k + 48, Block.planks.blockID);
		world.setBlock(i + 4, j + 5, k + 49, Block.planks.blockID);
		world.setBlock(i + 4, j + 5, k + 50, Block.planks.blockID);
		world.setBlock(i + 4, j + 5, k + 51, Block.planks.blockID);
		world.setBlock(i + 4, j + 6, k + 6, Block.planks.blockID);
		world.setBlock(i + 4, j + 6, k + 7, Block.planks.blockID);
		world.setBlockAndMetadata(i + 4, j + 6, k + 8, Block.chest.blockID, 5);
		world.setBlock(i + 4, j + 6, k + 12, Block.planks.blockID);
		world.setBlock(i + 4, j + 6, k + 33, Block.cloth.blockID);
		world.setBlock(i + 4, j + 6, k + 34, Block.cloth.blockID);
		world.setBlock(i + 4, j + 6, k + 35, Block.cloth.blockID);
		world.setBlock(i + 4, j + 6, k + 36, Block.cloth.blockID);
		world.setBlock(i + 4, j + 6, k + 37, Block.cloth.blockID);
		world.setBlock(i + 4, j + 6, k + 38, Block.cloth.blockID);
		world.setBlock(i + 4, j + 6, k + 39, Block.cloth.blockID);
		world.setBlock(i + 4, j + 6, k + 40, Block.cloth.blockID);
		world.setBlock(i + 4, j + 6, k + 44, Block.fence.blockID);
		world.setBlock(i + 4, j + 6, k + 45, Block.fence.blockID);
		world.setBlock(i + 4, j + 6, k + 46, Block.fence.blockID);
		world.setBlock(i + 4, j + 6, k + 47, Block.fence.blockID);
		world.setBlock(i + 4, j + 6, k + 48, Block.fence.blockID);
		world.setBlock(i + 4, j + 6, k + 51, Block.planks.blockID);
		world.setBlock(i + 4, j + 7, k + 5, Block.planks.blockID);
		world.setBlock(i + 4, j + 7, k + 6, Block.planks.blockID);
		world.setBlock(i + 4, j + 7, k + 12, Block.planks.blockID);
		world.setBlock(i + 4, j + 7, k + 34, Block.cloth.blockID);
		world.setBlock(i + 4, j + 7, k + 35, Block.cloth.blockID);
		world.setBlock(i + 4, j + 7, k + 36, Block.cloth.blockID);
		world.setBlock(i + 4, j + 7, k + 37, Block.cloth.blockID);
		world.setBlock(i + 4, j + 7, k + 38, Block.cloth.blockID);
		world.setBlock(i + 4, j + 7, k + 39, Block.cloth.blockID);
		world.setBlock(i + 4, j + 7, k + 51, Block.planks.blockID);
		world.setBlock(i + 4, j + 8, k + 5, Block.planks.blockID);
		world.setBlock(i + 4, j + 8, k + 6, Block.planks.blockID);
		world.setBlock(i + 4, j + 8, k + 7, Block.planks.blockID);
		world.setBlock(i + 4, j + 8, k + 8, Block.planks.blockID);
		world.setBlock(i + 4, j + 8, k + 9, Block.planks.blockID);
		world.setBlock(i + 4, j + 8, k + 10, Block.planks.blockID);
		world.setBlock(i + 4, j + 8, k + 11, Block.planks.blockID);
		world.setBlock(i + 4, j + 8, k + 12, Block.planks.blockID);
		world.setBlock(i + 4, j + 8, k + 13, Block.planks.blockID);
		world.setBlock(i + 4, j + 8, k + 14, Block.planks.blockID);
		world.setBlock(i + 4, j + 8, k + 15, Block.planks.blockID);
		world.setBlock(i + 4, j + 8, k + 16, Block.planks.blockID);
		world.setBlock(i + 4, j + 8, k + 17, Block.planks.blockID);
		world.setBlock(i + 4, j + 8, k + 18, Block.planks.blockID);
		world.setBlock(i + 4, j + 8, k + 19, Block.planks.blockID);
		world.setBlock(i + 4, j + 8, k + 20, Block.planks.blockID);
		world.setBlock(i + 4, j + 8, k + 21, Block.planks.blockID);
		world.setBlock(i + 4, j + 8, k + 22, Block.planks.blockID);
		world.setBlock(i + 4, j + 8, k + 23, Block.planks.blockID);
		world.setBlock(i + 4, j + 8, k + 24, Block.planks.blockID);
		world.setBlock(i + 4, j + 8, k + 25, Block.planks.blockID);
		world.setBlock(i + 4, j + 8, k + 26, Block.planks.blockID);
		world.setBlock(i + 4, j + 8, k + 27, Block.planks.blockID);
		world.setBlock(i + 4, j + 8, k + 28, Block.planks.blockID);
		world.setBlock(i + 4, j + 8, k + 29, Block.planks.blockID);
		world.setBlock(i + 4, j + 8, k + 30, Block.planks.blockID);
		world.setBlock(i + 4, j + 8, k + 31, Block.planks.blockID);
		world.setBlock(i + 4, j + 8, k + 32, Block.planks.blockID);
		world.setBlock(i + 4, j + 8, k + 33, Block.planks.blockID);
		world.setBlock(i + 4, j + 8, k + 34, Block.planks.blockID);
		world.setBlock(i + 4, j + 8, k + 35, Block.planks.blockID);
		world.setBlock(i + 4, j + 8, k + 36, Block.planks.blockID);
		world.setBlock(i + 4, j + 8, k + 37, Block.planks.blockID);
		world.setBlock(i + 4, j + 8, k + 38, Block.planks.blockID);
		world.setBlock(i + 4, j + 8, k + 39, Block.planks.blockID);
		world.setBlock(i + 4, j + 8, k + 40, Block.planks.blockID);
		world.setBlock(i + 4, j + 8, k + 41, Block.planks.blockID);
		world.setBlock(i + 4, j + 8, k + 42, Block.planks.blockID);
		world.setBlock(i + 4, j + 8, k + 43, Block.planks.blockID);
		world.setBlockAndMetadata(i + 4, j + 8, k + 44, Block.cloth.blockID, 14);
		world.setBlockAndMetadata(i + 4, j + 8, k + 45, Block.cloth.blockID, 14);
		world.setBlockAndMetadata(i + 4, j + 8, k + 46, Block.cloth.blockID, 14);
		world.setBlockAndMetadata(i + 4, j + 8, k + 47, Block.cloth.blockID, 14);
		world.setBlockAndMetadata(i + 4, j + 8, k + 48, Block.cloth.blockID, 14);
		world.setBlockAndMetadata(i + 4, j + 8, k + 49, Block.cloth.blockID, 14);
		world.setBlockAndMetadata(i + 4, j + 8, k + 50, Block.cloth.blockID, 14);
		world.setBlockAndMetadata(i + 4, j + 8, k + 51, Block.cloth.blockID, 14);
		world.setBlock(i + 4, j + 9, k + 4, Block.planks.blockID);
		world.setBlock(i + 4, j + 9, k + 6, Block.planks.blockID);
		world.setBlock(i + 4, j + 9, k + 25, Block.fence.blockID);
		world.setBlock(i + 4, j + 9, k + 26, Block.fence.blockID);
		world.setBlock(i + 4, j + 9, k + 27, Block.fence.blockID);
		world.setBlock(i + 4, j + 9, k + 28, Block.fence.blockID);
		world.setBlock(i + 4, j + 9, k + 29, Block.fence.blockID);
		world.setBlockAndMetadata(i + 4, j + 9, k + 41, Block.chest.blockID, 5);
		world.setBlock(i + 4, j + 9, k + 43, Block.planks.blockID);
		world.setBlock(i + 4, j + 9, k + 52, Block.planks.blockID);
		world.setBlock(i + 4, j + 10, k + 3, Block.planks.blockID);
		world.setBlock(i + 4, j + 10, k + 4, Block.planks.blockID);
		world.setBlock(i + 4, j + 10, k + 6, Block.planks.blockID);
		world.setBlock(i + 4, j + 10, k + 43, Block.planks.blockID);
		world.setBlock(i + 4, j + 10, k + 52, Block.glass.blockID);
		world.setBlock(i + 4, j + 11, k + 3, Block.planks.blockID);
		world.setBlock(i + 4, j + 11, k + 4, Block.planks.blockID);
		world.setBlock(i + 4, j + 11, k + 5, Block.planks.blockID);
		world.setBlock(i + 4, j + 11, k + 6, Block.planks.blockID);
		world.setBlock(i + 4, j + 11, k + 43, Block.planks.blockID);
		world.setBlock(i + 4, j + 11, k + 52, Block.planks.blockID);
		world.setBlock(i + 4, j + 12, k + 3, Block.fence.blockID);
		world.setBlock(i + 4, j + 12, k + 4, Block.fence.blockID);
		world.setBlock(i + 4, j + 12, k + 43, Block.planks.blockID);
		world.setBlock(i + 4, j + 12, k + 44, Block.planks.blockID);
		world.setBlock(i + 4, j + 12, k + 45, Block.planks.blockID);
		world.setBlock(i + 4, j + 12, k + 46, Block.planks.blockID);
		world.setBlock(i + 4, j + 12, k + 47, Block.planks.blockID);
		world.setBlock(i + 4, j + 12, k + 48, Block.planks.blockID);
		world.setBlock(i + 4, j + 12, k + 49, Block.planks.blockID);
		world.setBlock(i + 4, j + 12, k + 50, Block.planks.blockID);
		world.setBlock(i + 4, j + 12, k + 51, Block.planks.blockID);
		world.setBlock(i + 4, j + 12, k + 52, Block.planks.blockID);
		world.setBlock(i + 4, j + 13, k + 52, Block.fence.blockID);
		world.setBlock(i + 5, j + 0, k + 11, Block.planks.blockID);
		world.setBlock(i + 5, j + 0, k + 12, Block.planks.blockID);
		world.setBlock(i + 5, j + 0, k + 13, Block.planks.blockID);
		world.setBlock(i + 5, j + 0, k + 14, Block.planks.blockID);
		world.setBlock(i + 5, j + 0, k + 15, Block.planks.blockID);
		world.setBlock(i + 5, j + 0, k + 16, Block.planks.blockID);
		world.setBlock(i + 5, j + 0, k + 17, Block.planks.blockID);
		world.setBlock(i + 5, j + 0, k + 18, Block.planks.blockID);
		world.setBlock(i + 5, j + 0, k + 19, Block.planks.blockID);
		world.setBlock(i + 5, j + 0, k + 20, Block.planks.blockID);
		world.setBlock(i + 5, j + 0, k + 21, Block.planks.blockID);
		world.setBlock(i + 5, j + 0, k + 22, Block.planks.blockID);
		world.setBlock(i + 5, j + 0, k + 23, Block.planks.blockID);
		world.setBlock(i + 5, j + 0, k + 24, Block.planks.blockID);
		world.setBlock(i + 5, j + 0, k + 25, Block.planks.blockID);
		world.setBlock(i + 5, j + 0, k + 26, Block.planks.blockID);
		world.setBlock(i + 5, j + 0, k + 27, Block.planks.blockID);
		world.setBlock(i + 5, j + 0, k + 28, Block.planks.blockID);
		world.setBlock(i + 5, j + 0, k + 29, Block.planks.blockID);
		world.setBlock(i + 5, j + 0, k + 30, Block.planks.blockID);
		world.setBlock(i + 5, j + 0, k + 31, Block.planks.blockID);
		world.setBlock(i + 5, j + 0, k + 32, Block.planks.blockID);
		world.setBlock(i + 5, j + 0, k + 33, Block.planks.blockID);
		world.setBlock(i + 5, j + 0, k + 34, Block.planks.blockID);
		world.setBlock(i + 5, j + 0, k + 35, Block.planks.blockID);
		world.setBlock(i + 5, j + 0, k + 36, Block.planks.blockID);
		world.setBlock(i + 5, j + 0, k + 37, Block.planks.blockID);
		world.setBlock(i + 5, j + 0, k + 38, Block.planks.blockID);
		world.setBlock(i + 5, j + 0, k + 39, Block.planks.blockID);
		world.setBlock(i + 5, j + 0, k + 40, Block.planks.blockID);
		world.setBlock(i + 5, j + 0, k + 41, Block.planks.blockID);
		world.setBlock(i + 5, j + 0, k + 42, Block.planks.blockID);
		world.setBlock(i + 5, j + 0, k + 43, Block.planks.blockID);
		world.setBlock(i + 5, j + 0, k + 44, Block.planks.blockID);
		world.setBlock(i + 5, j + 0, k + 45, Block.planks.blockID);
		world.setBlock(i + 5, j + 0, k + 46, Block.planks.blockID);
		world.setBlock(i + 5, j + 0, k + 47, Block.planks.blockID);
		world.setBlock(i + 5, j + 1, k + 10, Block.planks.blockID);
		world.setBlock(i + 5, j + 1, k + 11, Block.planks.blockID);
		world.setBlock(i + 5, j + 1, k + 48, Block.planks.blockID);
		world.setBlock(i + 5, j + 1, k + 49, Block.planks.blockID);
		world.setBlock(i + 5, j + 2, k + 9, Block.planks.blockID);
		world.setBlock(i + 5, j + 2, k + 10, Block.planks.blockID);
		world.setBlock(i + 5, j + 2, k + 11, Block.planks.blockID);
		world.setBlock(i + 5, j + 2, k + 12, Block.planks.blockID);
		world.setBlock(i + 5, j + 2, k + 13, Block.planks.blockID);
		world.setBlock(i + 5, j + 2, k + 14, Block.planks.blockID);
		world.setBlock(i + 5, j + 2, k + 15, Block.planks.blockID);
		world.setBlock(i + 5, j + 2, k + 16, Block.planks.blockID);
		world.setBlock(i + 5, j + 2, k + 17, Block.planks.blockID);
		world.setBlock(i + 5, j + 2, k + 18, Block.planks.blockID);
		world.setBlock(i + 5, j + 2, k + 19, Block.planks.blockID);
		world.setBlock(i + 5, j + 2, k + 20, Block.planks.blockID);
		world.setBlock(i + 5, j + 2, k + 21, Block.planks.blockID);
		world.setBlock(i + 5, j + 2, k + 22, Block.planks.blockID);
		world.setBlock(i + 5, j + 2, k + 23, Block.planks.blockID);
		world.setBlock(i + 5, j + 2, k + 24, Block.planks.blockID);
		world.setBlock(i + 5, j + 2, k + 25, Block.planks.blockID);
		world.setBlock(i + 5, j + 2, k + 26, Block.planks.blockID);
		world.setBlock(i + 5, j + 2, k + 27, Block.planks.blockID);
		world.setBlock(i + 5, j + 2, k + 28, Block.planks.blockID);
		world.setBlock(i + 5, j + 2, k + 29, Block.planks.blockID);
		world.setBlock(i + 5, j + 2, k + 30, Block.planks.blockID);
		world.setBlock(i + 5, j + 2, k + 31, Block.planks.blockID);
		world.setBlock(i + 5, j + 2, k + 32, Block.planks.blockID);
		world.setBlock(i + 5, j + 2, k + 33, Block.planks.blockID);
		world.setBlock(i + 5, j + 2, k + 34, Block.planks.blockID);
		world.setBlock(i + 5, j + 2, k + 35, Block.planks.blockID);
		world.setBlock(i + 5, j + 2, k + 36, Block.planks.blockID);
		world.setBlock(i + 5, j + 2, k + 37, Block.planks.blockID);
		world.setBlock(i + 5, j + 2, k + 38, Block.planks.blockID);
		world.setBlock(i + 5, j + 2, k + 39, Block.planks.blockID);
		world.setBlock(i + 5, j + 2, k + 40, Block.planks.blockID);
		world.setBlock(i + 5, j + 2, k + 41, Block.planks.blockID);
		world.setBlock(i + 5, j + 2, k + 42, Block.planks.blockID);
		world.setBlock(i + 5, j + 2, k + 43, Block.planks.blockID);
		world.setBlock(i + 5, j + 2, k + 44, Block.planks.blockID);
		world.setBlock(i + 5, j + 2, k + 45, Block.planks.blockID);
		world.setBlock(i + 5, j + 2, k + 47, Block.planks.blockID);
		world.setBlock(i + 5, j + 2, k + 48, Block.planks.blockID);
		world.setBlock(i + 5, j + 2, k + 49, Block.planks.blockID);
		world.setBlock(i + 5, j + 2, k + 50, Block.planks.blockID);
		world.setBlock(i + 5, j + 3, k + 8, Block.planks.blockID);
		world.setBlockAndMetadata(i + 5, j + 3, k + 9, Block.stoneOvenIdle.blockID, 3);
		world.setBlock(i + 5, j + 3, k + 13, Block.planks.blockID);
		world.setBlock(i + 5, j + 3, k + 19, Block.planks.blockID);
		world.setBlock(i + 5, j + 3, k + 25, Block.planks.blockID);
		world.setBlock(i + 5, j + 3, k + 31, Block.planks.blockID);
		world.setBlock(i + 5, j + 3, k + 37, Block.planks.blockID);
		world.setBlock(i + 5, j + 3, k + 43, Block.planks.blockID);
		world.setBlockAndMetadata(i + 5, j + 3, k + 46, Block.stairCompactPlanks.blockID, 2);
		world.setBlock(i + 5, j + 3, k + 51, Block.planks.blockID);
		world.setBlock(i + 5, j + 4, k + 7, Block.planks.blockID);
		world.setBlockAndMetadata(i + 5, j + 4, k + 8, Block.stoneOvenIdle.blockID, 3);
		world.setBlock(i + 5, j + 4, k + 13, Block.planks.blockID);
		world.setBlock(i + 5, j + 4, k + 19, Block.planks.blockID);
		world.setBlock(i + 5, j + 4, k + 25, Block.planks.blockID);
		world.setBlock(i + 5, j + 4, k + 31, Block.planks.blockID);
		world.setBlock(i + 5, j + 4, k + 37, Block.planks.blockID);
		world.setBlock(i + 5, j + 4, k + 43, Block.planks.blockID);
		world.setBlockAndMetadata(i + 5, j + 4, k + 47, Block.stairCompactPlanks.blockID, 2);
		world.setBlock(i + 5, j + 4, k + 51, Block.planks.blockID);
		world.setBlock(i + 5, j + 5, k + 6, Block.planks.blockID);
		world.setBlock(i + 5, j + 5, k + 7, Block.planks.blockID);
		world.setBlock(i + 5, j + 5, k + 8, Block.planks.blockID);
		world.setBlock(i + 5, j + 5, k + 9, Block.planks.blockID);
		world.setBlock(i + 5, j + 5, k + 10, Block.planks.blockID);
		world.setBlock(i + 5, j + 5, k + 11, Block.planks.blockID);
		world.setBlock(i + 5, j + 5, k + 12, Block.planks.blockID);
		world.setBlock(i + 5, j + 5, k + 13, Block.planks.blockID);
		world.setBlock(i + 5, j + 5, k + 14, Block.planks.blockID);
		world.setBlock(i + 5, j + 5, k + 15, Block.planks.blockID);
		world.setBlock(i + 5, j + 5, k + 16, Block.planks.blockID);
		world.setBlock(i + 5, j + 5, k + 17, Block.planks.blockID);
		world.setBlock(i + 5, j + 5, k + 18, Block.planks.blockID);
		world.setBlock(i + 5, j + 5, k + 19, Block.planks.blockID);
		world.setBlock(i + 5, j + 5, k + 20, Block.planks.blockID);
		world.setBlock(i + 5, j + 5, k + 21, Block.planks.blockID);
		world.setBlock(i + 5, j + 5, k + 22, Block.planks.blockID);
		world.setBlock(i + 5, j + 5, k + 23, Block.planks.blockID);
		world.setBlock(i + 5, j + 5, k + 24, Block.planks.blockID);
		world.setBlock(i + 5, j + 5, k + 25, Block.planks.blockID);
		world.setBlock(i + 5, j + 5, k + 26, Block.planks.blockID);
		world.setBlock(i + 5, j + 5, k + 27, Block.planks.blockID);
		world.setBlock(i + 5, j + 5, k + 28, Block.planks.blockID);
		world.setBlock(i + 5, j + 5, k + 29, Block.planks.blockID);
		world.setBlock(i + 5, j + 5, k + 30, Block.planks.blockID);
		world.setBlock(i + 5, j + 5, k + 31, Block.planks.blockID);
		world.setBlock(i + 5, j + 5, k + 32, Block.planks.blockID);
		world.setBlock(i + 5, j + 5, k + 33, Block.planks.blockID);
		world.setBlock(i + 5, j + 5, k + 34, Block.planks.blockID);
		world.setBlock(i + 5, j + 5, k + 35, Block.planks.blockID);
		world.setBlock(i + 5, j + 5, k + 36, Block.planks.blockID);
		world.setBlock(i + 5, j + 5, k + 37, Block.planks.blockID);
		world.setBlock(i + 5, j + 5, k + 38, Block.planks.blockID);
		world.setBlock(i + 5, j + 5, k + 39, Block.planks.blockID);
		world.setBlock(i + 5, j + 5, k + 40, Block.planks.blockID);
		world.setBlock(i + 5, j + 5, k + 41, Block.planks.blockID);
		world.setBlock(i + 5, j + 5, k + 42, Block.planks.blockID);
		world.setBlock(i + 5, j + 5, k + 43, Block.planks.blockID);
		world.setBlock(i + 5, j + 5, k + 44, Block.planks.blockID);
		world.setBlockAndMetadata(i + 5, j + 5, k + 48, Block.stairCompactPlanks.blockID, 2);
		world.setBlock(i + 5, j + 5, k + 49, Block.planks.blockID);
		world.setBlock(i + 5, j + 5, k + 50, Block.planks.blockID);
		world.setBlock(i + 5, j + 5, k + 51, Block.planks.blockID);
		world.setBlock(i + 5, j + 6, k + 5, Block.planks.blockID);
		world.setBlock(i + 5, j + 6, k + 6, Block.planks.blockID);
		world.setBlockAndMetadata(i + 5, j + 6, k + 7, Block.stoneOvenIdle.blockID, 3);
		world.setBlock(i + 5, j + 6, k + 12, Block.planks.blockID);
		world.setBlockAndMetadata(i + 5, j + 6, k + 16, Block.chest.blockID, 2);
		world.setBlockAndMetadata(i + 5, j + 6, k + 18, Block.chest.blockID, 2);
		world.setBlockAndMetadata(i + 5, j + 6, k + 20, Block.chest.blockID, 2);
		world.setBlockAndMetadata(i + 5, j + 6, k + 22, Block.chest.blockID, 2);
		world.setBlockAndMetadata(i + 5, j + 6, k + 24, Block.chest.blockID, 2);
		world.setBlockAndMetadata(i + 5, j + 6, k + 27, Block.stairCompactPlanks.blockID, 3);
		world.setBlockAndMetadata(i + 5, j + 6, k + 30, Block.chest.blockID, 2);
		world.setBlock(i + 5, j + 6, k + 33, Block.cloth.blockID);
		world.setBlock(i + 5, j + 6, k + 34, Block.cloth.blockID);
		world.setBlock(i + 5, j + 6, k + 35, Block.cloth.blockID);
		world.setBlock(i + 5, j + 6, k + 36, Block.cloth.blockID);
		world.setBlock(i + 5, j + 6, k + 37, Block.cloth.blockID);
		world.setBlock(i + 5, j + 6, k + 38, Block.cloth.blockID);
		world.setBlock(i + 5, j + 6, k + 39, Block.cloth.blockID);
		world.setBlock(i + 5, j + 6, k + 40, Block.cloth.blockID);
		world.setBlock(i + 5, j + 6, k + 44, Block.fence.blockID);
		world.setBlock(i + 5, j + 6, k + 51, Block.planks.blockID);
		world.setBlock(i + 5, j + 7, k + 5, Block.planks.blockID);
		world.setBlockAndMetadata(i + 5, j + 7, k + 6, Block.stoneOvenIdle.blockID, 3);
		world.setBlock(i + 5, j + 7, k + 12, Block.planks.blockID);
		world.setBlockAndMetadata(i + 5, j + 7, k + 26, Block.stairCompactPlanks.blockID, 3);
		world.setBlock(i + 5, j + 7, k + 34, Block.cloth.blockID);
		world.setBlock(i + 5, j + 7, k + 35, Block.cloth.blockID);
		world.setBlock(i + 5, j + 7, k + 36, Block.cloth.blockID);
		world.setBlock(i + 5, j + 7, k + 37, Block.cloth.blockID);
		world.setBlock(i + 5, j + 7, k + 38, Block.cloth.blockID);
		world.setBlock(i + 5, j + 7, k + 39, Block.cloth.blockID);
		world.setBlock(i + 5, j + 7, k + 51, Block.planks.blockID);
		world.setBlock(i + 5, j + 8, k + 4, Block.planks.blockID);
		world.setBlock(i + 5, j + 8, k + 5, Block.planks.blockID);
		world.setBlock(i + 5, j + 8, k + 6, Block.planks.blockID);
		world.setBlock(i + 5, j + 8, k + 7, Block.planks.blockID);
		world.setBlock(i + 5, j + 8, k + 8, Block.planks.blockID);
		world.setBlock(i + 5, j + 8, k + 9, Block.planks.blockID);
		world.setBlock(i + 5, j + 8, k + 10, Block.planks.blockID);
		world.setBlock(i + 5, j + 8, k + 11, Block.planks.blockID);
		world.setBlock(i + 5, j + 8, k + 12, Block.planks.blockID);
		world.setBlock(i + 5, j + 8, k + 13, Block.planks.blockID);
		world.setBlock(i + 5, j + 8, k + 14, Block.planks.blockID);
		world.setBlock(i + 5, j + 8, k + 15, Block.planks.blockID);
		world.setBlock(i + 5, j + 8, k + 16, Block.planks.blockID);
		world.setBlock(i + 5, j + 8, k + 17, Block.planks.blockID);
		world.setBlock(i + 5, j + 8, k + 18, Block.planks.blockID);
		world.setBlock(i + 5, j + 8, k + 19, Block.planks.blockID);
		world.setBlock(i + 5, j + 8, k + 20, Block.planks.blockID);
		world.setBlock(i + 5, j + 8, k + 21, Block.planks.blockID);
		world.setBlock(i + 5, j + 8, k + 22, Block.planks.blockID);
		world.setBlock(i + 5, j + 8, k + 23, Block.planks.blockID);
		world.setBlock(i + 5, j + 8, k + 24, Block.planks.blockID);
		world.setBlockAndMetadata(i + 5, j + 8, k + 25, Block.stairCompactPlanks.blockID, 3);
		world.setBlock(i + 5, j + 8, k + 29, Block.planks.blockID);
		world.setBlock(i + 5, j + 8, k + 30, Block.planks.blockID);
		world.setBlock(i + 5, j + 8, k + 31, Block.planks.blockID);
		world.setBlock(i + 5, j + 8, k + 32, Block.planks.blockID);
		world.setBlock(i + 5, j + 8, k + 33, Block.planks.blockID);
		world.setBlock(i + 5, j + 8, k + 34, Block.planks.blockID);
		world.setBlock(i + 5, j + 8, k + 35, Block.planks.blockID);
		world.setBlock(i + 5, j + 8, k + 36, Block.planks.blockID);
		world.setBlock(i + 5, j + 8, k + 37, Block.planks.blockID);
		world.setBlock(i + 5, j + 8, k + 38, Block.planks.blockID);
		world.setBlock(i + 5, j + 8, k + 39, Block.planks.blockID);
		world.setBlock(i + 5, j + 8, k + 40, Block.planks.blockID);
		world.setBlock(i + 5, j + 8, k + 41, Block.planks.blockID);
		world.setBlock(i + 5, j + 8, k + 42, Block.planks.blockID);
		world.setBlock(i + 5, j + 8, k + 43, Block.planks.blockID);
		world.setBlockAndMetadata(i + 5, j + 8, k + 44, Block.cloth.blockID, 14);
		world.setBlockAndMetadata(i + 5, j + 8, k + 45, Block.cloth.blockID, 14);
		world.setBlockAndMetadata(i + 5, j + 8, k + 46, Block.cloth.blockID, 14);
		world.setBlockAndMetadata(i + 5, j + 8, k + 47, Block.cloth.blockID, 14);
		world.setBlockAndMetadata(i + 5, j + 8, k + 48, Block.cloth.blockID, 14);
		world.setBlockAndMetadata(i + 5, j + 8, k + 49, Block.cloth.blockID, 14);
		world.setBlockAndMetadata(i + 5, j + 8, k + 50, Block.cloth.blockID, 14);
		world.setBlockAndMetadata(i + 5, j + 8, k + 51, Block.cloth.blockID, 14);
		world.setBlock(i + 5, j + 9, k + 3, Block.planks.blockID);
		world.setBlock(i + 5, j + 9, k + 4, Block.planks.blockID);
		world.setBlock(i + 5, j + 9, k + 6, Block.planks.blockID);
		world.setBlock(i + 5, j + 9, k + 7, Block.planks.blockID);
		world.setBlock(i + 5, j + 9, k + 8, Block.planks.blockID);
		world.setBlockAndMetadata(i + 5, j + 9, k + 9, Block.stairCompactPlanks.blockID, 3);
		world.setBlock(i + 5, j + 9, k + 20, Block.wood.blockID);
		world.setBlock(i + 5, j + 9, k + 21, Block.wood.blockID);
		world.setBlock(i + 5, j + 9, k + 29, Block.fence.blockID);
		world.setBlock(i + 5, j + 9, k + 34, Block.wood.blockID);
		world.setBlock(i + 5, j + 9, k + 35, Block.wood.blockID);
		world.setBlock(i + 5, j + 9, k + 52, Block.planks.blockID);
		world.setBlock(i + 5, j + 10, k + 2, Block.planks.blockID);
		world.setBlock(i + 5, j + 10, k + 3, Block.planks.blockID);
		world.setBlock(i + 5, j + 10, k + 6, Block.planks.blockID);
		world.setBlock(i + 5, j + 10, k + 7, Block.planks.blockID);
		world.setBlockAndMetadata(i + 5, j + 10, k + 8, Block.stairCompactPlanks.blockID, 3);
		world.setBlock(i + 5, j + 10, k + 20, Block.wood.blockID);
		world.setBlock(i + 5, j + 10, k + 21, Block.wood.blockID);
		world.setBlock(i + 5, j + 10, k + 34, Block.wood.blockID);
		world.setBlock(i + 5, j + 10, k + 35, Block.wood.blockID);
		world.setBlock(i + 5, j + 10, k + 52, Block.glass.blockID);
		world.setBlock(i + 5, j + 11, k + 2, Block.planks.blockID);
		world.setBlock(i + 5, j + 11, k + 3, Block.planks.blockID);
		world.setBlock(i + 5, j + 11, k + 4, Block.planks.blockID);
		world.setBlock(i + 5, j + 11, k + 5, Block.planks.blockID);
		world.setBlock(i + 5, j + 11, k + 6, Block.planks.blockID);
		world.setBlockAndMetadata(i + 5, j + 11, k + 7, Block.stairCompactPlanks.blockID, 3);
		world.setBlock(i + 5, j + 11, k + 20, Block.wood.blockID);
		world.setBlock(i + 5, j + 11, k + 21, Block.wood.blockID);
		world.setBlock(i + 5, j + 11, k + 34, Block.wood.blockID);
		world.setBlock(i + 5, j + 11, k + 35, Block.wood.blockID);
		world.setBlock(i + 5, j + 11, k + 43, Block.planks.blockID);
		world.setBlock(i + 5, j + 11, k + 47, Block.pistonExtension.blockID);
		world.setBlock(i + 5, j + 11, k + 52, Block.planks.blockID);
		world.setBlock(i + 5, j + 12, k + 1, Block.planks.blockID);
		world.setBlock(i + 5, j + 12, k + 2, Block.planks.blockID);
		world.setBlock(i + 5, j + 12, k + 20, Block.wood.blockID);
		world.setBlock(i + 5, j + 12, k + 21, Block.wood.blockID);
		world.setBlock(i + 5, j + 12, k + 34, Block.wood.blockID);
		world.setBlock(i + 5, j + 12, k + 35, Block.wood.blockID);
		world.setBlock(i + 5, j + 12, k + 43, Block.planks.blockID);
		world.setBlock(i + 5, j + 12, k + 44, Block.planks.blockID);
		world.setBlock(i + 5, j + 12, k + 45, Block.planks.blockID);
		world.setBlock(i + 5, j + 12, k + 46, Block.planks.blockID);
		world.setBlock(i + 5, j + 12, k + 47, Block.planks.blockID);
		world.setBlock(i + 5, j + 12, k + 48, Block.planks.blockID);
		world.setBlock(i + 5, j + 12, k + 49, Block.planks.blockID);
		world.setBlock(i + 5, j + 12, k + 50, Block.planks.blockID);
		world.setBlock(i + 5, j + 12, k + 51, Block.planks.blockID);
		world.setBlock(i + 5, j + 12, k + 52, Block.planks.blockID);
		world.setBlock(i + 5, j + 13, k + 0, Block.planks.blockID);
		world.setBlock(i + 5, j + 13, k + 1, Block.planks.blockID);
		world.setBlock(i + 5, j + 13, k + 20, Block.wood.blockID);
		world.setBlock(i + 5, j + 13, k + 21, Block.wood.blockID);
		world.setBlock(i + 5, j + 13, k + 34, Block.wood.blockID);
		world.setBlock(i + 5, j + 13, k + 35, Block.wood.blockID);
		world.setBlock(i + 5, j + 13, k + 48, Block.wood.blockID);
		world.setBlock(i + 5, j + 13, k + 52, Block.fence.blockID);
		world.setBlock(i + 6, j + 0, k + 11, Block.planks.blockID);
		world.setBlock(i + 6, j + 0, k + 12, Block.planks.blockID);
		world.setBlock(i + 6, j + 0, k + 13, Block.planks.blockID);
		world.setBlock(i + 6, j + 0, k + 14, Block.planks.blockID);
		world.setBlock(i + 6, j + 0, k + 15, Block.planks.blockID);
		world.setBlock(i + 6, j + 0, k + 16, Block.planks.blockID);
		world.setBlock(i + 6, j + 0, k + 17, Block.planks.blockID);
		world.setBlock(i + 6, j + 0, k + 18, Block.planks.blockID);
		world.setBlock(i + 6, j + 0, k + 19, Block.planks.blockID);
		world.setBlock(i + 6, j + 0, k + 20, Block.planks.blockID);
		world.setBlock(i + 6, j + 0, k + 21, Block.planks.blockID);
		world.setBlock(i + 6, j + 0, k + 22, Block.planks.blockID);
		world.setBlock(i + 6, j + 0, k + 23, Block.planks.blockID);
		world.setBlock(i + 6, j + 0, k + 24, Block.planks.blockID);
		world.setBlock(i + 6, j + 0, k + 25, Block.planks.blockID);
		world.setBlock(i + 6, j + 0, k + 26, Block.planks.blockID);
		world.setBlock(i + 6, j + 0, k + 27, Block.planks.blockID);
		world.setBlock(i + 6, j + 0, k + 28, Block.planks.blockID);
		world.setBlock(i + 6, j + 0, k + 29, Block.planks.blockID);
		world.setBlock(i + 6, j + 0, k + 30, Block.planks.blockID);
		world.setBlock(i + 6, j + 0, k + 31, Block.planks.blockID);
		world.setBlock(i + 6, j + 0, k + 32, Block.planks.blockID);
		world.setBlock(i + 6, j + 0, k + 33, Block.planks.blockID);
		world.setBlock(i + 6, j + 0, k + 34, Block.planks.blockID);
		world.setBlock(i + 6, j + 0, k + 35, Block.planks.blockID);
		world.setBlock(i + 6, j + 0, k + 36, Block.planks.blockID);
		world.setBlock(i + 6, j + 0, k + 37, Block.planks.blockID);
		world.setBlock(i + 6, j + 0, k + 38, Block.planks.blockID);
		world.setBlock(i + 6, j + 0, k + 39, Block.planks.blockID);
		world.setBlock(i + 6, j + 0, k + 40, Block.planks.blockID);
		world.setBlock(i + 6, j + 0, k + 41, Block.planks.blockID);
		world.setBlock(i + 6, j + 0, k + 42, Block.planks.blockID);
		world.setBlock(i + 6, j + 0, k + 43, Block.planks.blockID);
		world.setBlock(i + 6, j + 0, k + 44, Block.planks.blockID);
		world.setBlock(i + 6, j + 0, k + 45, Block.planks.blockID);
		world.setBlock(i + 6, j + 0, k + 46, Block.planks.blockID);
		world.setBlock(i + 6, j + 0, k + 47, Block.planks.blockID);
		world.setBlock(i + 6, j + 0, k + 48, Block.planks.blockID);
		world.setBlock(i + 6, j + 1, k + 10, Block.planks.blockID);
		world.setBlock(i + 6, j + 1, k + 11, Block.planks.blockID);
		world.setBlock(i + 6, j + 1, k + 48, Block.planks.blockID);
		world.setBlock(i + 6, j + 1, k + 49, Block.planks.blockID);
		world.setBlock(i + 6, j + 2, k + 9, Block.planks.blockID);
		world.setBlock(i + 6, j + 2, k + 10, Block.planks.blockID);
		world.setBlock(i + 6, j + 2, k + 11, Block.planks.blockID);
		world.setBlock(i + 6, j + 2, k + 12, Block.planks.blockID);
		world.setBlock(i + 6, j + 2, k + 13, Block.planks.blockID);
		world.setBlock(i + 6, j + 2, k + 14, Block.planks.blockID);
		world.setBlock(i + 6, j + 2, k + 15, Block.planks.blockID);
		world.setBlock(i + 6, j + 2, k + 16, Block.planks.blockID);
		world.setBlock(i + 6, j + 2, k + 17, Block.planks.blockID);
		world.setBlock(i + 6, j + 2, k + 18, Block.planks.blockID);
		world.setBlock(i + 6, j + 2, k + 19, Block.planks.blockID);
		world.setBlock(i + 6, j + 2, k + 20, Block.planks.blockID);
		world.setBlock(i + 6, j + 2, k + 21, Block.planks.blockID);
		world.setBlock(i + 6, j + 2, k + 22, Block.planks.blockID);
		world.setBlock(i + 6, j + 2, k + 23, Block.planks.blockID);
		world.setBlock(i + 6, j + 2, k + 24, Block.planks.blockID);
		world.setBlock(i + 6, j + 2, k + 25, Block.planks.blockID);
		world.setBlock(i + 6, j + 2, k + 26, Block.planks.blockID);
		world.setBlock(i + 6, j + 2, k + 27, Block.planks.blockID);
		world.setBlock(i + 6, j + 2, k + 28, Block.planks.blockID);
		world.setBlock(i + 6, j + 2, k + 29, Block.planks.blockID);
		world.setBlock(i + 6, j + 2, k + 30, Block.planks.blockID);
		world.setBlock(i + 6, j + 2, k + 31, Block.planks.blockID);
		world.setBlock(i + 6, j + 2, k + 32, Block.planks.blockID);
		world.setBlock(i + 6, j + 2, k + 33, Block.planks.blockID);
		world.setBlock(i + 6, j + 2, k + 34, Block.planks.blockID);
		world.setBlock(i + 6, j + 2, k + 35, Block.planks.blockID);
		world.setBlock(i + 6, j + 2, k + 36, Block.planks.blockID);
		world.setBlock(i + 6, j + 2, k + 37, Block.planks.blockID);
		world.setBlock(i + 6, j + 2, k + 38, Block.planks.blockID);
		world.setBlock(i + 6, j + 2, k + 39, Block.planks.blockID);
		world.setBlock(i + 6, j + 2, k + 40, Block.planks.blockID);
		world.setBlock(i + 6, j + 2, k + 41, Block.planks.blockID);
		world.setBlock(i + 6, j + 2, k + 42, Block.planks.blockID);
		world.setBlock(i + 6, j + 2, k + 43, Block.planks.blockID);
		world.setBlock(i + 6, j + 2, k + 44, Block.planks.blockID);
		world.setBlock(i + 6, j + 2, k + 45, Block.planks.blockID);
		world.setBlock(i + 6, j + 2, k + 47, Block.planks.blockID);
		world.setBlock(i + 6, j + 2, k + 48, Block.planks.blockID);
		world.setBlock(i + 6, j + 2, k + 49, Block.planks.blockID);
		world.setBlock(i + 6, j + 2, k + 50, Block.planks.blockID);
		world.setBlock(i + 6, j + 3, k + 8, Block.planks.blockID);
		world.setBlockAndMetadata(i + 6, j + 3, k + 9, Block.stoneOvenIdle.blockID, 3);
		world.setBlock(i + 6, j + 3, k + 13, Block.planks.blockID);
		world.setBlock(i + 6, j + 3, k + 14, Block.planks.blockID);
		world.setBlock(i + 6, j + 3, k + 15, Block.planks.blockID);
		world.setBlock(i + 6, j + 3, k + 16, Block.planks.blockID);
		world.setBlock(i + 6, j + 3, k + 18, Block.planks.blockID);
		world.setBlock(i + 6, j + 3, k + 19, Block.planks.blockID);
		world.setBlock(i + 6, j + 3, k + 20, Block.planks.blockID);
		world.setBlock(i + 6, j + 3, k + 21, Block.planks.blockID);
		world.setBlock(i + 6, j + 3, k + 22, Block.planks.blockID);
		world.setBlock(i + 6, j + 3, k + 24, Block.planks.blockID);
		world.setBlock(i + 6, j + 3, k + 25, Block.planks.blockID);
		world.setBlock(i + 6, j + 3, k + 26, Block.planks.blockID);
		world.setBlock(i + 6, j + 3, k + 27, Block.planks.blockID);
		world.setBlock(i + 6, j + 3, k + 28, Block.planks.blockID);
		world.setBlock(i + 6, j + 3, k + 30, Block.planks.blockID);
		world.setBlock(i + 6, j + 3, k + 31, Block.planks.blockID);
		world.setBlock(i + 6, j + 3, k + 32, Block.planks.blockID);
		world.setBlock(i + 6, j + 3, k + 33, Block.planks.blockID);
		world.setBlock(i + 6, j + 3, k + 34, Block.planks.blockID);
		world.setBlock(i + 6, j + 3, k + 36, Block.planks.blockID);
		world.setBlock(i + 6, j + 3, k + 37, Block.planks.blockID);
		world.setBlock(i + 6, j + 3, k + 38, Block.planks.blockID);
		world.setBlock(i + 6, j + 3, k + 39, Block.planks.blockID);
		world.setBlock(i + 6, j + 3, k + 40, Block.planks.blockID);
		world.setBlock(i + 6, j + 3, k + 42, Block.planks.blockID);
		world.setBlock(i + 6, j + 3, k + 43, Block.planks.blockID);
		world.setBlockAndMetadata(i + 6, j + 3, k + 46, Block.stairCompactPlanks.blockID, 2);
		world.setBlock(i + 6, j + 3, k + 51, Block.planks.blockID);
		world.setBlock(i + 6, j + 4, k + 7, Block.planks.blockID);
		world.setBlockAndMetadata(i + 6, j + 4, k + 8, Block.stoneOvenIdle.blockID, 3);
		world.setBlock(i + 6, j + 4, k + 13, Block.planks.blockID);
		world.setBlock(i + 6, j + 4, k + 14, Block.planks.blockID);
		world.setBlock(i + 6, j + 4, k + 15, Block.planks.blockID);
		world.setBlock(i + 6, j + 4, k + 16, Block.planks.blockID);
		world.setBlock(i + 6, j + 4, k + 18, Block.planks.blockID);
		world.setBlock(i + 6, j + 4, k + 19, Block.planks.blockID);
		world.setBlock(i + 6, j + 4, k + 20, Block.planks.blockID);
		world.setBlock(i + 6, j + 4, k + 21, Block.planks.blockID);
		world.setBlock(i + 6, j + 4, k + 22, Block.planks.blockID);
		world.setBlock(i + 6, j + 4, k + 24, Block.planks.blockID);
		world.setBlock(i + 6, j + 4, k + 25, Block.planks.blockID);
		world.setBlock(i + 6, j + 4, k + 26, Block.planks.blockID);
		world.setBlock(i + 6, j + 4, k + 27, Block.planks.blockID);
		world.setBlock(i + 6, j + 4, k + 28, Block.planks.blockID);
		world.setBlock(i + 6, j + 4, k + 30, Block.planks.blockID);
		world.setBlock(i + 6, j + 4, k + 31, Block.planks.blockID);
		world.setBlock(i + 6, j + 4, k + 32, Block.planks.blockID);
		world.setBlock(i + 6, j + 4, k + 33, Block.planks.blockID);
		world.setBlock(i + 6, j + 4, k + 34, Block.planks.blockID);
		world.setBlock(i + 6, j + 4, k + 36, Block.planks.blockID);
		world.setBlock(i + 6, j + 4, k + 37, Block.planks.blockID);
		world.setBlock(i + 6, j + 4, k + 38, Block.planks.blockID);
		world.setBlock(i + 6, j + 4, k + 39, Block.planks.blockID);
		world.setBlock(i + 6, j + 4, k + 40, Block.planks.blockID);
		world.setBlock(i + 6, j + 4, k + 42, Block.planks.blockID);
		world.setBlock(i + 6, j + 4, k + 43, Block.planks.blockID);
		world.setBlockAndMetadata(i + 6, j + 4, k + 47, Block.stairCompactPlanks.blockID, 2);
		world.setBlock(i + 6, j + 4, k + 51, Block.planks.blockID);
		world.setBlock(i + 6, j + 5, k + 6, Block.planks.blockID);
		world.setBlock(i + 6, j + 5, k + 7, Block.planks.blockID);
		world.setBlock(i + 6, j + 5, k + 8, Block.planks.blockID);
		world.setBlock(i + 6, j + 5, k + 9, Block.planks.blockID);
		world.setBlock(i + 6, j + 5, k + 10, Block.planks.blockID);
		world.setBlock(i + 6, j + 5, k + 11, Block.planks.blockID);
		world.setBlock(i + 6, j + 5, k + 12, Block.planks.blockID);
		world.setBlock(i + 6, j + 5, k + 13, Block.planks.blockID);
		world.setBlock(i + 6, j + 5, k + 14, Block.planks.blockID);
		world.setBlock(i + 6, j + 5, k + 15, Block.planks.blockID);
		world.setBlock(i + 6, j + 5, k + 16, Block.planks.blockID);
		world.setBlock(i + 6, j + 5, k + 17, Block.planks.blockID);
		world.setBlock(i + 6, j + 5, k + 18, Block.planks.blockID);
		world.setBlock(i + 6, j + 5, k + 19, Block.planks.blockID);
		world.setBlock(i + 6, j + 5, k + 20, Block.planks.blockID);
		world.setBlock(i + 6, j + 5, k + 21, Block.planks.blockID);
		world.setBlock(i + 6, j + 5, k + 22, Block.planks.blockID);
		world.setBlock(i + 6, j + 5, k + 23, Block.planks.blockID);
		world.setBlock(i + 6, j + 5, k + 24, Block.planks.blockID);
		world.setBlock(i + 6, j + 5, k + 25, Block.planks.blockID);
		world.setBlock(i + 6, j + 5, k + 26, Block.planks.blockID);
		world.setBlock(i + 6, j + 5, k + 27, Block.planks.blockID);
		world.setBlock(i + 6, j + 5, k + 28, Block.planks.blockID);
		world.setBlock(i + 6, j + 5, k + 29, Block.planks.blockID);
		world.setBlock(i + 6, j + 5, k + 30, Block.planks.blockID);
		world.setBlock(i + 6, j + 5, k + 31, Block.planks.blockID);
		world.setBlock(i + 6, j + 5, k + 32, Block.planks.blockID);
		world.setBlock(i + 6, j + 5, k + 33, Block.planks.blockID);
		world.setBlock(i + 6, j + 5, k + 34, Block.planks.blockID);
		world.setBlock(i + 6, j + 5, k + 35, Block.planks.blockID);
		world.setBlock(i + 6, j + 5, k + 36, Block.planks.blockID);
		world.setBlock(i + 6, j + 5, k + 37, Block.planks.blockID);
		world.setBlock(i + 6, j + 5, k + 38, Block.planks.blockID);
		world.setBlock(i + 6, j + 5, k + 39, Block.planks.blockID);
		world.setBlock(i + 6, j + 5, k + 40, Block.planks.blockID);
		world.setBlock(i + 6, j + 5, k + 41, Block.planks.blockID);
		world.setBlock(i + 6, j + 5, k + 42, Block.planks.blockID);
		world.setBlock(i + 6, j + 5, k + 43, Block.planks.blockID);
		world.setBlock(i + 6, j + 5, k + 44, Block.planks.blockID);
		world.setBlockAndMetadata(i + 6, j + 5, k + 48, Block.stairCompactPlanks.blockID, 2);
		world.setBlock(i + 6, j + 5, k + 49, Block.planks.blockID);
		world.setBlock(i + 6, j + 5, k + 50, Block.planks.blockID);
		world.setBlock(i + 6, j + 5, k + 51, Block.planks.blockID);
		world.setBlock(i + 6, j + 6, k + 5, Block.planks.blockID);
		world.setBlock(i + 6, j + 6, k + 6, Block.planks.blockID);
		world.setBlockAndMetadata(i + 6, j + 6, k + 7, Block.stoneOvenIdle.blockID, 3);
		world.setBlock(i + 6, j + 6, k + 12, Block.planks.blockID);
		world.setBlockAndMetadata(i + 6, j + 6, k + 16, Block.chest.blockID, 2);
		world.setBlockAndMetadata(i + 6, j + 6, k + 18, Block.chest.blockID, 2);
		world.setBlockAndMetadata(i + 6, j + 6, k + 20, Block.chest.blockID, 2);
		world.setBlockAndMetadata(i + 6, j + 6, k + 22, Block.chest.blockID, 2);
		world.setBlockAndMetadata(i + 6, j + 6, k + 24, Block.chest.blockID, 2);
		world.setBlockAndMetadata(i + 6, j + 6, k + 27, Block.stairCompactPlanks.blockID, 3);
		world.setBlockAndMetadata(i + 6, j + 6, k + 30, Block.chest.blockID, 2);
		world.setBlock(i + 6, j + 6, k + 33, Block.cloth.blockID);
		world.setBlock(i + 6, j + 6, k + 34, Block.cloth.blockID);
		world.setBlock(i + 6, j + 6, k + 35, Block.cloth.blockID);
		world.setBlock(i + 6, j + 6, k + 36, Block.cloth.blockID);
		world.setBlock(i + 6, j + 6, k + 37, Block.cloth.blockID);
		world.setBlock(i + 6, j + 6, k + 38, Block.cloth.blockID);
		world.setBlock(i + 6, j + 6, k + 39, Block.cloth.blockID);
		world.setBlock(i + 6, j + 6, k + 40, Block.cloth.blockID);
		world.setBlock(i + 6, j + 6, k + 44, Block.fence.blockID);
		world.setBlock(i + 6, j + 6, k + 51, Block.planks.blockID);
		world.setBlock(i + 6, j + 7, k + 5, Block.planks.blockID);
		world.setBlockAndMetadata(i + 6, j + 7, k + 6, Block.stoneOvenIdle.blockID, 3);
		world.setBlock(i + 6, j + 7, k + 12, Block.planks.blockID);
		world.setBlockAndMetadata(i + 6, j + 7, k + 26, Block.stairCompactPlanks.blockID, 3);
		world.setBlock(i + 6, j + 7, k + 34, Block.cloth.blockID);

		generate2(world, rand, i, j, k);
		return true;
	}

	public boolean generate2(World world, Random rand, int i, int j, int k) {
		world.setBlock(i + 6, j + 7, k + 35, Block.cloth.blockID);
		world.setBlock(i + 6, j + 7, k + 36, Block.cloth.blockID);
		world.setBlock(i + 6, j + 7, k + 37, Block.cloth.blockID);
		world.setBlock(i + 6, j + 7, k + 38, Block.cloth.blockID);
		world.setBlock(i + 6, j + 7, k + 39, Block.cloth.blockID);
		world.setBlock(i + 6, j + 7, k + 51, Block.planks.blockID);
		world.setBlock(i + 6, j + 8, k + 4, Block.planks.blockID);
		world.setBlock(i + 6, j + 8, k + 5, Block.planks.blockID);
		world.setBlock(i + 6, j + 8, k + 6, Block.planks.blockID);
		world.setBlock(i + 6, j + 8, k + 7, Block.planks.blockID);
		world.setBlock(i + 6, j + 8, k + 8, Block.planks.blockID);
		world.setBlock(i + 6, j + 8, k + 9, Block.planks.blockID);
		world.setBlock(i + 6, j + 8, k + 10, Block.planks.blockID);
		world.setBlock(i + 6, j + 8, k + 11, Block.planks.blockID);
		world.setBlock(i + 6, j + 8, k + 12, Block.planks.blockID);
		world.setBlock(i + 6, j + 8, k + 13, Block.planks.blockID);
		world.setBlock(i + 6, j + 8, k + 14, Block.planks.blockID);
		world.setBlock(i + 6, j + 8, k + 15, Block.planks.blockID);
		world.setBlock(i + 6, j + 8, k + 16, Block.planks.blockID);
		world.setBlock(i + 6, j + 8, k + 17, Block.planks.blockID);
		world.setBlock(i + 6, j + 8, k + 18, Block.planks.blockID);
		world.setBlock(i + 6, j + 8, k + 19, Block.planks.blockID);
		world.setBlock(i + 6, j + 8, k + 20, Block.planks.blockID);
		world.setBlock(i + 6, j + 8, k + 21, Block.planks.blockID);
		world.setBlock(i + 6, j + 8, k + 22, Block.planks.blockID);
		world.setBlock(i + 6, j + 8, k + 23, Block.planks.blockID);
		world.setBlock(i + 6, j + 8, k + 24, Block.planks.blockID);
		world.setBlockAndMetadata(i + 6, j + 8, k + 25, Block.stairCompactPlanks.blockID, 3);
		world.setBlock(i + 6, j + 8, k + 29, Block.planks.blockID);
		world.setBlock(i + 6, j + 8, k + 30, Block.planks.blockID);
		world.setBlock(i + 6, j + 8, k + 31, Block.planks.blockID);
		world.setBlock(i + 6, j + 8, k + 32, Block.planks.blockID);
		world.setBlock(i + 6, j + 8, k + 33, Block.planks.blockID);
		world.setBlock(i + 6, j + 8, k + 34, Block.planks.blockID);
		world.setBlock(i + 6, j + 8, k + 35, Block.planks.blockID);
		world.setBlock(i + 6, j + 8, k + 36, Block.planks.blockID);
		world.setBlock(i + 6, j + 8, k + 37, Block.planks.blockID);
		world.setBlock(i + 6, j + 8, k + 38, Block.planks.blockID);
		world.setBlock(i + 6, j + 8, k + 39, Block.planks.blockID);
		world.setBlock(i + 6, j + 8, k + 40, Block.planks.blockID);
		world.setBlock(i + 6, j + 8, k + 41, Block.planks.blockID);
		world.setBlock(i + 6, j + 8, k + 42, Block.planks.blockID);
		world.setBlock(i + 6, j + 8, k + 43, Block.planks.blockID);
		world.setBlockAndMetadata(i + 6, j + 8, k + 44, Block.cloth.blockID, 14);
		world.setBlockAndMetadata(i + 6, j + 8, k + 45, Block.cloth.blockID, 14);
		world.setBlockAndMetadata(i + 6, j + 8, k + 46, Block.cloth.blockID, 14);
		world.setBlockAndMetadata(i + 6, j + 8, k + 47, Block.cloth.blockID, 14);
		world.setBlockAndMetadata(i + 6, j + 8, k + 48, Block.cloth.blockID, 14);
		world.setBlockAndMetadata(i + 6, j + 8, k + 49, Block.cloth.blockID, 14);
		world.setBlockAndMetadata(i + 6, j + 8, k + 50, Block.cloth.blockID, 14);
		world.setBlockAndMetadata(i + 6, j + 8, k + 51, Block.cloth.blockID, 14);
		world.setBlock(i + 6, j + 9, k + 3, Block.planks.blockID);
		world.setBlock(i + 6, j + 9, k + 4, Block.planks.blockID);
		world.setBlock(i + 6, j + 9, k + 6, Block.planks.blockID);
		world.setBlock(i + 6, j + 9, k + 7, Block.planks.blockID);
		world.setBlock(i + 6, j + 9, k + 8, Block.planks.blockID);
		world.setBlockAndMetadata(i + 6, j + 9, k + 9, Block.stairCompactPlanks.blockID, 3);
		world.setBlock(i + 6, j + 9, k + 20, Block.wood.blockID);
		world.setBlock(i + 6, j + 9, k + 21, Block.wood.blockID);
		world.setBlock(i + 6, j + 9, k + 29, Block.fence.blockID);
		world.setBlock(i + 6, j + 9, k + 34, Block.wood.blockID);
		world.setBlock(i + 6, j + 9, k + 35, Block.wood.blockID);
		world.setBlock(i + 6, j + 9, k + 52, Block.planks.blockID);
		world.setBlock(i + 6, j + 10, k + 3, Block.planks.blockID);
		world.setBlock(i + 6, j + 10, k + 4, Block.planks.blockID);
		world.setBlock(i + 6, j + 10, k + 6, Block.planks.blockID);
		world.setBlock(i + 6, j + 10, k + 7, Block.planks.blockID);
		world.setBlockAndMetadata(i + 6, j + 10, k + 8, Block.stairCompactPlanks.blockID, 3);
		world.setBlock(i + 6, j + 10, k + 20, Block.wood.blockID);
		world.setBlock(i + 6, j + 10, k + 21, Block.wood.blockID);
		world.setBlock(i + 6, j + 10, k + 34, Block.wood.blockID);
		world.setBlock(i + 6, j + 10, k + 35, Block.wood.blockID);
		world.setBlock(i + 6, j + 10, k + 52, Block.glass.blockID);
		world.setBlock(i + 6, j + 11, k + 3, Block.planks.blockID);
		world.setBlock(i + 6, j + 11, k + 4, Block.planks.blockID);
		world.setBlock(i + 6, j + 11, k + 5, Block.planks.blockID);
		world.setBlock(i + 6, j + 11, k + 6, Block.planks.blockID);
		world.setBlockAndMetadata(i + 6, j + 11, k + 7, Block.stairCompactPlanks.blockID, 3);
