package mod.fossil.common.gens;

import java.util.Random;

import net.minecraft.block.Block;
import net.minecraft.world.World;
import net.minecraft.world.gen.feature.WorldGenerator;

public class WorldGeneratorGalleonWreck extends WorldGenerator
{
	
	public boolean generate(World world, Random rand, int i, int j, int k)
	{
		System.out.println("Generating GalleonWreck");
		world.setBlock(i + 0, j + 0, k + 0, Block.bedrock.blockID);
		world.setBlock(i + 0, j + 0, k + 1, Block.bedrock.blockID);
		world.setBlock(i + 0, j + 0, k + 2, Block.bedrock.blockID);
		world.setBlock(i + 0, j + 0, k + 3, Block.bedrock.blockID);
		world.setBlock(i + 0, j + 0, k + 4, Block.bedrock.blockID);
		world.setBlock(i + 0, j + 0, k + 5, Block.bedrock.blockID);
		world.setBlock(i + 0, j + 0, k + 6, Block.bedrock.blockID);
		world.setBlock(i + 0, j + 0, k + 7, Block.bedrock.blockID);
		world.setBlock(i + 0, j + 0, k + 8, Block.bedrock.blockID);
		world.setBlock(i + 0, j + 0, k + 9, Block.bedrock.blockID);
		world.setBlock(i + 0, j + 0, k + 10, Block.bedrock.blockID);
		world.setBlock(i + 0, j + 0, k + 11, Block.bedrock.blockID);
		world.setBlock(i + 0, j + 0, k + 12, Block.bedrock.blockID);
		world.setBlock(i + 0, j + 0, k + 13, Block.bedrock.blockID);
		world.setBlock(i + 0, j + 0, k + 14, Block.bedrock.blockID);
		world.setBlock(i + 0, j + 0, k + 15, Block.bedrock.blockID);
		world.setBlock(i + 0, j + 0, k + 16, Block.bedrock.blockID);
		world.setBlock(i + 0, j + 0, k + 17, Block.bedrock.blockID);
		world.setBlock(i + 0, j + 0, k + 18, Block.bedrock.blockID);
		world.setBlock(i + 0, j + 0, k + 19, Block.bedrock.blockID);
		world.setBlock(i + 0, j + 0, k + 20, Block.bedrock.blockID);
		world.setBlock(i + 0, j + 0, k + 21, Block.bedrock.blockID);
		world.setBlock(i + 0, j + 0, k + 22, Block.bedrock.blockID);
		world.setBlock(i + 0, j + 0, k + 23, Block.bedrock.blockID);
		world.setBlock(i + 0, j + 0, k + 24, Block.bedrock.blockID);
		world.setBlock(i + 0, j + 0, k + 25, Block.bedrock.blockID);
		world.setBlock(i + 0, j + 0, k + 26, Block.bedrock.blockID);
		world.setBlock(i + 0, j + 0, k + 27, Block.bedrock.blockID);
		world.setBlock(i + 0, j + 0, k + 28, Block.bedrock.blockID);
		world.setBlock(i + 0, j + 0, k + 29, Block.bedrock.blockID);
		world.setBlock(i + 0, j + 0, k + 30, Block.bedrock.blockID);
		world.setBlock(i + 0, j + 0, k + 31, Block.bedrock.blockID);
		world.setBlock(i + 0, j + 0, k + 32, Block.bedrock.blockID);
		world.setBlock(i + 0, j + 0, k + 33, Block.bedrock.blockID);
		world.setBlock(i + 0, j + 0, k + 34, Block.bedrock.blockID);
		world.setBlock(i + 0, j + 0, k + 35, Block.bedrock.blockID);
		world.setBlock(i + 0, j + 0, k + 36, Block.bedrock.blockID);
		world.setBlock(i + 0, j + 0, k + 37, Block.bedrock.blockID);
		world.setBlock(i + 0, j + 0, k + 38, Block.bedrock.blockID);
		world.setBlock(i + 0, j + 0, k + 39, Block.bedrock.blockID);
		world.setBlock(i + 0, j + 0, k + 40, Block.bedrock.blockID);
		world.setBlock(i + 0, j + 0, k + 41, Block.bedrock.blockID);
		world.setBlock(i + 0, j + 0, k + 42, Block.bedrock.blockID);
		world.setBlock(i + 0, j + 0, k + 43, Block.bedrock.blockID);
		world.setBlock(i + 0, j + 0, k + 44, Block.bedrock.blockID);
		world.setBlock(i + 0, j + 0, k + 45, Block.bedrock.blockID);
		world.setBlock(i + 0, j + 0, k + 46, Block.bedrock.blockID);
		world.setBlock(i + 0, j + 0, k + 47, Block.bedrock.blockID);
		world.setBlock(i + 0, j + 0, k + 48, Block.bedrock.blockID);
		world.setBlock(i + 0, j + 0, k + 49, Block.bedrock.blockID);
		world.setBlock(i + 0, j + 0, k + 50, Block.bedrock.blockID);
		world.setBlock(i + 0, j + 0, k + 51, Block.bedrock.blockID);
		world.setBlock(i + 0, j + 0, k + 52, Block.bedrock.blockID);
		world.setBlock(i + 0, j + 0, k + 53, Block.bedrock.blockID);
		world.setBlock(i + 0, j + 0, k + 54, Block.bedrock.blockID);
		world.setBlock(i + 0, j + 0, k + 55, Block.bedrock.blockID);
		world.setBlock(i + 0, j + 0, k + 56, Block.bedrock.blockID);
		world.setBlock(i + 0, j + 0, k + 57, Block.bedrock.blockID);
		world.setBlock(i + 0, j + 0, k + 58, Block.bedrock.blockID);
		world.setBlock(i + 0, j + 0, k + 59, Block.bedrock.blockID);
		world.setBlock(i + 0, j + 0, k + 60, Block.bedrock.blockID);
		world.setBlock(i + 0, j + 0, k + 61, Block.bedrock.blockID);
		world.setBlock(i + 0, j + 0, k + 62, Block.bedrock.blockID);
		world.setBlock(i + 0, j + 0, k + 63, Block.bedrock.blockID);
		world.setBlock(i + 0, j + 0, k + 64, Block.bedrock.blockID);
		world.setBlock(i + 0, j + 0, k + 65, Block.bedrock.blockID);
		world.setBlock(i + 0, j + 0, k + 66, Block.bedrock.blockID);
		world.setBlock(i + 0, j + 0, k + 67, Block.bedrock.blockID);
		world.setBlock(i + 0, j + 0, k + 68, Block.bedrock.blockID);
		world.setBlock(i + 0, j + 0, k + 69, Block.bedrock.blockID);
		world.setBlock(i + 0, j + 1, k + 0, Block.dirt.blockID);
		world.setBlock(i + 0, j + 1, k + 1, Block.dirt.blockID);
		world.setBlock(i + 0, j + 1, k + 2, Block.dirt.blockID);
		world.setBlock(i + 0, j + 1, k + 3, Block.dirt.blockID);
		world.setBlock(i + 0, j + 1, k + 4, Block.dirt.blockID);
		world.setBlock(i + 0, j + 1, k + 5, Block.dirt.blockID);
		world.setBlock(i + 0, j + 1, k + 6, Block.dirt.blockID);
		world.setBlock(i + 0, j + 1, k + 7, Block.dirt.blockID);
		world.setBlock(i + 0, j + 1, k + 8, Block.dirt.blockID);
		world.setBlock(i + 0, j + 1, k + 9, Block.dirt.blockID);
		world.setBlock(i + 0, j + 1, k + 10, Block.dirt.blockID);
		world.setBlock(i + 0, j + 1, k + 11, Block.dirt.blockID);
		world.setBlock(i + 0, j + 1, k + 12, Block.dirt.blockID);
		world.setBlock(i + 0, j + 1, k + 13, Block.dirt.blockID);
		world.setBlock(i + 0, j + 1, k + 14, Block.dirt.blockID);
		world.setBlock(i + 0, j + 1, k + 15, Block.dirt.blockID);
		world.setBlock(i + 0, j + 1, k + 16, Block.dirt.blockID);
		world.setBlock(i + 0, j + 1, k + 17, Block.dirt.blockID);
		world.setBlock(i + 0, j + 1, k + 18, Block.dirt.blockID);
		world.setBlock(i + 0, j + 1, k + 19, Block.dirt.blockID);
		world.setBlock(i + 0, j + 1, k + 20, Block.dirt.blockID);
		world.setBlock(i + 0, j + 1, k + 21, Block.dirt.blockID);
		world.setBlock(i + 0, j + 1, k + 22, Block.dirt.blockID);
		world.setBlock(i + 0, j + 1, k + 23, Block.dirt.blockID);
		world.setBlock(i + 0, j + 1, k + 24, Block.dirt.blockID);
		world.setBlock(i + 0, j + 1, k + 25, Block.dirt.blockID);
		world.setBlock(i + 0, j + 1, k + 26, Block.dirt.blockID);
		world.setBlock(i + 0, j + 1, k + 27, Block.dirt.blockID);
		world.setBlock(i + 0, j + 1, k + 28, Block.dirt.blockID);
		world.setBlock(i + 0, j + 1, k + 29, Block.dirt.blockID);
		world.setBlock(i + 0, j + 1, k + 30, Block.dirt.blockID);
		world.setBlock(i + 0, j + 1, k + 31, Block.dirt.blockID);
		world.setBlock(i + 0, j + 1, k + 32, Block.dirt.blockID);
		world.setBlock(i + 0, j + 1, k + 33, Block.dirt.blockID);
		world.setBlock(i + 0, j + 1, k + 34, Block.dirt.blockID);
		world.setBlock(i + 0, j + 1, k + 35, Block.dirt.blockID);
		world.setBlock(i + 0, j + 1, k + 36, Block.dirt.blockID);
		world.setBlock(i + 0, j + 1, k + 37, Block.dirt.blockID);
		world.setBlock(i + 0, j + 1, k + 38, Block.dirt.blockID);
		world.setBlock(i + 0, j + 1, k + 39, Block.dirt.blockID);
		world.setBlock(i + 0, j + 1, k + 40, Block.dirt.blockID);
		world.setBlock(i + 0, j + 1, k + 41, Block.dirt.blockID);
		world.setBlock(i + 0, j + 1, k + 42, Block.dirt.blockID);
		world.setBlock(i + 0, j + 1, k + 43, Block.dirt.blockID);
		world.setBlock(i + 0, j + 1, k + 44, Block.dirt.blockID);
		world.setBlock(i + 0, j + 1, k + 45, Block.dirt.blockID);
		world.setBlock(i + 0, j + 1, k + 46, Block.dirt.blockID);
		world.setBlock(i + 0, j + 1, k + 47, Block.dirt.blockID);
		world.setBlock(i + 0, j + 1, k + 48, Block.dirt.blockID);
		world.setBlock(i + 0, j + 1, k + 49, Block.dirt.blockID);
		world.setBlock(i + 0, j + 1, k + 50, Block.dirt.blockID);
		world.setBlock(i + 0, j + 1, k + 51, Block.dirt.blockID);
		world.setBlock(i + 0, j + 1, k + 52, Block.dirt.blockID);
		world.setBlock(i + 0, j + 1, k + 53, Block.dirt.blockID);
		world.setBlock(i + 0, j + 1, k + 54, Block.dirt.blockID);
		world.setBlock(i + 0, j + 1, k + 55, Block.dirt.blockID);
		world.setBlock(i + 0, j + 1, k + 56, Block.dirt.blockID);
		world.setBlock(i + 0, j + 1, k + 57, Block.dirt.blockID);
		world.setBlock(i + 0, j + 1, k + 58, Block.dirt.blockID);
		world.setBlock(i + 0, j + 1, k + 59, Block.dirt.blockID);
		world.setBlock(i + 0, j + 1, k + 60, Block.dirt.blockID);
		world.setBlock(i + 0, j + 1, k + 61, Block.dirt.blockID);
		world.setBlock(i + 0, j + 1, k + 62, Block.dirt.blockID);
		world.setBlock(i + 0, j + 1, k + 63, Block.dirt.blockID);
		world.setBlock(i + 0, j + 1, k + 64, Block.dirt.blockID);
		world.setBlock(i + 0, j + 1, k + 65, Block.dirt.blockID);
		world.setBlock(i + 0, j + 1, k + 66, Block.dirt.blockID);
		world.setBlock(i + 0, j + 1, k + 67, Block.dirt.blockID);
		world.setBlock(i + 0, j + 1, k + 68, Block.dirt.blockID);
		world.setBlock(i + 0, j + 1, k + 69, Block.dirt.blockID);
		world.setBlock(i + 0, j + 2, k + 0, Block.dirt.blockID);
		world.setBlock(i + 0, j + 2, k + 1, Block.dirt.blockID);
		world.setBlock(i + 0, j + 2, k + 2, Block.dirt.blockID);
		world.setBlock(i + 0, j + 2, k + 3, Block.dirt.blockID);
		world.setBlock(i + 0, j + 2, k + 4, Block.dirt.blockID);
		world.setBlock(i + 0, j + 2, k + 5, Block.dirt.blockID);
		world.setBlock(i + 0, j + 2, k + 6, Block.dirt.blockID);
		world.setBlock(i + 0, j + 2, k + 7, Block.dirt.blockID);
		world.setBlock(i + 0, j + 2, k + 8, Block.dirt.blockID);
		world.setBlock(i + 0, j + 2, k + 9, Block.dirt.blockID);
		world.setBlock(i + 0, j + 2, k + 10, Block.dirt.blockID);
		world.setBlock(i + 0, j + 2, k + 11, Block.dirt.blockID);
		world.setBlock(i + 0, j + 2, k + 12, Block.dirt.blockID);
		world.setBlock(i + 0, j + 2, k + 13, Block.dirt.blockID);
		world.setBlock(i + 0, j + 2, k + 14, Block.dirt.blockID);
		world.setBlock(i + 0, j + 2, k + 15, Block.dirt.blockID);
		world.setBlock(i + 0, j + 2, k + 16, Block.dirt.blockID);
		world.setBlock(i + 0, j + 2, k + 17, Block.dirt.blockID);
		world.setBlock(i + 0, j + 2, k + 18, Block.dirt.blockID);
		world.setBlock(i + 0, j + 2, k + 19, Block.dirt.blockID);
		world.setBlock(i + 0, j + 2, k + 20, Block.dirt.blockID);
		world.setBlock(i + 0, j + 2, k + 21, Block.dirt.blockID);
		world.setBlock(i + 0, j + 2, k + 22, Block.dirt.blockID);
		world.setBlock(i + 0, j + 2, k + 23, Block.dirt.blockID);
		world.setBlock(i + 0, j + 2, k + 24, Block.dirt.blockID);
		world.setBlock(i + 0, j + 2, k + 25, Block.dirt.blockID);
		world.setBlock(i + 0, j + 2, k + 26, Block.dirt.blockID);
		world.setBlock(i + 0, j + 2, k + 27, Block.dirt.blockID);
		world.setBlock(i + 0, j + 2, k + 28, Block.dirt.blockID);
		world.setBlock(i + 0, j + 2, k + 29, Block.dirt.blockID);
		world.setBlock(i + 0, j + 2, k + 30, Block.dirt.blockID);
		world.setBlock(i + 0, j + 2, k + 31, Block.dirt.blockID);
		world.setBlock(i + 0, j + 2, k + 32, Block.dirt.blockID);
		world.setBlock(i + 0, j + 2, k + 33, Block.dirt.blockID);
		world.setBlock(i + 0, j + 2, k + 34, Block.dirt.blockID);
		world.setBlock(i + 0, j + 2, k + 35, Block.dirt.blockID);
		world.setBlock(i + 0, j + 2, k + 36, Block.dirt.blockID);
		world.setBlock(i + 0, j + 2, k + 37, Block.dirt.blockID);
		world.setBlock(i + 0, j + 2, k + 38, Block.dirt.blockID);
		world.setBlock(i + 0, j + 2, k + 39, Block.dirt.blockID);
		world.setBlock(i + 0, j + 2, k + 40, Block.dirt.blockID);
		world.setBlock(i + 0, j + 2, k + 41, Block.dirt.blockID);
		world.setBlock(i + 0, j + 2, k + 42, Block.dirt.blockID);
		world.setBlock(i + 0, j + 2, k + 43, Block.dirt.blockID);
		world.setBlock(i + 0, j + 2, k + 44, Block.dirt.blockID);
		world.setBlock(i + 0, j + 2, k + 45, Block.dirt.blockID);
		world.setBlock(i + 0, j + 2, k + 46, Block.dirt.blockID);
		world.setBlock(i + 0, j + 2, k + 47, Block.dirt.blockID);
		world.setBlock(i + 0, j + 2, k + 48, Block.dirt.blockID);
		world.setBlock(i + 0, j + 2, k + 49, Block.dirt.blockID);
		world.setBlock(i + 0, j + 2, k + 50, Block.dirt.blockID);
		world.setBlock(i + 0, j + 2, k + 51, Block.dirt.blockID);
		world.setBlock(i + 0, j + 2, k + 52, Block.dirt.blockID);
		world.setBlock(i + 0, j + 2, k + 53, Block.dirt.blockID);
		world.setBlock(i + 0, j + 2, k + 54, Block.dirt.blockID);
		world.setBlock(i + 0, j + 2, k + 55, Block.dirt.blockID);
		world.setBlock(i + 0, j + 2, k + 56, Block.dirt.blockID);
		world.setBlock(i + 0, j + 2, k + 57, Block.dirt.blockID);
		world.setBlock(i + 0, j + 2, k + 58, Block.dirt.blockID);
		world.setBlock(i + 0, j + 2, k + 59, Block.dirt.blockID);
		world.setBlock(i + 0, j + 2, k + 60, Block.dirt.blockID);
		world.setBlock(i + 0, j + 2, k + 61, Block.dirt.blockID);
		world.setBlock(i + 0, j + 2, k + 62, Block.dirt.blockID);
		world.setBlock(i + 0, j + 2, k + 63, Block.dirt.blockID);
		world.setBlock(i + 0, j + 2, k + 64, Block.dirt.blockID);
		world.setBlock(i + 0, j + 2, k + 65, Block.dirt.blockID);
		world.setBlock(i + 0, j + 2, k + 66, Block.dirt.blockID);
		world.setBlock(i + 0, j + 2, k + 67, Block.dirt.blockID);
		world.setBlock(i + 0, j + 2, k + 68, Block.dirt.blockID);
		world.setBlock(i + 0, j + 2, k + 69, Block.dirt.blockID);
		world.setBlock(i + 0, j + 3, k + 0, Block.grass.blockID);
		world.setBlock(i + 0, j + 3, k + 1, Block.grass.blockID);
		world.setBlock(i + 0, j + 3, k + 2, Block.grass.blockID);
		world.setBlock(i + 0, j + 3, k + 3, Block.grass.blockID);
		world.setBlock(i + 0, j + 3, k + 4, Block.grass.blockID);
		world.setBlock(i + 0, j + 3, k + 5, Block.grass.blockID);
		world.setBlock(i + 0, j + 3, k + 6, Block.grass.blockID);
		world.setBlock(i + 0, j + 3, k + 7, Block.grass.blockID);
		world.setBlock(i + 0, j + 3, k + 8, Block.grass.blockID);
		world.setBlock(i + 0, j + 3, k + 9, Block.grass.blockID);
		world.setBlock(i + 0, j + 3, k + 10, Block.grass.blockID);
		world.setBlock(i + 0, j + 3, k + 11, Block.grass.blockID);
		world.setBlock(i + 0, j + 3, k + 12, Block.grass.blockID);
		world.setBlock(i + 0, j + 3, k + 13, Block.grass.blockID);
		world.setBlock(i + 0, j + 3, k + 14, Block.grass.blockID);
		world.setBlock(i + 0, j + 3, k + 15, Block.grass.blockID);
		world.setBlock(i + 0, j + 3, k + 16, Block.grass.blockID);
		world.setBlock(i + 0, j + 3, k + 17, Block.grass.blockID);
		world.setBlock(i + 0, j + 3, k + 18, Block.grass.blockID);
		world.setBlock(i + 0, j + 3, k + 19, Block.grass.blockID);
		world.setBlock(i + 0, j + 3, k + 20, Block.grass.blockID);
		world.setBlock(i + 0, j + 3, k + 21, Block.grass.blockID);
		world.setBlock(i + 0, j + 3, k + 22, Block.grass.blockID);
		world.setBlock(i + 0, j + 3, k + 23, Block.grass.blockID);
		world.setBlock(i + 0, j + 3, k + 24, Block.planks.blockID);
		world.setBlock(i + 0, j + 3, k + 25, Block.planks.blockID);
		world.setBlock(i + 0, j + 3, k + 26, Block.planks.blockID);
		world.setBlock(i + 0, j + 3, k + 27, Block.planks.blockID);
		world.setBlock(i + 0, j + 3, k + 28, Block.planks.blockID);
		world.setBlock(i + 0, j + 3, k + 29, Block.planks.blockID);
		world.setBlock(i + 0, j + 3, k + 30, Block.planks.blockID);
		world.setBlock(i + 0, j + 3, k + 31, Block.planks.blockID);
		world.setBlock(i + 0, j + 3, k + 32, Block.planks.blockID);
		world.setBlock(i + 0, j + 3, k + 33, Block.planks.blockID);
		world.setBlock(i + 0, j + 3, k + 34, Block.planks.blockID);
		world.setBlock(i + 0, j + 3, k + 35, Block.planks.blockID);
		world.setBlock(i + 0, j + 3, k + 36, Block.planks.blockID);
		world.setBlock(i + 0, j + 3, k + 37, Block.planks.blockID);
		world.setBlock(i + 0, j + 3, k + 38, Block.planks.blockID);
		world.setBlock(i + 0, j + 3, k + 39, Block.planks.blockID);
		world.setBlock(i + 0, j + 3, k + 40, Block.planks.blockID);
		world.setBlock(i + 0, j + 3, k + 41, Block.planks.blockID);
		world.setBlock(i + 0, j + 3, k + 42, Block.planks.blockID);
		world.setBlock(i + 0, j + 3, k + 43, Block.grass.blockID);
		world.setBlock(i + 0, j + 3, k + 44, Block.grass.blockID);
		world.setBlock(i + 0, j + 3, k + 45, Block.grass.blockID);
		world.setBlock(i + 0, j + 3, k + 46, Block.grass.blockID);
		world.setBlock(i + 0, j + 3, k + 47, Block.grass.blockID);
		world.setBlock(i + 0, j + 3, k + 48, Block.grass.blockID);
		world.setBlock(i + 0, j + 3, k + 49, Block.grass.blockID);
		world.setBlock(i + 0, j + 3, k + 50, Block.grass.blockID);
		world.setBlock(i + 0, j + 3, k + 51, Block.grass.blockID);
		world.setBlock(i + 0, j + 3, k + 52, Block.grass.blockID);
		world.setBlock(i + 0, j + 3, k + 53, Block.grass.blockID);
		world.setBlock(i + 0, j + 3, k + 54, Block.grass.blockID);
		world.setBlock(i + 0, j + 3, k + 55, Block.grass.blockID);
		world.setBlock(i + 0, j + 3, k + 56, Block.grass.blockID);
		world.setBlock(i + 0, j + 3, k + 57, Block.grass.blockID);
		world.setBlock(i + 0, j + 3, k + 58, Block.grass.blockID);
		world.setBlock(i + 0, j + 3, k + 59, Block.grass.blockID);
		world.setBlock(i + 0, j + 3, k + 60, Block.grass.blockID);
		world.setBlock(i + 0, j + 3, k + 61, Block.grass.blockID);
		world.setBlock(i + 0, j + 3, k + 62, Block.grass.blockID);
		world.setBlock(i + 0, j + 3, k + 63, Block.grass.blockID);
		world.setBlock(i + 0, j + 3, k + 64, Block.grass.blockID);
		world.setBlock(i + 0, j + 3, k + 65, Block.grass.blockID);
		world.setBlock(i + 0, j + 3, k + 66, Block.grass.blockID);
		world.setBlock(i + 0, j + 3, k + 67, Block.grass.blockID);
		world.setBlock(i + 0, j + 3, k + 68, Block.grass.blockID);
		world.setBlock(i + 0, j + 3, k + 69, Block.grass.blockID);
		world.setBlock(i + 0, j + 4, k + 20, Block.planks.blockID);
		world.setBlock(i + 0, j + 4, k + 21, Block.planks.blockID);
		world.setBlock(i + 0, j + 4, k + 22, Block.planks.blockID);
		world.setBlock(i + 0, j + 4, k + 23, Block.planks.blockID);
		world.setBlock(i + 0, j + 4, k + 24, Block.planks.blockID);
		world.setBlock(i + 0, j + 4, k + 25, Block.planks.blockID);
		world.setBlock(i + 0, j + 4, k + 26, Block.planks.blockID);
		world.setBlock(i + 0, j + 4, k + 27, Block.planks.blockID);
		world.setBlock(i + 0, j + 4, k + 28, Block.planks.blockID);
		world.setBlock(i + 0, j + 4, k + 29, Block.planks.blockID);
		world.setBlock(i + 0, j + 4, k + 30, Block.planks.blockID);
		world.setBlock(i + 0, j + 4, k + 31, Block.planks.blockID);
		world.setBlock(i + 0, j + 4, k + 32, Block.planks.blockID);
		world.setBlock(i + 0, j + 4, k + 33, Block.planks.blockID);
		world.setBlock(i + 0, j + 4, k + 34, Block.planks.blockID);
		world.setBlock(i + 0, j + 4, k + 35, Block.planks.blockID);
		world.setBlock(i + 0, j + 4, k + 36, Block.planks.blockID);
		world.setBlock(i + 0, j + 4, k + 37, Block.planks.blockID);
		world.setBlock(i + 0, j + 4, k + 38, Block.planks.blockID);
		world.setBlock(i + 0, j + 4, k + 39, Block.planks.blockID);
		world.setBlock(i + 0, j + 4, k + 40, Block.planks.blockID);
		world.setBlock(i + 0, j + 4, k + 41, Block.planks.blockID);
		world.setBlock(i + 0, j + 4, k + 42, Block.planks.blockID);
		world.setBlock(i + 0, j + 4, k + 43, Block.planks.blockID);
		world.setBlock(i + 0, j + 4, k + 44, Block.planks.blockID);
		world.setBlock(i + 0, j + 4, k + 45, Block.planks.blockID);
		world.setBlock(i + 0, j + 5, k + 18, Block.planks.blockID);
		world.setBlock(i + 0, j + 5, k + 19, Block.planks.blockID);
		world.setBlock(i + 0, j + 5, k + 20, Block.planks.blockID);
		world.setBlock(i + 0, j + 5, k + 21, Block.planks.blockID);
		world.setBlock(i + 0, j + 5, k + 22, Block.planks.blockID);
		world.setBlock(i + 0, j + 5, k + 23, Block.planks.blockID);
		world.setBlock(i + 0, j + 5, k + 24, Block.planks.blockID);
		world.setBlock(i + 0, j + 5, k + 25, Block.planks.blockID);
		world.setBlock(i + 0, j + 5, k + 26, Block.planks.blockID);
		world.setBlock(i + 0, j + 5, k + 27, Block.planks.blockID);
		world.setBlock(i + 0, j + 5, k + 28, Block.planks.blockID);
		world.setBlock(i + 0, j + 5, k + 29, Block.planks.blockID);
		world.setBlock(i + 0, j + 5, k + 30, Block.planks.blockID);
		world.setBlock(i + 0, j + 5, k + 31, Block.planks.blockID);
		world.setBlock(i + 0, j + 5, k + 32, Block.planks.blockID);
		world.setBlock(i + 0, j + 5, k + 33, Block.planks.blockID);
		world.setBlock(i + 0, j + 5, k + 34, Block.planks.blockID);
		world.setBlock(i + 0, j + 5, k + 35, Block.planks.blockID);
		world.setBlock(i + 0, j + 5, k + 36, Block.planks.blockID);
		world.setBlock(i + 0, j + 5, k + 37, Block.planks.blockID);
		world.setBlock(i + 0, j + 5, k + 38, Block.planks.blockID);
		world.setBlock(i + 0, j + 5, k + 39, Block.planks.blockID);
		world.setBlock(i + 0, j + 5, k + 40, Block.planks.blockID);
		world.setBlock(i + 0, j + 5, k + 41, Block.planks.blockID);
		world.setBlock(i + 0, j + 5, k + 42, Block.planks.blockID);
		world.setBlock(i + 0, j + 5, k + 43, Block.planks.blockID);
		world.setBlock(i + 0, j + 5, k + 44, Block.planks.blockID);
		world.setBlock(i + 0, j + 5, k + 45, Block.planks.blockID);
		world.setBlock(i + 0, j + 5, k + 46, Block.planks.blockID);
		world.setBlock(i + 0, j + 5, k + 47, Block.planks.blockID);
		world.setBlockAndMetadata(i + 0, j + 6, k + 18, Block.wood.blockID, 3);
		world.setBlockAndMetadata(i + 0, j + 6, k + 19, Block.wood.blockID, 3);
		world.setBlockAndMetadata(i + 0, j + 6, k + 20, Block.wood.blockID, 3);
		world.setBlockAndMetadata(i + 0, j + 6, k + 21, Block.wood.blockID, 3);
		world.setBlockAndMetadata(i + 0, j + 6, k + 22, Block.wood.blockID, 3);
		world.setBlockAndMetadata(i + 0, j + 6, k + 23, Block.wood.blockID, 3);
		world.setBlockAndMetadata(i + 0, j + 6, k + 24, Block.wood.blockID, 3);
		world.setBlockAndMetadata(i + 0, j + 6, k + 25, Block.wood.blockID, 3);
		world.setBlockAndMetadata(i + 0, j + 6, k + 26, Block.wood.blockID, 3);
		world.setBlockAndMetadata(i + 0, j + 6, k + 27, Block.wood.blockID, 3);
		world.setBlockAndMetadata(i + 0, j + 6, k + 28, Block.wood.blockID, 3);
		world.setBlockAndMetadata(i + 0, j + 6, k + 29, Block.wood.blockID, 3);
		world.setBlockAndMetadata(i + 0, j + 6, k + 30, Block.wood.blockID, 3);
		world.setBlockAndMetadata(i + 0, j + 6, k + 31, Block.wood.blockID, 3);
		world.setBlockAndMetadata(i + 0, j + 6, k + 32, Block.wood.blockID, 3);
		world.setBlockAndMetadata(i + 0, j + 6, k + 33, Block.wood.blockID, 3);
		world.setBlockAndMetadata(i + 0, j + 6, k + 34, Block.wood.blockID, 3);
		world.setBlockAndMetadata(i + 0, j + 6, k + 35, Block.wood.blockID, 3);
		world.setBlockAndMetadata(i + 0, j + 6, k + 36, Block.wood.blockID, 3);
		world.setBlockAndMetadata(i + 0, j + 6, k + 37, Block.wood.blockID, 3);
		world.setBlockAndMetadata(i + 0, j + 6, k + 38, Block.wood.blockID, 3);
		world.setBlockAndMetadata(i + 0, j + 6, k + 39, Block.wood.blockID, 3);
		world.setBlockAndMetadata(i + 0, j + 6, k + 40, Block.wood.blockID, 3);
		world.setBlockAndMetadata(i + 0, j + 6, k + 41, Block.wood.blockID, 3);
		world.setBlockAndMetadata(i + 0, j + 6, k + 42, Block.wood.blockID, 3);
		world.setBlockAndMetadata(i + 0, j + 6, k + 43, Block.wood.blockID, 3);
		world.setBlockAndMetadata(i + 0, j + 6, k + 44, Block.wood.blockID, 3);
		world.setBlockAndMetadata(i + 0, j + 6, k + 45, Block.wood.blockID, 3);
		world.setBlockAndMetadata(i + 0, j + 6, k + 46, Block.wood.blockID, 3);
		world.setBlockAndMetadata(i + 0, j + 6, k + 47, Block.wood.blockID, 3);
		world.setBlock(i + 0, j + 7, k + 17, Block.planks.blockID);
		world.setBlock(i + 0, j + 7, k + 18, Block.planks.blockID);
		world.setBlock(i + 0, j + 7, k + 19, Block.planks.blockID);
		world.setBlock(i + 0, j + 7, k + 20, Block.planks.blockID);
		world.setBlock(i + 0, j + 7, k + 21, Block.planks.blockID);
		world.setBlock(i + 0, j + 7, k + 22, Block.planks.blockID);
		world.setBlock(i + 0, j + 7, k + 23, Block.planks.blockID);
		world.setBlock(i + 0, j + 7, k + 24, Block.planks.blockID);
		world.setBlock(i + 0, j + 7, k + 25, Block.planks.blockID);
		world.setBlock(i + 0, j + 7, k + 26, Block.planks.blockID);
		world.setBlock(i + 0, j + 7, k + 27, Block.planks.blockID);
		world.setBlock(i + 0, j + 7, k + 28, Block.planks.blockID);
		world.setBlock(i + 0, j + 7, k + 29, Block.planks.blockID);
		world.setBlock(i + 0, j + 7, k + 30, Block.planks.blockID);
		world.setBlock(i + 0, j + 7, k + 31, Block.planks.blockID);
		world.setBlock(i + 0, j + 7, k + 32, Block.planks.blockID);
		world.setBlock(i + 0, j + 7, k + 33, Block.planks.blockID);
		world.setBlock(i + 0, j + 7, k + 34, Block.planks.blockID);
		world.setBlock(i + 0, j + 7, k + 35, Block.planks.blockID);
		world.setBlock(i + 0, j + 7, k + 36, Block.planks.blockID);
		world.setBlock(i + 0, j + 7, k + 37, Block.planks.blockID);
		world.setBlock(i + 0, j + 7, k + 38, Block.planks.blockID);
		world.setBlock(i + 0, j + 7, k + 39, Block.planks.blockID);
		world.setBlock(i + 0, j + 7, k + 40, Block.planks.blockID);
		world.setBlock(i + 0, j + 7, k + 41, Block.planks.blockID);
		world.setBlock(i + 0, j + 7, k + 42, Block.planks.blockID);
		world.setBlock(i + 0, j + 7, k + 43, Block.planks.blockID);
		world.setBlock(i + 0, j + 7, k + 44, Block.planks.blockID);
		world.setBlock(i + 0, j + 7, k + 45, Block.planks.blockID);
		world.setBlock(i + 0, j + 7, k + 46, Block.planks.blockID);
		world.setBlock(i + 0, j + 7, k + 47, Block.planks.blockID);
		world.setBlock(i + 0, j + 8, k + 17, Block.planks.blockID);
		world.setBlock(i + 0, j + 8, k + 18, Block.planks.blockID);
		world.setBlock(i + 0, j + 8, k + 19, Block.planks.blockID);
		world.setBlock(i + 0, j + 8, k + 20, Block.planks.blockID);
		world.setBlock(i + 0, j + 8, k + 21, Block.planks.blockID);
		world.setBlock(i + 0, j + 8, k + 22, Block.planks.blockID);
		world.setBlock(i + 0, j + 8, k + 23, Block.planks.blockID);
		world.setBlock(i + 0, j + 8, k + 24, Block.planks.blockID);
		world.setBlock(i + 0, j + 8, k + 25, Block.planks.blockID);
		world.setBlock(i + 0, j + 8, k + 26, Block.planks.blockID);
		world.setBlock(i + 0, j + 8, k + 27, Block.planks.blockID);
		world.setBlock(i + 0, j + 8, k + 28, Block.planks.blockID);
		world.setBlock(i + 0, j + 8, k + 29, Block.planks.blockID);
		world.setBlock(i + 0, j + 8, k + 30, Block.planks.blockID);
		world.setBlock(i + 0, j + 8, k + 31, Block.planks.blockID);
		world.setBlock(i + 0, j + 8, k + 32, Block.planks.blockID);
		world.setBlock(i + 0, j + 8, k + 33, Block.planks.blockID);
		world.setBlock(i + 0, j + 8, k + 34, Block.planks.blockID);
		world.setBlock(i + 0, j + 8, k + 35, Block.planks.blockID);
		world.setBlock(i + 0, j + 8, k + 36, Block.planks.blockID);
		world.setBlock(i + 0, j + 8, k + 37, Block.planks.blockID);
		world.setBlock(i + 0, j + 8, k + 38, Block.planks.blockID);
		world.setBlock(i + 0, j + 8, k + 39, Block.planks.blockID);
		world.setBlock(i + 0, j + 8, k + 40, Block.planks.blockID);
		world.setBlock(i + 0, j + 8, k + 41, Block.planks.blockID);
		world.setBlock(i + 0, j + 8, k + 42, Block.planks.blockID);
		world.setBlock(i + 0, j + 8, k + 43, Block.planks.blockID);
		world.setBlock(i + 0, j + 8, k + 44, Block.planks.blockID);
		world.setBlock(i + 0, j + 8, k + 45, Block.planks.blockID);
		world.setBlock(i + 0, j + 8, k + 46, Block.planks.blockID);
		world.setBlock(i + 0, j + 10, k + 3, Block.planks.blockID);
		world.setBlock(i + 0, j + 10, k + 4, Block.planks.blockID);
		world.setBlock(i + 0, j + 10, k + 5, Block.planks.blockID);
		world.setBlock(i + 0, j + 10, k + 6, Block.planks.blockID);
		world.setBlock(i + 0, j + 10, k + 7, Block.planks.blockID);
		world.setBlock(i + 0, j + 10, k + 8, Block.planks.blockID);
		world.setBlock(i + 0, j + 10, k + 9, Block.planks.blockID);
		world.setBlock(i + 0, j + 11, k + 3, Block.planks.blockID);
		world.setBlock(i + 0, j + 11, k + 4, Block.planks.blockID);
		world.setBlock(i + 0, j + 11, k + 5, Block.planks.blockID);
		world.setBlock(i + 0, j + 11, k + 6, Block.planks.blockID);
		world.setBlock(i + 0, j + 11, k + 7, Block.planks.blockID);
		world.setBlock(i + 0, j + 11, k + 8, Block.planks.blockID);
		world.setBlock(i + 0, j + 11, k + 9, Block.planks.blockID);
		world.setBlock(i + 1, j + 0, k + 0, Block.bedrock.blockID);
		world.setBlock(i + 1, j + 0, k + 1, Block.bedrock.blockID);
		world.setBlock(i + 1, j + 0, k + 2, Block.bedrock.blockID);
		world.setBlock(i + 1, j + 0, k + 3, Block.bedrock.blockID);
		world.setBlock(i + 1, j + 0, k + 4, Block.bedrock.blockID);
		world.setBlock(i + 1, j + 0, k + 5, Block.bedrock.blockID);
		world.setBlock(i + 1, j + 0, k + 6, Block.bedrock.blockID);
		world.setBlock(i + 1, j + 0, k + 7, Block.bedrock.blockID);
		world.setBlock(i + 1, j + 0, k + 8, Block.bedrock.blockID);
		world.setBlock(i + 1, j + 0, k + 9, Block.bedrock.blockID);
		world.setBlock(i + 1, j + 0, k + 10, Block.bedrock.blockID);
		world.setBlock(i + 1, j + 0, k + 11, Block.bedrock.blockID);
		world.setBlock(i + 1, j + 0, k + 12, Block.bedrock.blockID);
		world.setBlock(i + 1, j + 0, k + 13, Block.bedrock.blockID);
		world.setBlock(i + 1, j + 0, k + 14, Block.bedrock.blockID);
		world.setBlock(i + 1, j + 0, k + 15, Block.bedrock.blockID);
		world.setBlock(i + 1, j + 0, k + 16, Block.bedrock.blockID);
		world.setBlock(i + 1, j + 0, k + 17, Block.bedrock.blockID);
		world.setBlock(i + 1, j + 0, k + 18, Block.bedrock.blockID);
		world.setBlock(i + 1, j + 0, k + 19, Block.bedrock.blockID);
		world.setBlock(i + 1, j + 0, k + 20, Block.bedrock.blockID);
		world.setBlock(i + 1, j + 0, k + 21, Block.bedrock.blockID);
		world.setBlock(i + 1, j + 0, k + 22, Block.bedrock.blockID);
		world.setBlock(i + 1, j + 0, k + 23, Block.bedrock.blockID);
		world.setBlock(i + 1, j + 0, k + 24, Block.bedrock.blockID);
		world.setBlock(i + 1, j + 0, k + 25, Block.bedrock.blockID);
		world.setBlock(i + 1, j + 0, k + 26, Block.bedrock.blockID);
		world.setBlock(i + 1, j + 0, k + 27, Block.bedrock.blockID);
		world.setBlock(i + 1, j + 0, k + 28, Block.bedrock.blockID);
		world.setBlock(i + 1, j + 0, k + 29, Block.bedrock.blockID);
		world.setBlock(i + 1, j + 0, k + 30, Block.bedrock.blockID);
		world.setBlock(i + 1, j + 0, k + 31, Block.bedrock.blockID);
		world.setBlock(i + 1, j + 0, k + 32, Block.bedrock.blockID);
		world.setBlock(i + 1, j + 0, k + 33, Block.bedrock.blockID);
		world.setBlock(i + 1, j + 0, k + 34, Block.bedrock.blockID);
		world.setBlock(i + 1, j + 0, k + 35, Block.bedrock.blockID);
		world.setBlock(i + 1, j + 0, k + 36, Block.bedrock.blockID);
		world.setBlock(i + 1, j + 0, k + 37, Block.bedrock.blockID);
		world.setBlock(i + 1, j + 0, k + 38, Block.bedrock.blockID);
		world.setBlock(i + 1, j + 0, k + 39, Block.bedrock.blockID);
		world.setBlock(i + 1, j + 0, k + 40, Block.bedrock.blockID);
		world.setBlock(i + 1, j + 0, k + 41, Block.bedrock.blockID);
		world.setBlock(i + 1, j + 0, k + 42, Block.bedrock.blockID);
		world.setBlock(i + 1, j + 0, k + 43, Block.bedrock.blockID);
		world.setBlock(i + 1, j + 0, k + 44, Block.bedrock.blockID);
		world.setBlock(i + 1, j + 0, k + 45, Block.bedrock.blockID);
		world.setBlock(i + 1, j + 0, k + 46, Block.bedrock.blockID);
		world.setBlock(i + 1, j + 0, k + 47, Block.bedrock.blockID);
		world.setBlock(i + 1, j + 0, k + 48, Block.bedrock.blockID);
		world.setBlock(i + 1, j + 0, k + 49, Block.bedrock.blockID);
		world.setBlock(i + 1, j + 0, k + 50, Block.bedrock.blockID);
		world.setBlock(i + 1, j + 0, k + 51, Block.bedrock.blockID);
		world.setBlock(i + 1, j + 0, k + 52, Block.bedrock.blockID);
		world.setBlock(i + 1, j + 0, k + 53, Block.bedrock.blockID);
		world.setBlock(i + 1, j + 0, k + 54, Block.bedrock.blockID);
		world.setBlock(i + 1, j + 0, k + 55, Block.bedrock.blockID);
		world.setBlock(i + 1, j + 0, k + 56, Block.bedrock.blockID);
		world.setBlock(i + 1, j + 0, k + 57, Block.bedrock.blockID);
		world.setBlock(i + 1, j + 0, k + 58, Block.bedrock.blockID);
		world.setBlock(i + 1, j + 0, k + 59, Block.bedrock.blockID);
		world.setBlock(i + 1, j + 0, k + 60, Block.bedrock.blockID);
		world.setBlock(i + 1, j + 0, k + 61, Block.bedrock.blockID);
		world.setBlock(i + 1, j + 0, k + 62, Block.bedrock.blockID);
		world.setBlock(i + 1, j + 0, k + 63, Block.bedrock.blockID);
		world.setBlock(i + 1, j + 0, k + 64, Block.bedrock.blockID);
		world.setBlock(i + 1, j + 0, k + 65, Block.bedrock.blockID);
		world.setBlock(i + 1, j + 0, k + 66, Block.bedrock.blockID);
		world.setBlock(i + 1, j + 0, k + 67, Block.bedrock.blockID);
		world.setBlock(i + 1, j + 0, k + 68, Block.bedrock.blockID);
		world.setBlock(i + 1, j + 0, k + 69, Block.bedrock.blockID);
		world.setBlock(i + 1, j + 1, k + 0, Block.dirt.blockID);
		world.setBlock(i + 1, j + 1, k + 1, Block.dirt.blockID);
		world.setBlock(i + 1, j + 1, k + 2, Block.dirt.blockID);
		world.setBlock(i + 1, j + 1, k + 3, Block.dirt.blockID);
		world.setBlock(i + 1, j + 1, k + 4, Block.dirt.blockID);
		world.setBlock(i + 1, j + 1, k + 5, Block.dirt.blockID);
		world.setBlock(i + 1, j + 1, k + 6, Block.dirt.blockID);
		world.setBlock(i + 1, j + 1, k + 7, Block.dirt.blockID);
		world.setBlock(i + 1, j + 1, k + 8, Block.dirt.blockID);
		world.setBlock(i + 1, j + 1, k + 9, Block.dirt.blockID);
		world.setBlock(i + 1, j + 1, k + 10, Block.dirt.blockID);
		world.setBlock(i + 1, j + 1, k + 11, Block.dirt.blockID);
		world.setBlock(i + 1, j + 1, k + 12, Block.dirt.blockID);
		world.setBlock(i + 1, j + 1, k + 13, Block.dirt.blockID);
		world.setBlock(i + 1, j + 1, k + 14, Block.dirt.blockID);
		world.setBlock(i + 1, j + 1, k + 15, Block.dirt.blockID);
		world.setBlock(i + 1, j + 1, k + 16, Block.dirt.blockID);
		world.setBlock(i + 1, j + 1, k + 17, Block.planks.blockID);
		world.setBlock(i + 1, j + 1, k + 18, Block.planks.blockID);
		world.setBlock(i + 1, j + 1, k + 19, Block.planks.blockID);
		world.setBlock(i + 1, j + 1, k + 20, Block.planks.blockID);
		world.setBlock(i + 1, j + 1, k + 21, Block.planks.blockID);
		world.setBlock(i + 1, j + 1, k + 22, Block.planks.blockID);
		world.setBlock(i + 1, j + 1, k + 23, Block.planks.blockID);
		world.setBlock(i + 1, j + 1, k + 24, Block.planks.blockID);
		world.setBlock(i + 1, j + 1, k + 25, Block.planks.blockID);
		world.setBlock(i + 1, j + 1, k + 26, Block.planks.blockID);
		world.setBlock(i + 1, j + 1, k + 27, Block.planks.blockID);
		world.setBlock(i + 1, j + 1, k + 28, Block.planks.blockID);
		world.setBlock(i + 1, j + 1, k + 29, Block.planks.blockID);
		world.setBlock(i + 1, j + 1, k + 30, Block.planks.blockID);
		world.setBlock(i + 1, j + 1, k + 31, Block.planks.blockID);
		world.setBlock(i + 1, j + 1, k + 32, Block.planks.blockID);
		world.setBlock(i + 1, j + 1, k + 33, Block.planks.blockID);
		world.setBlock(i + 1, j + 1, k + 34, Block.planks.blockID);
		world.setBlock(i + 1, j + 1, k + 35, Block.planks.blockID);
		world.setBlock(i + 1, j + 1, k + 36, Block.planks.blockID);
		world.setBlock(i + 1, j + 1, k + 37, Block.planks.blockID);
		world.setBlock(i + 1, j + 1, k + 38, Block.planks.blockID);
		world.setBlock(i + 1, j + 1, k + 39, Block.planks.blockID);
		world.setBlock(i + 1, j + 1, k + 40, Block.planks.blockID);
		world.setBlock(i + 1, j + 1, k + 41, Block.planks.blockID);
		world.setBlock(i + 1, j + 1, k + 42, Block.planks.blockID);
		world.setBlock(i + 1, j + 1, k + 43, Block.planks.blockID);
		world.setBlock(i + 1, j + 1, k + 44, Block.planks.blockID);
		world.setBlock(i + 1, j + 1, k + 45, Block.dirt.blockID);
		world.setBlock(i + 1, j + 1, k + 46, Block.dirt.blockID);
		world.setBlock(i + 1, j + 1, k + 47, Block.dirt.blockID);
		world.setBlock(i + 1, j + 1, k + 48, Block.dirt.blockID);
		world.setBlock(i + 1, j + 1, k + 49, Block.dirt.blockID);
		world.setBlock(i + 1, j + 1, k + 50, Block.dirt.blockID);
		world.setBlock(i + 1, j + 1, k + 51, Block.dirt.blockID);
		world.setBlock(i + 1, j + 1, k + 52, Block.dirt.blockID);
		world.setBlock(i + 1, j + 1, k + 53, Block.dirt.blockID);
		world.setBlock(i + 1, j + 1, k + 54, Block.dirt.blockID);
		world.setBlock(i + 1, j + 1, k + 55, Block.dirt.blockID);
		world.setBlock(i + 1, j + 1, k + 56, Block.dirt.blockID);
		world.setBlock(i + 1, j + 1, k + 57, Block.dirt.blockID);
		world.setBlock(i + 1, j + 1, k + 58, Block.dirt.blockID);
		world.setBlock(i + 1, j + 1, k + 59, Block.dirt.blockID);
		world.setBlock(i + 1, j + 1, k + 60, Block.dirt.blockID);
		world.setBlock(i + 1, j + 1, k + 61, Block.dirt.blockID);
		world.setBlock(i + 1, j + 1, k + 62, Block.dirt.blockID);
		world.setBlock(i + 1, j + 1, k + 63, Block.dirt.blockID);
		world.setBlock(i + 1, j + 1, k + 64, Block.dirt.blockID);
		world.setBlock(i + 1, j + 1, k + 65, Block.dirt.blockID);
		world.setBlock(i + 1, j + 1, k + 66, Block.dirt.blockID);
		world.setBlock(i + 1, j + 1, k + 67, Block.dirt.blockID);
		world.setBlock(i + 1, j + 1, k + 68, Block.dirt.blockID);
		world.setBlock(i + 1, j + 1, k + 69, Block.dirt.blockID);
		world.setBlock(i + 1, j + 2, k + 0, Block.dirt.blockID);
		world.setBlock(i + 1, j + 2, k + 1, Block.dirt.blockID);
		world.setBlock(i + 1, j + 2, k + 2, Block.dirt.blockID);
		world.setBlock(i + 1, j + 2, k + 3, Block.dirt.blockID);
		world.setBlock(i + 1, j + 2, k + 4, Block.dirt.blockID);
		world.setBlock(i + 1, j + 2, k + 5, Block.dirt.blockID);
		world.setBlock(i + 1, j + 2, k + 6, Block.dirt.blockID);
		world.setBlock(i + 1, j + 2, k + 7, Block.dirt.blockID);
		world.setBlock(i + 1, j + 2, k + 8, Block.dirt.blockID);
		world.setBlock(i + 1, j + 2, k + 9, Block.dirt.blockID);
		world.setBlock(i + 1, j + 2, k + 10, Block.dirt.blockID);
		world.setBlock(i + 1, j + 2, k + 11, Block.dirt.blockID);
		world.setBlock(i + 1, j + 2, k + 12, Block.dirt.blockID);
		world.setBlock(i + 1, j + 2, k + 13, Block.dirt.blockID);
		world.setBlock(i + 1, j + 2, k + 14, Block.dirt.blockID);
		world.setBlock(i + 1, j + 2, k + 15, Block.planks.blockID);
		world.setBlock(i + 1, j + 2, k + 16, Block.planks.blockID);
		world.setBlock(i + 1, j + 2, k + 17, Block.planks.blockID);
		world.setBlock(i + 1, j + 2, k + 18, Block.planks.blockID);
		world.setBlock(i + 1, j + 2, k + 19, Block.planks.blockID);
		world.setBlock(i + 1, j + 2, k + 20, Block.planks.blockID);
		world.setBlock(i + 1, j + 2, k + 21, Block.planks.blockID);
		world.setBlock(i + 1, j + 2, k + 22, Block.planks.blockID);
		world.setBlock(i + 1, j + 2, k + 23, Block.planks.blockID);
		world.setBlock(i + 1, j + 2, k + 24, Block.planks.blockID);
		world.setBlock(i + 1, j + 2, k + 25, Block.planks.blockID);
		world.setBlock(i + 1, j + 2, k + 26, Block.planks.blockID);
		world.setBlock(i + 1, j + 2, k + 27, Block.planks.blockID);
		world.setBlock(i + 1, j + 2, k + 28, Block.planks.blockID);
		world.setBlock(i + 1, j + 2, k + 29, Block.planks.blockID);
		world.setBlock(i + 1, j + 2, k + 30, Block.planks.blockID);
		world.setBlock(i + 1, j + 2, k + 31, Block.planks.blockID);
		world.setBlock(i + 1, j + 2, k + 32, Block.planks.blockID);
		world.setBlock(i + 1, j + 2, k + 33, Block.planks.blockID);
		world.setBlock(i + 1, j + 2, k + 34, Block.planks.blockID);
		world.setBlock(i + 1, j + 2, k + 35, Block.planks.blockID);
		world.setBlock(i + 1, j + 2, k + 36, Block.planks.blockID);
		world.setBlock(i + 1, j + 2, k + 37, Block.planks.blockID);
		world.setBlock(i + 1, j + 2, k + 38, Block.planks.blockID);
		world.setBlock(i + 1, j + 2, k + 39, Block.planks.blockID);
		world.setBlock(i + 1, j + 2, k + 40, Block.planks.blockID);
		world.setBlock(i + 1, j + 2, k + 41, Block.planks.blockID);
		world.setBlock(i + 1, j + 2, k + 42, Block.planks.blockID);
		world.setBlock(i + 1, j + 2, k + 43, Block.planks.blockID);
		world.setBlock(i + 1, j + 2, k + 44, Block.planks.blockID);
		world.setBlock(i + 1, j + 2, k + 45, Block.planks.blockID);
		world.setBlock(i + 1, j + 2, k + 46, Block.planks.blockID);
		world.setBlock(i + 1, j + 2, k + 47, Block.dirt.blockID);
		world.setBlock(i + 1, j + 2, k + 48, Block.dirt.blockID);
		world.setBlock(i + 1, j + 2, k + 49, Block.dirt.blockID);
		world.setBlock(i + 1, j + 2, k + 50, Block.dirt.blockID);
		world.setBlock(i + 1, j + 2, k + 51, Block.dirt.blockID);
		world.setBlock(i + 1, j + 2, k + 52, Block.dirt.blockID);
		world.setBlock(i + 1, j + 2, k + 53, Block.dirt.blockID);
		world.setBlock(i + 1, j + 2, k + 54, Block.dirt.blockID);
		world.setBlock(i + 1, j + 2, k + 55, Block.dirt.blockID);
		world.setBlock(i + 1, j + 2, k + 56, Block.dirt.blockID);
		world.setBlock(i + 1, j + 2, k + 57, Block.dirt.blockID);
		world.setBlock(i + 1, j + 2, k + 58, Block.dirt.blockID);
		world.setBlock(i + 1, j + 2, k + 59, Block.dirt.blockID);
		world.setBlock(i + 1, j + 2, k + 60, Block.dirt.blockID);
		world.setBlock(i + 1, j + 2, k + 61, Block.dirt.blockID);
		world.setBlock(i + 1, j + 2, k + 62, Block.dirt.blockID);
		world.setBlock(i + 1, j + 2, k + 63, Block.dirt.blockID);
		world.setBlock(i + 1, j + 2, k + 64, Block.dirt.blockID);
		world.setBlock(i + 1, j + 2, k + 65, Block.dirt.blockID);
		world.setBlock(i + 1, j + 2, k + 66, Block.dirt.blockID);
		world.setBlock(i + 1, j + 2, k + 67, Block.dirt.blockID);
		world.setBlock(i + 1, j + 2, k + 68, Block.dirt.blockID);
		world.setBlock(i + 1, j + 2, k + 69, Block.dirt.blockID);
		world.setBlock(i + 1, j + 3, k + 0, Block.grass.blockID);
		world.setBlock(i + 1, j + 3, k + 1, Block.grass.blockID);
		world.setBlock(i + 1, j + 3, k + 2, Block.grass.blockID);
		world.setBlock(i + 1, j + 3, k + 3, Block.grass.blockID);
		world.setBlock(i + 1, j + 3, k + 4, Block.grass.blockID);
		world.setBlock(i + 1, j + 3, k + 5, Block.grass.blockID);
		world.setBlock(i + 1, j + 3, k + 6, Block.grass.blockID);
		world.setBlock(i + 1, j + 3, k + 7, Block.grass.blockID);
		world.setBlock(i + 1, j + 3, k + 8, Block.grass.blockID);
		world.setBlock(i + 1, j + 3, k + 9, Block.grass.blockID);
		world.setBlock(i + 1, j + 3, k + 10, Block.grass.blockID);
		world.setBlock(i + 1, j + 3, k + 11, Block.grass.blockID);
		world.setBlock(i + 1, j + 3, k + 12, Block.grass.blockID);
		world.setBlock(i + 1, j + 3, k + 13, Block.planks.blockID);
		world.setBlock(i + 1, j + 3, k + 14, Block.planks.blockID);
		world.setBlock(i + 1, j + 3, k + 15, Block.planks.blockID);
		world.setBlock(i + 1, j + 3, k + 16, Block.planks.blockID);
		world.setBlock(i + 1, j + 3, k + 17, Block.planks.blockID);
		world.setBlock(i + 1, j + 3, k + 18, Block.planks.blockID);
		world.setBlock(i + 1, j + 3, k + 19, Block.planks.blockID);
		world.setBlock(i + 1, j + 3, k + 20, Block.planks.blockID);
		world.setBlock(i + 1, j + 3, k + 21, Block.planks.blockID);
		world.setBlock(i + 1, j + 3, k + 22, Block.planks.blockID);
		world.setBlock(i + 1, j + 3, k + 23, Block.planks.blockID);
		world.setBlock(i + 1, j + 3, k + 24, Block.planks.blockID);
		world.setBlock(i + 1, j + 3, k + 25, Block.planks.blockID);
		world.setBlock(i + 1, j + 3, k + 26, Block.planks.blockID);
		world.setBlock(i + 1, j + 3, k + 27, Block.planks.blockID);
		world.setBlock(i + 1, j + 3, k + 28, Block.planks.blockID);
		world.setBlock(i + 1, j + 3, k + 29, Block.planks.blockID);
		world.setBlock(i + 1, j + 3, k + 30, Block.planks.blockID);
		world.setBlock(i + 1, j + 3, k + 31, Block.planks.blockID);
		world.setBlock(i + 1, j + 3, k + 32, Block.planks.blockID);
		world.setBlock(i + 1, j + 3, k + 33, Block.planks.blockID);
		world.setBlock(i + 1, j + 3, k + 34, Block.planks.blockID);
		world.setBlock(i + 1, j + 3, k + 35, Block.planks.blockID);
		world.setBlock(i + 1, j + 3, k + 36, Block.planks.blockID);
		world.setBlock(i + 1, j + 3, k + 37, Block.planks.blockID);
		world.setBlock(i + 1, j + 3, k + 38, Block.planks.blockID);
		world.setBlock(i + 1, j + 3, k + 39, Block.planks.blockID);
		world.setBlock(i + 1, j + 3, k + 40, Block.planks.blockID);
		world.setBlock(i + 1, j + 3, k + 41, Block.planks.blockID);
		world.setBlock(i + 1, j + 3, k + 42, Block.planks.blockID);
		world.setBlock(i + 1, j + 3, k + 43, Block.planks.blockID);
		world.setBlock(i + 1, j + 3, k + 44, Block.planks.blockID);
		world.setBlock(i + 1, j + 3, k + 45, Block.planks.blockID);
		world.setBlock(i + 1, j + 3, k + 46, Block.planks.blockID);
		world.setBlock(i + 1, j + 3, k + 47, Block.planks.blockID);
		world.setBlock(i + 1, j + 3, k + 48, Block.grass.blockID);
		world.setBlock(i + 1, j + 3, k + 49, Block.grass.blockID);
		world.setBlock(i + 1, j + 3, k + 50, Block.grass.blockID);
		world.setBlock(i + 1, j + 3, k + 51, Block.grass.blockID);
		world.setBlock(i + 1, j + 3, k + 52, Block.grass.blockID);
		world.setBlock(i + 1, j + 3, k + 53, Block.grass.blockID);
		world.setBlock(i + 1, j + 3, k + 54, Block.grass.blockID);
		world.setBlock(i + 1, j + 3, k + 55, Block.grass.blockID);
		world.setBlock(i + 1, j + 3, k + 56, Block.grass.blockID);
		world.setBlock(i + 1, j + 3, k + 57, Block.grass.blockID);
		world.setBlock(i + 1, j + 3, k + 58, Block.grass.blockID);
		world.setBlock(i + 1, j + 3, k + 59, Block.grass.blockID);
		world.setBlock(i + 1, j + 3, k + 60, Block.grass.blockID);
		world.setBlock(i + 1, j + 3, k + 61, Block.grass.blockID);
		world.setBlock(i + 1, j + 3, k + 62, Block.grass.blockID);
		world.setBlock(i + 1, j + 3, k + 63, Block.grass.blockID);
		world.setBlock(i + 1, j + 3, k + 64, Block.grass.blockID);
		world.setBlock(i + 1, j + 3, k + 65, Block.grass.blockID);
		world.setBlock(i + 1, j + 3, k + 66, Block.grass.blockID);
		world.setBlock(i + 1, j + 3, k + 67, Block.grass.blockID);
		world.setBlock(i + 1, j + 3, k + 68, Block.grass.blockID);
		world.setBlock(i + 1, j + 3, k + 69, Block.grass.blockID);
		world.setBlock(i + 1, j + 4, k + 12, Block.planks.blockID);
		world.setBlock(i + 1, j + 4, k + 13, Block.planks.blockID);
		world.setBlock(i + 1, j + 4, k + 14, Block.planks.blockID);
		world.setBlock(i + 1, j + 4, k + 15, Block.planks.blockID);
		world.setBlock(i + 1, j + 4, k + 16, Block.planks.blockID);
		world.setBlock(i + 1, j + 4, k + 17, Block.planks.blockID);
		world.setBlock(i + 1, j + 4, k + 18, Block.planks.blockID);
		world.setBlock(i + 1, j + 4, k + 19, Block.planks.blockID);
		world.setBlock(i + 1, j + 4, k + 46, Block.planks.blockID);
		world.setBlock(i + 1, j + 4, k + 47, Block.planks.blockID);
		world.setBlock(i + 1, j + 4, k + 48, Block.planks.blockID);
		world.setBlock(i + 1, j + 5, k + 11, Block.planks.blockID);
		world.setBlock(i + 1, j + 5, k + 12, Block.planks.blockID);
		world.setBlock(i + 1, j + 5, k + 13, Block.planks.blockID);
		world.setBlock(i + 1, j + 5, k + 14, Block.planks.blockID);
		world.setBlock(i + 1, j + 5, k + 15, Block.planks.blockID);
		world.setBlock(i + 1, j + 5, k + 16, Block.planks.blockID);
		world.setBlock(i + 1, j + 5, k + 17, Block.planks.blockID);
		world.setBlock(i + 1, j + 5, k + 18, Block.planks.blockID);
		world.setBlock(i + 1, j + 5, k + 46, Block.planks.blockID);
		world.setBlock(i + 1, j + 5, k + 48, Block.planks.blockID);
		world.setBlock(i + 1, j + 5, k + 49, Block.planks.blockID);
		world.setBlockAndMetadata(i + 1, j + 6, k + 11, Block.wood.blockID, 3);
		world.setBlockAndMetadata(i + 1, j + 6, k + 12, Block.wood.blockID, 3);
		world.setBlockAndMetadata(i + 1, j + 6, k + 13, Block.wood.blockID, 3);
		world.setBlockAndMetadata(i + 1, j + 6, k + 14, Block.wood.blockID, 3);
		world.setBlockAndMetadata(i + 1, j + 6, k + 15, Block.wood.blockID, 3);
		world.setBlockAndMetadata(i + 1, j + 6, k + 16, Block.wood.blockID, 3);
		world.setBlockAndMetadata(i + 1, j + 6, k + 17, Block.wood.blockID, 3);
		world.setBlock(i + 1, j + 6, k + 22, Block.planks.blockID);
		world.setBlock(i + 1, j + 6, k + 23, Block.planks.blockID);
		world.setBlock(i + 1, j + 6, k + 24, Block.planks.blockID);
		world.setBlock(i + 1, j + 6, k + 25, Block.planks.blockID);
		world.setBlock(i + 1, j + 6, k + 26, Block.planks.blockID);
		world.setBlock(i + 1, j + 6, k + 27, Block.planks.blockID);
		world.setBlock(i + 1, j + 6, k + 28, Block.planks.blockID);
		world.setBlock(i + 1, j + 6, k + 29, Block.planks.blockID);
		world.setBlock(i + 1, j + 6, k + 30, Block.planks.blockID);
		world.setBlock(i + 1, j + 6, k + 31, Block.planks.blockID);
		world.setBlock(i + 1, j + 6, k + 32, Block.planks.blockID);
		world.setBlock(i + 1, j + 6, k + 33, Block.planks.blockID);
		world.setBlock(i + 1, j + 6, k + 34, Block.planks.blockID);
		world.setBlock(i + 1, j + 6, k + 35, Block.planks.blockID);
		world.setBlock(i + 1, j + 6, k + 36, Block.planks.blockID);
		world.setBlock(i + 1, j + 6, k + 37, Block.planks.blockID);
		world.setBlock(i + 1, j + 6, k + 38, Block.planks.blockID);
		world.setBlock(i + 1, j + 6, k + 39, Block.planks.blockID);
		world.setBlock(i + 1, j + 6, k + 40, Block.planks.blockID);
		world.setBlock(i + 1, j + 6, k + 41, Block.planks.blockID);
		world.setBlock(i + 1, j + 6, k + 42, Block.planks.blockID);
		world.setBlock(i + 1, j + 6, k + 43, Block.planks.blockID);
		world.setBlock(i + 1, j + 6, k + 44, Block.planks.blockID);
		world.setBlock(i + 1, j + 6, k + 45, Block.planks.blockID);
		world.setBlock(i + 1, j + 6, k + 46, Block.planks.blockID);
		world.setBlock(i + 1, j + 6, k + 47, Block.planks.blockID);
		world.setBlockAndMetadata(i + 1, j + 6, k + 48, Block.wood.blockID, 3);
		world.setBlockAndMetadata(i + 1, j + 6, k + 49, Block.wood.blockID, 3);
		world.setBlockAndMetadata(i + 1, j + 6, k + 50, Block.wood.blockID, 3);
		world.setBlock(i + 1, j + 7, k + 10, Block.planks.blockID);
		world.setBlock(i + 1, j + 7, k + 11, Block.planks.blockID);
		world.setBlock(i + 1, j + 7, k + 12, Block.planks.blockID);
		world.setBlock(i + 1, j + 7, k + 13, Block.planks.blockID);
		world.setBlock(i + 1, j + 7, k + 14, Block.planks.blockID);
		world.setBlock(i + 1, j + 7, k + 15, Block.planks.blockID);
		world.setBlock(i + 1, j + 7, k + 16, Block.planks.blockID);
		world.setBlock(i + 1, j + 7, k + 21, Block.planks.blockID);
		world.setBlock(i + 1, j + 7, k + 22, Block.planks.blockID);
		world.setBlock(i + 1, j + 7, k + 46, Block.planks.blockID);
		world.setBlock(i + 1, j + 7, k + 47, Block.planks.blockID);
		world.setBlock(i + 1, j + 7, k + 48, Block.planks.blockID);
		world.setBlock(i + 1, j + 7, k + 49, Block.planks.blockID);
		world.setBlock(i + 1, j + 7, k + 50, Block.planks.blockID);
		world.setBlock(i + 1, j + 8, k + 10, Block.planks.blockID);
		world.setBlock(i + 1, j + 8, k + 11, Block.planks.blockID);
		world.setBlock(i + 1, j + 8, k + 12, Block.planks.blockID);
		world.setBlock(i + 1, j + 8, k + 13, Block.planks.blockID);
		world.setBlock(i + 1, j + 8, k + 14, Block.planks.blockID);
		world.setBlock(i + 1, j + 8, k + 15, Block.planks.blockID);
		world.setBlock(i + 1, j + 8, k + 16, Block.planks.blockID);
		world.setBlock(i + 1, j + 8, k + 20, Block.planks.blockID);
		world.setBlock(i + 1, j + 8, k + 21, Block.planks.blockID);
		world.setBlock(i + 1, j + 8, k + 22, Block.planks.blockID);
		world.setBlock(i + 1, j + 8, k + 46, Block.planks.blockID);
		world.setBlock(i + 1, j + 8, k + 47, Block.planks.blockID);
		world.setBlock(i + 1, j + 8, k + 48, Block.planks.blockID);
		world.setBlock(i + 1, j + 8, k + 49, Block.planks.blockID);
		world.setBlockAndMetadata(i + 1, j + 9, k + 3, Block.wood.blockID, 3);
		world.setBlockAndMetadata(i + 1, j + 9, k + 4, Block.wood.blockID, 3);
		world.setBlockAndMetadata(i + 1, j + 9, k + 5, Block.wood.blockID, 3);
		world.setBlockAndMetadata(i + 1, j + 9, k + 6, Block.wood.blockID, 3);
		world.setBlockAndMetadata(i + 1, j + 9, k + 7, Block.wood.blockID, 3);
		world.setBlockAndMetadata(i + 1, j + 9, k + 8, Block.wood.blockID, 3);
		world.setBlockAndMetadata(i + 1, j + 9, k + 9, Block.wood.blockID, 3);
		world.setBlockAndMetadata(i + 1, j + 9, k + 10, Block.wood.blockID, 3);
		world.setBlockAndMetadata(i + 1, j + 9, k + 11, Block.wood.blockID, 3);
		world.setBlockAndMetadata(i + 1, j + 9, k + 12, Block.wood.blockID, 3);
		world.setBlockAndMetadata(i + 1, j + 9, k + 13, Block.wood.blockID, 3);
		world.setBlockAndMetadata(i + 1, j + 9, k + 14, Block.wood.blockID, 3);
		world.setBlockAndMetadata(i + 1, j + 9, k + 15, Block.wood.blockID, 3);
		world.setBlockAndMetadata(i + 1, j + 9, k + 16, Block.wood.blockID, 3);
		world.setBlockAndMetadata(i + 1, j + 9, k + 17, Block.wood.blockID, 3);
		world.setBlockAndMetadata(i + 1, j + 9, k + 18, Block.wood.blockID, 3);
		world.setBlockAndMetadata(i + 1, j + 9, k + 19, Block.wood.blockID, 3);
		world.setBlockAndMetadata(i + 1, j + 9, k + 20, Block.wood.blockID, 3);
		world.setBlockAndMetadata(i + 1, j + 9, k + 21, Block.wood.blockID, 3);
		world.setBlockAndMetadata(i + 1, j + 9, k + 22, Block.wood.blockID, 3);
		world.setBlockAndMetadata(i + 1, j + 9, k + 23, Block.wood.blockID, 3);
		world.setBlockAndMetadata(i + 1, j + 9, k + 24, Block.wood.blockID, 3);
		world.setBlockAndMetadata(i + 1, j + 9, k + 25, Block.wood.blockID, 3);
		world.setBlockAndMetadata(i + 1, j + 9, k + 26, Block.wood.blockID, 3);
		world.setBlockAndMetadata(i + 1, j + 9, k + 27, Block.wood.blockID, 3);
		world.setBlockAndMetadata(i + 1, j + 9, k + 28, Block.wood.blockID, 3);
		world.setBlockAndMetadata(i + 1, j + 9, k + 29, Block.wood.blockID, 3);
		world.setBlockAndMetadata(i + 1, j + 9, k + 30, Block.wood.blockID, 3);
		world.setBlockAndMetadata(i + 1, j + 9, k + 31, Block.wood.blockID, 3);
		world.setBlockAndMetadata(i + 1, j + 9, k + 32, Block.wood.blockID, 3);
		world.setBlockAndMetadata(i + 1, j + 9, k + 33, Block.wood.blockID, 3);
		world.setBlockAndMetadata(i + 1, j + 9, k + 34, Block.wood.blockID, 3);
		world.setBlockAndMetadata(i + 1, j + 9, k + 35, Block.wood.blockID, 3);
		world.setBlockAndMetadata(i + 1, j + 9, k + 36, Block.wood.blockID, 3);
		world.setBlockAndMetadata(i + 1, j + 9, k + 37, Block.wood.blockID, 3);
		world.setBlockAndMetadata(i + 1, j + 9, k + 38, Block.wood.blockID, 3);
		world.setBlockAndMetadata(i + 1, j + 9, k + 39, Block.wood.blockID, 3);
		world.setBlockAndMetadata(i + 1, j + 9, k + 40, Block.wood.blockID, 3);
		world.setBlockAndMetadata(i + 1, j + 9, k + 41, Block.wood.blockID, 3);
		world.setBlockAndMetadata(i + 1, j + 9, k + 42, Block.wood.blockID, 3);
		world.setBlockAndMetadata(i + 1, j + 9, k + 43, Block.wood.blockID, 3);
		world.setBlockAndMetadata(i + 1, j + 9, k + 44, Block.wood.blockID, 3);
		world.setBlockAndMetadata(i + 1, j + 9, k + 45, Block.wood.blockID, 3);
		world.setBlockAndMetadata(i + 1, j + 9, k + 46, Block.wood.blockID, 3);
		world.setBlock(i + 1, j + 10, k + 2, Block.planks.blockID);
		world.setBlock(i + 1, j + 10, k + 10, Block.planks.blockID);
		world.setBlock(i + 1, j + 10, k + 11, Block.planks.blockID);
		world.setBlock(i + 1, j + 10, k + 12, Block.planks.blockID);
		world.setBlock(i + 1, j + 10, k + 13, Block.planks.blockID);
		world.setBlock(i + 1, j + 10, k + 14, Block.planks.blockID);
		world.setBlock(i + 1, j + 10, k + 15, Block.planks.blockID);
		world.setBlock(i + 1, j + 10, k + 16, Block.planks.blockID);
		world.setBlock(i + 1, j + 10, k + 17, Block.planks.blockID);
		world.setBlock(i + 1, j + 10, k + 18, Block.planks.blockID);
		world.setBlock(i + 1, j + 10, k + 19, Block.planks.blockID);
		world.setBlock(i + 1, j + 10, k + 20, Block.planks.blockID);
		world.setBlock(i + 1, j + 10, k + 21, Block.planks.blockID);
		world.setBlock(i + 1, j + 10, k + 22, Block.planks.blockID);
		world.setBlock(i + 1, j + 10, k + 23, Block.planks.blockID);
		world.setBlock(i + 1, j + 10, k + 24, Block.planks.blockID);
		world.setBlock(i + 1, j + 10, k + 25, Block.planks.blockID);
		world.setBlock(i + 1, j + 10, k + 26, Block.planks.blockID);
		world.setBlock(i + 1, j + 10, k + 27, Block.planks.blockID);
		world.setBlock(i + 1, j + 10, k + 28, Block.planks.blockID);
		world.setBlock(i + 1, j + 10, k + 29, Block.planks.blockID);
		world.setBlock(i + 1, j + 10, k + 30, Block.planks.blockID);
		world.setBlock(i + 1, j + 10, k + 31, Block.planks.blockID);
		world.setBlock(i + 1, j + 10, k + 32, Block.planks.blockID);
		world.setBlock(i + 1, j + 10, k + 33, Block.planks.blockID);
		world.setBlock(i + 1, j + 10, k + 34, Block.planks.blockID);
		world.setBlock(i + 1, j + 10, k + 35, Block.planks.blockID);
		world.setBlock(i + 1, j + 10, k + 36, Block.planks.blockID);
		world.setBlock(i + 1, j + 10, k + 37, Block.planks.blockID);
		world.setBlock(i + 1, j + 10, k + 38, Block.planks.blockID);
		world.setBlock(i + 1, j + 10, k + 39, Block.planks.blockID);
		world.setBlock(i + 1, j + 10, k + 40, Block.planks.blockID);
		world.setBlock(i + 1, j + 10, k + 41, Block.planks.blockID);
		world.setBlock(i + 1, j + 10, k + 42, Block.planks.blockID);
		world.setBlock(i + 1, j + 10, k + 43, Block.planks.blockID);
		world.setBlock(i + 1, j + 10, k + 44, Block.planks.blockID);
		world.setBlock(i + 1, j + 10, k + 45, Block.planks.blockID);
		world.setBlock(i + 1, j + 10, k + 46, Block.planks.blockID);
		world.setBlock(i + 1, j + 11, k + 2, Block.planks.blockID);
		world.setBlock(i + 1, j + 11, k + 10, Block.planks.blockID);
		world.setBlock(i + 1, j + 11, k + 11, Block.planks.blockID);
		world.setBlock(i + 1, j + 11, k + 12, Block.planks.blockID);
		world.setBlock(i + 1, j + 11, k + 13, Block.planks.blockID);
		world.setBlock(i + 1, j + 11, k + 14, Block.planks.blockID);
		world.setBlock(i + 1, j + 11, k + 15, Block.planks.blockID);
		world.setBlock(i + 1, j + 11, k + 16, Block.planks.blockID);
		world.setBlock(i + 1, j + 11, k + 17, Block.planks.blockID);
		world.setBlock(i + 1, j + 11, k + 18, Block.planks.blockID);
		world.setBlock(i + 1, j + 11, k + 19, Block.planks.blockID);
		world.setBlock(i + 1, j + 11, k + 20, Block.planks.blockID);
		world.setBlock(i + 1, j + 11, k + 21, Block.planks.blockID);
		world.setBlock(i + 1, j + 11, k + 22, Block.planks.blockID);
		world.setBlock(i + 1, j + 11, k + 23, Block.planks.blockID);
		world.setBlock(i + 1, j + 11, k + 24, Block.planks.blockID);
		world.setBlock(i + 1, j + 11, k + 25, Block.planks.blockID);
		world.setBlock(i + 1, j + 11, k + 26, Block.planks.blockID);
		world.setBlock(i + 1, j + 11, k + 27, Block.planks.blockID);
		world.setBlock(i + 1, j + 11, k + 28, Block.planks.blockID);
		world.setBlock(i + 1, j + 11, k + 29, Block.planks.blockID);
		world.setBlockAndMetadata(i + 1, j + 12, k + 3, Block.wood.blockID, 3);
		world.setBlockAndMetadata(i + 1, j + 12, k + 4, Block.wood.blockID, 3);
		world.setBlockAndMetadata(i + 1, j + 12, k + 5, Block.wood.blockID, 3);
		world.setBlockAndMetadata(i + 1, j + 12, k + 6, Block.wood.blockID, 3);
		world.setBlockAndMetadata(i + 1, j + 12, k + 7, Block.wood.blockID, 3);
		world.setBlockAndMetadata(i + 1, j + 12, k + 8, Block.wood.blockID, 3);
		world.setBlockAndMetadata(i + 1, j + 12, k + 9, Block.wood.blockID, 3);
		world.setBlockAndMetadata(i + 1, j + 12, k + 10, Block.wood.blockID, 3);
		world.setBlockAndMetadata(i + 1, j + 12, k + 11, Block.wood.blockID, 3);
		world.setBlockAndMetadata(i + 1, j + 12, k + 12, Block.wood.blockID, 3);
		world.setBlockAndMetadata(i + 1, j + 12, k + 13, Block.wood.blockID, 3);
		world.setBlockAndMetadata(i + 1, j + 12, k + 14, Block.wood.blockID, 3);
		world.setBlockAndMetadata(i + 1, j + 12, k + 15, Block.wood.blockID, 3);
		world.setBlockAndMetadata(i + 1, j + 12, k + 16, Block.wood.blockID, 3);
		world.setBlockAndMetadata(i + 1, j + 12, k + 17, Block.wood.blockID, 3);
		world.setBlockAndMetadata(i + 1, j + 12, k + 18, Block.wood.blockID, 3);
		world.setBlockAndMetadata(i + 1, j + 12, k + 19, Block.wood.blockID, 3);
		world.setBlockAndMetadata(i + 1, j + 12, k + 20, Block.wood.blockID, 3);
		world.setBlockAndMetadata(i + 1, j + 12, k + 21, Block.wood.blockID, 3);
		world.setBlockAndMetadata(i + 1, j + 12, k + 22, Block.wood.blockID, 3);
		world.setBlockAndMetadata(i + 1, j + 12, k + 23, Block.wood.blockID, 3);
		world.setBlockAndMetadata(i + 1, j + 12, k + 24, Block.wood.blockID, 3);
		world.setBlockAndMetadata(i + 1, j + 12, k + 25, Block.wood.blockID, 3);
		world.setBlockAndMetadata(i + 1, j + 12, k + 26, Block.wood.blockID, 3);
		world.setBlock(i + 1, j + 13, k + 10, Block.planks.blockID);
		world.setBlock(i + 1, j + 13, k + 11, Block.planks.blockID);
		world.setBlock(i + 1, j + 13, k + 12, Block.planks.blockID);
		world.setBlock(i + 1, j + 13, k + 13, Block.planks.blockID);
		world.setBlock(i + 1, j + 13, k + 14, Block.planks.blockID);
		world.setBlock(i + 1, j + 13, k + 15, Block.planks.blockID);
		world.setBlock(i + 1, j + 13, k + 16, Block.planks.blockID);
		world.setBlock(i + 1, j + 13, k + 17, Block.planks.blockID);
		world.setBlock(i + 1, j + 13, k + 18, Block.planks.blockID);
		world.setBlock(i + 1, j + 13, k + 19, Block.planks.blockID);
		world.setBlock(i + 1, j + 13, k + 20, Block.planks.blockID);
		world.setBlock(i + 1, j + 13, k + 21, Block.planks.blockID);
		world.setBlock(i + 1, j + 13, k + 22, Block.planks.blockID);
		world.setBlock(i + 1, j + 14, k + 10, Block.planks.blockID);
		world.setBlock(i + 1, j + 14, k + 11, Block.planks.blockID);
		world.setBlock(i + 1, j + 14, k + 12, Block.planks.blockID);
		world.setBlock(i + 1, j + 14, k + 13, Block.planks.blockID);
		world.setBlock(i + 1, j + 14, k + 14, Block.planks.blockID);
		world.setBlock(i + 1, j + 14, k + 15, Block.planks.blockID);
		world.setBlock(i + 1, j + 14, k + 16, Block.planks.blockID);
		world.setBlock(i + 1, j + 14, k + 17, Block.planks.blockID);
		world.setBlock(i + 2, j + 0, k + 0, Block.bedrock.blockID);
		world.setBlock(i + 2, j + 0, k + 1, Block.bedrock.blockID);
		world.setBlock(i + 2, j + 0, k + 2, Block.bedrock.blockID);
		world.setBlock(i + 2, j + 0, k + 3, Block.bedrock.blockID);
		world.setBlock(i + 2, j + 0, k + 4, Block.bedrock.blockID);
		world.setBlock(i + 2, j + 0, k + 5, Block.bedrock.blockID);
		world.setBlock(i + 2, j + 0, k + 6, Block.bedrock.blockID);
		world.setBlock(i + 2, j + 0, k + 7, Block.bedrock.blockID);
		world.setBlock(i + 2, j + 0, k + 8, Block.bedrock.blockID);
		world.setBlock(i + 2, j + 0, k + 9, Block.bedrock.blockID);
		world.setBlock(i + 2, j + 0, k + 10, Block.bedrock.blockID);
		world.setBlock(i + 2, j + 0, k + 11, Block.bedrock.blockID);
		world.setBlock(i + 2, j + 0, k + 12, Block.bedrock.blockID);
		world.setBlock(i + 2, j + 0, k + 13, Block.bedrock.blockID);
		world.setBlock(i + 2, j + 0, k + 14, Block.bedrock.blockID);
		world.setBlock(i + 2, j + 0, k + 15, Block.planks.blockID);
		world.setBlock(i + 2, j + 0, k + 16, Block.planks.blockID);
		world.setBlock(i + 2, j + 0, k + 17, Block.planks.blockID);
		world.setBlock(i + 2, j + 0, k + 18, Block.planks.blockID);
		world.setBlock(i + 2, j + 0, k + 19, Block.planks.blockID);
		world.setBlock(i + 2, j + 0, k + 20, Block.planks.blockID);
		world.setBlock(i + 2, j + 0, k + 21, Block.planks.blockID);
		world.setBlock(i + 2, j + 0, k + 22, Block.planks.blockID);
		world.setBlock(i + 2, j + 0, k + 23, Block.planks.blockID);
		world.setBlock(i + 2, j + 0, k + 24, Block.planks.blockID);
		world.setBlock(i + 2, j + 0, k + 25, Block.planks.blockID);
		world.setBlock(i + 2, j + 0, k + 26, Block.planks.blockID);
		world.setBlock(i + 2, j + 0, k + 27, Block.planks.blockID);
		world.setBlock(i + 2, j + 0, k + 28, Block.planks.blockID);
		world.setBlock(i + 2, j + 0, k + 29, Block.planks.blockID);
		world.setBlock(i + 2, j + 0, k + 30, Block.planks.blockID);
		world.setBlock(i + 2, j + 0, k + 31, Block.planks.blockID);
		world.setBlock(i + 2, j + 0, k + 32, Block.planks.blockID);
		world.setBlock(i + 2, j + 0, k + 33, Block.planks.blockID);
		world.setBlock(i + 2, j + 0, k + 34, Block.planks.blockID);
		world.setBlock(i + 2, j + 0, k + 35, Block.planks.blockID);
		world.setBlock(i + 2, j + 0, k + 36, Block.planks.blockID);
		world.setBlock(i + 2, j + 0, k + 37, Block.planks.blockID);
		world.setBlock(i + 2, j + 0, k + 38, Block.planks.blockID);
		world.setBlock(i + 2, j + 0, k + 39, Block.planks.blockID);
		world.setBlock(i + 2, j + 0, k + 40, Block.planks.blockID);
		world.setBlock(i + 2, j + 0, k + 41, Block.planks.blockID);
		world.setBlock(i + 2, j + 0, k + 42, Block.planks.blockID);
		world.setBlock(i + 2, j + 0, k + 43, Block.planks.blockID);
		world.setBlock(i + 2, j + 0, k + 44, Block.planks.blockID);
		world.setBlock(i + 2, j + 0, k + 45, Block.bedrock.blockID);
		world.setBlock(i + 2, j + 0, k + 46, Block.bedrock.blockID);
		world.setBlock(i + 2, j + 0, k + 47, Block.bedrock.blockID);
		world.setBlock(i + 2, j + 0, k + 48, Block.bedrock.blockID);
		world.setBlock(i + 2, j + 0, k + 49, Block.bedrock.blockID);
		world.setBlock(i + 2, j + 0, k + 50, Block.bedrock.blockID);
		world.setBlock(i + 2, j + 0, k + 51, Block.bedrock.blockID);
		world.setBlock(i + 2, j + 0, k + 52, Block.bedrock.blockID);
		world.setBlock(i + 2, j + 0, k + 53, Block.bedrock.blockID);
		world.setBlock(i + 2, j + 0, k + 54, Block.bedrock.blockID);
		world.setBlock(i + 2, j + 0, k + 55, Block.bedrock.blockID);
		world.setBlock(i + 2, j + 0, k + 56, Block.bedrock.blockID);
		world.setBlock(i + 2, j + 0, k + 57, Block.bedrock.blockID);
		world.setBlock(i + 2, j + 0, k + 58, Block.bedrock.blockID);
		world.setBlock(i + 2, j + 0, k + 59, Block.bedrock.blockID);
		world.setBlock(i + 2, j + 0, k + 60, Block.bedrock.blockID);
		world.setBlock(i + 2, j + 0, k + 61, Block.bedrock.blockID);
		world.setBlock(i + 2, j + 0, k + 62, Block.bedrock.blockID);
		world.setBlock(i + 2, j + 0, k + 63, Block.bedrock.blockID);
		world.setBlock(i + 2, j + 0, k + 64, Block.bedrock.blockID);
		world.setBlock(i + 2, j + 0, k + 65, Block.bedrock.blockID);
		world.setBlock(i + 2, j + 0, k + 66, Block.bedrock.blockID);
		world.setBlock(i + 2, j + 0, k + 67, Block.bedrock.blockID);
		world.setBlock(i + 2, j + 0, k + 68, Block.bedrock.blockID);
		world.setBlock(i + 2, j + 0, k + 69, Block.bedrock.blockID);
		world.setBlock(i + 2, j + 1, k + 0, Block.dirt.blockID);
		world.setBlock(i + 2, j + 1, k + 1, Block.dirt.blockID);
		world.setBlock(i + 2, j + 1, k + 2, Block.dirt.blockID);
		world.setBlock(i + 2, j + 1, k + 3, Block.dirt.blockID);
		world.setBlock(i + 2, j + 1, k + 4, Block.dirt.blockID);
		world.setBlock(i + 2, j + 1, k + 5, Block.dirt.blockID);
		world.setBlock(i + 2, j + 1, k + 6, Block.dirt.blockID);
		world.setBlock(i + 2, j + 1, k + 7, Block.dirt.blockID);
		world.setBlock(i + 2, j + 1, k + 8, Block.dirt.blockID);
		world.setBlock(i + 2, j + 1, k + 9, Block.dirt.blockID);
		world.setBlock(i + 2, j + 1, k + 10, Block.dirt.blockID);
		world.setBlock(i + 2, j + 1, k + 11, Block.planks.blockID);
		world.setBlock(i + 2, j + 1, k + 12, Block.planks.blockID);
		world.setBlock(i + 2, j + 1, k + 13, Block.planks.blockID);
		world.setBlock(i + 2, j + 1, k + 14, Block.planks.blockID);
		world.setBlock(i + 2, j + 1, k + 15, Block.planks.blockID);
		world.setBlock(i + 2, j + 1, k + 16, Block.planks.blockID);
		world.setBlock(i + 2, j + 1, k + 17, Block.dirt.blockID);
		world.setBlock(i + 2, j + 1, k + 18, Block.dirt.blockID);
		world.setBlock(i + 2, j + 1, k + 19, Block.dirt.blockID);
		world.setBlock(i + 2, j + 1, k + 20, Block.planks.blockID);
		world.setBlock(i + 2, j + 1, k + 21, Block.planks.blockID);
		world.setBlock(i + 2, j + 1, k + 22, Block.dirt.blockID);
		world.setBlock(i + 2, j + 1, k + 23, Block.dirt.blockID);
		world.setBlock(i + 2, j + 1, k + 24, Block.dirt.blockID);
		world.setBlock(i + 2, j + 1, k + 25, Block.dirt.blockID);
		world.setBlock(i + 2, j + 1, k + 26, Block.dirt.blockID);
		world.setBlock(i + 2, j + 1, k + 27, Block.planks.blockID);
		world.setBlock(i + 2, j + 1, k + 28, Block.dirt.blockID);
		world.setBlock(i + 2, j + 1, k + 29, Block.dirt.blockID);
		world.setBlock(i + 2, j + 1, k + 30, Block.dirt.blockID);
		world.setBlock(i + 2, j + 1, k + 31, Block.dirt.blockID);
		world.setBlock(i + 2, j + 1, k + 32, Block.dirt.blockID);
		world.setBlock(i + 2, j + 1, k + 33, Block.planks.blockID);
		world.setBlock(i + 2, j + 1, k + 34, Block.dirt.blockID);
		world.setBlock(i + 2, j + 1, k + 35, Block.dirt.blockID);
		world.setBlock(i + 2, j + 1, k + 36, Block.dirt.blockID);
		world.setBlock(i + 2, j + 1, k + 37, Block.dirt.blockID);
		world.setBlock(i + 2, j + 1, k + 38, Block.dirt.blockID);
		world.setBlock(i + 2, j + 1, k + 39, Block.planks.blockID);
		world.setBlock(i + 2, j + 1, k + 40, Block.dirt.blockID);
		world.setBlock(i + 2, j + 1, k + 41, Block.dirt.blockID);
		world.setBlock(i + 2, j + 1, k + 42, Block.dirt.blockID);
		world.setBlock(i + 2, j + 1, k + 43, Block.dirt.blockID);
		world.setBlock(i + 2, j + 1, k + 44, Block.dirt.blockID);
		world.setBlock(i + 2, j + 1, k + 45, Block.planks.blockID);
		world.setBlock(i + 2, j + 1, k + 46, Block.planks.blockID);
		world.setBlock(i + 2, j + 1, k + 47, Block.dirt.blockID);
		world.setBlock(i + 2, j + 1, k + 48, Block.dirt.blockID);
		world.setBlock(i + 2, j + 1, k + 49, Block.dirt.blockID);
		world.setBlock(i + 2, j + 1, k + 50, Block.dirt.blockID);
		world.setBlock(i + 2, j + 1, k + 51, Block.dirt.blockID);
		world.setBlock(i + 2, j + 1, k + 52, Block.dirt.blockID);
		world.setBlock(i + 2, j + 1, k + 53, Block.dirt.blockID);
		world.setBlock(i + 2, j + 1, k + 54, Block.dirt.blockID);
		world.setBlock(i + 2, j + 1, k + 55, Block.dirt.blockID);
		world.setBlock(i + 2, j + 1, k + 56, Block.dirt.blockID);
		world.setBlock(i + 2, j + 1, k + 57, Block.dirt.blockID);
		world.setBlock(i + 2, j + 1, k + 58, Block.dirt.blockID);
		world.setBlock(i + 2, j + 1, k + 59, Block.dirt.blockID);
		world.setBlock(i + 2, j + 1, k + 60, Block.dirt.blockID);
		world.setBlock(i + 2, j + 1, k + 61, Block.dirt.blockID);
		world.setBlock(i + 2, j + 1, k + 62, Block.dirt.blockID);
		world.setBlock(i + 2, j + 1, k + 63, Block.dirt.blockID);
		world.setBlock(i + 2, j + 1, k + 64, Block.dirt.blockID);
		world.setBlock(i + 2, j + 1, k + 65, Block.dirt.blockID);
		world.setBlock(i + 2, j + 1, k + 66, Block.dirt.blockID);
		world.setBlock(i + 2, j + 1, k + 67, Block.dirt.blockID);
		world.setBlock(i + 2, j + 1, k + 68, Block.dirt.blockID);
		world.setBlock(i + 2, j + 1, k + 69, Block.dirt.blockID);
		world.setBlock(i + 2, j + 2, k + 0, Block.dirt.blockID);
		world.setBlock(i + 2, j + 2, k + 1, Block.dirt.blockID);
		world.setBlock(i + 2, j + 2, k + 2, Block.dirt.blockID);
		world.setBlock(i + 2, j + 2, k + 3, Block.dirt.blockID);
		world.setBlock(i + 2, j + 2, k + 4, Block.dirt.blockID);
		world.setBlock(i + 2, j + 2, k + 5, Block.dirt.blockID);
		world.setBlock(i + 2, j + 2, k + 6, Block.dirt.blockID);
		world.setBlock(i + 2, j + 2, k + 7, Block.dirt.blockID);
		world.setBlock(i + 2, j + 2, k + 8, Block.dirt.blockID);
		world.setBlock(i + 2, j + 2, k + 9, Block.planks.blockID);
		world.setBlock(i + 2, j + 2, k + 10, Block.planks.blockID);
		world.setBlock(i + 2, j + 2, k + 11, Block.planks.blockID);
		world.setBlock(i + 2, j + 2, k + 12, Block.planks.blockID);
		world.setBlock(i + 2, j + 2, k + 13, Block.planks.blockID);
		world.setBlock(i + 2, j + 2, k + 14, Block.planks.blockID);
		world.setBlock(i + 2, j + 2, k + 15, Block.planks.blockID);
		world.setBlock(i + 2, j + 2, k + 16, Block.planks.blockID);
		world.setBlock(i + 2, j + 2, k + 17, Block.dirt.blockID);
		world.setBlock(i + 2, j + 2, k + 18, Block.dirt.blockID);
		world.setBlock(i + 2, j + 2, k + 19, Block.dirt.blockID);
		world.setBlock(i + 2, j + 2, k + 20, Block.dirt.blockID);
		world.setBlock(i + 2, j + 2, k + 21, Block.planks.blockID);
		world.setBlock(i + 2, j + 2, k + 22, Block.dirt.blockID);
		world.setBlock(i + 2, j + 2, k + 23, Block.dirt.blockID);
		world.setBlock(i + 2, j + 2, k + 24, Block.dirt.blockID);
		world.setBlock(i + 2, j + 2, k + 25, Block.dirt.blockID);
		world.setBlock(i + 2, j + 2, k + 26, Block.dirt.blockID);
		world.setBlock(i + 2, j + 2, k + 27, Block.planks.blockID);
		world.setBlock(i + 2, j + 2, k + 28, Block.dirt.blockID);
		world.setBlock(i + 2, j + 2, k + 29, Block.dirt.blockID);
		world.setBlock(i + 2, j + 2, k + 30, Block.dirt.blockID);
		world.setBlock(i + 2, j + 2, k + 31, Block.dirt.blockID);
		world.setBlock(i + 2, j + 2, k + 32, Block.dirt.blockID);
		world.setBlock(i + 2, j + 2, k + 33, Block.planks.blockID);
		world.setBlock(i + 2, j + 2, k + 34, Block.dirt.blockID);
		world.setBlock(i + 2, j + 2, k + 35, Block.dirt.blockID);
		world.setBlock(i + 2, j + 2, k + 36, Block.dirt.blockID);
		world.setBlock(i + 2, j + 2, k + 37, Block.dirt.blockID);
		world.setBlock(i + 2, j + 2, k + 38, Block.dirt.blockID);
		world.setBlock(i + 2, j + 2, k + 39, Block.planks.blockID);
		world.setBlock(i + 2, j + 2, k + 40, Block.dirt.blockID);
		world.setBlock(i + 2, j + 2, k + 41, Block.dirt.blockID);
		world.setBlock(i + 2, j + 2, k + 42, Block.dirt.blockID);
		world.setBlock(i + 2, j + 2, k + 43, Block.dirt.blockID);
		world.setBlock(i + 2, j + 2, k + 44, Block.dirt.blockID);
		world.setBlock(i + 2, j + 2, k + 45, Block.planks.blockID);
		world.setBlock(i + 2, j + 2, k + 46, Block.dirt.blockID);
		world.setBlock(i + 2, j + 2, k + 47, Block.planks.blockID);
		world.setBlock(i + 2, j + 2, k + 48, Block.planks.blockID);
		world.setBlock(i + 2, j + 2, k + 49, Block.dirt.blockID);
		world.setBlock(i + 2, j + 2, k + 50, Block.dirt.blockID);
		world.setBlock(i + 2, j + 2, k + 51, Block.dirt.blockID);
		world.setBlock(i + 2, j + 2, k + 52, Block.dirt.blockID);
		world.setBlock(i + 2, j + 2, k + 53, Block.dirt.blockID);
		world.setBlock(i + 2, j + 2, k + 54, Block.dirt.blockID);
		world.setBlock(i + 2, j + 2, k + 55, Block.dirt.blockID);
		world.setBlock(i + 2, j + 2, k + 56, Block.dirt.blockID);
		world.setBlock(i + 2, j + 2, k + 57, Block.dirt.blockID);
		world.setBlock(i + 2, j + 2, k + 58, Block.dirt.blockID);
		world.setBlock(i + 2, j + 2, k + 59, Block.dirt.blockID);
		world.setBlock(i + 2, j + 2, k + 60, Block.dirt.blockID);
		world.setBlock(i + 2, j + 2, k + 61, Block.dirt.blockID);
		world.setBlock(i + 2, j + 2, k + 62, Block.dirt.blockID);
		world.setBlock(i + 2, j + 2, k + 63, Block.dirt.blockID);
		world.setBlock(i + 2, j + 2, k + 64, Block.dirt.blockID);
		world.setBlock(i + 2, j + 2, k + 65, Block.dirt.blockID);
		world.setBlock(i + 2, j + 2, k + 66, Block.dirt.blockID);
		world.setBlock(i + 2, j + 2, k + 67, Block.dirt.blockID);
		world.setBlock(i + 2, j + 2, k + 68, Block.dirt.blockID);
		world.setBlock(i + 2, j + 2, k + 69, Block.dirt.blockID);
		world.setBlock(i + 2, j + 3, k + 0, Block.grass.blockID);
		world.setBlock(i + 2, j + 3, k + 1, Block.grass.blockID);
		world.setBlock(i + 2, j + 3, k + 2, Block.grass.blockID);
		world.setBlock(i + 2, j + 3, k + 3, Block.grass.blockID);
		world.setBlock(i + 2, j + 3, k + 4, Block.grass.blockID);
		world.setBlock(i + 2, j + 3, k + 5, Block.grass.blockID);
		world.setBlock(i + 2, j + 3, k + 6, Block.grass.blockID);
		world.setBlock(i + 2, j + 3, k + 7, Block.planks.blockID);
		world.setBlock(i + 2, j + 3, k + 8, Block.planks.blockID);
		world.setBlock(i + 2, j + 3, k + 9, Block.planks.blockID);
		world.setBlock(i + 2, j + 3, k + 10, Block.planks.blockID);
		world.setBlock(i + 2, j + 3, k + 11, Block.planks.blockID);
		world.setBlock(i + 2, j + 3, k + 12, Block.planks.blockID);
		world.setBlock(i + 2, j + 3, k + 13, Block.planks.blockID);
		world.setBlock(i + 2, j + 3, k + 14, Block.planks.blockID);
		world.setBlock(i + 2, j + 3, k + 15, Block.planks.blockID);
		world.setBlock(i + 2, j + 3, k + 16, Block.planks.blockID);
		world.setBlock(i + 2, j + 3, k + 17, Block.planks.blockID);
		world.setBlock(i + 2, j + 3, k + 18, Block.grass.blockID);
		world.setBlock(i + 2, j + 3, k + 19, Block.grass.blockID);
		world.setBlock(i + 2, j + 3, k + 20, Block.grass.blockID);
		world.setBlock(i + 2, j + 3, k + 21, Block.grass.blockID);
		world.setBlock(i + 2, j + 3, k + 22, Block.planks.blockID);
		world.setBlock(i + 2, j + 3, k + 23, Block.planks.blockID);
		world.setBlock(i + 2, j + 3, k + 24, Block.planks.blockID);
		world.setBlock(i + 2, j + 3, k + 25, Block.planks.blockID);
		world.setBlock(i + 2, j + 3, k + 26, Block.planks.blockID);
		world.setBlock(i + 2, j + 3, k + 27, Block.planks.blockID);
		world.setBlock(i + 2, j + 3, k + 28, Block.planks.blockID);
		world.setBlock(i + 2, j + 3, k + 29, Block.planks.blockID);
		world.setBlock(i + 2, j + 3, k + 30, Block.planks.blockID);
		world.setBlock(i + 2, j + 3, k + 31, Block.planks.blockID);
		world.setBlock(i + 2, j + 3, k + 32, Block.planks.blockID);
		world.setBlock(i + 2, j + 3, k + 33, Block.planks.blockID);
		world.setBlock(i + 2, j + 3, k + 34, Block.planks.blockID);
		world.setBlock(i + 2, j + 3, k + 35, Block.planks.blockID);
		world.setBlock(i + 2, j + 3, k + 36, Block.planks.blockID);
		world.setBlock(i + 2, j + 3, k + 37, Block.planks.blockID);
		world.setBlock(i + 2, j + 3, k + 38, Block.planks.blockID);
		world.setBlock(i + 2, j + 3, k + 39, Block.planks.blockID);
		world.setBlock(i + 2, j + 3, k + 40, Block.planks.blockID);
		world.setBlock(i + 2, j + 3, k + 41, Block.planks.blockID);
		world.setBlock(i + 2, j + 3, k + 42, Block.planks.blockID);
		world.setBlock(i + 2, j + 3, k + 43, Block.planks.blockID);
		world.setBlock(i + 2, j + 3, k + 44, Block.planks.blockID);
		world.setBlock(i + 2, j + 3, k + 45, Block.planks.blockID);
		world.setBlock(i + 2, j + 3, k + 46, Block.planks.blockID);
		world.setBlock(i + 2, j + 3, k + 47, Block.planks.blockID);
		world.setBlock(i + 2, j + 3, k + 48, Block.planks.blockID);
		world.setBlock(i + 2, j + 3, k + 49, Block.planks.blockID);
		world.setBlock(i + 2, j + 3, k + 50, Block.grass.blockID);
		world.setBlock(i + 2, j + 3, k + 51, Block.grass.blockID);
		world.setBlock(i + 2, j + 3, k + 52, Block.grass.blockID);
		world.setBlock(i + 2, j + 3, k + 53, Block.grass.blockID);
		world.setBlock(i + 2, j + 3, k + 54, Block.grass.blockID);
		world.setBlock(i + 2, j + 3, k + 55, Block.grass.blockID);
		world.setBlock(i + 2, j + 3, k + 56, Block.grass.blockID);
		world.setBlock(i + 2, j + 3, k + 57, Block.grass.blockID);
		world.setBlock(i + 2, j + 3, k + 58, Block.grass.blockID);
		world.setBlock(i + 2, j + 3, k + 59, Block.grass.blockID);
		world.setBlock(i + 2, j + 3, k + 60, Block.grass.blockID);
		world.setBlock(i + 2, j + 3, k + 61, Block.grass.blockID);
		world.setBlock(i + 2, j + 3, k + 62, Block.grass.blockID);
		world.setBlock(i + 2, j + 3, k + 63, Block.grass.blockID);
		world.setBlock(i + 2, j + 3, k + 64, Block.grass.blockID);
		world.setBlock(i + 2, j + 3, k + 65, Block.grass.blockID);
		world.setBlock(i + 2, j + 3, k + 66, Block.grass.blockID);
		world.setBlock(i + 2, j + 3, k + 67, Block.grass.blockID);
		world.setBlock(i + 2, j + 3, k + 68, Block.grass.blockID);
		world.setBlock(i + 2, j + 3, k + 69, Block.grass.blockID);
		world.setBlock(i + 2, j + 4, k + 6, Block.planks.blockID);
		world.setBlock(i + 2, j + 4, k + 7, Block.planks.blockID);
		world.setBlock(i + 2, j + 4, k + 8, Block.planks.blockID);
		world.setBlock(i + 2, j + 4, k + 9, Block.planks.blockID);
		world.setBlock(i + 2, j + 4, k + 10, Block.planks.blockID);
		world.setBlock(i + 2, j + 4, k + 11, Block.planks.blockID);
		world.setBlock(i + 2, j + 4, k + 16, Block.planks.blockID);
		world.setBlock(i + 2, j + 4, k + 46, Block.planks.blockID);
		world.setBlock(i + 2, j + 4, k + 49, Block.planks.blockID);
		world.setBlock(i + 2, j + 5, k + 5, Block.planks.blockID);
		world.setBlock(i + 2, j + 5, k + 6, Block.planks.blockID);
		world.setBlock(i + 2, j + 5, k + 7, Block.planks.blockID);
		world.setBlock(i + 2, j + 5, k + 8, Block.planks.blockID);
		world.setBlock(i + 2, j + 5, k + 9, Block.planks.blockID);
		world.setBlock(i + 2, j + 5, k + 10, Block.planks.blockID);
		world.setBlock(i + 2, j + 5, k + 11, Block.planks.blockID);
		world.setBlock(i + 2, j + 5, k + 16, Block.planks.blockID);
		world.setBlock(i + 2, j + 5, k + 46, Block.planks.blockID);
		world.setBlock(i + 2, j + 5, k + 50, Block.planks.blockID);
		world.setBlockAndMetadata(i + 2, j + 6, k + 5, Block.wood.blockID, 3);
		world.setBlockAndMetadata(i + 2, j + 6, k + 6, Block.wood.blockID, 3);
		world.setBlockAndMetadata(i + 2, j + 6, k + 7, Block.wood.blockID, 3);
		world.setBlockAndMetadata(i + 2, j + 6, k + 8, Block.wood.blockID, 3);
		world.setBlockAndMetadata(i + 2, j + 6, k + 9, Block.wood.blockID, 3);
		world.setBlockAndMetadata(i + 2, j + 6, k + 10, Block.wood.blockID, 3);
		world.setBlock(i + 2, j + 6, k + 11, Block.planks.blockID);
		world.setBlock(i + 2, j + 6, k + 12, Block.planks.blockID);
		world.setBlock(i + 2, j + 6, k + 13, Block.planks.blockID);
		world.setBlock(i + 2, j + 6, k + 14, Block.planks.blockID);
		world.setBlock(i + 2, j + 6, k + 15, Block.planks.blockID);
		world.setBlock(i + 2, j + 6, k + 16, Block.planks.blockID);
		world.setBlock(i + 2, j + 6, k + 17, Block.planks.blockID);
		world.setBlock(i + 2, j + 6, k + 18, Block.planks.blockID);
		world.setBlock(i + 2, j + 6, k + 19, Block.planks.blockID);
		world.setBlock(i + 2, j + 6, k + 20, Block.planks.blockID);
		world.setBlock(i + 2, j + 6, k + 21, Block.planks.blockID);
		world.setBlock(i + 2, j + 6, k + 22, Block.planks.blockID);
		world.setBlock(i + 2, j + 6, k + 23, Block.planks.blockID);
		world.setBlock(i + 2, j + 6, k + 24, Block.planks.blockID);
		world.setBlock(i + 2, j + 6, k + 25, Block.planks.blockID);
		world.setBlock(i + 2, j + 6, k + 26, Block.planks.blockID);
		world.setBlock(i + 2, j + 6, k + 27, Block.planks.blockID);
		world.setBlock(i + 2, j + 6, k + 28, Block.planks.blockID);
		world.setBlock(i + 2, j + 6, k + 29, Block.planks.blockID);
		world.setBlock(i + 2, j + 6, k + 30, Block.planks.blockID);
		world.setBlock(i + 2, j + 6, k + 31, Block.planks.blockID);
		world.setBlock(i + 2, j + 6, k + 32, Block.planks.blockID);
		world.setBlock(i + 2, j + 6, k + 33, Block.planks.blockID);
		world.setBlock(i + 2, j + 6, k + 34, Block.planks.blockID);
		world.setBlock(i + 2, j + 6, k + 35, Block.planks.blockID);
		world.setBlock(i + 2, j + 6, k + 36, Block.planks.blockID);
		world.setBlock(i + 2, j + 6, k + 37, Block.planks.blockID);
		world.setBlock(i + 2, j + 6, k + 38, Block.planks.blockID);
		world.setBlock(i + 2, j + 6, k + 39, Block.planks.blockID);
		world.setBlock(i + 2, j + 6, k + 40, Block.planks.blockID);
		world.setBlock(i + 2, j + 6, k + 41, Block.planks.blockID);
		world.setBlock(i + 2, j + 6, k + 42, Block.planks.blockID);
		world.setBlock(i + 2, j + 6, k + 43, Block.planks.blockID);
		world.setBlock(i + 2, j + 6, k + 44, Block.planks.blockID);
		world.setBlock(i + 2, j + 6, k + 45, Block.planks.blockID);
		world.setBlock(i + 2, j + 6, k + 46, Block.planks.blockID);
		world.setBlock(i + 2, j + 6, k + 47, Block.planks.blockID);
		world.setBlock(i + 2, j + 6, k + 48, Block.planks.blockID);
		world.setBlock(i + 2, j + 6, k + 49, Block.planks.blockID);
		world.setBlock(i + 2, j + 6, k + 50, Block.planks.blockID);
		world.setBlockAndMetadata(i + 2, j + 6, k + 51, Block.wood.blockID, 3);
		world.setBlock(i + 2, j + 7, k + 5, Block.planks.blockID);
		world.setBlock(i + 2, j + 7, k + 6, Block.planks.blockID);
		world.setBlock(i + 2, j + 7, k + 7, Block.planks.blockID);
		world.setBlock(i + 2, j + 7, k + 8, Block.planks.blockID);
		world.setBlock(i + 2, j + 7, k + 9, Block.planks.blockID);
		world.setBlock(i + 2, j + 7, k + 10, Block.planks.blockID);
		world.setBlock(i + 2, j + 7, k + 20, Block.planks.blockID);
		world.setBlock(i + 2, j + 7, k + 50, Block.planks.blockID);
		world.setBlock(i + 2, j + 7, k + 51, Block.planks.blockID);
		world.setBlock(i + 2, j + 7, k + 52, Block.planks.blockID);
		world.setBlock(i + 2, j + 8, k + 4, Block.planks.blockID);
		world.setBlock(i + 2, j + 8, k + 5, Block.planks.blockID);
		world.setBlock(i + 2, j + 8, k + 6, Block.planks.blockID);
		world.setBlock(i + 2, j + 8, k + 7, Block.planks.blockID);
		world.setBlock(i + 2, j + 8, k + 8, Block.planks.blockID);
		world.setBlock(i + 2, j + 8, k + 9, Block.planks.blockID);
		world.setBlock(i + 2, j + 8, k + 10, Block.planks.blockID);
		world.setBlock(i + 2, j + 8, k + 19, Block.planks.blockID);
		world.setBlock(i + 2, j + 8, k + 50, Block.planks.blockID);
		world.setBlock(i + 2, j + 8, k + 51, Block.planks.blockID);
		world.setBlock(i + 2, j + 8, k + 52, Block.planks.blockID);
		world.setBlockAndMetadata(i + 2, j + 8, k + 53, Block.wood.blockID, 3);
		world.setBlockAndMetadata(i + 2, j + 8, k + 54, Block.wood.blockID, 3);
		world.setBlockAndMetadata(i + 2, j + 9, k + 2, Block.wood.blockID, 3);
		world.setBlock(i + 2, j + 9, k + 3, Block.planks.blockID);
		world.setBlock(i + 2, j + 9, k + 4, Block.planks.blockID);
		world.setBlock(i + 2, j + 9, k + 5, Block.planks.blockID);
		world.setBlock(i + 2, j + 9, k + 6, Block.planks.blockID);
		world.setBlock(i + 2, j + 9, k + 7, Block.planks.blockID);
		world.setBlock(i + 2, j + 9, k + 8, Block.planks.blockID);
		world.setBlock(i + 2, j + 9, k + 9, Block.planks.blockID);
		world.setBlock(i + 2, j + 9, k + 10, Block.planks.blockID);
		world.setBlock(i + 2, j + 9, k + 11, Block.planks.blockID);
		world.setBlock(i + 2, j + 9, k + 12, Block.planks.blockID);
		world.setBlock(i + 2, j + 9, k + 13, Block.planks.blockID);
		world.setBlock(i + 2, j + 9, k + 14, Block.planks.blockID);
		world.setBlock(i + 2, j + 9, k + 15, Block.planks.blockID);
		world.setBlock(i + 2, j + 9, k + 16, Block.planks.blockID);
		world.setBlock(i + 2, j + 9, k + 17, Block.planks.blockID);
		world.setBlock(i + 2, j + 9, k + 18, Block.planks.blockID);
		world.setBlock(i + 2, j + 9, k + 23, Block.planks.blockID);
		world.setBlock(i + 2, j + 9, k + 24, Block.planks.blockID);
		world.setBlock(i + 2, j + 9, k + 25, Block.planks.blockID);
		world.setBlock(i + 2, j + 9, k + 26, Block.planks.blockID);
		world.setBlock(i + 2, j + 9, k + 27, Block.planks.blockID);
		world.setBlock(i + 2, j + 9, k + 28, Block.planks.blockID);
		world.setBlock(i + 2, j + 9, k + 29, Block.planks.blockID);
		world.setBlock(i + 2, j + 9, k + 30, Block.planks.blockID);
		world.setBlock(i + 2, j + 9, k + 31, Block.planks.blockID);
		world.setBlock(i + 2, j + 9, k + 32, Block.planks.blockID);
		world.setBlock(i + 2, j + 9, k + 33, Block.planks.blockID);
		world.setBlock(i + 2, j + 9, k + 34, Block.planks.blockID);
		world.setBlock(i + 2, j + 9, k + 35, Block.planks.blockID);
		world.setBlock(i + 2, j + 9, k + 36, Block.planks.blockID);
		world.setBlock(i + 2, j + 9, k + 37, Block.planks.blockID);
		world.setBlock(i + 2, j + 9, k + 38, Block.planks.blockID);
		world.setBlock(i + 2, j + 9, k + 39, Block.planks.blockID);
		world.setBlock(i + 2, j + 9, k + 40, Block.planks.blockID);
		world.setBlock(i + 2, j + 9, k + 41, Block.planks.blockID);
		world.setBlock(i + 2, j + 9, k + 42, Block.planks.blockID);
		world.setBlock(i + 2, j + 9, k + 43, Block.planks.blockID);
		world.setBlock(i + 2, j + 9, k + 44, Block.planks.blockID);
		world.setBlock(i + 2, j + 9, k + 45, Block.planks.blockID);
		world.setBlock(i + 2, j + 9, k + 46, Block.planks.blockID);
		world.setBlockAndMetadata(i + 2, j + 9, k + 47, Block.wood.blockID, 3);
		world.setBlockAndMetadata(i + 2, j + 9, k + 48, Block.wood.blockID, 3);
		world.setBlockAndMetadata(i + 2, j + 9, k + 49, Block.wood.blockID, 3);
		world.setBlockAndMetadata(i + 2, j + 9, k + 50, Block.wood.blockID, 3);
		world.setBlockAndMetadata(i + 2, j + 9, k + 51, Block.wood.blockID, 3);
		world.setBlockAndMetadata(i + 2, j + 9, k + 52, Block.wood.blockID, 3);
		world.setBlock(i + 2, j + 10, k + 2, Block.planks.blockID);
		world.setBlock(i + 2, j + 10, k + 10, Block.planks.blockID);
		world.setBlock(i + 2, j + 10, k + 17, Block.planks.blockID);
		world.setBlock(i + 2, j + 10, k + 22, Block.planks.blockID);
		world.setBlock(i + 2, j + 10, k + 47, Block.planks.blockID);
		world.setBlock(i + 2, j + 10, k + 48, Block.planks.blockID);
		world.setBlock(i + 2, j + 10, k + 49, Block.planks.blockID);
		world.setBlock(i + 2, j + 10, k + 50, Block.planks.blockID);
		world.setBlock(i + 2, j + 10, k + 51, Block.planks.blockID);
		world.setBlock(i + 2, j + 11, k + 2, Block.planks.blockID);
		world.setBlock(i + 2, j + 11, k + 10, Block.planks.blockID);
		world.setBlock(i + 2, j + 11, k + 17, Block.planks.blockID);
		world.setBlock(i + 2, j + 11, k + 21, Block.planks.blockID);
		world.setBlockAndMetadata(i + 2, j + 12, k + 2, Block.wood.blockID, 3);
		world.setBlock(i + 2, j + 12, k + 3, Block.planks.blockID);
		world.setBlock(i + 2, j + 12, k + 4, Block.planks.blockID);
		world.setBlock(i + 2, j + 12, k + 5, Block.planks.blockID);
		world.setBlock(i + 2, j + 12, k + 6, Block.planks.blockID);
		world.setBlock(i + 2, j + 12, k + 7, Block.planks.blockID);
		world.setBlock(i + 2, j + 12, k + 8, Block.planks.blockID);
		world.setBlock(i + 2, j + 12, k + 9, Block.planks.blockID);
		world.setBlock(i + 2, j + 12, k + 10, Block.planks.blockID);
		world.setBlock(i + 2, j + 12, k + 11, Block.planks.blockID);
		world.setBlock(i + 2, j + 12, k + 12, Block.planks.blockID);
		world.setBlock(i + 2, j + 12, k + 13, Block.planks.blockID);
		world.setBlock(i + 2, j + 12, k + 14, Block.planks.blockID);
		world.setBlock(i + 2, j + 12, k + 15, Block.planks.blockID);
		world.setBlock(i + 2, j + 12, k + 16, Block.planks.blockID);
		world.setBlock(i + 2, j + 12, k + 17, Block.planks.blockID);
		world.setBlock(i + 2, j + 12, k + 18, Block.planks.blockID);
		world.setBlock(i + 2, j + 12, k + 19, Block.planks.blockID);
		world.setBlock(i + 2, j + 12, k + 20, Block.planks.blockID);
		world.setBlock(i + 2, j + 13, k + 3, Block.planks.blockID);
		world.setBlock(i + 2, j + 13, k + 4, Block.planks.blockID);
		world.setBlock(i + 2, j + 13, k + 5, Block.planks.blockID);
		world.setBlock(i + 2, j + 13, k + 6, Block.planks.blockID);
		world.setBlock(i + 2, j + 13, k + 7, Block.planks.blockID);
		world.setBlock(i + 2, j + 13, k + 8, Block.planks.blockID);
		world.setBlock(i + 2, j + 13, k + 9, Block.planks.blockID);
		world.setBlock(i + 2, j + 13, k + 10, Block.planks.blockID);
		world.setBlock(i + 2, j + 13, k + 11, Block.planks.blockID);
		world.setBlock(i + 2, j + 14, k + 8, Block.planks.blockID);
		world.setBlock(i + 2, j + 14, k + 9, Block.planks.blockID);
		world.setBlock(i + 2, j + 14, k + 10, Block.planks.blockID);
		world.setBlock(i + 2, j + 14, k + 11, Block.planks.blockID);
		world.setBlockAndMetadata(i + 2, j + 15, k + 10, Block.wood.blockID, 3);
		world.setBlockAndMetadata(i + 2, j + 15, k + 11, Block.wood.blockID, 3);
		world.setBlockAndMetadata(i + 2, j + 15, k + 12, Block.wood.blockID, 3);
		world.setBlock(i + 3, j + 0, k + 0, Block.bedrock.blockID);
		world.setBlock(i + 3, j + 0, k + 1, Block.bedrock.blockID);
		world.setBlock(i + 3, j + 0, k + 2, Block.bedrock.blockID);
		world.setBlock(i + 3, j + 0, k + 3, Block.bedrock.blockID);
		world.setBlock(i + 3, j + 0, k + 4, Block.bedrock.blockID);
		world.setBlock(i + 3, j + 0, k + 5, Block.bedrock.blockID);
		world.setBlock(i + 3, j + 0, k + 6, Block.bedrock.blockID);
		world.setBlock(i + 3, j + 0, k + 7, Block.bedrock.blockID);
		world.setBlock(i + 3, j + 0, k + 8, Block.bedrock.blockID);
		world.setBlock(i + 3, j + 0, k + 9, Block.bedrock.blockID);
		world.setBlock(i + 3, j + 0, k + 10, Block.planks.blockID);
		world.setBlock(i + 3, j + 0, k + 11, Block.planks.blockID);
		world.setBlock(i + 3, j + 0, k + 12, Block.planks.blockID);
		world.setBlock(i + 3, j + 0, k + 13, Block.planks.blockID);
		world.setBlock(i + 3, j + 0, k + 14, Block.planks.blockID);
		world.setBlock(i + 3, j + 0, k + 15, Block.planks.blockID);
		world.setBlock(i + 3, j + 0, k + 16, Block.planks.blockID);
		world.setBlock(i + 3, j + 0, k + 17, Block.planks.blockID);
		world.setBlock(i + 3, j + 0, k + 18, Block.planks.blockID);
		world.setBlock(i + 3, j + 0, k + 19, Block.planks.blockID);
		world.setBlock(i + 3, j + 0, k + 20, Block.planks.blockID);
		world.setBlock(i + 3, j + 0, k + 21, Block.planks.blockID);
		world.setBlock(i + 3, j + 0, k + 22, Block.planks.blockID);
		world.setBlock(i + 3, j + 0, k + 23, Block.planks.blockID);
		world.setBlock(i + 3, j + 0, k + 24, Block.planks.blockID);
		world.setBlock(i + 3, j + 0, k + 25, Block.planks.blockID);
		world.setBlock(i + 3, j + 0, k + 26, Block.planks.blockID);
		world.setBlock(i + 3, j + 0, k + 27, Block.planks.blockID);
		world.setBlock(i + 3, j + 0, k + 28, Block.planks.blockID);
		world.setBlock(i + 3, j + 0, k + 29, Block.planks.blockID);
		world.setBlock(i + 3, j + 0, k + 30, Block.planks.blockID);
		world.setBlock(i + 3, j + 0, k + 31, Block.planks.blockID);
		world.setBlock(i + 3, j + 0, k + 32, Block.planks.blockID);
		world.setBlock(i + 3, j + 0, k + 33, Block.planks.blockID);
		world.setBlock(i + 3, j + 0, k + 34, Block.planks.blockID);
		world.setBlock(i + 3, j + 0, k + 35, Block.planks.blockID);
		world.setBlock(i + 3, j + 0, k + 36, Block.planks.blockID);
		world.setBlock(i + 3, j + 0, k + 37, Block.planks.blockID);
		world.setBlock(i + 3, j + 0, k + 38, Block.planks.blockID);
		world.setBlock(i + 3, j + 0, k + 39, Block.planks.blockID);
		world.setBlock(i + 3, j + 0, k + 40, Block.planks.blockID);
		world.setBlock(i + 3, j + 0, k + 41, Block.planks.blockID);
		world.setBlock(i + 3, j + 0, k + 42, Block.planks.blockID);
		world.setBlock(i + 3, j + 0, k + 43, Block.planks.blockID);
		world.setBlock(i + 3, j + 0, k + 44, Block.planks.blockID);
		world.setBlock(i + 3, j + 0, k + 45, Block.planks.blockID);
		world.setBlock(i + 3, j + 0, k + 46, Block.planks.blockID);
		world.setBlock(i + 3, j + 0, k + 47, Block.bedrock.blockID);
		world.setBlock(i + 3, j + 0, k + 48, Block.bedrock.blockID);
		world.setBlock(i + 3, j + 0, k + 49, Block.bedrock.blockID);
		world.setBlock(i + 3, j + 0, k + 50, Block.bedrock.blockID);
		world.setBlock(i + 3, j + 0, k + 51, Block.bedrock.blockID);
		world.setBlock(i + 3, j + 0, k + 52, Block.bedrock.blockID);
		world.setBlock(i + 3, j + 0, k + 53, Block.bedrock.blockID);
		world.setBlock(i + 3, j + 0, k + 54, Block.bedrock.blockID);
		world.setBlock(i + 3, j + 0, k + 55, Block.bedrock.blockID);
		world.setBlock(i + 3, j + 0, k + 56, Block.bedrock.blockID);
		world.setBlock(i + 3, j + 0, k + 57, Block.bedrock.blockID);
		world.setBlock(i + 3, j + 0, k + 58, Block.bedrock.blockID);
		world.setBlock(i + 3, j + 0, k + 59, Block.bedrock.blockID);
		world.setBlock(i + 3, j + 0, k + 60, Block.bedrock.blockID);
		world.setBlock(i + 3, j + 0, k + 61, Block.bedrock.blockID);
		world.setBlock(i + 3, j + 0, k + 62, Block.bedrock.blockID);
		world.setBlock(i + 3, j + 0, k + 63, Block.bedrock.blockID);
		world.setBlock(i + 3, j + 0, k + 64, Block.bedrock.blockID);
		world.setBlock(i + 3, j + 0, k + 65, Block.bedrock.blockID);
		world.setBlock(i + 3, j + 0, k + 66, Block.bedrock.blockID);
		world.setBlock(i + 3, j + 0, k + 67, Block.bedrock.blockID);
		world.setBlock(i + 3, j + 0, k + 68, Block.bedrock.blockID);
		world.setBlock(i + 3, j + 0, k + 69, Block.bedrock.blockID);
		world.setBlock(i + 3, j + 1, k + 0, Block.dirt.blockID);
		world.setBlock(i + 3, j + 1, k + 1, Block.dirt.blockID);
		world.setBlock(i + 3, j + 1, k + 2, Block.dirt.blockID);
		world.setBlock(i + 3, j + 1, k + 3, Block.dirt.blockID);
		world.setBlock(i + 3, j + 1, k + 4, Block.dirt.blockID);
		world.setBlock(i + 3, j + 1, k + 5, Block.dirt.blockID);
		world.setBlock(i + 3, j + 1, k + 6, Block.dirt.blockID);
		world.setBlock(i + 3, j + 1, k + 7, Block.dirt.blockID);
		world.setBlock(i + 3, j + 1, k + 8, Block.planks.blockID);
		world.setBlock(i + 3, j + 1, k + 9, Block.planks.blockID);
		world.setBlock(i + 3, j + 1, k + 10, Block.planks.blockID);

		generate2(world, rand, i, j, k);
		return true;
	}

	public boolean generate2(World world, Random rand, int i, int j, int k) {
		world.setBlock(i + 3, j + 1, k + 11, Block.dirt.blockID);
		world.setBlock(i + 3, j + 1, k + 12, Block.dirt.blockID);
		world.setBlock(i + 3, j + 1, k + 13, Block.dirt.blockID);
		world.setBlock(i + 3, j + 1, k + 14, Block.dirt.blockID);
		world.setBlock(i + 3, j + 1, k + 15, Block.dirt.blockID);
		world.setBlock(i + 3, j + 1, k + 16, Block.dirt.blockID);
		world.setBlock(i + 3, j + 1, k + 17, Block.dirt.blockID);
		world.setBlock(i + 3, j + 1, k + 18, Block.dirt.blockID);
		world.setBlock(i + 3, j + 1, k + 19, Block.dirt.blockID);
		world.setBlock(i + 3, j + 1, k + 20, Block.dirt.blockID);
		world.setBlock(i + 3, j + 1, k + 21, Block.dirt.blockID);
		world.setBlock(i + 3, j + 1, k + 22, Block.dirt.blockID);
		world.setBlock(i + 3, j + 1, k + 23, Block.dirt.blockID);
		world.setBlock(i + 3, j + 1, k + 24, Block.dirt.blockID);
		world.setBlock(i + 3, j + 1, k + 25, Block.dirt.blockID);
		world.setBlock(i + 3, j + 1, k + 26, Block.dirt.blockID);
		world.setBlock(i + 3, j + 1, k + 27, Block.dirt.blockID);
		world.setBlock(i + 3, j + 1, k + 28, Block.dirt.blockID);
		world.setBlock(i + 3, j + 1, k + 29, Block.dirt.blockID);
		world.setBlock(i + 3, j + 1, k + 30, Block.dirt.blockID);
		world.setBlock(i + 3, j + 1, k + 31, Block.dirt.blockID);
		world.setBlock(i + 3, j + 1, k + 32, Block.dirt.blockID);
		world.setBlock(i + 3, j + 1, k + 33, Block.dirt.blockID);
		world.setBlock(i + 3, j + 1, k + 34, Block.dirt.blockID);
		world.setBlock(i + 3, j + 1, k + 35, Block.dirt.blockID);
		world.setBlock(i + 3, j + 1, k + 36, Block.dirt.blockID);
		world.setBlock(i + 3, j + 1, k + 37, Block.dirt.blockID);
		world.setBlock(i + 3, j + 1, k + 38, Block.dirt.blockID);
		world.setBlock(i + 3, j + 1, k + 39, Block.dirt.blockID);
		world.setBlock(i + 3, j + 1, k + 40, Block.dirt.blockID);
		world.setBlock(i + 3, j + 1, k + 41, Block.dirt.blockID);
		world.setBlock(i + 3, j + 1, k + 42, Block.dirt.blockID);
		world.setBlock(i + 3, j + 1, k + 43, Block.dirt.blockID);
		world.setBlock(i + 3, j + 1, k + 44, Block.dirt.blockID);
		world.setBlock(i + 3, j + 1, k + 45, Block.dirt.blockID);
		world.setBlock(i + 3, j + 1, k + 46, Block.dirt.blockID);
		world.setBlock(i + 3, j + 1, k + 47, Block.planks.blockID);
		world.setBlock(i + 3, j + 1, k + 48, Block.dirt.blockID);
		world.setBlock(i + 3, j + 1, k + 49, Block.dirt.blockID);
		world.setBlock(i + 3, j + 1, k + 50, Block.dirt.blockID);
		world.setBlock(i + 3, j + 1, k + 51, Block.dirt.blockID);
		world.setBlock(i + 3, j + 1, k + 52, Block.dirt.blockID);
		world.setBlock(i + 3, j + 1, k + 53, Block.dirt.blockID);
		world.setBlock(i + 3, j + 1, k + 54, Block.dirt.blockID);
		world.setBlock(i + 3, j + 1, k + 55, Block.dirt.blockID);
		world.setBlock(i + 3, j + 1, k + 56, Block.dirt.blockID);
		world.setBlock(i + 3, j + 1, k + 57, Block.dirt.blockID);
		world.setBlock(i + 3, j + 1, k + 58, Block.dirt.blockID);
		world.setBlock(i + 3, j + 1, k + 59, Block.dirt.blockID);
		world.setBlock(i + 3, j + 1, k + 60, Block.dirt.blockID);
		world.setBlock(i + 3, j + 1, k + 61, Block.dirt.blockID);
		world.setBlock(i + 3, j + 1, k + 62, Block.dirt.blockID);
		world.setBlock(i + 3, j + 1, k + 63, Block.dirt.blockID);
		world.setBlock(i + 3, j + 1, k + 64, Block.dirt.blockID);
		world.setBlock(i + 3, j + 1, k + 65, Block.dirt.blockID);
		world.setBlock(i + 3, j + 1, k + 66, Block.dirt.blockID);
		world.setBlock(i + 3, j + 1, k + 67, Block.dirt.blockID);
		world.setBlock(i + 3, j + 1, k + 68, Block.dirt.blockID);
		world.setBlock(i + 3, j + 1, k + 69, Block.dirt.blockID);
		world.setBlock(i + 3, j + 2, k + 0, Block.dirt.blockID);
		world.setBlock(i + 3, j + 2, k + 1, Block.dirt.blockID);
		world.setBlock(i + 3, j + 2, k + 2, Block.dirt.blockID);
		world.setBlock(i + 3, j + 2, k + 3, Block.dirt.blockID);
		world.setBlock(i + 3, j + 2, k + 4, Block.dirt.blockID);
		world.setBlock(i + 3, j + 2, k + 5, Block.dirt.blockID);
		world.setBlock(i + 3, j + 2, k + 6, Block.dirt.blockID);
		world.setBlock(i + 3, j + 2, k + 7, Block.planks.blockID);
		world.setBlock(i + 3, j + 2, k + 8, Block.planks.blockID);
		world.setBlock(i + 3, j + 2, k + 9, Block.dirt.blockID);
		world.setBlock(i + 3, j + 2, k + 10, Block.dirt.blockID);
		world.setBlock(i + 3, j + 2, k + 11, Block.dirt.blockID);
		world.setBlock(i + 3, j + 2, k + 12, Block.dirt.blockID);
		world.setBlock(i + 3, j + 2, k + 13, Block.dirt.blockID);
		world.setBlock(i + 3, j + 2, k + 14, Block.dirt.blockID);
		world.setBlock(i + 3, j + 2, k + 15, Block.dirt.blockID);
		world.setBlock(i + 3, j + 2, k + 16, Block.dirt.blockID);
		world.setBlock(i + 3, j + 2, k + 17, Block.dirt.blockID);
		world.setBlock(i + 3, j + 2, k + 18, Block.dirt.blockID);
		world.setBlock(i + 3, j + 2, k + 19, Block.dirt.blockID);
		world.setBlock(i + 3, j + 2, k + 20, Block.dirt.blockID);
		world.setBlock(i + 3, j + 2, k + 21, Block.dirt.blockID);
		world.setBlock(i + 3, j + 2, k + 22, Block.dirt.blockID);
		world.setBlock(i + 3, j + 2, k + 23, Block.dirt.blockID);
		world.setBlock(i + 3, j + 2, k + 24, Block.dirt.blockID);
		world.setBlock(i + 3, j + 2, k + 25, Block.dirt.blockID);
		world.setBlock(i + 3, j + 2, k + 26, Block.dirt.blockID);
		world.setBlock(i + 3, j + 2, k + 27, Block.dirt.blockID);
		world.setBlock(i + 3, j + 2, k + 28, Block.dirt.blockID);
		world.setBlock(i + 3, j + 2, k + 29, Block.dirt.blockID);
		world.setBlock(i + 3, j + 2, k + 30, Block.dirt.blockID);
		world.setBlock(i + 3, j + 2, k + 31, Block.dirt.blockID);
		world.setBlock(i + 3, j + 2, k + 32, Block.dirt.blockID);
		world.setBlock(i + 3, j + 2, k + 33, Block.dirt.blockID);
