package fossil.gens;

import java.util.Random;

import fossil.Fossil;

import net.minecraft.block.Block;
import net.minecraft.item.Item;
import net.minecraft.item.ItemStack;
import net.minecraft.tileentity.TileEntity;
import net.minecraft.tileentity.TileEntityChest;
import net.minecraft.world.World;
import net.minecraft.world.gen.feature.WorldGenerator;

public class WorldGeneratorAcademy extends WorldGenerator
{
	protected int[] GetValidSpawnBlocks() 
	{
		return new int[] 
		{
			Block.grass.blockID,
			Block.dirt.blockID,
			Block.sand.blockID
		};
	}

	public boolean LocationIsValidSpawn(World world, int i, int j, int k)
	{
		int distanceToAir = 0;
		int checkID = world.getBlockId(i, j, k);

		while (checkID != 0)
		{
			distanceToAir++;
			checkID = world.getBlockId(i, j + distanceToAir, k);
		}

		if (distanceToAir > 3)
		{
			return false;
		}
		j += distanceToAir - 1;

		int blockID = world.getBlockId(i, j, k);
		int blockIDAbove = world.getBlockId(i, j+1, k);
		int blockIDBelow = world.getBlockId(i, j-1, k);
		for (int x : GetValidSpawnBlocks())
		{
			if (blockIDAbove != 0)
			{
				return false;
			}
			if (blockID == x)
			{
				return true;
			}else if (blockID == Block.snow.blockID && blockIDBelow == x)
			{
				return true;
			}
		}
		return false;
	}

	public WorldGeneratorAcademy() { }

	public boolean generate(World var1, Random var2, int i, int j, int k) 
	{
		//check that each corner is one of the valid spawn blocks
		if(!LocationIsValidSpawn(var1, i, j, k) || !LocationIsValidSpawn(var1, i + 23, j, k) || !LocationIsValidSpawn(var1, i + 23, j, k + 26) || !LocationIsValidSpawn(var1, i, j, k + 26))
		{
			return false;
		}
		System.out.println("Generating Academy");
		
		var1.setBlock(i + 1, j + 2, k + 14, Block.brick.blockID);
		var1.setBlock(i + 1, j + 2, k + 15, Block.brick.blockID);
		var1.setBlock(i + 1, j + 2, k + 24, Block.brick.blockID);
		var1.setBlock(i + 1, j + 2, k + 25, Block.brick.blockID);
		var1.setBlock(i + 1, j + 3, k + 4, Block.brick.blockID);
		var1.setBlock(i + 1, j + 3, k + 5, Block.brick.blockID);
		var1.setBlock(i + 1, j + 3, k + 14, Block.brick.blockID);
		var1.setBlock(i + 1, j + 3, k + 15, Block.brick.blockID);
		var1.setBlock(i + 1, j + 3, k + 19, Block.brick.blockID);
		var1.setBlock(i + 1, j + 3, k + 20, Block.brick.blockID);
		var1.setBlock(i + 1, j + 3, k + 24, Block.brick.blockID);
		var1.setBlock(i + 1, j + 3, k + 25, Block.brick.blockID);
		var1.setBlock(i + 1, j + 4, k + 4, Block.brick.blockID);
		var1.setBlock(i + 1, j + 4, k + 5, Block.brick.blockID);
		var1.setBlock(i + 1, j + 4, k + 14, Block.brick.blockID);
		var1.setBlock(i + 1, j + 4, k + 15, Block.brick.blockID);
		var1.setBlock(i + 1, j + 4, k + 19, Block.brick.blockID);
		var1.setBlock(i + 1, j + 4, k + 20, Block.brick.blockID);
		var1.setBlock(i + 1, j + 4, k + 24, Block.brick.blockID);
		var1.setBlock(i + 1, j + 4, k + 25, Block.brick.blockID);
		var1.setBlock(i + 1, j + 5, k + 4, Block.brick.blockID);
		var1.setBlock(i + 1, j + 5, k + 5, Block.brick.blockID);
		var1.setBlock(i + 1, j + 5, k + 14, Block.brick.blockID);
		var1.setBlock(i + 1, j + 5, k + 15, Block.brick.blockID);
		var1.setBlock(i + 1, j + 5, k + 19, Block.brick.blockID);
		var1.setBlock(i + 1, j + 5, k + 20, Block.brick.blockID);
		var1.setBlock(i + 1, j + 5, k + 24, Block.brick.blockID);
		var1.setBlock(i + 1, j + 5, k + 25, Block.brick.blockID);
		var1.setBlock(i + 1, j + 6, k + 4, Block.brick.blockID);
		var1.setBlock(i + 1, j + 6, k + 5, Block.brick.blockID);
		var1.setBlock(i + 1, j + 6, k + 14, Block.brick.blockID);
		var1.setBlock(i + 1, j + 6, k + 15, Block.brick.blockID);
		var1.setBlock(i + 1, j + 6, k + 19, Block.brick.blockID);
		var1.setBlock(i + 1, j + 6, k + 20, Block.brick.blockID);
		var1.setBlock(i + 1, j + 6, k + 21, Block.brick.blockID);
		var1.setBlock(i + 1, j + 6, k + 22, Block.brick.blockID);
		var1.setBlock(i + 1, j + 6, k + 23, Block.brick.blockID);
		var1.setBlock(i + 1, j + 6, k + 24, Block.brick.blockID);
		var1.setBlock(i + 1, j + 6, k + 25, Block.brick.blockID);
		var1.setBlock(i + 1, j + 7, k + 4, Block.brick.blockID);
		var1.setBlock(i + 1, j + 7, k + 5, Block.brick.blockID);
		var1.setBlock(i + 1, j + 7, k + 14, Block.brick.blockID);
		var1.setBlock(i + 1, j + 7, k + 15, Block.brick.blockID);
		var1.setBlock(i + 1, j + 7, k + 19, Block.brick.blockID);
		var1.setBlock(i + 1, j + 7, k + 20, Block.brick.blockID);
		var1.setBlock(i + 1, j + 7, k + 21, Block.brick.blockID);
		var1.setBlock(i + 1, j + 7, k + 22, Block.brick.blockID);
		var1.setBlock(i + 1, j + 7, k + 23, Block.brick.blockID);
		var1.setBlock(i + 1, j + 7, k + 24, Block.brick.blockID);
		var1.setBlock(i + 1, j + 7, k + 25, Block.brick.blockID);
		var1.setBlock(i + 1, j + 8, k + 4, Block.brick.blockID);
		var1.setBlock(i + 1, j + 8, k + 5, Block.brick.blockID);
		var1.setBlock(i + 1, j + 8, k + 14, Block.brick.blockID);
		var1.setBlock(i + 1, j + 8, k + 15, Block.brick.blockID);
		var1.setBlock(i + 1, j + 8, k + 19, Block.brick.blockID);
		var1.setBlock(i + 1, j + 8, k + 20, Block.brick.blockID);
		var1.setBlock(i + 1, j + 8, k + 24, Block.brick.blockID);
		var1.setBlock(i + 1, j + 8, k + 25, Block.brick.blockID);
		var1.setBlock(i + 1, j + 9, k + 4, Block.brick.blockID);
		var1.setBlock(i + 1, j + 9, k + 5, Block.brick.blockID);
		var1.setBlock(i + 1, j + 9, k + 6, Block.brick.blockID);
		var1.setBlock(i + 1, j + 9, k + 7, Block.brick.blockID);
		var1.setBlock(i + 1, j + 9, k + 8, Block.brick.blockID);
		var1.setBlock(i + 1, j + 9, k + 9, Block.brick.blockID);
		var1.setBlock(i + 1, j + 9, k + 10, Block.brick.blockID);
		var1.setBlock(i + 1, j + 9, k + 11, Block.brick.blockID);
		var1.setBlock(i + 1, j + 9, k + 12, Block.brick.blockID);
		var1.setBlock(i + 1, j + 9, k + 13, Block.brick.blockID);
		var1.setBlock(i + 1, j + 9, k + 14, Block.brick.blockID);
		var1.setBlock(i + 1, j + 9, k + 15, Block.brick.blockID);
		var1.setBlock(i + 1, j + 9, k + 16, Block.web.blockID);
		var1.setBlock(i + 1, j + 9, k + 17, Block.web.blockID);
		var1.setBlock(i + 1, j + 9, k + 19, Block.brick.blockID);
		var1.setBlock(i + 1, j + 9, k + 20, Block.brick.blockID);
		var1.setBlock(i + 1, j + 9, k + 24, Block.brick.blockID);
		var1.setBlock(i + 1, j + 9, k + 25, Block.brick.blockID);
		var1.setBlock(i + 1, j + 10, k + 4, Block.brick.blockID);
		var1.setBlock(i + 1, j + 10, k + 5, Block.brick.blockID);
		var1.setBlock(i + 1, j + 10, k + 6, Block.brick.blockID);
		var1.setBlock(i + 1, j + 10, k + 7, Block.brick.blockID);
		var1.setBlock(i + 1, j + 10, k + 8, Block.brick.blockID);
		var1.setBlock(i + 1, j + 10, k + 9, Block.brick.blockID);
		var1.setBlock(i + 1, j + 10, k + 10, Block.brick.blockID);
		var1.setBlock(i + 1, j + 10, k + 11, Block.brick.blockID);
		var1.setBlock(i + 1, j + 10, k + 12, Block.brick.blockID);
		var1.setBlock(i + 1, j + 10, k + 13, Block.brick.blockID);
		var1.setBlock(i + 1, j + 10, k + 14, Block.brick.blockID);
		var1.setBlock(i + 1, j + 10, k + 15, Block.brick.blockID);
		var1.setBlock(i + 1, j + 10, k + 16, Block.brick.blockID);
		var1.setBlock(i + 1, j + 10, k + 17, Block.brick.blockID);
		var1.setBlock(i + 1, j + 10, k + 18, Block.brick.blockID);
		var1.setBlock(i + 1, j + 10, k + 19, Block.brick.blockID);
		var1.setBlock(i + 1, j + 10, k + 20, Block.brick.blockID);
		var1.setBlock(i + 1, j + 10, k + 21, Block.brick.blockID);
		var1.setBlock(i + 1, j + 10, k + 22, Block.brick.blockID);
		var1.setBlock(i + 1, j + 10, k + 23, Block.brick.blockID);
		var1.setBlock(i + 1, j + 10, k + 24, Block.brick.blockID);
		var1.setBlock(i + 1, j + 10, k + 25, Block.brick.blockID);
		var1.setBlock(i + 1, j + 11, k + 4, Block.brick.blockID);
		var1.setBlock(i + 1, j + 11, k + 5, Block.brick.blockID);
		var1.setBlock(i + 1, j + 11, k + 14, Block.brick.blockID);
		var1.setBlock(i + 1, j + 11, k + 15, Block.brick.blockID);
		var1.setBlock(i + 1, j + 11, k + 16, Block.brick.blockID);
		var1.setBlock(i + 1, j + 11, k + 17, Block.brick.blockID);
		var1.setBlock(i + 1, j + 11, k + 18, Block.brick.blockID);
		var1.setBlock(i + 1, j + 11, k + 19, Block.brick.blockID);
		var1.setBlock(i + 1, j + 11, k + 20, Block.brick.blockID);
		var1.setBlock(i + 1, j + 11, k + 21, Block.brick.blockID);
		var1.setBlock(i + 1, j + 11, k + 22, Block.brick.blockID);
		var1.setBlock(i + 1, j + 11, k + 23, Block.brick.blockID);
		var1.setBlock(i + 1, j + 11, k + 24, Block.brick.blockID);
		var1.setBlock(i + 1, j + 11, k + 25, Block.brick.blockID);
		var1.setBlock(i + 1, j + 12, k + 4, Block.brick.blockID);
		var1.setBlock(i + 1, j + 12, k + 5, Block.brick.blockID);
		var1.setBlock(i + 1, j + 12, k + 14, Block.brick.blockID);
		var1.setBlock(i + 1, j + 12, k + 15, Block.brick.blockID);
		var1.setBlock(i + 1, j + 12, k + 19, Block.stoneBrick.blockID);
		var1.setBlock(i + 1, j + 12, k + 20, Block.stoneBrick.blockID);
		var1.setBlock(i + 1, j + 12, k + 24, Block.brick.blockID);
		var1.setBlock(i + 1, j + 12, k + 25, Block.brick.blockID);
		var1.setBlock(i + 1, j + 13, k + 4, Block.brick.blockID);
		var1.setBlock(i + 1, j + 13, k + 5, Block.brick.blockID);
		var1.setBlock(i + 1, j + 13, k + 6, Block.web.blockID);
		var1.setBlock(i + 1, j + 13, k + 14, Block.brick.blockID);
		var1.setBlock(i + 1, j + 13, k + 15, Block.brick.blockID);
		var1.setBlock(i + 1, j + 13, k + 19, Block.stoneBrick.blockID);
		var1.setBlock(i + 1, j + 13, k + 20, Block.stoneBrick.blockID);
		var1.setBlock(i + 1, j + 13, k + 24, Block.brick.blockID);
		var1.setBlock(i + 1, j + 13, k + 25, Block.brick.blockID);
		var1.setBlock(i + 1, j + 14, k + 4, Block.brick.blockID);
		var1.setBlock(i + 1, j + 14, k + 5, Block.brick.blockID);
		var1.setBlock(i + 1, j + 14, k + 6, Block.stoneBrick.blockID);
		var1.setBlock(i + 1, j + 14, k + 7, Block.stoneBrick.blockID);
		var1.setBlock(i + 1, j + 14, k + 8, Block.stoneBrick.blockID);
		var1.setBlock(i + 1, j + 14, k + 9, Block.stoneBrick.blockID);
		var1.setBlock(i + 1, j + 14, k + 10, Block.stoneBrick.blockID);
		var1.setBlock(i + 1, j + 14, k + 11, Block.stoneBrick.blockID);
		var1.setBlock(i + 1, j + 14, k + 12, Block.stoneBrick.blockID);
		var1.setBlock(i + 1, j + 14, k + 13, Block.stoneBrick.blockID);
		var1.setBlock(i + 1, j + 14, k + 14, Block.brick.blockID);
		var1.setBlock(i + 1, j + 14, k + 15, Block.brick.blockID);
		var1.setBlock(i + 1, j + 14, k + 19, Block.stoneBrick.blockID);
		var1.setBlock(i + 1, j + 14, k + 20, Block.stoneBrick.blockID);
		var1.setBlock(i + 1, j + 14, k + 24, Block.brick.blockID);
		var1.setBlock(i + 1, j + 14, k + 25, Block.brick.blockID);
		var1.setBlock(i + 1, j + 15, k + 4, Block.stoneBrick.blockID);
		var1.setBlock(i + 1, j + 15, k + 5, Block.stoneBrick.blockID);
		var1.setBlock(i + 1, j + 15, k + 6, Block.stoneBrick.blockID);
		var1.setBlock(i + 1, j + 15, k + 7, Block.stoneBrick.blockID);
		var1.setBlock(i + 1, j + 15, k + 8, Block.stoneBrick.blockID);
		var1.setBlock(i + 1, j + 15, k + 9, Block.stoneBrick.blockID);
		var1.setBlock(i + 1, j + 15, k + 10, Block.stoneBrick.blockID);
		var1.setBlock(i + 1, j + 15, k + 11, Block.stoneBrick.blockID);
		var1.setBlock(i + 1, j + 15, k + 12, Block.stoneBrick.blockID);
		var1.setBlock(i + 1, j + 15, k + 13, Block.stoneBrick.blockID);
		var1.setBlock(i + 1, j + 15, k + 14, Block.stoneBrick.blockID);
		var1.setBlock(i + 1, j + 15, k + 15, Block.stoneBrick.blockID);
		var1.setBlock(i + 1, j + 15, k + 19, Block.stoneBrick.blockID);
		var1.setBlock(i + 1, j + 15, k + 20, Block.stoneBrick.blockID);
		var1.setBlock(i + 1, j + 15, k + 24, Block.stoneBrick.blockID);
		var1.setBlock(i + 1, j + 15, k + 25, Block.stoneBrick.blockID);
		var1.setBlock(i + 1, j + 16, k + 14, Block.stoneBrick.blockID);
		var1.setBlock(i + 1, j + 16, k + 15, Block.stoneBrick.blockID);
		var1.setBlock(i + 1, j + 16, k + 16, Block.stoneBrick.blockID);
		var1.setBlock(i + 1, j + 16, k + 17, Block.stoneBrick.blockID);
		var1.setBlock(i + 1, j + 16, k + 18, Block.stoneBrick.blockID);
		var1.setBlock(i + 1, j + 16, k + 19, Block.stoneBrick.blockID);
		var1.setBlock(i + 1, j + 16, k + 20, Block.stoneBrick.blockID);
		var1.setBlock(i + 1, j + 16, k + 21, Block.stoneBrick.blockID);
		var1.setBlock(i + 1, j + 16, k + 22, Block.stoneBrick.blockID);
		var1.setBlock(i + 1, j + 16, k + 23, Block.stoneBrick.blockID);
		var1.setBlock(i + 1, j + 16, k + 24, Block.stoneBrick.blockID);
		var1.setBlock(i + 1, j + 16, k + 25, Block.stoneBrick.blockID);
		var1.setBlock(i + 2, j + 2, k + 5, Block.brick.blockID);
		var1.setBlock(i + 2, j + 2, k + 6, Block.stoneBrick.blockID);
		var1.setBlock(i + 2, j + 2, k + 7, Block.stoneBrick.blockID);
		var1.setBlock(i + 2, j + 2, k + 8, Block.stoneBrick.blockID);
		var1.setBlock(i + 2, j + 2, k + 9, Block.stoneBrick.blockID);
		var1.setBlock(i + 2, j + 2, k + 10, Block.stoneBrick.blockID);
		var1.setBlock(i + 2, j + 2, k + 11, Block.stoneBrick.blockID);
		var1.setBlock(i + 2, j + 2, k + 12, Block.stoneBrick.blockID);
		var1.setBlock(i + 2, j + 2, k + 13, Block.stoneBrick.blockID);
		var1.setBlock(i + 2, j + 2, k + 14, Block.brick.blockID);
		var1.setBlock(i + 2, j + 2, k + 15, Block.brick.blockID);
		var1.setBlock(i + 2, j + 2, k + 16, Block.stoneBrick.blockID);
		var1.setBlock(i + 2, j + 2, k + 17, Block.stoneBrick.blockID);
		var1.setBlock(i + 2, j + 2, k + 18, Block.stoneBrick.blockID);
		var1.setBlock(i + 2, j + 2, k + 19, Block.brick.blockID);
		var1.setBlock(i + 2, j + 2, k + 20, Block.brick.blockID);
		var1.setBlock(i + 2, j + 2, k + 21, Block.stoneBrick.blockID);
		var1.setBlock(i + 2, j + 2, k + 22, Block.stoneBrick.blockID);
		var1.setBlock(i + 2, j + 2, k + 23, Block.stoneBrick.blockID);
		var1.setBlock(i + 2, j + 2, k + 24, Block.brick.blockID);
		var1.setBlock(i + 2, j + 2, k + 25, Block.brick.blockID);
		var1.setBlock(i + 2, j + 3, k + 4, Block.brick.blockID);
		var1.setBlock(i + 2, j + 3, k + 5, Block.brick.blockID);
		var1.setBlockMetadataWithNotify(i + 2, j + 3, k + 6, Block.stoneBrick.blockID, 1);
		var1.setBlock(i + 2, j + 3, k + 7, Block.stoneBrick.blockID);
		var1.setBlock(i + 2, j + 3, k + 8, Block.stoneBrick.blockID);
		var1.setBlock(i + 2, j + 3, k + 9, Block.stoneBrick.blockID);
		var1.setBlockMetadataWithNotify(i + 2, j + 3, k + 10, Block.stoneBrick.blockID, 2);
		var1.setBlock(i + 2, j + 3, k + 11, Block.stoneBrick.blockID);
		var1.setBlock(i + 2, j + 3, k + 12, Block.stoneBrick.blockID);
		var1.setBlock(i + 2, j + 3, k + 13, Block.stoneBrick.blockID);
		var1.setBlock(i + 2, j + 3, k + 14, Block.brick.blockID);
		var1.setBlock(i + 2, j + 3, k + 15, Block.brick.blockID);
		var1.setBlock(i + 2, j + 3, k + 16, Block.stoneBrick.blockID);
		var1.setBlock(i + 2, j + 3, k + 17, Block.stoneBrick.blockID);
		var1.setBlock(i + 2, j + 3, k + 18, Block.stoneBrick.blockID);
		var1.setBlock(i + 2, j + 3, k + 19, Block.brick.blockID);
		var1.setBlock(i + 2, j + 3, k + 20, Block.brick.blockID);
		var1.setBlock(i + 2, j + 3, k + 21, Block.stoneBrick.blockID);
		var1.setBlock(i + 2, j + 3, k + 22, Block.stoneBrick.blockID);
		var1.setBlock(i + 2, j + 3, k + 23, Block.stoneBrick.blockID);
		var1.setBlock(i + 2, j + 3, k + 24, Block.brick.blockID);
		var1.setBlock(i + 2, j + 3, k + 25, Block.brick.blockID);
		var1.setBlock(i + 2, j + 4, k + 4, Block.brick.blockID);
		var1.setBlock(i + 2, j + 4, k + 5, Block.brick.blockID);
		var1.setBlock(i + 2, j + 4, k + 6, Block.stoneBrick.blockID);
		var1.setBlock(i + 2, j + 4, k + 7, Block.stoneBrick.blockID);
		var1.setBlock(i + 2, j + 4, k + 8, Block.stoneBrick.blockID);
		var1.setBlock(i + 2, j + 4, k + 9, Block.stoneBrick.blockID);
		var1.setBlock(i + 2, j + 4, k + 10, Block.stoneBrick.blockID);
		var1.setBlock(i + 2, j + 4, k + 11, Block.stoneBrick.blockID);
		var1.setBlock(i + 2, j + 4, k + 12, Block.stoneBrick.blockID);
		var1.setBlockMetadataWithNotify(i + 2, j + 4, k + 13, Block.stoneBrick.blockID, 2);
		var1.setBlock(i + 2, j + 4, k + 14, Block.brick.blockID);
		var1.setBlock(i + 2, j + 4, k + 15, Block.brick.blockID);
		var1.setBlock(i + 2, j + 4, k + 16, Block.stoneBrick.blockID);
		var1.setBlock(i + 2, j + 4, k + 17, Block.stoneBrick.blockID);
		var1.setBlock(i + 2, j + 4, k + 18, Block.stoneBrick.blockID);
		var1.setBlock(i + 2, j + 4, k + 19, Block.brick.blockID);
		var1.setBlock(i + 2, j + 4, k + 20, Block.brick.blockID);
		var1.setBlock(i + 2, j + 4, k + 21, Block.stoneBrick.blockID);
		var1.setBlock(i + 2, j + 4, k + 22, Block.stoneBrick.blockID);
		var1.setBlock(i + 2, j + 4, k + 23, Block.stoneBrick.blockID);
		var1.setBlock(i + 2, j + 4, k + 24, Block.brick.blockID);
		var1.setBlock(i + 2, j + 4, k + 25, Block.brick.blockID);
		var1.setBlock(i + 2, j + 5, k + 4, Block.brick.blockID);
		var1.setBlock(i + 2, j + 5, k + 5, Block.brick.blockID);
		var1.setBlock(i + 2, j + 5, k + 6, Block.stoneBrick.blockID);
		var1.setBlock(i + 2, j + 5, k + 7, Block.stoneBrick.blockID);
		var1.setBlock(i + 2, j + 5, k + 8, Block.thinGlass.blockID);
		var1.setBlock(i + 2, j + 5, k + 9, Block.stoneBrick.blockID);
		var1.setBlock(i + 2, j + 5, k + 10, Block.thinGlass.blockID);
		var1.setBlock(i + 2, j + 5, k + 11, Block.stoneBrick.blockID);
		var1.setBlock(i + 2, j + 5, k + 12, Block.thinGlass.blockID);
		var1.setBlock(i + 2, j + 5, k + 13, Block.stoneBrick.blockID);
		var1.setBlock(i + 2, j + 5, k + 14, Block.brick.blockID);
		var1.setBlock(i + 2, j + 5, k + 15, Block.brick.blockID);
		var1.setBlock(i + 2, j + 5, k + 16, Block.thinGlass.blockID);
		var1.setBlock(i + 2, j + 5, k + 17, Block.stoneBrick.blockID);
		var1.setBlock(i + 2, j + 5, k + 18, Block.stoneBrick.blockID);
		var1.setBlock(i + 2, j + 5, k + 19, Block.brick.blockID);
		var1.setBlock(i + 2, j + 5, k + 20, Block.brick.blockID);
		var1.setBlock(i + 2, j + 5, k + 21, Block.stoneBrick.blockID);
		var1.setBlock(i + 2, j + 5, k + 22, Block.stoneBrick.blockID);
		var1.setBlock(i + 2, j + 5, k + 23, Block.stoneBrick.blockID);
		var1.setBlock(i + 2, j + 5, k + 24, Block.brick.blockID);
		var1.setBlock(i + 2, j + 5, k + 25, Block.brick.blockID);
		var1.setBlock(i + 2, j + 6, k + 4, Block.brick.blockID);
		var1.setBlock(i + 2, j + 6, k + 5, Block.brick.blockID);
		var1.setBlock(i + 2, j + 6, k + 6, Block.stoneBrick.blockID);
		var1.setBlock(i + 2, j + 6, k + 7, Block.stoneBrick.blockID);
		var1.setBlock(i + 2, j + 6, k + 8, Block.thinGlass.blockID);
		var1.setBlock(i + 2, j + 6, k + 9, Block.stoneBrick.blockID);
		var1.setBlock(i + 2, j + 6, k + 10, Block.thinGlass.blockID);
		var1.setBlock(i + 2, j + 6, k + 11, Block.stoneBrick.blockID);
		var1.setBlock(i + 2, j + 6, k + 12, Block.thinGlass.blockID);
		var1.setBlock(i + 2, j + 6, k + 13, Block.stoneBrick.blockID);
		var1.setBlock(i + 2, j + 6, k + 14, Block.brick.blockID);
		var1.setBlock(i + 2, j + 6, k + 15, Block.brick.blockID);
		var1.setBlock(i + 2, j + 6, k + 16, Block.thinGlass.blockID);
		var1.setBlock(i + 2, j + 6, k + 17, Block.stoneBrick.blockID);
		var1.setBlock(i + 2, j + 6, k + 18, Block.thinGlass.blockID);
		var1.setBlock(i + 2, j + 6, k + 19, Block.brick.blockID);
		var1.setBlock(i + 2, j + 6, k + 20, Block.brick.blockID);
		var1.setBlock(i + 2, j + 6, k + 21, Block.brick.blockID);
		var1.setBlock(i + 2, j + 6, k + 22, Block.brick.blockID);
		var1.setBlock(i + 2, j + 6, k + 23, Block.brick.blockID);
		var1.setBlock(i + 2, j + 6, k + 24, Block.brick.blockID);
		var1.setBlock(i + 2, j + 6, k + 25, Block.brick.blockID);
		var1.setBlock(i + 2, j + 7, k + 4, Block.brick.blockID);
		var1.setBlock(i + 2, j + 7, k + 5, Block.brick.blockID);
		var1.setBlock(i + 2, j + 7, k + 6, Block.stoneBrick.blockID);
		var1.setBlock(i + 2, j + 7, k + 7, Block.stoneBrick.blockID);
		var1.setBlock(i + 2, j + 7, k + 8, Block.thinGlass.blockID);
		var1.setBlock(i + 2, j + 7, k + 9, Block.stoneBrick.blockID);
		var1.setBlock(i + 2, j + 7, k + 10, Block.thinGlass.blockID);
		var1.setBlock(i + 2, j + 7, k + 11, Block.stoneBrick.blockID);
		var1.setBlock(i + 2, j + 7, k + 12, Block.thinGlass.blockID);
		var1.setBlock(i + 2, j + 7, k + 13, Block.stoneBrick.blockID);
		var1.setBlock(i + 2, j + 7, k + 14, Block.brick.blockID);
		var1.setBlock(i + 2, j + 7, k + 15, Block.brick.blockID);
		var1.setBlock(i + 2, j + 7, k + 16, Block.thinGlass.blockID);
		var1.setBlock(i + 2, j + 7, k + 17, Block.stoneBrick.blockID);
		var1.setBlock(i + 2, j + 7, k + 18, Block.thinGlass.blockID);
		var1.setBlock(i + 2, j + 7, k + 19, Block.brick.blockID);
		var1.setBlock(i + 2, j + 7, k + 20, Block.brick.blockID);
		var1.setBlock(i + 2, j + 7, k + 21, Block.brick.blockID);
		var1.setBlock(i + 2, j + 7, k + 22, Block.brick.blockID);
		var1.setBlock(i + 2, j + 7, k + 23, Block.brick.blockID);
		var1.setBlock(i + 2, j + 7, k + 24, Block.brick.blockID);
		var1.setBlock(i + 2, j + 7, k + 25, Block.brick.blockID);
		var1.setBlock(i + 2, j + 8, k + 4, Block.brick.blockID);
		var1.setBlock(i + 2, j + 8, k + 5, Block.brick.blockID);
		var1.setBlock(i + 2, j + 8, k + 6, Block.stoneBrick.blockID);
		var1.setBlock(i + 2, j + 8, k + 7, Block.stoneBrick.blockID);
		var1.setBlock(i + 2, j + 8, k + 8, Block.stoneBrick.blockID);
		var1.setBlock(i + 2, j + 8, k + 9, Block.stoneBrick.blockID);
		var1.setBlock(i + 2, j + 8, k + 10, Block.stoneBrick.blockID);
		var1.setBlock(i + 2, j + 8, k + 11, Block.stoneBrick.blockID);
		var1.setBlock(i + 2, j + 8, k + 12, Block.stoneBrick.blockID);
		var1.setBlock(i + 2, j + 8, k + 13, Block.stoneBrick.blockID);
		var1.setBlock(i + 2, j + 8, k + 14, Block.brick.blockID);
		var1.setBlock(i + 2, j + 8, k + 15, Block.brick.blockID);
		var1.setBlock(i + 2, j + 8, k + 16, Block.stoneBrick.blockID);
		var1.setBlock(i + 2, j + 8, k + 17, Block.stoneBrick.blockID);
		var1.setBlock(i + 2, j + 8, k + 18, Block.thinGlass.blockID);
		var1.setBlock(i + 2, j + 8, k + 19, Block.brick.blockID);
		var1.setBlock(i + 2, j + 8, k + 20, Block.brick.blockID);
		var1.setBlock(i + 2, j + 8, k + 21, Block.thinGlass.blockID);
		var1.setBlock(i + 2, j + 8, k + 22, Block.thinGlass.blockID);
		var1.setBlock(i + 2, j + 8, k + 23, Block.thinGlass.blockID);
		var1.setBlock(i + 2, j + 8, k + 24, Block.brick.blockID);
		var1.setBlock(i + 2, j + 8, k + 25, Block.brick.blockID);
		var1.setBlock(i + 2, j + 9, k + 4, Block.brick.blockID);
		var1.setBlock(i + 2, j + 9, k + 5, Block.brick.blockID);
		var1.setBlock(i + 2, j + 9, k + 6, Block.brick.blockID);
		var1.setBlock(i + 2, j + 9, k + 7, Block.brick.blockID);
		var1.setBlock(i + 2, j + 9, k + 8, Block.brick.blockID);
		var1.setBlock(i + 2, j + 9, k + 9, Block.brick.blockID);
		var1.setBlock(i + 2, j + 9, k + 10, Block.brick.blockID);
		var1.setBlock(i + 2, j + 9, k + 11, Block.brick.blockID);
		var1.setBlock(i + 2, j + 9, k + 12, Block.brick.blockID);
		var1.setBlock(i + 2, j + 9, k + 13, Block.brick.blockID);
		var1.setBlock(i + 2, j + 9, k + 14, Block.brick.blockID);
		var1.setBlock(i + 2, j + 9, k + 15, Block.brick.blockID);
		var1.setBlock(i + 2, j + 9, k + 16, Block.stoneBrick.blockID);
		var1.setBlock(i + 2, j + 9, k + 17, Block.stoneBrick.blockID);
		var1.setBlock(i + 2, j + 9, k + 18, Block.stoneBrick.blockID);
		var1.setBlock(i + 2, j + 9, k + 19, Block.brick.blockID);
		var1.setBlock(i + 2, j + 9, k + 20, Block.brick.blockID);
		var1.setBlock(i + 2, j + 9, k + 21, Block.thinGlass.blockID);
		var1.setBlock(i + 2, j + 9, k + 22, Block.thinGlass.blockID);
		var1.setBlock(i + 2, j + 9, k + 23, Block.thinGlass.blockID);
		var1.setBlock(i + 2, j + 9, k + 24, Block.brick.blockID);
		var1.setBlock(i + 2, j + 9, k + 25, Block.brick.blockID);
		var1.setBlock(i + 2, j + 10, k + 4, Block.brick.blockID);
		var1.setBlock(i + 2, j + 10, k + 5, Block.brick.blockID);
		var1.setBlock(i + 2, j + 10, k + 6, Block.brick.blockID);
		var1.setBlock(i + 2, j + 10, k + 7, Block.brick.blockID);
		var1.setBlock(i + 2, j + 10, k + 8, Block.brick.blockID);
		var1.setBlock(i + 2, j + 10, k + 9, Block.brick.blockID);
		var1.setBlock(i + 2, j + 10, k + 10, Block.brick.blockID);
		var1.setBlock(i + 2, j + 10, k + 11, Block.brick.blockID);
		var1.setBlock(i + 2, j + 10, k + 12, Block.brick.blockID);
		var1.setBlock(i + 2, j + 10, k + 13, Block.brick.blockID);
		var1.setBlock(i + 2, j + 10, k + 14, Block.brick.blockID);
		var1.setBlock(i + 2, j + 10, k + 15, Block.brick.blockID);
		var1.setBlock(i + 2, j + 10, k + 16, Block.brick.blockID);
		var1.setBlock(i + 2, j + 10, k + 17, Block.brick.blockID);
		var1.setBlock(i + 2, j + 10, k + 18, Block.brick.blockID);
		var1.setBlock(i + 2, j + 10, k + 19, Block.brick.blockID);
		var1.setBlock(i + 2, j + 10, k + 20, Block.brick.blockID);
		var1.setBlock(i + 2, j + 10, k + 21, Block.brick.blockID);
		var1.setBlock(i + 2, j + 10, k + 22, Block.brick.blockID);
		var1.setBlock(i + 2, j + 10, k + 23, Block.brick.blockID);
		var1.setBlock(i + 2, j + 10, k + 24, Block.brick.blockID);
		var1.setBlock(i + 2, j + 10, k + 25, Block.brick.blockID);
		var1.setBlock(i + 2, j + 11, k + 4, Block.brick.blockID);
		var1.setBlock(i + 2, j + 11, k + 5, Block.brick.blockID);
		var1.setBlock(i + 2, j + 11, k + 6, Block.stoneBrick.blockID);
		var1.setBlock(i + 2, j + 11, k + 7, Block.stoneBrick.blockID);
		var1.setBlock(i + 2, j + 11, k + 8, Block.stoneBrick.blockID);
		var1.setBlock(i + 2, j + 11, k + 9, Block.stoneBrick.blockID);
		var1.setBlock(i + 2, j + 11, k + 10, Block.stoneBrick.blockID);
		var1.setBlock(i + 2, j + 11, k + 11, Block.stoneBrick.blockID);
		var1.setBlock(i + 2, j + 11, k + 12, Block.stoneBrick.blockID);
		var1.setBlock(i + 2, j + 11, k + 13, Block.stoneBrick.blockID);
		var1.setBlock(i + 2, j + 11, k + 14, Block.brick.blockID);
		var1.setBlock(i + 2, j + 11, k + 15, Block.brick.blockID);
		var1.setBlock(i + 2, j + 11, k + 16, Block.brick.blockID);
		var1.setBlock(i + 2, j + 11, k + 17, Block.brick.blockID);
		var1.setBlock(i + 2, j + 11, k + 18, Block.brick.blockID);
		var1.setBlock(i + 2, j + 11, k + 19, Block.brick.blockID);
		var1.setBlock(i + 2, j + 11, k + 20, Block.brick.blockID);
		var1.setBlock(i + 2, j + 11, k + 21, Block.brick.blockID);
		var1.setBlock(i + 2, j + 11, k + 22, Block.brick.blockID);
		var1.setBlock(i + 2, j + 11, k + 23, Block.brick.blockID);
		var1.setBlock(i + 2, j + 11, k + 24, Block.brick.blockID);
		var1.setBlock(i + 2, j + 11, k + 25, Block.brick.blockID);
		var1.setBlock(i + 2, j + 12, k + 4, Block.brick.blockID);
		var1.setBlock(i + 2, j + 12, k + 5, Block.brick.blockID);
		var1.setBlock(i + 2, j + 12, k + 6, Block.stoneBrick.blockID);
		var1.setBlock(i + 2, j + 12, k + 7, Block.stoneBrick.blockID);
		var1.setBlock(i + 2, j + 12, k + 8, Block.stoneBrick.blockID);
		var1.setBlock(i + 2, j + 12, k + 9, Block.stoneBrick.blockID);
		var1.setBlock(i + 2, j + 12, k + 10, Block.stoneBrick.blockID);
		var1.setBlock(i + 2, j + 12, k + 11, Block.stoneBrick.blockID);
		var1.setBlock(i + 2, j + 12, k + 12, Block.stoneBrick.blockID);
		var1.setBlock(i + 2, j + 12, k + 13, Block.stoneBrick.blockID);
		var1.setBlock(i + 2, j + 12, k + 14, Block.brick.blockID);
		var1.setBlock(i + 2, j + 12, k + 15, Block.brick.blockID);
		var1.setBlock(i + 2, j + 12, k + 16, Block.stoneBrick.blockID);
		var1.setBlock(i + 2, j + 12, k + 17, Block.stoneBrick.blockID);
		var1.setBlock(i + 2, j + 12, k + 18, Block.stoneBrick.blockID);
		var1.setBlock(i + 2, j + 12, k + 19, Block.stoneBrick.blockID);
		var1.setBlock(i + 2, j + 12, k + 20, Block.stoneBrick.blockID);
		var1.setBlock(i + 2, j + 12, k + 21, Block.stoneBrick.blockID);
		var1.setBlock(i + 2, j + 12, k + 22, Block.stoneBrick.blockID);
		var1.setBlock(i + 2, j + 12, k + 23, Block.stoneBrick.blockID);
		var1.setBlock(i + 2, j + 12, k + 24, Block.brick.blockID);
		var1.setBlock(i + 2, j + 12, k + 25, Block.brick.blockID);
		var1.setBlock(i + 2, j + 13, k + 4, Block.brick.blockID);
		var1.setBlock(i + 2, j + 13, k + 5, Block.brick.blockID);
		var1.setBlock(i + 2, j + 13, k + 6, Block.stoneBrick.blockID);
		var1.setBlock(i + 2, j + 13, k + 7, Block.stoneBrick.blockID);
		var1.setBlock(i + 2, j + 13, k + 8, Block.stoneBrick.blockID);
		var1.setBlock(i + 2, j + 13, k + 9, Block.stoneBrick.blockID);
		var1.setBlock(i + 2, j + 13, k + 10, Block.stoneBrick.blockID);
		var1.setBlock(i + 2, j + 13, k + 11, Block.stoneBrick.blockID);
		var1.setBlock(i + 2, j + 13, k + 12, Block.stoneBrick.blockID);
		var1.setBlock(i + 2, j + 13, k + 13, Block.stoneBrick.blockID);
		var1.setBlock(i + 2, j + 13, k + 14, Block.brick.blockID);
		var1.setBlock(i + 2, j + 13, k + 15, Block.brick.blockID);
		var1.setBlock(i + 2, j + 13, k + 16, Block.stoneBrick.blockID);
		var1.setBlock(i + 2, j + 13, k + 17, Block.stoneBrick.blockID);
		var1.setBlock(i + 2, j + 13, k + 18, Block.stoneBrick.blockID);
		var1.setBlock(i + 2, j + 13, k + 19, Block.stoneBrick.blockID);
		var1.setBlock(i + 2, j + 13, k + 20, Block.stoneBrick.blockID);
		var1.setBlock(i + 2, j + 13, k + 21, Block.stoneBrick.blockID);
		var1.setBlock(i + 2, j + 13, k + 22, Block.stoneBrick.blockID);
		var1.setBlock(i + 2, j + 13, k + 23, Block.stoneBrick.blockID);
		var1.setBlock(i + 2, j + 13, k + 24, Block.brick.blockID);
		var1.setBlock(i + 2, j + 13, k + 25, Block.brick.blockID);
		var1.setBlock(i + 2, j + 14, k + 4, Block.brick.blockID);
		var1.setBlock(i + 2, j + 14, k + 5, Block.brick.blockID);
		var1.setBlock(i + 2, j + 14, k + 6, Block.stoneBrick.blockID);
		var1.setBlock(i + 2, j + 14, k + 7, Block.stoneBrick.blockID);
		var1.setBlock(i + 2, j + 14, k + 8, Block.stoneBrick.blockID);
		var1.setBlock(i + 2, j + 14, k + 9, Block.stoneBrick.blockID);
		var1.setBlock(i + 2, j + 14, k + 10, Block.stoneBrick.blockID);
		var1.setBlock(i + 2, j + 14, k + 11, Block.stoneBrick.blockID);
		var1.setBlock(i + 2, j + 14, k + 12, Block.stoneBrick.blockID);
		var1.setBlock(i + 2, j + 14, k + 13, Block.stoneBrick.blockID);
		var1.setBlock(i + 2, j + 14, k + 14, Block.brick.blockID);
		var1.setBlock(i + 2, j + 14, k + 15, Block.brick.blockID);
		var1.setBlock(i + 2, j + 14, k + 16, Block.stoneBrick.blockID);
		var1.setBlock(i + 2, j + 14, k + 17, Block.stoneBrick.blockID);
		var1.setBlock(i + 2, j + 14, k + 18, Block.stoneBrick.blockID);
		var1.setBlock(i + 2, j + 14, k + 19, Block.stoneBrick.blockID);
		var1.setBlock(i + 2, j + 14, k + 20, Block.stoneBrick.blockID);
		var1.setBlock(i + 2, j + 14, k + 21, Block.stoneBrick.blockID);
		var1.setBlock(i + 2, j + 14, k + 22, Block.thinGlass.blockID);
		var1.setBlock(i + 2, j + 14, k + 23, Block.stoneBrick.blockID);
		var1.setBlock(i + 2, j + 14, k + 24, Block.brick.blockID);
		var1.setBlock(i + 2, j + 14, k + 25, Block.brick.blockID);
		var1.setBlock(i + 2, j + 15, k + 4, Block.stoneBrick.blockID);
		var1.setBlock(i + 2, j + 15, k + 14, Block.stoneBrick.blockID);
		var1.setBlock(i + 2, j + 15, k + 15, Block.stoneBrick.blockID);
		var1.setBlock(i + 2, j + 15, k + 16, Block.stoneBrick.blockID);
		var1.setBlock(i + 2, j + 15, k + 17, Block.stoneBrick.blockID);
		var1.setBlock(i + 2, j + 15, k + 18, Block.stoneBrick.blockID);
		var1.setBlock(i + 2, j + 15, k + 19, Block.stoneBrick.blockID);
		var1.setBlock(i + 2, j + 15, k + 20, Block.stoneBrick.blockID);
		var1.setBlock(i + 2, j + 15, k + 21, Block.stoneBrick.blockID);
		var1.setBlock(i + 2, j + 15, k + 22, Block.thinGlass.blockID);
		var1.setBlock(i + 2, j + 15, k + 23, Block.stoneBrick.blockID);
		var1.setBlock(i + 2, j + 15, k + 24, Block.stoneBrick.blockID);
		var1.setBlock(i + 2, j + 15, k + 25, Block.stoneBrick.blockID);
		var1.setBlock(i + 2, j + 16, k + 14, Block.stoneBrick.blockID);
		var1.setBlock(i + 2, j + 16, k + 15, Block.stoneBrick.blockID);
		var1.setBlock(i + 2, j + 16, k + 16, Block.stoneBrick.blockID);
		var1.setBlock(i + 2, j + 16, k + 17, Block.stoneBrick.blockID);
		var1.setBlock(i + 2, j + 16, k + 18, Block.stoneBrick.blockID);
		var1.setBlock(i + 2, j + 16, k + 19, Block.stoneBrick.blockID);
		var1.setBlock(i + 2, j + 16, k + 20, Block.stoneBrick.blockID);
		var1.setBlock(i + 2, j + 16, k + 21, Block.stoneBrick.blockID);
		var1.setBlock(i + 2, j + 16, k + 22, Block.stoneBrick.blockID);
		var1.setBlock(i + 2, j + 16, k + 23, Block.stoneBrick.blockID);
		var1.setBlock(i + 2, j + 16, k + 24, Block.stoneBrick.blockID);
		var1.setBlock(i + 2, j + 16, k + 25, Block.stoneBrick.blockID);
		var1.setBlock(i + 2, j + 17, k + 15, Block.stoneBrick.blockID);
		var1.setBlock(i + 2, j + 17, k + 16, Block.stoneBrick.blockID);
		var1.setBlock(i + 2, j + 17, k + 17, Block.thinGlass.blockID);
		var1.setBlock(i + 2, j + 17, k + 18, Block.stoneBrick.blockID);
		var1.setBlock(i + 2, j + 17, k + 19, Block.stoneBrick.blockID);
		var1.setBlock(i + 2, j + 17, k + 20, Block.stoneBrick.blockID);
		var1.setBlock(i + 2, j + 17, k + 21, Block.stoneBrick.blockID);
		var1.setBlock(i + 2, j + 17, k + 22, Block.stoneBrick.blockID);
		var1.setBlock(i + 2, j + 17, k + 23, Block.stoneBrick.blockID);
		var1.setBlock(i + 2, j + 17, k + 24, Block.stoneBrick.blockID);
		var1.setBlock(i + 2, j + 17, k + 25, Block.stoneBrick.blockID);
		var1.setBlock(i + 2, j + 18, k + 15, Block.stoneBrick.blockID);
		var1.setBlock(i + 2, j + 18, k + 16, Block.stoneBrick.blockID);
		var1.setBlock(i + 2, j + 18, k + 17, Block.thinGlass.blockID);
		var1.setBlock(i + 2, j + 18, k + 18, Block.stoneBrick.blockID);
		var1.setBlock(i + 2, j + 18, k + 19, Block.stoneBrick.blockID);
		var1.setBlock(i + 2, j + 18, k + 20, Block.stoneBrick.blockID);
		var1.setBlock(i + 2, j + 18, k + 21, Block.stoneBrick.blockID);
		var1.setBlock(i + 2, j + 19, k + 15, Block.stoneBrick.blockID);
		var1.setBlock(i + 2, j + 19, k + 16, Block.stoneBrick.blockID);
		var1.setBlock(i + 2, j + 19, k + 17, Block.stoneBrick.blockID);
		var1.setBlock(i + 2, j + 19, k + 18, Block.stoneBrick.blockID);
		var1.setBlock(i + 2, j + 19, k + 19, Block.stoneBrick.blockID);
		var1.setBlock(i + 2, j + 19, k + 20, Block.stoneBrick.blockID);
		var1.setBlock(i + 2, j + 19, k + 21, Block.stoneBrick.blockID);
		var1.setBlock(i + 3, j + 2, k + 5, Block.stoneBrick.blockID);
		var1.setBlockMetadataWithNotify(i + 3, j + 2, k + 6, Block.stoneBrick.blockID, 1);
		var1.setBlock(i + 3, j + 2, k + 7, Block.stoneBrick.blockID);
		var1.setBlock(i + 3, j + 2, k + 8, Block.stoneBrick.blockID);
		var1.setBlock(i + 3, j + 2, k + 9, Block.stoneBrick.blockID);
		var1.setBlock(i + 3, j + 2, k + 10, Block.stoneBrick.blockID);
		var1.setBlock(i + 3, j + 2, k + 11, Block.stoneBrick.blockID);
		var1.setBlock(i + 3, j + 2, k + 12, Block.stoneBrick.blockID);
		var1.setBlock(i + 3, j + 2, k + 13, Block.stoneBrick.blockID);
		var1.setBlock(i + 3, j + 2, k + 14, Block.stoneBrick.blockID);
		var1.setBlock(i + 3, j + 2, k + 15, Block.stoneBrick.blockID);
		var1.setBlock(i + 3, j + 2, k + 16, Block.stoneBrick.blockID);
		var1.setBlock(i + 3, j + 2, k + 17, Block.stoneBrick.blockID);
		var1.setBlock(i + 3, j + 2, k + 18, Block.stoneBrick.blockID);
		var1.setBlock(i + 3, j + 2, k + 19, Block.stoneBrick.blockID);
		var1.setBlock(i + 3, j + 2, k + 20, Block.stoneBrick.blockID);
		var1.setBlockMetadataWithNotify(i + 3, j + 2, k + 21, Block.stoneBrick.blockID, 2);
		var1.setBlockMetadataWithNotify(i + 3, j + 2, k + 22, Block.stoneBrick.blockID, 2);
		var1.setBlockMetadataWithNotify(i + 3, j + 2, k + 23, Block.stoneBrick.blockID, 1);
		var1.setBlock(i + 3, j + 2, k + 24, Block.brick.blockID);
		var1.setBlock(i + 3, j + 2, k + 25, Block.brick.blockID);
		var1.setBlockMetadataWithNotify(i + 3, j + 3, k + 5, Block.stoneBrick.blockID, 1);
		var1.setBlockMetadataWithNotify(i + 3, j + 3, k + 15, Block.stoneSingleSlab.blockID, 5);
		var1.setBlock(i + 3, j + 3, k + 16, Block.stoneBrick.blockID);
		var1.setBlock(i + 3, j + 3, k + 17, Block.stoneBrick.blockID);
		var1.setBlock(i + 3, j + 3, k + 18, Block.stoneBrick.blockID);
		var1.setBlock(i + 3, j + 3, k + 19, Block.stoneBrick.blockID);
		var1.setBlock(i + 3, j + 3, k + 20, Block.stoneBrick.blockID);
		var1.setBlockMetadataWithNotify(i + 3, j + 3, k + 21, Block.chest.blockID, 5);
		TileEntityChest var9 = (TileEntityChest)var1.getBlockTileEntity(i + 3, j + 3, k + 21);
        int var10;

        if (var9 != null)
        {
            for (var10 = 0; var10 < 8; ++var10)
            {
                ItemStack var11 = this.pickCheckLootItem(var2);

                if (var11 != null)
                {
                    var9.setInventorySlotContents(var2.nextInt(var9.getSizeInventory()), var11);
                }
            }
        }
		var1.setBlockMetadataWithNotify(i + 3, j + 3, k + 23, Block.chest.blockID, 5);
		var1.setBlock(i + 3, j + 3, k + 24, Block.brick.blockID);
		var1.setBlock(i + 3, j + 3, k + 25, Block.brick.blockID);
		var1.setBlock(i + 3, j + 4, k + 5, Block.stoneBrick.blockID);
		var1.setBlockMetadataWithNotify(i + 3, j + 4, k + 17, Block.stoneSingleSlab.blockID, 5);
		var1.setBlock(i + 3, j + 4, k + 18, Block.stoneBrick.blockID);
		var1.setBlock(i + 3, j + 4, k + 19, Block.stoneBrick.blockID);
		var1.setBlock(i + 3, j + 4, k + 20, Block.stoneBrick.blockID);
		var1.setBlockMetadataWithNotify(i + 3, j + 4, k + 21, Block.chest.blockID, 5);
		var1.setBlockMetadataWithNotify(i + 3, j + 4, k + 23, Block.chest.blockID, 5);
		TileEntityChest var12 = (TileEntityChest)var1.getBlockTileEntity(i + 3, j + 4, k + 23);
        int var13;

        if (var12 != null)
        {
            for (var13 = 0; var13 < 8; ++var13)
            {
                ItemStack var11 = this.pickCheckLootItem(var2);

                if (var11 != null)
                {
                    var12.setInventorySlotContents(var2.nextInt(var12.getSizeInventory()), var11);
                }
            }
        }
		var1.setBlock(i + 3, j + 4, k + 24, Block.brick.blockID);
		var1.setBlock(i + 3, j + 4, k + 25, Block.brick.blockID);
		var1.setBlock(i + 3, j + 5, k + 5, Block.stoneBrick.blockID);
		var1.setBlockMetadataWithNotify(i + 3, j + 5, k + 19, Block.stoneSingleSlab.blockID, 5);
		var1.setBlock(i + 3, j + 5, k + 20, Block.stoneBrick.blockID);
		var1.setBlock(i + 3, j + 5, k + 24, Block.brick.blockID);
		var1.setBlock(i + 3, j + 5, k + 25, Block.brick.blockID);
		var1.setBlock(i + 3, j + 6, k + 4, Block.brick.blockID);
		var1.setBlock(i + 3, j + 6, k + 5, Block.brick.blockID);
		var1.setBlock(i + 3, j + 6, k + 9, Block.glowStone.blockID);
		var1.setBlock(i + 3, j + 6, k + 11, Block.glowStone.blockID);
		var1.setBlockMetadataWithNotify(i + 3, j + 6, k + 21, Block.stoneSingleSlab.blockID, 5);
		var1.setBlock(i + 3, j + 6, k + 22, Block.stoneBrick.blockID);
		var1.setBlock(i + 3, j + 6, k + 23, Block.stoneBrick.blockID);
		var1.setBlock(i + 3, j + 6, k + 24, Block.brick.blockID);
		var1.setBlock(i + 3, j + 6, k + 25, Block.brick.blockID);
		var1.setBlock(i + 3, j + 7, k + 4, Block.brick.blockID);
		var1.setBlock(i + 3, j + 7, k + 5, Block.brick.blockID);
		var1.setBlock(i + 3, j + 7, k + 9, Block.fence.blockID);
		var1.setBlock(i + 3, j + 7, k + 11, Block.fence.blockID);
		var1.setBlock(i + 3, j + 7, k + 24, Block.brick.blockID);
		var1.setBlock(i + 3, j + 7, k + 25, Block.brick.blockID);
		var1.setBlock(i + 3, j + 8, k + 4, Block.web.blockID);
		var1.setBlock(i + 3, j + 8, k + 5, Block.stoneBrick.blockID);
		var1.setBlock(i + 3, j + 8, k + 6, Block.web.blockID);
		var1.setBlock(i + 3, j + 8, k + 17, Block.glowStone.blockID);
		var1.setBlock(i + 3, j + 8, k + 24, Block.brick.blockID);
		var1.setBlock(i + 3, j + 8, k + 25, Block.brick.blockID);
		var1.setBlock(i + 3, j + 9, k + 5, Block.stoneBrick.blockID);
		var1.setBlock(i + 3, j + 9, k + 6, Block.stoneBrick.blockID);
		var1.setBlock(i + 3, j + 9, k + 7, Block.stoneBrick.blockID);
		var1.setBlock(i + 3, j + 9, k + 8, Block.stoneBrick.blockID);
		var1.setBlock(i + 3, j + 9, k + 9, Block.stoneBrick.blockID);
		var1.setBlock(i + 3, j + 9, k + 10, Block.stoneBrick.blockID);
		var1.setBlock(i + 3, j + 9, k + 11, Block.stoneBrick.blockID);
		var1.setBlock(i + 3, j + 9, k + 12, Block.stoneBrick.blockID);
		var1.setBlock(i + 3, j + 9, k + 13, Block.stoneBrick.blockID);
		var1.setBlock(i + 3, j + 9, k + 14, Block.brick.blockID);
		var1.setBlock(i + 3, j + 9, k + 15, Block.brick.blockID);
		var1.setBlock(i + 3, j + 9, k + 16, Block.stoneBrick.blockID);
		var1.setBlock(i + 3, j + 9, k + 17, Block.stoneBrick.blockID);
		var1.setBlock(i + 3, j + 9, k + 18, Block.stoneBrick.blockID);
		var1.setBlockMetadataWithNotify(i + 3, j + 9, k + 19, Block.stoneBrick.blockID, 2);
		var1.setBlock(i + 3, j + 9, k + 20, Block.stoneBrick.blockID);
		var1.setBlock(i + 3, j + 9, k + 24, Block.glowStone.blockID);
		var1.setBlock(i + 3, j + 9, k + 25, Block.brick.blockID);
		var1.setBlock(i + 3, j + 10, k + 5, Block.stoneBrick.blockID);
		var1.setBlock(i + 3, j + 10, k + 6, Block.bookShelf.blockID);
		var1.setBlock(i + 3, j + 10, k + 7, Block.bookShelf.blockID);
		var1.setBlock(i + 3, j + 10, k + 8, Block.stoneBrick.blockID);
		var1.setBlock(i + 3, j + 10, k + 9, Block.bookShelf.blockID);
		var1.setBlock(i + 3, j + 10, k + 10, Block.bookShelf.blockID);
		var1.setBlock(i + 3, j + 10, k + 11, Block.stoneBrick.blockID);
		var1.setBlockMetadataWithNotify(i + 3, j + 10, k + 12, Block.furnaceIdle.blockID, 5);
		var1.setBlockMetadataWithNotify(i + 3, j + 10, k + 17, Block.stoneSingleSlab.blockID, 5);
		var1.setBlock(i + 3, j + 10, k + 18, Block.stoneBrick.blockID);
		var1.setBlock(i + 3, j + 10, k + 19, Block.stoneBrick.blockID);
		var1.setBlock(i + 3, j + 10, k + 20, Block.stoneBrick.blockID);
		var1.setBlock(i + 3, j + 10, k + 21, Block.stoneBrick.blockID);
		var1.setBlock(i + 3, j + 10, k + 22, Block.stoneBrick.blockID);
		var1.setBlock(i + 3, j + 10, k + 23, Block.stoneBrick.blockID);
		var1.setBlock(i + 3, j + 10, k + 24, Block.brick.blockID);
		var1.setBlock(i + 3, j + 10, k + 25, Block.brick.blockID);
		var1.setBlock(i + 3, j + 11, k + 5, Block.stoneBrick.blockID);
		var1.setBlock(i + 3, j + 11, k + 6, Block.bookShelf.blockID);
		var1.setBlock(i + 3, j + 11, k + 7, Block.bookShelf.blockID);
		var1.setBlock(i + 3, j + 11, k + 8, Block.stoneBrick.blockID);
		var1.setBlock(i + 3, j + 11, k + 9, Block.bookShelf.blockID);
		var1.setBlock(i + 3, j + 11, k + 10, Block.bookShelf.blockID);
		var1.setBlockMetadataWithNotify(i + 3, j + 11, k + 11, Block.stoneBrick.blockID, 2);
		var1.setBlockMetadataWithNotify(i + 3, j + 11, k + 19, Block.stoneSingleSlab.blockID, 5);
		var1.setBlock(i + 3, j + 11, k + 20, Block.stoneBrick.blockID);
		var1.setBlock(i + 3, j + 11, k + 21, Block.stoneBrick.blockID);
		var1.setBlock(i + 3, j + 11, k + 22, Block.stoneBrick.blockID);
		var1.setBlock(i + 3, j + 11, k + 23, Block.stoneBrick.blockID);
		var1.setBlock(i + 3, j + 11, k + 24, Block.brick.blockID);
		var1.setBlock(i + 3, j + 11, k + 25, Block.brick.blockID);
		var1.setBlock(i + 3, j + 12, k + 5, Block.stoneBrick.blockID);
		var1.setBlock(i + 3, j + 12, k + 6, Block.bookShelf.blockID);
		var1.setBlock(i + 3, j + 12, k + 7, Block.bookShelf.blockID);
		var1.setBlockMetadataWithNotify(i + 3, j + 12, k + 8, Block.stoneBrick.blockID, 2);
		var1.setBlock(i + 3, j + 12, k + 9, Block.bookShelf.blockID);
		var1.setBlock(i + 3, j + 12, k + 10, Block.bookShelf.blockID);
		var1.setBlock(i + 3, j + 12, k + 11, Block.stoneBrick.blockID);
		var1.setBlock(i + 3, j + 12, k + 15, Block.stoneBrick.blockID);
		var1.setBlockMetadataWithNotify(i + 3, j + 12, k + 21, Block.stoneSingleSlab.blockID, 5);
		var1.setBlock(i + 3, j + 12, k + 22, Block.stoneBrick.blockID);
		var1.setBlock(i + 3, j + 12, k + 23, Block.stoneBrick.blockID);
		var1.setBlock(i + 3, j + 12, k + 24, Block.brick.blockID);
		var1.setBlock(i + 3, j + 12, k + 25, Block.brick.blockID);
		var1.setBlock(i + 3, j + 13, k + 5, Block.stoneBrick.blockID);
		var1.setBlock(i + 3, j + 13, k + 6, Block.stoneBrick.blockID);
		var1.setBlock(i + 3, j + 13, k + 7, Block.stoneBrick.blockID);
		var1.setBlock(i + 3, j + 13, k + 8, Block.stoneBrick.blockID);
		var1.setBlock(i + 3, j + 13, k + 9, Block.stoneBrick.blockID);
		var1.setBlock(i + 3, j + 13, k + 10, Block.stoneBrick.blockID);
		var1.setBlock(i + 3, j + 13, k + 11, Block.stoneBrick.blockID);
		var1.setBlock(i + 3, j + 13, k + 12, Block.glowStone.blockID);
		var1.setBlock(i + 3, j + 13, k + 15, Block.stoneBrick.blockID);
		var1.setBlock(i + 3, j + 13, k + 16, Block.stoneBrick.blockID);
		var1.setBlock(i + 3, j + 13, k + 17, Block.glowStone.blockID);
		var1.setBlock(i + 3, j + 13, k + 24, Block.brick.blockID);
		var1.setBlock(i + 3, j + 13, k + 25, Block.brick.blockID);
		var1.setBlock(i + 3, j + 14, k + 4, Block.stoneBrick.blockID);
		var1.setBlock(i + 3, j + 14, k + 5, Block.stoneBrick.blockID);
		var1.setBlock(i + 3, j + 14, k + 6, Block.stoneBrick.blockID);
		var1.setBlock(i + 3, j + 14, k + 7, Block.stoneBrick.blockID);
		var1.setBlock(i + 3, j + 14, k + 8, Block.stoneBrick.blockID);
		var1.setBlock(i + 3, j + 14, k + 9, Block.stoneBrick.blockID);
		var1.setBlock(i + 3, j + 14, k + 10, Block.stoneBrick.blockID);
		var1.setBlock(i + 3, j + 14, k + 11, Block.stoneBrick.blockID);
		var1.setBlock(i + 3, j + 14, k + 12, Block.stoneBrick.blockID);
		var1.setBlock(i + 3, j + 14, k + 13, Block.stoneBrick.blockID);
		var1.setBlock(i + 3, j + 14, k + 14, Block.stoneBrick.blockID);
		var1.setBlock(i + 3, j + 14, k + 15, Block.stoneBrick.blockID);
		var1.setBlock(i + 3, j + 14, k + 16, Block.stoneBrick.blockID);
		var1.setBlock(i + 3, j + 14, k + 17, Block.stoneBrick.blockID);
		var1.setBlock(i + 3, j + 14, k + 18, Block.stoneBrick.blockID);
		var1.setBlock(i + 3, j + 14, k + 19, Block.stoneBrick.blockID);
		var1.setBlock(i + 3, j + 14, k + 24, Block.brick.blockID);
		var1.setBlock(i + 3, j + 14, k + 25, Block.brick.blockID);
		var1.setBlock(i + 3, j + 15, k + 4, Block.stoneBrick.blockID);
		var1.setBlock(i + 3, j + 15, k + 15, Block.stoneBrick.blockID);
		var1.setBlock(i + 3, j + 15, k + 16, Block.stoneBrick.blockID);
		var1.setBlock(i + 3, j + 15, k + 17, Block.stoneBrick.blockID);
		var1.setBlock(i + 3, j + 15, k + 18, Block.stoneBrick.blockID);
		var1.setBlock(i + 3, j + 15, k + 19, Block.stoneBrick.blockID);
		var1.setBlock(i + 3, j + 15, k + 20, Block.stoneBrick.blockID);
		var1.setBlock(i + 3, j + 15, k + 21, Block.stoneBrick.blockID);
		var1.setBlock(i + 3, j + 15, k + 24, Block.stoneBrick.blockID);
		var1.setBlock(i + 3, j + 15, k + 25, Block.stoneBrick.blockID);
		var1.setBlock(i + 3, j + 16, k + 15, Block.stoneBrick.blockID);
		var1.setBlockMetadataWithNotify(i + 3, j + 16, k + 16, Block.bed.blockID, 9);
		var1.setBlock(i + 3, j + 16, k + 21, Block.stoneBrick.blockID);
		var1.setBlockMetadataWithNotify(i + 3, j + 16, k + 24, Block.stoneBrick.blockID, 2);
		var1.setBlock(i + 3, j + 16, k + 25, Block.stoneBrick.blockID);
		var1.setBlock(i + 3, j + 17, k + 15, Block.stoneBrick.blockID);
		var1.setBlock(i + 3, j + 17, k + 21, Block.stoneBrick.blockID);
		var1.setBlock(i + 3, j + 17, k + 22, Block.stoneBrick.blockID);
		var1.setBlock(i + 3, j + 17, k + 23, Block.stoneBrick.blockID);
		var1.setBlock(i + 3, j + 17, k + 24, Block.stoneBrick.blockID);
		var1.setBlock(i + 3, j + 17, k + 25, Block.stoneBrick.blockID);
		var1.setBlock(i + 3, j + 18, k + 15, Block.stoneBrick.blockID);
		var1.setBlock(i + 3, j + 18, k + 18, Block.glowStone.blockID);
		var1.setBlock(i + 3, j + 18, k + 21, Block.stoneBrick.blockID);
		var1.setBlock(i + 3, j + 18, k + 22, Block.stoneBrick.blockID);
		var1.setBlock(i + 3, j + 18, k + 23, Block.stoneBrick.blockID);
		var1.setBlock(i + 3, j + 18, k + 24, Block.stoneBrick.blockID);
		var1.setBlock(i + 3, j + 18, k + 25, Block.stoneBrick.blockID);
		var1.setBlock(i + 3, j + 19, k + 15, Block.stoneBrick.blockID);
		var1.setBlock(i + 3, j + 19, k + 16, Block.stoneBrick.blockID);
		var1.setBlock(i + 3, j + 19, k + 17, Block.stoneBrick.blockID);
		var1.setBlock(i + 3, j + 19, k + 18, Block.stoneBrick.blockID);
		var1.setBlock(i + 3, j + 19, k + 19, Block.stoneBrick.blockID);
		var1.setBlock(i + 3, j + 19, k + 20, Block.stoneBrick.blockID);
		var1.setBlock(i + 3, j + 19, k + 21, Block.stoneBrick.blockID);
		var1.setBlock(i + 4, j + 2, k + 5, Block.stoneBrick.blockID);
		var1.setBlock(i + 4, j + 2, k + 6, Block.stoneBrick.blockID);
		var1.setBlock(i + 4, j + 2, k + 7, Block.stoneBrick.blockID);
		var1.setBlock(i + 4, j + 2, k + 8, Block.stoneBrick.blockID);
		var1.setBlock(i + 4, j + 2, k + 9, Block.stoneBrick.blockID);
		var1.setBlock(i + 4, j + 2, k + 10, Block.stoneBrick.blockID);
		var1.setBlock(i + 4, j + 2, k + 11, Block.stoneBrick.blockID);
		var1.setBlock(i + 4, j + 2, k + 12, Block.stoneBrick.blockID);
		var1.setBlockMetadataWithNotify(i + 4, j + 2, k + 13, Block.stoneBrick.blockID, 2);
		var1.setBlock(i + 4, j + 2, k + 14, Block.stoneBrick.blockID);
		var1.setBlock(i + 4, j + 2, k + 15, Block.stoneBrick.blockID);
		var1.setBlock(i + 4, j + 2, k + 16, Block.stoneBrick.blockID);
		var1.setBlock(i + 4, j + 2, k + 17, Block.stoneBrick.blockID);
		var1.setBlock(i + 4, j + 2, k + 18, Block.stoneBrick.blockID);
		var1.setBlock(i + 4, j + 2, k + 19, Block.stoneBrick.blockID);
		var1.setBlock(i + 4, j + 2, k + 20, Block.stoneBrick.blockID);
		var1.setBlockMetadataWithNotify(i + 4, j + 2, k + 21, Block.stoneBrick.blockID, 2);
		var1.setBlock(i + 4, j + 2, k + 22, Block.stoneBrick.blockID);
		var1.setBlock(i + 4, j + 2, k + 23, Block.stoneBrick.blockID);
		var1.setBlock(i + 4, j + 2, k + 24, Block.stoneBrick.blockID);
		var1.setBlock(i + 4, j + 3, k + 5, Block.stoneBrick.blockID);
		var1.setBlockMetadataWithNotify(i + 4, j + 3, k + 15, Block.stoneSingleSlab.blockID, 5);
		var1.setBlock(i + 4, j + 3, k + 16, Block.stoneBrick.blockID);
		var1.setBlock(i + 4, j + 3, k + 17, Block.stoneBrick.blockID);
		var1.setBlock(i + 4, j + 3, k + 18, Block.stoneBrick.blockID);
		var1.setBlock(i + 4, j + 3, k + 19, Block.stoneBrick.blockID);
		var1.setBlock(i + 4, j + 3, k + 20, Block.stoneBrick.blockID);
		var1.setBlock(i + 4, j + 3, k + 24, Block.stoneBrick.blockID);
		var1.setBlock(i + 4, j + 4, k + 5, Block.thinGlass.blockID);
		var1.setBlockMetadataWithNotify(i + 4, j + 4, k + 17, Block.stoneSingleSlab.blockID, 5);
		var1.setBlock(i + 4, j + 4, k + 18, Block.stoneBrick.blockID);
		var1.setBlock(i + 4, j + 4, k + 19, Block.stoneBrick.blockID);
		var1.setBlock(i + 4, j + 4, k + 20, Block.stoneBrick.blockID);
		var1.setBlock(i + 4, j + 4, k + 24, Block.stoneBrick.blockID);
		var1.setBlock(i + 4, j + 5, k + 5, Block.thinGlass.blockID);
		var1.setBlockMetadataWithNotify(i + 4, j + 5, k + 19, Block.stoneSingleSlab.blockID, 5);
		var1.setBlock(i + 4, j + 5, k + 20, Block.stoneBrick.blockID);
		var1.setBlock(i + 4, j + 5, k + 24, Block.stoneBrick.blockID);
		var1.setBlock(i + 4, j + 6, k + 4, Block.brick.blockID);
		var1.setBlock(i + 4, j + 6, k + 5, Block.brick.blockID);
		var1.setBlockMetadataWithNotify(i + 4, j + 6, k + 21, Block.stoneSingleSlab.blockID, 5);
		var1.setBlock(i + 4, j + 6, k + 22, Block.stoneBrick.blockID);
		var1.setBlock(i + 4, j + 6, k + 23, Block.stoneBrick.blockID);
		var1.setBlock(i + 4, j + 6, k + 24, Block.stoneBrick.blockID);
		var1.setBlock(i + 4, j + 6, k + 25, Block.stoneBrick.blockID);
		var1.setBlock(i + 4, j + 7, k + 4, Block.brick.blockID);
		var1.setBlock(i + 4, j + 7, k + 5, Block.brick.blockID);
		var1.setBlock(i + 4, j + 7, k + 6, Block.web.blockID);
		var1.setBlock(i + 4, j + 7, k + 25, Block.stoneBrick.blockID);
		var1.setBlock(i + 4, j + 8, k + 5, Block.stoneBrick.blockID);
		var1.setBlock(i + 4, j + 8, k + 25, Block.thinGlass.blockID);
		var1.setBlock(i + 4, j + 9, k + 5, Block.stoneBrick.blockID);
		var1.setBlock(i + 4, j + 9, k + 6, Block.stoneBrick.blockID);
		var1.setBlock(i + 4, j + 9, k + 7, Block.stoneBrick.blockID);
		var1.setBlock(i + 4, j + 9, k + 8, Block.stoneBrick.blockID);
		var1.setBlock(i + 4, j + 9, k + 9, Block.stoneBrick.blockID);
		var1.setBlock(i + 4, j + 9, k + 10, Block.stoneBrick.blockID);
		var1.setBlock(i + 4, j + 9, k + 11, Block.stoneBrick.blockID);
		var1.setBlock(i + 4, j + 9, k + 12, Block.stoneBrick.blockID);
		var1.setBlock(i + 4, j + 9, k + 13, Block.stoneBrick.blockID);
		var1.setBlock(i + 4, j + 9, k + 14, Block.brick.blockID);
		var1.setBlock(i + 4, j + 9, k + 15, Block.brick.blockID);
		var1.setBlock(i + 4, j + 9, k + 16, Block.stoneBrick.blockID);
		var1.setBlockMetadataWithNotify(i + 4, j + 9, k + 17, Block.stoneBrick.blockID, 2);
		var1.setBlock(i + 4, j + 9, k + 18, Block.stoneBrick.blockID);
		var1.setBlock(i + 4, j + 9, k + 19, Block.stoneBrick.blockID);
		var1.setBlock(i + 4, j + 9, k + 20, Block.stoneBrick.blockID);
		var1.setBlock(i + 4, j + 9, k + 25, Block.thinGlass.blockID);
		var1.setBlock(i + 4, j + 10, k + 5, Block.stoneBrick.blockID);
		var1.setBlock(i + 4, j + 10, k + 8, Block.enchantmentTable.blockID);
		var1.setBlock(i + 4, j + 10, k + 16, Block.stoneBrick.blockID);
		var1.setBlock(i + 4, j + 10, k + 17, Block.stoneBrick.blockID);
		var1.setBlock(i + 4, j + 10, k + 18, Block.stoneBrick.blockID);
		var1.setBlock(i + 4, j + 10, k + 19, Block.stoneBrick.blockID);
		var1.setBlock(i + 4, j + 10, k + 20, Block.stoneBrick.blockID);
		var1.setBlock(i + 4, j + 10, k + 21, Block.stoneBrick.blockID);
		var1.setBlock(i + 4, j + 10, k + 22, Block.stoneBrick.blockID);
		var1.setBlock(i + 4, j + 10, k + 23, Block.stoneBrick.blockID);
		var1.setBlock(i + 4, j + 10, k + 24, Block.brick.blockID);
		var1.setBlock(i + 4, j + 10, k + 25, Block.brick.blockID);
		var1.setBlock(i + 4, j + 11, k + 5, Block.thinGlass.blockID);
		var1.setBlock(i + 4, j + 11, k + 16, Block.stoneBrick.blockID);
		var1.setBlock(i + 4, j + 11, k + 17, Block.stoneBrick.blockID);
		var1.setBlock(i + 4, j + 11, k + 18, Block.stoneBrick.blockID);
		var1.setBlockMetadataWithNotify(i + 4, j + 11, k + 19, Block.stoneBrick.blockID, 2);
		var1.setBlock(i + 4, j + 11, k + 20, Block.stoneBrick.blockID);
		var1.setBlock(i + 4, j + 11, k + 21, Block.stoneBrick.blockID);
		var1.setBlock(i + 4, j + 11, k + 22, Block.stoneBrick.blockID);
		var1.setBlock(i + 4, j + 11, k + 23, Block.stoneBrick.blockID);
		var1.setBlock(i + 4, j + 11, k + 24, Block.brick.blockID);
		var1.setBlock(i + 4, j + 11, k + 25, Block.brick.blockID);
		var1.setBlock(i + 4, j + 12, k + 5, Block.thinGlass.blockID);
		var1.setBlock(i + 4, j + 12, k + 15, Block.glowStone.blockID);
		var1.setBlock(i + 4, j + 12, k + 16, Block.stoneBrick.blockID);
		var1.setBlock(i + 4, j + 12, k + 17, Block.stoneBrick.blockID);
		var1.setBlock(i + 4, j + 12, k + 18, Block.stoneBrick.blockID);
		var1.setBlock(i + 4, j + 12, k + 19, Block.stoneBrick.blockID);
		var1.setBlock(i + 4, j + 12, k + 20, Block.stoneBrick.blockID);
		var1.setBlock(i + 4, j + 12, k + 21, Block.stoneBrick.blockID);
		var1.setBlock(i + 4, j + 12, k + 22, Block.stoneBrick.blockID);
		var1.setBlock(i + 4, j + 12, k + 23, Block.stoneBrick.blockID);
		var1.setBlock(i + 4, j + 12, k + 24, Block.brick.blockID);
		var1.setBlock(i + 4, j + 12, k + 25, Block.brick.blockID);
		var1.setBlock(i + 4, j + 13, k + 5, Block.stoneBrick.blockID);
		var1.setBlock(i + 4, j + 13, k + 6, Block.web.blockID);
		var1.setBlock(i + 4, j + 13, k + 15, Block.stoneBrick.blockID);
		var1.setBlock(i + 4, j + 13, k + 16, Block.stoneBrick.blockID);
		var1.setBlock(i + 4, j + 13, k + 17, Block.stoneBrick.blockID);
		var1.setBlock(i + 4, j + 13, k + 18, Block.stoneBrick.blockID);
		var1.setBlock(i + 4, j + 13, k + 19, Block.stoneBrick.blockID);
		var1.setBlock(i + 4, j + 13, k + 20, Block.stoneBrick.blockID);
		var1.setBlock(i + 4, j + 13, k + 21, Block.stoneBrick.blockID);
		var1.setBlockMetadataWithNotify(i + 4, j + 13, k + 22, Block.stoneSingleSlab.blockID, 5);
		var1.setBlockMetadataWithNotify(i + 4, j + 13, k + 23, Block.stoneSingleSlab.blockID, 5);
		var1.setBlock(i + 4, j + 13, k + 24, Block.stoneBrick.blockID);
		var1.setBlock(i + 4, j + 13, k + 25, Block.stoneBrick.blockID);
		var1.setBlock(i + 4, j + 14, k + 4, Block.stoneBrick.blockID);
		var1.setBlock(i + 4, j + 14, k + 5, Block.stoneBrick.blockID);
		var1.setBlock(i + 4, j + 14, k + 6, Block.stoneBrick.blockID);
		var1.setBlock(i + 4, j + 14, k + 7, Block.stoneBrick.blockID);
		var1.setBlock(i + 4, j + 14, k + 8, Block.stoneBrick.blockID);
		var1.setBlock(i + 4, j + 14, k + 9, Block.stoneBrick.blockID);
		var1.setBlock(i + 4, j + 14, k + 10, Block.stoneBrick.blockID);
		var1.setBlock(i + 4, j + 14, k + 11, Block.stoneBrick.blockID);
		var1.setBlock(i + 4, j + 14, k + 12, Block.stoneBrick.blockID);
		var1.setBlock(i + 4, j + 14, k + 13, Block.stoneBrick.blockID);
		var1.setBlock(i + 4, j + 14, k + 14, Block.stoneBrick.blockID);
		var1.setBlock(i + 4, j + 14, k + 15, Block.stoneBrick.blockID);
		var1.setBlock(i + 4, j + 14, k + 16, Block.stoneBrick.blockID);
		var1.setBlock(i + 4, j + 14, k + 17, Block.stoneBrick.blockID);
		var1.setBlock(i + 4, j + 14, k + 18, Block.stoneBrick.blockID);
		var1.setBlock(i + 4, j + 14, k + 19, Block.stoneBrick.blockID);
		var1.setBlock(i + 4, j + 14, k + 20, Block.stoneBrick.blockID);
		var1.setBlock(i + 4, j + 14, k + 21, Block.stoneBrick.blockID);
		var1.setBlock(i + 4, j + 14, k + 24, Block.stoneBrick.blockID);
		var1.setBlock(i + 4, j + 14, k + 25, Block.stoneBrick.blockID);
		var1.setBlock(i + 4, j + 15, k + 4, Block.stoneBrick.blockID);
		var1.setBlock(i + 4, j + 15, k + 15, Block.stoneBrick.blockID);
		var1.setBlock(i + 4, j + 15, k + 16, Block.stoneBrick.blockID);
		var1.setBlock(i + 4, j + 15, k + 17, Block.stoneBrick.blockID);
		var1.setBlock(i + 4, j + 15, k + 18, Block.stoneBrick.blockID);
		var1.setBlock(i + 4, j + 15, k + 19, Block.stoneBrick.blockID);
		var1.setBlock(i + 4, j + 15, k + 20, Block.stoneBrick.blockID);
		var1.setBlock(i + 4, j + 15, k + 21, Block.stoneBrick.blockID);
		var1.setBlock(i + 4, j + 15, k + 24, Block.stoneBrick.blockID);
		var1.setBlock(i + 4, j + 15, k + 25, Block.stoneBrick.blockID);
		var1.setBlock(i + 4, j + 16, k + 15, Block.stoneBrick.blockID);
		var1.setBlockMetadataWithNotify(i + 4, j + 16, k + 16, Block.bed.blockID, 1);
		var1.setBlock(i + 4, j + 16, k + 19, Block.bed.blockID);
		var1.setBlockMetadataWithNotify(i + 4, j + 16, k + 20, Block.bed.blockID, 8);
		var1.setBlock(i + 4, j + 16, k + 21, Block.stoneBrick.blockID);
		var1.setBlock(i + 4, j + 16, k + 24, Block.stoneBrick.blockID);
		var1.setBlock(i + 4, j + 16, k + 25, Block.stoneBrick.blockID);
		var1.setBlock(i + 4, j + 17, k + 15, Block.thinGlass.blockID);
		var1.setBlock(i + 4, j + 17, k + 21, Block.stoneBrick.blockID);
		var1.setBlock(i + 4, j + 17, k + 24, Block.stoneBrick.blockID);
		var1.setBlock(i + 4, j + 17, k + 25, Block.stoneBrick.blockID);
		var1.setBlock(i + 4, j + 18, k + 15, Block.thinGlass.blockID);
		var1.setBlock(i + 4, j + 18, k + 21, Block.stoneBrick.blockID);
		var1.setBlock(i + 4, j + 18, k + 22, Block.stoneBrick.blockID);
		var1.setBlock(i + 4, j + 18, k + 23, Block.stoneBrick.blockID);
		var1.setBlock(i + 4, j + 18, k + 24, Block.stoneBrick.blockID);
		var1.setBlock(i + 4, j + 18, k + 25, Block.stoneBrick.blockID);
		var1.setBlock(i + 4, j + 19, k + 15, Block.stoneBrick.blockID);
		var1.setBlock(i + 4, j + 19, k + 16, Block.stoneBrick.blockID);
		var1.setBlock(i + 4, j + 19, k + 17, Block.stoneBrick.blockID);
		var1.setBlock(i + 4, j + 19, k + 18, Block.stoneBrick.blockID);
		var1.setBlock(i + 4, j + 19, k + 19, Block.stoneBrick.blockID);
		var1.setBlock(i + 4, j + 19, k + 20, Block.stoneBrick.blockID);
		var1.setBlock(i + 4, j + 19, k + 21, Block.stoneBrick.blockID);
		var1.setBlock(i + 4, j + 19, k + 22, Block.stoneBrick.blockID);
		var1.setBlock(i + 4, j + 19, k + 23, Block.stoneBrick.blockID);
		var1.setBlock(i + 4, j + 19, k + 24, Block.stoneBrick.blockID);
		var1.setBlock(i + 4, j + 19, k + 25, Block.stoneBrick.blockID);
		var1.setBlock(i + 5, j + 2, k + 5, Block.stoneBrick.blockID);
		var1.setBlock(i + 5, j + 2, k + 6, Block.stoneBrick.blockID);
		var1.setBlock(i + 5, j + 2, k + 7, Block.stoneBrick.blockID);
		var1.setBlock(i + 5, j + 2, k + 8, Block.stoneDoubleSlab.blockID);
		var1.setBlock(i + 5, j + 2, k + 9, Block.stoneDoubleSlab.blockID);
		var1.setBlock(i + 5, j + 2, k + 10, Block.stoneDoubleSlab.blockID);
		var1.setBlock(i + 5, j + 2, k + 11, Block.stoneDoubleSlab.blockID);
		var1.setBlock(i + 5, j + 2, k + 12, Block.stoneDoubleSlab.blockID);
		var1.setBlock(i + 5, j + 2, k + 13, Block.stoneDoubleSlab.blockID);
		var1.setBlock(i + 5, j + 2, k + 14, Block.brick.blockID);
		var1.setBlock(i + 5, j + 2, k + 15, Block.brick.blockID);
		var1.setBlock(i + 5, j + 2, k + 16, Block.stoneBrick.blockID);
		var1.setBlock(i + 5, j + 2, k + 17, Block.stoneBrick.blockID);
		var1.setBlock(i + 5, j + 2, k + 18, Block.stoneBrick.blockID);
		var1.setBlock(i + 5, j + 2, k + 19, Block.brick.blockID);
		var1.setBlock(i + 5, j + 2, k + 20, Block.stoneBrick.blockID);
		var1.setBlock(i + 5, j + 2, k + 21, Block.stoneBrick.blockID);
		var1.setBlock(i + 5, j + 2, k + 22, Block.stoneBrick.blockID);
		var1.setBlock(i + 5, j + 2, k + 23, Block.stoneBrick.blockID);
		var1.setBlock(i + 5, j + 2, k + 24, Block.stoneBrick.blockID);
		var1.setBlock(i + 5, j + 3, k + 4, Block.brick.blockID);
		var1.setBlock(i + 5, j + 3, k + 5, Block.brick.blockID);
		var1.setBlock(i + 5, j + 3, k + 6, Block.brick.blockID);
		var1.setBlock(i + 5, j + 3, k + 14, Block.brick.blockID);
		var1.setBlock(i + 5, j + 3, k + 15, Block.brick.blockID);
		var1.setBlock(i + 5, j + 3, k + 16, Block.stoneBrick.blockID);
		var1.setBlock(i + 5, j + 3, k + 17, Block.stoneBrick.blockID);
		var1.setBlock(i + 5, j + 3, k + 18, Block.stoneBrick.blockID);
		var1.setBlock(i + 5, j + 3, k + 19, Block.brick.blockID);
		var1.setBlock(i + 5, j + 3, k + 20, Block.brick.blockID);
		var1.setBlockMetadataWithNotify(i + 5, j + 3, k + 23, Block.chest.blockID, 2);
		var1.setBlock(i + 5, j + 3, k + 24, Block.stoneBrick.blockID);
		var1.setBlock(i + 5, j + 4, k + 4, Block.brick.blockID);
		var1.setBlock(i + 5, j + 4, k + 5, Block.brick.blockID);
		var1.setBlock(i + 5, j + 4, k + 6, Block.brick.blockID);
		var1.setBlock(i + 5, j + 4, k + 14, Block.brick.blockID);
		var1.setBlock(i + 5, j + 4, k + 15, Block.brick.blockID);
		var1.setBlock(i + 5, j + 4, k + 16, Block.stoneBrick.blockID);
		var1.setBlock(i + 5, j + 4, k + 17, Block.stoneBrick.blockID);
		var1.setBlock(i + 5, j + 4, k + 18, Block.stoneBrick.blockID);
		var1.setBlock(i + 5, j + 4, k + 19, Block.brick.blockID);
		var1.setBlock(i + 5, j + 4, k + 20, Block.blockClay.blockID);
		var1.setBlockMetadataWithNotify(i + 5, j + 4, k + 23, Block.chest.blockID, 2);
		var1.setBlock(i + 5, j + 4, k + 24, Block.stoneBrick.blockID);
		var1.setBlock(i + 5, j + 5, k + 4, Block.brick.blockID);
		var1.setBlock(i + 5, j + 5, k + 5, Block.brick.blockID);
		var1.setBlock(i + 5, j + 5, k + 6, Block.brick.blockID);
		var1.setBlock(i + 5, j + 5, k + 14, Block.brick.blockID);
		var1.setBlock(i + 5, j + 5, k + 15, Block.brick.blockID);
		var1.setBlock(i + 5, j + 5, k + 16, Block.stoneBrick.blockID);
		var1.setBlock(i + 5, j + 5, k + 17, Block.stoneBrick.blockID);
		var1.setBlock(i + 5, j + 5, k + 18, Block.stoneBrick.blockID);
		var1.setBlock(i + 5, j + 5, k + 19, Block.brick.blockID);
		var1.setBlock(i + 5, j + 5, k + 20, Block.glowStone.blockID);
		var1.setBlock(i + 5, j + 5, k + 24, Block.stoneBrick.blockID);
		var1.setBlock(i + 5, j + 6, k + 4, Block.brick.blockID);
		var1.setBlock(i + 5, j + 6, k + 5, Block.brick.blockID);
		var1.setBlock(i + 5, j + 6, k + 6, Block.brick.blockID);
		var1.setBlock(i + 5, j + 6, k + 14, Block.brick.blockID);
		var1.setBlock(i + 5, j + 6, k + 15, Block.brick.blockID);
		var1.setBlock(i + 5, j + 6, k + 16, Block.stoneBrick.blockID);
		var1.setBlock(i + 5, j + 6, k + 17, Block.stoneBrick.blockID);
		var1.setBlockMetadataWithNotify(i + 5, j + 6, k + 18, Block.stoneBrick.blockID, 2);
		var1.setBlock(i + 5, j + 6, k + 19, Block.brick.blockID);
		var1.setBlock(i + 5, j + 6, k + 20, Block.brick.blockID);
		var1.setBlock(i + 5, j + 6, k + 21, Block.stoneBrick.blockID);
		var1.setBlock(i + 5, j + 6, k + 22, Block.stoneBrick.blockID);
		var1.setBlock(i + 5, j + 6, k + 23, Block.stoneBrick.blockID);
		var1.setBlock(i + 5, j + 6, k + 24, Block.stoneBrick.blockID);
		var1.setBlock(i + 5, j + 6, k + 25, Block.stoneBrick.blockID);
		var1.setBlock(i + 5, j + 7, k + 4, Block.brick.blockID);
		var1.setBlock(i + 5, j + 7, k + 5, Block.brick.blockID);
		var1.setBlock(i + 5, j + 7, k + 6, Block.brick.blockID);
		var1.setBlock(i + 5, j + 7, k + 14, Block.netherrack.blockID);
		var1.setBlock(i + 5, j + 7, k + 15, Block.brick.blockID);
		var1.setBlock(i + 5, j + 7, k + 16, Block.stoneBrick.blockID);
		var1.setBlock(i + 5, j + 7, k + 17, Block.stoneBrick.blockID);
		var1.setBlock(i + 5, j + 7, k + 18, Block.stoneBrick.blockID);
		var1.setBlock(i + 5, j + 7, k + 19, Block.stoneBrick.blockID);
		var1.setBlock(i + 5, j + 7, k + 20, Block.stoneBrick.blockID);
		var1.setBlockMetadataWithNotify(i + 5, j + 7, k + 21, Block.stoneSingleSlab.blockID, 5);
		var1.setBlock(i + 5, j + 7, k + 25, Block.stoneBrick.blockID);
		var1.setBlock(i + 5, j + 8, k + 4, Block.brick.blockID);
		var1.setBlock(i + 5, j + 8, k + 5, Block.brick.blockID);
		var1.setBlock(i + 5, j + 8, k + 6, Block.brick.blockID);
		var1.setBlock(i + 5, j + 8, k + 14, Block.brick.blockID);
		var1.setBlock(i + 5, j + 8, k + 15, Block.brick.blockID);
		var1.setBlock(i + 5, j + 8, k + 16, Block.brick.blockID);
		var1.setBlock(i + 5, j + 8, k + 17, Block.brick.blockID);
		var1.setBlock(i + 5, j + 8, k + 18, Block.stoneBrick.blockID);
		var1.setBlockMetadataWithNotify(i + 5, j + 8, k + 19, Block.stoneSingleSlab.blockID, 5);
		var1.setBlock(i + 5, j + 8, k + 25, Block.thinGlass.blockID);
		var1.setBlock(i + 5, j + 9, k + 4, Block.brick.blockID);
		var1.setBlock(i + 5, j + 9, k + 5, Block.brick.blockID);
		var1.setBlock(i + 5, j + 9, k + 6, Block.brick.blockID);
		var1.setBlock(i + 5, j + 9, k + 7, Block.brick.blockID);
		var1.setBlock(i + 5, j + 9, k + 8, Block.brick.blockID);
		var1.setBlock(i + 5, j + 9, k + 9, Block.brick.blockID);
		var1.setBlock(i + 5, j + 9, k + 10, Block.brick.blockID);
		var1.setBlock(i + 5, j + 9, k + 11, Block.brick.blockID);
		var1.setBlock(i + 5, j + 9, k + 12, Block.brick.blockID);
		var1.setBlock(i + 5, j + 9, k + 13, Block.brick.blockID);
		var1.setBlock(i + 5, j + 9, k + 14, Block.brick.blockID);
		var1.setBlock(i + 5, j + 9, k + 15, Block.brick.blockID);
		var1.setBlock(i + 5, j + 9, k + 16, Block.stoneBrick.blockID);
		var1.setBlockMetadataWithNotify(i + 5, j + 9, k + 17, Block.stoneSingleSlab.blockID, 5);
		var1.setBlock(i + 5, j + 9, k + 25, Block.thinGlass.blockID);
		var1.setBlock(i + 5, j + 10, k + 4, Block.stoneBrick.blockID);
		var1.setBlockMetadataWithNotify(i + 5, j + 10, k + 5, Block.stoneBrick.blockID, 2);
		var1.setBlock(i + 5, j + 10, k + 8, Block.stoneBrick.blockID);
		var1.setBlock(i + 5, j + 10, k + 11, Block.stoneBrick.blockID);
		var1.setBlock(i + 5, j + 10, k + 24, Block.brick.blockID);
		var1.setBlock(i + 5, j + 10, k + 25, Block.brick.blockID);
		var1.setBlockMetadataWithNotify(i + 5, j + 11, k + 4, Block.stoneBrick.blockID, 2);
		var1.setBlock(i + 5, j + 11, k + 5, Block.stoneBrick.blockID);
		var1.setBlock(i + 5, j + 11, k + 22, Block.glowStone.blockID);
		var1.setBlock(i + 5, j + 11, k + 23, Block.stoneBrick.blockID);
		var1.setBlock(i + 5, j + 11, k + 24, Block.brick.blockID);
		var1.setBlock(i + 5, j + 11, k + 25, Block.brick.blockID);
		var1.setBlock(i + 5, j + 12, k + 4, Block.stoneBrick.blockID);
		var1.setBlock(i + 5, j + 12, k + 5, Block.stoneBrick.blockID);
		var1.setBlock(i + 5, j + 12, k + 16, Block.stoneBrick.blockID);
		var1.setBlock(i + 5, j + 12, k + 22, Block.fence.blockID);
		var1.setBlock(i + 5, j + 12, k + 23, Block.stoneBrick.blockID);
		var1.setBlock(i + 5, j + 12, k + 24, Block.brick.blockID);
		var1.setBlock(i + 5, j + 12, k + 25, Block.brick.blockID);
		var1.setBlock(i + 5, j + 13, k + 4, Block.stoneBrick.blockID);
		var1.setBlock(i + 5, j + 13, k + 5, Block.stoneBrick.blockID);
		var1.setBlockMetadataWithNotify(i + 5, j + 13, k + 15, Block.stoneBrick.blockID, 2);
		var1.setBlock(i + 5, j + 13, k + 16, Block.stoneBrick.blockID);
		var1.setBlock(i + 5, j + 13, k + 17, Block.stoneBrick.blockID);
		var1.setBlock(i + 5, j + 13, k + 18, Block.stoneBrick.blockID);
		var1.setBlock(i + 5, j + 13, k + 19, Block.stoneBrick.blockID);
		var1.setBlock(i + 5, j + 13, k + 20, Block.stoneBrick.blockID);
		var1.setBlock(i + 5, j + 13, k + 21, Block.stoneBrick.blockID);
		var1.setBlock(i + 5, j + 13, k + 22, Block.stoneBrick.blockID);
		var1.setBlock(i + 5, j + 13, k + 23, Block.stoneBrick.blockID);
		var1.setBlock(i + 5, j + 13, k + 24, Block.stoneBrick.blockID);
		var1.setBlock(i + 5, j + 13, k + 25, Block.stoneBrick.blockID);
		var1.setBlock(i + 5, j + 14, k + 4, Block.stoneBrick.blockID);
		var1.setBlock(i + 5, j + 14, k + 5, Block.stoneBrick.blockID);
		var1.setBlock(i + 5, j + 14, k + 6, Block.stoneBrick.blockID);
		var1.setBlock(i + 5, j + 14, k + 7, Block.stoneBrick.blockID);
		var1.setBlock(i + 5, j + 14, k + 8, Block.stoneBrick.blockID);
		var1.setBlock(i + 5, j + 14, k + 9, Block.stoneBrick.blockID);
		var1.setBlock(i + 5, j + 14, k + 10, Block.stoneBrick.blockID);
		var1.setBlock(i + 5, j + 14, k + 11, Block.stoneBrick.blockID);
		var1.setBlock(i + 5, j + 14, k + 12, Block.stoneBrick.blockID);
		var1.setBlock(i + 5, j + 14, k + 13, Block.stoneBrick.blockID);
		var1.setBlock(i + 5, j + 14, k + 14, Block.stoneBrick.blockID);
		var1.setBlock(i + 5, j + 14, k + 15, Block.stoneBrick.blockID);
		var1.setBlock(i + 5, j + 14, k + 16, Block.stoneBrick.blockID);
		var1.setBlock(i + 5, j + 14, k + 17, Block.stoneBrick.blockID);
		var1.setBlock(i + 5, j + 14, k + 18, Block.stoneBrick.blockID);
		var1.setBlock(i + 5, j + 14, k + 19, Block.stoneBrick.blockID);
		var1.setBlock(i + 5, j + 14, k + 20, Block.stoneBrick.blockID);
		var1.setBlock(i + 5, j + 14, k + 21, Block.stoneBrick.blockID);
		var1.setBlock(i + 5, j + 14, k + 24, Block.stoneBrick.blockID);
		var1.setBlock(i + 5, j + 14, k + 25, Block.stoneBrick.blockID);
		var1.setBlock(i + 5, j + 15, k + 4, Block.stoneBrick.blockID);
		var1.setBlock(i + 5, j + 15, k + 15, Block.stoneBrick.blockID);
		var1.setBlock(i + 5, j + 15, k + 16, Block.stoneBrick.blockID);
		var1.setBlock(i + 5, j + 15, k + 17, Block.stoneBrick.blockID);
		var1.setBlock(i + 5, j + 15, k + 18, Block.stoneBrick.blockID);
		var1.setBlock(i + 5, j + 15, k + 19, Block.stoneBrick.blockID);
		var1.setBlock(i + 5, j + 15, k + 20, Block.stoneBrick.blockID);
		var1.setBlock(i + 5, j + 15, k + 21, Block.stoneBrick.blockID);
		var1.setBlock(i + 5, j + 15, k + 25, Block.stoneBrick.blockID);
		var1.setBlock(i + 5, j + 16, k + 15, Block.stoneBrick.blockID);
		var1.setBlock(i + 5, j + 16, k + 21, Block.stoneBrick.blockID);
		var1.setBlock(i + 5, j + 16, k + 24, Block.stoneBrick.blockID);
		var1.setBlock(i + 5, j + 16, k + 25, Block.stoneBrick.blockID);
		var1.setBlock(i + 5, j + 17, k + 15, Block.stoneBrick.blockID);
		var1.setBlock(i + 5, j + 17, k + 21, Block.stoneBrick.blockID);
		var1.setBlock(i + 5, j + 17, k + 24, Block.stoneBrick.blockID);
		var1.setBlock(i + 5, j + 17, k + 25, Block.stoneBrick.blockID);
		var1.setBlock(i + 5, j + 18, k + 15, Block.stoneBrick.blockID);
		var1.setBlock(i + 5, j + 18, k + 21, Block.stoneBrick.blockID);
		var1.setBlock(i + 5, j + 18, k + 24, Block.stoneBrick.blockID);
		var1.setBlock(i + 5, j + 18, k + 25, Block.stoneBrick.blockID);
		var1.setBlock(i + 5, j + 19, k + 15, Block.stoneBrick.blockID);
		var1.setBlock(i + 5, j + 19, k + 16, Block.stoneBrick.blockID);
		var1.setBlock(i + 5, j + 19, k + 17, Block.stoneBrick.blockID);
		var1.setBlock(i + 5, j + 19, k + 18, Block.stoneBrick.blockID);
		var1.setBlock(i + 5, j + 19, k + 19, Block.stoneBrick.blockID);
		var1.setBlock(i + 5, j + 19, k + 20, Block.stoneBrick.blockID);
		var1.setBlock(i + 5, j + 19, k + 21, Block.stoneBrick.blockID);
		var1.setBlock(i + 5, j + 19, k + 22, Block.stoneBrick.blockID);
		var1.setBlock(i + 5, j + 19, k + 23, Block.stoneBrick.blockID);
		var1.setBlock(i + 5, j + 19, k + 24, Block.stoneBrick.blockID);
		var1.setBlock(i + 5, j + 19, k + 25, Block.stoneBrick.blockID);

		generate2(var1, var2, i, j, k);
		return true;
	}

	public boolean generate2(World var1, Random var2, int i, int j, int k) 
	{
		var1.setBlock(i + 6, j + 2, k + 5, Block.stoneBrick.blockID);
		var1.setBlock(i + 6, j + 2, k + 6, Block.stoneBrick.blockID);
		var1.setBlock(i + 6, j + 2, k + 7, Block.stoneBrick.blockID);
		var1.setBlock(i + 6, j + 2, k + 8, Block.stoneDoubleSlab.blockID);
		var1.setBlock(i + 6, j + 2, k + 9, Block.stoneDoubleSlab.blockID);
		var1.setBlock(i + 6, j + 2, k + 10, Block.stoneDoubleSlab.blockID);
		var1.setBlock(i + 6, j + 2, k + 11, Block.stoneDoubleSlab.blockID);
		var1.setBlock(i + 6, j + 2, k + 12, Block.stoneDoubleSlab.blockID);
		var1.setBlock(i + 6, j + 2, k + 13, Block.stoneDoubleSlab.blockID);
		var1.setBlock(i + 6, j + 2, k + 14, Block.brick.blockID);
		var1.setBlock(i + 6, j + 2, k + 15, Block.brick.blockID);
		var1.setBlock(i + 6, j + 2, k + 16, Block.stoneBrick.blockID);
		var1.setBlock(i + 6, j + 2, k + 17, Block.stoneBrick.blockID);
		var1.setBlock(i + 6, j + 2, k + 18, Block.stoneBrick.blockID);
		var1.setBlock(i + 6, j + 2, k + 19, Block.brick.blockID);
		var1.setBlock(i + 6, j + 2, k + 20, Block.brick.blockID);
		var1.setBlock(i + 6, j + 2, k + 21, Block.stoneBrick.blockID);
		var1.setBlockMetadataWithNotify(i + 6, j + 2, k + 22, Block.stoneBrick.blockID, 2);
		var1.setBlock(i + 6, j + 2, k + 23, Block.stoneBrick.blockID);
		var1.setBlock(i + 6, j + 2, k + 24, Block.stoneBrick.blockID);
		var1.setBlock(i + 6, j + 3, k + 4, Block.brick.blockID);
		var1.setBlock(i + 6, j + 3, k + 5, Block.brick.blockID);
		var1.setBlock(i + 6, j + 3, k + 6, Block.brick.blockID);
		var1.setBlock(i + 6, j + 3, k + 14, Block.brick.blockID);
		var1.setBlock(i + 6, j + 3, k + 15, Block.brick.blockID);
		var1.setBlock(i + 6, j + 3, k + 19, Block.brick.blockID);
		var1.setBlock(i + 6, j + 3, k + 20, Block.brick.blockID);
		var1.setBlockMetadataWithNotify(i + 6, j + 3, k + 23, Block.chest.blockID, 2);
		var1.setBlock(i + 6, j + 3, k + 24, Block.stoneBrick.blockID);
		var1.setBlock(i + 6, j + 4, k + 4, Block.brick.blockID);
		var1.setBlock(i + 6, j + 4, k + 5, Block.brick.blockID);
		var1.setBlock(i + 6, j + 4, k + 6, Block.brick.blockID);
		var1.setBlock(i + 6, j + 4, k + 14, Block.brick.blockID);
		var1.setBlock(i + 6, j + 4, k + 15, Block.brick.blockID);
		var1.setBlock(i + 6, j + 4, k + 19, Block.brick.blockID);
		var1.setBlock(i + 6, j + 4, k + 20, Block.brick.blockID);
		var1.setBlockMetadataWithNotify(i + 6, j + 4, k + 23, Block.chest.blockID, 2);
		var1.setBlock(i + 6, j + 4, k + 24, Block.stoneBrick.blockID);
		var1.setBlock(i + 6, j + 5, k + 4, Block.brick.blockID);
		var1.setBlock(i + 6, j + 5, k + 5, Block.brick.blockID);
		var1.setBlock(i + 6, j + 5, k + 6, Block.brick.blockID);
		var1.setBlock(i + 6, j + 5, k + 14, Block.brick.blockID);
		var1.setBlock(i + 6, j + 5, k + 15, Block.brick.blockID);
		var1.setBlock(i + 6, j + 5, k + 19, Block.brick.blockID);
		var1.setBlock(i + 6, j + 5, k + 20, Block.brick.blockID);
		var1.setBlock(i + 6, j + 5, k + 24, Block.stoneBrick.blockID);
		var1.setBlock(i + 6, j + 6, k + 4, Block.brick.blockID);
		var1.setBlock(i + 6, j + 6, k + 5, Block.brick.blockID);
		var1.setBlock(i + 6, j + 6, k + 6, Block.brick.blockID);
		var1.setBlock(i + 6, j + 6, k + 7, Block.glowStone.blockID);
		var1.setBlock(i + 6, j + 6, k + 14, Block.netherrack.blockID);
		var1.setBlock(i + 6, j + 6, k + 15, Block.brick.blockID);
		var1.setBlock(i + 6, j + 6, k + 19, Block.brick.blockID);
		var1.setBlock(i + 6, j + 6, k + 20, Block.brick.blockID);
		var1.setBlock(i + 6, j + 6, k + 21, Block.stoneBrick.blockID);
		var1.setBlock(i + 6, j + 6, k + 22, Block.stoneBrick.blockID);
		var1.setBlock(i + 6, j + 6, k + 23, Block.stoneBrick.blockID);
		var1.setBlock(i + 6, j + 6, k + 24, Block.stoneBrick.blockID);
		var1.setBlock(i + 6, j + 6, k + 25, Block.stoneBrick.blockID);
		var1.setBlock(i + 6, j + 7, k + 4, Block.brick.blockID);
		var1.setBlock(i + 6, j + 7, k + 5, Block.brick.blockID);
		var1.setBlock(i + 6, j + 7, k + 6, Block.brick.blockID);
		var1.setBlock(i + 6, j + 7, k + 7, Block.fence.blockID);
		var1.setBlock(i + 6, j + 7, k + 14, Block.netherrack.blockID);
		var1.setBlock(i + 6, j + 7, k + 15, Block.brick.blockID);
		var1.setBlock(i + 6, j + 7, k + 19, Block.brick.blockID);
		var1.setBlock(i + 6, j + 7, k + 20, Block.stoneBrick.blockID);
		var1.setBlockMetadataWithNotify(i + 6, j + 7, k + 21, Block.stoneSingleSlab.blockID, 5);
		var1.setBlock(i + 6, j + 7, k + 25, Block.stoneBrick.blockID);
		var1.setBlock(i + 6, j + 8, k + 4, Block.brick.blockID);
		var1.setBlock(i + 6, j + 8, k + 5, Block.brick.blockID);
		var1.setBlock(i + 6, j + 8, k + 6, Block.brick.blockID);
		var1.setBlock(i + 6, j + 8, k + 14, Block.brick.blockID);
		var1.setBlock(i + 6, j + 8, k + 15, Block.brick.blockID);
		var1.setBlock(i + 6, j + 8, k + 16, Block.brick.blockID);
		var1.setBlock(i + 6, j + 8, k + 17, Block.brick.blockID);
		var1.setBlock(i + 6, j + 8, k + 18, Block.stoneBrick.blockID);
		var1.setBlockMetadataWithNotify(i + 6, j + 8, k + 19, Block.stoneSingleSlab.blockID, 5);
		var1.setBlock(i + 6, j + 8, k + 25, Block.thinGlass.blockID);
		var1.setBlock(i + 6, j + 9, k + 4, Block.brick.blockID);
		var1.setBlock(i + 6, j + 9, k + 5, Block.brick.blockID);
		var1.setBlock(i + 6, j + 9, k + 6, Block.brick.blockID);
		var1.setBlock(i + 6, j + 9, k + 7, Block.brick.blockID);
		var1.setBlock(i + 6, j + 9, k + 8, Block.brick.blockID);
		var1.setBlock(i + 6, j + 9, k + 9, Block.brick.blockID);
		var1.setBlock(i + 6, j + 9, k + 10, Block.brick.blockID);
		var1.setBlock(i + 6, j + 9, k + 11, Block.brick.blockID);
		var1.setBlock(i + 6, j + 9, k + 12, Block.brick.blockID);
		var1.setBlock(i + 6, j + 9, k + 13, Block.brick.blockID);
		var1.setBlock(i + 6, j + 9, k + 14, Block.netherrack.blockID);
		var1.setBlock(i + 6, j + 9, k + 15, Block.brick.blockID);
		var1.setBlock(i + 6, j + 9, k + 16, Block.stoneBrick.blockID);
		var1.setBlockMetadataWithNotify(i + 6, j + 9, k + 17, Block.stoneSingleSlab.blockID, 5);
		var1.setBlock(i + 6, j + 9, k + 25, Block.thinGlass.blockID);
		var1.setBlock(i + 6, j + 10, k + 4, Block.stoneBrick.blockID);
		var1.setBlock(i + 6, j + 10, k + 5, Block.stoneBrick.blockID);
		var1.setBlockMetadataWithNotify(i + 6, j + 10, k + 8, Block.stoneBrick.blockID, 2);
		var1.setBlock(i + 6, j + 10, k + 11, Block.stoneBrick.blockID);
		var1.setBlock(i + 6, j + 10, k + 24, Block.brick.blockID);
		var1.setBlock(i + 6, j + 10, k + 25, Block.brick.blockID);
		var1.setBlock(i + 6, j + 11, k + 4, Block.stoneBrick.blockID);
		var1.setBlockMetadataWithNotify(i + 6, j + 11, k + 5, Block.stoneBrick.blockID, 2);
		var1.setBlock(i + 6, j + 11, k + 23, Block.stoneBrick.blockID);
		var1.setBlock(i + 6, j + 11, k + 24, Block.brick.blockID);
		var1.setBlock(i + 6, j + 11, k + 25, Block.brick.blockID);
		var1.setBlock(i + 6, j + 12, k + 4, Block.stoneBrick.blockID);
		var1.setBlock(i + 6, j + 12, k + 5, Block.stoneBrick.blockID);
		var1.setBlock(i + 6, j + 12, k + 16, Block.stoneBrick.blockID);
		var1.setBlock(i + 6, j + 12, k + 19, Block.web.blockID);
		var1.setBlock(i + 6, j + 12, k + 23, Block.stoneBrick.blockID);
		var1.setBlock(i + 6, j + 12, k + 24, Block.brick.blockID);
		var1.setBlock(i + 6, j + 12, k + 25, Block.brick.blockID);
		var1.setBlock(i + 6, j + 13, k + 4, Block.stoneBrick.blockID);
		var1.setBlock(i + 6, j + 13, k + 5, Block.stoneBrick.blockID);
		var1.setBlock(i + 6, j + 13, k + 15, Block.stoneBrick.blockID);
		var1.setBlock(i + 6, j + 13, k + 16, Block.stoneBrick.blockID);
		var1.setBlock(i + 6, j + 13, k + 17, Block.stoneBrick.blockID);
		var1.setBlock(i + 6, j + 13, k + 18, Block.stoneBrick.blockID);
		var1.setBlock(i + 6, j + 13, k + 19, Block.stoneBrick.blockID);
		var1.setBlock(i + 6, j + 13, k + 20, Block.stoneBrick.blockID);
		var1.setBlock(i + 6, j + 13, k + 21, Block.stoneBrick.blockID);
		var1.setBlock(i + 6, j + 13, k + 22, Block.stoneBrick.blockID);
		var1.setBlock(i + 6, j + 13, k + 23, Block.stoneBrick.blockID);
		var1.setBlock(i + 6, j + 13, k + 24, Block.stoneBrick.blockID);
		var1.setBlock(i + 6, j + 13, k + 25, Block.stoneBrick.blockID);
		var1.setBlock(i + 6, j + 14, k + 4, Block.stoneBrick.blockID);
		var1.setBlock(i + 6, j + 14, k + 5, Block.stoneBrick.blockID);
		var1.setBlock(i + 6, j + 14, k + 6, Block.stoneBrick.blockID);
		var1.setBlock(i + 6, j + 14, k + 7, Block.stoneBrick.blockID);
		var1.setBlock(i + 6, j + 14, k + 8, Block.stoneBrick.blockID);
		var1.setBlock(i + 6, j + 14, k + 9, Block.stoneBrick.blockID);
		var1.setBlock(i + 6, j + 14, k + 10, Block.stoneBrick.blockID);
		var1.setBlock(i + 6, j + 14, k + 11, Block.stoneBrick.blockID);
		var1.setBlock(i + 6, j + 14, k + 12, Block.stoneBrick.blockID);
		var1.setBlock(i + 6, j + 14, k + 13, Block.stoneBrick.blockID);
		var1.setBlock(i + 6, j + 14, k + 14, Block.stoneBrick.blockID);
		var1.setBlock(i + 6, j + 14, k + 15, Block.stoneBrick.blockID);
		var1.setBlock(i + 6, j + 14, k + 16, Block.stoneBrick.blockID);
		var1.setBlock(i + 6, j + 14, k + 17, Block.stoneBrick.blockID);
		var1.setBlock(i + 6, j + 14, k + 18, Block.stoneBrick.blockID);
		var1.setBlock(i + 6, j + 14, k + 19, Block.stoneBrick.blockID);
		var1.setBlock(i + 6, j + 14, k + 20, Block.stoneBrick.blockID);
		var1.setBlock(i + 6, j + 14, k + 21, Block.stoneBrick.blockID);
		var1.setBlockMetadataWithNotify(i + 6, j + 14, k + 22, Block.stoneSingleSlab.blockID, 5);
		var1.setBlockMetadataWithNotify(i + 6, j + 14, k + 23, Block.stoneSingleSlab.blockID, 5);
		var1.setBlock(i + 6, j + 14, k + 24, Block.stoneBrick.blockID);
		var1.setBlock(i + 6, j + 14, k + 25, Block.stoneBrick.blockID);
		var1.setBlock(i + 6, j + 15, k + 4, Block.stoneBrick.blockID);
		var1.setBlock(i + 6, j + 15, k + 14, Block.stoneBrick.blockID);
		var1.setBlock(i + 6, j + 15, k + 15, Block.stoneBrick.blockID);
		var1.setBlock(i + 6, j + 15, k + 16, Block.stoneBrick.blockID);
		var1.setBlock(i + 6, j + 15, k + 17, Block.stoneBrick.blockID);
		var1.setBlock(i + 6, j + 15, k + 18, Block.stoneBrick.blockID);
		var1.setBlock(i + 6, j + 15, k + 19, Block.stoneBrick.blockID);
		var1.setBlock(i + 6, j + 15, k + 20, Block.stoneBrick.blockID);
		var1.setBlock(i + 6, j + 15, k + 21, Block.stoneBrick.blockID);
		var1.setBlock(i + 6, j + 15, k + 24, Block.stoneBrick.blockID);
		var1.setBlock(i + 6, j + 15, k + 25, Block.stoneBrick.blockID);
		var1.setBlock(i + 6, j + 16, k + 14, Block.stoneBrick.blockID);
		var1.setBlock(i + 6, j + 16, k + 15, Block.stoneBrick.blockID);
		var1.setBlock(i + 6, j + 16, k + 19, Block.bed.blockID);
		var1.setBlockMetadataWithNotify(i + 6, j + 16, k + 20, Block.bed.blockID, 8);
		var1.setBlock(i + 6, j + 16, k + 21, Block.stoneBrick.blockID);
		var1.setBlock(i + 6, j + 16, k + 24, Block.stoneBrick.blockID);
		var1.setBlock(i + 6, j + 16, k + 25, Block.stoneBrick.blockID);
		var1.setBlock(i + 6, j + 17, k + 14, Block.stoneBrick.blockID);
		var1.setBlock(i + 6, j + 17, k + 15, Block.stoneBrick.blockID);
		var1.setBlock(i + 6, j + 17, k + 21, Block.stoneBrick.blockID);
		var1.setBlock(i + 6, j + 17, k + 24, Block.stoneBrick.blockID);
		var1.setBlock(i + 6, j + 17, k + 25, Block.stoneBrick.blockID);
		var1.setBlock(i + 6, j + 18, k + 14, Block.stoneBrick.blockID);
		var1.setBlock(i + 6, j + 18, k + 15, Block.stoneBrick.blockID);
		var1.setBlock(i + 6, j + 18, k + 21, Block.stoneBrick.blockID);
		var1.setBlock(i + 6, j + 18, k + 24, Block.stoneBrick.blockID);
		var1.setBlock(i + 6, j + 18, k + 25, Block.stoneBrick.blockID);
		var1.setBlock(i + 6, j + 19, k + 14, Block.stoneBrick.blockID);
		var1.setBlock(i + 6, j + 19, k + 15, Block.stoneBrick.blockID);
		var1.setBlock(i + 6, j + 19, k + 16, Block.stoneBrick.blockID);
		var1.setBlock(i + 6, j + 19, k + 17, Block.stoneBrick.blockID);
		var1.setBlock(i + 6, j + 19, k + 18, Block.stoneBrick.blockID);
		var1.setBlock(i + 6, j + 19, k + 19, Block.stoneBrick.blockID);
		var1.setBlock(i + 6, j + 19, k + 20, Block.stoneBrick.blockID);
		var1.setBlock(i + 6, j + 19, k + 21, Block.stoneBrick.blockID);
		var1.setBlock(i + 6, j + 19, k + 22, Block.stoneBrick.blockID);
		var1.setBlock(i + 6, j + 19, k + 23, Block.stoneBrick.blockID);
		var1.setBlock(i + 6, j + 19, k + 24, Block.stoneBrick.blockID);
		var1.setBlock(i + 6, j + 19, k + 25, Block.stoneBrick.blockID);
		var1.setBlock(i + 6, j + 20, k + 14, Block.stoneBrick.blockID);
		var1.setBlock(i + 6, j + 20, k + 15, Block.stoneBrick.blockID);
		var1.setBlock(i + 6, j + 20, k + 16, Block.stoneBrick.blockID);
		var1.setBlock(i + 6, j + 20, k + 17, Block.stoneBrick.blockID);
		var1.setBlock(i + 6, j + 20, k + 18, Block.stoneBrick.blockID);
		var1.setBlock(i + 6, j + 20, k + 19, Block.stoneBrick.blockID);
		var1.setBlock(i + 6, j + 20, k + 20, Block.stoneBrick.blockID);
		var1.setBlock(i + 6, j + 20, k + 21, Block.stoneBrick.blockID);
		var1.setBlock(i + 6, j + 20, k + 22, Block.stoneBrick.blockID);
		var1.setBlock(i + 6, j + 20, k + 23, Block.stoneBrick.blockID);
		var1.setBlock(i + 6, j + 20, k + 24, Block.stoneBrick.blockID);
		var1.setBlock(i + 6, j + 20, k + 25, Block.stoneBrick.blockID);
		var1.setBlock(i + 7, j + 1, k + 10, Block.stoneBrick.blockID);
		var1.setBlock(i + 7, j + 2, k + 5, Block.stoneBrick.blockID);
		var1.setBlock(i + 7, j + 2, k + 6, Block.stoneBrick.blockID);
		var1.setBlock(i + 7, j + 2, k + 7, Block.stoneBrick.blockID);
		var1.setBlock(i + 7, j + 2, k + 8, Block.stoneDoubleSlab.blockID);
		var1.setBlock(i + 7, j + 2, k + 9, Block.stoneDoubleSlab.blockID);
		var1.setBlock(i + 7, j + 2, k + 10, Block.stoneDoubleSlab.blockID);
		var1.setBlock(i + 7, j + 2, k + 11, Block.stoneDoubleSlab.blockID);
		var1.setBlock(i + 7, j + 2, k + 12, Block.stoneDoubleSlab.blockID);
		var1.setBlock(i + 7, j + 2, k + 13, Block.stoneDoubleSlab.blockID);
		var1.setBlock(i + 7, j + 2, k + 14, Block.stoneDoubleSlab.blockID);
		var1.setBlock(i + 7, j + 2, k + 15, Block.stoneDoubleSlab.blockID);
		var1.setBlock(i + 7, j + 2, k + 16, Block.stoneBrick.blockID);
		var1.setBlock(i + 7, j + 2, k + 17, Block.stoneBrick.blockID);
		var1.setBlock(i + 7, j + 2, k + 18, Block.stoneBrick.blockID);
		var1.setBlock(i + 7, j + 2, k + 19, Block.stoneBrick.blockID);
		var1.setBlock(i + 7, j + 2, k + 20, Block.stoneBrick.blockID);
		var1.setBlock(i + 7, j + 2, k + 21, Block.stoneBrick.blockID);
		var1.setBlock(i + 7, j + 2, k + 22, Block.stoneBrick.blockID);
		var1.setBlock(i + 7, j + 2, k + 23, Block.brick.blockID);
		var1.setBlock(i + 7, j + 2, k + 24, Block.brick.blockID);
		var1.setBlock(i + 7, j + 2, k + 25, Block.brick.blockID);
		var1.setBlock(i + 7, j + 2, k + 26, Block.grass.blockID);
		var1.setBlock(i + 7, j + 3, k + 5, Block.stoneBrick.blockID);
		var1.setBlock(i + 7, j + 3, k + 11, Block.stoneDoubleSlab.blockID);
		var1.setBlock(i + 7, j + 3, k + 12, Block.stoneDoubleSlab.blockID);
		var1.setBlock(i + 7, j + 3, k + 14, Block.stoneDoubleSlab.blockID);
		var1.setBlockMetadataWithNotify(i + 7, j + 3, k + 15, Block.furnaceIdle.blockID, 5);
		var1.setBlock(i + 7, j + 3, k + 23, Block.brick.blockID);
		var1.setBlock(i + 7, j + 3, k + 24, Block.brick.blockID);
		var1.setBlock(i + 7, j + 3, k + 25, Block.brick.blockID);
		var1.setBlock(i + 7, j + 4, k + 5, Block.thinGlass.blockID);
		var1.setBlock(i + 7, j + 4, k + 14, Block.stoneDoubleSlab.blockID);
		var1.setBlockMetadataWithNotify(i + 7, j + 4, k + 15, Block.furnaceIdle.blockID, 5);
		var1.setBlock(i + 7, j + 4, k + 23, Block.brick.blockID);
		var1.setBlock(i + 7, j + 4, k + 24, Block.brick.blockID);
		var1.setBlock(i + 7, j + 4, k + 25, Block.brick.blockID);
		var1.setBlock(i + 7, j + 5, k + 5, Block.thinGlass.blockID);
		var1.setBlock(i + 7, j + 5, k + 23, Block.brick.blockID);
		var1.setBlock(i + 7, j + 5, k + 24, Block.brick.blockID);
		var1.setBlock(i + 7, j + 5, k + 25, Block.brick.blockID);
		var1.setBlock(i + 7, j + 6, k + 4, Block.brick.blockID);
		var1.setBlock(i + 7, j + 6, k + 5, Block.brick.blockID);
		var1.setBlock(i + 7, j + 6, k + 14, Block.glowStone.blockID);
		var1.setBlock(i + 7, j + 6, k + 19, Block.glowStone.blockID);
		var1.setBlock(i + 7, j + 6, k + 20, Block.stoneBrick.blockID);
		var1.setBlock(i + 7, j + 6, k + 21, Block.stoneBrick.blockID);
		var1.setBlock(i + 7, j + 6, k + 22, Block.stoneBrick.blockID);
		var1.setBlock(i + 7, j + 6, k + 23, Block.brick.blockID);
		var1.setBlock(i + 7, j + 6, k + 24, Block.brick.blockID);
		var1.setBlock(i + 7, j + 6, k + 25, Block.brick.blockID);
		var1.setBlock(i + 7, j + 7, k + 4, Block.brick.blockID);
		var1.setBlock(i + 7, j + 7, k + 5, Block.brick.blockID);
		var1.setBlock(i + 7, j + 7, k + 14, Block.fence.blockID);
		var1.setBlock(i + 7, j + 7, k + 19, Block.fence.blockID);
		var1.setBlock(i + 7, j + 7, k + 20, Block.stoneBrick.blockID);
		var1.setBlock(i + 7, j + 7, k + 21, Block.stoneBrick.blockID);
		var1.setBlock(i + 7, j + 7, k + 22, Block.thinGlass.blockID);
		var1.setBlock(i + 7, j + 7, k + 23, Block.brick.blockID);
		var1.setBlock(i + 7, j + 7, k + 24, Block.brick.blockID);
		var1.setBlock(i + 7, j + 7, k + 25, Block.brick.blockID);
		var1.setBlock(i + 7, j + 8, k + 5, Block.stoneBrick.blockID);
		var1.setBlock(i + 7, j + 8, k + 18, Block.stoneBrick.blockID);
		var1.setBlock(i + 7, j + 8, k + 19, Block.stoneBrick.blockID);
		var1.setBlock(i + 7, j + 8, k + 20, Block.stoneBrick.blockID);
		var1.setBlock(i + 7, j + 8, k + 21, Block.thinGlass.blockID);
		var1.setBlock(i + 7, j + 8, k + 22, Block.thinGlass.blockID);
		var1.setBlock(i + 7, j + 8, k + 23, Block.brick.blockID);
		var1.setBlock(i + 7, j + 8, k + 24, Block.brick.blockID);
		var1.setBlock(i + 7, j + 8, k + 25, Block.brick.blockID);
		var1.setBlock(i + 7, j + 9, k + 5, Block.stoneBrick.blockID);
		var1.setBlock(i + 7, j + 9, k + 6, Block.stoneBrick.blockID);
		var1.setBlock(i + 7, j + 9, k + 7, Block.stoneBrick.blockID);
		var1.setBlock(i + 7, j + 9, k + 8, Block.stoneBrick.blockID);
		var1.setBlock(i + 7, j + 9, k + 9, Block.stoneBrick.blockID);
		var1.setBlock(i + 7, j + 9, k + 10, Block.stoneBrick.blockID);
		var1.setBlock(i + 7, j + 9, k + 11, Block.stoneBrick.blockID);
		var1.setBlock(i + 7, j + 9, k + 12, Block.stoneBrick.blockID);
		var1.setBlock(i + 7, j + 9, k + 13, Block.stoneBrick.blockID);
		var1.setBlock(i + 7, j + 9, k + 14, Block.brick.blockID);
		var1.setBlock(i + 7, j + 9, k + 15, Block.brick.blockID);
		var1.setBlock(i + 7, j + 9, k + 16, Block.stoneBrick.blockID);
		var1.setBlock(i + 7, j + 9, k + 17, Block.stoneBrick.blockID);
		var1.setBlock(i + 7, j + 9, k + 18, Block.stoneBrick.blockID);
		var1.setBlock(i + 7, j + 9, k + 19, Block.stoneBrick.blockID);
		var1.setBlock(i + 7, j + 9, k + 20, Block.stoneBrick.blockID);
		var1.setBlock(i + 7, j + 9, k + 21, Block.thinGlass.blockID);
		var1.setBlock(i + 7, j + 9, k + 22, Block.thinGlass.blockID);
		var1.setBlock(i + 7, j + 9, k + 23, Block.brick.blockID);
		var1.setBlock(i + 7, j + 9, k + 24, Block.brick.blockID);
		var1.setBlock(i + 7, j + 9, k + 25, Block.brick.blockID);
		var1.setBlock(i + 7, j + 10, k + 5, Block.stoneBrick.blockID);
		var1.setBlockMetadataWithNotify(i + 7, j + 10, k + 8, Block.chest.blockID, 2);
		TileEntityChest var14 = (TileEntityChest)var1.getBlockTileEntity(i + 7, j + 10, k + 8);
        int var15;

        if (var14 != null)
        {
            for (var15 = 0; var15 < 8; ++var15)
            {
                ItemStack var11 = this.pickCheckLootItem(var2);

                if (var11 != null)
                {
                    var14.setInventorySlotContents(var2.nextInt(var14.getSizeInventory()), var11);
                }
            }
        }
		var1.setBlockMetadataWithNotify(i + 7, j + 10, k + 11, Block.chest.blockID, 2);
		var1.setBlock(i + 7, j + 10, k + 16, Block.stoneBrick.blockID);
		var1.setBlock(i + 7, j + 10, k + 17, Block.thinGlass.blockID);
		var1.setBlock(i + 7, j + 10, k + 18, Block.stoneBrick.blockID);
		var1.setBlock(i + 7, j + 10, k + 19, Block.thinGlass.blockID);
		var1.setBlock(i + 7, j + 10, k + 20, Block.stoneBrick.blockID);
		var1.setBlock(i + 7, j + 10, k + 21, Block.thinGlass.blockID);
		var1.setBlock(i + 7, j + 10, k + 22, Block.thinGlass.blockID);
		var1.setBlock(i + 7, j + 10, k + 23, Block.brick.blockID);
		var1.setBlock(i + 7, j + 10, k + 24, Block.brick.blockID);
		var1.setBlock(i + 7, j + 10, k + 25, Block.brick.blockID);
		var1.setBlock(i + 7, j + 11, k + 5, Block.stoneBrick.blockID);
		var1.setBlock(i + 7, j + 11, k + 16, Block.stoneBrick.blockID);
		var1.setBlock(i + 7, j + 11, k + 17, Block.thinGlass.blockID);
		var1.setBlock(i + 7, j + 11, k + 18, Block.stoneBrick.blockID);
		var1.setBlock(i + 7, j + 11, k + 19, Block.thinGlass.blockID);
		var1.setBlock(i + 7, j + 11, k + 20, Block.stoneBrick.blockID);
		var1.setBlock(i + 7, j + 11, k + 21, Block.stoneBrick.blockID);
		var1.setBlock(i + 7, j + 11, k + 22, Block.stoneBrick.blockID);
		var1.setBlock(i + 7, j + 11, k + 23, Block.brick.blockID);
		var1.setBlock(i + 7, j + 11, k + 24, Block.brick.blockID);
		var1.setBlock(i + 7, j + 11, k + 25, Block.brick.blockID);
		var1.setBlock(i + 7, j + 12, k + 5, Block.stoneBrick.blockID);
		var1.setBlock(i + 7, j + 12, k + 16, Block.stoneBrick.blockID);
		var1.setBlock(i + 7, j + 12, k + 17, Block.stoneBrick.blockID);
		var1.setBlock(i + 7, j + 12, k + 18, Block.stoneBrick.blockID);
		var1.setBlock(i + 7, j + 12, k + 19, Block.stoneBrick.blockID);
		var1.setBlockMetadataWithNotify(i + 7, j + 12, k + 20, Block.stoneBrick.blockID, 2);
		var1.setBlock(i + 7, j + 12, k + 21, Block.stoneBrick.blockID);
		var1.setBlock(i + 7, j + 12, k + 22, Block.stoneBrick.blockID);
		var1.setBlock(i + 7, j + 12, k + 23, Block.brick.blockID);
		var1.setBlock(i + 7, j + 12, k + 24, Block.brick.blockID);
		var1.setBlock(i + 7, j + 12, k + 25, Block.brick.blockID);
		var1.setBlock(i + 7, j + 13, k + 5, Block.stoneBrick.blockID);
		var1.setBlock(i + 7, j + 13, k + 15, Block.stoneBrick.blockID);
		var1.setBlock(i + 7, j + 13, k + 16, Block.stoneBrick.blockID);
		var1.setBlock(i + 7, j + 13, k + 17, Block.stoneBrick.blockID);
		var1.setBlock(i + 7, j + 13, k + 18, Block.stoneBrick.blockID);
		var1.setBlock(i + 7, j + 13, k + 19, Block.stoneBrick.blockID);
		var1.setBlock(i + 7, j + 13, k + 20, Block.stoneBrick.blockID);
		var1.setBlock(i + 7, j + 13, k + 21, Block.stoneBrick.blockID);
		var1.setBlock(i + 7, j + 13, k + 22, Block.stoneBrick.blockID);
		var1.setBlock(i + 7, j + 13, k + 23, Block.brick.blockID);
		var1.setBlock(i + 7, j + 13, k + 24, Block.brick.blockID);
		var1.setBlock(i + 7, j + 13, k + 25, Block.brick.blockID);
		var1.setBlock(i + 7, j + 14, k + 4, Block.stoneBrick.blockID);
		var1.setBlock(i + 7, j + 14, k + 5, Block.stoneBrick.blockID);
		var1.setBlock(i + 7, j + 14, k + 6, Block.stoneBrick.blockID);
		var1.setBlock(i + 7, j + 14, k + 7, Block.stoneBrick.blockID);
		var1.setBlock(i + 7, j + 14, k + 8, Block.stoneBrick.blockID);
		var1.setBlock(i + 7, j + 14, k + 9, Block.stoneBrick.blockID);
		var1.setBlock(i + 7, j + 14, k + 10, Block.stoneBrick.blockID);
		var1.setBlock(i + 7, j + 14, k + 11, Block.stoneBrick.blockID);
		var1.setBlock(i + 7, j + 14, k + 12, Block.stoneBrick.blockID);
		var1.setBlock(i + 7, j + 14, k + 13, Block.stoneBrick.blockID);
		var1.setBlock(i + 7, j + 14, k + 14, Block.stoneBrick.blockID);
		var1.setBlock(i + 7, j + 14, k + 15, Block.stoneBrick.blockID);
		var1.setBlock(i + 7, j + 14, k + 16, Block.stoneBrick.blockID);
		var1.setBlock(i + 7, j + 14, k + 17, Block.stoneBrick.blockID);
		var1.setBlock(i + 7, j + 14, k + 18, Block.stoneBrick.blockID);
		var1.setBlock(i + 7, j + 14, k + 19, Block.stoneBrick.blockID);
		var1.setBlock(i + 7, j + 14, k + 20, Block.stoneBrick.blockID);
		var1.setBlock(i + 7, j + 14, k + 21, Block.stoneBrick.blockID);
		var1.setBlock(i + 7, j + 14, k + 22, Block.stoneBrick.blockID);
		var1.setBlock(i + 7, j + 14, k + 23, Block.stoneBrick.blockID);
		var1.setBlock(i + 7, j + 14, k + 24, Block.brick.blockID);
		var1.setBlock(i + 7, j + 14, k + 25, Block.brick.blockID);
		var1.setBlock(i + 7, j + 15, k + 4, Block.stoneBrick.blockID);
		var1.setBlock(i + 7, j + 15, k + 14, Block.stoneBrick.blockID);
		var1.setBlock(i + 7, j + 15, k + 15, Block.stoneBrick.blockID);
		var1.setBlock(i + 7, j + 15, k + 16, Block.stoneBrick.blockID);
		var1.setBlock(i + 7, j + 15, k + 17, Block.stoneBrick.blockID);
		var1.setBlock(i + 7, j + 15, k + 18, Block.stoneBrick.blockID);
		var1.setBlock(i + 7, j + 15, k + 19, Block.stoneBrick.blockID);
		var1.setBlock(i + 7, j + 15, k + 20, Block.stoneBrick.blockID);
		var1.setBlock(i + 7, j + 15, k + 21, Block.stoneBrick.blockID);
		var1.setBlock(i + 7, j + 15, k + 24, Block.brick.blockID);
		var1.setBlock(i + 7, j + 15, k + 25, Block.brick.blockID);
		var1.setBlock(i + 7, j + 16, k + 14, Block.stoneBrick.blockID);
		var1.setBlock(i + 7, j + 16, k + 15, Block.bookShelf.blockID);
		var1.setBlock(i + 7, j + 16, k + 21, Block.stoneBrick.blockID);
		var1.setBlock(i + 7, j + 16, k + 24, Block.brick.blockID);
		var1.setBlock(i + 7, j + 16, k + 25, Block.brick.blockID);
		var1.setBlock(i + 7, j + 17, k + 14, Block.stoneBrick.blockID);
		var1.setBlock(i + 7, j + 17, k + 15, Block.bookShelf.blockID);
		var1.setBlock(i + 7, j + 17, k + 21, Block.stoneBrick.blockID);
		var1.setBlock(i + 7, j + 17, k + 24, Block.brick.blockID);
		var1.setBlock(i + 7, j + 17, k + 25, Block.brick.blockID);
		var1.setBlock(i + 7, j + 18, k + 14, Block.stoneBrick.blockID);
		var1.setBlock(i + 7, j + 18, k + 15, Block.bookShelf.blockID);
		var1.setBlock(i + 7, j + 18, k + 21, Block.stoneBrick.blockID);
		var1.setBlock(i + 7, j + 18, k + 24, Block.brick.blockID);
		var1.setBlock(i + 7, j + 18, k + 25, Block.brick.blockID);
		var1.setBlock(i + 7, j + 19, k + 14, Block.stoneBrick.blockID);
		var1.setBlock(i + 7, j + 19, k + 15, Block.stoneBrick.blockID);
		var1.setBlock(i + 7, j + 19, k + 16, Block.glowStone.blockID);
		var1.setBlock(i + 7, j + 19, k + 21, Block.stoneBrick.blockID);
		var1.setBlock(i + 7, j + 19, k + 22, Block.stoneBrick.blockID);
		var1.setBlock(i + 7, j + 19, k + 23, Block.stoneBrick.blockID);
		var1.setBlock(i + 7, j + 19, k + 24, Block.stoneBrick.blockID);
		var1.setBlock(i + 7, j + 19, k + 25, Block.stoneBrick.blockID);
		var1.setBlock(i + 7, j + 20, k + 14, Block.stoneBrick.blockID);
		var1.setBlock(i + 7, j + 20, k + 15, Block.stoneBrick.blockID);
		var1.setBlock(i + 7, j + 20, k + 16, Block.stoneBrick.blockID);
		var1.setBlock(i + 7, j + 20, k + 17, Block.stoneBrick.blockID);
		var1.setBlock(i + 7, j + 20, k + 18, Block.stoneBrick.blockID);
		var1.setBlock(i + 7, j + 20, k + 19, Block.stoneBrick.blockID);
		var1.setBlock(i + 7, j + 20, k + 20, Block.stoneBrick.blockID);
		var1.setBlock(i + 7, j + 20, k + 21, Block.stoneBrick.blockID);
		var1.setBlock(i + 7, j + 20, k + 22, Block.stoneBrick.blockID);
		var1.setBlock(i + 7, j + 20, k + 23, Block.stoneBrick.blockID);
		var1.setBlock(i + 7, j + 20, k + 24, Block.stoneBrick.blockID);
		var1.setBlock(i + 7, j + 20, k + 25, Block.stoneBrick.blockID);
		var1.setBlock(i + 7, j + 21, k + 14, Block.stoneBrick.blockID);
		var1.setBlock(i + 7, j + 21, k + 15, Block.stoneBrick.blockID);
		var1.setBlock(i + 7, j + 21, k + 16, Block.stoneBrick.blockID);
		var1.setBlock(i + 7, j + 21, k + 17, Block.stoneBrick.blockID);
		var1.setBlock(i + 7, j + 21, k + 18, Block.stoneBrick.blockID);
		var1.setBlock(i + 7, j + 21, k + 19, Block.stoneBrick.blockID);
		var1.setBlock(i + 7, j + 21, k + 20, Block.stoneBrick.blockID);
		var1.setBlock(i + 7, j + 21, k + 21, Block.stoneBrick.blockID);
		var1.setBlock(i + 7, j + 21, k + 22, Block.stoneBrick.blockID);
		var1.setBlock(i + 7, j + 21, k + 23, Block.stoneBrick.blockID);
		var1.setBlock(i + 7, j + 21, k + 24, Block.stoneBrick.blockID);
		var1.setBlock(i + 7, j + 21, k + 25, Block.stoneBrick.blockID);
		var1.setBlock(i + 8, j + 0, k + 10, Block.stoneBrick.blockID);
		var1.setBlock(i + 8, j + 1, k + 9, Block.stoneBrick.blockID);
		var1.setBlock(i + 8, j + 1, k + 10, Block.glowStone.blockID);
		var1.setBlock(i + 8, j + 1, k + 11, Block.stoneBrick.blockID);
		var1.setBlock(i + 8, j + 1, k + 15, Block.stoneBrick.blockID);
		var1.setBlock(i + 8, j + 1, k + 19, Block.stoneBrick.blockID);
		var1.setBlock(i + 8, j + 2, k + 5, Block.stoneBrick.blockID);
		var1.setBlockMetadataWithNotify(i + 8, j + 2, k + 6, Block.stoneBrick.blockID, 2);
		var1.setBlock(i + 8, j + 2, k + 7, Block.stoneBrick.blockID);
		var1.setBlock(i + 8, j + 2, k + 8, Block.stoneDoubleSlab.blockID);
		var1.setBlock(i + 8, j + 2, k + 9, Block.stoneDoubleSlab.blockID);
		var1.setBlock(i + 8, j + 2, k + 10, Block.glass.blockID);
