package fossil.gens;

import java.util.Random;

import fossil.Fossil;

import net.minecraft.block.Block;
import net.minecraft.item.Item;
import net.minecraft.item.ItemStack;
import net.minecraft.tileentity.TileEntityChest;
import net.minecraft.world.World;
import net.minecraft.world.gen.feature.WorldGenerator;

public class WorldGeneratorWeaponShop extends WorldGenerator
{
	
	public boolean generate(World world, Random rand, int i, int j, int k)
	{
		
		System.out.println("Generating shop");
		world.setBlock(i + 0, j + 0, k + 0, Block.stone.blockID);
		world.setBlock(i + 0, j + 0, k + 1, Block.stone.blockID);
		world.setBlock(i + 0, j + 0, k + 2, Block.stone.blockID);
		world.setBlock(i + 0, j + 0, k + 3, Block.stone.blockID);
		world.setBlock(i + 0, j + 0, k + 4, Block.stone.blockID);
		world.setBlock(i + 0, j + 0, k + 5, Block.stone.blockID);
		world.setBlock(i + 0, j + 0, k + 6, Block.stone.blockID);
		world.setBlock(i + 0, j + 0, k + 7, Block.cobblestone.blockID);
		world.setBlock(i + 0, j + 0, k + 8, Block.cobblestone.blockID);
		world.setBlock(i + 0, j + 0, k + 9, Block.cobblestone.blockID);
		world.setBlock(i + 0, j + 0, k + 10, Block.cobblestone.blockID);
		world.setBlock(i + 0, j + 1, k + 0, Block.stone.blockID);
		world.setBlock(i + 0, j + 1, k + 1, Block.stone.blockID);
		world.setBlock(i + 0, j + 1, k + 2, Block.stone.blockID);
		world.setBlock(i + 0, j + 1, k + 3, Block.cobblestone.blockID);
		world.setBlock(i + 0, j + 1, k + 4, Block.stone.blockID);
		world.setBlock(i + 0, j + 1, k + 5, Block.stone.blockID);
		world.setBlock(i + 0, j + 1, k + 6, Block.cobblestone.blockID);
		world.setBlock(i + 0, j + 1, k + 7, Block.cobblestoneMossy.blockID);
		world.setBlock(i + 0, j + 1, k + 8, Block.cobblestoneMossy.blockID);
		world.setBlock(i + 0, j + 1, k + 9, Block.cobblestoneMossy.blockID);
		world.setBlock(i + 0, j + 1, k + 10, Block.cobblestoneMossy.blockID);
		world.setBlock(i + 0, j + 2, k + 0, Block.stone.blockID);
		world.setBlock(i + 0, j + 2, k + 1, Block.stone.blockID);
		world.setBlock(i + 0, j + 2, k + 2, Block.cobblestone.blockID);
		world.setBlock(i + 0, j + 2, k + 3, Block.cobblestoneMossy.blockID);
		world.setBlock(i + 0, j + 2, k + 4, Block.cobblestone.blockID);
		world.setBlock(i + 0, j + 2, k + 5, Block.cobblestone.blockID);
		world.setBlock(i + 0, j + 2, k + 6, Block.cobblestoneMossy.blockID);
		world.setBlock(i + 0, j + 2, k + 7, Block.cobblestoneMossy.blockID);
		world.setBlock(i + 0, j + 2, k + 8, Block.cobblestone.blockID);
		world.setBlock(i + 0, j + 2, k + 9, Block.cobblestone.blockID);
		world.setBlock(i + 0, j + 2, k + 10, Block.cobblestoneMossy.blockID);
		world.setBlock(i + 0, j + 3, k + 0, Block.stone.blockID);
		world.setBlock(i + 0, j + 3, k + 1, Block.stone.blockID);
		world.setBlock(i + 0, j + 3, k + 2, Block.cobblestone.blockID);
		world.setBlock(i + 0, j + 3, k + 3, Block.cobblestoneMossy.blockID);
		world.setBlock(i + 0, j + 3, k + 4, Block.cobblestone.blockID);
		world.setBlock(i + 0, j + 3, k + 5, Block.cobblestone.blockID);
		world.setBlock(i + 0, j + 3, k + 6, Block.cobblestoneMossy.blockID);
		world.setBlock(i + 0, j + 3, k + 7, Block.cobblestoneMossy.blockID);
		world.setBlock(i + 0, j + 3, k + 8, Block.cobblestoneMossy.blockID);
		world.setBlock(i + 0, j + 3, k + 9, Block.cobblestone.blockID);
		world.setBlock(i + 0, j + 3, k + 10, Block.cobblestone.blockID);
		world.setBlock(i + 0, j + 4, k + 0, Block.stone.blockID);
		world.setBlock(i + 0, j + 4, k + 1, Block.stone.blockID);
		world.setBlock(i + 0, j + 4, k + 2, Block.wood.blockID);
		world.setBlock(i + 0, j + 4, k + 3, Block.cobblestone.blockID);
		world.setBlock(i + 0, j + 4, k + 4, Block.wood.blockID);
		world.setBlock(i + 0, j + 4, k + 5, Block.cobblestone.blockID);
		world.setBlock(i + 0, j + 4, k + 6, Block.cobblestoneMossy.blockID);
		world.setBlock(i + 0, j + 4, k + 7, Block.cobblestoneMossy.blockID);
		world.setBlock(i + 0, j + 4, k + 8, Block.cobblestone.blockID);
		world.setBlock(i + 0, j + 4, k + 9, Block.cobblestoneMossy.blockID);
		world.setBlock(i + 0, j + 4, k + 10, Block.cobblestoneMossy.blockID);
		world.setBlock(i + 0, j + 5, k + 0, Block.stone.blockID);
		world.setBlock(i + 0, j + 5, k + 1, Block.stone.blockID);
		world.setBlock(i + 0, j + 5, k + 2, Block.stone.blockID);
		world.setBlock(i + 0, j + 5, k + 3, Block.cobblestone.blockID);
		world.setBlock(i + 0, j + 5, k + 4, Block.cobblestone.blockID);
		world.setBlock(i + 0, j + 5, k + 5, Block.cobblestone.blockID);
		world.setBlock(i + 0, j + 5, k + 6, Block.cobblestone.blockID);
		world.setBlock(i + 0, j + 5, k + 7, Block.cobblestone.blockID);
		world.setBlock(i + 0, j + 5, k + 8, Block.cobblestone.blockID);
		world.setBlock(i + 0, j + 5, k + 9, Block.cobblestone.blockID);
		world.setBlock(i + 0, j + 5, k + 10, Block.cobblestone.blockID);
		world.setBlock(i + 0, j + 6, k + 0, Block.stone.blockID);
		world.setBlock(i + 0, j + 6, k + 1, Block.stone.blockID);
		world.setBlock(i + 0, j + 6, k + 2, Block.stone.blockID);
		world.setBlock(i + 0, j + 6, k + 3, Block.stone.blockID);
		world.setBlock(i + 0, j + 6, k + 4, Block.stone.blockID);
		world.setBlock(i + 0, j + 6, k + 5, Block.cobblestone.blockID);
		world.setBlock(i + 0, j + 6, k + 6, Block.cobblestone.blockID);
		world.setBlock(i + 0, j + 6, k + 7, Block.cobblestone.blockID);
		world.setBlock(i + 0, j + 6, k + 8, Block.cobblestone.blockID);
		world.setBlock(i + 0, j + 6, k + 9, Block.cobblestone.blockID);
		world.setBlock(i + 0, j + 6, k + 10, Block.cobblestone.blockID);
		world.setBlock(i + 1, j + 0, k + 0, Block.stone.blockID);
		world.setBlock(i + 1, j + 0, k + 1, Block.sandStone.blockID);
		world.setBlock(i + 1, j + 0, k + 2, Block.sandStone.blockID);
		world.setBlock(i + 1, j + 0, k + 3, Block.sandStone.blockID);
		world.setBlock(i + 1, j + 0, k + 4, Block.sandStone.blockID);
		world.setBlock(i + 1, j + 0, k + 5, Block.sandStone.blockID);
		world.setBlock(i + 1, j + 0, k + 6, Block.sandStone.blockID);
		world.setBlock(i + 1, j + 0, k + 7, Block.sandStone.blockID);
		world.setBlock(i + 1, j + 0, k + 8, Block.sandStone.blockID);
		world.setBlock(i + 1, j + 0, k + 9, Block.sandStone.blockID);
		world.setBlock(i + 1, j + 0, k + 10, Block.cobblestone.blockID);
		world.setBlock(i + 1, j + 1, k + 0, Block.stone.blockID);
		world.setBlock(i + 1, j + 1, k + 1, Block.planks.blockID);
		world.setBlock(i + 1, j + 1, k + 2, Block.planks.blockID);
		world.setBlock(i + 1, j + 1, k + 3, Block.planks.blockID);
		world.setBlock(i + 1, j + 1, k + 4, Block.planks.blockID);
		world.setBlock(i + 1, j + 1, k + 5, Block.stairsWoodBirch.blockID);
		world.setBlock(i + 1, j + 1, k + 6, Block.planks.blockID);
		world.setBlock(i + 1, j + 1, k + 7, Block.stairsWoodBirch.blockID);
		world.setBlock(i + 1, j + 1, k + 9, Block.sandStone.blockID);
		world.setBlock(i + 1, j + 1, k + 10, Block.cobblestone.blockID);
		world.setBlock(i + 1, j + 2, k + 0, Block.stone.blockID);
		world.setBlock(i + 1, j + 2, k + 1, Block.planks.blockID);
		world.setBlock(i + 1, j + 2, k + 2, Block.planks.blockID);
		world.setBlock(i + 1, j + 2, k + 4, Block.stairsWoodBirch.blockID);
		world.setBlock(i + 1, j + 2, k + 5, Block.planks.blockID);
		world.setBlock(i + 1, j + 2, k + 6, Block.stairsWoodBirch.blockID);
		world.setBlock(i + 1, j + 2, k + 10, Block.cobblestoneMossy.blockID);
		world.setBlock(i + 1, j + 3, k + 0, Block.stone.blockID);
		world.setBlock(i + 1, j + 3, k + 1, Block.sandStone.blockID);
		world.setBlock(i + 1, j + 3, k + 2, Block.sandStone.blockID);
		world.setBlock(i + 1, j + 3, k + 4, Block.sandStone.blockID);
		world.setBlock(i + 1, j + 3, k + 5, Block.sandStone.blockID);
		world.setBlock(i + 1, j + 3, k + 10, Block.cobblestoneMossy.blockID);
		world.setBlock(i + 1, j + 4, k + 0, Block.stone.blockID);
		world.setBlock(i + 1, j + 4, k + 1, Block.sandStone.blockID);
		world.setBlock(i + 1, j + 4, k + 2, Block.sandStone.blockID);
		world.setBlock(i + 1, j + 4, k + 3, Block.sandStone.blockID);
		world.setBlock(i + 1, j + 4, k + 4, Block.sandStone.blockID);
		world.setBlock(i + 1, j + 4, k + 5, Block.sandStone.blockID);
		world.setBlock(i + 1, j + 4, k + 10, Block.cobblestoneMossy.blockID);
		world.setBlock(i + 1, j + 5, k + 0, Block.stone.blockID);
		world.setBlock(i + 1, j + 5, k + 1, Block.sandStone.blockID);
		world.setBlock(i + 1, j + 5, k + 2, Block.sandStone.blockID);
		world.setBlock(i + 1, j + 5, k + 3, Block.sandStone.blockID);
		world.setBlock(i + 1, j + 5, k + 4, Block.sandStone.blockID);
		world.setBlock(i + 1, j + 5, k + 5, Block.sandStone.blockID);
		world.setBlockMetadataWithNotify(i + 1, j + 5, k + 6, Block.stoneSingleSlab.blockID, 1);
		world.setBlock(i + 1, j + 5, k + 10, Block.cobblestoneMossy.blockID);
		world.setBlock(i + 1, j + 6, k + 0, Block.stone.blockID);
		world.setBlock(i + 1, j + 6, k + 1, Block.sandStone.blockID);
		world.setBlock(i + 1, j + 6, k + 2, Block.sandStone.blockID);
		world.setBlock(i + 1, j + 6, k + 3, Block.sandStone.blockID);
		world.setBlock(i + 1, j + 6, k + 10, Block.cobblestone.blockID);
		world.setBlock(i + 2, j + 0, k + 0, Block.stone.blockID);
		world.setBlock(i + 2, j + 0, k + 1, Block.sandStone.blockID);
		world.setBlock(i + 2, j + 0, k + 2, Block.planks.blockID);
		world.setBlock(i + 2, j + 0, k + 3, Block.planks.blockID);
		world.setBlock(i + 2, j + 0, k + 4, Block.dirt.blockID);
		world.setBlock(i + 2, j + 0, k + 5, Block.planks.blockID);
		world.setBlock(i + 2, j + 0, k + 6, Block.planks.blockID);
		world.setBlock(i + 2, j + 0, k + 7, Block.planks.blockID);
		world.setBlock(i + 2, j + 0, k + 8, Block.planks.blockID);
		world.setBlock(i + 2, j + 0, k + 9, Block.sandStone.blockID);
		world.setBlock(i + 2, j + 0, k + 10, Block.cobblestone.blockID);
		world.setBlock(i + 2, j + 1, k + 0, Block.stone.blockID);
		world.setBlock(i + 2, j + 1, k + 1, Block.planks.blockID);
		world.setBlockMetadataWithNotify(i + 2, j + 1, k + 2, Block.chest.blockID, 5);
		TileEntityChest var9 = (TileEntityChest)world.getBlockTileEntity(i + 2, j + 1, k + 2);
        int var10;

        if (var9 != null)
        {
            for (var10 = 0; var10 < 8; ++var10)
            {
                ItemStack var11 = this.pickCheckLootItem(rand);

                if (var11 != null)
                {
                    var9.setInventorySlotContents(rand.nextInt(var9.getSizeInventory()), var11);
                }
            }
        }
		world.setBlock(i + 2, j + 1, k + 9, Block.stairsWoodBirch.blockID);
		world.setBlock(i + 2, j + 1, k + 10, Block.cobblestone.blockID);
		world.setBlock(i + 2, j + 2, k + 0, Block.stone.blockID);
		world.setBlock(i + 2, j + 2, k + 1, Block.planks.blockID);
		world.setBlock(i + 2, j + 2, k + 10, Block.cobblestoneMossy.blockID);
		world.setBlock(i + 2, j + 3, k + 0, Block.stone.blockID);
		world.setBlock(i + 2, j + 3, k + 1, Block.sandStone.blockID);
		world.setBlockMetadataWithNotify(i + 2, j + 3, k + 9, Block.stoneSingleSlab.blockID, 1);
		world.setBlock(i + 2, j + 3, k + 10, Block.cobblestoneMossy.blockID);
		world.setBlock(i + 2, j + 4, k + 0, Block.wood.blockID);
		world.setBlock(i + 2, j + 4, k + 1, Block.sandStone.blockID);
		world.setBlock(i + 2, j + 4, k + 3, Block.sandStone.blockID);
		world.setBlock(i + 2, j + 4, k + 5, Block.fence.blockID);
		world.setBlock(i + 2, j + 4, k + 10, Block.cobblestoneMossy.blockID);
		world.setBlock(i + 2, j + 5, k + 0, Block.stone.blockID);
		world.setBlock(i + 2, j + 5, k + 1, Block.sandStone.blockID);
		world.setBlock(i + 2, j + 5, k + 2, Block.tnt.blockID);
		world.setBlock(i + 2, j + 5, k + 3, Block.sandStone.blockID);
		world.setBlockMetadataWithNotify(i + 2, j + 5, k + 4, Block.stoneSingleSlab.blockID, 2);
		world.setBlockMetadataWithNotify(i + 2, j + 5, k + 5, Block.stoneSingleSlab.blockID, 2);
		world.setBlock(i + 2, j + 5, k + 10, Block.cobblestone.blockID);
		world.setBlock(i + 2, j + 6, k + 0, Block.stone.blockID);
		world.setBlock(i + 2, j + 6, k + 1, Block.sandStone.blockID);
		world.setBlockMetadataWithNotify(i + 2, j + 6, k + 2, Block.stoneSingleSlab.blockID, 2);
		world.setBlock(i + 2, j + 6, k + 3, Block.sandStone.blockID);
		world.setBlock(i + 2, j + 6, k + 10, Block.cobblestone.blockID);
		world.setBlock(i + 3, j + 0, k + 0, Block.stone.blockID);
		world.setBlock(i + 3, j + 0, k + 1, Block.sandStone.blockID);
		world.setBlock(i + 3, j + 0, k + 2, Block.planks.blockID);
		world.setBlock(i + 3, j + 0, k + 3, Block.dirt.blockID);
		world.setBlock(i + 3, j + 0, k + 4, Block.dirt.blockID);
		world.setBlock(i + 3, j + 0, k + 5, Block.dirt.blockID);
		world.setBlock(i + 3, j + 0, k + 6, Block.planks.blockID);
		world.setBlock(i + 3, j + 0, k + 7, Block.planks.blockID);
		world.setBlock(i + 3, j + 0, k + 8, Block.planks.blockID);
		world.setBlock(i + 3, j + 0, k + 9, Block.sandStone.blockID);
		world.setBlock(i + 3, j + 0, k + 10, Block.cobblestone.blockID);
		world.setBlock(i + 3, j + 1, k + 0, Block.stone.blockID);
		world.setBlock(i + 3, j + 1, k + 1, Block.planks.blockID);
		world.setBlockMetadataWithNotify(i + 3, j + 1, k + 6, Block.stoneSingleSlab.blockID, 1);
		world.setBlock(i + 3, j + 1, k + 8, Block.netherFence.blockID);
		world.setBlockMetadataWithNotify(i + 3, j + 1, k + 9, Block.stairsWoodBirch.blockID, 1);
		world.setBlock(i + 3, j + 1, k + 10, Block.cobblestone.blockID);
		world.setBlock(i + 3, j + 2, k + 0, Block.stone.blockID);
		world.setBlock(i + 3, j + 2, k + 1, Block.planks.blockID);
		world.setBlock(i + 3, j + 2, k + 8, Block.netherFence.blockID);
		world.setBlock(i + 3, j + 2, k + 9, Block.planks.blockID);
		world.setBlock(i + 3, j + 2, k + 10, Block.cobblestone.blockID);
		world.setBlock(i + 3, j + 3, k + 0, Block.stone.blockID);
		world.setBlock(i + 3, j + 3, k + 1, Block.sandStone.blockID);
		world.setBlock(i + 3, j + 3, k + 8, Block.fenceIron.blockID);
		world.setBlockMetadataWithNotify(i + 3, j + 3, k + 9, Block.stoneSingleSlab.blockID, 1);
		world.setBlock(i + 3, j + 3, k + 10, Block.cobblestone.blockID);
		world.setBlock(i + 3, j + 4, k + 0, Block.stone.blockID);
		world.setBlock(i + 3, j + 4, k + 1, Block.sandStone.blockID);
		world.setBlock(i + 3, j + 4, k + 2, Block.sandStone.blockID);
		world.setBlock(i + 3, j + 4, k + 3, Block.sandStone.blockID);
		world.setBlock(i + 3, j + 4, k + 5, Block.fence.blockID);
		world.setBlock(i + 3, j + 4, k + 10, Block.cobblestoneMossy.blockID);
		world.setBlock(i + 3, j + 5, k + 0, Block.stone.blockID);
		world.setBlock(i + 3, j + 5, k + 1, Block.sandStone.blockID);
		world.setBlock(i + 3, j + 5, k + 3, Block.sandStone.blockID);
		world.setBlockMetadataWithNotify(i + 3, j + 5, k + 4, Block.stoneSingleSlab.blockID, 2);
		world.setBlock(i + 3, j + 5, k + 10, Block.cobblestone.blockID);
		world.setBlock(i + 3, j + 6, k + 0, Block.stone.blockID);
		world.setBlock(i + 3, j + 6, k + 1, Block.sandStone.blockID);
		world.setBlockMetadataWithNotify(i + 3, j + 6, k + 2, Block.stoneSingleSlab.blockID, 2);
		world.setBlock(i + 3, j + 6, k + 3, Block.sandStone.blockID);
		world.setBlock(i + 3, j + 6, k + 10, Block.cobblestone.blockID);
		world.setBlock(i + 4, j + 0, k + 0, Block.stone.blockID);
		world.setBlock(i + 4, j + 0, k + 1, Block.sandStone.blockID);
		world.setBlock(i + 4, j + 0, k + 2, Block.planks.blockID);
		world.setBlock(i + 4, j + 0, k + 3, Block.dirt.blockID);
		world.setBlock(i + 4, j + 0, k + 4, Block.dirt.blockID);
		world.setBlock(i + 4, j + 0, k + 5, Block.dirt.blockID);
		world.setBlock(i + 4, j + 0, k + 6, Block.planks.blockID);
		world.setBlock(i + 4, j + 0, k + 7, Block.planks.blockID);
		world.setBlock(i + 4, j + 0, k + 8, Block.planks.blockID);
		world.setBlock(i + 4, j + 0, k + 9, Block.sandStone.blockID);
		world.setBlock(i + 4, j + 0, k + 10, Block.stone.blockID);
		world.setBlock(i + 4, j + 1, k + 0, Block.stone.blockID);
		world.setBlock(i + 4, j + 1, k + 1, Block.planks.blockID);
		world.setBlock(i + 4, j + 1, k + 6, Block.sandStone.blockID);
		world.setBlock(i + 4, j + 1, k + 9, Block.planks.blockID);
		world.setBlock(i + 4, j + 1, k + 10, Block.cobblestone.blockID);
		world.setBlock(i + 4, j + 2, k + 0, Block.cobblestone.blockID);
		world.setBlock(i + 4, j + 2, k + 1, Block.stairsWoodBirch.blockID);
		world.setBlock(i + 4, j + 2, k + 9, Block.planks.blockID);
		world.setBlock(i + 4, j + 2, k + 10, Block.cobblestone.blockID);
		world.setBlock(i + 4, j + 3, k + 0, Block.cobblestone.blockID);
		world.setBlockMetadataWithNotify(i + 4, j + 3, k + 9, Block.stoneSingleSlab.blockID, 1);
		world.setBlock(i + 4, j + 3, k + 10, Block.cobblestone.blockID);
		world.setBlock(i + 4, j + 4, k + 0, Block.wood.blockID);
		world.setBlock(i + 4, j + 4, k + 1, Block.sandStone.blockID);
		world.setBlock(i + 4, j + 4, k + 3, Block.sandStone.blockID);
		world.setBlock(i + 4, j + 4, k + 5, Block.fence.blockID);
		world.setBlock(i + 4, j + 4, k + 10, Block.cobblestoneMossy.blockID);
		world.setBlock(i + 4, j + 5, k + 0, Block.stone.blockID);
		world.setBlock(i + 4, j + 5, k + 1, Block.sandStone.blockID);
		world.setBlock(i + 4, j + 5, k + 2, Block.tnt.blockID);
		world.setBlock(i + 4, j + 5, k + 3, Block.sandStone.blockID);
		world.setBlockMetadataWithNotify(i + 4, j + 5, k + 9, Block.stoneSingleSlab.blockID, 1);
		world.setBlock(i + 4, j + 5, k + 10, Block.cobblestone.blockID);
		world.setBlock(i + 4, j + 6, k + 0, Block.stone.blockID);
		world.setBlock(i + 4, j + 6, k + 1, Block.sandStone.blockID);
		world.setBlockMetadataWithNotify(i + 4, j + 6, k + 2, Block.stoneSingleSlab.blockID, 2);
		world.setBlock(i + 4, j + 6, k + 3, Block.sandStone.blockID);
		world.setBlock(i + 4, j + 6, k + 10, Block.cobblestone.blockID);
		world.setBlock(i + 5, j + 0, k + 0, Block.stone.blockID);
		world.setBlock(i + 5, j + 0, k + 1, Block.sandStone.blockID);
		world.setBlock(i + 5, j + 0, k + 2, Block.dirt.blockID);
		world.setBlock(i + 5, j + 0, k + 3, Block.dirt.blockID);
		world.setBlock(i + 5, j + 0, k + 4, Block.dirt.blockID);
		world.setBlock(i + 5, j + 0, k + 5, Block.planks.blockID);
		world.setBlock(i + 5, j + 0, k + 6, Block.planks.blockID);
		world.setBlock(i + 5, j + 0, k + 7, Block.planks.blockID);
		world.setBlock(i + 5, j + 0, k + 8, Block.planks.blockID);
		world.setBlock(i + 5, j + 0, k + 9, Block.sandStone.blockID);
		world.setBlock(i + 5, j + 0, k + 10, Block.stone.blockID);
		world.setBlock(i + 5, j + 1, k + 0, Block.stone.blockID);
		world.setBlockMetadataWithNotify(i + 5, j + 1, k + 1, Block.stoneSingleSlab.blockID, 2);
		world.setBlock(i + 5, j + 1, k + 8, Block.netherFence.blockID);
		world.setBlock(i + 5, j + 1, k + 9, Block.stairsWoodBirch.blockID);
		world.setBlock(i + 5, j + 1, k + 10, Block.cobblestone.blockID);
		world.setBlock(i + 5, j + 2, k + 0, Block.cobblestoneMossy.blockID);
		world.setBlock(i + 5, j + 2, k + 8, Block.netherFence.blockID);
		world.setBlock(i + 5, j + 2, k + 9, Block.planks.blockID);
		world.setBlock(i + 5, j + 2, k + 10, Block.cobblestone.blockID);
		world.setBlock(i + 5, j + 3, k + 0, Block.cobblestoneMossy.blockID);
		world.setBlock(i + 5, j + 3, k + 8, Block.fenceIron.blockID);
		world.setBlockMetadataWithNotify(i + 5, j + 3, k + 9, Block.stoneSingleSlab.blockID, 1);
		world.setBlock(i + 5, j + 3, k + 10, Block.cobblestone.blockID);
		world.setBlock(i + 5, j + 4, k + 0, Block.cobblestone.blockID);
		world.setBlock(i + 5, j + 4, k + 1, Block.sandStone.blockID);
		world.setBlock(i + 5, j + 4, k + 2, Block.sandStone.blockID);
		world.setBlock(i + 5, j + 4, k + 3, Block.sandStone.blockID);
		world.setBlock(i + 5, j + 4, k + 5, Block.fence.blockID);
		world.setBlock(i + 5, j + 4, k + 9, Block.sandStone.blockID);
		world.setBlock(i + 5, j + 4, k + 10, Block.cobblestone.blockID);
		world.setBlock(i + 5, j + 5, k + 0, Block.stone.blockID);
		world.setBlock(i + 5, j + 5, k + 1, Block.sandStone.blockID);
		world.setBlock(i + 5, j + 5, k + 2, Block.sandStone.blockID);
		world.setBlock(i + 5, j + 5, k + 3, Block.sandStone.blockID);
		world.setBlock(i + 5, j + 5, k + 9, Block.sandStone.blockID);
		world.setBlock(i + 5, j + 5, k + 10, Block.cobblestone.blockID);
		world.setBlock(i + 5, j + 6, k + 0, Block.stone.blockID);
		world.setBlock(i + 5, j + 6, k + 1, Block.sandStone.blockID);
		world.setBlock(i + 5, j + 6, k + 2, Block.sandStone.blockID);
		world.setBlock(i + 5, j + 6, k + 3, Block.sandStone.blockID);
		world.setBlock(i + 5, j + 6, k + 9, Block.stone.blockID);
		world.setBlock(i + 5, j + 6, k + 10, Block.stone.blockID);
		world.setBlock(i + 6, j + 0, k + 0, Block.stone.blockID);
		world.setBlock(i + 6, j + 0, k + 1, Block.sandStone.blockID);
		world.setBlock(i + 6, j + 0, k + 2, Block.dirt.blockID);
		world.setBlock(i + 6, j + 0, k + 3, Block.dirt.blockID);
		world.setBlock(i + 6, j + 0, k + 4, Block.planks.blockID);
		world.setBlock(i + 6, j + 0, k + 5, Block.planks.blockID);
		world.setBlock(i + 6, j + 0, k + 6, Block.planks.blockID);
		world.setBlock(i + 6, j + 0, k + 7, Block.planks.blockID);
		world.setBlock(i + 6, j + 0, k + 8, Block.planks.blockID);
		world.setBlock(i + 6, j + 0, k + 9, Block.sandStone.blockID);
		world.setBlock(i + 6, j + 0, k + 10, Block.stone.blockID);
		world.setBlock(i + 6, j + 1, k + 0, Block.stone.blockID);
		world.setBlock(i + 6, j + 1, k + 1, Block.planks.blockID);
		world.setBlock(i + 6, j + 1, k + 9, Block.planks.blockID);
		world.setBlock(i + 6, j + 1, k + 10, Block.stone.blockID);
		world.setBlock(i + 6, j + 2, k + 0, Block.cobblestone.blockID);
		world.setBlock(i + 6, j + 2, k + 1, Block.planks.blockID);
		world.setBlock(i + 6, j + 2, k + 9, Block.planks.blockID);
		world.setBlock(i + 6, j + 2, k + 10, Block.stone.blockID);
		world.setBlock(i + 6, j + 3, k + 0, Block.cobblestone.blockID);
		world.setBlock(i + 6, j + 3, k + 1, Block.sandStone.blockID);
		world.setBlock(i + 6, j + 3, k + 9, Block.sandStone.blockID);
		world.setBlock(i + 6, j + 3, k + 10, Block.stone.blockID);
		world.setBlock(i + 6, j + 4, k + 0, Block.wood.blockID);
		world.setBlock(i + 6, j + 4, k + 1, Block.sandStone.blockID);
		world.setBlock(i + 6, j + 4, k + 5, Block.fence.blockID);
		world.setBlock(i + 6, j + 4, k + 9, Block.sandStone.blockID);
		world.setBlock(i + 6, j + 4, k + 10, Block.stone.blockID);
		world.setBlock(i + 6, j + 5, k + 0, Block.stone.blockID);
		world.setBlockMetadataWithNotify(i + 6, j + 5, k + 1, Block.stoneSingleSlab.blockID, 1);
		world.setBlockMetadataWithNotify(i + 6, j + 5, k + 9, Block.stoneSingleSlab.blockID, 1);
		world.setBlock(i + 6, j + 5, k + 10, Block.stone.blockID);
		world.setBlock(i + 6, j + 6, k + 0, Block.cobblestone.blockID);
		world.setBlock(i + 6, j + 6, k + 10, Block.stone.blockID);
		world.setBlock(i + 7, j + 0, k + 0, Block.cobblestone.blockID);
		world.setBlock(i + 7, j + 0, k + 1, Block.sandStone.blockID);
		world.setBlock(i + 7, j + 0, k + 2, Block.dirt.blockID);
		world.setBlock(i + 7, j + 0, k + 3, Block.dirt.blockID);
		world.setBlock(i + 7, j + 0, k + 4, Block.planks.blockID);
		world.setBlock(i + 7, j + 0, k + 5, Block.wood.blockID);
		world.setBlock(i + 7, j + 0, k + 6, Block.planks.blockID);
		world.setBlock(i + 7, j + 0, k + 7, Block.planks.blockID);
		world.setBlock(i + 7, j + 0, k + 8, Block.planks.blockID);
		world.setBlock(i + 7, j + 0, k + 9, Block.sandStone.blockID);
		world.setBlock(i + 7, j + 0, k + 10, Block.stone.blockID);
		world.setBlock(i + 7, j + 1, k + 0, Block.cobblestone.blockID);
		world.setBlock(i + 7, j + 1, k + 1, Block.planks.blockID);
		world.setBlock(i + 7, j + 1, k + 5, Block.glowStone.blockID);
		world.setBlock(i + 7, j + 1, k + 6, Block.planks.blockID);
		world.setBlock(i + 7, j + 1, k + 7, Block.planks.blockID);
		world.setBlock(i + 7, j + 1, k + 8, Block.planks.blockID);
		world.setBlock(i + 7, j + 1, k + 9, Block.planks.blockID);
		world.setBlock(i + 7, j + 1, k + 10, Block.stone.blockID);
		world.setBlock(i + 7, j + 2, k + 0, Block.cobblestoneMossy.blockID);
		world.setBlock(i + 7, j + 2, k + 5, Block.wood.blockID);
		world.setBlock(i + 7, j + 2, k + 9, Block.planks.blockID);
		world.setBlock(i + 7, j + 2, k + 10, Block.stone.blockID);
		world.setBlock(i + 7, j + 3, k + 0, Block.cobblestoneMossy.blockID);
		world.setBlock(i + 7, j + 3, k + 5, Block.wood.blockID);
		world.setBlock(i + 7, j + 3, k + 9, Block.sandStone.blockID);
		world.setBlock(i + 7, j + 3, k + 10, Block.stone.blockID);
		world.setBlock(i + 7, j + 4, k + 0, Block.cobblestoneMossy.blockID);
		world.setBlock(i + 7, j + 4, k + 1, Block.sandStone.blockID);
		world.setBlock(i + 7, j + 4, k + 3, Block.fence.blockID);
		world.setBlock(i + 7, j + 4, k + 4, Block.fence.blockID);
		world.setBlock(i + 7, j + 4, k + 5, Block.planks.blockID);
		world.setBlock(i + 7, j + 4, k + 6, Block.fence.blockID);
		world.setBlock(i + 7, j + 4, k + 7, Block.fence.blockID);
		world.setBlock(i + 7, j + 4, k + 8, Block.fence.blockID);
		world.setBlock(i + 7, j + 4, k + 9, Block.sandStone.blockID);
		world.setBlock(i + 7, j + 4, k + 10, Block.wood.blockID);
		world.setBlock(i + 7, j + 5, k + 0, Block.cobblestone.blockID);
		world.setBlockMetadataWithNotify(i + 7, j + 5, k + 5, Block.stoneSingleSlab.blockID, 2);
		world.setBlockMetadataWithNotify(i + 7, j + 5, k + 6, Block.stoneSingleSlab.blockID, 2);
		world.setBlockMetadataWithNotify(i + 7, j + 5, k + 7, Block.stoneSingleSlab.blockID, 2);
		world.setBlockMetadataWithNotify(i + 7, j + 5, k + 8, Block.stoneSingleSlab.blockID, 2);
		world.setBlock(i + 7, j + 5, k + 9, Block.sandStone.blockID);
		world.setBlock(i + 7, j + 5, k + 10, Block.stone.blockID);
		world.setBlock(i + 7, j + 6, k + 0, Block.cobblestone.blockID);
		world.setBlock(i + 7, j + 6, k + 9, Block.stone.blockID);
		world.setBlock(i + 7, j + 6, k + 10, Block.stone.blockID);
		world.setBlock(i + 8, j + 0, k + 0, Block.cobblestone.blockID);
		world.setBlock(i + 8, j + 0, k + 1, Block.sandStone.blockID);
		world.setBlock(i + 8, j + 0, k + 2, Block.dirt.blockID);
		world.setBlock(i + 8, j + 0, k + 3, Block.dirt.blockID);
		world.setBlock(i + 8, j + 0, k + 4, Block.planks.blockID);
		world.setBlock(i + 8, j + 0, k + 5, Block.planks.blockID);
		world.setBlock(i + 8, j + 0, k + 6, Block.planks.blockID);
		world.setBlock(i + 8, j + 0, k + 7, Block.planks.blockID);
		world.setBlock(i + 8, j + 0, k + 8, Block.planks.blockID);
		world.setBlock(i + 8, j + 0, k + 9, Block.sandStone.blockID);
		world.setBlock(i + 8, j + 0, k + 10, Block.stone.blockID);
		world.setBlock(i + 8, j + 1, k + 0, Block.cobblestoneMossy.blockID);
		world.setBlockMetadataWithNotify(i + 8, j + 1, k + 5, Block.fenceGate.blockID, 2);
		world.setBlockMetadataWithNotify(i + 8, j + 1, k + 8, Block.chest.blockID, 2);
		TileEntityChest var12 = (TileEntityChest)world.getBlockTileEntity(i + 8, j + 1, k + 8);
        int var13;

        if (var12 != null)
        {
            for (var13 = 0; var13 < 8; ++var13)
            {
                ItemStack var11 = this.pickCheckLootItem(rand);

                if (var11 != null)
                {
                    var12.setInventorySlotContents(rand.nextInt(var12.getSizeInventory()), var11);
                }
            }
        }
		world.setBlock(i + 8, j + 1, k + 9, Block.planks.blockID);
		world.setBlock(i + 8, j + 1, k + 10, Block.stone.blockID);
		world.setBlock(i + 8, j + 2, k + 0, Block.cobblestone.blockID);
		world.setBlock(i + 8, j + 2, k + 9, Block.planks.blockID);
		world.setBlock(i + 8, j + 2, k + 10, Block.stone.blockID);
		world.setBlock(i + 8, j + 3, k + 0, Block.cobblestoneMossy.blockID);
		world.setBlock(i + 8, j + 3, k + 9, Block.sandStone.blockID);
		world.setBlock(i + 8, j + 3, k + 10, Block.stone.blockID);
		world.setBlock(i + 8, j + 4, k + 0, Block.cobblestoneMossy.blockID);
		world.setBlock(i + 8, j + 4, k + 5, Block.fence.blockID);
		world.setBlock(i + 8, j + 4, k + 9, Block.sandStone.blockID);
		world.setBlock(i + 8, j + 4, k + 10, Block.stone.blockID);
		world.setBlock(i + 8, j + 5, k + 0, Block.cobblestoneMossy.blockID);
		world.setBlockMetadataWithNotify(i + 8, j + 5, k + 5, Block.stoneSingleSlab.blockID, 2);
		world.setBlockMetadataWithNotify(i + 8, j + 5, k + 6, Block.stoneSingleSlab.blockID, 2);
		world.setBlockMetadataWithNotify(i + 8, j + 5, k + 7, Block.stoneSingleSlab.blockID, 2);
		world.setBlockMetadataWithNotify(i + 8, j + 5, k + 8, Block.stoneSingleSlab.blockID, 2);
		world.setBlock(i + 8, j + 5, k + 9, Block.sandStone.blockID);
		world.setBlock(i + 8, j + 5, k + 10, Block.stone.blockID);
		world.setBlock(i + 8, j + 6, k + 0, Block.cobblestone.blockID);
		world.setBlock(i + 8, j + 6, k + 9, Block.stone.blockID);
		world.setBlock(i + 8, j + 6, k + 10, Block.stone.blockID);
		world.setBlock(i + 9, j + 0, k + 0, Block.cobblestone.blockID);
		world.setBlock(i + 9, j + 0, k + 1, Block.sandStone.blockID);
		world.setBlock(i + 9, j + 0, k + 2, Block.dirt.blockID);
		world.setBlock(i + 9, j + 0, k + 3, Block.planks.blockID);
		world.setBlock(i + 9, j + 0, k + 4, Block.planks.blockID);
		world.setBlock(i + 9, j + 0, k + 5, Block.planks.blockID);
		world.setBlock(i + 9, j + 0, k + 6, Block.planks.blockID);
		world.setBlock(i + 9, j + 0, k + 7, Block.planks.blockID);
		world.setBlock(i + 9, j + 0, k + 8, Block.planks.blockID);
		world.setBlock(i + 9, j + 0, k + 9, Block.sandStone.blockID);
		world.setBlock(i + 9, j + 0, k + 10, Block.stone.blockID);
		world.setBlock(i + 9, j + 1, k + 0, Block.cobblestoneMossy.blockID);
		world.setBlock(i + 9, j + 1, k + 5, Block.wood.blockID);
		world.setBlock(i + 9, j + 1, k + 6, Block.stairsWoodBirch.blockID);
		world.setBlock(i + 9, j + 1, k + 7, Block.stairsWoodBirch.blockID);
		world.setBlock(i + 9, j + 1, k + 8, Block.stairsWoodBirch.blockID);
		world.setBlock(i + 9, j + 1, k + 9, Block.planks.blockID);
		world.setBlock(i + 9, j + 1, k + 10, Block.stone.blockID);
		world.setBlock(i + 9, j + 2, k + 0, Block.cobblestone.blockID);
		world.setBlock(i + 9, j + 2, k + 5, Block.wood.blockID);
		world.setBlock(i + 9, j + 2, k + 6, Block.stairsWoodBirch.blockID);
		world.setBlock(i + 9, j + 2, k + 7, Block.stairsWoodBirch.blockID);
		world.setBlock(i + 9, j + 2, k + 8, Block.stairsWoodBirch.blockID);
		world.setBlock(i + 9, j + 2, k + 9, Block.planks.blockID);
		world.setBlock(i + 9, j + 2, k + 10, Block.stone.blockID);
		world.setBlock(i + 9, j + 3, k + 0, Block.cobblestone.blockID);
		world.setBlock(i + 9, j + 3, k + 5, Block.wood.blockID);
		world.setBlock(i + 9, j + 3, k + 6, Block.stairsWoodBirch.blockID);
		world.setBlock(i + 9, j + 3, k + 7, Block.stairsWoodBirch.blockID);
		world.setBlock(i + 9, j + 3, k + 8, Block.stairsWoodBirch.blockID);
		world.setBlock(i + 9, j + 3, k + 9, Block.sandStone.blockID);
		world.setBlock(i + 9, j + 3, k + 10, Block.stone.blockID);
		world.setBlock(i + 9, j + 4, k + 0, Block.cobblestoneMossy.blockID);
		world.setBlock(i + 9, j + 4, k + 5, Block.planks.blockID);
		world.setBlock(i + 9, j + 4, k + 9, Block.sandStone.blockID);
		world.setBlock(i + 9, j + 4, k + 10, Block.wood.blockID);
		world.setBlock(i + 9, j + 5, k + 0, Block.cobblestone.blockID);
		world.setBlockMetadataWithNotify(i + 9, j + 5, k + 5, Block.stoneSingleSlab.blockID, 2);
		world.setBlockMetadataWithNotify(i + 9, j + 5, k + 6, Block.stoneSingleSlab.blockID, 2);
		world.setBlockMetadataWithNotify(i + 9, j + 5, k + 7, Block.stoneSingleSlab.blockID, 2);
		world.setBlockMetadataWithNotify(i + 9, j + 5, k + 8, Block.stoneSingleSlab.blockID, 2);
		world.setBlock(i + 9, j + 5, k + 9, Block.sandStone.blockID);
		world.setBlock(i + 9, j + 5, k + 10, Block.stone.blockID);
		world.setBlock(i + 9, j + 6, k + 0, Block.cobblestoneMossy.blockID);
		world.setBlock(i + 9, j + 6, k + 9, Block.stone.blockID);
		world.setBlock(i + 9, j + 6, k + 10, Block.stone.blockID);
		world.setBlock(i + 10, j + 0, k + 0, Block.cobblestone.blockID);
		world.setBlock(i + 10, j + 0, k + 1, Block.sandStone.blockID);
		world.setBlock(i + 10, j + 0, k + 2, Block.sandStone.blockID);
		world.setBlock(i + 10, j + 0, k + 3, Block.sandStone.blockID);
		world.setBlock(i + 10, j + 0, k + 4, Block.sandStone.blockID);
		world.setBlock(i + 10, j + 0, k + 5, Block.sandStone.blockID);
		world.setBlock(i + 10, j + 0, k + 6, Block.sandStone.blockID);
		world.setBlock(i + 10, j + 0, k + 7, Block.sandStone.blockID);
		world.setBlock(i + 10, j + 0, k + 8, Block.sandStone.blockID);
		world.setBlock(i + 10, j + 0, k + 9, Block.sandStone.blockID);
		world.setBlock(i + 10, j + 0, k + 10, Block.stone.blockID);
		world.setBlock(i + 10, j + 1, k + 0, Block.cobblestoneMossy.blockID);
		world.setBlock(i + 10, j + 1, k + 3, Block.planks.blockID);
		world.setBlock(i + 10, j + 1, k + 4, Block.planks.blockID);
		world.setBlock(i + 10, j + 1, k + 5, Block.planks.blockID);
		world.setBlock(i + 10, j + 1, k + 6, Block.planks.blockID);
		world.setBlock(i + 10, j + 1, k + 7, Block.planks.blockID);
		world.setBlock(i + 10, j + 1, k + 8, Block.planks.blockID);
		world.setBlock(i + 10, j + 1, k + 9, Block.planks.blockID);
		world.setBlock(i + 10, j + 1, k + 10, Block.stone.blockID);
		world.setBlock(i + 10, j + 2, k + 0, Block.cobblestone.blockID);
		world.setBlock(i + 10, j + 2, k + 4, Block.planks.blockID);
		world.setBlock(i + 10, j + 2, k + 5, Block.planks.blockID);
		world.setBlock(i + 10, j + 2, k + 6, Block.planks.blockID);
		world.setBlock(i + 10, j + 2, k + 7, Block.planks.blockID);
		world.setBlock(i + 10, j + 2, k + 8, Block.planks.blockID);
		world.setBlock(i + 10, j + 2, k + 9, Block.planks.blockID);
		world.setBlock(i + 10, j + 2, k + 10, Block.stone.blockID);
		world.setBlock(i + 10, j + 3, k + 0, Block.cobblestoneMossy.blockID);
		world.setBlock(i + 10, j + 3, k + 5, Block.sandStone.blockID);
		world.setBlock(i + 10, j + 3, k + 6, Block.sandStone.blockID);
		world.setBlock(i + 10, j + 3, k + 7, Block.sandStone.blockID);
		world.setBlock(i + 10, j + 3, k + 8, Block.sandStone.blockID);
		world.setBlock(i + 10, j + 3, k + 9, Block.sandStone.blockID);
		world.setBlock(i + 10, j + 3, k + 10, Block.stone.blockID);
		world.setBlock(i + 10, j + 4, k + 0, Block.cobblestoneMossy.blockID);
		world.setBlock(i + 10, j + 4, k + 3, Block.sandStone.blockID);
		world.setBlock(i + 10, j + 4, k + 4, Block.sandStone.blockID);
		world.setBlock(i + 10, j + 4, k + 5, Block.sandStone.blockID);
		world.setBlock(i + 10, j + 4, k + 6, Block.sandStone.blockID);
		world.setBlock(i + 10, j + 4, k + 7, Block.sandStone.blockID);
		world.setBlock(i + 10, j + 4, k + 8, Block.sandStone.blockID);
		world.setBlock(i + 10, j + 4, k + 9, Block.sandStone.blockID);
		world.setBlock(i + 10, j + 4, k + 10, Block.stone.blockID);
		world.setBlock(i + 10, j + 5, k + 0, Block.cobblestoneMossy.blockID);
		world.setBlockMetadataWithNotify(i + 10, j + 5, k + 4, Block.stoneSingleSlab.blockID, 1);
		world.setBlockMetadataWithNotify(i + 10, j + 5, k + 5, Block.stoneSingleSlab.blockID, 1);
		world.setBlock(i + 10, j + 5, k + 6, Block.sandStone.blockID);
		world.setBlockMetadataWithNotify(i + 10, j + 5, k + 7, Block.stoneSingleSlab.blockID, 1);
		world.setBlock(i + 10, j + 5, k + 8, Block.sandStone.blockID);
		world.setBlock(i + 10, j + 5, k + 9, Block.sandStone.blockID);
		world.setBlock(i + 10, j + 5, k + 10, Block.stone.blockID);
		world.setBlock(i + 10, j + 6, k + 0, Block.cobblestone.blockID);
		world.setBlock(i + 10, j + 6, k + 6, Block.stone.blockID);
		world.setBlock(i + 10, j + 6, k + 8, Block.stone.blockID);
		world.setBlock(i + 10, j + 6, k + 9, Block.stone.blockID);
		world.setBlock(i + 10, j + 6, k + 10, Block.stone.blockID);
		world.setBlock(i + 11, j + 0, k + 0, Block.cobblestone.blockID);
		world.setBlock(i + 11, j + 0, k + 1, Block.cobblestone.blockID);
		world.setBlock(i + 11, j + 0, k + 2, Block.cobblestone.blockID);
		world.setBlock(i + 11, j + 0, k + 3, Block.stone.blockID);
		world.setBlock(i + 11, j + 0, k + 4, Block.stone.blockID);
		world.setBlock(i + 11, j + 0, k + 5, Block.stone.blockID);
		world.setBlock(i + 11, j + 0, k + 6, Block.stone.blockID);
		world.setBlock(i + 11, j + 0, k + 7, Block.stone.blockID);
		world.setBlock(i + 11, j + 0, k + 8, Block.stone.blockID);
		world.setBlock(i + 11, j + 0, k + 9, Block.stone.blockID);
		world.setBlock(i + 11, j + 0, k + 10, Block.stone.blockID);
		world.setBlock(i + 11, j + 1, k + 0, Block.cobblestoneMossy.blockID);
		world.setBlock(i + 11, j + 1, k + 1, Block.cobblestoneMossy.blockID);
		world.setBlock(i + 11, j + 1, k + 2, Block.cobblestoneMossy.blockID);
		world.setBlock(i + 11, j + 1, k + 3, Block.cobblestone.blockID);
		world.setBlock(i + 11, j + 1, k + 4, Block.stone.blockID);
		world.setBlock(i + 11, j + 1, k + 5, Block.stone.blockID);
		world.setBlock(i + 11, j + 1, k + 6, Block.stone.blockID);
		world.setBlock(i + 11, j + 1, k + 7, Block.stone.blockID);
		world.setBlock(i + 11, j + 1, k + 8, Block.stone.blockID);
		world.setBlock(i + 11, j + 1, k + 9, Block.stone.blockID);
		world.setBlock(i + 11, j + 1, k + 10, Block.stone.blockID);
		world.setBlock(i + 11, j + 2, k + 0, Block.cobblestoneMossy.blockID);
		world.setBlock(i + 11, j + 2, k + 1, Block.cobblestone.blockID);
		world.setBlock(i + 11, j + 2, k + 2, Block.cobblestoneMossy.blockID);
		world.setBlock(i + 11, j + 2, k + 3, Block.cobblestone.blockID);
		world.setBlock(i + 11, j + 2, k + 4, Block.cobblestone.blockID);
		world.setBlock(i + 11, j + 2, k + 5, Block.cobblestone.blockID);
		world.setBlock(i + 11, j + 2, k + 6, Block.cobblestone.blockID);
		world.setBlock(i + 11, j + 2, k + 7, Block.stone.blockID);
		world.setBlock(i + 11, j + 2, k + 8, Block.stone.blockID);
		world.setBlock(i + 11, j + 2, k + 9, Block.stone.blockID);
		world.setBlock(i + 11, j + 2, k + 10, Block.stone.blockID);
		world.setBlock(i + 11, j + 3, k + 0, Block.cobblestoneMossy.blockID);
		world.setBlock(i + 11, j + 3, k + 1, Block.cobblestone.blockID);
		world.setBlock(i + 11, j + 3, k + 2, Block.cobblestone.blockID);
		world.setBlock(i + 11, j + 3, k + 3, Block.cobblestoneMossy.blockID);
		world.setBlock(i + 11, j + 3, k + 4, Block.cobblestone.blockID);
		world.setBlock(i + 11, j + 3, k + 5, Block.cobblestone.blockID);
		world.setBlock(i + 11, j + 3, k + 6, Block.cobblestone.blockID);
		world.setBlock(i + 11, j + 3, k + 7, Block.cobblestone.blockID);
		world.setBlock(i + 11, j + 3, k + 8, Block.stone.blockID);
		world.setBlock(i + 11, j + 3, k + 9, Block.stone.blockID);
		world.setBlock(i + 11, j + 3, k + 10, Block.stone.blockID);
		world.setBlock(i + 11, j + 4, k + 0, Block.cobblestoneMossy.blockID);
		world.setBlock(i + 11, j + 4, k + 1, Block.cobblestoneMossy.blockID);
		world.setBlock(i + 11, j + 4, k + 2, Block.cobblestoneMossy.blockID);
		world.setBlock(i + 11, j + 4, k + 3, Block.cobblestone.blockID);
		world.setBlock(i + 11, j + 4, k + 4, Block.wood.blockID);
		world.setBlock(i + 11, j + 4, k + 5, Block.stone.blockID);
		world.setBlock(i + 11, j + 4, k + 6, Block.wood.blockID);
		world.setBlock(i + 11, j + 4, k + 7, Block.cobblestone.blockID);
		world.setBlock(i + 11, j + 4, k + 8, Block.wood.blockID);
		world.setBlock(i + 11, j + 4, k + 9, Block.stone.blockID);
		world.setBlock(i + 11, j + 4, k + 10, Block.stone.blockID);
		world.setBlock(i + 11, j + 5, k + 0, Block.cobblestone.blockID);
		world.setBlock(i + 11, j + 5, k + 1, Block.cobblestoneMossy.blockID);
		world.setBlock(i + 11, j + 5, k + 2, Block.cobblestone.blockID);
		world.setBlock(i + 11, j + 5, k + 3, Block.stone.blockID);
		world.setBlock(i + 11, j + 5, k + 4, Block.stone.blockID);
		world.setBlock(i + 11, j + 5, k + 5, Block.stone.blockID);
		world.setBlock(i + 11, j + 5, k + 6, Block.stone.blockID);
		world.setBlock(i + 11, j + 5, k + 7, Block.stone.blockID);
		world.setBlock(i + 11, j + 5, k + 8, Block.stone.blockID);
		world.setBlock(i + 11, j + 5, k + 9, Block.stone.blockID);
		world.setBlock(i + 11, j + 5, k + 10, Block.stone.blockID);
		world.setBlock(i + 11, j + 6, k + 0, Block.cobblestone.blockID);
		world.setBlock(i + 11, j + 6, k + 1, Block.cobblestoneMossy.blockID);
		world.setBlock(i + 11, j + 6, k + 2, Block.cobblestoneMossy.blockID);
		world.setBlock(i + 11, j + 6, k + 3, Block.stone.blockID);
		world.setBlock(i + 11, j + 6, k + 4, Block.stone.blockID);
		world.setBlock(i + 11, j + 6, k + 5, Block.stone.blockID);
		world.setBlock(i + 11, j + 6, k + 6, Block.stone.blockID);
		world.setBlock(i + 11, j + 6, k + 7, Block.stone.blockID);
		world.setBlock(i + 11, j + 6, k + 8, Block.stone.blockID);
		world.setBlock(i + 11, j + 6, k + 9, Block.stone.blockID);
		world.setBlock(i + 11, j + 6, k + 10, Block.stone.blockID);
		world.setBlockMetadataWithNotify(i + 1, j + 4, k + 9, Block.vine.blockID, 1);
		world.setBlockMetadataWithNotify(i + 1, j + 5, k + 7, Block.vine.blockID, 2);
		world.setBlockMetadataWithNotify(i + 1, j + 5, k + 8, Block.vine.blockID, 2);
		world.setBlockMetadataWithNotify(i + 1, j + 5, k + 9, Block.vine.blockID, 1);
		world.setBlock(i + 2, j + 1, k + 3, Block.gravel.blockID);
		world.setBlock(i + 2, j + 1, k + 4, Block.gravel.blockID);
		world.setBlock(i + 2, j + 2, k + 2, Block.gravel.blockID);
		world.setBlock(i + 2, j + 3, k + 2, Block.gravel.blockID);
		world.setBlockMetadataWithNotify(i + 2, j + 4, k + 4, Block.vine.blockID, 4);
		world.setBlock(i + 3, j + 1, k + 2, Block.gravel.blockID);
		world.setBlock(i + 3, j + 1, k + 3, Block.gravel.blockID);
		world.setBlock(i + 3, j + 1, k + 4, Block.gravel.blockID);
		world.setBlock(i + 3, j + 2, k + 2, Block.gravel.blockID);
		world.setBlock(i + 3, j + 2, k + 3, Block.gravel.blockID);
		world.setBlockMetadataWithNotify(i + 3, j + 3, k + 2, Block.torchRedstoneActive.blockID, 2);
		world.setBlock(i + 3, j + 3, k + 3, Block.gravel.blockID);
		world.setBlockMetadataWithNotify(i + 3, j + 4, k + 4, Block.vine.blockID, 4);
		world.setBlockMetadataWithNotify(i + 3, j + 5, k + 2, Block.torchRedstoneIdle.blockID, 5);
		world.setBlock(i + 4, j + 1, k + 2, Block.gravel.blockID);
		world.setBlock(i + 4, j + 1, k + 3, Block.gravel.blockID);
		world.setBlock(i + 4, j + 2, k + 2, Block.gravel.blockID);
		world.setBlock(i + 4, j + 2, k + 3, Block.gravel.blockID);
		world.setBlock(i + 4, j + 3, k + 2, Block.gravel.blockID);
		world.setBlockMetadataWithNotify(i + 4, j + 4, k + 4, Block.vine.blockID, 4);
		world.setBlock(i + 5, j + 1, k + 2, Block.gravel.blockID);
		world.setBlockMetadataWithNotify(i + 7, j + 3, k + 2, Block.vine.blockID, 4);
		world.setBlockMetadataWithNotify(i + 7, j + 4, k + 2, Block.vine.blockID, 4);
		world.setBlockMetadataWithNotify(i + 8, j + 4, k + 1, Block.vine.blockID, 2);
		world.setBlockMetadataWithNotify(i + 9, j + 4, k + 1, Block.vine.blockID, 4);
		world.setBlockMetadataWithNotify(i + 9, j + 4, k + 3, Block.vine.blockID, 8);

		return true;
	}
	private ItemStack pickCheckLootItem(Random var1)
    {
        int var2 = var1.nextInt(11);
        return var2 == 0 ? new ItemStack(Item.swordDiamond, var1.nextInt(5) + 1) : (var2 == 1 && var1.nextInt(3) == 0 ? new ItemStack(Fossil.diamondjavelin) : (var2 == 2 && var1.nextInt(3) == 0 ? new ItemStack(Item.swordGold) : (var2 == 3 ? new ItemStack(Fossil.goldjavelin, var1.nextInt(6) + 1) : (var2 == 4 ? new ItemStack(Item.swordSteel, var1.nextInt(8) + 1) : (var2 == 5 ? new ItemStack(Fossil.ironjavelin, var1.nextInt(15) + 1) : (var2 == 6 && var1.nextInt(2) == 0 ? new ItemStack(Item.swordStone, var1.nextInt(7) + 1) : (var2 == 7 && var1.nextInt(2) == 0 ? new ItemStack(Fossil.stonejavelin, var1.nextInt(4) + 1) : (var2 == 8 ? new ItemStack(Item.swordWood, var1.nextInt(3) + 1) : (var2 == 9 && var1.nextInt(25) == 0 ? new ItemStack(Fossil.woodjavelin, var1.nextInt(3) + 1, 1) : (var2 == 10 && var1.nextInt(4) == 0 ? new ItemStack(Item.bow) : null))))))))));
        
    }
}
