package fossil.gens;

import java.util.Random;

import net.minecraft.block.Block;
import net.minecraft.item.Item;
import net.minecraft.item.ItemStack;
import net.minecraft.tileentity.TileEntityChest;
import net.minecraft.world.World;
import net.minecraft.world.gen.feature.WorldGenerator;

public class WorldGeneratorShipWreck90 extends WorldGenerator
{
	protected int[] GetValidSpawnBlocks()
	{
	return new int[] { Block.waterStill.blockID};
	}
	
	public boolean LocationIsValidSpawn(World world, int i, int j, int k)
	{
	int distanceToAir = 0;
	int checkID = world.getBlockId(i, j, k);

	while (checkID != 0)
	{
	distanceToAir++;
	checkID = world.getBlockId(i, j + distanceToAir, k);
	}

	if (distanceToAir > 0)
	{
	return false;
	}
	j += distanceToAir - 1;

	int blockID = world.getBlockId(i, j, k);
	int blockIDAbove = world.getBlockId(i, j + 1, k);
	int blockIDBelow = world.getBlockId(i, j - 1, k);
	for (int x : GetValidSpawnBlocks())
	{
	if (blockIDAbove != 0)
	{
	return false;
	}
	if (blockID == x)
	{
	return true;
	} else if (blockID == Block.snow.blockID && blockIDBelow == x)
	{
	return true;
	}
	}
	return false;
	}
	
	public WorldGeneratorShipWreck90()
	{
	}
	
	public boolean generate(World world, Random rand, int i, int j, int k)
	{
		if (!LocationIsValidSpawn(world, i, j, k) || !LocationIsValidSpawn(world, i + 4, j, k) || !LocationIsValidSpawn(world, i + 4, j, k + 4) || !LocationIsValidSpawn(world, i, j, k + 4))
		{
		return false;
		}
		
		System.out.println("Generating ShipWreck90");
		world.setBlock(i + 0, j + 9, k + 3, Block.planks.blockID);
		world.setBlock(i + 0, j + 9, k + 4, Block.planks.blockID);
		world.setBlock(i + 0, j + 9, k + 5, Block.planks.blockID);
		world.setBlock(i + 0, j + 9, k + 6, Block.planks.blockID);
		world.setBlock(i + 0, j + 9, k + 7, Block.planks.blockID);
		world.setBlock(i + 0, j + 9, k + 8, Block.planks.blockID);
		world.setBlock(i + 0, j + 10, k + 3, Block.planks.blockID);
		world.setBlock(i + 0, j + 10, k + 4, Block.glass.blockID);
		world.setBlock(i + 0, j + 10, k + 5, Block.glass.blockID);
		world.setBlock(i + 0, j + 10, k + 6, Block.glass.blockID);
		world.setBlock(i + 0, j + 10, k + 7, Block.glass.blockID);
		world.setBlock(i + 0, j + 10, k + 8, Block.planks.blockID);
		world.setBlock(i + 0, j + 11, k + 3, Block.planks.blockID);
		world.setBlock(i + 0, j + 11, k + 4, Block.planks.blockID);
		world.setBlock(i + 0, j + 11, k + 5, Block.planks.blockID);
		world.setBlock(i + 0, j + 11, k + 6, Block.planks.blockID);
		world.setBlock(i + 0, j + 11, k + 7, Block.planks.blockID);
		world.setBlock(i + 0, j + 11, k + 8, Block.planks.blockID);
		world.setBlock(i + 0, j + 12, k + 3, Block.planks.blockID);
		world.setBlock(i + 0, j + 12, k + 4, Block.planks.blockID);
		world.setBlock(i + 0, j + 12, k + 5, Block.planks.blockID);
		world.setBlock(i + 0, j + 12, k + 6, Block.planks.blockID);
		world.setBlock(i + 0, j + 12, k + 7, Block.planks.blockID);
		world.setBlock(i + 0, j + 12, k + 8, Block.planks.blockID);
		world.setBlock(i + 0, j + 13, k + 3, Block.fence.blockID);
		world.setBlock(i + 0, j + 13, k + 4, Block.fence.blockID);
		world.setBlock(i + 0, j + 13, k + 5, Block.fence.blockID);
		world.setBlock(i + 0, j + 13, k + 6, Block.fence.blockID);
		world.setBlock(i + 0, j + 13, k + 7, Block.fence.blockID);
		world.setBlock(i + 0, j + 13, k + 8, Block.fence.blockID);
		world.setBlock(i + 1, j + 3, k + 3, Block.planks.blockID);
		world.setBlock(i + 1, j + 3, k + 4, Block.planks.blockID);
		world.setBlock(i + 1, j + 3, k + 5, Block.planks.blockID);
		world.setBlock(i + 1, j + 3, k + 6, Block.planks.blockID);
		world.setBlock(i + 1, j + 3, k + 7, Block.planks.blockID);
		world.setBlock(i + 1, j + 3, k + 8, Block.planks.blockID);
		world.setBlock(i + 1, j + 4, k + 3, Block.planks.blockID);
		world.setBlock(i + 1, j + 4, k + 4, Block.planks.blockID);
		world.setBlock(i + 1, j + 4, k + 5, Block.planks.blockID);
		world.setBlock(i + 1, j + 4, k + 6, Block.planks.blockID);
		world.setBlock(i + 1, j + 4, k + 7, Block.planks.blockID);
		world.setBlock(i + 1, j + 4, k + 8, Block.planks.blockID);
		world.setBlock(i + 1, j + 5, k + 3, Block.planks.blockID);
		world.setBlock(i + 1, j + 5, k + 4, Block.planks.blockID);
		world.setBlock(i + 1, j + 5, k + 5, Block.planks.blockID);
		world.setBlock(i + 1, j + 5, k + 6, Block.planks.blockID);
		world.setBlock(i + 1, j + 5, k + 7, Block.planks.blockID);
		world.setBlock(i + 1, j + 5, k + 8, Block.planks.blockID);
		world.setBlock(i + 1, j + 6, k + 3, Block.planks.blockID);
		world.setBlock(i + 1, j + 6, k + 4, Block.planks.blockID);
		world.setBlock(i + 1, j + 6, k + 5, Block.planks.blockID);
		world.setBlock(i + 1, j + 6, k + 6, Block.planks.blockID);
		world.setBlock(i + 1, j + 6, k + 7, Block.planks.blockID);
		world.setBlock(i + 1, j + 6, k + 8, Block.planks.blockID);
		world.setBlock(i + 1, j + 7, k + 3, Block.planks.blockID);
		world.setBlock(i + 1, j + 7, k + 4, Block.planks.blockID);
		world.setBlock(i + 1, j + 7, k + 5, Block.planks.blockID);
		world.setBlock(i + 1, j + 7, k + 6, Block.planks.blockID);
		world.setBlock(i + 1, j + 7, k + 7, Block.planks.blockID);
		world.setBlock(i + 1, j + 7, k + 8, Block.planks.blockID);
		world.setBlockAndMetadata(i + 1, j + 8, k + 3, Block.cloth.blockID, 14);
		world.setBlockAndMetadata(i + 1, j + 8, k + 4, Block.cloth.blockID, 14);
		world.setBlockAndMetadata(i + 1, j + 8, k + 5, Block.cloth.blockID, 14);
		world.setBlockAndMetadata(i + 1, j + 8, k + 6, Block.cloth.blockID, 14);
		world.setBlockAndMetadata(i + 1, j + 8, k + 7, Block.cloth.blockID, 14);
		world.setBlockAndMetadata(i + 1, j + 8, k + 8, Block.cloth.blockID, 14);
		world.setBlock(i + 1, j + 9, k + 2, Block.planks.blockID);
		world.setBlock(i + 1, j + 9, k + 9, Block.planks.blockID);
		world.setBlock(i + 1, j + 10, k + 2, Block.planks.blockID);
		world.setBlock(i + 1, j + 10, k + 9, Block.planks.blockID);
		world.setBlock(i + 1, j + 11, k + 2, Block.planks.blockID);
		world.setBlock(i + 1, j + 11, k + 9, Block.planks.blockID);
		world.setBlock(i + 1, j + 12, k + 2, Block.planks.blockID);
		world.setBlock(i + 1, j + 12, k + 3, Block.planks.blockID);
		world.setBlock(i + 1, j + 12, k + 4, Block.planks.blockID);
		world.setBlock(i + 1, j + 12, k + 5, Block.planks.blockID);
		world.setBlock(i + 1, j + 12, k + 6, Block.planks.blockID);
		world.setBlock(i + 1, j + 12, k + 7, Block.planks.blockID);
		world.setBlock(i + 1, j + 12, k + 8, Block.planks.blockID);
		world.setBlock(i + 1, j + 12, k + 9, Block.planks.blockID);
		world.setBlock(i + 1, j + 13, k + 2, Block.fence.blockID);
		world.setBlock(i + 1, j + 13, k + 3, Block.fence.blockID);
		world.setBlock(i + 1, j + 13, k + 8, Block.fence.blockID);
		world.setBlock(i + 1, j + 13, k + 9, Block.fence.blockID);
		world.setBlock(i + 2, j + 2, k + 4, Block.planks.blockID);
		world.setBlock(i + 2, j + 2, k + 5, Block.planks.blockID);
		world.setBlock(i + 2, j + 2, k + 6, Block.planks.blockID);
		world.setBlock(i + 2, j + 2, k + 7, Block.planks.blockID);
		world.setBlock(i + 2, j + 2, k + 8, Block.planks.blockID);
		world.setBlock(i + 2, j + 3, k + 2, Block.planks.blockID);
		world.setBlock(i + 2, j + 3, k + 3, Block.planks.blockID);
		world.setBlock(i + 2, j + 3, k + 8, Block.planks.blockID);
		world.setBlock(i + 2, j + 3, k + 9, Block.planks.blockID);
		world.setBlock(i + 2, j + 4, k + 2, Block.planks.blockID);
		world.setBlock(i + 2, j + 4, k + 3, Block.planks.blockID);
		world.setBlock(i + 2, j + 4, k + 8, Block.planks.blockID);
		world.setBlock(i + 2, j + 4, k + 9, Block.planks.blockID);
		world.setBlock(i + 2, j + 5, k + 2, Block.planks.blockID);
		world.setBlock(i + 2, j + 5, k + 3, Block.planks.blockID);
		world.setBlock(i + 2, j + 5, k + 4, Block.planks.blockID);
		world.setBlock(i + 2, j + 5, k + 5, Block.planks.blockID);
		world.setBlock(i + 2, j + 5, k + 6, Block.planks.blockID);
		world.setBlock(i + 2, j + 5, k + 7, Block.planks.blockID);
		world.setBlock(i + 2, j + 5, k + 8, Block.planks.blockID);
		world.setBlock(i + 2, j + 5, k + 9, Block.planks.blockID);
		world.setBlock(i + 2, j + 6, k + 2, Block.planks.blockID);
		world.setBlock(i + 2, j + 6, k + 3, Block.planks.blockID);
		world.setBlock(i + 2, j + 6, k + 8, Block.planks.blockID);
		world.setBlock(i + 2, j + 6, k + 9, Block.planks.blockID);
		world.setBlock(i + 2, j + 7, k + 2, Block.planks.blockID);
		world.setBlock(i + 2, j + 7, k + 3, Block.planks.blockID);
		world.setBlock(i + 2, j + 7, k + 8, Block.planks.blockID);
		world.setBlock(i + 2, j + 7, k + 9, Block.planks.blockID);
		world.setBlockAndMetadata(i + 2, j + 8, k + 2, Block.cloth.blockID, 14);
		world.setBlockAndMetadata(i + 2, j + 8, k + 3, Block.cloth.blockID, 14);
		world.setBlockAndMetadata(i + 2, j + 8, k + 4, Block.cloth.blockID, 14);
		world.setBlockAndMetadata(i + 2, j + 8, k + 5, Block.cloth.blockID, 14);
		world.setBlockAndMetadata(i + 2, j + 8, k + 6, Block.cloth.blockID, 14);
		world.setBlockAndMetadata(i + 2, j + 8, k + 7, Block.cloth.blockID, 14);
		world.setBlockAndMetadata(i + 2, j + 8, k + 8, Block.cloth.blockID, 14);
		world.setBlockAndMetadata(i + 2, j + 8, k + 9, Block.cloth.blockID, 14);
		world.setBlock(i + 2, j + 9, k + 1, Block.planks.blockID);
		world.setBlock(i + 2, j + 9, k + 10, Block.planks.blockID);
		world.setBlock(i + 2, j + 10, k + 1, Block.planks.blockID);
		world.setBlock(i + 2, j + 10, k + 10, Block.planks.blockID);
		world.setBlock(i + 2, j + 11, k + 1, Block.planks.blockID);
		world.setBlock(i + 2, j + 11, k + 10, Block.planks.blockID);
		world.setBlock(i + 2, j + 12, k + 1, Block.planks.blockID);
		world.setBlock(i + 2, j + 12, k + 2, Block.planks.blockID);
		world.setBlock(i + 2, j + 12, k + 3, Block.planks.blockID);
		world.setBlock(i + 2, j + 12, k + 4, Block.planks.blockID);
		world.setBlock(i + 2, j + 12, k + 5, Block.planks.blockID);
		world.setBlock(i + 2, j + 12, k + 6, Block.planks.blockID);
		world.setBlock(i + 2, j + 12, k + 7, Block.planks.blockID);
		world.setBlock(i + 2, j + 12, k + 8, Block.planks.blockID);
		world.setBlock(i + 2, j + 12, k + 9, Block.planks.blockID);
		world.setBlock(i + 2, j + 12, k + 10, Block.planks.blockID);
		world.setBlock(i + 2, j + 13, k + 1, Block.fence.blockID);
		world.setBlock(i + 2, j + 13, k + 2, Block.fence.blockID);
		world.setBlock(i + 2, j + 13, k + 9, Block.fence.blockID);
		world.setBlock(i + 2, j + 13, k + 10, Block.fence.blockID);
		world.setBlock(i + 3, j + 1, k + 5, Block.planks.blockID);
		world.setBlock(i + 3, j + 1, k + 6, Block.planks.blockID);
		world.setBlock(i + 3, j + 1, k + 7, Block.planks.blockID);
		world.setBlock(i + 3, j + 2, k + 3, Block.planks.blockID);
		world.setBlock(i + 3, j + 2, k + 4, Block.planks.blockID);
		world.setBlock(i + 3, j + 2, k + 5, Block.planks.blockID);
		world.setBlock(i + 3, j + 2, k + 6, Block.planks.blockID);
		world.setBlock(i + 3, j + 2, k + 7, Block.planks.blockID);
		world.setBlock(i + 3, j + 2, k + 8, Block.planks.blockID);
		world.setBlock(i + 3, j + 2, k + 9, Block.planks.blockID);
		world.setBlock(i + 3, j + 3, k + 1, Block.planks.blockID);
		world.setBlock(i + 3, j + 3, k + 2, Block.planks.blockID);
		world.setBlock(i + 3, j + 3, k + 9, Block.planks.blockID);
		world.setBlock(i + 3, j + 3, k + 10, Block.planks.blockID);
		world.setBlock(i + 3, j + 4, k + 1, Block.planks.blockID);
		world.setBlock(i + 3, j + 4, k + 2, Block.planks.blockID);
		world.setBlock(i + 3, j + 4, k + 9, Block.planks.blockID);
		world.setBlock(i + 3, j + 4, k + 10, Block.planks.blockID);
		world.setBlock(i + 3, j + 5, k + 1, Block.planks.blockID);
		world.setBlock(i + 3, j + 5, k + 2, Block.planks.blockID);
		world.setBlock(i + 3, j + 5, k + 3, Block.planks.blockID);
		world.setBlock(i + 3, j + 5, k + 4, Block.planks.blockID);
		world.setBlock(i + 3, j + 5, k + 5, Block.planks.blockID);
		world.setBlock(i + 3, j + 5, k + 6, Block.planks.blockID);
		world.setBlock(i + 3, j + 5, k + 7, Block.planks.blockID);
		world.setBlock(i + 3, j + 5, k + 8, Block.planks.blockID);
		world.setBlock(i + 3, j + 5, k + 9, Block.planks.blockID);
		world.setBlock(i + 3, j + 5, k + 10, Block.planks.blockID);
		world.setBlock(i + 3, j + 6, k + 1, Block.planks.blockID);
		world.setBlock(i + 3, j + 6, k + 2, Block.planks.blockID);
		world.setBlock(i + 3, j + 6, k + 9, Block.planks.blockID);
		world.setBlock(i + 3, j + 6, k + 10, Block.planks.blockID);
		world.setBlock(i + 3, j + 7, k + 1, Block.planks.blockID);
		world.setBlock(i + 3, j + 7, k + 2, Block.planks.blockID);
		world.setBlock(i + 3, j + 7, k + 9, Block.planks.blockID);
		world.setBlock(i + 3, j + 7, k + 10, Block.planks.blockID);
		world.setBlockAndMetadata(i + 3, j + 8, k + 1, Block.cloth.blockID, 14);
		world.setBlockAndMetadata(i + 3, j + 8, k + 2, Block.cloth.blockID, 14);
		world.setBlockAndMetadata(i + 3, j + 8, k + 3, Block.cloth.blockID, 14);
		world.setBlockAndMetadata(i + 3, j + 8, k + 4, Block.cloth.blockID, 14);
		world.setBlockAndMetadata(i + 3, j + 8, k + 5, Block.cloth.blockID, 14);
		world.setBlockAndMetadata(i + 3, j + 8, k + 6, Block.cloth.blockID, 14);
		world.setBlockAndMetadata(i + 3, j + 8, k + 7, Block.cloth.blockID, 14);
		world.setBlockAndMetadata(i + 3, j + 8, k + 8, Block.cloth.blockID, 14);
		world.setBlockAndMetadata(i + 3, j + 8, k + 9, Block.cloth.blockID, 14);
		world.setBlockAndMetadata(i + 3, j + 8, k + 10, Block.cloth.blockID, 14);
		world.setBlock(i + 3, j + 9, k + 0, Block.planks.blockID);
		world.setBlock(i + 3, j + 9, k + 11, Block.planks.blockID);
		world.setBlock(i + 3, j + 10, k + 0, Block.planks.blockID);
		world.setBlock(i + 3, j + 10, k + 11, Block.planks.blockID);
		world.setBlock(i + 3, j + 11, k + 0, Block.planks.blockID);
		world.setBlock(i + 3, j + 11, k + 11, Block.planks.blockID);
		world.setBlock(i + 3, j + 12, k + 0, Block.planks.blockID);
		world.setBlock(i + 3, j + 12, k + 1, Block.planks.blockID);
		world.setBlock(i + 3, j + 12, k + 2, Block.planks.blockID);
		world.setBlock(i + 3, j + 12, k + 3, Block.planks.blockID);
		world.setBlock(i + 3, j + 12, k + 4, Block.planks.blockID);
		world.setBlock(i + 3, j + 12, k + 5, Block.planks.blockID);
		world.setBlock(i + 3, j + 12, k + 6, Block.planks.blockID);
		world.setBlock(i + 3, j + 12, k + 7, Block.planks.blockID);
		world.setBlock(i + 3, j + 12, k + 8, Block.planks.blockID);
		world.setBlock(i + 3, j + 12, k + 9, Block.planks.blockID);
		world.setBlock(i + 3, j + 12, k + 10, Block.planks.blockID);
		world.setBlock(i + 3, j + 12, k + 11, Block.planks.blockID);
		world.setBlock(i + 3, j + 13, k + 0, Block.fence.blockID);
		world.setBlock(i + 3, j + 13, k + 1, Block.fence.blockID);
		world.setBlock(i + 3, j + 13, k + 10, Block.fence.blockID);
		world.setBlock(i + 3, j + 13, k + 11, Block.fence.blockID);
		world.setBlock(i + 4, j + 0, k + 6, Block.planks.blockID);
		world.setBlock(i + 4, j + 1, k + 4, Block.planks.blockID);
		world.setBlock(i + 4, j + 1, k + 5, Block.planks.blockID);
		world.setBlock(i + 4, j + 1, k + 6, Block.planks.blockID);
		world.setBlock(i + 4, j + 1, k + 7, Block.planks.blockID);
		world.setBlock(i + 4, j + 1, k + 8, Block.planks.blockID);
		world.setBlock(i + 4, j + 2, k + 2, Block.planks.blockID);
		world.setBlock(i + 4, j + 2, k + 3, Block.planks.blockID);
		world.setBlock(i + 4, j + 2, k + 4, Block.planks.blockID);
		world.setBlock(i + 4, j + 2, k + 5, Block.planks.blockID);
		world.setBlock(i + 4, j + 2, k + 6, Block.planks.blockID);
		world.setBlock(i + 4, j + 2, k + 7, Block.planks.blockID);
		world.setBlock(i + 4, j + 2, k + 8, Block.planks.blockID);
		world.setBlock(i + 4, j + 2, k + 9, Block.planks.blockID);
		world.setBlock(i + 4, j + 3, k + 1, Block.planks.blockID);
		world.setBlock(i + 4, j + 3, k + 10, Block.planks.blockID);
		world.setBlock(i + 4, j + 4, k + 1, Block.planks.blockID);
		world.setBlock(i + 4, j + 4, k + 10, Block.planks.blockID);
		world.setBlock(i + 4, j + 5, k + 1, Block.planks.blockID);
		world.setBlock(i + 4, j + 5, k + 2, Block.planks.blockID);
		world.setBlock(i + 4, j + 5, k + 3, Block.planks.blockID);
		world.setBlock(i + 4, j + 5, k + 4, Block.planks.blockID);
		world.setBlockAndMetadata(i + 4, j + 5, k + 5, Block.stairCompactPlanks.blockID, 1);
		world.setBlockAndMetadata(i + 4, j + 5, k + 6, Block.stairCompactPlanks.blockID, 1);
		world.setBlock(i + 4, j + 5, k + 7, Block.planks.blockID);
		world.setBlock(i + 4, j + 5, k + 8, Block.planks.blockID);
		world.setBlock(i + 4, j + 5, k + 9, Block.planks.blockID);
		world.setBlock(i + 4, j + 5, k + 10, Block.planks.blockID);
		world.setBlock(i + 4, j + 6, k + 1, Block.planks.blockID);
		world.setBlock(i + 4, j + 6, k + 4, Block.fence.blockID);
		world.setBlock(i + 4, j + 6, k + 7, Block.fence.blockID);
		world.setBlock(i + 4, j + 6, k + 10, Block.planks.blockID);
		world.setBlock(i + 4, j + 7, k + 1, Block.planks.blockID);
		world.setBlock(i + 4, j + 7, k + 10, Block.planks.blockID);
		world.setBlockAndMetadata(i + 4, j + 8, k + 1, Block.cloth.blockID, 14);
		world.setBlockAndMetadata(i + 4, j + 8, k + 2, Block.cloth.blockID, 14);
		world.setBlockAndMetadata(i + 4, j + 8, k + 3, Block.cloth.blockID, 14);
		world.setBlockAndMetadata(i + 4, j + 8, k + 4, Block.cloth.blockID, 14);
		world.setBlockAndMetadata(i + 4, j + 8, k + 5, Block.cloth.blockID, 14);
		world.setBlockAndMetadata(i + 4, j + 8, k + 6, Block.cloth.blockID, 14);
		world.setBlockAndMetadata(i + 4, j + 8, k + 7, Block.cloth.blockID, 14);
		world.setBlockAndMetadata(i + 4, j + 8, k + 8, Block.cloth.blockID, 14);
		world.setBlockAndMetadata(i + 4, j + 8, k + 9, Block.cloth.blockID, 14);
		world.setBlockAndMetadata(i + 4, j + 8, k + 10, Block.cloth.blockID, 14);
		world.setBlock(i + 4, j + 9, k + 0, Block.planks.blockID);
		world.setBlock(i + 4, j + 9, k + 11, Block.planks.blockID);
		world.setBlock(i + 4, j + 10, k + 0, Block.glass.blockID);
		world.setBlock(i + 4, j + 10, k + 11, Block.glass.blockID);
		world.setBlock(i + 4, j + 11, k + 0, Block.planks.blockID);
		world.setBlock(i + 4, j + 11, k + 11, Block.planks.blockID);
		world.setBlock(i + 4, j + 12, k + 0, Block.planks.blockID);
		world.setBlock(i + 4, j + 12, k + 1, Block.planks.blockID);
		world.setBlock(i + 4, j + 12, k + 2, Block.planks.blockID);
		world.setBlock(i + 4, j + 12, k + 3, Block.planks.blockID);
		world.setBlock(i + 4, j + 12, k + 4, Block.planks.blockID);
		world.setBlock(i + 4, j + 12, k + 5, Block.planks.blockID);
		world.setBlock(i + 4, j + 12, k + 6, Block.planks.blockID);
		world.setBlock(i + 4, j + 12, k + 7, Block.planks.blockID);
		world.setBlock(i + 4, j + 12, k + 8, Block.planks.blockID);
		world.setBlock(i + 4, j + 12, k + 9, Block.planks.blockID);
		world.setBlock(i + 4, j + 12, k + 10, Block.planks.blockID);
		world.setBlock(i + 4, j + 12, k + 11, Block.planks.blockID);
		world.setBlock(i + 4, j + 13, k + 0, Block.fence.blockID);
		world.setBlock(i + 4, j + 13, k + 5, Block.wood.blockID);
		world.setBlock(i + 4, j + 13, k + 11, Block.fence.blockID);
		world.setBlock(i + 5, j + 0, k + 5, Block.planks.blockID);
		world.setBlock(i + 5, j + 0, k + 6, Block.planks.blockID);
		world.setBlock(i + 5, j + 0, k + 7, Block.planks.blockID);
		world.setBlock(i + 5, j + 1, k + 3, Block.planks.blockID);
		world.setBlock(i + 5, j + 1, k + 4, Block.planks.blockID);
		world.setBlock(i + 5, j + 1, k + 7, Block.planks.blockID);
		world.setBlock(i + 5, j + 1, k + 8, Block.planks.blockID);
		world.setBlock(i + 5, j + 2, k + 2, Block.planks.blockID);
		world.setBlock(i + 5, j + 2, k + 3, Block.planks.blockID);
		world.setBlock(i + 5, j + 2, k + 4, Block.planks.blockID);
		world.setBlock(i + 5, j + 2, k + 5, Block.planks.blockID);
		world.setBlock(i + 5, j + 2, k + 6, Block.planks.blockID);
		world.setBlock(i + 5, j + 2, k + 7, Block.planks.blockID);
		world.setBlock(i + 5, j + 2, k + 8, Block.planks.blockID);
		world.setBlock(i + 5, j + 2, k + 9, Block.planks.blockID);
		world.setBlock(i + 5, j + 3, k + 1, Block.planks.blockID);
		world.setBlock(i + 5, j + 3, k + 10, Block.planks.blockID);
		world.setBlock(i + 5, j + 4, k + 1, Block.planks.blockID);
		world.setBlockAndMetadata(i + 5, j + 4, k + 5, Block.stairCompactPlanks.blockID, 1);
		world.setBlockAndMetadata(i + 5, j + 4, k + 6, Block.stairCompactPlanks.blockID, 1);
		world.setBlock(i + 5, j + 4, k + 10, Block.planks.blockID);
		world.setBlock(i + 5, j + 5, k + 1, Block.planks.blockID);
		world.setBlock(i + 5, j + 5, k + 2, Block.planks.blockID);
		world.setBlock(i + 5, j + 5, k + 3, Block.planks.blockID);
		world.setBlock(i + 5, j + 5, k + 4, Block.planks.blockID);
		world.setBlock(i + 5, j + 5, k + 7, Block.planks.blockID);
		world.setBlock(i + 5, j + 5, k + 8, Block.planks.blockID);
		world.setBlock(i + 5, j + 5, k + 9, Block.planks.blockID);
		world.setBlock(i + 5, j + 5, k + 10, Block.planks.blockID);
		world.setBlock(i + 5, j + 6, k + 4, Block.fence.blockID);
		world.setBlock(i + 5, j + 6, k + 7, Block.fence.blockID);
		world.setBlockAndMetadata(i + 5, j + 8, k + 1, Block.cloth.blockID, 14);
		world.setBlockAndMetadata(i + 5, j + 8, k + 2, Block.cloth.blockID, 14);
		world.setBlockAndMetadata(i + 5, j + 8, k + 3, Block.cloth.blockID, 14);
		world.setBlockAndMetadata(i + 5, j + 8, k + 4, Block.cloth.blockID, 14);
		world.setBlockAndMetadata(i + 5, j + 8, k + 5, Block.cloth.blockID, 14);
		world.setBlockAndMetadata(i + 5, j + 8, k + 6, Block.cloth.blockID, 14);
		world.setBlockAndMetadata(i + 5, j + 8, k + 7, Block.cloth.blockID, 14);
		world.setBlockAndMetadata(i + 5, j + 8, k + 8, Block.cloth.blockID, 14);
		world.setBlockAndMetadata(i + 5, j + 8, k + 9, Block.cloth.blockID, 14);
		world.setBlockAndMetadata(i + 5, j + 8, k + 10, Block.cloth.blockID, 14);
		world.setBlock(i + 5, j + 9, k + 0, Block.planks.blockID);
		world.setBlock(i + 5, j + 9, k + 11, Block.planks.blockID);
		world.setBlock(i + 5, j + 10, k + 0, Block.glass.blockID);
		world.setBlock(i + 5, j + 10, k + 11, Block.glass.blockID);
		world.setBlock(i + 5, j + 11, k + 0, Block.planks.blockID);
		world.setBlock(i + 5, j + 11, k + 5, Block.pistonExtension.blockID);
		world.setBlock(i + 5, j + 11, k + 11, Block.planks.blockID);
		world.setBlock(i + 5, j + 12, k + 0, Block.planks.blockID);
		world.setBlock(i + 5, j + 12, k + 1, Block.planks.blockID);
		world.setBlock(i + 5, j + 12, k + 2, Block.planks.blockID);
		world.setBlock(i + 5, j + 12, k + 3, Block.planks.blockID);
		world.setBlock(i + 5, j + 12, k + 4, Block.planks.blockID);
		world.setBlock(i + 5, j + 12, k + 5, Block.planks.blockID);
		world.setBlock(i + 5, j + 12, k + 6, Block.planks.blockID);
		world.setBlock(i + 5, j + 12, k + 7, Block.planks.blockID);
		world.setBlock(i + 5, j + 12, k + 8, Block.planks.blockID);
		world.setBlock(i + 5, j + 12, k + 9, Block.planks.blockID);
		world.setBlock(i + 5, j + 12, k + 10, Block.planks.blockID);
		world.setBlock(i + 5, j + 12, k + 11, Block.planks.blockID);
		world.setBlock(i + 5, j + 13, k + 0, Block.fence.blockID);
		world.setBlock(i + 5, j + 13, k + 11, Block.fence.blockID);
		world.setBlock(i + 6, j + 0, k + 4, Block.planks.blockID);
		world.setBlock(i + 6, j + 0, k + 5, Block.planks.blockID);
		world.setBlock(i + 6, j + 0, k + 6, Block.planks.blockID);
		world.setBlock(i + 6, j + 0, k + 7, Block.planks.blockID);
		world.setBlock(i + 6, j + 1, k + 3, Block.planks.blockID);
		world.setBlock(i + 6, j + 1, k + 8, Block.planks.blockID);
		world.setBlock(i + 6, j + 2, k + 2, Block.planks.blockID);
		world.setBlock(i + 6, j + 2, k + 3, Block.planks.blockID);
		world.setBlock(i + 6, j + 2, k + 4, Block.planks.blockID);
		world.setBlock(i + 6, j + 2, k + 7, Block.planks.blockID);
		world.setBlock(i + 6, j + 2, k + 8, Block.planks.blockID);
		world.setBlock(i + 6, j + 2, k + 9, Block.planks.blockID);
		world.setBlock(i + 6, j + 3, k + 1, Block.planks.blockID);
		world.setBlockAndMetadata(i + 6, j + 3, k + 5, Block.stairCompactPlanks.blockID, 1);
		world.setBlockAndMetadata(i + 6, j + 3, k + 6, Block.stairCompactPlanks.blockID, 1);
		world.setBlock(i + 6, j + 3, k + 10, Block.planks.blockID);
		world.setBlock(i + 6, j + 4, k + 1, Block.planks.blockID);
		world.setBlock(i + 6, j + 4, k + 10, Block.planks.blockID);
		world.setBlock(i + 6, j + 5, k + 1, Block.planks.blockID);
		world.setBlock(i + 6, j + 5, k + 2, Block.planks.blockID);
		world.setBlock(i + 6, j + 5, k + 3, Block.planks.blockID);
		world.setBlock(i + 6, j + 5, k + 4, Block.planks.blockID);
		world.setBlock(i + 6, j + 5, k + 7, Block.planks.blockID);
		world.setBlock(i + 6, j + 5, k + 8, Block.planks.blockID);
		world.setBlock(i + 6, j + 5, k + 9, Block.planks.blockID);
		world.setBlock(i + 6, j + 5, k + 10, Block.planks.blockID);
		world.setBlock(i + 6, j + 6, k + 1, Block.planks.blockID);
		world.setBlock(i + 6, j + 6, k + 4, Block.fence.blockID);
		world.setBlock(i + 6, j + 6, k + 7, Block.fence.blockID);
		world.setBlock(i + 6, j + 6, k + 10, Block.planks.blockID);
		world.setBlock(i + 6, j + 7, k + 1, Block.planks.blockID);
		world.setBlock(i + 6, j + 7, k + 10, Block.planks.blockID);
		world.setBlockAndMetadata(i + 6, j + 8, k + 1, Block.cloth.blockID, 14);
		world.setBlockAndMetadata(i + 6, j + 8, k + 2, Block.cloth.blockID, 14);
		world.setBlockAndMetadata(i + 6, j + 8, k + 3, Block.cloth.blockID, 14);
		world.setBlockAndMetadata(i + 6, j + 8, k + 4, Block.cloth.blockID, 14);
		world.setBlockAndMetadata(i + 6, j + 8, k + 5, Block.cloth.blockID, 14);
		world.setBlockAndMetadata(i + 6, j + 8, k + 6, Block.cloth.blockID, 14);
		world.setBlockAndMetadata(i + 6, j + 8, k + 7, Block.cloth.blockID, 14);
		world.setBlockAndMetadata(i + 6, j + 8, k + 8, Block.cloth.blockID, 14);
		world.setBlockAndMetadata(i + 6, j + 8, k + 9, Block.cloth.blockID, 14);
		world.setBlockAndMetadata(i + 6, j + 8, k + 10, Block.cloth.blockID, 14);
		world.setBlock(i + 6, j + 9, k + 0, Block.planks.blockID);
		world.setBlock(i + 6, j + 9, k + 11, Block.planks.blockID);
		world.setBlock(i + 6, j + 10, k + 0, Block.glass.blockID);
		world.setBlock(i + 6, j + 10, k + 11, Block.glass.blockID);
		world.setBlock(i + 6, j + 11, k + 0, Block.planks.blockID);
		world.setBlock(i + 6, j + 11, k + 11, Block.planks.blockID);
		world.setBlock(i + 6, j + 12, k + 0, Block.planks.blockID);
		world.setBlock(i + 6, j + 12, k + 1, Block.planks.blockID);
		world.setBlock(i + 6, j + 12, k + 2, Block.planks.blockID);
		world.setBlock(i + 6, j + 12, k + 3, Block.planks.blockID);
		world.setBlock(i + 6, j + 12, k + 4, Block.planks.blockID);
		world.setBlock(i + 6, j + 12, k + 5, Block.planks.blockID);
		world.setBlock(i + 6, j + 12, k + 6, Block.planks.blockID);
		world.setBlock(i + 6, j + 12, k + 7, Block.planks.blockID);
		world.setBlock(i + 6, j + 12, k + 8, Block.planks.blockID);
		world.setBlock(i + 6, j + 12, k + 9, Block.planks.blockID);
		world.setBlock(i + 6, j + 12, k + 10, Block.planks.blockID);
		world.setBlock(i + 6, j + 12, k + 11, Block.planks.blockID);
		world.setBlock(i + 6, j + 13, k + 0, Block.fence.blockID);
		world.setBlock(i + 6, j + 13, k + 11, Block.fence.blockID);
		world.setBlock(i + 7, j + 0, k + 4, Block.planks.blockID);
		world.setBlock(i + 7, j + 0, k + 5, Block.planks.blockID);
		world.setBlock(i + 7, j + 0, k + 6, Block.planks.blockID);
		world.setBlock(i + 7, j + 0, k + 7, Block.planks.blockID);
		world.setBlock(i + 7, j + 1, k + 3, Block.planks.blockID);
		world.setBlock(i + 7, j + 1, k + 8, Block.planks.blockID);
		world.setBlock(i + 7, j + 2, k + 2, Block.planks.blockID);
		world.setBlock(i + 7, j + 2, k + 3, Block.planks.blockID);
		world.setBlock(i + 7, j + 2, k + 4, Block.planks.blockID);
		world.setBlock(i + 7, j + 2, k + 5, Block.planks.blockID);
		world.setBlock(i + 7, j + 2, k + 6, Block.planks.blockID);
		world.setBlock(i + 7, j + 2, k + 7, Block.planks.blockID);
		world.setBlock(i + 7, j + 2, k + 8, Block.planks.blockID);
		world.setBlock(i + 7, j + 2, k + 9, Block.planks.blockID);
		world.setBlock(i + 7, j + 3, k + 1, Block.planks.blockID);
		world.setBlock(i + 7, j + 3, k + 10, Block.planks.blockID);
		world.setBlock(i + 7, j + 4, k + 1, Block.planks.blockID);
		world.setBlock(i + 7, j + 4, k + 10, Block.planks.blockID);
		world.setBlock(i + 7, j + 5, k + 1, Block.planks.blockID);
		world.setBlock(i + 7, j + 5, k + 2, Block.planks.blockID);
		world.setBlock(i + 7, j + 5, k + 3, Block.planks.blockID);
		world.setBlock(i + 7, j + 5, k + 4, Block.planks.blockID);
		world.setBlock(i + 7, j + 5, k + 7, Block.planks.blockID);
		world.setBlock(i + 7, j + 5, k + 8, Block.planks.blockID);
		world.setBlock(i + 7, j + 5, k + 9, Block.planks.blockID);
		world.setBlock(i + 7, j + 5, k + 10, Block.planks.blockID);
		world.setBlock(i + 7, j + 6, k + 1, Block.planks.blockID);
		world.setBlock(i + 7, j + 6, k + 4, Block.fence.blockID);
		world.setBlock(i + 7, j + 6, k + 7, Block.fence.blockID);
		world.setBlock(i + 7, j + 6, k + 10, Block.planks.blockID);
		world.setBlock(i + 7, j + 7, k + 1, Block.planks.blockID);
		world.setBlock(i + 7, j + 7, k + 10, Block.planks.blockID);
		world.setBlockAndMetadata(i + 7, j + 8, k + 1, Block.cloth.blockID, 14);
		world.setBlockAndMetadata(i + 7, j + 8, k + 2, Block.cloth.blockID, 14);
		world.setBlockAndMetadata(i + 7, j + 8, k + 3, Block.cloth.blockID, 14);
		world.setBlockAndMetadata(i + 7, j + 8, k + 4, Block.cloth.blockID, 14);
		world.setBlockAndMetadata(i + 7, j + 8, k + 5, Block.cloth.blockID, 14);
		world.setBlockAndMetadata(i + 7, j + 8, k + 6, Block.cloth.blockID, 14);
		world.setBlockAndMetadata(i + 7, j + 8, k + 7, Block.cloth.blockID, 14);
		world.setBlockAndMetadata(i + 7, j + 8, k + 8, Block.cloth.blockID, 14);
		world.setBlockAndMetadata(i + 7, j + 8, k + 9, Block.cloth.blockID, 14);
		world.setBlockAndMetadata(i + 7, j + 8, k + 10, Block.cloth.blockID, 14);
		world.setBlock(i + 7, j + 9, k + 0, Block.planks.blockID);
		world.setBlock(i + 7, j + 9, k + 11, Block.planks.blockID);
		world.setBlock(i + 7, j + 10, k + 0, Block.glass.blockID);
		world.setBlock(i + 7, j + 10, k + 11, Block.glass.blockID);
		world.setBlock(i + 7, j + 11, k + 0, Block.planks.blockID);
		world.setBlock(i + 7, j + 11, k + 11, Block.planks.blockID);
		world.setBlock(i + 7, j + 12, k + 0, Block.planks.blockID);
		world.setBlock(i + 7, j + 12, k + 1, Block.planks.blockID);
		world.setBlock(i + 7, j + 12, k + 2, Block.planks.blockID);
		world.setBlock(i + 7, j + 12, k + 3, Block.planks.blockID);
		world.setBlock(i + 7, j + 12, k + 4, Block.planks.blockID);
		world.setBlock(i + 7, j + 12, k + 5, Block.planks.blockID);
		world.setBlock(i + 7, j + 12, k + 6, Block.planks.blockID);
		world.setBlock(i + 7, j + 12, k + 7, Block.planks.blockID);
		world.setBlock(i + 7, j + 12, k + 8, Block.planks.blockID);
		world.setBlock(i + 7, j + 12, k + 9, Block.planks.blockID);
		world.setBlock(i + 7, j + 12, k + 10, Block.planks.blockID);
		world.setBlock(i + 7, j + 12, k + 11, Block.planks.blockID);
		world.setBlock(i + 7, j + 13, k + 0, Block.fence.blockID);
		world.setBlock(i + 7, j + 13, k + 11, Block.fence.blockID);
		world.setBlock(i + 8, j + 0, k + 4, Block.planks.blockID);
		world.setBlock(i + 8, j + 0, k + 5, Block.planks.blockID);
		world.setBlock(i + 8, j + 0, k + 6, Block.planks.blockID);
		world.setBlock(i + 8, j + 0, k + 7, Block.planks.blockID);
		world.setBlock(i + 8, j + 1, k + 3, Block.planks.blockID);
		world.setBlock(i + 8, j + 1, k + 8, Block.planks.blockID);
		world.setBlock(i + 8, j + 2, k + 2, Block.planks.blockID);
		world.setBlock(i + 8, j + 2, k + 3, Block.planks.blockID);
		world.setBlock(i + 8, j + 2, k + 4, Block.planks.blockID);
		world.setBlock(i + 8, j + 2, k + 5, Block.planks.blockID);
		world.setBlock(i + 8, j + 2, k + 6, Block.planks.blockID);
		world.setBlock(i + 8, j + 2, k + 7, Block.planks.blockID);
		world.setBlock(i + 8, j + 2, k + 8, Block.planks.blockID);
		world.setBlock(i + 8, j + 2, k + 9, Block.planks.blockID);
		world.setBlock(i + 8, j + 3, k + 1, Block.planks.blockID);
		world.setBlock(i + 8, j + 3, k + 10, Block.planks.blockID);
		world.setBlock(i + 8, j + 4, k + 1, Block.planks.blockID);
		world.setBlock(i + 8, j + 4, k + 10, Block.planks.blockID);
		world.setBlock(i + 8, j + 5, k + 1, Block.planks.blockID);
		world.setBlock(i + 8, j + 5, k + 2, Block.planks.blockID);
		world.setBlock(i + 8, j + 5, k + 3, Block.planks.blockID);
		world.setBlock(i + 8, j + 5, k + 4, Block.planks.blockID);
		world.setBlock(i + 8, j + 5, k + 5, Block.planks.blockID);
		world.setBlock(i + 8, j + 5, k + 6, Block.planks.blockID);
		world.setBlock(i + 8, j + 5, k + 7, Block.planks.blockID);
		world.setBlock(i + 8, j + 5, k + 8, Block.planks.blockID);
		world.setBlock(i + 8, j + 5, k + 9, Block.planks.blockID);
		world.setBlock(i + 8, j + 5, k + 10, Block.planks.blockID);
		world.setBlock(i + 8, j + 6, k + 4, Block.fence.blockID);
		world.setBlock(i + 8, j + 6, k + 5, Block.fence.blockID);
		world.setBlock(i + 8, j + 6, k + 6, Block.fence.blockID);
		world.setBlock(i + 8, j + 6, k + 7, Block.fence.blockID);
		world.setBlockAndMetadata(i + 8, j + 8, k + 1, Block.cloth.blockID, 14);
		world.setBlockAndMetadata(i + 8, j + 8, k + 2, Block.cloth.blockID, 14);
		world.setBlockAndMetadata(i + 8, j + 8, k + 3, Block.cloth.blockID, 14);
		world.setBlockAndMetadata(i + 8, j + 8, k + 4, Block.cloth.blockID, 14);
		world.setBlockAndMetadata(i + 8, j + 8, k + 5, Block.cloth.blockID, 14);
		world.setBlockAndMetadata(i + 8, j + 8, k + 6, Block.cloth.blockID, 14);
		world.setBlockAndMetadata(i + 8, j + 8, k + 7, Block.cloth.blockID, 14);
		world.setBlockAndMetadata(i + 8, j + 8, k + 8, Block.cloth.blockID, 14);
		world.setBlockAndMetadata(i + 8, j + 8, k + 9, Block.cloth.blockID, 14);
		world.setBlockAndMetadata(i + 8, j + 8, k + 10, Block.cloth.blockID, 14);
		world.setBlock(i + 8, j + 9, k + 0, Block.planks.blockID);
		world.setBlock(i + 8, j + 9, k + 11, Block.planks.blockID);
		world.setBlock(i + 8, j + 10, k + 0, Block.planks.blockID);
		world.setBlock(i + 8, j + 10, k + 11, Block.planks.blockID);
		world.setBlock(i + 8, j + 11, k + 0, Block.planks.blockID);
		world.setBlock(i + 8, j + 11, k + 11, Block.planks.blockID);
		world.setBlock(i + 8, j + 12, k + 0, Block.planks.blockID);
		world.setBlock(i + 8, j + 12, k + 1, Block.planks.blockID);
		world.setBlock(i + 8, j + 12, k + 2, Block.planks.blockID);
		world.setBlock(i + 8, j + 12, k + 3, Block.planks.blockID);
		world.setBlock(i + 8, j + 12, k + 4, Block.planks.blockID);
		world.setBlock(i + 8, j + 12, k + 5, Block.planks.blockID);
		world.setBlock(i + 8, j + 12, k + 6, Block.planks.blockID);
		world.setBlock(i + 8, j + 12, k + 7, Block.planks.blockID);
		world.setBlock(i + 8, j + 12, k + 8, Block.planks.blockID);
		world.setBlock(i + 8, j + 12, k + 9, Block.planks.blockID);
		world.setBlock(i + 8, j + 12, k + 10, Block.planks.blockID);
		world.setBlock(i + 8, j + 12, k + 11, Block.planks.blockID);
		world.setBlock(i + 8, j + 13, k + 0, Block.fence.blockID);
		world.setBlock(i + 8, j + 13, k + 11, Block.fence.blockID);
		world.setBlock(i + 9, j + 0, k + 4, Block.planks.blockID);
		world.setBlock(i + 9, j + 0, k + 5, Block.planks.blockID);
		world.setBlock(i + 9, j + 0, k + 6, Block.planks.blockID);
		world.setBlock(i + 9, j + 0, k + 7, Block.planks.blockID);
		world.setBlock(i + 9, j + 1, k + 3, Block.planks.blockID);
		world.setBlock(i + 9, j + 1, k + 8, Block.planks.blockID);
		world.setBlock(i + 9, j + 2, k + 2, Block.planks.blockID);
		world.setBlock(i + 9, j + 2, k + 3, Block.planks.blockID);
		world.setBlock(i + 9, j + 2, k + 4, Block.planks.blockID);
		world.setBlock(i + 9, j + 2, k + 5, Block.planks.blockID);
		world.setBlock(i + 9, j + 2, k + 6, Block.planks.blockID);
		world.setBlock(i + 9, j + 2, k + 7, Block.planks.blockID);
		world.setBlock(i + 9, j + 2, k + 8, Block.planks.blockID);
		world.setBlock(i + 9, j + 2, k + 9, Block.planks.blockID);
		world.setBlock(i + 9, j + 3, k + 1, Block.planks.blockID);
		world.setBlock(i + 9, j + 3, k + 2, Block.planks.blockID);
		world.setBlock(i + 9, j + 3, k + 3, Block.planks.blockID);
		world.setBlock(i + 9, j + 3, k + 4, Block.planks.blockID);
		world.setBlock(i + 9, j + 3, k + 5, Block.planks.blockID);
		world.setBlock(i + 9, j + 3, k + 6, Block.planks.blockID);
		world.setBlock(i + 9, j + 3, k + 10, Block.planks.blockID);
		world.setBlock(i + 9, j + 4, k + 1, Block.planks.blockID);
		world.setBlock(i + 9, j + 4, k + 2, Block.planks.blockID);
		world.setBlock(i + 9, j + 4, k + 3, Block.planks.blockID);
		world.setBlock(i + 9, j + 4, k + 4, Block.planks.blockID);
		world.setBlock(i + 9, j + 4, k + 5, Block.planks.blockID);
		world.setBlock(i + 9, j + 4, k + 6, Block.planks.blockID);
		world.setBlock(i + 9, j + 4, k + 10, Block.planks.blockID);
		world.setBlock(i + 9, j + 5, k + 1, Block.planks.blockID);
		world.setBlock(i + 9, j + 5, k + 2, Block.planks.blockID);
		world.setBlock(i + 9, j + 5, k + 3, Block.planks.blockID);
		world.setBlock(i + 9, j + 5, k + 4, Block.planks.blockID);
		world.setBlock(i + 9, j + 5, k + 5, Block.planks.blockID);
		world.setBlock(i + 9, j + 5, k + 6, Block.planks.blockID);
		world.setBlock(i + 9, j + 5, k + 7, Block.planks.blockID);
		world.setBlock(i + 9, j + 5, k + 8, Block.planks.blockID);
		world.setBlock(i + 9, j + 5, k + 9, Block.planks.blockID);
		world.setBlock(i + 9, j + 5, k + 10, Block.planks.blockID);
		world.setBlock(i + 9, j + 6, k + 1, Block.planks.blockID);
		world.setBlock(i + 9, j + 6, k + 10, Block.planks.blockID);
		world.setBlock(i + 9, j + 7, k + 1, Block.planks.blockID);
		world.setBlock(i + 9, j + 7, k + 10, Block.planks.blockID);
		world.setBlock(i + 9, j + 8, k + 1, Block.planks.blockID);
		world.setBlock(i + 9, j + 8, k + 2, Block.planks.blockID);
		world.setBlock(i + 9, j + 8, k + 3, Block.planks.blockID);
		world.setBlock(i + 9, j + 8, k + 4, Block.planks.blockID);
		world.setBlock(i + 9, j + 8, k + 5, Block.planks.blockID);
		world.setBlock(i + 9, j + 8, k + 6, Block.planks.blockID);
		world.setBlock(i + 9, j + 8, k + 7, Block.planks.blockID);
		world.setBlock(i + 9, j + 8, k + 8, Block.planks.blockID);
		world.setBlock(i + 9, j + 8, k + 9, Block.planks.blockID);
		world.setBlock(i + 9, j + 8, k + 10, Block.planks.blockID);
		world.setBlock(i + 9, j + 9, k + 0, Block.planks.blockID);
		world.setBlock(i + 9, j + 9, k + 1, Block.planks.blockID);
		world.setBlock(i + 9, j + 9, k + 2, Block.planks.blockID);
		world.setBlock(i + 9, j + 9, k + 3, Block.planks.blockID);
		world.setBlock(i + 9, j + 9, k + 4, Block.planks.blockID);
		world.setBlock(i + 9, j + 9, k + 7, Block.planks.blockID);
		world.setBlock(i + 9, j + 9, k + 8, Block.planks.blockID);
		world.setBlock(i + 9, j + 9, k + 9, Block.planks.blockID);
		world.setBlock(i + 9, j + 9, k + 10, Block.planks.blockID);
		world.setBlock(i + 9, j + 9, k + 11, Block.planks.blockID);
		world.setBlock(i + 9, j + 10, k + 0, Block.planks.blockID);
		world.setBlock(i + 9, j + 10, k + 1, Block.planks.blockID);
		world.setBlock(i + 9, j + 10, k + 2, Block.planks.blockID);
		world.setBlock(i + 9, j + 10, k + 3, Block.planks.blockID);
		world.setBlock(i + 9, j + 10, k + 4, Block.planks.blockID);
		world.setBlock(i + 9, j + 10, k + 7, Block.planks.blockID);
		world.setBlock(i + 9, j + 10, k + 8, Block.planks.blockID);
		world.setBlock(i + 9, j + 10, k + 9, Block.planks.blockID);
		world.setBlock(i + 9, j + 10, k + 10, Block.planks.blockID);
		world.setBlock(i + 9, j + 10, k + 11, Block.planks.blockID);
		world.setBlock(i + 9, j + 11, k + 1, Block.planks.blockID);
		world.setBlock(i + 9, j + 11, k + 2, Block.planks.blockID);
		world.setBlock(i + 9, j + 11, k + 3, Block.planks.blockID);
		world.setBlock(i + 9, j + 11, k + 4, Block.planks.blockID);
		world.setBlock(i + 9, j + 11, k + 5, Block.planks.blockID);
		world.setBlock(i + 9, j + 11, k + 6, Block.planks.blockID);
		world.setBlock(i + 9, j + 11, k + 7, Block.planks.blockID);
		world.setBlock(i + 9, j + 11, k + 8, Block.planks.blockID);
		world.setBlock(i + 9, j + 11, k + 9, Block.planks.blockID);
		world.setBlock(i + 9, j + 11, k + 10, Block.planks.blockID);
		world.setBlock(i + 9, j + 11, k + 11, Block.planks.blockID);
		world.setBlock(i + 9, j + 12, k + 0, Block.planks.blockID);
		world.setBlock(i + 9, j + 12, k + 1, Block.planks.blockID);
		world.setBlock(i + 9, j + 12, k + 2, Block.planks.blockID);
		world.setBlock(i + 9, j + 12, k + 3, Block.planks.blockID);
		world.setBlock(i + 9, j + 12, k + 4, Block.planks.blockID);
		world.setBlock(i + 9, j + 12, k + 5, Block.planks.blockID);
		world.setBlock(i + 9, j + 12, k + 6, Block.planks.blockID);
		world.setBlock(i + 9, j + 12, k + 7, Block.planks.blockID);
		world.setBlock(i + 9, j + 12, k + 8, Block.planks.blockID);
		world.setBlock(i + 9, j + 12, k + 9, Block.planks.blockID);
		world.setBlock(i + 9, j + 12, k + 10, Block.planks.blockID);
		world.setBlock(i + 9, j + 12, k + 11, Block.planks.blockID);
		world.setBlock(i + 9, j + 13, k + 0, Block.fence.blockID);
		world.setBlock(i + 9, j + 13, k + 11, Block.fence.blockID);
		world.setBlock(i + 10, j + 0, k + 4, Block.planks.blockID);
		world.setBlock(i + 10, j + 0, k + 5, Block.planks.blockID);
		world.setBlock(i + 10, j + 0, k + 6, Block.planks.blockID);
		world.setBlock(i + 10, j + 0, k + 7, Block.planks.blockID);
		world.setBlock(i + 10, j + 1, k + 3, Block.planks.blockID);
		world.setBlock(i + 10, j + 1, k + 8, Block.planks.blockID);
		world.setBlock(i + 10, j + 2, k + 2, Block.planks.blockID);
		world.setBlock(i + 10, j + 2, k + 3, Block.planks.blockID);
		world.setBlock(i + 10, j + 2, k + 4, Block.planks.blockID);
		world.setBlock(i + 10, j + 2, k + 5, Block.planks.blockID);
		world.setBlock(i + 10, j + 2, k + 6, Block.planks.blockID);
		world.setBlock(i + 10, j + 2, k + 7, Block.planks.blockID);
		world.setBlock(i + 10, j + 2, k + 8, Block.planks.blockID);
		world.setBlock(i + 10, j + 2, k + 9, Block.planks.blockID);
		world.setBlock(i + 10, j + 3, k + 1, Block.planks.blockID);
		world.setBlock(i + 10, j + 3, k + 6, Block.planks.blockID);
		world.setBlock(i + 10, j + 3, k + 10, Block.planks.blockID);
		world.setBlock(i + 10, j + 4, k + 1, Block.planks.blockID);
		world.setBlock(i + 10, j + 4, k + 6, Block.planks.blockID);
		world.setBlock(i + 10, j + 4, k + 10, Block.planks.blockID);
		world.setBlock(i + 10, j + 5, k + 1, Block.planks.blockID);
		world.setBlock(i + 10, j + 5, k + 2, Block.planks.blockID);
		world.setBlock(i + 10, j + 5, k + 3, Block.planks.blockID);
		world.setBlock(i + 10, j + 5, k + 4, Block.planks.blockID);
		world.setBlock(i + 10, j + 5, k + 5, Block.planks.blockID);
		world.setBlock(i + 10, j + 5, k + 6, Block.planks.blockID);
		world.setBlock(i + 10, j + 5, k + 7, Block.planks.blockID);
		world.setBlock(i + 10, j + 5, k + 8, Block.planks.blockID);
		world.setBlock(i + 10, j + 5, k + 9, Block.planks.blockID);
		world.setBlock(i + 10, j + 5, k + 10, Block.planks.blockID);
		world.setBlock(i + 10, j + 6, k + 1, Block.planks.blockID);
		world.setBlock(i + 10, j + 6, k + 10, Block.planks.blockID);
		world.setBlock(i + 10, j + 7, k + 1, Block.planks.blockID);
		world.setBlock(i + 10, j + 7, k + 10, Block.planks.blockID);
		world.setBlock(i + 10, j + 8, k + 1, Block.planks.blockID);
		world.setBlock(i + 10, j + 8, k + 2, Block.planks.blockID);
		world.setBlock(i + 10, j + 8, k + 3, Block.planks.blockID);
		world.setBlock(i + 10, j + 8, k + 4, Block.planks.blockID);
		world.setBlock(i + 10, j + 8, k + 5, Block.planks.blockID);
		world.setBlock(i + 10, j + 8, k + 6, Block.planks.blockID);
		world.setBlock(i + 10, j + 8, k + 7, Block.planks.blockID);
		world.setBlock(i + 10, j + 8, k + 8, Block.planks.blockID);
		world.setBlock(i + 10, j + 8, k + 9, Block.planks.blockID);
		world.setBlock(i + 10, j + 8, k + 10, Block.planks.blockID);
		world.setBlock(i + 10, j + 9, k + 2, Block.planks.blockID);
		world.setBlock(i + 10, j + 9, k + 3, Block.planks.blockID);
		world.setBlock(i + 10, j + 9, k + 8, Block.planks.blockID);
		world.setBlock(i + 10, j + 9, k + 9, Block.planks.blockID);
		world.setBlock(i + 10, j + 10, k + 2, Block.planks.blockID);
		world.setBlock(i + 10, j + 10, k + 3, Block.planks.blockID);
		world.setBlock(i + 10, j + 10, k + 8, Block.planks.blockID);
		world.setBlock(i + 10, j + 10, k + 9, Block.planks.blockID);
		world.setBlock(i + 10, j + 11, k + 2, Block.planks.blockID);
		world.setBlock(i + 10, j + 11, k + 3, Block.planks.blockID);
		world.setBlock(i + 10, j + 11, k + 8, Block.planks.blockID);
		world.setBlock(i + 10, j + 11, k + 9, Block.planks.blockID);
		world.setBlockAndMetadata(i + 10, j + 12, k + 2, Block.stairCompactPlanks.blockID, 1);
		world.setBlockAndMetadata(i + 10, j + 12, k + 3, Block.stairCompactPlanks.blockID, 1);
		world.setBlockAndMetadata(i + 10, j + 12, k + 8, Block.stairCompactPlanks.blockID, 1);
		world.setBlockAndMetadata(i + 10, j + 12, k + 9, Block.stairCompactPlanks.blockID, 1);
		world.setBlock(i + 11, j + 0, k + 4, Block.planks.blockID);
		world.setBlock(i + 11, j + 0, k + 5, Block.planks.blockID);
		world.setBlock(i + 11, j + 0, k + 6, Block.planks.blockID);
		world.setBlock(i + 11, j + 0, k + 7, Block.planks.blockID);
		world.setBlock(i + 11, j + 1, k + 3, Block.planks.blockID);
		world.setBlock(i + 11, j + 1, k + 8, Block.planks.blockID);
		world.setBlock(i + 11, j + 2, k + 2, Block.planks.blockID);
		world.setBlock(i + 11, j + 2, k + 3, Block.planks.blockID);
		world.setBlock(i + 11, j + 2, k + 4, Block.planks.blockID);
		world.setBlock(i + 11, j + 2, k + 5, Block.planks.blockID);
		world.setBlock(i + 11, j + 2, k + 6, Block.planks.blockID);
		world.setBlock(i + 11, j + 2, k + 7, Block.planks.blockID);
		world.setBlock(i + 11, j + 2, k + 8, Block.planks.blockID);
		world.setBlock(i + 11, j + 2, k + 9, Block.planks.blockID);
		world.setBlock(i + 11, j + 3, k + 1, Block.planks.blockID);
		world.setBlock(i + 11, j + 3, k + 10, Block.planks.blockID);
		world.setBlock(i + 11, j + 4, k + 1, Block.glass.blockID);
		world.setBlock(i + 11, j + 4, k + 10, Block.glass.blockID);
		world.setBlock(i + 11, j + 5, k + 1, Block.planks.blockID);
		world.setBlock(i + 11, j + 5, k + 2, Block.planks.blockID);
		world.setBlock(i + 11, j + 5, k + 3, Block.planks.blockID);
		world.setBlock(i + 11, j + 5, k + 4, Block.planks.blockID);
		world.setBlock(i + 11, j + 5, k + 5, Block.planks.blockID);
		world.setBlock(i + 11, j + 5, k + 6, Block.planks.blockID);
		world.setBlock(i + 11, j + 5, k + 7, Block.planks.blockID);
		world.setBlock(i + 11, j + 5, k + 8, Block.planks.blockID);
		world.setBlock(i + 11, j + 5, k + 9, Block.planks.blockID);
		world.setBlock(i + 11, j + 5, k + 10, Block.planks.blockID);
		world.setBlock(i + 11, j + 8, k + 1, Block.planks.blockID);
		world.setBlock(i + 11, j + 8, k + 2, Block.planks.blockID);
		world.setBlock(i + 11, j + 8, k + 3, Block.planks.blockID);
		world.setBlock(i + 11, j + 8, k + 4, Block.planks.blockID);
		world.setBlock(i + 11, j + 8, k + 5, Block.planks.blockID);
		world.setBlock(i + 11, j + 8, k + 6, Block.planks.blockID);
		world.setBlock(i + 11, j + 8, k + 7, Block.planks.blockID);
		world.setBlock(i + 11, j + 8, k + 8, Block.planks.blockID);
		world.setBlock(i + 11, j + 8, k + 9, Block.planks.blockID);
		world.setBlock(i + 11, j + 8, k + 10, Block.planks.blockID);
		world.setBlock(i + 11, j + 9, k + 1, Block.fence.blockID);
		world.setBlock(i + 11, j + 9, k + 2, Block.planks.blockID);
		world.setBlock(i + 11, j + 9, k + 3, Block.planks.blockID);
		world.setBlockAndMetadata(i + 11, j + 9, k + 4, Block.chest.blockID, 3);
		TileEntityChest var9 = (TileEntityChest)world.getBlockTileEntity(i + 11, j + 9, k + 4);
        int var10;

        if (var9 != null)
        {
            for (var10 = 0; var10 < 8; ++var10)
            {
                ItemStack var11 = this.pickCheckLootItem(rand);

                if (var11 != null)
                {
                    var9.setInventorySlotContents(rand.nextInt(var9.getSizeInventory()), var11);
                }
            }
        }
		world.setBlock(i + 11, j + 9, k + 8, Block.planks.blockID);
		world.setBlock(i + 11, j + 9, k + 9, Block.planks.blockID);
		world.setBlock(i + 11, j + 9, k + 10, Block.fence.blockID);
		world.setBlock(i + 11, j + 10, k + 2, Block.planks.blockID);
		world.setBlock(i + 11, j + 10, k + 3, Block.planks.blockID);
		world.setBlock(i + 11, j + 10, k + 8, Block.planks.blockID);
		world.setBlock(i + 11, j + 10, k + 9, Block.planks.blockID);
		world.setBlockAndMetadata(i + 11, j + 11, k + 2, Block.stairCompactPlanks.blockID, 1);
		world.setBlockAndMetadata(i + 11, j + 11, k + 3, Block.stairCompactPlanks.blockID, 1);
		world.setBlockAndMetadata(i + 11, j + 11, k + 8, Block.stairCompactPlanks.blockID, 1);
		world.setBlockAndMetadata(i + 11, j + 11, k + 9, Block.stairCompactPlanks.blockID, 1);
		world.setBlock(i + 12, j + 0, k + 4, Block.planks.blockID);
		world.setBlock(i + 12, j + 0, k + 5, Block.planks.blockID);
		world.setBlock(i + 12, j + 0, k + 6, Block.planks.blockID);
		world.setBlock(i + 12, j + 0, k + 7, Block.planks.blockID);
		world.setBlock(i + 12, j + 1, k + 3, Block.planks.blockID);
		world.setBlock(i + 12, j + 1, k + 8, Block.planks.blockID);
		world.setBlock(i + 12, j + 2, k + 2, Block.planks.blockID);
		world.setBlock(i + 12, j + 2, k + 3, Block.planks.blockID);
		world.setBlock(i + 12, j + 2, k + 4, Block.planks.blockID);
		world.setBlock(i + 12, j + 2, k + 5, Block.planks.blockID);
		world.setBlock(i + 12, j + 2, k + 6, Block.planks.blockID);
		world.setBlock(i + 12, j + 2, k + 7, Block.planks.blockID);
		world.setBlock(i + 12, j + 2, k + 8, Block.planks.blockID);
		world.setBlock(i + 12, j + 2, k + 9, Block.planks.blockID);
		world.setBlock(i + 12, j + 3, k + 1, Block.planks.blockID);
		world.setBlock(i + 12, j + 3, k + 6, Block.planks.blockID);
		world.setBlock(i + 12, j + 3, k + 10, Block.planks.blockID);
		world.setBlock(i + 12, j + 4, k + 1, Block.planks.blockID);
		world.setBlock(i + 12, j + 4, k + 6, Block.planks.blockID);
		world.setBlock(i + 12, j + 4, k + 10, Block.planks.blockID);
		world.setBlock(i + 12, j + 5, k + 1, Block.planks.blockID);
		world.setBlock(i + 12, j + 5, k + 2, Block.planks.blockID);
		world.setBlock(i + 12, j + 5, k + 3, Block.planks.blockID);
		world.setBlock(i + 12, j + 5, k + 4, Block.planks.blockID);
		world.setBlock(i + 12, j + 5, k + 5, Block.planks.blockID);
		world.setBlock(i + 12, j + 5, k + 6, Block.planks.blockID);
		world.setBlock(i + 12, j + 5, k + 7, Block.planks.blockID);
		world.setBlock(i + 12, j + 5, k + 8, Block.planks.blockID);
		world.setBlock(i + 12, j + 5, k + 9, Block.planks.blockID);
		world.setBlock(i + 12, j + 5, k + 10, Block.planks.blockID);
		world.setBlock(i + 12, j + 6, k + 1, Block.planks.blockID);
		world.setBlock(i + 12, j + 6, k + 3, Block.cloth.blockID);
		world.setBlock(i + 12, j + 6, k + 4, Block.cloth.blockID);
		world.setBlock(i + 12, j + 6, k + 5, Block.cloth.blockID);
		world.setBlock(i + 12, j + 6, k + 6, Block.cloth.blockID);
		world.setBlock(i + 12, j + 6, k + 7, Block.cloth.blockID);
		world.setBlock(i + 12, j + 6, k + 8, Block.cloth.blockID);
		world.setBlock(i + 12, j + 6, k + 10, Block.planks.blockID);
		world.setBlock(i + 12, j + 7, k + 1, Block.planks.blockID);
		world.setBlock(i + 12, j + 7, k + 10, Block.planks.blockID);
		world.setBlock(i + 12, j + 8, k + 1, Block.planks.blockID);
		world.setBlock(i + 12, j + 8, k + 2, Block.planks.blockID);
		world.setBlock(i + 12, j + 8, k + 3, Block.planks.blockID);
		world.setBlock(i + 12, j + 8, k + 4, Block.planks.blockID);
		world.setBlock(i + 12, j + 8, k + 5, Block.planks.blockID);
		world.setBlock(i + 12, j + 8, k + 6, Block.planks.blockID);
		world.setBlock(i + 12, j + 8, k + 7, Block.planks.blockID);
		world.setBlock(i + 12, j + 8, k + 8, Block.planks.blockID);
		world.setBlock(i + 12, j + 8, k + 9, Block.planks.blockID);
		world.setBlock(i + 12, j + 8, k + 10, Block.planks.blockID);
		world.setBlock(i + 12, j + 9, k + 1, Block.fence.blockID);
		world.setBlock(i + 12, j + 9, k + 2, Block.planks.blockID);
		world.setBlock(i + 12, j + 9, k + 3, Block.planks.blockID);
		world.setBlock(i + 12, j + 9, k + 8, Block.planks.blockID);
		world.setBlock(i + 12, j + 9, k + 9, Block.planks.blockID);
		world.setBlock(i + 12, j + 9, k + 10, Block.fence.blockID);
		world.setBlockAndMetadata(i + 12, j + 10, k + 2, Block.stairCompactPlanks.blockID, 1);
		world.setBlockAndMetadata(i + 12, j + 10, k + 3, Block.stairCompactPlanks.blockID, 1);
		world.setBlockAndMetadata(i + 12, j + 10, k + 8, Block.stairCompactPlanks.blockID, 1);
		world.setBlockAndMetadata(i + 12, j + 10, k + 9, Block.stairCompactPlanks.blockID, 1);
		world.setBlock(i + 13, j + 0, k + 4, Block.planks.blockID);
		world.setBlock(i + 13, j + 0, k + 5, Block.planks.blockID);
		world.setBlock(i + 13, j + 0, k + 6, Block.planks.blockID);
		world.setBlock(i + 13, j + 0, k + 7, Block.planks.blockID);
		world.setBlock(i + 13, j + 1, k + 3, Block.planks.blockID);
		world.setBlock(i + 13, j + 1, k + 8, Block.planks.blockID);
		world.setBlock(i + 13, j + 2, k + 2, Block.planks.blockID);
		world.setBlock(i + 13, j + 2, k + 3, Block.planks.blockID);
		world.setBlock(i + 13, j + 2, k + 4, Block.planks.blockID);
		world.setBlock(i + 13, j + 2, k + 5, Block.planks.blockID);
		world.setBlock(i + 13, j + 2, k + 6, Block.planks.blockID);
		world.setBlock(i + 13, j + 2, k + 7, Block.planks.blockID);
		world.setBlock(i + 13, j + 2, k + 8, Block.planks.blockID);
		world.setBlock(i + 13, j + 2, k + 9, Block.planks.blockID);
		world.setBlock(i + 13, j + 3, k + 1, Block.planks.blockID);
		world.setBlock(i + 13, j + 3, k + 6, Block.planks.blockID);
		world.setBlock(i + 13, j + 3, k + 10, Block.planks.blockID);
		world.setBlock(i + 13, j + 4, k + 1, Block.planks.blockID);
		world.setBlock(i + 13, j + 4, k + 6, Block.planks.blockID);
		world.setBlock(i + 13, j + 4, k + 10, Block.planks.blockID);
		world.setBlock(i + 13, j + 5, k + 1, Block.planks.blockID);
		world.setBlock(i + 13, j + 5, k + 2, Block.planks.blockID);
		world.setBlock(i + 13, j + 5, k + 3, Block.planks.blockID);
		world.setBlock(i + 13, j + 5, k + 4, Block.planks.blockID);
		world.setBlock(i + 13, j + 5, k + 5, Block.planks.blockID);
		world.setBlock(i + 13, j + 5, k + 6, Block.planks.blockID);
		world.setBlock(i + 13, j + 5, k + 7, Block.planks.blockID);
		world.setBlock(i + 13, j + 5, k + 8, Block.planks.blockID);
		world.setBlock(i + 13, j + 5, k + 9, Block.planks.blockID);
		world.setBlock(i + 13, j + 5, k + 10, Block.planks.blockID);
		world.setBlock(i + 13, j + 6, k + 1, Block.planks.blockID);
		world.setBlock(i + 13, j + 6, k + 3, Block.cloth.blockID);
		world.setBlock(i + 13, j + 6, k + 4, Block.cloth.blockID);
		world.setBlock(i + 13, j + 6, k + 5, Block.cloth.blockID);
		world.setBlock(i + 13, j + 6, k + 6, Block.cloth.blockID);
		world.setBlock(i + 13, j + 6, k + 7, Block.cloth.blockID);
		world.setBlock(i + 13, j + 6, k + 8, Block.cloth.blockID);
		world.setBlock(i + 13, j + 6, k + 10, Block.planks.blockID);
		world.setBlock(i + 13, j + 7, k + 1, Block.planks.blockID);
		world.setBlock(i + 13, j + 7, k + 3, Block.cloth.blockID);
		world.setBlock(i + 13, j + 7, k + 4, Block.cloth.blockID);
		world.setBlock(i + 13, j + 7, k + 5, Block.cloth.blockID);
		world.setBlock(i + 13, j + 7, k + 6, Block.cloth.blockID);
		world.setBlock(i + 13, j + 7, k + 7, Block.cloth.blockID);
		world.setBlock(i + 13, j + 7, k + 8, Block.cloth.blockID);
		world.setBlock(i + 13, j + 7, k + 10, Block.planks.blockID);
		world.setBlock(i + 13, j + 8, k + 1, Block.planks.blockID);
		world.setBlock(i + 13, j + 8, k + 2, Block.planks.blockID);
		world.setBlock(i + 13, j + 8, k + 3, Block.planks.blockID);
		world.setBlock(i + 13, j + 8, k + 4, Block.planks.blockID);
		world.setBlock(i + 13, j + 8, k + 5, Block.planks.blockID);
		world.setBlock(i + 13, j + 8, k + 6, Block.planks.blockID);
		world.setBlock(i + 13, j + 8, k + 7, Block.planks.blockID);
		world.setBlock(i + 13, j + 8, k + 8, Block.planks.blockID);
		world.setBlock(i + 13, j + 8, k + 9, Block.planks.blockID);
		world.setBlock(i + 13, j + 8, k + 10, Block.planks.blockID);
		world.setBlock(i + 13, j + 9, k + 1, Block.fence.blockID);
		world.setBlockAndMetadata(i + 13, j + 9, k + 2, Block.stairCompactPlanks.blockID, 1);
		world.setBlockAndMetadata(i + 13, j + 9, k + 3, Block.stairCompactPlanks.blockID, 1);
		world.setBlockAndMetadata(i + 13, j + 9, k + 8, Block.stairCompactPlanks.blockID, 1);
		world.setBlockAndMetadata(i + 13, j + 9, k + 9, Block.stairCompactPlanks.blockID, 1);
		world.setBlock(i + 13, j + 9, k + 10, Block.fence.blockID);
		world.setBlock(i + 14, j + 0, k + 4, Block.planks.blockID);
		world.setBlock(i + 14, j + 0, k + 5, Block.planks.blockID);
		world.setBlock(i + 14, j + 0, k + 6, Block.planks.blockID);
		world.setBlock(i + 14, j + 0, k + 7, Block.planks.blockID);
		world.setBlock(i + 14, j + 1, k + 3, Block.planks.blockID);
		world.setBlock(i + 14, j + 1, k + 8, Block.planks.blockID);
		world.setBlock(i + 14, j + 2, k + 2, Block.planks.blockID);
		world.setBlock(i + 14, j + 2, k + 3, Block.planks.blockID);
		world.setBlock(i + 14, j + 2, k + 4, Block.planks.blockID);
		world.setBlock(i + 14, j + 2, k + 5, Block.planks.blockID);
		world.setBlock(i + 14, j + 2, k + 6, Block.planks.blockID);
		world.setBlock(i + 14, j + 2, k + 7, Block.planks.blockID);
		world.setBlock(i + 14, j + 2, k + 8, Block.planks.blockID);
		world.setBlock(i + 14, j + 2, k + 9, Block.planks.blockID);
		world.setBlock(i + 14, j + 3, k + 1, Block.planks.blockID);
		world.setBlockAndMetadata(i + 14, j + 3, k + 2, Block.bed.blockID, 8);
		world.setBlock(i + 14, j + 3, k + 3, Block.bed.blockID);
		world.setBlock(i + 14, j + 3, k + 6, Block.planks.blockID);
		world.setBlock(i + 14, j + 3, k + 10, Block.planks.blockID);
		world.setBlock(i + 14, j + 4, k + 1, Block.planks.blockID);
		world.setBlock(i + 14, j + 4, k + 6, Block.planks.blockID);
		world.setBlock(i + 14, j + 4, k + 10, Block.planks.blockID);
		world.setBlock(i + 14, j + 5, k + 1, Block.planks.blockID);
		world.setBlock(i + 14, j + 5, k + 2, Block.planks.blockID);
		world.setBlock(i + 14, j + 5, k + 3, Block.planks.blockID);
		world.setBlock(i + 14, j + 5, k + 4, Block.planks.blockID);
		world.setBlock(i + 14, j + 5, k + 5, Block.planks.blockID);
		world.setBlock(i + 14, j + 5, k + 6, Block.planks.blockID);
		world.setBlock(i + 14, j + 5, k + 7, Block.planks.blockID);
		world.setBlock(i + 14, j + 5, k + 8, Block.planks.blockID);
		world.setBlock(i + 14, j + 5, k + 9, Block.planks.blockID);
		world.setBlock(i + 14, j + 5, k + 10, Block.planks.blockID);
		world.setBlock(i + 14, j + 6, k + 3, Block.cloth.blockID);
		world.setBlock(i + 14, j + 6, k + 4, Block.cloth.blockID);
		world.setBlock(i + 14, j + 6, k + 5, Block.cloth.blockID);
		world.setBlock(i + 14, j + 6, k + 6, Block.cloth.blockID);
		world.setBlock(i + 14, j + 6, k + 7, Block.cloth.blockID);
		world.setBlock(i + 14, j + 6, k + 8, Block.cloth.blockID);
		world.setBlock(i + 14, j + 7, k + 3, Block.cloth.blockID);
		world.setBlock(i + 14, j + 7, k + 4, Block.cloth.blockID);
		world.setBlock(i + 14, j + 7, k + 5, Block.cloth.blockID);
		world.setBlock(i + 14, j + 7, k + 6, Block.cloth.blockID);
		world.setBlock(i + 14, j + 7, k + 7, Block.cloth.blockID);
		world.setBlock(i + 14, j + 7, k + 8, Block.cloth.blockID);
		world.setBlock(i + 14, j + 8, k + 1, Block.planks.blockID);
		world.setBlock(i + 14, j + 8, k + 2, Block.planks.blockID);
		world.setBlock(i + 14, j + 8, k + 3, Block.planks.blockID);
		world.setBlock(i + 14, j + 8, k + 4, Block.planks.blockID);
		world.setBlock(i + 14, j + 8, k + 5, Block.planks.blockID);
		world.setBlock(i + 14, j + 8, k + 6, Block.planks.blockID);
		world.setBlock(i + 14, j + 8, k + 7, Block.planks.blockID);
		world.setBlock(i + 14, j + 8, k + 8, Block.planks.blockID);
		world.setBlock(i + 14, j + 8, k + 9, Block.planks.blockID);
		world.setBlock(i + 14, j + 8, k + 10, Block.planks.blockID);
		world.setBlock(i + 14, j + 9, k + 1, Block.fence.blockID);
		world.setBlock(i + 14, j + 9, k + 10, Block.fence.blockID);
		world.setBlock(i + 15, j + 0, k + 4, Block.planks.blockID);
		world.setBlock(i + 15, j + 0, k + 5, Block.planks.blockID);
		world.setBlock(i + 15, j + 0, k + 6, Block.planks.blockID);
		world.setBlock(i + 15, j + 0, k + 7, Block.planks.blockID);
		world.setBlock(i + 15, j + 1, k + 3, Block.planks.blockID);
		world.setBlock(i + 15, j + 1, k + 8, Block.planks.blockID);
		world.setBlock(i + 15, j + 2, k + 2, Block.planks.blockID);
		world.setBlock(i + 15, j + 2, k + 3, Block.planks.blockID);
		world.setBlock(i + 15, j + 2, k + 4, Block.planks.blockID);
		world.setBlock(i + 15, j + 2, k + 5, Block.planks.blockID);
		world.setBlock(i + 15, j + 2, k + 6, Block.planks.blockID);
		world.setBlock(i + 15, j + 2, k + 7, Block.planks.blockID);
		world.setBlock(i + 15, j + 2, k + 8, Block.planks.blockID);
		world.setBlock(i + 15, j + 2, k + 9, Block.planks.blockID);
		world.setBlock(i + 15, j + 3, k + 1, Block.planks.blockID);
		world.setBlock(i + 15, j + 3, k + 2, Block.planks.blockID);
		world.setBlock(i + 15, j + 3, k + 3, Block.planks.blockID);
		world.setBlock(i + 15, j + 3, k + 4, Block.planks.blockID);
		world.setBlock(i + 15, j + 3, k + 5, Block.planks.blockID);
		world.setBlock(i + 15, j + 3, k + 6, Block.planks.blockID);
		world.setBlock(i + 15, j + 3, k + 10, Block.planks.blockID);
		world.setBlock(i + 15, j + 4, k + 1, Block.planks.blockID);
		world.setBlock(i + 15, j + 4, k + 2, Block.planks.blockID);
		world.setBlock(i + 15, j + 4, k + 3, Block.planks.blockID);
		world.setBlock(i + 15, j + 4, k + 4, Block.planks.blockID);
		world.setBlock(i + 15, j + 4, k + 5, Block.planks.blockID);
		world.setBlock(i + 15, j + 4, k + 6, Block.planks.blockID);
		world.setBlock(i + 15, j + 4, k + 10, Block.planks.blockID);
		world.setBlock(i + 15, j + 5, k + 1, Block.planks.blockID);
		world.setBlock(i + 15, j + 5, k + 2, Block.planks.blockID);
		world.setBlock(i + 15, j + 5, k + 3, Block.planks.blockID);
		world.setBlock(i + 15, j + 5, k + 4, Block.planks.blockID);
		world.setBlock(i + 15, j + 5, k + 5, Block.planks.blockID);
		world.setBlock(i + 15, j + 5, k + 6, Block.planks.blockID);
		world.setBlock(i + 15, j + 5, k + 7, Block.planks.blockID);
		world.setBlock(i + 15, j + 5, k + 8, Block.planks.blockID);
		world.setBlock(i + 15, j + 5, k + 9, Block.planks.blockID);
		world.setBlock(i + 15, j + 5, k + 10, Block.planks.blockID);
		world.setBlock(i + 15, j + 6, k + 1, Block.planks.blockID);
		world.setBlock(i + 15, j + 6, k + 3, Block.cloth.blockID);
		world.setBlock(i + 15, j + 6, k + 4, Block.cloth.blockID);
		world.setBlock(i + 15, j + 6, k + 5, Block.cloth.blockID);
		world.setBlock(i + 15, j + 6, k + 6, Block.cloth.blockID);
		world.setBlock(i + 15, j + 6, k + 7, Block.cloth.blockID);
		world.setBlock(i + 15, j + 6, k + 8, Block.cloth.blockID);
		world.setBlock(i + 15, j + 6, k + 10, Block.planks.blockID);
		world.setBlock(i + 15, j + 7, k + 1, Block.planks.blockID);
		world.setBlock(i + 15, j + 7, k + 3, Block.cloth.blockID);
		world.setBlock(i + 15, j + 7, k + 4, Block.cloth.blockID);
		world.setBlock(i + 15, j + 7, k + 5, Block.cloth.blockID);
		world.setBlock(i + 15, j + 7, k + 6, Block.cloth.blockID);
		world.setBlock(i + 15, j + 7, k + 7, Block.cloth.blockID);
		world.setBlock(i + 15, j + 7, k + 8, Block.cloth.blockID);
		world.setBlock(i + 15, j + 7, k + 10, Block.planks.blockID);
		world.setBlock(i + 15, j + 8, k + 1, Block.planks.blockID);
		world.setBlock(i + 15, j + 8, k + 2, Block.planks.blockID);
		world.setBlock(i + 15, j + 8, k + 3, Block.planks.blockID);
		world.setBlock(i + 15, j + 8, k + 4, Block.planks.blockID);
		world.setBlock(i + 15, j + 8, k + 5, Block.planks.blockID);
		world.setBlock(i + 15, j + 8, k + 6, Block.planks.blockID);
		world.setBlock(i + 15, j + 8, k + 7, Block.planks.blockID);
		world.setBlock(i + 15, j + 8, k + 8, Block.planks.blockID);
		world.setBlock(i + 15, j + 8, k + 9, Block.planks.blockID);
		world.setBlock(i + 15, j + 8, k + 10, Block.planks.blockID);
		world.setBlock(i + 15, j + 9, k + 1, Block.fence.blockID);
		world.setBlock(i + 15, j + 9, k + 10, Block.fence.blockID);
		world.setBlock(i + 16, j + 0, k + 4, Block.planks.blockID);
		world.setBlock(i + 16, j + 0, k + 5, Block.planks.blockID);
		world.setBlock(i + 16, j + 0, k + 6, Block.planks.blockID);
		world.setBlock(i + 16, j + 0, k + 7, Block.planks.blockID);
		world.setBlock(i + 16, j + 1, k + 3, Block.planks.blockID);
		world.setBlock(i + 16, j + 1, k + 8, Block.planks.blockID);
		world.setBlock(i + 16, j + 2, k + 2, Block.planks.blockID);
		world.setBlock(i + 16, j + 2, k + 3, Block.planks.blockID);
		world.setBlock(i + 16, j + 2, k + 4, Block.planks.blockID);
		world.setBlock(i + 16, j + 2, k + 5, Block.planks.blockID);
		world.setBlock(i + 16, j + 2, k + 6, Block.planks.blockID);
		world.setBlock(i + 16, j + 2, k + 7, Block.planks.blockID);
		world.setBlock(i + 16, j + 2, k + 8, Block.planks.blockID);
		world.setBlock(i + 16, j + 2, k + 9, Block.planks.blockID);
		world.setBlock(i + 16, j + 3, k + 1, Block.planks.blockID);
		world.setBlock(i + 16, j + 3, k + 6, Block.planks.blockID);
		world.setBlock(i + 16, j + 3, k + 10, Block.planks.blockID);
		world.setBlock(i + 16, j + 4, k + 1, Block.planks.blockID);
		world.setBlock(i + 16, j + 4, k + 6, Block.planks.blockID);
		world.setBlock(i + 16, j + 4, k + 10, Block.glass.blockID);
		world.setBlock(i + 16, j + 5, k + 1, Block.planks.blockID);
		world.setBlock(i + 16, j + 5, k + 2, Block.planks.blockID);
		world.setBlock(i + 16, j + 5, k + 3, Block.planks.blockID);
		world.setBlock(i + 16, j + 5, k + 4, Block.planks.blockID);
		world.setBlock(i + 16, j + 5, k + 5, Block.planks.blockID);
		world.setBlock(i + 16, j + 5, k + 6, Block.planks.blockID);
		world.setBlock(i + 16, j + 5, k + 7, Block.planks.blockID);
		world.setBlock(i + 16, j + 5, k + 8, Block.planks.blockID);
		world.setBlock(i + 16, j + 5, k + 9, Block.planks.blockID);
		world.setBlock(i + 16, j + 5, k + 10, Block.planks.blockID);
		world.setBlock(i + 16, j + 6, k + 1, Block.planks.blockID);
		world.setBlock(i + 16, j + 6, k + 3, Block.cloth.blockID);
		world.setBlock(i + 16, j + 6, k + 4, Block.cloth.blockID);
		world.setBlock(i + 16, j + 6, k + 5, Block.cloth.blockID);
		world.setBlock(i + 16, j + 6, k + 6, Block.cloth.blockID);
		world.setBlock(i + 16, j + 6, k + 7, Block.cloth.blockID);
		world.setBlock(i + 16, j + 6, k + 8, Block.cloth.blockID);
		world.setBlock(i + 16, j + 6, k + 10, Block.planks.blockID);
		world.setBlock(i + 16, j + 7, k + 1, Block.planks.blockID);
		world.setBlock(i + 16, j + 7, k + 3, Block.cloth.blockID);
		world.setBlock(i + 16, j + 7, k + 4, Block.cloth.blockID);
		world.setBlock(i + 16, j + 7, k + 5, Block.cloth.blockID);
		world.setBlock(i + 16, j + 7, k + 6, Block.cloth.blockID);
		world.setBlock(i + 16, j + 7, k + 7, Block.cloth.blockID);
		world.setBlock(i + 16, j + 7, k + 8, Block.cloth.blockID);
		world.setBlock(i + 16, j + 7, k + 10, Block.planks.blockID);
		world.setBlock(i + 16, j + 8, k + 1, Block.planks.blockID);
		world.setBlock(i + 16, j + 8, k + 2, Block.planks.blockID);
		world.setBlock(i + 16, j + 8, k + 3, Block.planks.blockID);
		world.setBlock(i + 16, j + 8, k + 4, Block.planks.blockID);
		world.setBlock(i + 16, j + 8, k + 5, Block.planks.blockID);
		world.setBlock(i + 16, j + 8, k + 6, Block.planks.blockID);
		world.setBlock(i + 16, j + 8, k + 7, Block.planks.blockID);
		world.setBlock(i + 16, j + 8, k + 8, Block.planks.blockID);
		world.setBlock(i + 16, j + 8, k + 9, Block.planks.blockID);
		world.setBlock(i + 16, j + 8, k + 10, Block.planks.blockID);
		world.setBlock(i + 16, j + 9, k + 1, Block.fence.blockID);
		world.setBlock(i + 16, j + 9, k + 10, Block.fence.blockID);
		world.setBlock(i + 17, j + 0, k + 4, Block.planks.blockID);
		world.setBlock(i + 17, j + 0, k + 5, Block.planks.blockID);
		world.setBlock(i + 17, j + 0, k + 6, Block.planks.blockID);
		world.setBlock(i + 17, j + 0, k + 7, Block.planks.blockID);
		world.setBlock(i + 17, j + 1, k + 3, Block.planks.blockID);
		world.setBlock(i + 17, j + 1, k + 8, Block.planks.blockID);
		world.setBlock(i + 17, j + 2, k + 2, Block.planks.blockID);
		world.setBlock(i + 17, j + 2, k + 3, Block.planks.blockID);
		world.setBlock(i + 17, j + 2, k + 4, Block.planks.blockID);
		world.setBlock(i + 17, j + 2, k + 5, Block.planks.blockID);
		world.setBlock(i + 17, j + 2, k + 6, Block.planks.blockID);
		world.setBlock(i + 17, j + 2, k + 7, Block.planks.blockID);
		world.setBlock(i + 17, j + 2, k + 8, Block.planks.blockID);
		world.setBlock(i + 17, j + 2, k + 9, Block.planks.blockID);
		world.setBlock(i + 17, j + 3, k + 1, Block.planks.blockID);
		world.setBlock(i + 17, j + 3, k + 10, Block.planks.blockID);
		world.setBlock(i + 17, j + 4, k + 1, Block.glass.blockID);
		world.setBlock(i + 17, j + 4, k + 10, Block.planks.blockID);
		world.setBlock(i + 17, j + 5, k + 1, Block.planks.blockID);
		world.setBlock(i + 17, j + 5, k + 2, Block.planks.blockID);
		world.setBlock(i + 17, j + 5, k + 3, Block.planks.blockID);
		world.setBlock(i + 17, j + 5, k + 4, Block.planks.blockID);
		world.setBlock(i + 17, j + 5, k + 5, Block.planks.blockID);
		world.setBlock(i + 17, j + 5, k + 6, Block.planks.blockID);
		world.setBlock(i + 17, j + 5, k + 7, Block.planks.blockID);
		world.setBlock(i + 17, j + 5, k + 8, Block.planks.blockID);
		world.setBlock(i + 17, j + 5, k + 9, Block.planks.blockID);
		world.setBlock(i + 17, j + 5, k + 10, Block.planks.blockID);
		world.setBlock(i + 17, j + 6, k + 3, Block.cloth.blockID);
		world.setBlock(i + 17, j + 6, k + 4, Block.cloth.blockID);
		world.setBlock(i + 17, j + 6, k + 5, Block.cloth.blockID);
		world.setBlock(i + 17, j + 6, k + 6, Block.cloth.blockID);
		world.setBlock(i + 17, j + 6, k + 7, Block.cloth.blockID);
		world.setBlock(i + 17, j + 6, k + 8, Block.cloth.blockID);
		world.setBlock(i + 17, j + 7, k + 3, Block.cloth.blockID);
		world.setBlock(i + 17, j + 7, k + 4, Block.cloth.blockID);
		world.setBlock(i + 17, j + 7, k + 5, Block.cloth.blockID);
		world.setBlock(i + 17, j + 7, k + 6, Block.cloth.blockID);
		world.setBlock(i + 17, j + 7, k + 7, Block.cloth.blockID);
		world.setBlock(i + 17, j + 7, k + 8, Block.cloth.blockID);
		world.setBlock(i + 17, j + 8, k + 1, Block.planks.blockID);
		world.setBlock(i + 17, j + 8, k + 2, Block.planks.blockID);
		world.setBlock(i + 17, j + 8, k + 3, Block.planks.blockID);
		world.setBlock(i + 17, j + 8, k + 4, Block.planks.blockID);
		world.setBlock(i + 17, j + 8, k + 5, Block.planks.blockID);
		world.setBlock(i + 17, j + 8, k + 6, Block.planks.blockID);
		world.setBlock(i + 17, j + 8, k + 7, Block.planks.blockID);
		world.setBlock(i + 17, j + 8, k + 8, Block.planks.blockID);
		world.setBlock(i + 17, j + 8, k + 9, Block.planks.blockID);
		world.setBlock(i + 17, j + 8, k + 10, Block.planks.blockID);
		world.setBlock(i + 17, j + 9, k + 1, Block.fence.blockID);
		world.setBlock(i + 17, j + 9, k + 5, Block.wood.blockID);
		world.setBlock(i + 17, j + 9, k + 6, Block.wood.blockID);
		world.setBlock(i + 17, j + 9, k + 10, Block.fence.blockID);
		world.setBlock(i + 17, j + 10, k + 5, Block.wood.blockID);
		world.setBlock(i + 17, j + 10, k + 6, Block.wood.blockID);
		world.setBlock(i + 17, j + 11, k + 5, Block.wood.blockID);
		world.setBlock(i + 17, j + 11, k + 6, Block.wood.blockID);
		world.setBlock(i + 17, j + 12, k + 5, Block.wood.blockID);
		world.setBlock(i + 17, j + 12, k + 6, Block.wood.blockID);
		world.setBlock(i + 17, j + 13, k + 5, Block.wood.blockID);
		world.setBlock(i + 17, j + 13, k + 6, Block.wood.blockID);
		world.setBlock(i + 18, j + 0, k + 4, Block.planks.blockID);
		world.setBlock(i + 18, j + 0, k + 5, Block.planks.blockID);
		world.setBlock(i + 18, j + 0, k + 6, Block.planks.blockID);
		world.setBlock(i + 18, j + 0, k + 7, Block.planks.blockID);
		world.setBlock(i + 18, j + 1, k + 3, Block.planks.blockID);
		world.setBlock(i + 18, j + 1, k + 8, Block.planks.blockID);
		world.setBlock(i + 18, j + 2, k + 2, Block.planks.blockID);
		world.setBlock(i + 18, j + 2, k + 3, Block.planks.blockID);
		world.setBlock(i + 18, j + 2, k + 4, Block.planks.blockID);
		world.setBlock(i + 18, j + 2, k + 5, Block.planks.blockID);
		world.setBlock(i + 18, j + 2, k + 6, Block.planks.blockID);
		world.setBlock(i + 18, j + 2, k + 7, Block.planks.blockID);
		world.setBlock(i + 18, j + 2, k + 8, Block.planks.blockID);
		world.setBlock(i + 18, j + 2, k + 9, Block.planks.blockID);
		world.setBlock(i + 18, j + 3, k + 1, Block.planks.blockID);
		world.setBlock(i + 18, j + 3, k + 6, Block.planks.blockID);
		world.setBlock(i + 18, j + 3, k + 10, Block.planks.blockID);
		world.setBlock(i + 18, j + 4, k + 1, Block.planks.blockID);
		world.setBlock(i + 18, j + 4, k + 6, Block.planks.blockID);
		world.setBlock(i + 18, j + 4, k + 10, Block.planks.blockID);
		world.setBlock(i + 18, j + 5, k + 1, Block.planks.blockID);
		world.setBlock(i + 18, j + 5, k + 2, Block.planks.blockID);
		world.setBlock(i + 18, j + 5, k + 3, Block.planks.blockID);
		world.setBlock(i + 18, j + 5, k + 4, Block.planks.blockID);
		world.setBlock(i + 18, j + 5, k + 5, Block.planks.blockID);
		world.setBlock(i + 18, j + 5, k + 6, Block.planks.blockID);
		world.setBlock(i + 18, j + 5, k + 7, Block.planks.blockID);
		world.setBlock(i + 18, j + 5, k + 8, Block.planks.blockID);
		world.setBlock(i + 18, j + 5, k + 9, Block.planks.blockID);
		world.setBlock(i + 18, j + 5, k + 10, Block.planks.blockID);
		world.setBlock(i + 18, j + 6, k + 1, Block.planks.blockID);
		world.setBlock(i + 18, j + 6, k + 3, Block.cloth.blockID);
		world.setBlock(i + 18, j + 6, k + 4, Block.cloth.blockID);
		world.setBlock(i + 18, j + 6, k + 5, Block.cloth.blockID);
		world.setBlock(i + 18, j + 6, k + 6, Block.cloth.blockID);
		world.setBlock(i + 18, j + 6, k + 7, Block.cloth.blockID);
		world.setBlock(i + 18, j + 6, k + 8, Block.cloth.blockID);
		world.setBlock(i + 18, j + 6, k + 10, Block.planks.blockID);
		world.setBlock(i + 18, j + 7, k + 1, Block.planks.blockID);
		world.setBlock(i + 18, j + 7, k + 3, Block.cloth.blockID);
		world.setBlock(i + 18, j + 7, k + 4, Block.cloth.blockID);
		world.setBlock(i + 18, j + 7, k + 5, Block.cloth.blockID);
		world.setBlock(i + 18, j + 7, k + 6, Block.cloth.blockID);
		world.setBlock(i + 18, j + 7, k + 7, Block.cloth.blockID);
		world.setBlock(i + 18, j + 7, k + 8, Block.cloth.blockID);
		world.setBlock(i + 18, j + 7, k + 10, Block.planks.blockID);
		world.setBlock(i + 18, j + 8, k + 1, Block.planks.blockID);
		world.setBlock(i + 18, j + 8, k + 2, Block.planks.blockID);
		world.setBlock(i + 18, j + 8, k + 3, Block.planks.blockID);
		world.setBlock(i + 18, j + 8, k + 4, Block.planks.blockID);
		world.setBlock(i + 18, j + 8, k + 5, Block.planks.blockID);
		world.setBlock(i + 18, j + 8, k + 6, Block.planks.blockID);
		world.setBlock(i + 18, j + 8, k + 7, Block.planks.blockID);
		world.setBlock(i + 18, j + 8, k + 8, Block.planks.blockID);
		world.setBlock(i + 18, j + 8, k + 9, Block.planks.blockID);
		world.setBlock(i + 18, j + 8, k + 10, Block.planks.blockID);
		world.setBlock(i + 18, j + 9, k + 1, Block.fence.blockID);
		world.setBlock(i + 18, j + 9, k + 5, Block.wood.blockID);
		world.setBlock(i + 18, j + 9, k + 6, Block.wood.blockID);
		world.setBlock(i + 18, j + 9, k + 10, Block.fence.blockID);
		world.setBlock(i + 18, j + 10, k + 5, Block.wood.blockID);
		world.setBlock(i + 18, j + 10, k + 6, Block.wood.blockID);
		world.setBlock(i + 18, j + 11, k + 5, Block.wood.blockID);
		world.setBlock(i + 18, j + 11, k + 6, Block.wood.blockID);
		world.setBlock(i + 18, j + 12, k + 5, Block.wood.blockID);
		world.setBlock(i + 18, j + 12, k + 6, Block.wood.blockID);
		world.setBlock(i + 18, j + 13, k + 5, Block.wood.blockID);
		world.setBlock(i + 18, j + 13, k + 6, Block.wood.blockID);
		world.setBlock(i + 19, j + 0, k + 4, Block.planks.blockID);
		world.setBlock(i + 19, j + 0, k + 5, Block.planks.blockID);
		world.setBlock(i + 19, j + 0, k + 6, Block.planks.blockID);
		world.setBlock(i + 19, j + 0, k + 7, Block.planks.blockID);
		world.setBlock(i + 19, j + 1, k + 3, Block.planks.blockID);
		world.setBlock(i + 19, j + 1, k + 8, Block.planks.blockID);
		world.setBlock(i + 19, j + 2, k + 2, Block.planks.blockID);
		world.setBlock(i + 19, j + 2, k + 3, Block.planks.blockID);
		world.setBlock(i + 19, j + 2, k + 4, Block.planks.blockID);
		world.setBlock(i + 19, j + 2, k + 5, Block.planks.blockID);
		world.setBlock(i + 19, j + 2, k + 6, Block.planks.blockID);
		world.setBlock(i + 19, j + 2, k + 7, Block.planks.blockID);
		world.setBlock(i + 19, j + 2, k + 8, Block.planks.blockID);
		world.setBlock(i + 19, j + 2, k + 9, Block.planks.blockID);
		world.setBlock(i + 19, j + 3, k + 1, Block.planks.blockID);
		world.setBlock(i + 19, j + 3, k + 6, Block.planks.blockID);
		world.setBlock(i + 19, j + 3, k + 10, Block.planks.blockID);
		world.setBlock(i + 19, j + 4, k + 1, Block.planks.blockID);
		world.setBlock(i + 19, j + 4, k + 6, Block.planks.blockID);
		world.setBlock(i + 19, j + 4, k + 10, Block.planks.blockID);
		world.setBlock(i + 19, j + 5, k + 1, Block.planks.blockID);
		world.setBlock(i + 19, j + 5, k + 2, Block.planks.blockID);
		world.setBlock(i + 19, j + 5, k + 3, Block.planks.blockID);
		world.setBlock(i + 19, j + 5, k + 4, Block.planks.blockID);
		world.setBlock(i + 19, j + 5, k + 5, Block.planks.blockID);
		world.setBlock(i + 19, j + 5, k + 6, Block.planks.blockID);
		world.setBlock(i + 19, j + 5, k + 7, Block.planks.blockID);
		world.setBlock(i + 19, j + 5, k + 8, Block.planks.blockID);
		world.setBlock(i + 19, j + 5, k + 9, Block.planks.blockID);
		world.setBlock(i + 19, j + 5, k + 10, Block.planks.blockID);
		world.setBlock(i + 19, j + 6, k + 1, Block.planks.blockID);
		world.setBlock(i + 19, j + 6, k + 3, Block.cloth.blockID);
		world.setBlock(i + 19, j + 6, k + 4, Block.cloth.blockID);
		world.setBlock(i + 19, j + 6, k + 5, Block.cloth.blockID);
		world.setBlock(i + 19, j + 6, k + 6, Block.cloth.blockID);
		world.setBlock(i + 19, j + 6, k + 7, Block.cloth.blockID);
		world.setBlock(i + 19, j + 6, k + 8, Block.cloth.blockID);
		world.setBlock(i + 19, j + 6, k + 10, Block.planks.blockID);
		world.setBlock(i + 19, j + 7, k + 1, Block.planks.blockID);
		world.setBlock(i + 19, j + 7, k + 10, Block.planks.blockID);
		world.setBlock(i + 19, j + 8, k + 1, Block.planks.blockID);
		world.setBlock(i + 19, j + 8, k + 2, Block.planks.blockID);
		world.setBlock(i + 19, j + 8, k + 3, Block.planks.blockID);
		world.setBlock(i + 19, j + 8, k + 4, Block.planks.blockID);
		world.setBlock(i + 19, j + 8, k + 5, Block.planks.blockID);
		world.setBlock(i + 19, j + 8, k + 6, Block.planks.blockID);
		world.setBlock(i + 19, j + 8, k + 7, Block.planks.blockID);
		world.setBlock(i + 19, j + 8, k + 8, Block.planks.blockID);
		world.setBlock(i + 19, j + 8, k + 9, Block.planks.blockID);
		world.setBlock(i + 19, j + 8, k + 10, Block.planks.blockID);
		world.setBlock(i + 19, j + 9, k + 1, Block.fence.blockID);
		world.setBlock(i + 19, j + 9, k + 10, Block.fence.blockID);
		world.setBlock(i + 20, j + 0, k + 4, Block.planks.blockID);
		world.setBlock(i + 20, j + 0, k + 5, Block.planks.blockID);
		world.setBlock(i + 20, j + 0, k + 6, Block.planks.blockID);
		world.setBlock(i + 20, j + 0, k + 7, Block.planks.blockID);
		world.setBlock(i + 20, j + 1, k + 3, Block.planks.blockID);
		world.setBlock(i + 20, j + 1, k + 8, Block.planks.blockID);
		world.setBlock(i + 20, j + 2, k + 2, Block.planks.blockID);
		world.setBlock(i + 20, j + 2, k + 3, Block.planks.blockID);
		world.setBlock(i + 20, j + 2, k + 4, Block.planks.blockID);
		world.setBlock(i + 20, j + 2, k + 5, Block.planks.blockID);
		world.setBlock(i + 20, j + 2, k + 6, Block.planks.blockID);
		world.setBlock(i + 20, j + 2, k + 7, Block.planks.blockID);
		world.setBlock(i + 20, j + 2, k + 8, Block.planks.blockID);
		world.setBlock(i + 20, j + 2, k + 9, Block.planks.blockID);
		world.setBlock(i + 20, j + 3, k + 1, Block.planks.blockID);
		world.setBlockAndMetadata(i + 20, j + 3, k + 2, Block.bed.blockID, 8);
		world.setBlock(i + 20, j + 3, k + 3, Block.bed.blockID);
		world.setBlock(i + 20, j + 3, k + 6, Block.planks.blockID);
		world.setBlock(i + 20, j + 3, k + 10, Block.planks.blockID);
		world.setBlock(i + 20, j + 4, k + 1, Block.planks.blockID);
		world.setBlock(i + 20, j + 4, k + 6, Block.planks.blockID);
		world.setBlock(i + 20, j + 4, k + 10, Block.glass.blockID);
		world.setBlock(i + 20, j + 5, k + 1, Block.planks.blockID);
		world.setBlock(i + 20, j + 5, k + 2, Block.planks.blockID);
		world.setBlock(i + 20, j + 5, k + 3, Block.planks.blockID);
		world.setBlock(i + 20, j + 5, k + 4, Block.planks.blockID);
		world.setBlock(i + 20, j + 5, k + 5, Block.planks.blockID);
		world.setBlock(i + 20, j + 5, k + 6, Block.planks.blockID);
		world.setBlock(i + 20, j + 5, k + 7, Block.planks.blockID);
		world.setBlock(i + 20, j + 5, k + 8, Block.planks.blockID);
		world.setBlock(i + 20, j + 5, k + 9, Block.planks.blockID);
		world.setBlock(i + 20, j + 5, k + 10, Block.planks.blockID);
		world.setBlock(i + 20, j + 6, k + 1, Block.planks.blockID);
		world.setBlock(i + 20, j + 6, k + 10, Block.planks.blockID);
		world.setBlock(i + 20, j + 7, k + 1, Block.planks.blockID);
		world.setBlock(i + 20, j + 7, k + 10, Block.planks.blockID);
		world.setBlock(i + 20, j + 8, k + 1, Block.planks.blockID);
		world.setBlock(i + 20, j + 8, k + 2, Block.planks.blockID);
		world.setBlock(i + 20, j + 8, k + 3, Block.planks.blockID);
		world.setBlock(i + 20, j + 8, k + 4, Block.planks.blockID);
		world.setBlock(i + 20, j + 8, k + 5, Block.planks.blockID);
		world.setBlock(i + 20, j + 8, k + 6, Block.planks.blockID);
		world.setBlock(i + 20, j + 8, k + 7, Block.planks.blockID);
		world.setBlock(i + 20, j + 8, k + 8, Block.planks.blockID);
		world.setBlock(i + 20, j + 8, k + 9, Block.planks.blockID);
		world.setBlock(i + 20, j + 8, k + 10, Block.planks.blockID);
		world.setBlock(i + 20, j + 9, k + 1, Block.fence.blockID);
		world.setBlock(i + 20, j + 9, k + 10, Block.fence.blockID);
		world.setBlock(i + 21, j + 0, k + 4, Block.planks.blockID);
		world.setBlock(i + 21, j + 0, k + 5, Block.planks.blockID);
		world.setBlock(i + 21, j + 0, k + 6, Block.planks.blockID);
		world.setBlock(i + 21, j + 0, k + 7, Block.planks.blockID);
		world.setBlock(i + 21, j + 1, k + 3, Block.planks.blockID);
		world.setBlock(i + 21, j + 1, k + 8, Block.planks.blockID);
		world.setBlock(i + 21, j + 2, k + 2, Block.planks.blockID);
		world.setBlock(i + 21, j + 2, k + 3, Block.planks.blockID);
		world.setBlock(i + 21, j + 2, k + 4, Block.planks.blockID);
		world.setBlock(i + 21, j + 2, k + 5, Block.planks.blockID);
		world.setBlock(i + 21, j + 2, k + 6, Block.planks.blockID);
		world.setBlock(i + 21, j + 2, k + 7, Block.planks.blockID);
		world.setBlock(i + 21, j + 2, k + 8, Block.planks.blockID);
		world.setBlock(i + 21, j + 2, k + 9, Block.planks.blockID);
		world.setBlock(i + 21, j + 3, k + 1, Block.planks.blockID);
		world.setBlock(i + 21, j + 3, k + 2, Block.planks.blockID);
		world.setBlock(i + 21, j + 3, k + 3, Block.planks.blockID);
		world.setBlock(i + 21, j + 3, k + 4, Block.planks.blockID);
		world.setBlock(i + 21, j + 3, k + 5, Block.planks.blockID);
		world.setBlock(i + 21, j + 3, k + 6, Block.planks.blockID);
		world.setBlock(i + 21, j + 3, k + 10, Block.planks.blockID);
		world.setBlock(i + 21, j + 4, k + 1, Block.planks.blockID);
		world.setBlock(i + 21, j + 4, k + 2, Block.planks.blockID);
		world.setBlock(i + 21, j + 4, k + 3, Block.planks.blockID);
		world.setBlock(i + 21, j + 4, k + 4, Block.planks.blockID);
		world.setBlock(i + 21, j + 4, k + 5, Block.planks.blockID);
		world.setBlock(i + 21, j + 4, k + 6, Block.planks.blockID);
		world.setBlock(i + 21, j + 4, k + 10, Block.planks.blockID);
		world.setBlock(i + 21, j + 5, k + 1, Block.planks.blockID);
		world.setBlock(i + 21, j + 5, k + 2, Block.planks.blockID);
		world.setBlock(i + 21, j + 5, k + 3, Block.planks.blockID);
		world.setBlock(i + 21, j + 5, k + 4, Block.planks.blockID);
		world.setBlock(i + 21, j + 5, k + 5, Block.planks.blockID);
		world.setBlock(i + 21, j + 5, k + 6, Block.planks.blockID);
		world.setBlock(i + 21, j + 5, k + 7, Block.planks.blockID);
		world.setBlock(i + 21, j + 5, k + 8, Block.planks.blockID);
		world.setBlock(i + 21, j + 5, k + 9, Block.planks.blockID);
		world.setBlock(i + 21, j + 5, k + 10, Block.planks.blockID);
		world.setBlock(i + 21, j + 6, k + 1, Block.planks.blockID);
		world.setBlock(i + 21, j + 6, k + 10, Block.planks.blockID);
		world.setBlock(i + 21, j + 7, k + 1, Block.planks.blockID);
		world.setBlock(i + 21, j + 7, k + 10, Block.planks.blockID);
		world.setBlockAndMetadata(i + 21, j + 8, k + 0, Block.stoneSingleSlab.blockID, 2);
		world.setBlock(i + 21, j + 8, k + 1, Block.planks.blockID);
		world.setBlock(i + 21, j + 8, k + 2, Block.planks.blockID);
		world.setBlock(i + 21, j + 8, k + 3, Block.planks.blockID);
		world.setBlock(i + 21, j + 8, k + 4, Block.planks.blockID);
		world.setBlock(i + 21, j + 8, k + 5, Block.planks.blockID);
		world.setBlock(i + 21, j + 8, k + 6, Block.planks.blockID);
		world.setBlock(i + 21, j + 8, k + 7, Block.planks.blockID);
		world.setBlock(i + 21, j + 8, k + 8, Block.planks.blockID);
		world.setBlock(i + 21, j + 8, k + 9, Block.planks.blockID);
		world.setBlock(i + 21, j + 8, k + 10, Block.planks.blockID);
		world.setBlockAndMetadata(i + 21, j + 8, k + 11, Block.stoneSingleSlab.blockID, 2);
		world.setBlock(i + 22, j + 0, k + 4, Block.planks.blockID);
		world.setBlock(i + 22, j + 0, k + 5, Block.planks.blockID);
		world.setBlock(i + 22, j + 0, k + 6, Block.planks.blockID);
		world.setBlock(i + 22, j + 0, k + 7, Block.planks.blockID);
		world.setBlock(i + 22, j + 1, k + 3, Block.planks.blockID);
		world.setBlock(i + 22, j + 1, k + 8, Block.planks.blockID);
		world.setBlock(i + 22, j + 2, k + 2, Block.planks.blockID);
		world.setBlock(i + 22, j + 2, k + 3, Block.planks.blockID);
		world.setBlock(i + 22, j + 2, k + 4, Block.planks.blockID);
		world.setBlock(i + 22, j + 2, k + 5, Block.planks.blockID);
		world.setBlock(i + 22, j + 2, k + 6, Block.planks.blockID);
		world.setBlock(i + 22, j + 2, k + 7, Block.planks.blockID);
		world.setBlock(i + 22, j + 2, k + 8, Block.planks.blockID);
		world.setBlock(i + 22, j + 2, k + 9, Block.planks.blockID);
		world.setBlock(i + 22, j + 3, k + 1, Block.planks.blockID);
		world.setBlock(i + 22, j + 3, k + 6, Block.planks.blockID);
		world.setBlock(i + 22, j + 3, k + 10, Block.planks.blockID);
		world.setBlock(i + 22, j + 4, k + 1, Block.planks.blockID);
		world.setBlock(i + 22, j + 4, k + 6, Block.planks.blockID);
		world.setBlock(i + 22, j + 4, k + 10, Block.planks.blockID);
		world.setBlock(i + 22, j + 5, k + 1, Block.planks.blockID);
		world.setBlock(i + 22, j + 5, k + 2, Block.planks.blockID);
		world.setBlock(i + 22, j + 5, k + 3, Block.planks.blockID);
		world.setBlock(i + 22, j + 5, k + 4, Block.planks.blockID);
		world.setBlock(i + 22, j + 5, k + 5, Block.planks.blockID);
		world.setBlock(i + 22, j + 5, k + 6, Block.planks.blockID);
		world.setBlock(i + 22, j + 5, k + 7, Block.planks.blockID);
		world.setBlock(i + 22, j + 5, k + 8, Block.planks.blockID);
		world.setBlock(i + 22, j + 5, k + 9, Block.planks.blockID);
		world.setBlock(i + 22, j + 5, k + 10, Block.planks.blockID);
		world.setBlock(i + 22, j + 6, k + 1, Block.planks.blockID);
		world.setBlockAndMetadata(i + 22, j + 6, k + 5, Block.chest.blockID, 5);
		world.setBlockAndMetadata(i + 22, j + 6, k + 6, Block.chest.blockID, 5);
		TileEntityChest var12 = (TileEntityChest)world.getBlockTileEntity(i + 22, j + 6, k + 6);
        int var13;

        if (var12 != null)
        {
            for (var13 = 0; var13 < 8; ++var13)
            {
                ItemStack var11 = this.pickCheckLootItem(rand);

                if (var11 != null)
                {
                    var12.setInventorySlotContents(rand.nextInt(var12.getSizeInventory()), var11);
                }
            }
        }
		world.setBlock(i + 22, j + 6, k + 10, Block.planks.blockID);
		world.setBlock(i + 22, j + 7, k + 1, Block.planks.blockID);
		world.setBlock(i + 22, j + 7, k + 10, Block.planks.blockID);
		world.setBlock(i + 22, j + 8, k + 1, Block.planks.blockID);
		world.setBlock(i + 22, j + 8, k + 2, Block.planks.blockID);
		world.setBlock(i + 22, j + 8, k + 3, Block.planks.blockID);
		world.setBlock(i + 22, j + 8, k + 4, Block.planks.blockID);
		world.setBlock(i + 22, j + 8, k + 5, Block.planks.blockID);
		world.setBlock(i + 22, j + 8, k + 6, Block.planks.blockID);
		world.setBlock(i + 22, j + 8, k + 7, Block.planks.blockID);
		world.setBlock(i + 22, j + 8, k + 8, Block.planks.blockID);
		world.setBlock(i + 22, j + 8, k + 9, Block.planks.blockID);
		world.setBlock(i + 22, j + 8, k + 10, Block.planks.blockID);
		world.setBlock(i + 22, j + 9, k + 1, Block.fence.blockID);
		world.setBlock(i + 22, j + 9, k + 10, Block.fence.blockID);
		world.setBlock(i + 23, j + 0, k + 4, Block.planks.blockID);
		world.setBlock(i + 23, j + 0, k + 5, Block.planks.blockID);
		world.setBlock(i + 23, j + 0, k + 6, Block.planks.blockID);
		world.setBlock(i + 23, j + 0, k + 7, Block.planks.blockID);
		world.setBlock(i + 23, j + 1, k + 3, Block.planks.blockID);
		world.setBlock(i + 23, j + 1, k + 8, Block.planks.blockID);
		world.setBlock(i + 23, j + 2, k + 2, Block.planks.blockID);
		world.setBlock(i + 23, j + 2, k + 3, Block.planks.blockID);
		world.setBlock(i + 23, j + 2, k + 4, Block.planks.blockID);
		world.setBlock(i + 23, j + 2, k + 5, Block.planks.blockID);
		world.setBlock(i + 23, j + 2, k + 6, Block.planks.blockID);
		world.setBlock(i + 23, j + 2, k + 7, Block.planks.blockID);
		world.setBlock(i + 23, j + 2, k + 8, Block.planks.blockID);
		world.setBlock(i + 23, j + 2, k + 9, Block.planks.blockID);
		world.setBlock(i + 23, j + 3, k + 1, Block.planks.blockID);
		world.setBlock(i + 23, j + 3, k + 10, Block.planks.blockID);
		world.setBlock(i + 23, j + 4, k + 1, Block.glass.blockID);
		world.setBlock(i + 23, j + 4, k + 10, Block.planks.blockID);
		world.setBlock(i + 23, j + 5, k + 1, Block.planks.blockID);
		world.setBlock(i + 23, j + 5, k + 2, Block.planks.blockID);
		world.setBlock(i + 23, j + 5, k + 3, Block.planks.blockID);
		world.setBlock(i + 23, j + 5, k + 4, Block.planks.blockID);
		world.setBlock(i + 23, j + 5, k + 5, Block.planks.blockID);
		world.setBlock(i + 23, j + 5, k + 6, Block.planks.blockID);
		world.setBlock(i + 23, j + 5, k + 7, Block.planks.blockID);
		world.setBlock(i + 23, j + 5, k + 8, Block.planks.blockID);
		world.setBlock(i + 23, j + 5, k + 9, Block.planks.blockID);
		world.setBlock(i + 23, j + 5, k + 10, Block.planks.blockID);
		world.setBlock(i + 23, j + 6, k + 1, Block.planks.blockID);
		world.setBlock(i + 23, j + 6, k + 10, Block.planks.blockID);
		world.setBlock(i + 23, j + 7, k + 1, Block.planks.blockID);
		world.setBlock(i + 23, j + 7, k + 10, Block.planks.blockID);
		world.setBlock(i + 23, j + 8, k + 1, Block.planks.blockID);
		world.setBlock(i + 23, j + 8, k + 2, Block.planks.blockID);
		world.setBlock(i + 23, j + 8, k + 3, Block.planks.blockID);
		world.setBlock(i + 23, j + 8, k + 4, Block.planks.blockID);
		world.setBlock(i + 23, j + 8, k + 5, Block.planks.blockID);
		world.setBlock(i + 23, j + 8, k + 6, Block.planks.blockID);
		world.setBlock(i + 23, j + 8, k + 7, Block.planks.blockID);
		world.setBlock(i + 23, j + 8, k + 8, Block.planks.blockID);
		world.setBlock(i + 23, j + 8, k + 9, Block.planks.blockID);
		world.setBlock(i + 23, j + 8, k + 10, Block.planks.blockID);
		world.setBlock(i + 23, j + 9, k + 1, Block.fence.blockID);
		world.setBlock(i + 23, j + 9, k + 4, Block.fence.blockID);
		world.setBlock(i + 23, j + 9, k + 5, Block.fence.blockID);
		world.setBlock(i + 23, j + 9, k + 6, Block.fence.blockID);
		world.setBlock(i + 23, j + 9, k + 7, Block.fence.blockID);
		world.setBlock(i + 23, j + 9, k + 10, Block.fence.blockID);
		world.setBlock(i + 24, j + 0, k + 4, Block.planks.blockID);
		world.setBlock(i + 24, j + 0, k + 5, Block.planks.blockID);
		world.setBlock(i + 24, j + 0, k + 6, Block.planks.blockID);
		world.setBlock(i + 24, j + 0, k + 7, Block.planks.blockID);
		world.setBlock(i + 24, j + 1, k + 3, Block.planks.blockID);
		world.setBlock(i + 24, j + 1, k + 8, Block.planks.blockID);
		world.setBlock(i + 24, j + 2, k + 2, Block.planks.blockID);
		world.setBlock(i + 24, j + 2, k + 3, Block.planks.blockID);
		world.setBlock(i + 24, j + 2, k + 4, Block.planks.blockID);
		world.setBlock(i + 24, j + 2, k + 5, Block.planks.blockID);
		world.setBlock(i + 24, j + 2, k + 6, Block.planks.blockID);
		world.setBlock(i + 24, j + 2, k + 7, Block.planks.blockID);
		world.setBlock(i + 24, j + 2, k + 8, Block.planks.blockID);
		world.setBlock(i + 24, j + 2, k + 9, Block.planks.blockID);
		world.setBlock(i + 24, j + 3, k + 1, Block.planks.blockID);
		world.setBlock(i + 24, j + 3, k + 6, Block.planks.blockID);
		world.setBlock(i + 24, j + 3, k + 10, Block.planks.blockID);
		world.setBlock(i + 24, j + 4, k + 1, Block.planks.blockID);
		world.setBlock(i + 24, j + 4, k + 6, Block.planks.blockID);
		world.setBlock(i + 24, j + 4, k + 10, Block.planks.blockID);
		world.setBlock(i + 24, j + 5, k + 1, Block.planks.blockID);
		world.setBlock(i + 24, j + 5, k + 2, Block.planks.blockID);
		world.setBlock(i + 24, j + 5, k + 3, Block.planks.blockID);
		world.setBlock(i + 24, j + 5, k + 4, Block.planks.blockID);
		world.setBlock(i + 24, j + 5, k + 5, Block.planks.blockID);
		world.setBlock(i + 24, j + 5, k + 6, Block.planks.blockID);
		world.setBlock(i + 24, j + 5, k + 7, Block.planks.blockID);
		world.setBlock(i + 24, j + 5, k + 8, Block.planks.blockID);
		world.setBlock(i + 24, j + 5, k + 9, Block.planks.blockID);
		world.setBlock(i + 24, j + 5, k + 10, Block.planks.blockID);
		world.setBlock(i + 24, j + 6, k + 1, Block.planks.blockID);
		world.setBlock(i + 24, j + 6, k + 10, Block.planks.blockID);
		world.setBlock(i + 24, j + 7, k + 1, Block.planks.blockID);
		world.setBlock(i + 24, j + 7, k + 10, Block.planks.blockID);
		world.setBlock(i + 24, j + 8, k + 1, Block.planks.blockID);
		world.setBlock(i + 24, j + 8, k + 2, Block.planks.blockID);
		world.setBlock(i + 24, j + 8, k + 3, Block.planks.blockID);
		world.setBlock(i + 24, j + 8, k + 4, Block.planks.blockID);
		world.setBlock(i + 24, j + 8, k + 7, Block.planks.blockID);
		world.setBlock(i + 24, j + 8, k + 8, Block.planks.blockID);
		world.setBlock(i + 24, j + 8, k + 9, Block.planks.blockID);
		world.setBlock(i + 24, j + 8, k + 10, Block.planks.blockID);
		world.setBlock(i + 24, j + 9, k + 1, Block.fence.blockID);
		world.setBlock(i + 24, j + 9, k + 4, Block.fence.blockID);
		world.setBlock(i + 24, j + 9, k + 7, Block.fence.blockID);
		world.setBlock(i + 24, j + 9, k + 10, Block.fence.blockID);
		world.setBlock(i + 25, j + 0, k + 4, Block.planks.blockID);
		world.setBlock(i + 25, j + 0, k + 5, Block.planks.blockID);
		world.setBlock(i + 25, j + 0, k + 6, Block.planks.blockID);
		world.setBlock(i + 25, j + 0, k + 7, Block.planks.blockID);
		world.setBlock(i + 25, j + 1, k + 3, Block.planks.blockID);
		world.setBlock(i + 25, j + 1, k + 8, Block.planks.blockID);
		world.setBlock(i + 25, j + 2, k + 2, Block.planks.blockID);
		world.setBlock(i + 25, j + 2, k + 3, Block.planks.blockID);
		world.setBlock(i + 25, j + 2, k + 4, Block.planks.blockID);
		world.setBlock(i + 25, j + 2, k + 5, Block.planks.blockID);
		world.setBlock(i + 25, j + 2, k + 6, Block.planks.blockID);
		world.setBlock(i + 25, j + 2, k + 7, Block.planks.blockID);
		world.setBlock(i + 25, j + 2, k + 8, Block.planks.blockID);
		world.setBlock(i + 25, j + 2, k + 9, Block.planks.blockID);
		world.setBlock(i + 25, j + 3, k + 1, Block.planks.blockID);
		world.setBlock(i + 25, j + 3, k + 6, Block.planks.blockID);
		world.setBlock(i + 25, j + 3, k + 10, Block.planks.blockID);
		world.setBlock(i + 25, j + 4, k + 1, Block.planks.blockID);
		world.setBlock(i + 25, j + 4, k + 6, Block.planks.blockID);
		world.setBlock(i + 25, j + 4, k + 10, Block.planks.blockID);
		world.setBlock(i + 25, j + 5, k + 1, Block.planks.blockID);
		world.setBlock(i + 25, j + 5, k + 2, Block.planks.blockID);
		world.setBlock(i + 25, j + 5, k + 3, Block.planks.blockID);
		world.setBlock(i + 25, j + 5, k + 4, Block.planks.blockID);
		world.setBlock(i + 25, j + 5, k + 5, Block.planks.blockID);
		world.setBlock(i + 25, j + 5, k + 6, Block.planks.blockID);
		world.setBlock(i + 25, j + 5, k + 7, Block.planks.blockID);
		world.setBlock(i + 25, j + 5, k + 8, Block.planks.blockID);
		world.setBlock(i + 25, j + 5, k + 9, Block.planks.blockID);
		world.setBlock(i + 25, j + 5, k + 10, Block.planks.blockID);
		world.setBlock(i + 25, j + 6, k + 5, Block.stairCompactPlanks.blockID);
		world.setBlock(i + 25, j + 6, k + 6, Block.stairCompactPlanks.blockID);
		world.setBlock(i + 25, j + 8, k + 1, Block.planks.blockID);
		world.setBlock(i + 25, j + 8, k + 2, Block.planks.blockID);
		world.setBlock(i + 25, j + 8, k + 3, Block.planks.blockID);
		world.setBlock(i + 25, j + 8, k + 4, Block.planks.blockID);
		world.setBlock(i + 25, j + 8, k + 7, Block.planks.blockID);
		world.setBlock(i + 25, j + 8, k + 8, Block.planks.blockID);
		world.setBlock(i + 25, j + 8, k + 9, Block.planks.blockID);
		world.setBlock(i + 25, j + 8, k + 10, Block.planks.blockID);

		generate2(world, rand, i, j, k);
		return true;
	}

	public boolean generate2(World world, Random rand, int i, int j, int k) {
		world.setBlock(i + 25, j + 9, k + 1, Block.fence.blockID);
		world.setBlock(i + 25, j + 9, k + 4, Block.fence.blockID);
		world.setBlock(i + 25, j + 9, k + 7, Block.fence.blockID);
		world.setBlock(i + 25, j + 9, k + 10, Block.fence.blockID);
		world.setBlock(i + 26, j + 0, k + 4, Block.planks.blockID);
		world.setBlock(i + 26, j + 0, k + 5, Block.planks.blockID);
		world.setBlock(i + 26, j + 0, k + 6, Block.planks.blockID);
		world.setBlock(i + 26, j + 0, k + 7, Block.planks.blockID);
		world.setBlock(i + 26, j + 1, k + 3, Block.planks.blockID);
		world.setBlock(i + 26, j + 1, k + 7, Block.planks.blockID);
		world.setBlock(i + 26, j + 1, k + 8, Block.planks.blockID);
		world.setBlock(i + 26, j + 2, k + 2, Block.planks.blockID);
		world.setBlock(i + 26, j + 2, k + 3, Block.planks.blockID);
		world.setBlock(i + 26, j + 2, k + 4, Block.planks.blockID);
		world.setBlock(i + 26, j + 2, k + 5, Block.planks.blockID);
		world.setBlock(i + 26, j + 2, k + 6, Block.planks.blockID);
		world.setBlock(i + 26, j + 2, k + 7, Block.planks.blockID);
		world.setBlock(i + 26, j + 2, k + 8, Block.planks.blockID);
		world.setBlock(i + 26, j + 2, k + 9, Block.planks.blockID);
		world.setBlock(i + 26, j + 3, k + 1, Block.planks.blockID);
		world.setBlockAndMetadata(i + 26, j + 3, k + 2, Block.bed.blockID, 8);
		world.setBlock(i + 26, j + 3, k + 3, Block.bed.blockID);
		world.setBlock(i + 26, j + 3, k + 6, Block.planks.blockID);
		world.setBlock(i + 26, j + 3, k + 10, Block.planks.blockID);
		world.setBlock(i + 26, j + 4, k + 1, Block.planks.blockID);
		world.setBlock(i + 26, j + 4, k + 6, Block.planks.blockID);
		world.setBlock(i + 26, j + 4, k + 10, Block.glass.blockID);
		world.setBlock(i + 26, j + 5, k + 1, Block.planks.blockID);
		world.setBlock(i + 26, j + 5, k + 2, Block.planks.blockID);
		world.setBlock(i + 26, j + 5, k + 3, Block.planks.blockID);
		world.setBlock(i + 26, j + 5, k + 4, Block.planks.blockID);
		world.setBlock(i + 26, j + 5, k + 5, Block.planks.blockID);
		world.setBlock(i + 26, j + 5, k + 6, Block.planks.blockID);
		world.setBlock(i + 26, j + 5, k + 7, Block.planks.blockID);
		world.setBlock(i + 26, j + 5, k + 8, Block.planks.blockID);
		world.setBlock(i + 26, j + 5, k + 9, Block.planks.blockID);
		world.setBlock(i + 26, j + 5, k + 10, Block.planks.blockID);
		world.setBlock(i + 26, j + 6, k + 1, Block.planks.blockID);
		world.setBlock(i + 26, j + 6, k + 10, Block.planks.blockID);
		world.setBlock(i + 26, j + 7, k + 1, Block.planks.blockID);
		world.setBlock(i + 26, j + 7, k + 5, Block.stairCompactPlanks.blockID);
		world.setBlock(i + 26, j + 7, k + 6, Block.stairCompactPlanks.blockID);
		world.setBlock(i + 26, j + 7, k + 10, Block.planks.blockID);
		world.setBlock(i + 26, j + 8, k + 1, Block.planks.blockID);
		world.setBlock(i + 26, j + 8, k + 2, Block.planks.blockID);
		world.setBlock(i + 26, j + 8, k + 3, Block.planks.blockID);
		world.setBlock(i + 26, j + 8, k + 4, Block.planks.blockID);
		world.setBlock(i + 26, j + 8, k + 7, Block.planks.blockID);
		world.setBlock(i + 26, j + 8, k + 8, Block.planks.blockID);
