package fossil.gens;

import java.util.Random;

import net.minecraft.block.Block;
import net.minecraft.world.World;
import net.minecraft.world.gen.feature.WorldGenerator;

public class WorldGeneratorShortRangeWreck extends WorldGenerator
{
	
	public boolean generate(World world, Random rand, int i, int j, int k)
	{
		System.out.println("Generating ShortRangeWreck");
		world.setBlockAndMetadata(i + 0, j + 20, k + 8, Block.planks.blockID, 1);
		world.setBlockAndMetadata(i + 1, j + 20, k + 8, Block.planks.blockID, 1);
		world.setBlockAndMetadata(i + 2, j + 20, k + 8, Block.planks.blockID, 1);
		world.setBlockAndMetadata(i + 3, j + 20, k + 8, Block.planks.blockID, 1);
		world.setBlockAndMetadata(i + 4, j + 20, k + 8, Block.planks.blockID, 1);
		world.setBlockAndMetadata(i + 5, j + 20, k + 8, Block.planks.blockID, 1);
		world.setBlockAndMetadata(i + 6, j + 20, k + 8, Block.planks.blockID, 1);
		world.setBlockAndMetadata(i + 7, j + 19, k + 8, Block.planks.blockID, 1);
		world.setBlockAndMetadata(i + 7, j + 20, k + 8, Block.planks.blockID, 1);
		world.setBlockAndMetadata(i + 8, j + 19, k + 8, Block.planks.blockID, 1);
		world.setBlockAndMetadata(i + 9, j + 19, k + 6, Block.planks.blockID, 1);
		world.setBlockAndMetadata(i + 9, j + 19, k + 7, Block.planks.blockID, 1);
		world.setBlockAndMetadata(i + 9, j + 19, k + 8, Block.planks.blockID, 1);
		world.setBlockAndMetadata(i + 9, j + 19, k + 9, Block.planks.blockID, 1);
		world.setBlockAndMetadata(i + 9, j + 19, k + 10, Block.planks.blockID, 1);
		world.setBlockAndMetadata(i + 10, j + 19, k + 8, Block.planks.blockID, 1);
		world.setBlockAndMetadata(i + 11, j + 18, k + 8, Block.planks.blockID, 1);
		world.setBlockAndMetadata(i + 11, j + 19, k + 8, Block.planks.blockID, 1);
		world.setBlockAndMetadata(i + 12, j + 16, k + 7, Block.planks.blockID, 1);
		world.setBlockAndMetadata(i + 12, j + 16, k + 8, Block.planks.blockID, 1);
		world.setBlockAndMetadata(i + 12, j + 16, k + 9, Block.planks.blockID, 1);
		world.setBlock(i + 12, j + 17, k + 7, Block.obsidian.blockID);
		world.setBlock(i + 12, j + 17, k + 8, Block.obsidian.blockID);
		world.setBlock(i + 12, j + 17, k + 9, Block.obsidian.blockID);
		world.setBlockAndMetadata(i + 12, j + 18, k + 8, Block.planks.blockID, 1);
		world.setBlockAndMetadata(i + 13, j + 16, k + 7, Block.planks.blockID, 1);
		world.setBlockAndMetadata(i + 13, j + 16, k + 8, Block.planks.blockID, 1);
		world.setBlockAndMetadata(i + 13, j + 16, k + 9, Block.planks.blockID, 1);
		world.setBlock(i + 13, j + 17, k + 7, Block.obsidian.blockID);
		world.setBlockAndMetadata(i + 13, j + 17, k + 8, Block.planks.blockID, 1);
		world.setBlock(i + 13, j + 17, k + 9, Block.obsidian.blockID);
		world.setBlockAndMetadata(i + 13, j + 18, k + 8, Block.planks.blockID, 1);
		world.setBlockAndMetadata(i + 14, j + 15, k + 7, Block.planks.blockID, 1);
		world.setBlockAndMetadata(i + 14, j + 15, k + 8, Block.planks.blockID, 1);
		world.setBlockAndMetadata(i + 14, j + 15, k + 9, Block.planks.blockID, 1);
		world.setBlockAndMetadata(i + 14, j + 16, k + 7, Block.planks.blockID, 1);
		world.setBlockAndMetadata(i + 14, j + 16, k + 8, Block.planks.blockID, 1);
		world.setBlockAndMetadata(i + 14, j + 16, k + 9, Block.planks.blockID, 1);
		world.setBlock(i + 14, j + 17, k + 7, Block.obsidian.blockID);
		world.setBlockAndMetadata(i + 14, j + 17, k + 8, Block.planks.blockID, 1);
		world.setBlock(i + 14, j + 17, k + 9, Block.obsidian.blockID);
		world.setBlockAndMetadata(i + 15, j + 15, k + 7, Block.planks.blockID, 1);
		world.setBlockAndMetadata(i + 15, j + 15, k + 8, Block.planks.blockID, 1);
		world.setBlockAndMetadata(i + 15, j + 15, k + 9, Block.planks.blockID, 1);
		world.setBlockAndMetadata(i + 15, j + 16, k + 6, Block.planks.blockID, 1);
		world.setBlockAndMetadata(i + 15, j + 16, k + 7, Block.planks.blockID, 1);
		world.setBlockAndMetadata(i + 15, j + 16, k + 8, Block.planks.blockID, 1);
		world.setBlockAndMetadata(i + 15, j + 16, k + 9, Block.planks.blockID, 1);
		world.setBlockAndMetadata(i + 15, j + 16, k + 10, Block.planks.blockID, 1);
		world.setBlock(i + 15, j + 17, k + 6, Block.obsidian.blockID);
		world.setBlock(i + 15, j + 17, k + 7, Block.obsidian.blockID);
		world.setBlockAndMetadata(i + 15, j + 17, k + 8, Block.planks.blockID, 1);
		world.setBlock(i + 15, j + 17, k + 9, Block.obsidian.blockID);
		world.setBlock(i + 15, j + 17, k + 10, Block.obsidian.blockID);
		world.setBlockAndMetadata(i + 16, j + 13, k + 6, Block.planks.blockID, 1);
		world.setBlockAndMetadata(i + 16, j + 13, k + 7, Block.planks.blockID, 1);
		world.setBlockAndMetadata(i + 16, j + 13, k + 8, Block.planks.blockID, 1);
		world.setBlockAndMetadata(i + 16, j + 13, k + 9, Block.planks.blockID, 1);
		world.setBlockAndMetadata(i + 16, j + 13, k + 10, Block.planks.blockID, 1);
		world.setBlockAndMetadata(i + 16, j + 14, k + 6, Block.planks.blockID, 1);
		world.setBlockAndMetadata(i + 16, j + 14, k + 7, Block.planks.blockID, 1);
		world.setBlockAndMetadata(i + 16, j + 14, k + 8, Block.planks.blockID, 1);
		world.setBlockAndMetadata(i + 16, j + 14, k + 9, Block.planks.blockID, 1);
		world.setBlockAndMetadata(i + 16, j + 14, k + 10, Block.planks.blockID, 1);
		world.setBlockAndMetadata(i + 16, j + 15, k + 6, Block.planks.blockID, 1);
		world.setBlockAndMetadata(i + 16, j + 15, k + 7, Block.planks.blockID, 1);
		world.setBlockAndMetadata(i + 16, j + 15, k + 8, Block.planks.blockID, 1);
		world.setBlockAndMetadata(i + 16, j + 15, k + 9, Block.planks.blockID, 1);
		world.setBlockAndMetadata(i + 16, j + 15, k + 10, Block.planks.blockID, 1);
		world.setBlockAndMetadata(i + 16, j + 16, k + 6, Block.planks.blockID, 1);
		world.setBlockAndMetadata(i + 16, j + 16, k + 7, Block.planks.blockID, 1);
		world.setBlockAndMetadata(i + 16, j + 16, k + 8, Block.planks.blockID, 1);
		world.setBlockAndMetadata(i + 16, j + 16, k + 9, Block.planks.blockID, 1);
		world.setBlockAndMetadata(i + 16, j + 16, k + 10, Block.planks.blockID, 1);
		world.setBlock(i + 16, j + 17, k + 6, Block.obsidian.blockID);
		world.setBlockAndMetadata(i + 16, j + 17, k + 7, Block.planks.blockID, 1);
		world.setBlockAndMetadata(i + 16, j + 17, k + 8, Block.planks.blockID, 1);
		world.setBlockAndMetadata(i + 16, j + 17, k + 9, Block.planks.blockID, 1);
		world.setBlock(i + 16, j + 17, k + 10, Block.obsidian.blockID);
		world.setBlockAndMetadata(i + 17, j + 11, k + 7, Block.planks.blockID, 1);
		world.setBlockAndMetadata(i + 17, j + 11, k + 8, Block.planks.blockID, 1);
		world.setBlockAndMetadata(i + 17, j + 11, k + 9, Block.planks.blockID, 1);
		world.setBlockAndMetadata(i + 17, j + 12, k + 7, Block.planks.blockID, 1);
		world.setBlockAndMetadata(i + 17, j + 12, k + 8, Block.planks.blockID, 1);
		world.setBlockAndMetadata(i + 17, j + 12, k + 9, Block.planks.blockID, 1);
		world.setBlockAndMetadata(i + 17, j + 13, k + 6, Block.planks.blockID, 1);
		world.setBlockAndMetadata(i + 17, j + 13, k + 10, Block.planks.blockID, 1);
		world.setBlockAndMetadata(i + 17, j + 14, k + 6, Block.planks.blockID, 1);
		world.setBlockAndMetadata(i + 17, j + 14, k + 10, Block.planks.blockID, 1);
		world.setBlockAndMetadata(i + 17, j + 15, k + 5, Block.planks.blockID, 1);
		world.setBlockAndMetadata(i + 17, j + 15, k + 6, Block.planks.blockID, 1);
		world.setBlockAndMetadata(i + 17, j + 15, k + 10, Block.planks.blockID, 1);
		world.setBlockAndMetadata(i + 17, j + 15, k + 11, Block.planks.blockID, 1);
		world.setBlockAndMetadata(i + 17, j + 16, k + 4, Block.planks.blockID, 1);
		world.setBlock(i + 17, j + 16, k + 5, Block.obsidian.blockID);
		world.setBlockAndMetadata(i + 17, j + 16, k + 6, Block.planks.blockID, 1);
		world.setBlockAndMetadata(i + 17, j + 16, k + 10, Block.planks.blockID, 1);
		world.setBlock(i + 17, j + 16, k + 11, Block.obsidian.blockID);
		world.setBlockAndMetadata(i + 17, j + 16, k + 12, Block.planks.blockID, 1);
		world.setBlock(i + 17, j + 17, k + 4, Block.obsidian.blockID);
		world.setBlock(i + 17, j + 17, k + 5, Block.obsidian.blockID);
		world.setBlock(i + 17, j + 17, k + 6, Block.obsidian.blockID);
		world.setBlockAndMetadata(i + 17, j + 17, k + 7, Block.planks.blockID, 1);
		world.setBlockAndMetadata(i + 17, j + 17, k + 8, Block.planks.blockID, 1);
		world.setBlockAndMetadata(i + 17, j + 17, k + 9, Block.planks.blockID, 1);
		world.setBlock(i + 17, j + 17, k + 10, Block.obsidian.blockID);
		world.setBlock(i + 17, j + 17, k + 11, Block.obsidian.blockID);
		world.setBlock(i + 17, j + 17, k + 12, Block.obsidian.blockID);
		world.setBlock(i + 17, j + 18, k + 4, Block.obsidian.blockID);
		world.setBlock(i + 17, j + 18, k + 6, Block.obsidian.blockID);
		world.setBlock(i + 17, j + 18, k + 10, Block.obsidian.blockID);
		world.setBlock(i + 17, j + 18, k + 12, Block.obsidian.blockID);
		world.setBlockAndMetadata(i + 18, j + 9, k + 8, Block.planks.blockID, 1);
		world.setBlockAndMetadata(i + 18, j + 10, k + 8, Block.planks.blockID, 1);
		world.setBlockAndMetadata(i + 18, j + 11, k + 7, Block.planks.blockID, 1);
		world.setBlockAndMetadata(i + 18, j + 11, k + 8, Block.planks.blockID, 1);
		world.setBlockAndMetadata(i + 18, j + 11, k + 9, Block.planks.blockID, 1);
		world.setBlockAndMetadata(i + 18, j + 12, k + 7, Block.planks.blockID, 1);
		world.setBlockAndMetadata(i + 18, j + 12, k + 8, Block.planks.blockID, 1);
		world.setBlockAndMetadata(i + 18, j + 12, k + 9, Block.planks.blockID, 1);
		world.setBlockAndMetadata(i + 18, j + 13, k + 6, Block.planks.blockID, 1);
		world.setBlock(i + 18, j + 13, k + 8, Block.blockClay.blockID);
		world.setBlockAndMetadata(i + 18, j + 13, k + 10, Block.planks.blockID, 1);
		world.setBlockAndMetadata(i + 18, j + 14, k + 6, Block.planks.blockID, 1);
		world.setBlock(i + 18, j + 14, k + 8, Block.fence.blockID);
		world.setBlockAndMetadata(i + 18, j + 14, k + 10, Block.planks.blockID, 1);
		world.setBlockAndMetadata(i + 18, j + 15, k + 5, Block.planks.blockID, 1);
		world.setBlockAndMetadata(i + 18, j + 15, k + 6, Block.planks.blockID, 1);
		world.setBlockAndMetadata(i + 18, j + 15, k + 8, Block.leaves.blockID, 7);
		world.setBlockAndMetadata(i + 18, j + 15, k + 10, Block.planks.blockID, 1);
		world.setBlockAndMetadata(i + 18, j + 15, k + 11, Block.planks.blockID, 1);
		world.setBlockAndMetadata(i + 18, j + 16, k + 4, Block.planks.blockID, 1);
		world.setBlockAndMetadata(i + 18, j + 16, k + 5, Block.planks.blockID, 1);
		world.setBlockAndMetadata(i + 18, j + 16, k + 6, Block.planks.blockID, 1);
		world.setBlockAndMetadata(i + 18, j + 16, k + 10, Block.planks.blockID, 1);
		world.setBlockAndMetadata(i + 18, j + 16, k + 11, Block.planks.blockID, 1);
		world.setBlockAndMetadata(i + 18, j + 16, k + 12, Block.planks.blockID, 1);
		world.setBlock(i + 18, j + 17, k + 4, Block.obsidian.blockID);
		world.setBlock(i + 18, j + 17, k + 5, Block.obsidian.blockID);
		world.setBlockAndMetadata(i + 18, j + 17, k + 6, Block.planks.blockID, 1);
		world.setBlockAndMetadata(i + 18, j + 17, k + 7, Block.planks.blockID, 1);
		world.setBlockAndMetadata(i + 18, j + 17, k + 8, Block.planks.blockID, 1);
		world.setBlockAndMetadata(i + 18, j + 17, k + 9, Block.planks.blockID, 1);
		world.setBlockAndMetadata(i + 18, j + 17, k + 10, Block.planks.blockID, 1);
		world.setBlock(i + 18, j + 17, k + 11, Block.obsidian.blockID);
		world.setBlock(i + 18, j + 17, k + 12, Block.obsidian.blockID);
		world.setBlock(i + 18, j + 18, k + 4, Block.obsidian.blockID);
		world.setBlock(i + 18, j + 18, k + 6, Block.obsidian.blockID);
		world.setBlock(i + 18, j + 18, k + 10, Block.obsidian.blockID);
		world.setBlock(i + 18, j + 18, k + 12, Block.obsidian.blockID);
		world.setBlockAndMetadata(i + 19, j + 9, k + 8, Block.planks.blockID, 1);
		world.setBlockAndMetadata(i + 19, j + 10, k + 8, Block.planks.blockID, 1);
		world.setBlockAndMetadata(i + 19, j + 11, k + 7, Block.planks.blockID, 1);
		world.setBlockAndMetadata(i + 19, j + 11, k + 8, Block.planks.blockID, 1);
		world.setBlockAndMetadata(i + 19, j + 11, k + 9, Block.planks.blockID, 1);
		world.setBlockAndMetadata(i + 19, j + 12, k + 7, Block.planks.blockID, 1);
		world.setBlockAndMetadata(i + 19, j + 12, k + 8, Block.planks.blockID, 1);
		world.setBlockAndMetadata(i + 19, j + 12, k + 9, Block.planks.blockID, 1);
		world.setBlockAndMetadata(i + 19, j + 13, k + 6, Block.planks.blockID, 1);
		world.setBlockAndMetadata(i + 19, j + 13, k + 10, Block.planks.blockID, 1);
		world.setBlockAndMetadata(i + 19, j + 14, k + 6, Block.planks.blockID, 1);
		world.setBlockAndMetadata(i + 19, j + 14, k + 10, Block.planks.blockID, 1);
		world.setBlockAndMetadata(i + 19, j + 15, k + 5, Block.planks.blockID, 1);
		world.setBlockAndMetadata(i + 19, j + 15, k + 6, Block.planks.blockID, 1);
		world.setBlockAndMetadata(i + 19, j + 15, k + 10, Block.planks.blockID, 1);
		world.setBlockAndMetadata(i + 19, j + 15, k + 11, Block.planks.blockID, 1);
		world.setBlockAndMetadata(i + 19, j + 16, k + 4, Block.planks.blockID, 1);
		world.setBlockAndMetadata(i + 19, j + 16, k + 5, Block.planks.blockID, 1);
		world.setBlockAndMetadata(i + 19, j + 16, k + 6, Block.planks.blockID, 1);
		world.setBlockAndMetadata(i + 19, j + 16, k + 10, Block.planks.blockID, 1);
		world.setBlockAndMetadata(i + 19, j + 16, k + 11, Block.planks.blockID, 1);
		world.setBlockAndMetadata(i + 19, j + 16, k + 12, Block.planks.blockID, 1);
		world.setBlock(i + 19, j + 17, k + 4, Block.obsidian.blockID);
		world.setBlock(i + 19, j + 17, k + 5, Block.obsidian.blockID);
		world.setBlockAndMetadata(i + 19, j + 17, k + 6, Block.planks.blockID, 1);
		world.setBlockAndMetadata(i + 19, j + 17, k + 7, Block.planks.blockID, 1);
		world.setBlockAndMetadata(i + 19, j + 17, k + 8, Block.planks.blockID, 1);
		world.setBlockAndMetadata(i + 19, j + 17, k + 9, Block.planks.blockID, 1);
		world.setBlockAndMetadata(i + 19, j + 17, k + 10, Block.planks.blockID, 1);
		world.setBlock(i + 19, j + 17, k + 11, Block.obsidian.blockID);
		world.setBlock(i + 19, j + 17, k + 12, Block.obsidian.blockID);
		world.setBlock(i + 19, j + 18, k + 4, Block.obsidian.blockID);
		world.setBlock(i + 19, j + 18, k + 6, Block.obsidian.blockID);
		world.setBlock(i + 19, j + 18, k + 10, Block.obsidian.blockID);
		world.setBlock(i + 19, j + 18, k + 12, Block.obsidian.blockID);
		world.setBlockAndMetadata(i + 20, j + 9, k + 7, Block.planks.blockID, 1);
		world.setBlockAndMetadata(i + 20, j + 9, k + 8, Block.planks.blockID, 1);
		world.setBlockAndMetadata(i + 20, j + 9, k + 9, Block.planks.blockID, 1);
		world.setBlockAndMetadata(i + 20, j + 10, k + 7, Block.planks.blockID, 1);
		world.setBlockAndMetadata(i + 20, j + 10, k + 8, Block.planks.blockID, 1);
		world.setBlockAndMetadata(i + 20, j + 10, k + 9, Block.planks.blockID, 1);
		world.setBlockAndMetadata(i + 20, j + 11, k + 6, Block.planks.blockID, 1);
		world.setBlockAndMetadata(i + 20, j + 11, k + 7, Block.planks.blockID, 1);
		world.setBlockAndMetadata(i + 20, j + 11, k + 8, Block.planks.blockID, 1);
		world.setBlockAndMetadata(i + 20, j + 11, k + 9, Block.planks.blockID, 1);
		world.setBlockAndMetadata(i + 20, j + 11, k + 10, Block.planks.blockID, 1);
		world.setBlockAndMetadata(i + 20, j + 12, k + 6, Block.planks.blockID, 1);
		world.setBlockAndMetadata(i + 20, j + 12, k + 7, Block.planks.blockID, 1);
		world.setBlockAndMetadata(i + 20, j + 12, k + 8, Block.planks.blockID, 1);
		world.setBlockAndMetadata(i + 20, j + 12, k + 9, Block.planks.blockID, 1);
		world.setBlockAndMetadata(i + 20, j + 12, k + 10, Block.planks.blockID, 1);
		world.setBlockAndMetadata(i + 20, j + 13, k + 5, Block.planks.blockID, 1);
		world.setBlockAndMetadata(i + 20, j + 13, k + 11, Block.planks.blockID, 1);
		world.setBlockAndMetadata(i + 20, j + 14, k + 5, Block.planks.blockID, 1);
		world.setBlockAndMetadata(i + 20, j + 14, k + 11, Block.planks.blockID, 1);
		world.setBlockAndMetadata(i + 20, j + 15, k + 5, Block.planks.blockID, 1);
		world.setBlockAndMetadata(i + 20, j + 15, k + 11, Block.planks.blockID, 1);
		world.setBlockAndMetadata(i + 20, j + 16, k + 4, Block.planks.blockID, 1);
		world.setBlockAndMetadata(i + 20, j + 16, k + 5, Block.planks.blockID, 1);
		world.setBlockAndMetadata(i + 20, j + 16, k + 11, Block.planks.blockID, 1);
		world.setBlockAndMetadata(i + 20, j + 16, k + 12, Block.planks.blockID, 1);
		world.setBlockAndMetadata(i + 20, j + 16, k + 13, Block.planks.blockID, 1);
		world.setBlock(i + 20, j + 17, k + 3, Block.obsidian.blockID);
		world.setBlock(i + 20, j + 17, k + 4, Block.obsidian.blockID);
		world.setBlockAndMetadata(i + 20, j + 17, k + 5, Block.planks.blockID, 1);
		world.setBlockAndMetadata(i + 20, j + 17, k + 6, Block.planks.blockID, 1);
		world.setBlockAndMetadata(i + 20, j + 17, k + 7, Block.planks.blockID, 1);
		world.setBlockAndMetadata(i + 20, j + 17, k + 8, Block.planks.blockID, 1);
		world.setBlockAndMetadata(i + 20, j + 17, k + 9, Block.planks.blockID, 1);
		world.setBlockAndMetadata(i + 20, j + 17, k + 10, Block.planks.blockID, 1);
		world.setBlockAndMetadata(i + 20, j + 17, k + 11, Block.planks.blockID, 1);
		world.setBlock(i + 20, j + 17, k + 12, Block.obsidian.blockID);
		world.setBlock(i + 20, j + 17, k + 13, Block.obsidian.blockID);
		world.setBlock(i + 20, j + 18, k + 4, Block.obsidian.blockID);
		world.setBlock(i + 20, j + 18, k + 6, Block.obsidian.blockID);
		world.setBlock(i + 20, j + 18, k + 10, Block.obsidian.blockID);
		world.setBlock(i + 20, j + 18, k + 12, Block.obsidian.blockID);
		world.setBlockAndMetadata(i + 21, j + 6, k + 7, Block.planks.blockID, 1);
		world.setBlockAndMetadata(i + 21, j + 6, k + 8, Block.planks.blockID, 1);
		world.setBlockAndMetadata(i + 21, j + 6, k + 9, Block.planks.blockID, 1);
		world.setBlockAndMetadata(i + 21, j + 7, k + 7, Block.planks.blockID, 1);
		world.setBlockAndMetadata(i + 21, j + 7, k + 8, Block.planks.blockID, 1);
		world.setBlockAndMetadata(i + 21, j + 7, k + 9, Block.planks.blockID, 1);
		world.setBlockAndMetadata(i + 21, j + 8, k + 7, Block.planks.blockID, 1);
		world.setBlockAndMetadata(i + 21, j + 8, k + 8, Block.planks.blockID, 1);
		world.setBlockAndMetadata(i + 21, j + 8, k + 9, Block.planks.blockID, 1);
		world.setBlockAndMetadata(i + 21, j + 9, k + 6, Block.planks.blockID, 1);
		world.setBlockAndMetadata(i + 21, j + 9, k + 7, Block.stoneOvenIdle.blockID, 5);
		world.setBlockAndMetadata(i + 21, j + 9, k + 8, Block.stoneOvenIdle.blockID, 5);
		world.setBlockAndMetadata(i + 21, j + 9, k + 9, Block.stoneOvenIdle.blockID, 5);
		world.setBlockAndMetadata(i + 21, j + 9, k + 10, Block.planks.blockID, 1);
		world.setBlockAndMetadata(i + 21, j + 10, k + 6, Block.planks.blockID, 1);
		world.setBlockAndMetadata(i + 21, j + 10, k + 7, Block.stoneOvenIdle.blockID, 5);
		world.setBlockAndMetadata(i + 21, j + 10, k + 8, Block.stoneOvenIdle.blockID, 5);
		world.setBlockAndMetadata(i + 21, j + 10, k + 9, Block.stoneOvenIdle.blockID, 5);
		world.setBlockAndMetadata(i + 21, j + 10, k + 10, Block.planks.blockID, 1);
		world.setBlockAndMetadata(i + 21, j + 11, k + 6, Block.planks.blockID, 1);
		world.setBlock(i + 21, j + 11, k + 7, Block.workbench.blockID);
		world.setBlockAndMetadata(i + 21, j + 11, k + 8, Block.chest.blockID, 5);
		world.setBlockAndMetadata(i + 21, j + 11, k + 9, Block.chest.blockID, 5);
		world.setBlockAndMetadata(i + 21, j + 11, k + 10, Block.planks.blockID, 1);
		world.setBlockAndMetadata(i + 21, j + 12, k + 6, Block.planks.blockID, 1);
		world.setBlockAndMetadata(i + 21, j + 12, k + 7, Block.planks.blockID, 1);
		world.setBlockAndMetadata(i + 21, j + 12, k + 8, Block.planks.blockID, 1);
		world.setBlockAndMetadata(i + 21, j + 12, k + 9, Block.planks.blockID, 1);
		world.setBlockAndMetadata(i + 21, j + 12, k + 10, Block.planks.blockID, 1);
		world.setBlockAndMetadata(i + 21, j + 13, k + 5, Block.planks.blockID, 1);
		world.setBlockAndMetadata(i + 21, j + 13, k + 11, Block.planks.blockID, 1);
		world.setBlockAndMetadata(i + 21, j + 14, k + 5, Block.planks.blockID, 1);
		world.setBlockAndMetadata(i + 21, j + 14, k + 11, Block.planks.blockID, 1);
		world.setBlockAndMetadata(i + 21, j + 15, k + 5, Block.planks.blockID, 1);
		world.setBlockAndMetadata(i + 21, j + 15, k + 11, Block.planks.blockID, 1);
		world.setBlockAndMetadata(i + 21, j + 16, k + 3, Block.planks.blockID, 1);
		world.setBlockAndMetadata(i + 21, j + 16, k + 4, Block.planks.blockID, 1);
		world.setBlockAndMetadata(i + 21, j + 16, k + 5, Block.planks.blockID, 1);
		world.setBlockAndMetadata(i + 21, j + 16, k + 11, Block.planks.blockID, 1);
		world.setBlockAndMetadata(i + 21, j + 16, k + 12, Block.planks.blockID, 1);
		world.setBlockAndMetadata(i + 21, j + 16, k + 13, Block.planks.blockID, 1);
		world.setBlock(i + 21, j + 17, k + 3, Block.obsidian.blockID);
		world.setBlock(i + 21, j + 17, k + 4, Block.obsidian.blockID);
		world.setBlockAndMetadata(i + 21, j + 17, k + 5, Block.planks.blockID, 1);
		world.setBlockAndMetadata(i + 21, j + 17, k + 6, Block.planks.blockID, 1);
		world.setBlockAndMetadata(i + 21, j + 17, k + 7, Block.planks.blockID, 1);
		world.setBlockAndMetadata(i + 21, j + 17, k + 8, Block.planks.blockID, 1);
		world.setBlockAndMetadata(i + 21, j + 17, k + 9, Block.planks.blockID, 1);
		world.setBlockAndMetadata(i + 21, j + 17, k + 10, Block.planks.blockID, 1);
		world.setBlockAndMetadata(i + 21, j + 17, k + 11, Block.planks.blockID, 1);
		world.setBlock(i + 21, j + 17, k + 12, Block.obsidian.blockID);
		world.setBlock(i + 21, j + 17, k + 13, Block.obsidian.blockID);
		world.setBlock(i + 21, j + 18, k + 4, Block.obsidian.blockID);
		world.setBlock(i + 21, j + 18, k + 6, Block.obsidian.blockID);
		world.setBlock(i + 21, j + 18, k + 10, Block.obsidian.blockID);
		world.setBlock(i + 21, j + 18, k + 12, Block.obsidian.blockID);
		world.setBlockAndMetadata(i + 22, j + 6, k + 6, Block.planks.blockID, 1);
		world.setBlockAndMetadata(i + 22, j + 6, k + 7, Block.planks.blockID, 1);
		world.setBlockAndMetadata(i + 22, j + 6, k + 8, Block.planks.blockID, 1);
		world.setBlockAndMetadata(i + 22, j + 6, k + 9, Block.planks.blockID, 1);
		world.setBlockAndMetadata(i + 22, j + 6, k + 10, Block.planks.blockID, 1);
		world.setBlockAndMetadata(i + 22, j + 7, k + 6, Block.planks.blockID, 1);
		world.setBlock(i + 22, j + 7, k + 8, Block.fence.blockID);
		world.setBlockAndMetadata(i + 22, j + 7, k + 10, Block.planks.blockID, 1);
		world.setBlockAndMetadata(i + 22, j + 8, k + 6, Block.planks.blockID, 1);
		world.setBlockAndMetadata(i + 22, j + 8, k + 7, Block.planks.blockID, 1);
		world.setBlockAndMetadata(i + 22, j + 8, k + 8, Block.planks.blockID, 1);
		world.setBlockAndMetadata(i + 22, j + 8, k + 9, Block.planks.blockID, 1);
		world.setBlockAndMetadata(i + 22, j + 8, k + 10, Block.planks.blockID, 1);
		world.setBlockAndMetadata(i + 22, j + 9, k + 6, Block.planks.blockID, 1);
		world.setBlockAndMetadata(i + 22, j + 9, k + 10, Block.planks.blockID, 1);
		world.setBlockAndMetadata(i + 22, j + 10, k + 6, Block.planks.blockID, 1);
		world.setBlockAndMetadata(i + 22, j + 10, k + 10, Block.planks.blockID, 1);
		world.setBlockAndMetadata(i + 22, j + 11, k + 6, Block.planks.blockID, 1);
		world.setBlockAndMetadata(i + 22, j + 11, k + 10, Block.planks.blockID, 1);
		world.setBlockAndMetadata(i + 22, j + 12, k + 6, Block.planks.blockID, 1);
		world.setBlockAndMetadata(i + 22, j + 12, k + 7, Block.planks.blockID, 1);
		world.setBlockAndMetadata(i + 22, j + 12, k + 8, Block.planks.blockID, 1);
		world.setBlockAndMetadata(i + 22, j + 12, k + 9, Block.planks.blockID, 1);
		world.setBlockAndMetadata(i + 22, j + 12, k + 10, Block.planks.blockID, 1);
		world.setBlockAndMetadata(i + 22, j + 13, k + 4, Block.planks.blockID, 1);
		world.setBlockAndMetadata(i + 22, j + 13, k + 5, Block.planks.blockID, 1);
		world.setBlock(i + 22, j + 13, k + 8, Block.stoneBrick.blockID);
		world.setBlock(i + 22, j + 13, k + 9, Block.stoneBrick.blockID);
		world.setBlock(i + 22, j + 13, k + 10, Block.stoneBrick.blockID);
		world.setBlockAndMetadata(i + 22, j + 13, k + 11, Block.planks.blockID, 1);
		world.setBlockAndMetadata(i + 22, j + 13, k + 12, Block.planks.blockID, 1);
		world.setBlockAndMetadata(i + 22, j + 14, k + 4, Block.planks.blockID, 1);
		world.setBlockAndMetadata(i + 22, j + 14, k + 5, Block.planks.blockID, 1);
		world.setBlockAndMetadata(i + 22, j + 14, k + 11, Block.planks.blockID, 1);
		world.setBlockAndMetadata(i + 22, j + 14, k + 12, Block.planks.blockID, 1);
		world.setBlockAndMetadata(i + 22, j + 15, k + 4, Block.planks.blockID, 1);
		world.setBlockAndMetadata(i + 22, j + 15, k + 5, Block.planks.blockID, 1);
		world.setBlockAndMetadata(i + 22, j + 15, k + 11, Block.planks.blockID, 1);
		world.setBlockAndMetadata(i + 22, j + 15, k + 12, Block.planks.blockID, 1);
		world.setBlockAndMetadata(i + 22, j + 16, k + 3, Block.planks.blockID, 1);
		world.setBlockAndMetadata(i + 22, j + 16, k + 4, Block.planks.blockID, 1);
		world.setBlockAndMetadata(i + 22, j + 16, k + 5, Block.planks.blockID, 1);
		world.setBlockAndMetadata(i + 22, j + 16, k + 11, Block.planks.blockID, 1);
		world.setBlockAndMetadata(i + 22, j + 16, k + 12, Block.planks.blockID, 1);
		world.setBlockAndMetadata(i + 22, j + 16, k + 13, Block.planks.blockID, 1);
		world.setBlock(i + 22, j + 17, k + 3, Block.obsidian.blockID);
		world.setBlockAndMetadata(i + 22, j + 17, k + 4, Block.planks.blockID, 1);
		world.setBlockAndMetadata(i + 22, j + 17, k + 5, Block.planks.blockID, 1);
		world.setBlockAndMetadata(i + 22, j + 17, k + 6, Block.planks.blockID, 1);
		world.setBlockAndMetadata(i + 22, j + 17, k + 7, Block.planks.blockID, 1);
		world.setBlockAndMetadata(i + 22, j + 17, k + 8, Block.planks.blockID, 1);
		world.setBlockAndMetadata(i + 22, j + 17, k + 9, Block.planks.blockID, 1);
		world.setBlockAndMetadata(i + 22, j + 17, k + 10, Block.planks.blockID, 1);
		world.setBlockAndMetadata(i + 22, j + 17, k + 11, Block.planks.blockID, 1);
		world.setBlockAndMetadata(i + 22, j + 17, k + 12, Block.planks.blockID, 1);
		world.setBlock(i + 22, j + 17, k + 13, Block.obsidian.blockID);
		world.setBlock(i + 22, j + 18, k + 4, Block.obsidian.blockID);
		world.setBlock(i + 22, j + 18, k + 6, Block.obsidian.blockID);
		world.setBlock(i + 22, j + 18, k + 10, Block.obsidian.blockID);
		world.setBlock(i + 22, j + 18, k + 12, Block.obsidian.blockID);
		world.setBlockAndMetadata(i + 23, j + 6, k + 6, Block.planks.blockID, 1);
		world.setBlockAndMetadata(i + 23, j + 6, k + 7, Block.planks.blockID, 1);
		world.setBlockAndMetadata(i + 23, j + 6, k + 8, Block.planks.blockID, 1);
		world.setBlockAndMetadata(i + 23, j + 6, k + 9, Block.planks.blockID, 1);
		world.setBlockAndMetadata(i + 23, j + 6, k + 10, Block.planks.blockID, 1);
		world.setBlockAndMetadata(i + 23, j + 7, k + 6, Block.planks.blockID, 1);
		world.setBlock(i + 23, j + 7, k + 8, Block.fence.blockID);
		world.setBlockAndMetadata(i + 23, j + 7, k + 10, Block.planks.blockID, 1);
		world.setBlockAndMetadata(i + 23, j + 8, k + 6, Block.planks.blockID, 1);
		world.setBlockAndMetadata(i + 23, j + 8, k + 7, Block.planks.blockID, 1);
		world.setBlockAndMetadata(i + 23, j + 8, k + 8, Block.planks.blockID, 1);
		world.setBlockAndMetadata(i + 23, j + 8, k + 9, Block.planks.blockID, 1);
		world.setBlockAndMetadata(i + 23, j + 8, k + 10, Block.planks.blockID, 1);
		world.setBlockAndMetadata(i + 23, j + 9, k + 5, Block.planks.blockID, 1);
		world.setBlock(i + 23, j + 9, k + 6, Block.blockSteel.blockID);
		world.setBlockAndMetadata(i + 23, j + 9, k + 10, Block.planks.blockID, 1);
		world.setBlockAndMetadata(i + 23, j + 9, k + 11, Block.planks.blockID, 1);
		world.setBlockAndMetadata(i + 23, j + 10, k + 5, Block.planks.blockID, 1);
		world.setBlockAndMetadata(i + 23, j + 10, k + 10, Block.planks.blockID, 1);
		world.setBlockAndMetadata(i + 23, j + 10, k + 11, Block.planks.blockID, 1);
		world.setBlockAndMetadata(i + 23, j + 11, k + 5, Block.planks.blockID, 1);
		world.setBlockAndMetadata(i + 23, j + 11, k + 10, Block.planks.blockID, 1);
		world.setBlockAndMetadata(i + 23, j + 11, k + 11, Block.planks.blockID, 1);
		world.setBlockAndMetadata(i + 23, j + 12, k + 5, Block.planks.blockID, 1);
		world.setBlockAndMetadata(i + 23, j + 12, k + 6, Block.planks.blockID, 1);
		world.setBlockAndMetadata(i + 23, j + 12, k + 7, Block.planks.blockID, 1);
		world.setBlockAndMetadata(i + 23, j + 12, k + 8, Block.planks.blockID, 1);
		world.setBlockAndMetadata(i + 23, j + 12, k + 9, Block.planks.blockID, 1);
		world.setBlockAndMetadata(i + 23, j + 12, k + 10, Block.planks.blockID, 1);
		world.setBlockAndMetadata(i + 23, j + 12, k + 11, Block.planks.blockID, 1);
		world.setBlockAndMetadata(i + 23, j + 13, k + 4, Block.planks.blockID, 1);
		world.setBlockAndMetadata(i + 23, j + 13, k + 7, Block.stoneSingleSlab.blockID, 5);
		world.setBlock(i + 23, j + 13, k + 8, Block.stoneBrick.blockID);
		world.setBlockAndMetadata(i + 23, j + 13, k + 12, Block.planks.blockID, 1);
		world.setBlockAndMetadata(i + 23, j + 14, k + 4, Block.planks.blockID, 1);
		world.setBlockAndMetadata(i + 23, j + 14, k + 12, Block.planks.blockID, 1);
		world.setBlockAndMetadata(i + 23, j + 15, k + 4, Block.planks.blockID, 1);
		world.setBlockAndMetadata(i + 23, j + 15, k + 12, Block.planks.blockID, 1);
		world.setBlockAndMetadata(i + 23, j + 16, k + 3, Block.planks.blockID, 1);
		world.setBlockAndMetadata(i + 23, j + 16, k + 4, Block.planks.blockID, 1);
		world.setBlockAndMetadata(i + 23, j + 16, k + 5, Block.planks.blockID, 1);
		world.setBlockAndMetadata(i + 23, j + 16, k + 12, Block.planks.blockID, 1);
		world.setBlockAndMetadata(i + 23, j + 16, k + 13, Block.planks.blockID, 1);
		world.setBlock(i + 23, j + 17, k + 3, Block.obsidian.blockID);
		world.setBlockAndMetadata(i + 23, j + 17, k + 4, Block.planks.blockID, 1);
		world.setBlockAndMetadata(i + 23, j + 17, k + 5, Block.planks.blockID, 1);
		world.setBlockAndMetadata(i + 23, j + 17, k + 6, Block.planks.blockID, 1);
		world.setBlockAndMetadata(i + 23, j + 17, k + 7, Block.planks.blockID, 1);
		world.setBlockAndMetadata(i + 23, j + 17, k + 8, Block.planks.blockID, 1);
		world.setBlockAndMetadata(i + 23, j + 17, k + 9, Block.planks.blockID, 1);
		world.setBlockAndMetadata(i + 23, j + 17, k + 10, Block.planks.blockID, 1);
		world.setBlockAndMetadata(i + 23, j + 17, k + 11, Block.planks.blockID, 1);
		world.setBlockAndMetadata(i + 23, j + 17, k + 12, Block.planks.blockID, 1);
		world.setBlock(i + 23, j + 17, k + 13, Block.obsidian.blockID);
		world.setBlock(i + 23, j + 18, k + 4, Block.obsidian.blockID);
		world.setBlock(i + 23, j + 18, k + 6, Block.obsidian.blockID);
		world.setBlock(i + 23, j + 18, k + 10, Block.obsidian.blockID);
		world.setBlock(i + 23, j + 18, k + 12, Block.obsidian.blockID);
		world.setBlockAndMetadata(i + 24, j + 6, k + 6, Block.planks.blockID, 1);
		world.setBlockAndMetadata(i + 24, j + 6, k + 7, Block.planks.blockID, 1);
		world.setBlockAndMetadata(i + 24, j + 6, k + 8, Block.planks.blockID, 1);
		world.setBlockAndMetadata(i + 24, j + 6, k + 9, Block.planks.blockID, 1);
		world.setBlockAndMetadata(i + 24, j + 6, k + 10, Block.planks.blockID, 1);
		world.setBlockAndMetadata(i + 24, j + 7, k + 6, Block.planks.blockID, 1);
		world.setBlock(i + 24, j + 7, k + 7, Block.fence.blockID);
		world.setBlock(i + 24, j + 7, k + 8, Block.fence.blockID);
		world.setBlock(i + 24, j + 7, k + 9, Block.fence.blockID);
		world.setBlockAndMetadata(i + 24, j + 7, k + 10, Block.planks.blockID, 1);
		world.setBlockAndMetadata(i + 24, j + 8, k + 6, Block.planks.blockID, 1);
		world.setBlockAndMetadata(i + 24, j + 8, k + 7, Block.planks.blockID, 1);
		world.setBlockAndMetadata(i + 24, j + 8, k + 8, Block.planks.blockID, 1);
		world.setBlockAndMetadata(i + 24, j + 8, k + 9, Block.planks.blockID, 1);
		world.setBlockAndMetadata(i + 24, j + 8, k + 10, Block.planks.blockID, 1);
		world.setBlockAndMetadata(i + 24, j + 9, k + 5, Block.planks.blockID, 1);
		world.setBlockAndMetadata(i + 24, j + 9, k + 6, Block.cauldron.blockID, 3);
		world.setBlockAndMetadata(i + 24, j + 9, k + 10, Block.chest.blockID, 2);
		world.setBlockAndMetadata(i + 24, j + 9, k + 11, Block.planks.blockID, 1);
		world.setBlockAndMetadata(i + 24, j + 10, k + 5, Block.planks.blockID, 1);
		world.setBlockAndMetadata(i + 24, j + 10, k + 11, Block.planks.blockID, 1);
		world.setBlockAndMetadata(i + 24, j + 11, k + 5, Block.planks.blockID, 1);
		world.setBlockAndMetadata(i + 24, j + 11, k + 10, Block.chest.blockID, 2);
		world.setBlockAndMetadata(i + 24, j + 11, k + 11, Block.planks.blockID, 1);
		world.setBlockAndMetadata(i + 24, j + 12, k + 5, Block.planks.blockID, 1);
		world.setBlockAndMetadata(i + 24, j + 12, k + 6, Block.planks.blockID, 1);
		world.setBlockAndMetadata(i + 24, j + 12, k + 7, Block.planks.blockID, 1);
		world.setBlockAndMetadata(i + 24, j + 12, k + 8, Block.planks.blockID, 1);
		world.setBlockAndMetadata(i + 24, j + 12, k + 9, Block.planks.blockID, 1);
		world.setBlockAndMetadata(i + 24, j + 12, k + 10, Block.planks.blockID, 1);
		world.setBlockAndMetadata(i + 24, j + 12, k + 11, Block.planks.blockID, 1);
		world.setBlockAndMetadata(i + 24, j + 13, k + 4, Block.planks.blockID, 1);
		world.setBlockAndMetadata(i + 24, j + 13, k + 7, Block.stoneSingleSlab.blockID, 5);
		world.setBlock(i + 24, j + 13, k + 8, Block.stoneBrick.blockID);
		world.setBlockAndMetadata(i + 24, j + 13, k + 12, Block.planks.blockID, 1);
		world.setBlockAndMetadata(i + 24, j + 14, k + 4, Block.planks.blockID, 1);
		world.setBlockAndMetadata(i + 24, j + 14, k + 12, Block.planks.blockID, 1);
		world.setBlockAndMetadata(i + 24, j + 15, k + 4, Block.planks.blockID, 1);
		world.setBlockAndMetadata(i + 24, j + 15, k + 12, Block.planks.blockID, 1);
		world.setBlockAndMetadata(i + 24, j + 16, k + 3, Block.planks.blockID, 1);
		world.setBlockAndMetadata(i + 24, j + 16, k + 4, Block.planks.blockID, 1);
		world.setBlockAndMetadata(i + 24, j + 16, k + 5, Block.planks.blockID, 1);
		world.setBlockAndMetadata(i + 24, j + 16, k + 12, Block.planks.blockID, 1);
		world.setBlockAndMetadata(i + 24, j + 16, k + 13, Block.planks.blockID, 1);
		world.setBlock(i + 24, j + 17, k + 3, Block.obsidian.blockID);
		world.setBlockAndMetadata(i + 24, j + 17, k + 4, Block.planks.blockID, 1);
		world.setBlockAndMetadata(i + 24, j + 17, k + 5, Block.planks.blockID, 1);
		world.setBlockAndMetadata(i + 24, j + 17, k + 6, Block.planks.blockID, 1);
		world.setBlockAndMetadata(i + 24, j + 17, k + 7, Block.planks.blockID, 1);
		world.setBlockAndMetadata(i + 24, j + 17, k + 8, Block.planks.blockID, 1);
		world.setBlockAndMetadata(i + 24, j + 17, k + 9, Block.planks.blockID, 1);
		world.setBlockAndMetadata(i + 24, j + 17, k + 10, Block.planks.blockID, 1);
		world.setBlockAndMetadata(i + 24, j + 17, k + 11, Block.planks.blockID, 1);
		world.setBlockAndMetadata(i + 24, j + 17, k + 12, Block.planks.blockID, 1);
		world.setBlock(i + 24, j + 17, k + 13, Block.obsidian.blockID);
		world.setBlock(i + 24, j + 18, k + 4, Block.obsidian.blockID);
		world.setBlock(i + 24, j + 18, k + 6, Block.obsidian.blockID);
		world.setBlock(i + 24, j + 18, k + 10, Block.obsidian.blockID);
		world.setBlock(i + 24, j + 18, k + 12, Block.obsidian.blockID);
		world.setBlockAndMetadata(i + 25, j + 6, k + 6, Block.planks.blockID, 1);
		world.setBlockAndMetadata(i + 25, j + 6, k + 7, Block.planks.blockID, 1);
		world.setBlockAndMetadata(i + 25, j + 6, k + 8, Block.planks.blockID, 1);
		world.setBlockAndMetadata(i + 25, j + 6, k + 9, Block.planks.blockID, 1);
		world.setBlockAndMetadata(i + 25, j + 6, k + 10, Block.planks.blockID, 1);
		world.setBlockAndMetadata(i + 25, j + 7, k + 6, Block.planks.blockID, 1);
		world.setBlock(i + 25, j + 7, k + 8, Block.fence.blockID);
		world.setBlockAndMetadata(i + 25, j + 7, k + 10, Block.planks.blockID, 1);
		world.setBlockAndMetadata(i + 25, j + 8, k + 6, Block.planks.blockID, 1);
		world.setBlockAndMetadata(i + 25, j + 8, k + 7, Block.planks.blockID, 1);
		world.setBlockAndMetadata(i + 25, j + 8, k + 8, Block.planks.blockID, 1);
		world.setBlockAndMetadata(i + 25, j + 8, k + 9, Block.planks.blockID, 1);
		world.setBlockAndMetadata(i + 25, j + 8, k + 10, Block.planks.blockID, 1);
		world.setBlockAndMetadata(i + 25, j + 9, k + 5, Block.planks.blockID, 1);
		world.setBlock(i + 25, j + 9, k + 6, Block.blockSteel.blockID);
		world.setBlockAndMetadata(i + 25, j + 9, k + 10, Block.chest.blockID, 2);
		world.setBlockAndMetadata(i + 25, j + 9, k + 11, Block.planks.blockID, 1);
		world.setBlockAndMetadata(i + 25, j + 10, k + 5, Block.planks.blockID, 1);
		world.setBlockAndMetadata(i + 25, j + 10, k + 11, Block.planks.blockID, 1);
		world.setBlockAndMetadata(i + 25, j + 11, k + 5, Block.planks.blockID, 1);
		world.setBlockAndMetadata(i + 25, j + 11, k + 10, Block.chest.blockID, 2);
		world.setBlockAndMetadata(i + 25, j + 11, k + 11, Block.planks.blockID, 1);
		world.setBlockAndMetadata(i + 25, j + 12, k + 5, Block.planks.blockID, 1);
		world.setBlockAndMetadata(i + 25, j + 12, k + 6, Block.planks.blockID, 1);
		world.setBlockAndMetadata(i + 25, j + 12, k + 7, Block.planks.blockID, 1);
		world.setBlockAndMetadata(i + 25, j + 12, k + 8, Block.planks.blockID, 1);
		world.setBlockAndMetadata(i + 25, j + 12, k + 9, Block.planks.blockID, 1);
		world.setBlockAndMetadata(i + 25, j + 12, k + 10, Block.planks.blockID, 1);
		world.setBlockAndMetadata(i + 25, j + 12, k + 11, Block.planks.blockID, 1);
		world.setBlockAndMetadata(i + 25, j + 13, k + 4, Block.planks.blockID, 1);
		world.setBlockAndMetadata(i + 25, j + 13, k + 7, Block.stoneSingleSlab.blockID, 5);
		world.setBlock(i + 25, j + 13, k + 8, Block.stoneBrick.blockID);
		world.setBlockAndMetadata(i + 25, j + 13, k + 12, Block.planks.blockID, 1);
		world.setBlockAndMetadata(i + 25, j + 14, k + 4, Block.planks.blockID, 1);
		world.setBlockAndMetadata(i + 25, j + 14, k + 12, Block.planks.blockID, 1);
		world.setBlockAndMetadata(i + 25, j + 15, k + 4, Block.planks.blockID, 1);
		world.setBlockAndMetadata(i + 25, j + 15, k + 12, Block.planks.blockID, 1);
		world.setBlockAndMetadata(i + 25, j + 16, k + 2, Block.planks.blockID, 1);
		world.setBlockAndMetadata(i + 25, j + 16, k + 3, Block.planks.blockID, 1);
		world.setBlockAndMetadata(i + 25, j + 16, k + 13, Block.planks.blockID, 1);
		world.setBlockAndMetadata(i + 25, j + 16, k + 14, Block.planks.blockID, 1);
		world.setBlock(i + 25, j + 17, k + 2, Block.obsidian.blockID);
		world.setBlock(i + 25, j + 17, k + 3, Block.obsidian.blockID);
		world.setBlockAndMetadata(i + 25, j + 17, k + 4, Block.planks.blockID, 1);
		world.setBlockAndMetadata(i + 25, j + 17, k + 5, Block.planks.blockID, 1);
		world.setBlockAndMetadata(i + 25, j + 17, k + 6, Block.planks.blockID, 1);
		world.setBlockAndMetadata(i + 25, j + 17, k + 7, Block.planks.blockID, 1);
		world.setBlockAndMetadata(i + 25, j + 17, k + 8, Block.planks.blockID, 1);
		world.setBlockAndMetadata(i + 25, j + 17, k + 9, Block.planks.blockID, 1);
		world.setBlockAndMetadata(i + 25, j + 17, k + 10, Block.planks.blockID, 1);
		world.setBlockAndMetadata(i + 25, j + 17, k + 11, Block.planks.blockID, 1);
		world.setBlockAndMetadata(i + 25, j + 17, k + 12, Block.planks.blockID, 1);
		world.setBlock(i + 25, j + 17, k + 13, Block.obsidian.blockID);
		world.setBlock(i + 25, j + 17, k + 14, Block.obsidian.blockID);
		world.setBlock(i + 25, j + 18, k + 2, Block.fence.blockID);
		world.setBlock(i + 25, j + 18, k + 3, Block.fence.blockID);
		world.setBlock(i + 25, j + 18, k + 4, Block.obsidian.blockID);
		world.setBlock(i + 25, j + 18, k + 5, Block.obsidian.blockID);
		world.setBlock(i + 25, j + 18, k + 6, Block.obsidian.blockID);
		world.setBlock(i + 25, j + 18, k + 10, Block.obsidian.blockID);
		world.setBlock(i + 25, j + 18, k + 11, Block.obsidian.blockID);
		world.setBlock(i + 25, j + 18, k + 12, Block.obsidian.blockID);
		world.setBlock(i + 25, j + 18, k + 13, Block.fence.blockID);
		world.setBlock(i + 25, j + 18, k + 14, Block.fence.blockID);
		world.setBlockAndMetadata(i + 26, j + 6, k + 6, Block.planks.blockID, 1);
		world.setBlockAndMetadata(i + 26, j + 6, k + 7, Block.planks.blockID, 1);
		world.setBlockAndMetadata(i + 26, j + 6, k + 8, Block.planks.blockID, 1);
		world.setBlockAndMetadata(i + 26, j + 6, k + 9, Block.planks.blockID, 1);
		world.setBlockAndMetadata(i + 26, j + 6, k + 10, Block.planks.blockID, 1);
		world.setBlockAndMetadata(i + 26, j + 7, k + 6, Block.planks.blockID, 1);
		world.setBlock(i + 26, j + 7, k + 7, Block.fence.blockID);
		world.setBlock(i + 26, j + 7, k + 8, Block.fence.blockID);
		world.setBlock(i + 26, j + 7, k + 9, Block.fence.blockID);
		world.setBlockAndMetadata(i + 26, j + 7, k + 10, Block.planks.blockID, 1);
		world.setBlockAndMetadata(i + 26, j + 8, k + 6, Block.planks.blockID, 1);
		world.setBlockAndMetadata(i + 26, j + 8, k + 7, Block.planks.blockID, 1);
		world.setBlockAndMetadata(i + 26, j + 8, k + 8, Block.planks.blockID, 1);
		world.setBlockAndMetadata(i + 26, j + 8, k + 9, Block.planks.blockID, 1);
		world.setBlockAndMetadata(i + 26, j + 8, k + 10, Block.planks.blockID, 1);
		world.setBlockAndMetadata(i + 26, j + 9, k + 5, Block.planks.blockID, 1);
		world.setBlockAndMetadata(i + 26, j + 9, k + 11, Block.planks.blockID, 1);
		world.setBlockAndMetadata(i + 26, j + 10, k + 5, Block.planks.blockID, 1);
		world.setBlockAndMetadata(i + 26, j + 10, k + 11, Block.planks.blockID, 1);
		world.setBlockAndMetadata(i + 26, j + 11, k + 5, Block.planks.blockID, 1);
		world.setBlockAndMetadata(i + 26, j + 11, k + 11, Block.planks.blockID, 1);
		world.setBlockAndMetadata(i + 26, j + 12, k + 5, Block.planks.blockID, 1);
		world.setBlockAndMetadata(i + 26, j + 12, k + 6, Block.planks.blockID, 1);
		world.setBlockAndMetadata(i + 26, j + 12, k + 7, Block.planks.blockID, 1);
		world.setBlockAndMetadata(i + 26, j + 12, k + 8, Block.planks.blockID, 1);
		world.setBlockAndMetadata(i + 26, j + 12, k + 9, Block.planks.blockID, 1);
		world.setBlockAndMetadata(i + 26, j + 12, k + 10, Block.planks.blockID, 1);
		world.setBlockAndMetadata(i + 26, j + 12, k + 11, Block.planks.blockID, 1);
		world.setBlockAndMetadata(i + 26, j + 13, k + 3, Block.planks.blockID, 1);
		world.setBlockAndMetadata(i + 26, j + 13, k + 4, Block.planks.blockID, 1);
		world.setBlockAndMetadata(i + 26, j + 13, k + 7, Block.stoneSingleSlab.blockID, 5);
		world.setBlock(i + 26, j + 13, k + 8, Block.stoneBrick.blockID);
		world.setBlockAndMetadata(i + 26, j + 13, k + 12, Block.planks.blockID, 1);
		world.setBlockAndMetadata(i + 26, j + 13, k + 13, Block.planks.blockID, 1);
		world.setBlockAndMetadata(i + 26, j + 14, k + 3, Block.planks.blockID, 1);
		world.setBlockAndMetadata(i + 26, j + 14, k + 4, Block.planks.blockID, 1);
		world.setBlockAndMetadata(i + 26, j + 14, k + 12, Block.planks.blockID, 1);
		world.setBlockAndMetadata(i + 26, j + 14, k + 13, Block.planks.blockID, 1);
		world.setBlockAndMetadata(i + 26, j + 15, k + 3, Block.planks.blockID, 1);
		world.setBlockAndMetadata(i + 26, j + 15, k + 4, Block.planks.blockID, 1);
		world.setBlockAndMetadata(i + 26, j + 15, k + 12, Block.planks.blockID, 1);
		world.setBlockAndMetadata(i + 26, j + 15, k + 13, Block.planks.blockID, 1);
		world.setBlockAndMetadata(i + 26, j + 16, k + 2, Block.planks.blockID, 1);
		world.setBlockAndMetadata(i + 26, j + 16, k + 14, Block.planks.blockID, 1);
		world.setBlock(i + 26, j + 17, k + 2, Block.obsidian.blockID);
		world.setBlockAndMetadata(i + 26, j + 17, k + 3, Block.planks.blockID, 1);
		world.setBlockAndMetadata(i + 26, j + 17, k + 4, Block.planks.blockID, 1);
		world.setBlockAndMetadata(i + 26, j + 17, k + 5, Block.planks.blockID, 1);
		world.setBlockAndMetadata(i + 26, j + 17, k + 6, Block.planks.blockID, 1);
		world.setBlockAndMetadata(i + 26, j + 17, k + 7, Block.planks.blockID, 1);
		world.setBlockAndMetadata(i + 26, j + 17, k + 8, Block.planks.blockID, 1);
		world.setBlockAndMetadata(i + 26, j + 17, k + 9, Block.planks.blockID, 1);
		world.setBlockAndMetadata(i + 26, j + 17, k + 10, Block.planks.blockID, 1);
		world.setBlockAndMetadata(i + 26, j + 17, k + 11, Block.planks.blockID, 1);
		world.setBlockAndMetadata(i + 26, j + 17, k + 12, Block.planks.blockID, 1);
		world.setBlockAndMetadata(i + 26, j + 17, k + 13, Block.planks.blockID, 1);
		world.setBlock(i + 26, j + 17, k + 14, Block.obsidian.blockID);
		world.setBlock(i + 26, j + 18, k + 2, Block.fence.blockID);
		world.setBlockAndMetadata(i + 26, j + 18, k + 3, Block.chest.blockID, 3);
		world.setBlockAndMetadata(i + 26, j + 18, k + 13, Block.chest.blockID, 2);
		world.setBlock(i + 26, j + 18, k + 14, Block.fence.blockID);
		world.setBlockAndMetadata(i + 27, j + 6, k + 6, Block.planks.blockID, 1);
		world.setBlockAndMetadata(i + 27, j + 6, k + 7, Block.planks.blockID, 1);
		world.setBlockAndMetadata(i + 27, j + 6, k + 8, Block.planks.blockID, 1);
		world.setBlockAndMetadata(i + 27, j + 6, k + 9, Block.planks.blockID, 1);
		world.setBlockAndMetadata(i + 27, j + 6, k + 10, Block.planks.blockID, 1);
		world.setBlockAndMetadata(i + 27, j + 7, k + 6, Block.planks.blockID, 1);
		world.setBlock(i + 27, j + 7, k + 8, Block.fence.blockID);
		world.setBlockAndMetadata(i + 27, j + 7, k + 10, Block.planks.blockID, 1);
		world.setBlockAndMetadata(i + 27, j + 8, k + 6, Block.planks.blockID, 1);
		world.setBlockAndMetadata(i + 27, j + 8, k + 7, Block.planks.blockID, 1);
		world.setBlockAndMetadata(i + 27, j + 8, k + 8, Block.planks.blockID, 1);
		world.setBlockAndMetadata(i + 27, j + 8, k + 9, Block.planks.blockID, 1);
		world.setBlockAndMetadata(i + 27, j + 8, k + 10, Block.planks.blockID, 1);
		world.setBlockAndMetadata(i + 27, j + 9, k + 4, Block.planks.blockID, 1);
		world.setBlockAndMetadata(i + 27, j + 9, k + 5, Block.planks.blockID, 1);
		world.setBlockAndMetadata(i + 27, j + 9, k + 11, Block.planks.blockID, 1);
		world.setBlockAndMetadata(i + 27, j + 9, k + 12, Block.planks.blockID, 1);
		world.setBlockAndMetadata(i + 27, j + 10, k + 4, Block.planks.blockID, 1);
		world.setBlockAndMetadata(i + 27, j + 10, k + 5, Block.planks.blockID, 1);
		world.setBlockAndMetadata(i + 27, j + 10, k + 11, Block.planks.blockID, 1);
		world.setBlockAndMetadata(i + 27, j + 10, k + 12, Block.planks.blockID, 1);
		world.setBlockAndMetadata(i + 27, j + 11, k + 4, Block.planks.blockID, 1);
		world.setBlockAndMetadata(i + 27, j + 11, k + 5, Block.planks.blockID, 1);
		world.setBlockAndMetadata(i + 27, j + 11, k + 11, Block.planks.blockID, 1);
		world.setBlockAndMetadata(i + 27, j + 11, k + 12, Block.planks.blockID, 1);
		world.setBlockAndMetadata(i + 27, j + 12, k + 4, Block.planks.blockID, 1);
		world.setBlockAndMetadata(i + 27, j + 12, k + 5, Block.planks.blockID, 1);
		world.setBlockAndMetadata(i + 27, j + 12, k + 6, Block.planks.blockID, 1);
		world.setBlockAndMetadata(i + 27, j + 12, k + 7, Block.planks.blockID, 1);
		world.setBlockAndMetadata(i + 27, j + 12, k + 8, Block.planks.blockID, 1);
		world.setBlockAndMetadata(i + 27, j + 12, k + 9, Block.planks.blockID, 1);
		world.setBlockAndMetadata(i + 27, j + 12, k + 10, Block.planks.blockID, 1);
		world.setBlockAndMetadata(i + 27, j + 12, k + 11, Block.planks.blockID, 1);
		world.setBlockAndMetadata(i + 27, j + 12, k + 12, Block.planks.blockID, 1);
		world.setBlockAndMetadata(i + 27, j + 13, k + 3, Block.planks.blockID, 1);
		world.setBlock(i + 27, j + 13, k + 8, Block.stoneBrick.blockID);
		world.setBlock(i + 27, j + 13, k + 9, Block.stoneBrick.blockID);
		world.setBlock(i + 27, j + 13, k + 10, Block.planks.blockID);
		world.setBlockAndMetadata(i + 27, j + 13, k + 12, Block.planks.blockID, 1);
		world.setBlockAndMetadata(i + 27, j + 13, k + 13, Block.planks.blockID, 1);
		world.setBlockAndMetadata(i + 27, j + 14, k + 3, Block.planks.blockID, 1);
		world.setBlockAndMetadata(i + 27, j + 14, k + 13, Block.planks.blockID, 1);
		world.setBlockAndMetadata(i + 27, j + 15, k + 3, Block.planks.blockID, 1);
		world.setBlockAndMetadata(i + 27, j + 15, k + 13, Block.planks.blockID, 1);
		world.setBlockAndMetadata(i + 27, j + 16, k + 2, Block.planks.blockID, 1);
		world.setBlockAndMetadata(i + 27, j + 16, k + 14, Block.planks.blockID, 1);
		world.setBlock(i + 27, j + 17, k + 2, Block.obsidian.blockID);
		world.setBlockAndMetadata(i + 27, j + 17, k + 3, Block.planks.blockID, 1);
		world.setBlockAndMetadata(i + 27, j + 17, k + 4, Block.planks.blockID, 1);
		world.setBlockAndMetadata(i + 27, j + 17, k + 5, Block.planks.blockID, 1);
		world.setBlockAndMetadata(i + 27, j + 17, k + 6, Block.planks.blockID, 1);
		world.setBlockAndMetadata(i + 27, j + 17, k + 7, Block.planks.blockID, 1);
		world.setBlockAndMetadata(i + 27, j + 17, k + 8, Block.planks.blockID, 1);
		world.setBlockAndMetadata(i + 27, j + 17, k + 9, Block.planks.blockID, 1);
		world.setBlockAndMetadata(i + 27, j + 17, k + 10, Block.planks.blockID, 1);
		world.setBlockAndMetadata(i + 27, j + 17, k + 11, Block.planks.blockID, 1);
		world.setBlockAndMetadata(i + 27, j + 17, k + 12, Block.planks.blockID, 1);
		world.setBlockAndMetadata(i + 27, j + 17, k + 13, Block.planks.blockID, 1);
		world.setBlock(i + 27, j + 17, k + 14, Block.obsidian.blockID);
		world.setBlock(i + 27, j + 18, k + 2, Block.fence.blockID);
		world.setBlockAndMetadata(i + 27, j + 18, k + 3, Block.chest.blockID, 3);
		world.setBlockAndMetadata(i + 27, j + 18, k + 13, Block.chest.blockID, 2);
		world.setBlock(i + 27, j + 18, k + 14, Block.fence.blockID);
		world.setBlockAndMetadata(i + 28, j + 6, k + 5, Block.planks.blockID, 1);
		world.setBlockAndMetadata(i + 28, j + 6, k + 6, Block.planks.blockID, 1);
		world.setBlockAndMetadata(i + 28, j + 6, k + 7, Block.planks.blockID, 1);
		world.setBlockAndMetadata(i + 28, j + 6, k + 8, Block.planks.blockID, 1);
		world.setBlockAndMetadata(i + 28, j + 6, k + 9, Block.planks.blockID, 1);
		world.setBlockAndMetadata(i + 28, j + 6, k + 10, Block.planks.blockID, 1);
		world.setBlockAndMetadata(i + 28, j + 6, k + 11, Block.planks.blockID, 1);
		world.setBlockAndMetadata(i + 28, j + 7, k + 5, Block.planks.blockID, 1);
		world.setBlockAndMetadata(i + 28, j + 7, k + 6, Block.planks.blockID, 1);
		world.setBlock(i + 28, j + 7, k + 8, Block.fence.blockID);
		world.setBlockAndMetadata(i + 28, j + 7, k + 10, Block.planks.blockID, 1);
		world.setBlockAndMetadata(i + 28, j + 7, k + 11, Block.planks.blockID, 1);
		world.setBlockAndMetadata(i + 28, j + 8, k + 5, Block.planks.blockID, 1);
		world.setBlockAndMetadata(i + 28, j + 8, k + 6, Block.planks.blockID, 1);
		world.setBlockAndMetadata(i + 28, j + 8, k + 7, Block.planks.blockID, 1);
		world.setBlockAndMetadata(i + 28, j + 8, k + 8, Block.planks.blockID, 1);
		world.setBlockAndMetadata(i + 28, j + 8, k + 9, Block.planks.blockID, 1);
		world.setBlockAndMetadata(i + 28, j + 8, k + 10, Block.planks.blockID, 1);
		world.setBlockAndMetadata(i + 28, j + 8, k + 11, Block.planks.blockID, 1);
		world.setBlockAndMetadata(i + 28, j + 9, k + 4, Block.planks.blockID, 1);
		world.setBlockAndMetadata(i + 28, j + 9, k + 8, Block.stairCompactPlanks.blockID, 1);
		world.setBlockAndMetadata(i + 28, j + 9, k + 9, Block.stairCompactPlanks.blockID, 1);
		world.setBlockAndMetadata(i + 28, j + 9, k + 12, Block.planks.blockID, 1);
		world.setBlockAndMetadata(i + 28, j + 10, k + 4, Block.planks.blockID, 1);
		world.setBlockAndMetadata(i + 28, j + 10, k + 12, Block.planks.blockID, 1);
		world.setBlockAndMetadata(i + 28, j + 11, k + 4, Block.planks.blockID, 1);
		world.setBlockAndMetadata(i + 28, j + 11, k + 12, Block.planks.blockID, 1);
		world.setBlockAndMetadata(i + 28, j + 12, k + 4, Block.planks.blockID, 1);
		world.setBlockAndMetadata(i + 28, j + 12, k + 5, Block.planks.blockID, 1);
		world.setBlockAndMetadata(i + 28, j + 12, k + 6, Block.planks.blockID, 1);
		world.setBlockAndMetadata(i + 28, j + 12, k + 7, Block.planks.blockID, 1);
		world.setBlockAndMetadata(i + 28, j + 12, k + 8, Block.planks.blockID, 1);
		world.setBlockAndMetadata(i + 28, j + 12, k + 9, Block.planks.blockID, 1);
		world.setBlockAndMetadata(i + 28, j + 12, k + 10, Block.planks.blockID, 1);
		world.setBlockAndMetadata(i + 28, j + 12, k + 11, Block.planks.blockID, 1);
		world.setBlockAndMetadata(i + 28, j + 12, k + 12, Block.planks.blockID, 1);
		world.setBlockAndMetadata(i + 28, j + 13, k + 3, Block.planks.blockID, 1);
		world.setBlockAndMetadata(i + 28, j + 13, k + 4, Block.planks.blockID, 2);
		world.setBlockAndMetadata(i + 28, j + 13, k + 7, Block.planks.blockID, 2);
		world.setBlockAndMetadata(i + 28, j + 13, k + 8, Block.planks.blockID, 2);
		world.setBlockAndMetadata(i + 28, j + 13, k + 9, Block.planks.blockID, 2);
		world.setBlockAndMetadata(i + 28, j + 13, k + 11, Block.planks.blockID, 1);
		world.setBlockAndMetadata(i + 28, j + 13, k + 12, Block.planks.blockID, 1);
		world.setBlockAndMetadata(i + 28, j + 13, k + 13, Block.planks.blockID, 1);
		world.setBlockAndMetadata(i + 28, j + 14, k + 3, Block.planks.blockID, 1);
		world.setBlockAndMetadata(i + 28, j + 14, k + 4, Block.planks.blockID, 2);
		world.setBlockAndMetadata(i + 28, j + 14, k + 7, Block.planks.blockID, 2);
		world.setBlockAndMetadata(i + 28, j + 14, k + 8, Block.planks.blockID, 2);
		world.setBlockAndMetadata(i + 28, j + 14, k + 9, Block.planks.blockID, 2);
		world.setBlockAndMetadata(i + 28, j + 14, k + 10, Block.planks.blockID, 2);
		world.setBlockAndMetadata(i + 28, j + 14, k + 11, Block.planks.blockID, 1);
		world.setBlockAndMetadata(i + 28, j + 14, k + 12, Block.planks.blockID, 1);
		world.setBlockAndMetadata(i + 28, j + 14, k + 13, Block.planks.blockID, 1);
		world.setBlockAndMetadata(i + 28, j + 15, k + 3, Block.planks.blockID, 1);
		world.setBlockAndMetadata(i + 28, j + 15, k + 4, Block.planks.blockID, 2);
		world.setBlockAndMetadata(i + 28, j + 15, k + 5, Block.planks.blockID, 2);
		world.setBlockAndMetadata(i + 28, j + 15, k + 6, Block.planks.blockID, 2);
		world.setBlockAndMetadata(i + 28, j + 15, k + 7, Block.planks.blockID, 2);
		world.setBlockAndMetadata(i + 28, j + 15, k + 8, Block.planks.blockID, 2);
		world.setBlockAndMetadata(i + 28, j + 15, k + 9, Block.planks.blockID, 2);
		world.setBlockAndMetadata(i + 28, j + 15, k + 11, Block.pistonBase.blockID, 11);
		world.setBlockAndMetadata(i + 28, j + 15, k + 12, Block.pistonExtension.blockID, 3);
		world.setBlockAndMetadata(i + 28, j + 15, k + 13, Block.planks.blockID, 1);
		world.setBlockAndMetadata(i + 28, j + 16, k + 2, Block.planks.blockID, 1);
		world.setBlockAndMetadata(i + 28, j + 16, k + 4, Block.planks.blockID, 2);
		world.setBlockAndMetadata(i + 28, j + 16, k + 5, Block.planks.blockID, 2);
		world.setBlockAndMetadata(i + 28, j + 16, k + 6, Block.planks.blockID, 2);
		world.setBlockAndMetadata(i + 28, j + 16, k + 7, Block.planks.blockID, 2);
		world.setBlockAndMetadata(i + 28, j + 16, k + 8, Block.planks.blockID, 2);
		world.setBlockAndMetadata(i + 28, j + 16, k + 9, Block.planks.blockID, 2);
		world.setBlockAndMetadata(i + 28, j + 16, k + 10, Block.planks.blockID, 2);
		world.setBlockAndMetadata(i + 28, j + 16, k + 11, Block.planks.blockID, 2);
		world.setBlockAndMetadata(i + 28, j + 16, k + 12, Block.planks.blockID, 2);
		world.setBlockAndMetadata(i + 28, j + 16, k + 14, Block.planks.blockID, 1);
		world.setBlock(i + 28, j + 17, k + 2, Block.obsidian.blockID);
		world.setBlockAndMetadata(i + 28, j + 17, k + 3, Block.planks.blockID, 1);
		world.setBlockAndMetadata(i + 28, j + 17, k + 4, Block.planks.blockID, 1);
		world.setBlockAndMetadata(i + 28, j + 17, k + 5, Block.planks.blockID, 1);
		world.setBlockAndMetadata(i + 28, j + 17, k + 6, Block.planks.blockID, 1);
		world.setBlockAndMetadata(i + 28, j + 17, k + 7, Block.planks.blockID, 1);
		world.setBlockAndMetadata(i + 28, j + 17, k + 8, Block.planks.blockID, 1);
		world.setBlockAndMetadata(i + 28, j + 17, k + 9, Block.planks.blockID, 1);
		world.setBlockAndMetadata(i + 28, j + 17, k + 10, Block.planks.blockID, 1);
		world.setBlockAndMetadata(i + 28, j + 17, k + 11, Block.planks.blockID, 1);
		world.setBlockAndMetadata(i + 28, j + 17, k + 12, Block.planks.blockID, 1);
		world.setBlockAndMetadata(i + 28, j + 17, k + 13, Block.planks.blockID, 1);
		world.setBlock(i + 28, j + 17, k + 14, Block.obsidian.blockID);
		world.setBlock(i + 28, j + 18, k + 2, Block.fence.blockID);
		world.setBlock(i + 28, j + 18, k + 14, Block.fence.blockID);
		world.setBlockAndMetadata(i + 29, j + 6, k + 5, Block.planks.blockID, 1);
		world.setBlockAndMetadata(i + 29, j + 6, k + 6, Block.planks.blockID, 1);
		world.setBlockAndMetadata(i + 29, j + 6, k + 7, Block.planks.blockID, 1);
		world.setBlockAndMetadata(i + 29, j + 6, k + 8, Block.planks.blockID, 1);
		world.setBlockAndMetadata(i + 29, j + 6, k + 9, Block.planks.blockID, 1);
		world.setBlockAndMetadata(i + 29, j + 6, k + 10, Block.planks.blockID, 1);
		world.setBlockAndMetadata(i + 29, j + 6, k + 11, Block.planks.blockID, 1);
		world.setBlockAndMetadata(i + 29, j + 7, k + 5, Block.planks.blockID, 1);
		world.setBlock(i + 29, j + 7, k + 6, Block.fence.blockID);
		world.setBlock(i + 29, j + 7, k + 7, Block.fence.blockID);
		world.setBlock(i + 29, j + 7, k + 8, Block.fence.blockID);
		world.setBlock(i + 29, j + 7, k + 9, Block.fence.blockID);
		world.setBlock(i + 29, j + 7, k + 10, Block.fence.blockID);
		world.setBlockAndMetadata(i + 29, j + 7, k + 11, Block.planks.blockID, 1);
		world.setBlockAndMetadata(i + 29, j + 8, k + 5, Block.planks.blockID, 1);
		world.setBlockAndMetadata(i + 29, j + 8, k + 6, Block.planks.blockID, 1);
		world.setBlockAndMetadata(i + 29, j + 8, k + 7, Block.planks.blockID, 1);
		world.setBlockAndMetadata(i + 29, j + 8, k + 8, Block.planks.blockID, 1);
		world.setBlockAndMetadata(i + 29, j + 8, k + 9, Block.planks.blockID, 1);
		world.setBlockAndMetadata(i + 29, j + 8, k + 10, Block.planks.blockID, 1);
		world.setBlockAndMetadata(i + 29, j + 8, k + 11, Block.planks.blockID, 1);
		world.setBlockAndMetadata(i + 29, j + 9, k + 4, Block.planks.blockID, 1);
		world.setBlockAndMetadata(i + 29, j + 9, k + 7, Block.stairCompactPlanks.blockID, 3);
		world.setBlockAndMetadata(i + 29, j + 9, k + 8, Block.cloth.blockID, 2);
		world.setBlockAndMetadata(i + 29, j + 9, k + 9, Block.cloth.blockID, 2);
		world.setBlockAndMetadata(i + 29, j + 9, k + 10, Block.stairCompactPlanks.blockID, 2);
		world.setBlockAndMetadata(i + 29, j + 9, k + 12, Block.planks.blockID, 1);
		world.setBlockAndMetadata(i + 29, j + 10, k + 4, Block.planks.blockID, 1);
		world.setBlockAndMetadata(i + 29, j + 10, k + 12, Block.planks.blockID, 1);
		world.setBlockAndMetadata(i + 29, j + 11, k + 4, Block.planks.blockID, 1);
		world.setBlockAndMetadata(i + 29, j + 11, k + 12, Block.planks.blockID, 1);
		world.setBlockAndMetadata(i + 29, j + 12, k + 4, Block.planks.blockID, 1);
		world.setBlockAndMetadata(i + 29, j + 12, k + 5, Block.planks.blockID, 1);
		world.setBlockAndMetadata(i + 29, j + 12, k + 6, Block.planks.blockID, 1);
		world.setBlockAndMetadata(i + 29, j + 12, k + 7, Block.planks.blockID, 1);
		world.setBlockAndMetadata(i + 29, j + 12, k + 8, Block.planks.blockID, 1);
		world.setBlockAndMetadata(i + 29, j + 12, k + 9, Block.planks.blockID, 1);
		world.setBlockAndMetadata(i + 29, j + 12, k + 10, Block.planks.blockID, 1);
		world.setBlockAndMetadata(i + 29, j + 12, k + 11, Block.planks.blockID, 1);
		world.setBlockAndMetadata(i + 29, j + 12, k + 12, Block.planks.blockID, 1);
		world.setBlockAndMetadata(i + 29, j + 13, k + 3, Block.planks.blockID, 1);
		world.setBlockAndMetadata(i + 29, j + 13, k + 10, Block.stoneOvenIdle.blockID, 2);
		world.setBlockAndMetadata(i + 29, j + 13, k + 13, Block.planks.blockID, 1);
		world.setBlockAndMetadata(i + 29, j + 14, k + 3, Block.planks.blockID, 1);
		world.setBlockAndMetadata(i + 29, j + 14, k + 10, Block.stoneOvenIdle.blockID, 2);
		world.setBlockAndMetadata(i + 29, j + 14, k + 13, Block.planks.blockID, 1);
		world.setBlockAndMetadata(i + 29, j + 15, k + 3, Block.planks.blockID, 1);
		world.setBlockAndMetadata(i + 29, j + 15, k + 10, Block.stoneOvenIdle.blockID, 2);
		world.setBlockAndMetadata(i + 29, j + 15, k + 13, Block.planks.blockID, 1);
		world.setBlockAndMetadata(i + 29, j + 16, k + 1, Block.planks.blockID, 1);
		world.setBlockAndMetadata(i + 29, j + 16, k + 2, Block.planks.blockID, 1);
		world.setBlockAndMetadata(i + 29, j + 16, k + 14, Block.planks.blockID, 1);
		world.setBlockAndMetadata(i + 29, j + 16, k + 15, Block.planks.blockID, 1);
		world.setBlock(i + 29, j + 17, k + 1, Block.obsidian.blockID);
		world.setBlock(i + 29, j + 17, k + 2, Block.obsidian.blockID);
		world.setBlockAndMetadata(i + 29, j + 17, k + 3, Block.planks.blockID, 1);
		world.setBlockAndMetadata(i + 29, j + 17, k + 4, Block.planks.blockID, 1);
		world.setBlockAndMetadata(i + 29, j + 17, k + 5, Block.planks.blockID, 1);
		world.setBlockAndMetadata(i + 29, j + 17, k + 6, Block.planks.blockID, 1);
		world.setBlockAndMetadata(i + 29, j + 17, k + 7, Block.planks.blockID, 1);
		world.setBlockAndMetadata(i + 29, j + 17, k + 8, Block.planks.blockID, 1);
		world.setBlockAndMetadata(i + 29, j + 17, k + 9, Block.planks.blockID, 1);
		world.setBlockAndMetadata(i + 29, j + 17, k + 10, Block.planks.blockID, 1);
		world.setBlockAndMetadata(i + 29, j + 17, k + 11, Block.planks.blockID, 1);
		world.setBlockAndMetadata(i + 29, j + 17, k + 12, Block.planks.blockID, 1);
		world.setBlockAndMetadata(i + 29, j + 17, k + 13, Block.planks.blockID, 1);
		world.setBlock(i + 29, j + 17, k + 14, Block.obsidian.blockID);
		world.setBlock(i + 29, j + 17, k + 15, Block.obsidian.blockID);
		world.setBlock(i + 29, j + 18, k + 1, Block.fence.blockID);
		world.setBlock(i + 29, j + 18, k + 2, Block.fence.blockID);
		world.setBlock(i + 29, j + 18, k + 14, Block.fence.blockID);
		world.setBlock(i + 29, j + 18, k + 15, Block.fence.blockID);
		world.setBlockAndMetadata(i + 30, j + 6, k + 5, Block.planks.blockID, 1);
		world.setBlockAndMetadata(i + 30, j + 6, k + 6, Block.planks.blockID, 1);
		world.setBlockAndMetadata(i + 30, j + 6, k + 7, Block.planks.blockID, 1);
		world.setBlockAndMetadata(i + 30, j + 6, k + 8, Block.planks.blockID, 1);
		world.setBlockAndMetadata(i + 30, j + 6, k + 9, Block.planks.blockID, 1);
		world.setBlockAndMetadata(i + 30, j + 6, k + 10, Block.planks.blockID, 1);
		world.setBlockAndMetadata(i + 30, j + 6, k + 11, Block.planks.blockID, 1);
		world.setBlockAndMetadata(i + 30, j + 7, k + 5, Block.planks.blockID, 1);
		world.setBlock(i + 30, j + 7, k + 6, Block.fence.blockID);
		world.setBlock(i + 30, j + 7, k + 8, Block.fence.blockID);
		world.setBlock(i + 30, j + 7, k + 10, Block.fence.blockID);
		world.setBlockAndMetadata(i + 30, j + 7, k + 11, Block.planks.blockID, 1);
		world.setBlockAndMetadata(i + 30, j + 8, k + 5, Block.planks.blockID, 1);
		world.setBlockAndMetadata(i + 30, j + 8, k + 6, Block.planks.blockID, 1);
		world.setBlockAndMetadata(i + 30, j + 8, k + 7, Block.planks.blockID, 1);
		world.setBlockAndMetadata(i + 30, j + 8, k + 8, Block.planks.blockID, 1);
		world.setBlockAndMetadata(i + 30, j + 8, k + 9, Block.planks.blockID, 1);
		world.setBlockAndMetadata(i + 30, j + 8, k + 10, Block.planks.blockID, 1);
		world.setBlockAndMetadata(i + 30, j + 8, k + 11, Block.planks.blockID, 1);
		world.setBlockAndMetadata(i + 30, j + 9, k + 4, Block.planks.blockID, 1);
		world.setBlockAndMetadata(i + 30, j + 9, k + 7, Block.stairCompactPlanks.blockID, 3);
		world.setBlockAndMetadata(i + 30, j + 9, k + 8, Block.cloth.blockID, 2);
		world.setBlockAndMetadata(i + 30, j + 9, k + 9, Block.cloth.blockID, 2);
		world.setBlockAndMetadata(i + 30, j + 9, k + 10, Block.stairCompactPlanks.blockID, 2);
		world.setBlockAndMetadata(i + 30, j + 9, k + 12, Block.planks.blockID, 1);
		world.setBlockAndMetadata(i + 30, j + 10, k + 4, Block.planks.blockID, 1);
		world.setBlockAndMetadata(i + 30, j + 10, k + 12, Block.planks.blockID, 1);
		world.setBlockAndMetadata(i + 30, j + 11, k + 4, Block.planks.blockID, 1);
		world.setBlockAndMetadata(i + 30, j + 11, k + 12, Block.planks.blockID, 1);
		world.setBlockAndMetadata(i + 30, j + 12, k + 4, Block.planks.blockID, 1);
		world.setBlockAndMetadata(i + 30, j + 12, k + 5, Block.planks.blockID, 1);
		world.setBlockAndMetadata(i + 30, j + 12, k + 6, Block.planks.blockID, 1);
		world.setBlockAndMetadata(i + 30, j + 12, k + 7, Block.planks.blockID, 1);
		world.setBlockAndMetadata(i + 30, j + 12, k + 8, Block.planks.blockID, 1);
		world.setBlockAndMetadata(i + 30, j + 12, k + 9, Block.planks.blockID, 1);
		world.setBlockAndMetadata(i + 30, j + 12, k + 10, Block.planks.blockID, 1);
		world.setBlockAndMetadata(i + 30, j + 12, k + 11, Block.planks.blockID, 1);
		world.setBlockAndMetadata(i + 30, j + 12, k + 12, Block.planks.blockID, 1);
		world.setBlockAndMetadata(i + 30, j + 13, k + 2, Block.planks.blockID, 1);
		world.setBlockAndMetadata(i + 30, j + 13, k + 3, Block.planks.blockID, 1);
		world.setBlockAndMetadata(i + 30, j + 13, k + 10, Block.stoneOvenIdle.blockID, 2);
		world.setBlockAndMetadata(i + 30, j + 13, k + 13, Block.planks.blockID, 1);
		world.setBlockAndMetadata(i + 30, j + 13, k + 14, Block.planks.blockID, 1);
		world.setBlockAndMetadata(i + 30, j + 14, k + 2, Block.planks.blockID, 1);
		world.setBlockAndMetadata(i + 30, j + 14, k + 3, Block.planks.blockID, 1);
		world.setBlockAndMetadata(i + 30, j + 14, k + 10, Block.stoneOvenIdle.blockID, 2);
		world.setBlockAndMetadata(i + 30, j + 14, k + 13, Block.planks.blockID, 1);
		world.setBlockAndMetadata(i + 30, j + 14, k + 14, Block.planks.blockID, 1);
		world.setBlockAndMetadata(i + 30, j + 15, k + 2, Block.planks.blockID, 1);
		world.setBlockAndMetadata(i + 30, j + 15, k + 3, Block.planks.blockID, 1);
		world.setBlockAndMetadata(i + 30, j + 15, k + 10, Block.stoneOvenIdle.blockID, 2);
		world.setBlockAndMetadata(i + 30, j + 15, k + 13, Block.planks.blockID, 1);
		world.setBlockAndMetadata(i + 30, j + 15, k + 14, Block.planks.blockID, 1);
		world.setBlockAndMetadata(i + 30, j + 16, k + 1, Block.planks.blockID, 1);
		world.setBlockAndMetadata(i + 30, j + 16, k + 15, Block.planks.blockID, 1);
		world.setBlock(i + 30, j + 17, k + 1, Block.obsidian.blockID);
		world.setBlockAndMetadata(i + 30, j + 17, k + 2, Block.planks.blockID, 1);
		world.setBlockAndMetadata(i + 30, j + 17, k + 3, Block.planks.blockID, 1);
		world.setBlockAndMetadata(i + 30, j + 17, k + 4, Block.planks.blockID, 1);
		world.setBlockAndMetadata(i + 30, j + 17, k + 5, Block.planks.blockID, 1);
		world.setBlockAndMetadata(i + 30, j + 17, k + 6, Block.planks.blockID, 1);
		world.setBlockAndMetadata(i + 30, j + 17, k + 7, Block.planks.blockID, 1);
		world.setBlockAndMetadata(i + 30, j + 17, k + 8, Block.planks.blockID, 1);
		world.setBlockAndMetadata(i + 30, j + 17, k + 9, Block.planks.blockID, 1);
		world.setBlockAndMetadata(i + 30, j + 17, k + 10, Block.planks.blockID, 1);
		world.setBlockAndMetadata(i + 30, j + 17, k + 11, Block.planks.blockID, 1);
		world.setBlockAndMetadata(i + 30, j + 17, k + 12, Block.planks.blockID, 1);
		world.setBlockAndMetadata(i + 30, j + 17, k + 13, Block.planks.blockID, 1);
		world.setBlockAndMetadata(i + 30, j + 17, k + 14, Block.planks.blockID, 1);
		world.setBlock(i + 30, j + 17, k + 15, Block.obsidian.blockID);
		world.setBlock(i + 30, j + 18, k + 1, Block.fence.blockID);
		world.setBlock(i + 30, j + 18, k + 15, Block.fence.blockID);
		world.setBlockAndMetadata(i + 31, j + 6, k + 5, Block.planks.blockID, 1);
		world.setBlockAndMetadata(i + 31, j + 6, k + 6, Block.planks.blockID, 1);
		world.setBlockAndMetadata(i + 31, j + 6, k + 7, Block.planks.blockID, 1);
		world.setBlockAndMetadata(i + 31, j + 6, k + 8, Block.planks.blockID, 1);
		world.setBlockAndMetadata(i + 31, j + 6, k + 9, Block.planks.blockID, 1);
		world.setBlockAndMetadata(i + 31, j + 6, k + 10, Block.planks.blockID, 1);
		world.setBlockAndMetadata(i + 31, j + 6, k + 11, Block.planks.blockID, 1);
		world.setBlockAndMetadata(i + 31, j + 7, k + 5, Block.planks.blockID, 1);
		world.setBlock(i + 31, j + 7, k + 6, Block.fence.blockID);
		world.setBlock(i + 31, j + 7, k + 8, Block.fence.blockID);
		world.setBlock(i + 31, j + 7, k + 10, Block.fence.blockID);
		world.setBlockAndMetadata(i + 31, j + 7, k + 11, Block.planks.blockID, 1);
		world.setBlockAndMetadata(i + 31, j + 8, k + 5, Block.planks.blockID, 1);
		world.setBlockAndMetadata(i + 31, j + 8, k + 6, Block.planks.blockID, 1);
		world.setBlockAndMetadata(i + 31, j + 8, k + 7, Block.planks.blockID, 1);
		world.setBlockAndMetadata(i + 31, j + 8, k + 8, Block.planks.blockID, 1);
		world.setBlockAndMetadata(i + 31, j + 8, k + 9, Block.planks.blockID, 1);
		world.setBlockAndMetadata(i + 31, j + 8, k + 10, Block.planks.blockID, 1);
		world.setBlockAndMetadata(i + 31, j + 8, k + 11, Block.planks.blockID, 1);
		world.setBlockAndMetadata(i + 31, j + 9, k + 3, Block.planks.blockID, 1);
		world.setBlockAndMetadata(i + 31, j + 9, k + 4, Block.planks.blockID, 1);
		world.setBlock(i + 31, j + 9, k + 8, Block.stairCompactPlanks.blockID);
		world.setBlock(i + 31, j + 9, k + 9, Block.stairCompactPlanks.blockID);
		world.setBlockAndMetadata(i + 31, j + 9, k + 12, Block.planks.blockID, 1);
		world.setBlockAndMetadata(i + 31, j + 9, k + 13, Block.planks.blockID, 1);
		world.setBlockAndMetadata(i + 31, j + 10, k + 3, Block.planks.blockID, 1);
		world.setBlockAndMetadata(i + 31, j + 10, k + 4, Block.planks.blockID, 1);
		world.setBlockAndMetadata(i + 31, j + 10, k + 12, Block.planks.blockID, 1);
		world.setBlockAndMetadata(i + 31, j + 10, k + 13, Block.planks.blockID, 1);
		world.setBlockAndMetadata(i + 31, j + 11, k + 3, Block.planks.blockID, 1);
		world.setBlockAndMetadata(i + 31, j + 11, k + 4, Block.planks.blockID, 1);
		world.setBlockAndMetadata(i + 31, j + 11, k + 12, Block.planks.blockID, 1);
		world.setBlockAndMetadata(i + 31, j + 11, k + 13, Block.planks.blockID, 1);
		world.setBlockAndMetadata(i + 31, j + 12, k + 3, Block.planks.blockID, 1);
		world.setBlockAndMetadata(i + 31, j + 12, k + 4, Block.planks.blockID, 1);
		world.setBlockAndMetadata(i + 31, j + 12, k + 5, Block.planks.blockID, 1);
		world.setBlockAndMetadata(i + 31, j + 12, k + 6, Block.planks.blockID, 1);
		world.setBlockAndMetadata(i + 31, j + 12, k + 7, Block.planks.blockID, 1);
		world.setBlockAndMetadata(i + 31, j + 12, k + 8, Block.planks.blockID, 1);
		world.setBlockAndMetadata(i + 31, j + 12, k + 9, Block.planks.blockID, 1);
		world.setBlockAndMetadata(i + 31, j + 12, k + 10, Block.planks.blockID, 1);
		world.setBlockAndMetadata(i + 31, j + 12, k + 11, Block.planks.blockID, 1);
		world.setBlockAndMetadata(i + 31, j + 12, k + 12, Block.planks.blockID, 1);
		world.setBlockAndMetadata(i + 31, j + 12, k + 13, Block.planks.blockID, 1);
		world.setBlockAndMetadata(i + 31, j + 13, k + 2, Block.planks.blockID, 1);
		world.setBlockAndMetadata(i + 31, j + 13, k + 11, Block.planks.blockID, 1);
		world.setBlockAndMetadata(i + 31, j + 13, k + 12, Block.planks.blockID, 1);
		world.setBlockAndMetadata(i + 31, j + 13, k + 14, Block.planks.blockID, 1);
		world.setBlockAndMetadata(i + 31, j + 14, k + 2, Block.planks.blockID, 1);
		world.setBlockAndMetadata(i + 31, j + 14, k + 11, Block.planks.blockID, 1);
		world.setBlockAndMetadata(i + 31, j + 14, k + 12, Block.planks.blockID, 1);
		world.setBlockAndMetadata(i + 31, j + 14, k + 14, Block.planks.blockID, 1);
		world.setBlockAndMetadata(i + 31, j + 15, k + 2, Block.planks.blockID, 1);
		world.setBlock(i + 31, j + 15, k + 11, Block.planks.blockID);
		world.setBlock(i + 31, j + 15, k + 12, Block.planks.blockID);
		world.setBlockAndMetadata(i + 31, j + 15, k + 14, Block.planks.blockID, 1);
		world.setBlockAndMetadata(i + 31, j + 16, k + 1, Block.planks.blockID, 1);
		world.setBlockAndMetadata(i + 31, j + 16, k + 15, Block.planks.blockID, 1);
		world.setBlock(i + 31, j + 17, k + 1, Block.obsidian.blockID);
		world.setBlockAndMetadata(i + 31, j + 17, k + 2, Block.planks.blockID, 1);
		world.setBlockAndMetadata(i + 31, j + 17, k + 3, Block.planks.blockID, 1);
		world.setBlockAndMetadata(i + 31, j + 17, k + 4, Block.planks.blockID, 1);
		world.setBlockAndMetadata(i + 31, j + 17, k + 5, Block.planks.blockID, 1);
		world.setBlockAndMetadata(i + 31, j + 17, k + 6, Block.planks.blockID, 1);
		world.setBlockAndMetadata(i + 31, j + 17, k + 7, Block.planks.blockID, 1);
		world.setBlockAndMetadata(i + 31, j + 17, k + 8, Block.planks.blockID, 1);
		world.setBlockAndMetadata(i + 31, j + 17, k + 9, Block.planks.blockID, 1);
		world.setBlockAndMetadata(i + 31, j + 17, k + 10, Block.planks.blockID, 1);
		world.setBlockAndMetadata(i + 31, j + 17, k + 11, Block.planks.blockID, 1);
		world.setBlockAndMetadata(i + 31, j + 17, k + 12, Block.planks.blockID, 1);
		world.setBlockAndMetadata(i + 31, j + 17, k + 13, Block.planks.blockID, 1);
		world.setBlockAndMetadata(i + 31, j + 17, k + 14, Block.planks.blockID, 1);
		world.setBlock(i + 31, j + 17, k + 15, Block.obsidian.blockID);
		world.setBlock(i + 31, j + 18, k + 1, Block.fence.blockID);
		world.setBlock(i + 31, j + 18, k + 15, Block.fence.blockID);
		world.setBlockAndMetadata(i + 32, j + 6, k + 4, Block.planks.blockID, 1);
		world.setBlockAndMetadata(i + 32, j + 6, k + 5, Block.planks.blockID, 1);
		world.setBlockAndMetadata(i + 32, j + 6, k + 6, Block.planks.blockID, 1);
		world.setBlockAndMetadata(i + 32, j + 6, k + 7, Block.planks.blockID, 1);
		world.setBlockAndMetadata(i + 32, j + 6, k + 8, Block.planks.blockID, 1);
		world.setBlockAndMetadata(i + 32, j + 6, k + 9, Block.planks.blockID, 1);
		world.setBlockAndMetadata(i + 32, j + 6, k + 10, Block.planks.blockID, 1);
		world.setBlockAndMetadata(i + 32, j + 6, k + 11, Block.planks.blockID, 1);
		world.setBlockAndMetadata(i + 32, j + 6, k + 12, Block.planks.blockID, 1);
		world.setBlockAndMetadata(i + 32, j + 7, k + 4, Block.planks.blockID, 1);
		world.setBlockAndMetadata(i + 32, j + 7, k + 5, Block.planks.blockID, 1);
		world.setBlock(i + 32, j + 7, k + 6, Block.fence.blockID);
		world.setBlock(i + 32, j + 7, k + 8, Block.fence.blockID);
		world.setBlock(i + 32, j + 7, k + 10, Block.fence.blockID);
		world.setBlockAndMetadata(i + 32, j + 7, k + 11, Block.planks.blockID, 1);
		world.setBlockAndMetadata(i + 32, j + 7, k + 12, Block.planks.blockID, 1);
		world.setBlockAndMetadata(i + 32, j + 8, k + 4, Block.planks.blockID, 1);
		world.setBlockAndMetadata(i + 32, j + 8, k + 5, Block.planks.blockID, 1);
		world.setBlockAndMetadata(i + 32, j + 8, k + 6, Block.planks.blockID, 1);
		world.setBlockAndMetadata(i + 32, j + 8, k + 7, Block.planks.blockID, 1);
		world.setBlockAndMetadata(i + 32, j + 8, k + 8, Block.planks.blockID, 1);
		world.setBlockAndMetadata(i + 32, j + 8, k + 9, Block.planks.blockID, 1);
		world.setBlockAndMetadata(i + 32, j + 8, k + 10, Block.planks.blockID, 1);
		world.setBlockAndMetadata(i + 32, j + 8, k + 11, Block.planks.blockID, 1);
		world.setBlockAndMetadata(i + 32, j + 8, k + 12, Block.planks.blockID, 1);
		world.setBlockAndMetadata(i + 32, j + 9, k + 3, Block.planks.blockID, 1);
		world.setBlockAndMetadata(i + 32, j + 9, k + 8, Block.stairCompactPlanks.blockID, 1);
		world.setBlockAndMetadata(i + 32, j + 9, k + 9, Block.stairCompactPlanks.blockID, 1);
		world.setBlockAndMetadata(i + 32, j + 9, k + 13, Block.planks.blockID, 1);
		world.setBlockAndMetadata(i + 32, j + 10, k + 3, Block.planks.blockID, 1);
		world.setBlockAndMetadata(i + 32, j + 10, k + 13, Block.planks.blockID, 1);
		world.setBlockAndMetadata(i + 32, j + 11, k + 3, Block.planks.blockID, 1);
		world.setBlockAndMetadata(i + 32, j + 11, k + 13, Block.planks.blockID, 1);
		world.setBlockAndMetadata(i + 32, j + 12, k + 3, Block.planks.blockID, 1);
		world.setBlockAndMetadata(i + 32, j + 12, k + 4, Block.planks.blockID, 1);
		world.setBlockAndMetadata(i + 32, j + 12, k + 5, Block.planks.blockID, 1);
		world.setBlockAndMetadata(i + 32, j + 12, k + 6, Block.planks.blockID, 1);
		world.setBlockAndMetadata(i + 32, j + 12, k + 7, Block.planks.blockID, 1);
		world.setBlockAndMetadata(i + 32, j + 12, k + 8, Block.planks.blockID, 1);
		world.setBlockAndMetadata(i + 32, j + 12, k + 9, Block.planks.blockID, 1);
		world.setBlockAndMetadata(i + 32, j + 12, k + 10, Block.planks.blockID, 1);
		world.setBlockAndMetadata(i + 32, j + 12, k + 11, Block.planks.blockID, 1);
		world.setBlockAndMetadata(i + 32, j + 12, k + 12, Block.planks.blockID, 1);
		world.setBlockAndMetadata(i + 32, j + 12, k + 13, Block.planks.blockID, 1);
		world.setBlockAndMetadata(i + 32, j + 13, k + 2, Block.planks.blockID, 1);
		world.setBlockAndMetadata(i + 32, j + 13, k + 4, Block.planks.blockID, 2);
		world.setBlockAndMetadata(i + 32, j + 13, k + 5, Block.planks.blockID, 2);
		world.setBlockAndMetadata(i + 32, j + 13, k + 6, Block.planks.blockID, 2);
		world.setBlockAndMetadata(i + 32, j + 13, k + 7, Block.planks.blockID, 2);
		world.setBlockAndMetadata(i + 32, j + 13, k + 8, Block.planks.blockID, 2);
		world.setBlockAndMetadata(i + 32, j + 13, k + 9, Block.planks.blockID, 2);
		world.setBlockAndMetadata(i + 32, j + 13, k + 10, Block.planks.blockID, 2);
		world.setBlockAndMetadata(i + 32, j + 13, k + 11, Block.planks.blockID, 2);
		world.setBlockAndMetadata(i + 32, j + 13, k + 12, Block.planks.blockID, 2);
		world.setBlockAndMetadata(i + 32, j + 13, k + 13, Block.planks.blockID, 2);
		world.setBlockAndMetadata(i + 32, j + 13, k + 14, Block.planks.blockID, 1);
		world.setBlockAndMetadata(i + 32, j + 14, k + 2, Block.planks.blockID, 1);
		world.setBlockAndMetadata(i + 32, j + 14, k + 4, Block.planks.blockID, 2);
		world.setBlockAndMetadata(i + 32, j + 14, k + 5, Block.planks.blockID, 2);
		world.setBlockAndMetadata(i + 32, j + 14, k + 6, Block.planks.blockID, 2);
		world.setBlockAndMetadata(i + 32, j + 14, k + 7, Block.planks.blockID, 2);
		world.setBlockAndMetadata(i + 32, j + 14, k + 8, Block.planks.blockID, 2);
		world.setBlockAndMetadata(i + 32, j + 14, k + 9, Block.planks.blockID, 2);
		world.setBlockAndMetadata(i + 32, j + 14, k + 10, Block.planks.blockID, 2);
		world.setBlockAndMetadata(i + 32, j + 14, k + 11, Block.planks.blockID, 2);
		world.setBlockAndMetadata(i + 32, j + 14, k + 12, Block.planks.blockID, 2);
		world.setBlockAndMetadata(i + 32, j + 14, k + 13, Block.planks.blockID, 2);
		world.setBlockAndMetadata(i + 32, j + 14, k + 14, Block.planks.blockID, 1);
		world.setBlockAndMetadata(i + 32, j + 15, k + 2, Block.planks.blockID, 1);
		world.setBlockAndMetadata(i + 32, j + 15, k + 4, Block.planks.blockID, 2);
		world.setBlockAndMetadata(i + 32, j + 15, k + 5, Block.planks.blockID, 2);
		world.setBlock(i + 32, j + 15, k + 6, Block.thinGlass.blockID);
		world.setBlockAndMetadata(i + 32, j + 15, k + 7, Block.planks.blockID, 2);
		world.setBlockAndMetadata(i + 32, j + 15, k + 8, Block.planks.blockID, 2);
		world.setBlock(i + 32, j + 15, k + 9, Block.thinGlass.blockID);
		world.setBlockAndMetadata(i + 32, j + 15, k + 10, Block.planks.blockID, 2);
		world.setBlockAndMetadata(i + 32, j + 15, k + 11, Block.planks.blockID, 2);
		world.setBlock(i + 32, j + 15, k + 12, Block.thinGlass.blockID);
		world.setBlockAndMetadata(i + 32, j + 15, k + 13, Block.planks.blockID, 2);
		world.setBlockAndMetadata(i + 32, j + 15, k + 14, Block.planks.blockID, 1);
		world.setBlockAndMetadata(i + 32, j + 16, k + 1, Block.planks.blockID, 1);
		world.setBlockAndMetadata(i + 32, j + 16, k + 4, Block.planks.blockID, 2);
		world.setBlockAndMetadata(i + 32, j + 16, k + 5, Block.planks.blockID, 2);
		world.setBlockAndMetadata(i + 32, j + 16, k + 6, Block.planks.blockID, 2);
		world.setBlockAndMetadata(i + 32, j + 16, k + 7, Block.planks.blockID, 2);
		world.setBlockAndMetadata(i + 32, j + 16, k + 8, Block.planks.blockID, 2);
		world.setBlockAndMetadata(i + 32, j + 16, k + 9, Block.planks.blockID, 2);
		world.setBlockAndMetadata(i + 32, j + 16, k + 10, Block.planks.blockID, 2);
		world.setBlockAndMetadata(i + 32, j + 16, k + 11, Block.planks.blockID, 2);
		world.setBlockAndMetadata(i + 32, j + 16, k + 12, Block.planks.blockID, 2);
		world.setBlockAndMetadata(i + 32, j + 16, k + 13, Block.planks.blockID, 2);
		world.setBlockAndMetadata(i + 32, j + 16, k + 15, Block.planks.blockID, 1);
		world.setBlock(i + 32, j + 17, k + 1, Block.obsidian.blockID);
		world.setBlockAndMetadata(i + 32, j + 17, k + 2, Block.planks.blockID, 1);
		world.setBlockAndMetadata(i + 32, j + 17, k + 3, Block.planks.blockID, 1);
		world.setBlockAndMetadata(i + 32, j + 17, k + 4, Block.planks.blockID, 1);
		world.setBlockAndMetadata(i + 32, j + 17, k + 5, Block.planks.blockID, 1);
		world.setBlockAndMetadata(i + 32, j + 17, k + 6, Block.planks.blockID, 1);
		world.setBlockAndMetadata(i + 32, j + 17, k + 7, Block.planks.blockID, 1);
		world.setBlockAndMetadata(i + 32, j + 17, k + 8, Block.planks.blockID, 1);
		world.setBlockAndMetadata(i + 32, j + 17, k + 9, Block.planks.blockID, 1);
		world.setBlockAndMetadata(i + 32, j + 17, k + 10, Block.planks.blockID, 1);
		world.setBlockAndMetadata(i + 32, j + 17, k + 11, Block.planks.blockID, 1);
		world.setBlockAndMetadata(i + 32, j + 17, k + 12, Block.planks.blockID, 1);
		world.setBlockAndMetadata(i + 32, j + 17, k + 13, Block.planks.blockID, 1);
		world.setBlockAndMetadata(i + 32, j + 17, k + 14, Block.planks.blockID, 1);
		world.setBlock(i + 32, j + 17, k + 15, Block.obsidian.blockID);
		world.setBlock(i + 32, j + 18, k + 1, Block.fence.blockID);
		world.setBlock(i + 32, j + 18, k + 15, Block.fence.blockID);
		world.setBlockAndMetadata(i + 33, j + 6, k + 4, Block.planks.blockID, 1);
		world.setBlockAndMetadata(i + 33, j + 6, k + 5, Block.planks.blockID, 1);
		world.setBlockAndMetadata(i + 33, j + 6, k + 6, Block.planks.blockID, 1);
		world.setBlockAndMetadata(i + 33, j + 6, k + 7, Block.planks.blockID, 1);
		world.setBlockAndMetadata(i + 33, j + 6, k + 8, Block.planks.blockID, 1);
		world.setBlockAndMetadata(i + 33, j + 6, k + 9, Block.planks.blockID, 1);
		world.setBlockAndMetadata(i + 33, j + 6, k + 10, Block.planks.blockID, 1);
		world.setBlockAndMetadata(i + 33, j + 6, k + 11, Block.planks.blockID, 1);
		world.setBlockAndMetadata(i + 33, j + 6, k + 12, Block.planks.blockID, 1);
		world.setBlockAndMetadata(i + 33, j + 7, k + 4, Block.planks.blockID, 1);
		world.setBlock(i + 33, j + 7, k + 5, Block.fence.blockID);
		world.setBlock(i + 33, j + 7, k + 6, Block.fence.blockID);
		world.setBlock(i + 33, j + 7, k + 7, Block.fence.blockID);
		world.setBlock(i + 33, j + 7, k + 8, Block.fence.blockID);
		world.setBlock(i + 33, j + 7, k + 9, Block.fence.blockID);
		world.setBlock(i + 33, j + 7, k + 10, Block.fence.blockID);
		world.setBlock(i + 33, j + 7, k + 11, Block.fence.blockID);
		world.setBlockAndMetadata(i + 33, j + 7, k + 12, Block.planks.blockID, 1);
		world.setBlockAndMetadata(i + 33, j + 8, k + 4, Block.planks.blockID, 1);
		world.setBlockAndMetadata(i + 33, j + 8, k + 5, Block.planks.blockID, 1);
		world.setBlockAndMetadata(i + 33, j + 8, k + 6, Block.planks.blockID, 1);
		world.setBlockAndMetadata(i + 33, j + 8, k + 7, Block.planks.blockID, 1);
		world.setBlockAndMetadata(i + 33, j + 8, k + 8, Block.planks.blockID, 1);
		world.setBlockAndMetadata(i + 33, j + 8, k + 9, Block.planks.blockID, 1);
		world.setBlockAndMetadata(i + 33, j + 8, k + 10, Block.planks.blockID, 1);
		world.setBlockAndMetadata(i + 33, j + 8, k + 11, Block.planks.blockID, 1);
		world.setBlockAndMetadata(i + 33, j + 8, k + 12, Block.planks.blockID, 1);
		world.setBlockAndMetadata(i + 33, j + 9, k + 3, Block.planks.blockID, 1);
		world.setBlockAndMetadata(i + 33, j + 9, k + 4, Block.cloth.blockID, 2);
		world.setBlockAndMetadata(i + 33, j + 9, k + 5, Block.stairCompactPlanks.blockID, 2);
		world.setBlockAndMetadata(i + 33, j + 9, k + 7, Block.stairCompactPlanks.blockID, 3);
		world.setBlockAndMetadata(i + 33, j + 9, k + 8, Block.cloth.blockID, 2);
		world.setBlockAndMetadata(i + 33, j + 9, k + 9, Block.cloth.blockID, 2);
		world.setBlockAndMetadata(i + 33, j + 9, k + 10, Block.stairCompactPlanks.blockID, 2);
		world.setBlockAndMetadata(i + 33, j + 9, k + 13, Block.planks.blockID, 1);
		world.setBlockAndMetadata(i + 33, j + 10, k + 3, Block.planks.blockID, 1);
		world.setBlockAndMetadata(i + 33, j + 10, k + 13, Block.planks.blockID, 1);
		world.setBlockAndMetadata(i + 33, j + 11, k + 3, Block.planks.blockID, 1);
		world.setBlockAndMetadata(i + 33, j + 11, k + 13, Block.planks.blockID, 1);
		world.setBlockAndMetadata(i + 33, j + 12, k + 3, Block.planks.blockID, 1);
		world.setBlockAndMetadata(i + 33, j + 12, k + 4, Block.planks.blockID, 1);
		world.setBlockAndMetadata(i + 33, j + 12, k + 5, Block.planks.blockID, 1);
		world.setBlockAndMetadata(i + 33, j + 12, k + 6, Block.planks.blockID, 1);
		world.setBlockAndMetadata(i + 33, j + 12, k + 7, Block.planks.blockID, 1);
		world.setBlockAndMetadata(i + 33, j + 12, k + 8, Block.planks.blockID, 1);
		world.setBlockAndMetadata(i + 33, j + 12, k + 9, Block.planks.blockID, 1);
		world.setBlockAndMetadata(i + 33, j + 12, k + 10, Block.planks.blockID, 1);
		world.setBlockAndMetadata(i + 33, j + 12, k + 11, Block.planks.blockID, 1);
		world.setBlockAndMetadata(i + 33, j + 12, k + 12, Block.planks.blockID, 1);
		world.setBlockAndMetadata(i + 33, j + 12, k + 13, Block.planks.blockID, 1);
		world.setBlockAndMetadata(i + 33, j + 13, k + 2, Block.planks.blockID, 1);
		world.setBlockAndMetadata(i + 33, j + 13, k + 4, Block.planks.blockID, 2);
		world.setBlock(i + 33, j + 13, k + 5, Block.bookShelf.blockID);
		world.setBlockAndMetadata(i + 33, j + 13, k + 9, Block.stairCompactPlanks.blockID, 1);
		world.setBlockAndMetadata(i + 33, j + 13, k + 10, Block.stairCompactPlanks.blockID, 1);
		world.setBlockAndMetadata(i + 33, j + 13, k + 11, Block.stairCompactPlanks.blockID, 1);
		world.setBlockAndMetadata(i + 33, j + 13, k + 14, Block.planks.blockID, 1);
		world.setBlockAndMetadata(i + 33, j + 13, k + 15, Block.planks.blockID, 1);
		world.setBlockAndMetadata(i + 33, j + 14, k + 2, Block.planks.blockID, 1);
		world.setBlockAndMetadata(i + 33, j + 14, k + 4, Block.planks.blockID, 2);
		world.setBlock(i + 33, j + 14, k + 5, Block.bookShelf.blockID);
		world.setBlockAndMetadata(i + 33, j + 14, k + 15, Block.planks.blockID, 1);
		world.setBlockAndMetadata(i + 33, j + 15, k + 2, Block.planks.blockID, 1);
		world.setBlockAndMetadata(i + 33, j + 15, k + 4, Block.planks.blockID, 2);
		world.setBlockAndMetadata(i + 33, j + 15, k + 15, Block.planks.blockID, 1);
		world.setBlockAndMetadata(i + 33, j + 16, k + 0, Block.planks.blockID, 1);
		world.setBlockAndMetadata(i + 33, j + 16, k + 1, Block.planks.blockID, 1);
		world.setBlockAndMetadata(i + 33, j + 16, k + 4, Block.planks.blockID, 2);
		world.setBlockAndMetadata(i + 33, j + 16, k + 15, Block.planks.blockID, 1);
		world.setBlockAndMetadata(i + 33, j + 16, k + 16, Block.planks.blockID, 1);
		world.setBlock(i + 33, j + 17, k + 0, Block.obsidian.blockID);
		world.setBlock(i + 33, j + 17, k + 1, Block.obsidian.blockID);
		world.setBlockAndMetadata(i + 33, j + 17, k + 2, Block.planks.blockID, 1);
		world.setBlockAndMetadata(i + 33, j + 17, k + 3, Block.planks.blockID, 1);
		world.setBlockAndMetadata(i + 33, j + 17, k + 4, Block.planks.blockID, 1);
		world.setBlockAndMetadata(i + 33, j + 17, k + 5, Block.planks.blockID, 1);
		world.setBlockAndMetadata(i + 33, j + 17, k + 6, Block.planks.blockID, 1);
		world.setBlockAndMetadata(i + 33, j + 17, k + 7, Block.planks.blockID, 1);
		world.setBlockAndMetadata(i + 33, j + 17, k + 8, Block.planks.blockID, 1);
		world.setBlockAndMetadata(i + 33, j + 17, k + 9, Block.planks.blockID, 1);
		world.setBlockAndMetadata(i + 33, j + 17, k + 10, Block.planks.blockID, 1);
		world.setBlockAndMetadata(i + 33, j + 17, k + 11, Block.planks.blockID, 1);
		world.setBlockAndMetadata(i + 33, j + 17, k + 12, Block.planks.blockID, 1);
		world.setBlockAndMetadata(i + 33, j + 17, k + 13, Block.planks.blockID, 1);
		world.setBlockAndMetadata(i + 33, j + 17, k + 14, Block.planks.blockID, 1);
		world.setBlock(i + 33, j + 17, k + 15, Block.obsidian.blockID);
		world.setBlock(i + 33, j + 17, k + 16, Block.obsidian.blockID);
		world.setBlock(i + 33, j + 18, k + 0, Block.fence.blockID);
		world.setBlock(i + 33, j + 18, k + 1, Block.fence.blockID);
		world.setBlockAndMetadata(i + 33, j + 18, k + 8, Block.wood.blockID, 1);
		world.setBlock(i + 33, j + 18, k + 15, Block.fence.blockID);
		world.setBlock(i + 33, j + 18, k + 16, Block.fence.blockID);
		world.setBlockAndMetadata(i + 33, j + 19, k + 8, Block.wood.blockID, 1);
		world.setBlockAndMetadata(i + 33, j + 20, k + 8, Block.wood.blockID, 1);
		world.setBlockAndMetadata(i + 33, j + 21, k + 8, Block.wood.blockID, 1);
		world.setBlockAndMetadata(i + 33, j + 22, k + 8, Block.wood.blockID, 1);
		world.setBlockAndMetadata(i + 34, j + 6, k + 4, Block.planks.blockID, 1);
		world.setBlockAndMetadata(i + 34, j + 6, k + 5, Block.planks.blockID, 1);
		world.setBlockAndMetadata(i + 34, j + 6, k + 6, Block.planks.blockID, 1);
		world.setBlockAndMetadata(i + 34, j + 6, k + 7, Block.planks.blockID, 1);
		world.setBlockAndMetadata(i + 34, j + 6, k + 8, Block.planks.blockID, 1);
		world.setBlockAndMetadata(i + 34, j + 6, k + 9, Block.planks.blockID, 1);
		world.setBlockAndMetadata(i + 34, j + 6, k + 10, Block.planks.blockID, 1);
		world.setBlockAndMetadata(i + 34, j + 6, k + 11, Block.planks.blockID, 1);
		world.setBlockAndMetadata(i + 34, j + 6, k + 12, Block.planks.blockID, 1);
		world.setBlockAndMetadata(i + 34, j + 7, k + 4, Block.planks.blockID, 1);
		world.setBlock(i + 34, j + 7, k + 6, Block.fence.blockID);
		world.setBlock(i + 34, j + 7, k + 8, Block.fence.blockID);
		world.setBlock(i + 34, j + 7, k + 10, Block.fence.blockID);
		world.setBlockAndMetadata(i + 34, j + 7, k + 12, Block.planks.blockID, 1);
		world.setBlockAndMetadata(i + 34, j + 8, k + 4, Block.planks.blockID, 1);
		world.setBlockAndMetadata(i + 34, j + 8, k + 5, Block.planks.blockID, 1);
		world.setBlockAndMetadata(i + 34, j + 8, k + 6, Block.planks.blockID, 1);
		world.setBlockAndMetadata(i + 34, j + 8, k + 7, Block.planks.blockID, 1);
		world.setBlockAndMetadata(i + 34, j + 8, k + 8, Block.planks.blockID, 1);
		world.setBlockAndMetadata(i + 34, j + 8, k + 9, Block.planks.blockID, 1);
		world.setBlockAndMetadata(i + 34, j + 8, k + 10, Block.planks.blockID, 1);
		world.setBlockAndMetadata(i + 34, j + 8, k + 11, Block.planks.blockID, 1);
		world.setBlockAndMetadata(i + 34, j + 8, k + 12, Block.planks.blockID, 1);
		world.setBlockAndMetadata(i + 34, j + 9, k + 2, Block.planks.blockID, 1);
		world.setBlockAndMetadata(i + 34, j + 9, k + 3, Block.planks.blockID, 1);
		world.setBlockAndMetadata(i + 34, j + 9, k + 4, Block.cloth.blockID, 2);
		world.setBlockAndMetadata(i + 34, j + 9, k + 5, Block.stairCompactPlanks.blockID, 2);
		world.setBlockAndMetadata(i + 34, j + 9, k + 7, Block.stairCompactPlanks.blockID, 3);
		world.setBlockAndMetadata(i + 34, j + 9, k + 8, Block.cloth.blockID, 2);
		world.setBlockAndMetadata(i + 34, j + 9, k + 9, Block.cloth.blockID, 2);
		world.setBlockAndMetadata(i + 34, j + 9, k + 10, Block.stairCompactPlanks.blockID, 2);
		world.setBlockAndMetadata(i + 34, j + 9, k + 13, Block.planks.blockID, 1);
		world.setBlockAndMetadata(i + 34, j + 9, k + 14, Block.planks.blockID, 1);
		world.setBlockAndMetadata(i + 34, j + 10, k + 2, Block.planks.blockID, 1);
		world.setBlockAndMetadata(i + 34, j + 10, k + 3, Block.planks.blockID, 1);
		world.setBlockAndMetadata(i + 34, j + 10, k + 13, Block.planks.blockID, 1);
		world.setBlockAndMetadata(i + 34, j + 10, k + 14, Block.planks.blockID, 1);
		world.setBlockAndMetadata(i + 34, j + 11, k + 2, Block.planks.blockID, 1);
		world.setBlockAndMetadata(i + 34, j + 11, k + 3, Block.planks.blockID, 1);
		world.setBlockAndMetadata(i + 34, j + 11, k + 13, Block.planks.blockID, 1);
		world.setBlockAndMetadata(i + 34, j + 11, k + 14, Block.planks.blockID, 1);
		world.setBlockAndMetadata(i + 34, j + 12, k + 2, Block.planks.blockID, 1);
		world.setBlockAndMetadata(i + 34, j + 12, k + 3, Block.planks.blockID, 1);
		world.setBlockAndMetadata(i + 34, j + 12, k + 4, Block.planks.blockID, 1);
		world.setBlockAndMetadata(i + 34, j + 12, k + 5, Block.planks.blockID, 1);
		world.setBlockAndMetadata(i + 34, j + 12, k + 6, Block.planks.blockID, 1);
		world.setBlockAndMetadata(i + 34, j + 12, k + 7, Block.planks.blockID, 1);
		world.setBlockAndMetadata(i + 34, j + 12, k + 8, Block.planks.blockID, 1);
		world.setBlockAndMetadata(i + 34, j + 12, k + 9, Block.planks.blockID, 1);
		world.setBlockAndMetadata(i + 34, j + 12, k + 10, Block.planks.blockID, 1);
		world.setBlockAndMetadata(i + 34, j + 12, k + 11, Block.planks.blockID, 1);
		world.setBlockAndMetadata(i + 34, j + 12, k + 12, Block.planks.blockID, 1);
		world.setBlockAndMetadata(i + 34, j + 12, k + 13, Block.planks.blockID, 1);
		world.setBlockAndMetadata(i + 34, j + 12, k + 14, Block.planks.blockID, 1);
		world.setBlockAndMetadata(i + 34, j + 13, k + 1, Block.planks.blockID, 1);
		world.setBlockAndMetadata(i + 34, j + 13, k + 2, Block.chest.blockID, 3);
		world.setBlockAndMetadata(i + 34, j + 13, k + 4, Block.planks.blockID, 2);
		world.setBlockAndMetadata(i + 34, j + 13, k + 15, Block.planks.blockID, 1);
		world.setBlockAndMetadata(i + 34, j + 14, k + 1, Block.planks.blockID, 1);
		world.setBlockAndMetadata(i + 34, j + 14, k + 4, Block.planks.blockID, 2);
		world.setBlockAndMetadata(i + 34, j + 14, k + 15, Block.planks.blockID, 1);
		world.setBlockAndMetadata(i + 34, j + 15, k + 1, Block.planks.blockID, 1);
		world.setBlock(i + 34, j + 15, k + 4, Block.thinGlass.blockID);
		world.setBlockAndMetadata(i + 34, j + 15, k + 15, Block.planks.blockID, 1);
		world.setBlockAndMetadata(i + 34, j + 16, k + 0, Block.planks.blockID, 1);
		world.setBlockAndMetadata(i + 34, j + 16, k + 2, Block.stairCompactPlanks.blockID, 4);
		world.setBlockAndMetadata(i + 34, j + 16, k + 4, Block.planks.blockID, 2);
		world.setBlockAndMetadata(i + 34, j + 16, k + 16, Block.planks.blockID, 1);
		world.setBlock(i + 34, j + 17, k + 0, Block.obsidian.blockID);
		world.setBlockAndMetadata(i + 34, j + 17, k + 1, Block.planks.blockID, 1);
		world.setBlockAndMetadata(i + 34, j + 17, k + 2, Block.stairCompactPlanks.blockID, 1);
		world.setBlockAndMetadata(i + 34, j + 17, k + 3, Block.planks.blockID, 1);
		world.setBlockAndMetadata(i + 34, j + 17, k + 4, Block.planks.blockID, 1);
		world.setBlockAndMetadata(i + 34, j + 17, k + 5, Block.planks.blockID, 1);
		world.setBlockAndMetadata(i + 34, j + 17, k + 6, Block.planks.blockID, 1);
		world.setBlockAndMetadata(i + 34, j + 17, k + 7, Block.planks.blockID, 1);
		world.setBlockAndMetadata(i + 34, j + 17, k + 8, Block.planks.blockID, 1);
		world.setBlockAndMetadata(i + 34, j + 17, k + 9, Block.planks.blockID, 1);
		world.setBlockAndMetadata(i + 34, j + 17, k + 10, Block.planks.blockID, 1);
		world.setBlockAndMetadata(i + 34, j + 17, k + 11, Block.planks.blockID, 1);
		world.setBlockAndMetadata(i + 34, j + 17, k + 12, Block.planks.blockID, 1);
		world.setBlockAndMetadata(i + 34, j + 17, k + 13, Block.planks.blockID, 1);
		world.setBlockAndMetadata(i + 34, j + 17, k + 14, Block.planks.blockID, 1);
		world.setBlockAndMetadata(i + 34, j + 17, k + 15, Block.planks.blockID, 1);
		world.setBlock(i + 34, j + 17, k + 16, Block.obsidian.blockID);
		world.setBlock(i + 34, j + 18, k + 0, Block.fence.blockID);
		world.setBlock(i + 34, j + 18, k + 16, Block.fence.blockID);
		world.setBlockAndMetadata(i + 35, j + 6, k + 3, Block.planks.blockID, 1);
		world.setBlockAndMetadata(i + 35, j + 6, k + 4, Block.planks.blockID, 1);
		world.setBlockAndMetadata(i + 35, j + 6, k + 5, Block.planks.blockID, 1);
		world.setBlockAndMetadata(i + 35, j + 6, k + 6, Block.planks.blockID, 1);
		world.setBlockAndMetadata(i + 35, j + 6, k + 7, Block.planks.blockID, 1);
		world.setBlockAndMetadata(i + 35, j + 6, k + 8, Block.planks.blockID, 1);
		world.setBlockAndMetadata(i + 35, j + 6, k + 9, Block.planks.blockID, 1);
		world.setBlockAndMetadata(i + 35, j + 6, k + 10, Block.planks.blockID, 1);
		world.setBlockAndMetadata(i + 35, j + 6, k + 11, Block.planks.blockID, 1);
		world.setBlockAndMetadata(i + 35, j + 6, k + 12, Block.planks.blockID, 1);
		world.setBlockAndMetadata(i + 35, j + 6, k + 13, Block.planks.blockID, 1);
		world.setBlockAndMetadata(i + 35, j + 7, k + 3, Block.planks.blockID, 1);
		world.setBlockAndMetadata(i + 35, j + 7, k + 4, Block.planks.blockID, 1);
		world.setBlock(i + 35, j + 7, k + 6, Block.fence.blockID);
		world.setBlock(i + 35, j + 7, k + 8, Block.fence.blockID);
		world.setBlock(i + 35, j + 7, k + 10, Block.fence.blockID);
		world.setBlockAndMetadata(i + 35, j + 7, k + 12, Block.planks.blockID, 1);
		world.setBlockAndMetadata(i + 35, j + 7, k + 13, Block.planks.blockID, 1);
		world.setBlockAndMetadata(i + 35, j + 8, k + 3, Block.planks.blockID, 1);
		world.setBlockAndMetadata(i + 35, j + 8, k + 4, Block.planks.blockID, 1);
		world.setBlockAndMetadata(i + 35, j + 8, k + 5, Block.planks.blockID, 1);
		world.setBlockAndMetadata(i + 35, j + 8, k + 6, Block.planks.blockID, 1);
		world.setBlockAndMetadata(i + 35, j + 8, k + 7, Block.planks.blockID, 1);
		world.setBlockAndMetadata(i + 35, j + 8, k + 8, Block.planks.blockID, 1);
		world.setBlockAndMetadata(i + 35, j + 8, k + 9, Block.planks.blockID, 1);
		world.setBlockAndMetadata(i + 35, j + 8, k + 10, Block.planks.blockID, 1);
		world.setBlockAndMetadata(i + 35, j + 8, k + 11, Block.planks.blockID, 1);
		world.setBlockAndMetadata(i + 35, j + 8, k + 12, Block.planks.blockID, 1);
		world.setBlockAndMetadata(i + 35, j + 8, k + 13, Block.planks.blockID, 1);
		world.setBlockAndMetadata(i + 35, j + 9, k + 2, Block.planks.blockID, 1);
		world.setBlock(i + 35, j + 9, k + 3, Block.planks.blockID);
		world.setBlock(i + 35, j + 9, k + 8, Block.stairCompactPlanks.blockID);
		world.setBlock(i + 35, j + 9, k + 9, Block.stairCompactPlanks.blockID);
		world.setBlock(i + 35, j + 9, k + 13, Block.dirt.blockID);
		world.setBlockAndMetadata(i + 35, j + 9, k + 14, Block.planks.blockID, 1);
		world.setBlockAndMetadata(i + 35, j + 10, k + 2, Block.planks.blockID, 1);
		world.setBlock(i + 35, j + 10, k + 3, Block.planks.blockID);
		world.setBlockAndMetadata(i + 35, j + 10, k + 14, Block.planks.blockID, 1);
		world.setBlockAndMetadata(i + 35, j + 11, k + 2, Block.planks.blockID, 1);
		world.setBlock(i + 35, j + 11, k + 3, Block.planks.blockID);
		world.setBlockAndMetadata(i + 35, j + 11, k + 14, Block.planks.blockID, 1);
		world.setBlockAndMetadata(i + 35, j + 12, k + 2, Block.planks.blockID, 1);
		world.setBlockAndMetadata(i + 35, j + 12, k + 3, Block.planks.blockID, 1);
		world.setBlockAndMetadata(i + 35, j + 12, k + 4, Block.planks.blockID, 1);
		world.setBlockAndMetadata(i + 35, j + 12, k + 5, Block.planks.blockID, 1);
		world.setBlockAndMetadata(i + 35, j + 12, k + 6, Block.planks.blockID, 1);
		world.setBlockAndMetadata(i + 35, j + 12, k + 7, Block.planks.blockID, 1);
		world.setBlockAndMetadata(i + 35, j + 12, k + 8, Block.planks.blockID, 1);
		world.setBlockAndMetadata(i + 35, j + 12, k + 9, Block.planks.blockID, 1);
		world.setBlockAndMetadata(i + 35, j + 12, k + 10, Block.planks.blockID, 1);
		world.setBlockAndMetadata(i + 35, j + 12, k + 11, Block.planks.blockID, 1);
		world.setBlockAndMetadata(i + 35, j + 12, k + 12, Block.planks.blockID, 1);
		world.setBlockAndMetadata(i + 35, j + 12, k + 13, Block.planks.blockID, 1);
		world.setBlockAndMetadata(i + 35, j + 12, k + 14, Block.planks.blockID, 1);
		world.setBlockAndMetadata(i + 35, j + 13, k + 1, Block.planks.blockID, 1);
		world.setBlockAndMetadata(i + 35, j + 13, k + 2, Block.chest.blockID, 3);
		world.setBlockAndMetadata(i + 35, j + 13, k + 4, Block.planks.blockID, 2);
		world.setBlock(i + 35, j + 13, k + 5, Block.bookShelf.blockID);
		world.setBlockAndMetadata(i + 35, j + 13, k + 7, Block.stairCompactPlanks.blockID, 3);
		world.setBlockAndMetadata(i + 35, j + 13, k + 9, Block.cloth.blockID, 10);
		world.setBlockAndMetadata(i + 35, j + 13, k + 10, Block.cloth.blockID, 10);
		world.setBlockAndMetadata(i + 35, j + 13, k + 11, Block.cloth.blockID, 10);
		world.setBlockAndMetadata(i + 35, j + 13, k + 13, Block.stairCompactPlanks.blockID, 2);
		world.setBlockAndMetadata(i + 35, j + 13, k + 15, Block.planks.blockID, 1);
		world.setBlockAndMetadata(i + 35, j + 14, k + 1, Block.planks.blockID, 1);
		world.setBlockAndMetadata(i + 35, j + 14, k + 4, Block.planks.blockID, 2);
		world.setBlock(i + 35, j + 14, k + 5, Block.bookShelf.blockID);
		world.setBlockAndMetadata(i + 35, j + 14, k + 15, Block.planks.blockID, 1);
		world.setBlockAndMetadata(i + 35, j + 15, k + 1, Block.planks.blockID, 1);
		world.setBlockAndMetadata(i + 35, j + 15, k + 2, Block.stairCompactPlanks.blockID, 4);
		world.setBlockAndMetadata(i + 35, j + 15, k + 4, Block.planks.blockID, 2);
		world.setBlockAndMetadata(i + 35, j + 15, k + 15, Block.planks.blockID, 1);
		world.setBlockAndMetadata(i + 35, j + 16, k + 0, Block.planks.blockID, 1);
