package fossil.gens;

import java.util.Random;

import net.minecraft.block.Block;
import net.minecraft.world.World;
import net.minecraft.world.gen.feature.WorldGenerator;

public class WorldGeneratorAcademy extends WorldGenerator
{
	
	public boolean generate(World var1, Random var2, int i, int j, int k)
	{
		System.out.println("Generating Academy");
		var1.setBlock(i + 0, j + 0, k + 0, Block.dirt.blockID);
		var1.setBlock(i + 0, j + 0, k + 1, Block.dirt.blockID);
		var1.setBlock(i + 0, j + 0, k + 2, Block.dirt.blockID);
		var1.setBlock(i + 0, j + 0, k + 3, Block.dirt.blockID);
		var1.setBlock(i + 0, j + 0, k + 4, Block.dirt.blockID);
		var1.setBlock(i + 0, j + 0, k + 5, Block.dirt.blockID);
		var1.setBlock(i + 0, j + 0, k + 6, Block.dirt.blockID);
		var1.setBlock(i + 0, j + 0, k + 7, Block.dirt.blockID);
		var1.setBlock(i + 0, j + 0, k + 8, Block.dirt.blockID);
		var1.setBlock(i + 0, j + 0, k + 9, Block.dirt.blockID);
		var1.setBlock(i + 0, j + 0, k + 10, Block.dirt.blockID);
		var1.setBlock(i + 0, j + 0, k + 11, Block.dirt.blockID);
		var1.setBlock(i + 0, j + 0, k + 12, Block.dirt.blockID);
		var1.setBlock(i + 0, j + 0, k + 13, Block.dirt.blockID);
		var1.setBlock(i + 0, j + 0, k + 14, Block.dirt.blockID);
		var1.setBlock(i + 0, j + 0, k + 15, Block.dirt.blockID);
		var1.setBlock(i + 0, j + 0, k + 16, Block.dirt.blockID);
		var1.setBlock(i + 0, j + 0, k + 17, Block.dirt.blockID);
		var1.setBlock(i + 0, j + 0, k + 18, Block.dirt.blockID);
		var1.setBlock(i + 0, j + 0, k + 19, Block.dirt.blockID);
		var1.setBlock(i + 0, j + 0, k + 20, Block.dirt.blockID);
		var1.setBlock(i + 0, j + 0, k + 21, Block.dirt.blockID);
		var1.setBlock(i + 0, j + 0, k + 22, Block.dirt.blockID);
		var1.setBlock(i + 0, j + 0, k + 23, Block.dirt.blockID);
		var1.setBlock(i + 0, j + 0, k + 24, Block.dirt.blockID);
		var1.setBlock(i + 0, j + 0, k + 25, Block.dirt.blockID);
		var1.setBlock(i + 0, j + 0, k + 26, Block.dirt.blockID);
		var1.setBlock(i + 0, j + 1, k + 0, Block.dirt.blockID);
		var1.setBlock(i + 0, j + 1, k + 1, Block.dirt.blockID);
		var1.setBlock(i + 0, j + 1, k + 2, Block.dirt.blockID);
		var1.setBlock(i + 0, j + 1, k + 3, Block.dirt.blockID);
		var1.setBlock(i + 0, j + 1, k + 4, Block.dirt.blockID);
		var1.setBlock(i + 0, j + 1, k + 5, Block.dirt.blockID);
		var1.setBlock(i + 0, j + 1, k + 6, Block.dirt.blockID);
		var1.setBlock(i + 0, j + 1, k + 7, Block.dirt.blockID);
		var1.setBlock(i + 0, j + 1, k + 8, Block.dirt.blockID);
		var1.setBlock(i + 0, j + 1, k + 9, Block.dirt.blockID);
		var1.setBlock(i + 0, j + 1, k + 10, Block.dirt.blockID);
		var1.setBlock(i + 0, j + 1, k + 11, Block.dirt.blockID);
		var1.setBlock(i + 0, j + 1, k + 12, Block.dirt.blockID);
		var1.setBlock(i + 0, j + 1, k + 13, Block.dirt.blockID);
		var1.setBlock(i + 0, j + 1, k + 14, Block.dirt.blockID);
		var1.setBlock(i + 0, j + 1, k + 15, Block.dirt.blockID);
		var1.setBlock(i + 0, j + 1, k + 16, Block.dirt.blockID);
		var1.setBlock(i + 0, j + 1, k + 17, Block.dirt.blockID);
		var1.setBlock(i + 0, j + 1, k + 18, Block.dirt.blockID);
		var1.setBlock(i + 0, j + 1, k + 19, Block.dirt.blockID);
		var1.setBlock(i + 0, j + 1, k + 20, Block.dirt.blockID);
		var1.setBlock(i + 0, j + 1, k + 21, Block.dirt.blockID);
		var1.setBlock(i + 0, j + 1, k + 22, Block.dirt.blockID);
		var1.setBlock(i + 0, j + 1, k + 23, Block.dirt.blockID);
		var1.setBlock(i + 0, j + 1, k + 24, Block.dirt.blockID);
		var1.setBlock(i + 0, j + 1, k + 25, Block.dirt.blockID);
		var1.setBlock(i + 0, j + 1, k + 26, Block.dirt.blockID);
		var1.setBlock(i + 0, j + 2, k + 0, Block.grass.blockID);
		var1.setBlock(i + 0, j + 2, k + 1, Block.grass.blockID);
		var1.setBlock(i + 0, j + 2, k + 2, Block.grass.blockID);
		var1.setBlock(i + 0, j + 2, k + 3, Block.grass.blockID);
		var1.setBlock(i + 0, j + 2, k + 4, Block.grass.blockID);
		var1.setBlock(i + 0, j + 2, k + 5, Block.grass.blockID);
		var1.setBlock(i + 0, j + 2, k + 6, Block.grass.blockID);
		var1.setBlock(i + 0, j + 2, k + 7, Block.grass.blockID);
		var1.setBlock(i + 0, j + 2, k + 8, Block.grass.blockID);
		var1.setBlock(i + 0, j + 2, k + 9, Block.grass.blockID);
		var1.setBlock(i + 0, j + 2, k + 10, Block.grass.blockID);
		var1.setBlock(i + 0, j + 2, k + 11, Block.grass.blockID);
		var1.setBlock(i + 0, j + 2, k + 12, Block.grass.blockID);
		var1.setBlock(i + 0, j + 2, k + 13, Block.grass.blockID);
		var1.setBlock(i + 0, j + 2, k + 14, Block.grass.blockID);
		var1.setBlock(i + 0, j + 2, k + 15, Block.grass.blockID);
		var1.setBlock(i + 0, j + 2, k + 16, Block.grass.blockID);
		var1.setBlock(i + 0, j + 2, k + 17, Block.grass.blockID);
		var1.setBlock(i + 0, j + 2, k + 18, Block.grass.blockID);
		var1.setBlock(i + 0, j + 2, k + 19, Block.grass.blockID);
		var1.setBlock(i + 0, j + 2, k + 20, Block.grass.blockID);
		var1.setBlock(i + 0, j + 2, k + 21, Block.grass.blockID);
		var1.setBlock(i + 0, j + 2, k + 22, Block.grass.blockID);
		var1.setBlock(i + 0, j + 2, k + 23, Block.grass.blockID);
		var1.setBlock(i + 0, j + 2, k + 24, Block.grass.blockID);
		var1.setBlock(i + 0, j + 2, k + 25, Block.grass.blockID);
		var1.setBlock(i + 0, j + 2, k + 26, Block.grass.blockID);
		var1.setBlock(i + 1, j + 0, k + 0, Block.dirt.blockID);
		var1.setBlock(i + 1, j + 0, k + 1, Block.dirt.blockID);
		var1.setBlock(i + 1, j + 0, k + 2, Block.dirt.blockID);
		var1.setBlock(i + 1, j + 0, k + 3, Block.dirt.blockID);
		var1.setBlock(i + 1, j + 0, k + 4, Block.dirt.blockID);
		var1.setBlock(i + 1, j + 0, k + 5, Block.dirt.blockID);
		var1.setBlock(i + 1, j + 0, k + 6, Block.dirt.blockID);
		var1.setBlock(i + 1, j + 0, k + 7, Block.dirt.blockID);
		var1.setBlock(i + 1, j + 0, k + 8, Block.dirt.blockID);
		var1.setBlock(i + 1, j + 0, k + 9, Block.dirt.blockID);
		var1.setBlock(i + 1, j + 0, k + 10, Block.dirt.blockID);
		var1.setBlock(i + 1, j + 0, k + 11, Block.dirt.blockID);
		var1.setBlock(i + 1, j + 0, k + 12, Block.dirt.blockID);
		var1.setBlock(i + 1, j + 0, k + 13, Block.dirt.blockID);
		var1.setBlock(i + 1, j + 0, k + 14, Block.dirt.blockID);
		var1.setBlock(i + 1, j + 0, k + 15, Block.dirt.blockID);
		var1.setBlock(i + 1, j + 0, k + 16, Block.dirt.blockID);
		var1.setBlock(i + 1, j + 0, k + 17, Block.dirt.blockID);
		var1.setBlock(i + 1, j + 0, k + 18, Block.dirt.blockID);
		var1.setBlock(i + 1, j + 0, k + 19, Block.dirt.blockID);
		var1.setBlock(i + 1, j + 0, k + 20, Block.dirt.blockID);
		var1.setBlock(i + 1, j + 0, k + 21, Block.dirt.blockID);
		var1.setBlock(i + 1, j + 0, k + 22, Block.dirt.blockID);
		var1.setBlock(i + 1, j + 0, k + 23, Block.dirt.blockID);
		var1.setBlock(i + 1, j + 0, k + 24, Block.dirt.blockID);
		var1.setBlock(i + 1, j + 0, k + 25, Block.dirt.blockID);
		var1.setBlock(i + 1, j + 0, k + 26, Block.dirt.blockID);
		var1.setBlock(i + 1, j + 1, k + 0, Block.dirt.blockID);
		var1.setBlock(i + 1, j + 1, k + 1, Block.dirt.blockID);
		var1.setBlock(i + 1, j + 1, k + 2, Block.dirt.blockID);
		var1.setBlock(i + 1, j + 1, k + 3, Block.dirt.blockID);
		var1.setBlock(i + 1, j + 1, k + 4, Block.dirt.blockID);
		var1.setBlock(i + 1, j + 1, k + 5, Block.dirt.blockID);
		var1.setBlock(i + 1, j + 1, k + 6, Block.dirt.blockID);
		var1.setBlock(i + 1, j + 1, k + 7, Block.dirt.blockID);
		var1.setBlock(i + 1, j + 1, k + 8, Block.dirt.blockID);
		var1.setBlock(i + 1, j + 1, k + 9, Block.dirt.blockID);
		var1.setBlock(i + 1, j + 1, k + 10, Block.dirt.blockID);
		var1.setBlock(i + 1, j + 1, k + 11, Block.dirt.blockID);
		var1.setBlock(i + 1, j + 1, k + 12, Block.dirt.blockID);
		var1.setBlock(i + 1, j + 1, k + 13, Block.dirt.blockID);
		var1.setBlock(i + 1, j + 1, k + 14, Block.dirt.blockID);
		var1.setBlock(i + 1, j + 1, k + 15, Block.dirt.blockID);
		var1.setBlock(i + 1, j + 1, k + 16, Block.dirt.blockID);
		var1.setBlock(i + 1, j + 1, k + 17, Block.dirt.blockID);
		var1.setBlock(i + 1, j + 1, k + 18, Block.dirt.blockID);
		var1.setBlock(i + 1, j + 1, k + 19, Block.dirt.blockID);
		var1.setBlock(i + 1, j + 1, k + 20, Block.dirt.blockID);
		var1.setBlock(i + 1, j + 1, k + 21, Block.dirt.blockID);
		var1.setBlock(i + 1, j + 1, k + 22, Block.dirt.blockID);
		var1.setBlock(i + 1, j + 1, k + 23, Block.dirt.blockID);
		var1.setBlock(i + 1, j + 1, k + 24, Block.dirt.blockID);
		var1.setBlock(i + 1, j + 1, k + 25, Block.dirt.blockID);
		var1.setBlock(i + 1, j + 1, k + 26, Block.dirt.blockID);
		var1.setBlock(i + 1, j + 2, k + 0, Block.grass.blockID);
		var1.setBlock(i + 1, j + 2, k + 1, Block.grass.blockID);
		var1.setBlock(i + 1, j + 2, k + 2, Block.grass.blockID);
		var1.setBlock(i + 1, j + 2, k + 3, Block.grass.blockID);
		var1.setBlock(i + 1, j + 2, k + 4, Block.dirt.blockID);
		var1.setBlock(i + 1, j + 2, k + 5, Block.dirt.blockID);
		var1.setBlock(i + 1, j + 2, k + 6, Block.grass.blockID);
		var1.setBlock(i + 1, j + 2, k + 7, Block.grass.blockID);
		var1.setBlock(i + 1, j + 2, k + 8, Block.grass.blockID);
		var1.setBlock(i + 1, j + 2, k + 9, Block.grass.blockID);
		var1.setBlock(i + 1, j + 2, k + 10, Block.grass.blockID);
		var1.setBlock(i + 1, j + 2, k + 11, Block.grass.blockID);
		var1.setBlock(i + 1, j + 2, k + 12, Block.grass.blockID);
		var1.setBlock(i + 1, j + 2, k + 13, Block.grass.blockID);
		var1.setBlock(i + 1, j + 2, k + 14, Block.brick.blockID);
		var1.setBlock(i + 1, j + 2, k + 15, Block.brick.blockID);
		var1.setBlock(i + 1, j + 2, k + 16, Block.grass.blockID);
		var1.setBlock(i + 1, j + 2, k + 17, Block.grass.blockID);
		var1.setBlock(i + 1, j + 2, k + 18, Block.grass.blockID);
		var1.setBlock(i + 1, j + 2, k + 19, Block.dirt.blockID);
		var1.setBlock(i + 1, j + 2, k + 20, Block.dirt.blockID);
		var1.setBlock(i + 1, j + 2, k + 21, Block.grass.blockID);
		var1.setBlock(i + 1, j + 2, k + 22, Block.grass.blockID);
		var1.setBlock(i + 1, j + 2, k + 23, Block.grass.blockID);
		var1.setBlock(i + 1, j + 2, k + 24, Block.brick.blockID);
		var1.setBlock(i + 1, j + 2, k + 25, Block.brick.blockID);
		var1.setBlock(i + 1, j + 2, k + 26, Block.grass.blockID);
		var1.setBlock(i + 1, j + 3, k + 4, Block.brick.blockID);
		var1.setBlock(i + 1, j + 3, k + 5, Block.brick.blockID);
		var1.setBlock(i + 1, j + 3, k + 14, Block.brick.blockID);
		var1.setBlock(i + 1, j + 3, k + 15, Block.brick.blockID);
		var1.setBlock(i + 1, j + 3, k + 19, Block.brick.blockID);
		var1.setBlock(i + 1, j + 3, k + 20, Block.brick.blockID);
		var1.setBlock(i + 1, j + 3, k + 24, Block.brick.blockID);
		var1.setBlock(i + 1, j + 3, k + 25, Block.brick.blockID);
		var1.setBlock(i + 1, j + 4, k + 4, Block.brick.blockID);
		var1.setBlock(i + 1, j + 4, k + 5, Block.brick.blockID);
		var1.setBlock(i + 1, j + 4, k + 14, Block.brick.blockID);
		var1.setBlock(i + 1, j + 4, k + 15, Block.brick.blockID);
		var1.setBlock(i + 1, j + 4, k + 19, Block.brick.blockID);
		var1.setBlock(i + 1, j + 4, k + 20, Block.brick.blockID);
		var1.setBlock(i + 1, j + 4, k + 24, Block.brick.blockID);
		var1.setBlock(i + 1, j + 4, k + 25, Block.brick.blockID);
		var1.setBlock(i + 1, j + 5, k + 4, Block.brick.blockID);
		var1.setBlock(i + 1, j + 5, k + 5, Block.brick.blockID);
		var1.setBlock(i + 1, j + 5, k + 14, Block.brick.blockID);
		var1.setBlock(i + 1, j + 5, k + 15, Block.brick.blockID);
		var1.setBlock(i + 1, j + 5, k + 19, Block.brick.blockID);
		var1.setBlock(i + 1, j + 5, k + 20, Block.brick.blockID);
		var1.setBlock(i + 1, j + 5, k + 24, Block.brick.blockID);
		var1.setBlock(i + 1, j + 5, k + 25, Block.brick.blockID);
		var1.setBlock(i + 1, j + 6, k + 4, Block.brick.blockID);
		var1.setBlock(i + 1, j + 6, k + 5, Block.brick.blockID);
		var1.setBlock(i + 1, j + 6, k + 14, Block.brick.blockID);
		var1.setBlock(i + 1, j + 6, k + 15, Block.brick.blockID);
		var1.setBlock(i + 1, j + 6, k + 19, Block.brick.blockID);
		var1.setBlock(i + 1, j + 6, k + 20, Block.brick.blockID);
		var1.setBlock(i + 1, j + 6, k + 21, Block.brick.blockID);
		var1.setBlock(i + 1, j + 6, k + 22, Block.brick.blockID);
		var1.setBlock(i + 1, j + 6, k + 23, Block.brick.blockID);
		var1.setBlock(i + 1, j + 6, k + 24, Block.brick.blockID);
		var1.setBlock(i + 1, j + 6, k + 25, Block.brick.blockID);
		var1.setBlock(i + 1, j + 7, k + 4, Block.brick.blockID);
		var1.setBlock(i + 1, j + 7, k + 5, Block.brick.blockID);
		var1.setBlock(i + 1, j + 7, k + 14, Block.brick.blockID);
		var1.setBlock(i + 1, j + 7, k + 15, Block.brick.blockID);
		var1.setBlock(i + 1, j + 7, k + 19, Block.brick.blockID);
		var1.setBlock(i + 1, j + 7, k + 20, Block.brick.blockID);
		var1.setBlock(i + 1, j + 7, k + 21, Block.brick.blockID);
		var1.setBlock(i + 1, j + 7, k + 22, Block.brick.blockID);
		var1.setBlock(i + 1, j + 7, k + 23, Block.brick.blockID);
		var1.setBlock(i + 1, j + 7, k + 24, Block.brick.blockID);
		var1.setBlock(i + 1, j + 7, k + 25, Block.brick.blockID);
		var1.setBlock(i + 1, j + 8, k + 4, Block.brick.blockID);
		var1.setBlock(i + 1, j + 8, k + 5, Block.brick.blockID);
		var1.setBlock(i + 1, j + 8, k + 14, Block.brick.blockID);
		var1.setBlock(i + 1, j + 8, k + 15, Block.brick.blockID);
		var1.setBlock(i + 1, j + 8, k + 19, Block.brick.blockID);
		var1.setBlock(i + 1, j + 8, k + 20, Block.brick.blockID);
		var1.setBlock(i + 1, j + 8, k + 24, Block.brick.blockID);
		var1.setBlock(i + 1, j + 8, k + 25, Block.brick.blockID);
		var1.setBlock(i + 1, j + 9, k + 4, Block.brick.blockID);
		var1.setBlock(i + 1, j + 9, k + 5, Block.brick.blockID);
		var1.setBlock(i + 1, j + 9, k + 6, Block.brick.blockID);
		var1.setBlock(i + 1, j + 9, k + 7, Block.brick.blockID);
		var1.setBlock(i + 1, j + 9, k + 8, Block.brick.blockID);
		var1.setBlock(i + 1, j + 9, k + 9, Block.brick.blockID);
		var1.setBlock(i + 1, j + 9, k + 10, Block.brick.blockID);
		var1.setBlock(i + 1, j + 9, k + 11, Block.brick.blockID);
		var1.setBlock(i + 1, j + 9, k + 12, Block.brick.blockID);
		var1.setBlock(i + 1, j + 9, k + 13, Block.brick.blockID);
		var1.setBlock(i + 1, j + 9, k + 14, Block.brick.blockID);
		var1.setBlock(i + 1, j + 9, k + 15, Block.brick.blockID);
		var1.setBlock(i + 1, j + 9, k + 16, Block.web.blockID);
		var1.setBlock(i + 1, j + 9, k + 17, Block.web.blockID);
		var1.setBlock(i + 1, j + 9, k + 19, Block.brick.blockID);
		var1.setBlock(i + 1, j + 9, k + 20, Block.brick.blockID);
		var1.setBlock(i + 1, j + 9, k + 24, Block.brick.blockID);
		var1.setBlock(i + 1, j + 9, k + 25, Block.brick.blockID);
		var1.setBlock(i + 1, j + 10, k + 4, Block.brick.blockID);
		var1.setBlock(i + 1, j + 10, k + 5, Block.brick.blockID);
		var1.setBlock(i + 1, j + 10, k + 6, Block.brick.blockID);
		var1.setBlock(i + 1, j + 10, k + 7, Block.brick.blockID);
		var1.setBlock(i + 1, j + 10, k + 8, Block.brick.blockID);
		var1.setBlock(i + 1, j + 10, k + 9, Block.brick.blockID);
		var1.setBlock(i + 1, j + 10, k + 10, Block.brick.blockID);
		var1.setBlock(i + 1, j + 10, k + 11, Block.brick.blockID);
		var1.setBlock(i + 1, j + 10, k + 12, Block.brick.blockID);
		var1.setBlock(i + 1, j + 10, k + 13, Block.brick.blockID);
		var1.setBlock(i + 1, j + 10, k + 14, Block.brick.blockID);
		var1.setBlock(i + 1, j + 10, k + 15, Block.brick.blockID);
		var1.setBlock(i + 1, j + 10, k + 16, Block.brick.blockID);
		var1.setBlock(i + 1, j + 10, k + 17, Block.brick.blockID);
		var1.setBlock(i + 1, j + 10, k + 18, Block.brick.blockID);
		var1.setBlock(i + 1, j + 10, k + 19, Block.brick.blockID);
		var1.setBlock(i + 1, j + 10, k + 20, Block.brick.blockID);
		var1.setBlock(i + 1, j + 10, k + 21, Block.brick.blockID);
		var1.setBlock(i + 1, j + 10, k + 22, Block.brick.blockID);
		var1.setBlock(i + 1, j + 10, k + 23, Block.brick.blockID);
		var1.setBlock(i + 1, j + 10, k + 24, Block.brick.blockID);
		var1.setBlock(i + 1, j + 10, k + 25, Block.brick.blockID);
		var1.setBlock(i + 1, j + 11, k + 4, Block.brick.blockID);
		var1.setBlock(i + 1, j + 11, k + 5, Block.brick.blockID);
		var1.setBlock(i + 1, j + 11, k + 14, Block.brick.blockID);
		var1.setBlock(i + 1, j + 11, k + 15, Block.brick.blockID);
		var1.setBlock(i + 1, j + 11, k + 16, Block.brick.blockID);
		var1.setBlock(i + 1, j + 11, k + 17, Block.brick.blockID);
		var1.setBlock(i + 1, j + 11, k + 18, Block.brick.blockID);
		var1.setBlock(i + 1, j + 11, k + 19, Block.brick.blockID);
		var1.setBlock(i + 1, j + 11, k + 20, Block.brick.blockID);
		var1.setBlock(i + 1, j + 11, k + 21, Block.brick.blockID);
		var1.setBlock(i + 1, j + 11, k + 22, Block.brick.blockID);
		var1.setBlock(i + 1, j + 11, k + 23, Block.brick.blockID);
		var1.setBlock(i + 1, j + 11, k + 24, Block.brick.blockID);
		var1.setBlock(i + 1, j + 11, k + 25, Block.brick.blockID);
		var1.setBlock(i + 1, j + 12, k + 4, Block.brick.blockID);
		var1.setBlock(i + 1, j + 12, k + 5, Block.brick.blockID);
		var1.setBlock(i + 1, j + 12, k + 14, Block.brick.blockID);
		var1.setBlock(i + 1, j + 12, k + 15, Block.brick.blockID);
		var1.setBlock(i + 1, j + 12, k + 19, Block.stoneBrick.blockID);
		var1.setBlock(i + 1, j + 12, k + 20, Block.stoneBrick.blockID);
		var1.setBlock(i + 1, j + 12, k + 24, Block.brick.blockID);
		var1.setBlock(i + 1, j + 12, k + 25, Block.brick.blockID);
		var1.setBlock(i + 1, j + 13, k + 4, Block.brick.blockID);
		var1.setBlock(i + 1, j + 13, k + 5, Block.brick.blockID);
		var1.setBlock(i + 1, j + 13, k + 6, Block.web.blockID);
		var1.setBlock(i + 1, j + 13, k + 14, Block.brick.blockID);
		var1.setBlock(i + 1, j + 13, k + 15, Block.brick.blockID);
		var1.setBlock(i + 1, j + 13, k + 19, Block.stoneBrick.blockID);
		var1.setBlock(i + 1, j + 13, k + 20, Block.stoneBrick.blockID);
		var1.setBlock(i + 1, j + 13, k + 24, Block.brick.blockID);
		var1.setBlock(i + 1, j + 13, k + 25, Block.brick.blockID);
		var1.setBlock(i + 1, j + 14, k + 4, Block.brick.blockID);
		var1.setBlock(i + 1, j + 14, k + 5, Block.brick.blockID);
		var1.setBlock(i + 1, j + 14, k + 6, Block.stoneBrick.blockID);
		var1.setBlock(i + 1, j + 14, k + 7, Block.stoneBrick.blockID);
		var1.setBlock(i + 1, j + 14, k + 8, Block.stoneBrick.blockID);
		var1.setBlock(i + 1, j + 14, k + 9, Block.stoneBrick.blockID);
		var1.setBlock(i + 1, j + 14, k + 10, Block.stoneBrick.blockID);
		var1.setBlock(i + 1, j + 14, k + 11, Block.stoneBrick.blockID);
		var1.setBlock(i + 1, j + 14, k + 12, Block.stoneBrick.blockID);
		var1.setBlock(i + 1, j + 14, k + 13, Block.stoneBrick.blockID);
		var1.setBlock(i + 1, j + 14, k + 14, Block.brick.blockID);
		var1.setBlock(i + 1, j + 14, k + 15, Block.brick.blockID);
		var1.setBlock(i + 1, j + 14, k + 19, Block.stoneBrick.blockID);
		var1.setBlock(i + 1, j + 14, k + 20, Block.stoneBrick.blockID);
		var1.setBlock(i + 1, j + 14, k + 24, Block.brick.blockID);
		var1.setBlock(i + 1, j + 14, k + 25, Block.brick.blockID);
		var1.setBlock(i + 1, j + 15, k + 4, Block.stoneBrick.blockID);
		var1.setBlock(i + 1, j + 15, k + 5, Block.stoneBrick.blockID);
		var1.setBlock(i + 1, j + 15, k + 6, Block.stoneBrick.blockID);
		var1.setBlock(i + 1, j + 15, k + 7, Block.stoneBrick.blockID);
		var1.setBlock(i + 1, j + 15, k + 8, Block.stoneBrick.blockID);
		var1.setBlock(i + 1, j + 15, k + 9, Block.stoneBrick.blockID);
		var1.setBlock(i + 1, j + 15, k + 10, Block.stoneBrick.blockID);
		var1.setBlock(i + 1, j + 15, k + 11, Block.stoneBrick.blockID);
		var1.setBlock(i + 1, j + 15, k + 12, Block.stoneBrick.blockID);
		var1.setBlock(i + 1, j + 15, k + 13, Block.stoneBrick.blockID);
		var1.setBlock(i + 1, j + 15, k + 14, Block.stoneBrick.blockID);
		var1.setBlock(i + 1, j + 15, k + 15, Block.stoneBrick.blockID);
		var1.setBlock(i + 1, j + 15, k + 19, Block.stoneBrick.blockID);
		var1.setBlock(i + 1, j + 15, k + 20, Block.stoneBrick.blockID);
		var1.setBlock(i + 1, j + 15, k + 24, Block.stoneBrick.blockID);
		var1.setBlock(i + 1, j + 15, k + 25, Block.stoneBrick.blockID);
		var1.setBlock(i + 1, j + 16, k + 14, Block.stoneBrick.blockID);
		var1.setBlock(i + 1, j + 16, k + 15, Block.stoneBrick.blockID);
		var1.setBlock(i + 1, j + 16, k + 16, Block.stoneBrick.blockID);
		var1.setBlock(i + 1, j + 16, k + 17, Block.stoneBrick.blockID);
		var1.setBlock(i + 1, j + 16, k + 18, Block.stoneBrick.blockID);
		var1.setBlock(i + 1, j + 16, k + 19, Block.stoneBrick.blockID);
		var1.setBlock(i + 1, j + 16, k + 20, Block.stoneBrick.blockID);
		var1.setBlock(i + 1, j + 16, k + 21, Block.stoneBrick.blockID);
		var1.setBlock(i + 1, j + 16, k + 22, Block.stoneBrick.blockID);
		var1.setBlock(i + 1, j + 16, k + 23, Block.stoneBrick.blockID);
		var1.setBlock(i + 1, j + 16, k + 24, Block.stoneBrick.blockID);
		var1.setBlock(i + 1, j + 16, k + 25, Block.stoneBrick.blockID);
		var1.setBlock(i + 2, j + 0, k + 0, Block.dirt.blockID);
		var1.setBlock(i + 2, j + 0, k + 1, Block.dirt.blockID);
		var1.setBlock(i + 2, j + 0, k + 2, Block.dirt.blockID);
		var1.setBlock(i + 2, j + 0, k + 3, Block.dirt.blockID);
		var1.setBlock(i + 2, j + 0, k + 4, Block.dirt.blockID);
		var1.setBlock(i + 2, j + 0, k + 5, Block.dirt.blockID);
		var1.setBlock(i + 2, j + 0, k + 6, Block.dirt.blockID);
		var1.setBlock(i + 2, j + 0, k + 7, Block.dirt.blockID);
		var1.setBlock(i + 2, j + 0, k + 8, Block.dirt.blockID);
		var1.setBlock(i + 2, j + 0, k + 9, Block.dirt.blockID);
		var1.setBlock(i + 2, j + 0, k + 10, Block.dirt.blockID);
		var1.setBlock(i + 2, j + 0, k + 11, Block.dirt.blockID);
		var1.setBlock(i + 2, j + 0, k + 12, Block.dirt.blockID);
		var1.setBlock(i + 2, j + 0, k + 13, Block.dirt.blockID);
		var1.setBlock(i + 2, j + 0, k + 14, Block.dirt.blockID);
		var1.setBlock(i + 2, j + 0, k + 15, Block.dirt.blockID);
		var1.setBlock(i + 2, j + 0, k + 16, Block.dirt.blockID);
		var1.setBlock(i + 2, j + 0, k + 17, Block.dirt.blockID);
		var1.setBlock(i + 2, j + 0, k + 18, Block.dirt.blockID);
		var1.setBlock(i + 2, j + 0, k + 19, Block.dirt.blockID);
		var1.setBlock(i + 2, j + 0, k + 20, Block.dirt.blockID);
		var1.setBlock(i + 2, j + 0, k + 21, Block.dirt.blockID);
		var1.setBlock(i + 2, j + 0, k + 22, Block.dirt.blockID);
		var1.setBlock(i + 2, j + 0, k + 23, Block.dirt.blockID);
		var1.setBlock(i + 2, j + 0, k + 24, Block.dirt.blockID);
		var1.setBlock(i + 2, j + 0, k + 25, Block.dirt.blockID);
		var1.setBlock(i + 2, j + 0, k + 26, Block.dirt.blockID);
		var1.setBlock(i + 2, j + 1, k + 0, Block.dirt.blockID);
		var1.setBlock(i + 2, j + 1, k + 1, Block.dirt.blockID);
		var1.setBlock(i + 2, j + 1, k + 2, Block.dirt.blockID);
		var1.setBlock(i + 2, j + 1, k + 3, Block.dirt.blockID);
		var1.setBlock(i + 2, j + 1, k + 4, Block.dirt.blockID);
		var1.setBlock(i + 2, j + 1, k + 5, Block.dirt.blockID);
		var1.setBlock(i + 2, j + 1, k + 6, Block.dirt.blockID);
		var1.setBlock(i + 2, j + 1, k + 7, Block.dirt.blockID);
		var1.setBlock(i + 2, j + 1, k + 8, Block.dirt.blockID);
		var1.setBlock(i + 2, j + 1, k + 9, Block.dirt.blockID);
		var1.setBlock(i + 2, j + 1, k + 10, Block.dirt.blockID);
		var1.setBlock(i + 2, j + 1, k + 11, Block.dirt.blockID);
		var1.setBlock(i + 2, j + 1, k + 12, Block.dirt.blockID);
		var1.setBlock(i + 2, j + 1, k + 13, Block.dirt.blockID);
		var1.setBlock(i + 2, j + 1, k + 14, Block.dirt.blockID);
		var1.setBlock(i + 2, j + 1, k + 15, Block.dirt.blockID);
		var1.setBlock(i + 2, j + 1, k + 16, Block.dirt.blockID);
		var1.setBlock(i + 2, j + 1, k + 17, Block.dirt.blockID);
		var1.setBlock(i + 2, j + 1, k + 18, Block.dirt.blockID);
		var1.setBlock(i + 2, j + 1, k + 19, Block.dirt.blockID);
		var1.setBlock(i + 2, j + 1, k + 20, Block.dirt.blockID);
		var1.setBlock(i + 2, j + 1, k + 21, Block.dirt.blockID);
		var1.setBlock(i + 2, j + 1, k + 22, Block.dirt.blockID);
		var1.setBlock(i + 2, j + 1, k + 23, Block.dirt.blockID);
		var1.setBlock(i + 2, j + 1, k + 24, Block.dirt.blockID);
		var1.setBlock(i + 2, j + 1, k + 25, Block.dirt.blockID);
		var1.setBlock(i + 2, j + 1, k + 26, Block.dirt.blockID);
		var1.setBlock(i + 2, j + 2, k + 0, Block.grass.blockID);
		var1.setBlock(i + 2, j + 2, k + 1, Block.grass.blockID);
		var1.setBlock(i + 2, j + 2, k + 2, Block.grass.blockID);
		var1.setBlock(i + 2, j + 2, k + 3, Block.grass.blockID);
		var1.setBlock(i + 2, j + 2, k + 4, Block.dirt.blockID);
		var1.setBlock(i + 2, j + 2, k + 5, Block.brick.blockID);
		var1.setBlock(i + 2, j + 2, k + 6, Block.stoneBrick.blockID);
		var1.setBlock(i + 2, j + 2, k + 7, Block.stoneBrick.blockID);
		var1.setBlock(i + 2, j + 2, k + 8, Block.stoneBrick.blockID);
		var1.setBlock(i + 2, j + 2, k + 9, Block.stoneBrick.blockID);
		var1.setBlock(i + 2, j + 2, k + 10, Block.stoneBrick.blockID);
		var1.setBlock(i + 2, j + 2, k + 11, Block.stoneBrick.blockID);
		var1.setBlock(i + 2, j + 2, k + 12, Block.stoneBrick.blockID);
		var1.setBlock(i + 2, j + 2, k + 13, Block.stoneBrick.blockID);
		var1.setBlock(i + 2, j + 2, k + 14, Block.brick.blockID);
		var1.setBlock(i + 2, j + 2, k + 15, Block.brick.blockID);
		var1.setBlock(i + 2, j + 2, k + 16, Block.stoneBrick.blockID);
		var1.setBlock(i + 2, j + 2, k + 17, Block.stoneBrick.blockID);
		var1.setBlock(i + 2, j + 2, k + 18, Block.stoneBrick.blockID);
		var1.setBlock(i + 2, j + 2, k + 19, Block.brick.blockID);
		var1.setBlock(i + 2, j + 2, k + 20, Block.brick.blockID);
		var1.setBlock(i + 2, j + 2, k + 21, Block.stoneBrick.blockID);
		var1.setBlock(i + 2, j + 2, k + 22, Block.stoneBrick.blockID);
		var1.setBlock(i + 2, j + 2, k + 23, Block.stoneBrick.blockID);
		var1.setBlock(i + 2, j + 2, k + 24, Block.brick.blockID);
		var1.setBlock(i + 2, j + 2, k + 25, Block.brick.blockID);
		var1.setBlock(i + 2, j + 2, k + 26, Block.grass.blockID);
		var1.setBlock(i + 2, j + 3, k + 4, Block.brick.blockID);
		var1.setBlock(i + 2, j + 3, k + 5, Block.brick.blockID);
		var1.setBlockAndMetadata(i + 2, j + 3, k + 6, Block.stoneBrick.blockID, 1);
		var1.setBlock(i + 2, j + 3, k + 7, Block.stoneBrick.blockID);
		var1.setBlock(i + 2, j + 3, k + 8, Block.stoneBrick.blockID);
		var1.setBlock(i + 2, j + 3, k + 9, Block.stoneBrick.blockID);
		var1.setBlockAndMetadata(i + 2, j + 3, k + 10, Block.stoneBrick.blockID, 2);
		var1.setBlock(i + 2, j + 3, k + 11, Block.stoneBrick.blockID);
		var1.setBlock(i + 2, j + 3, k + 12, Block.stoneBrick.blockID);
		var1.setBlock(i + 2, j + 3, k + 13, Block.stoneBrick.blockID);
		var1.setBlock(i + 2, j + 3, k + 14, Block.brick.blockID);
		var1.setBlock(i + 2, j + 3, k + 15, Block.brick.blockID);
		var1.setBlock(i + 2, j + 3, k + 16, Block.stoneBrick.blockID);
		var1.setBlock(i + 2, j + 3, k + 17, Block.stoneBrick.blockID);
		var1.setBlock(i + 2, j + 3, k + 18, Block.stoneBrick.blockID);
		var1.setBlock(i + 2, j + 3, k + 19, Block.brick.blockID);
		var1.setBlock(i + 2, j + 3, k + 20, Block.brick.blockID);
		var1.setBlock(i + 2, j + 3, k + 21, Block.stoneBrick.blockID);
		var1.setBlock(i + 2, j + 3, k + 22, Block.stoneBrick.blockID);
		var1.setBlock(i + 2, j + 3, k + 23, Block.stoneBrick.blockID);
		var1.setBlock(i + 2, j + 3, k + 24, Block.brick.blockID);
		var1.setBlock(i + 2, j + 3, k + 25, Block.brick.blockID);
		var1.setBlock(i + 2, j + 4, k + 4, Block.brick.blockID);
		var1.setBlock(i + 2, j + 4, k + 5, Block.brick.blockID);
		var1.setBlock(i + 2, j + 4, k + 6, Block.stoneBrick.blockID);
		var1.setBlock(i + 2, j + 4, k + 7, Block.stoneBrick.blockID);
		var1.setBlock(i + 2, j + 4, k + 8, Block.stoneBrick.blockID);
		var1.setBlock(i + 2, j + 4, k + 9, Block.stoneBrick.blockID);
		var1.setBlock(i + 2, j + 4, k + 10, Block.stoneBrick.blockID);
		var1.setBlock(i + 2, j + 4, k + 11, Block.stoneBrick.blockID);
		var1.setBlock(i + 2, j + 4, k + 12, Block.stoneBrick.blockID);
		var1.setBlockAndMetadata(i + 2, j + 4, k + 13, Block.stoneBrick.blockID, 2);
		var1.setBlock(i + 2, j + 4, k + 14, Block.brick.blockID);
		var1.setBlock(i + 2, j + 4, k + 15, Block.brick.blockID);
		var1.setBlock(i + 2, j + 4, k + 16, Block.stoneBrick.blockID);
		var1.setBlock(i + 2, j + 4, k + 17, Block.stoneBrick.blockID);
		var1.setBlock(i + 2, j + 4, k + 18, Block.stoneBrick.blockID);
		var1.setBlock(i + 2, j + 4, k + 19, Block.brick.blockID);
		var1.setBlock(i + 2, j + 4, k + 20, Block.brick.blockID);
		var1.setBlock(i + 2, j + 4, k + 21, Block.stoneBrick.blockID);
		var1.setBlock(i + 2, j + 4, k + 22, Block.stoneBrick.blockID);
		var1.setBlock(i + 2, j + 4, k + 23, Block.stoneBrick.blockID);
		var1.setBlock(i + 2, j + 4, k + 24, Block.brick.blockID);
		var1.setBlock(i + 2, j + 4, k + 25, Block.brick.blockID);
		var1.setBlock(i + 2, j + 5, k + 4, Block.brick.blockID);
		var1.setBlock(i + 2, j + 5, k + 5, Block.brick.blockID);
		var1.setBlock(i + 2, j + 5, k + 6, Block.stoneBrick.blockID);
		var1.setBlock(i + 2, j + 5, k + 7, Block.stoneBrick.blockID);
		var1.setBlock(i + 2, j + 5, k + 8, Block.thinGlass.blockID);
		var1.setBlock(i + 2, j + 5, k + 9, Block.stoneBrick.blockID);
		var1.setBlock(i + 2, j + 5, k + 10, Block.thinGlass.blockID);
		var1.setBlock(i + 2, j + 5, k + 11, Block.stoneBrick.blockID);
		var1.setBlock(i + 2, j + 5, k + 12, Block.thinGlass.blockID);
		var1.setBlock(i + 2, j + 5, k + 13, Block.stoneBrick.blockID);
		var1.setBlock(i + 2, j + 5, k + 14, Block.brick.blockID);
		var1.setBlock(i + 2, j + 5, k + 15, Block.brick.blockID);
		var1.setBlock(i + 2, j + 5, k + 16, Block.thinGlass.blockID);
		var1.setBlock(i + 2, j + 5, k + 17, Block.stoneBrick.blockID);
		var1.setBlock(i + 2, j + 5, k + 18, Block.stoneBrick.blockID);
		var1.setBlock(i + 2, j + 5, k + 19, Block.brick.blockID);
		var1.setBlock(i + 2, j + 5, k + 20, Block.brick.blockID);
		var1.setBlock(i + 2, j + 5, k + 21, Block.stoneBrick.blockID);
		var1.setBlock(i + 2, j + 5, k + 22, Block.stoneBrick.blockID);
		var1.setBlock(i + 2, j + 5, k + 23, Block.stoneBrick.blockID);
		var1.setBlock(i + 2, j + 5, k + 24, Block.brick.blockID);
		var1.setBlock(i + 2, j + 5, k + 25, Block.brick.blockID);
		var1.setBlock(i + 2, j + 6, k + 4, Block.brick.blockID);
		var1.setBlock(i + 2, j + 6, k + 5, Block.brick.blockID);
		var1.setBlock(i + 2, j + 6, k + 6, Block.stoneBrick.blockID);
		var1.setBlock(i + 2, j + 6, k + 7, Block.stoneBrick.blockID);
		var1.setBlock(i + 2, j + 6, k + 8, Block.thinGlass.blockID);
		var1.setBlock(i + 2, j + 6, k + 9, Block.stoneBrick.blockID);
		var1.setBlock(i + 2, j + 6, k + 10, Block.thinGlass.blockID);
		var1.setBlock(i + 2, j + 6, k + 11, Block.stoneBrick.blockID);
		var1.setBlock(i + 2, j + 6, k + 12, Block.thinGlass.blockID);
		var1.setBlock(i + 2, j + 6, k + 13, Block.stoneBrick.blockID);
		var1.setBlock(i + 2, j + 6, k + 14, Block.brick.blockID);
		var1.setBlock(i + 2, j + 6, k + 15, Block.brick.blockID);
		var1.setBlock(i + 2, j + 6, k + 16, Block.thinGlass.blockID);
		var1.setBlock(i + 2, j + 6, k + 17, Block.stoneBrick.blockID);
		var1.setBlock(i + 2, j + 6, k + 18, Block.thinGlass.blockID);
		var1.setBlock(i + 2, j + 6, k + 19, Block.brick.blockID);
		var1.setBlock(i + 2, j + 6, k + 20, Block.brick.blockID);
		var1.setBlock(i + 2, j + 6, k + 21, Block.brick.blockID);
		var1.setBlock(i + 2, j + 6, k + 22, Block.brick.blockID);
		var1.setBlock(i + 2, j + 6, k + 23, Block.brick.blockID);
		var1.setBlock(i + 2, j + 6, k + 24, Block.brick.blockID);
		var1.setBlock(i + 2, j + 6, k + 25, Block.brick.blockID);
		var1.setBlock(i + 2, j + 7, k + 4, Block.brick.blockID);
		var1.setBlock(i + 2, j + 7, k + 5, Block.brick.blockID);
		var1.setBlock(i + 2, j + 7, k + 6, Block.stoneBrick.blockID);
		var1.setBlock(i + 2, j + 7, k + 7, Block.stoneBrick.blockID);
		var1.setBlock(i + 2, j + 7, k + 8, Block.thinGlass.blockID);
		var1.setBlock(i + 2, j + 7, k + 9, Block.stoneBrick.blockID);
		var1.setBlock(i + 2, j + 7, k + 10, Block.thinGlass.blockID);
		var1.setBlock(i + 2, j + 7, k + 11, Block.stoneBrick.blockID);
		var1.setBlock(i + 2, j + 7, k + 12, Block.thinGlass.blockID);
		var1.setBlock(i + 2, j + 7, k + 13, Block.stoneBrick.blockID);
		var1.setBlock(i + 2, j + 7, k + 14, Block.brick.blockID);
		var1.setBlock(i + 2, j + 7, k + 15, Block.brick.blockID);
		var1.setBlock(i + 2, j + 7, k + 16, Block.thinGlass.blockID);
		var1.setBlock(i + 2, j + 7, k + 17, Block.stoneBrick.blockID);
		var1.setBlock(i + 2, j + 7, k + 18, Block.thinGlass.blockID);
		var1.setBlock(i + 2, j + 7, k + 19, Block.brick.blockID);
		var1.setBlock(i + 2, j + 7, k + 20, Block.brick.blockID);
		var1.setBlock(i + 2, j + 7, k + 21, Block.brick.blockID);
		var1.setBlock(i + 2, j + 7, k + 22, Block.brick.blockID);
		var1.setBlock(i + 2, j + 7, k + 23, Block.brick.blockID);
		var1.setBlock(i + 2, j + 7, k + 24, Block.brick.blockID);
		var1.setBlock(i + 2, j + 7, k + 25, Block.brick.blockID);
		var1.setBlock(i + 2, j + 8, k + 4, Block.brick.blockID);
		var1.setBlock(i + 2, j + 8, k + 5, Block.brick.blockID);
		var1.setBlock(i + 2, j + 8, k + 6, Block.stoneBrick.blockID);
		var1.setBlock(i + 2, j + 8, k + 7, Block.stoneBrick.blockID);
		var1.setBlock(i + 2, j + 8, k + 8, Block.stoneBrick.blockID);
		var1.setBlock(i + 2, j + 8, k + 9, Block.stoneBrick.blockID);
		var1.setBlock(i + 2, j + 8, k + 10, Block.stoneBrick.blockID);
		var1.setBlock(i + 2, j + 8, k + 11, Block.stoneBrick.blockID);
		var1.setBlock(i + 2, j + 8, k + 12, Block.stoneBrick.blockID);
		var1.setBlock(i + 2, j + 8, k + 13, Block.stoneBrick.blockID);
		var1.setBlock(i + 2, j + 8, k + 14, Block.brick.blockID);
		var1.setBlock(i + 2, j + 8, k + 15, Block.brick.blockID);
		var1.setBlock(i + 2, j + 8, k + 16, Block.stoneBrick.blockID);
		var1.setBlock(i + 2, j + 8, k + 17, Block.stoneBrick.blockID);
		var1.setBlock(i + 2, j + 8, k + 18, Block.thinGlass.blockID);
		var1.setBlock(i + 2, j + 8, k + 19, Block.brick.blockID);
		var1.setBlock(i + 2, j + 8, k + 20, Block.brick.blockID);
		var1.setBlock(i + 2, j + 8, k + 21, Block.thinGlass.blockID);
		var1.setBlock(i + 2, j + 8, k + 22, Block.thinGlass.blockID);
		var1.setBlock(i + 2, j + 8, k + 23, Block.thinGlass.blockID);
		var1.setBlock(i + 2, j + 8, k + 24, Block.brick.blockID);
		var1.setBlock(i + 2, j + 8, k + 25, Block.brick.blockID);
		var1.setBlock(i + 2, j + 9, k + 4, Block.brick.blockID);
		var1.setBlock(i + 2, j + 9, k + 5, Block.brick.blockID);
		var1.setBlock(i + 2, j + 9, k + 6, Block.brick.blockID);
		var1.setBlock(i + 2, j + 9, k + 7, Block.brick.blockID);
		var1.setBlock(i + 2, j + 9, k + 8, Block.brick.blockID);
		var1.setBlock(i + 2, j + 9, k + 9, Block.brick.blockID);
		var1.setBlock(i + 2, j + 9, k + 10, Block.brick.blockID);
		var1.setBlock(i + 2, j + 9, k + 11, Block.brick.blockID);
		var1.setBlock(i + 2, j + 9, k + 12, Block.brick.blockID);
		var1.setBlock(i + 2, j + 9, k + 13, Block.brick.blockID);
		var1.setBlock(i + 2, j + 9, k + 14, Block.brick.blockID);
		var1.setBlock(i + 2, j + 9, k + 15, Block.brick.blockID);
		var1.setBlock(i + 2, j + 9, k + 16, Block.stoneBrick.blockID);
		var1.setBlock(i + 2, j + 9, k + 17, Block.stoneBrick.blockID);
		var1.setBlock(i + 2, j + 9, k + 18, Block.stoneBrick.blockID);
		var1.setBlock(i + 2, j + 9, k + 19, Block.brick.blockID);
		var1.setBlock(i + 2, j + 9, k + 20, Block.brick.blockID);
		var1.setBlock(i + 2, j + 9, k + 21, Block.thinGlass.blockID);
		var1.setBlock(i + 2, j + 9, k + 22, Block.thinGlass.blockID);
		var1.setBlock(i + 2, j + 9, k + 23, Block.thinGlass.blockID);
		var1.setBlock(i + 2, j + 9, k + 24, Block.brick.blockID);
		var1.setBlock(i + 2, j + 9, k + 25, Block.brick.blockID);
		var1.setBlock(i + 2, j + 10, k + 4, Block.brick.blockID);
		var1.setBlock(i + 2, j + 10, k + 5, Block.brick.blockID);
		var1.setBlock(i + 2, j + 10, k + 6, Block.brick.blockID);
		var1.setBlock(i + 2, j + 10, k + 7, Block.brick.blockID);
		var1.setBlock(i + 2, j + 10, k + 8, Block.brick.blockID);
		var1.setBlock(i + 2, j + 10, k + 9, Block.brick.blockID);
		var1.setBlock(i + 2, j + 10, k + 10, Block.brick.blockID);
		var1.setBlock(i + 2, j + 10, k + 11, Block.brick.blockID);
		var1.setBlock(i + 2, j + 10, k + 12, Block.brick.blockID);
		var1.setBlock(i + 2, j + 10, k + 13, Block.brick.blockID);
		var1.setBlock(i + 2, j + 10, k + 14, Block.brick.blockID);
		var1.setBlock(i + 2, j + 10, k + 15, Block.brick.blockID);
		var1.setBlock(i + 2, j + 10, k + 16, Block.brick.blockID);
		var1.setBlock(i + 2, j + 10, k + 17, Block.brick.blockID);
		var1.setBlock(i + 2, j + 10, k + 18, Block.brick.blockID);
		var1.setBlock(i + 2, j + 10, k + 19, Block.brick.blockID);
		var1.setBlock(i + 2, j + 10, k + 20, Block.brick.blockID);
		var1.setBlock(i + 2, j + 10, k + 21, Block.brick.blockID);
		var1.setBlock(i + 2, j + 10, k + 22, Block.brick.blockID);
		var1.setBlock(i + 2, j + 10, k + 23, Block.brick.blockID);
		var1.setBlock(i + 2, j + 10, k + 24, Block.brick.blockID);
		var1.setBlock(i + 2, j + 10, k + 25, Block.brick.blockID);
		var1.setBlock(i + 2, j + 11, k + 4, Block.brick.blockID);
		var1.setBlock(i + 2, j + 11, k + 5, Block.brick.blockID);
		var1.setBlock(i + 2, j + 11, k + 6, Block.stoneBrick.blockID);
		var1.setBlock(i + 2, j + 11, k + 7, Block.stoneBrick.blockID);
		var1.setBlock(i + 2, j + 11, k + 8, Block.stoneBrick.blockID);
		var1.setBlock(i + 2, j + 11, k + 9, Block.stoneBrick.blockID);
		var1.setBlock(i + 2, j + 11, k + 10, Block.stoneBrick.blockID);
		var1.setBlock(i + 2, j + 11, k + 11, Block.stoneBrick.blockID);
		var1.setBlock(i + 2, j + 11, k + 12, Block.stoneBrick.blockID);
		var1.setBlock(i + 2, j + 11, k + 13, Block.stoneBrick.blockID);
		var1.setBlock(i + 2, j + 11, k + 14, Block.brick.blockID);
		var1.setBlock(i + 2, j + 11, k + 15, Block.brick.blockID);
		var1.setBlock(i + 2, j + 11, k + 16, Block.brick.blockID);
		var1.setBlock(i + 2, j + 11, k + 17, Block.brick.blockID);
		var1.setBlock(i + 2, j + 11, k + 18, Block.brick.blockID);
		var1.setBlock(i + 2, j + 11, k + 19, Block.brick.blockID);
		var1.setBlock(i + 2, j + 11, k + 20, Block.brick.blockID);
		var1.setBlock(i + 2, j + 11, k + 21, Block.brick.blockID);
		var1.setBlock(i + 2, j + 11, k + 22, Block.brick.blockID);
		var1.setBlock(i + 2, j + 11, k + 23, Block.brick.blockID);
		var1.setBlock(i + 2, j + 11, k + 24, Block.brick.blockID);
		var1.setBlock(i + 2, j + 11, k + 25, Block.brick.blockID);
		var1.setBlock(i + 2, j + 12, k + 4, Block.brick.blockID);
		var1.setBlock(i + 2, j + 12, k + 5, Block.brick.blockID);
		var1.setBlock(i + 2, j + 12, k + 6, Block.stoneBrick.blockID);
		var1.setBlock(i + 2, j + 12, k + 7, Block.stoneBrick.blockID);
		var1.setBlock(i + 2, j + 12, k + 8, Block.stoneBrick.blockID);
		var1.setBlock(i + 2, j + 12, k + 9, Block.stoneBrick.blockID);
		var1.setBlock(i + 2, j + 12, k + 10, Block.stoneBrick.blockID);
		var1.setBlock(i + 2, j + 12, k + 11, Block.stoneBrick.blockID);
		var1.setBlock(i + 2, j + 12, k + 12, Block.stoneBrick.blockID);
		var1.setBlock(i + 2, j + 12, k + 13, Block.stoneBrick.blockID);
		var1.setBlock(i + 2, j + 12, k + 14, Block.brick.blockID);
		var1.setBlock(i + 2, j + 12, k + 15, Block.brick.blockID);
		var1.setBlock(i + 2, j + 12, k + 16, Block.stoneBrick.blockID);
		var1.setBlock(i + 2, j + 12, k + 17, Block.stoneBrick.blockID);
		var1.setBlock(i + 2, j + 12, k + 18, Block.stoneBrick.blockID);
		var1.setBlock(i + 2, j + 12, k + 19, Block.stoneBrick.blockID);
		var1.setBlock(i + 2, j + 12, k + 20, Block.stoneBrick.blockID);
		var1.setBlock(i + 2, j + 12, k + 21, Block.stoneBrick.blockID);
		var1.setBlock(i + 2, j + 12, k + 22, Block.stoneBrick.blockID);
		var1.setBlock(i + 2, j + 12, k + 23, Block.stoneBrick.blockID);
		var1.setBlock(i + 2, j + 12, k + 24, Block.brick.blockID);
		var1.setBlock(i + 2, j + 12, k + 25, Block.brick.blockID);
		var1.setBlock(i + 2, j + 13, k + 4, Block.brick.blockID);
		var1.setBlock(i + 2, j + 13, k + 5, Block.brick.blockID);
		var1.setBlock(i + 2, j + 13, k + 6, Block.stoneBrick.blockID);
		var1.setBlock(i + 2, j + 13, k + 7, Block.stoneBrick.blockID);
		var1.setBlock(i + 2, j + 13, k + 8, Block.stoneBrick.blockID);
		var1.setBlock(i + 2, j + 13, k + 9, Block.stoneBrick.blockID);
		var1.setBlock(i + 2, j + 13, k + 10, Block.stoneBrick.blockID);
		var1.setBlock(i + 2, j + 13, k + 11, Block.stoneBrick.blockID);
		var1.setBlock(i + 2, j + 13, k + 12, Block.stoneBrick.blockID);
		var1.setBlock(i + 2, j + 13, k + 13, Block.stoneBrick.blockID);
		var1.setBlock(i + 2, j + 13, k + 14, Block.brick.blockID);
		var1.setBlock(i + 2, j + 13, k + 15, Block.brick.blockID);
		var1.setBlock(i + 2, j + 13, k + 16, Block.stoneBrick.blockID);
		var1.setBlock(i + 2, j + 13, k + 17, Block.stoneBrick.blockID);
		var1.setBlock(i + 2, j + 13, k + 18, Block.stoneBrick.blockID);
		var1.setBlock(i + 2, j + 13, k + 19, Block.stoneBrick.blockID);
		var1.setBlock(i + 2, j + 13, k + 20, Block.stoneBrick.blockID);
		var1.setBlock(i + 2, j + 13, k + 21, Block.stoneBrick.blockID);
		var1.setBlock(i + 2, j + 13, k + 22, Block.stoneBrick.blockID);
		var1.setBlock(i + 2, j + 13, k + 23, Block.stoneBrick.blockID);
		var1.setBlock(i + 2, j + 13, k + 24, Block.brick.blockID);
		var1.setBlock(i + 2, j + 13, k + 25, Block.brick.blockID);
		var1.setBlock(i + 2, j + 14, k + 4, Block.brick.blockID);
		var1.setBlock(i + 2, j + 14, k + 5, Block.brick.blockID);
		var1.setBlock(i + 2, j + 14, k + 6, Block.stoneBrick.blockID);
		var1.setBlock(i + 2, j + 14, k + 7, Block.stoneBrick.blockID);
		var1.setBlock(i + 2, j + 14, k + 8, Block.stoneBrick.blockID);
		var1.setBlock(i + 2, j + 14, k + 9, Block.stoneBrick.blockID);
		var1.setBlock(i + 2, j + 14, k + 10, Block.stoneBrick.blockID);
		var1.setBlock(i + 2, j + 14, k + 11, Block.stoneBrick.blockID);
		var1.setBlock(i + 2, j + 14, k + 12, Block.stoneBrick.blockID);
		var1.setBlock(i + 2, j + 14, k + 13, Block.stoneBrick.blockID);
		var1.setBlock(i + 2, j + 14, k + 14, Block.brick.blockID);
		var1.setBlock(i + 2, j + 14, k + 15, Block.brick.blockID);
		var1.setBlock(i + 2, j + 14, k + 16, Block.stoneBrick.blockID);
		var1.setBlock(i + 2, j + 14, k + 17, Block.stoneBrick.blockID);
		var1.setBlock(i + 2, j + 14, k + 18, Block.stoneBrick.blockID);
		var1.setBlock(i + 2, j + 14, k + 19, Block.stoneBrick.blockID);
		var1.setBlock(i + 2, j + 14, k + 20, Block.stoneBrick.blockID);
		var1.setBlock(i + 2, j + 14, k + 21, Block.stoneBrick.blockID);
		var1.setBlock(i + 2, j + 14, k + 22, Block.thinGlass.blockID);
		var1.setBlock(i + 2, j + 14, k + 23, Block.stoneBrick.blockID);
		var1.setBlock(i + 2, j + 14, k + 24, Block.brick.blockID);
		var1.setBlock(i + 2, j + 14, k + 25, Block.brick.blockID);
		var1.setBlock(i + 2, j + 15, k + 4, Block.stoneBrick.blockID);
		var1.setBlock(i + 2, j + 15, k + 14, Block.stoneBrick.blockID);
		var1.setBlock(i + 2, j + 15, k + 15, Block.stoneBrick.blockID);
		var1.setBlock(i + 2, j + 15, k + 16, Block.stoneBrick.blockID);
		var1.setBlock(i + 2, j + 15, k + 17, Block.stoneBrick.blockID);
		var1.setBlock(i + 2, j + 15, k + 18, Block.stoneBrick.blockID);
		var1.setBlock(i + 2, j + 15, k + 19, Block.stoneBrick.blockID);
		var1.setBlock(i + 2, j + 15, k + 20, Block.stoneBrick.blockID);
		var1.setBlock(i + 2, j + 15, k + 21, Block.stoneBrick.blockID);
		var1.setBlock(i + 2, j + 15, k + 22, Block.thinGlass.blockID);
		var1.setBlock(i + 2, j + 15, k + 23, Block.stoneBrick.blockID);
		var1.setBlock(i + 2, j + 15, k + 24, Block.stoneBrick.blockID);
		var1.setBlock(i + 2, j + 15, k + 25, Block.stoneBrick.blockID);
		var1.setBlock(i + 2, j + 16, k + 14, Block.stoneBrick.blockID);
		var1.setBlock(i + 2, j + 16, k + 15, Block.stoneBrick.blockID);
		var1.setBlock(i + 2, j + 16, k + 16, Block.stoneBrick.blockID);
		var1.setBlock(i + 2, j + 16, k + 17, Block.stoneBrick.blockID);
		var1.setBlock(i + 2, j + 16, k + 18, Block.stoneBrick.blockID);
		var1.setBlock(i + 2, j + 16, k + 19, Block.stoneBrick.blockID);
		var1.setBlock(i + 2, j + 16, k + 20, Block.stoneBrick.blockID);
		var1.setBlock(i + 2, j + 16, k + 21, Block.stoneBrick.blockID);
		var1.setBlock(i + 2, j + 16, k + 22, Block.stoneBrick.blockID);
		var1.setBlock(i + 2, j + 16, k + 23, Block.stoneBrick.blockID);
		var1.setBlock(i + 2, j + 16, k + 24, Block.stoneBrick.blockID);
		var1.setBlock(i + 2, j + 16, k + 25, Block.stoneBrick.blockID);
		var1.setBlock(i + 2, j + 17, k + 15, Block.stoneBrick.blockID);
		var1.setBlock(i + 2, j + 17, k + 16, Block.stoneBrick.blockID);
		var1.setBlock(i + 2, j + 17, k + 17, Block.thinGlass.blockID);
		var1.setBlock(i + 2, j + 17, k + 18, Block.stoneBrick.blockID);
		var1.setBlock(i + 2, j + 17, k + 19, Block.stoneBrick.blockID);
		var1.setBlock(i + 2, j + 17, k + 20, Block.stoneBrick.blockID);
		var1.setBlock(i + 2, j + 17, k + 21, Block.stoneBrick.blockID);
		var1.setBlock(i + 2, j + 17, k + 22, Block.stoneBrick.blockID);
		var1.setBlock(i + 2, j + 17, k + 23, Block.stoneBrick.blockID);
		var1.setBlock(i + 2, j + 17, k + 24, Block.stoneBrick.blockID);
		var1.setBlock(i + 2, j + 17, k + 25, Block.stoneBrick.blockID);
		var1.setBlock(i + 2, j + 18, k + 15, Block.stoneBrick.blockID);
		var1.setBlock(i + 2, j + 18, k + 16, Block.stoneBrick.blockID);
		var1.setBlock(i + 2, j + 18, k + 17, Block.thinGlass.blockID);
		var1.setBlock(i + 2, j + 18, k + 18, Block.stoneBrick.blockID);
		var1.setBlock(i + 2, j + 18, k + 19, Block.stoneBrick.blockID);
		var1.setBlock(i + 2, j + 18, k + 20, Block.stoneBrick.blockID);
		var1.setBlock(i + 2, j + 18, k + 21, Block.stoneBrick.blockID);
		var1.setBlock(i + 2, j + 19, k + 15, Block.stoneBrick.blockID);
		var1.setBlock(i + 2, j + 19, k + 16, Block.stoneBrick.blockID);
		var1.setBlock(i + 2, j + 19, k + 17, Block.stoneBrick.blockID);
		var1.setBlock(i + 2, j + 19, k + 18, Block.stoneBrick.blockID);
		var1.setBlock(i + 2, j + 19, k + 19, Block.stoneBrick.blockID);
		var1.setBlock(i + 2, j + 19, k + 20, Block.stoneBrick.blockID);
		var1.setBlock(i + 2, j + 19, k + 21, Block.stoneBrick.blockID);
		var1.setBlock(i + 3, j + 0, k + 0, Block.dirt.blockID);
		var1.setBlock(i + 3, j + 0, k + 1, Block.dirt.blockID);
		var1.setBlock(i + 3, j + 0, k + 2, Block.dirt.blockID);
		var1.setBlock(i + 3, j + 0, k + 3, Block.dirt.blockID);
		var1.setBlock(i + 3, j + 0, k + 4, Block.dirt.blockID);
		var1.setBlock(i + 3, j + 0, k + 5, Block.dirt.blockID);
		var1.setBlock(i + 3, j + 0, k + 6, Block.dirt.blockID);
		var1.setBlock(i + 3, j + 0, k + 7, Block.dirt.blockID);
		var1.setBlock(i + 3, j + 0, k + 8, Block.dirt.blockID);
		var1.setBlock(i + 3, j + 0, k + 9, Block.dirt.blockID);
		var1.setBlock(i + 3, j + 0, k + 10, Block.dirt.blockID);
		var1.setBlock(i + 3, j + 0, k + 11, Block.dirt.blockID);
		var1.setBlock(i + 3, j + 0, k + 12, Block.dirt.blockID);
		var1.setBlock(i + 3, j + 0, k + 13, Block.dirt.blockID);
		var1.setBlock(i + 3, j + 0, k + 14, Block.dirt.blockID);
		var1.setBlock(i + 3, j + 0, k + 15, Block.dirt.blockID);
		var1.setBlock(i + 3, j + 0, k + 16, Block.dirt.blockID);
		var1.setBlock(i + 3, j + 0, k + 17, Block.dirt.blockID);
		var1.setBlock(i + 3, j + 0, k + 18, Block.dirt.blockID);
		var1.setBlock(i + 3, j + 0, k + 19, Block.dirt.blockID);
		var1.setBlock(i + 3, j + 0, k + 20, Block.dirt.blockID);
		var1.setBlock(i + 3, j + 0, k + 21, Block.dirt.blockID);
		var1.setBlock(i + 3, j + 0, k + 22, Block.dirt.blockID);
		var1.setBlock(i + 3, j + 0, k + 23, Block.dirt.blockID);
		var1.setBlock(i + 3, j + 0, k + 24, Block.dirt.blockID);
		var1.setBlock(i + 3, j + 0, k + 25, Block.dirt.blockID);
		var1.setBlock(i + 3, j + 0, k + 26, Block.dirt.blockID);
		var1.setBlock(i + 3, j + 1, k + 0, Block.dirt.blockID);
		var1.setBlock(i + 3, j + 1, k + 1, Block.dirt.blockID);
		var1.setBlock(i + 3, j + 1, k + 2, Block.dirt.blockID);
		var1.setBlock(i + 3, j + 1, k + 3, Block.dirt.blockID);
		var1.setBlock(i + 3, j + 1, k + 4, Block.dirt.blockID);
		var1.setBlock(i + 3, j + 1, k + 5, Block.dirt.blockID);
		var1.setBlock(i + 3, j + 1, k + 6, Block.dirt.blockID);
		var1.setBlock(i + 3, j + 1, k + 7, Block.dirt.blockID);
		var1.setBlock(i + 3, j + 1, k + 8, Block.dirt.blockID);
		var1.setBlock(i + 3, j + 1, k + 9, Block.dirt.blockID);
		var1.setBlock(i + 3, j + 1, k + 10, Block.dirt.blockID);
		var1.setBlock(i + 3, j + 1, k + 11, Block.dirt.blockID);
		var1.setBlock(i + 3, j + 1, k + 12, Block.dirt.blockID);
		var1.setBlock(i + 3, j + 1, k + 13, Block.dirt.blockID);
		var1.setBlock(i + 3, j + 1, k + 14, Block.dirt.blockID);
		var1.setBlock(i + 3, j + 1, k + 15, Block.dirt.blockID);
		var1.setBlock(i + 3, j + 1, k + 16, Block.dirt.blockID);
		var1.setBlock(i + 3, j + 1, k + 17, Block.dirt.blockID);
		var1.setBlock(i + 3, j + 1, k + 18, Block.dirt.blockID);
		var1.setBlock(i + 3, j + 1, k + 19, Block.dirt.blockID);
		var1.setBlock(i + 3, j + 1, k + 20, Block.dirt.blockID);
		var1.setBlock(i + 3, j + 1, k + 21, Block.dirt.blockID);
		var1.setBlock(i + 3, j + 1, k + 22, Block.dirt.blockID);
		var1.setBlock(i + 3, j + 1, k + 23, Block.dirt.blockID);
		var1.setBlock(i + 3, j + 1, k + 24, Block.dirt.blockID);
		var1.setBlock(i + 3, j + 1, k + 25, Block.dirt.blockID);
		var1.setBlock(i + 3, j + 1, k + 26, Block.dirt.blockID);
		var1.setBlock(i + 3, j + 2, k + 0, Block.grass.blockID);
		var1.setBlock(i + 3, j + 2, k + 1, Block.grass.blockID);
		var1.setBlock(i + 3, j + 2, k + 2, Block.grass.blockID);
		var1.setBlock(i + 3, j + 2, k + 3, Block.grass.blockID);
		var1.setBlock(i + 3, j + 2, k + 4, Block.grass.blockID);
		var1.setBlock(i + 3, j + 2, k + 5, Block.stoneBrick.blockID);
		var1.setBlockAndMetadata(i + 3, j + 2, k + 6, Block.stoneBrick.blockID, 1);
		var1.setBlock(i + 3, j + 2, k + 7, Block.stoneBrick.blockID);
		var1.setBlock(i + 3, j + 2, k + 8, Block.stoneBrick.blockID);
		var1.setBlock(i + 3, j + 2, k + 9, Block.stoneBrick.blockID);
		var1.setBlock(i + 3, j + 2, k + 10, Block.stoneBrick.blockID);
		var1.setBlock(i + 3, j + 2, k + 11, Block.stoneBrick.blockID);
		var1.setBlock(i + 3, j + 2, k + 12, Block.stoneBrick.blockID);
		var1.setBlock(i + 3, j + 2, k + 13, Block.stoneBrick.blockID);
		var1.setBlock(i + 3, j + 2, k + 14, Block.stoneBrick.blockID);
		var1.setBlock(i + 3, j + 2, k + 15, Block.stoneBrick.blockID);
		var1.setBlock(i + 3, j + 2, k + 16, Block.stoneBrick.blockID);
		var1.setBlock(i + 3, j + 2, k + 17, Block.stoneBrick.blockID);
		var1.setBlock(i + 3, j + 2, k + 18, Block.stoneBrick.blockID);
		var1.setBlock(i + 3, j + 2, k + 19, Block.stoneBrick.blockID);
		var1.setBlock(i + 3, j + 2, k + 20, Block.stoneBrick.blockID);
		var1.setBlockAndMetadata(i + 3, j + 2, k + 21, Block.stoneBrick.blockID, 2);
		var1.setBlockAndMetadata(i + 3, j + 2, k + 22, Block.stoneBrick.blockID, 2);
		var1.setBlockAndMetadata(i + 3, j + 2, k + 23, Block.stoneBrick.blockID, 1);
		var1.setBlock(i + 3, j + 2, k + 24, Block.brick.blockID);
		var1.setBlock(i + 3, j + 2, k + 25, Block.brick.blockID);
		var1.setBlock(i + 3, j + 2, k + 26, Block.grass.blockID);
		var1.setBlockAndMetadata(i + 3, j + 3, k + 5, Block.stoneBrick.blockID, 1);
		var1.setBlockAndMetadata(i + 3, j + 3, k + 15, Block.stoneSingleSlab.blockID, 5);
		var1.setBlock(i + 3, j + 3, k + 16, Block.stoneBrick.blockID);
		var1.setBlock(i + 3, j + 3, k + 17, Block.stoneBrick.blockID);
		var1.setBlock(i + 3, j + 3, k + 18, Block.stoneBrick.blockID);
		var1.setBlock(i + 3, j + 3, k + 19, Block.stoneBrick.blockID);
		var1.setBlock(i + 3, j + 3, k + 20, Block.stoneBrick.blockID);
		var1.setBlockAndMetadata(i + 3, j + 3, k + 21, Block.chest.blockID, 5);
		var1.setBlockAndMetadata(i + 3, j + 3, k + 23, Block.chest.blockID, 5);
		var1.setBlock(i + 3, j + 3, k + 24, Block.brick.blockID);
		var1.setBlock(i + 3, j + 3, k + 25, Block.brick.blockID);
		var1.setBlock(i + 3, j + 4, k + 5, Block.stoneBrick.blockID);
		var1.setBlockAndMetadata(i + 3, j + 4, k + 17, Block.stoneSingleSlab.blockID, 5);
		var1.setBlock(i + 3, j + 4, k + 18, Block.stoneBrick.blockID);
		var1.setBlock(i + 3, j + 4, k + 19, Block.stoneBrick.blockID);
		var1.setBlock(i + 3, j + 4, k + 20, Block.stoneBrick.blockID);
		var1.setBlockAndMetadata(i + 3, j + 4, k + 21, Block.chest.blockID, 5);
		var1.setBlockAndMetadata(i + 3, j + 4, k + 23, Block.chest.blockID, 5);
		var1.setBlock(i + 3, j + 4, k + 24, Block.brick.blockID);
		var1.setBlock(i + 3, j + 4, k + 25, Block.brick.blockID);
		var1.setBlock(i + 3, j + 5, k + 5, Block.stoneBrick.blockID);
		var1.setBlockAndMetadata(i + 3, j + 5, k + 19, Block.stoneSingleSlab.blockID, 5);
		var1.setBlock(i + 3, j + 5, k + 20, Block.stoneBrick.blockID);
		var1.setBlock(i + 3, j + 5, k + 24, Block.brick.blockID);
		var1.setBlock(i + 3, j + 5, k + 25, Block.brick.blockID);
		var1.setBlock(i + 3, j + 6, k + 4, Block.brick.blockID);
		var1.setBlock(i + 3, j + 6, k + 5, Block.brick.blockID);
		var1.setBlock(i + 3, j + 6, k + 9, Block.glowStone.blockID);
		var1.setBlock(i + 3, j + 6, k + 11, Block.glowStone.blockID);
		var1.setBlockAndMetadata(i + 3, j + 6, k + 21, Block.stoneSingleSlab.blockID, 5);
		var1.setBlock(i + 3, j + 6, k + 22, Block.stoneBrick.blockID);
		var1.setBlock(i + 3, j + 6, k + 23, Block.stoneBrick.blockID);
		var1.setBlock(i + 3, j + 6, k + 24, Block.brick.blockID);
		var1.setBlock(i + 3, j + 6, k + 25, Block.brick.blockID);
		var1.setBlock(i + 3, j + 7, k + 4, Block.brick.blockID);
		var1.setBlock(i + 3, j + 7, k + 5, Block.brick.blockID);
		var1.setBlock(i + 3, j + 7, k + 9, Block.fence.blockID);
		var1.setBlock(i + 3, j + 7, k + 11, Block.fence.blockID);
		var1.setBlock(i + 3, j + 7, k + 24, Block.brick.blockID);
		var1.setBlock(i + 3, j + 7, k + 25, Block.brick.blockID);
		var1.setBlock(i + 3, j + 8, k + 4, Block.web.blockID);
		var1.setBlock(i + 3, j + 8, k + 5, Block.stoneBrick.blockID);
		var1.setBlock(i + 3, j + 8, k + 6, Block.web.blockID);
		var1.setBlock(i + 3, j + 8, k + 17, Block.glowStone.blockID);
		var1.setBlock(i + 3, j + 8, k + 24, Block.brick.blockID);
		var1.setBlock(i + 3, j + 8, k + 25, Block.brick.blockID);
		var1.setBlock(i + 3, j + 9, k + 5, Block.stoneBrick.blockID);
		var1.setBlock(i + 3, j + 9, k + 6, Block.stoneBrick.blockID);
		var1.setBlock(i + 3, j + 9, k + 7, Block.stoneBrick.blockID);
		var1.setBlock(i + 3, j + 9, k + 8, Block.stoneBrick.blockID);
		var1.setBlock(i + 3, j + 9, k + 9, Block.stoneBrick.blockID);
		var1.setBlock(i + 3, j + 9, k + 10, Block.stoneBrick.blockID);
		var1.setBlock(i + 3, j + 9, k + 11, Block.stoneBrick.blockID);
		var1.setBlock(i + 3, j + 9, k + 12, Block.stoneBrick.blockID);
		var1.setBlock(i + 3, j + 9, k + 13, Block.stoneBrick.blockID);
		var1.setBlock(i + 3, j + 9, k + 14, Block.brick.blockID);
		var1.setBlock(i + 3, j + 9, k + 15, Block.brick.blockID);
		var1.setBlock(i + 3, j + 9, k + 16, Block.stoneBrick.blockID);
		var1.setBlock(i + 3, j + 9, k + 17, Block.stoneBrick.blockID);
		var1.setBlock(i + 3, j + 9, k + 18, Block.stoneBrick.blockID);
		var1.setBlockAndMetadata(i + 3, j + 9, k + 19, Block.stoneBrick.blockID, 2);
		var1.setBlock(i + 3, j + 9, k + 20, Block.stoneBrick.blockID);
		var1.setBlock(i + 3, j + 9, k + 24, Block.glowStone.blockID);
		var1.setBlock(i + 3, j + 9, k + 25, Block.brick.blockID);
		var1.setBlock(i + 3, j + 10, k + 5, Block.stoneBrick.blockID);
		var1.setBlock(i + 3, j + 10, k + 6, Block.bookShelf.blockID);
		var1.setBlock(i + 3, j + 10, k + 7, Block.bookShelf.blockID);
		var1.setBlock(i + 3, j + 10, k + 8, Block.stoneBrick.blockID);
		var1.setBlock(i + 3, j + 10, k + 9, Block.bookShelf.blockID);
		var1.setBlock(i + 3, j + 10, k + 10, Block.bookShelf.blockID);
		var1.setBlock(i + 3, j + 10, k + 11, Block.stoneBrick.blockID);
		var1.setBlockAndMetadata(i + 3, j + 10, k + 12, Block.stoneOvenIdle.blockID, 5);
		var1.setBlockAndMetadata(i + 3, j + 10, k + 17, Block.stoneSingleSlab.blockID, 5);
		var1.setBlock(i + 3, j + 10, k + 18, Block.stoneBrick.blockID);
		var1.setBlock(i + 3, j + 10, k + 19, Block.stoneBrick.blockID);
		var1.setBlock(i + 3, j + 10, k + 20, Block.stoneBrick.blockID);
		var1.setBlock(i + 3, j + 10, k + 21, Block.stoneBrick.blockID);
		var1.setBlock(i + 3, j + 10, k + 22, Block.stoneBrick.blockID);
		var1.setBlock(i + 3, j + 10, k + 23, Block.stoneBrick.blockID);
		var1.setBlock(i + 3, j + 10, k + 24, Block.brick.blockID);
		var1.setBlock(i + 3, j + 10, k + 25, Block.brick.blockID);
		var1.setBlock(i + 3, j + 11, k + 5, Block.stoneBrick.blockID);
		var1.setBlock(i + 3, j + 11, k + 6, Block.bookShelf.blockID);
		var1.setBlock(i + 3, j + 11, k + 7, Block.bookShelf.blockID);
		var1.setBlock(i + 3, j + 11, k + 8, Block.stoneBrick.blockID);
		var1.setBlock(i + 3, j + 11, k + 9, Block.bookShelf.blockID);
		var1.setBlock(i + 3, j + 11, k + 10, Block.bookShelf.blockID);
		var1.setBlockAndMetadata(i + 3, j + 11, k + 11, Block.stoneBrick.blockID, 2);
		var1.setBlockAndMetadata(i + 3, j + 11, k + 19, Block.stoneSingleSlab.blockID, 5);
		var1.setBlock(i + 3, j + 11, k + 20, Block.stoneBrick.blockID);
		var1.setBlock(i + 3, j + 11, k + 21, Block.stoneBrick.blockID);
		var1.setBlock(i + 3, j + 11, k + 22, Block.stoneBrick.blockID);
		var1.setBlock(i + 3, j + 11, k + 23, Block.stoneBrick.blockID);
		var1.setBlock(i + 3, j + 11, k + 24, Block.brick.blockID);
		var1.setBlock(i + 3, j + 11, k + 25, Block.brick.blockID);
		var1.setBlock(i + 3, j + 12, k + 5, Block.stoneBrick.blockID);
		var1.setBlock(i + 3, j + 12, k + 6, Block.bookShelf.blockID);
		var1.setBlock(i + 3, j + 12, k + 7, Block.bookShelf.blockID);
		var1.setBlockAndMetadata(i + 3, j + 12, k + 8, Block.stoneBrick.blockID, 2);
		var1.setBlock(i + 3, j + 12, k + 9, Block.bookShelf.blockID);
		var1.setBlock(i + 3, j + 12, k + 10, Block.bookShelf.blockID);
		var1.setBlock(i + 3, j + 12, k + 11, Block.stoneBrick.blockID);
		var1.setBlock(i + 3, j + 12, k + 15, Block.stoneBrick.blockID);
		var1.setBlockAndMetadata(i + 3, j + 12, k + 21, Block.stoneSingleSlab.blockID, 5);
		var1.setBlock(i + 3, j + 12, k + 22, Block.stoneBrick.blockID);
		var1.setBlock(i + 3, j + 12, k + 23, Block.stoneBrick.blockID);
		var1.setBlock(i + 3, j + 12, k + 24, Block.brick.blockID);
		var1.setBlock(i + 3, j + 12, k + 25, Block.brick.blockID);
		var1.setBlock(i + 3, j + 13, k + 5, Block.stoneBrick.blockID);
		var1.setBlock(i + 3, j + 13, k + 6, Block.stoneBrick.blockID);
		var1.setBlock(i + 3, j + 13, k + 7, Block.stoneBrick.blockID);
		var1.setBlock(i + 3, j + 13, k + 8, Block.stoneBrick.blockID);
		var1.setBlock(i + 3, j + 13, k + 9, Block.stoneBrick.blockID);
		var1.setBlock(i + 3, j + 13, k + 10, Block.stoneBrick.blockID);
		var1.setBlock(i + 3, j + 13, k + 11, Block.stoneBrick.blockID);
		var1.setBlock(i + 3, j + 13, k + 12, Block.glowStone.blockID);
		var1.setBlock(i + 3, j + 13, k + 15, Block.stoneBrick.blockID);
		var1.setBlock(i + 3, j + 13, k + 16, Block.stoneBrick.blockID);
		var1.setBlock(i + 3, j + 13, k + 17, Block.glowStone.blockID);
		var1.setBlock(i + 3, j + 13, k + 24, Block.brick.blockID);
		var1.setBlock(i + 3, j + 13, k + 25, Block.brick.blockID);
		var1.setBlock(i + 3, j + 14, k + 4, Block.stoneBrick.blockID);
		var1.setBlock(i + 3, j + 14, k + 5, Block.stoneBrick.blockID);
		var1.setBlock(i + 3, j + 14, k + 6, Block.stoneBrick.blockID);
		var1.setBlock(i + 3, j + 14, k + 7, Block.stoneBrick.blockID);
		var1.setBlock(i + 3, j + 14, k + 8, Block.stoneBrick.blockID);
		var1.setBlock(i + 3, j + 14, k + 9, Block.stoneBrick.blockID);
		var1.setBlock(i + 3, j + 14, k + 10, Block.stoneBrick.blockID);
		var1.setBlock(i + 3, j + 14, k + 11, Block.stoneBrick.blockID);
		var1.setBlock(i + 3, j + 14, k + 12, Block.stoneBrick.blockID);
		var1.setBlock(i + 3, j + 14, k + 13, Block.stoneBrick.blockID);
		var1.setBlock(i + 3, j + 14, k + 14, Block.stoneBrick.blockID);
		var1.setBlock(i + 3, j + 14, k + 15, Block.stoneBrick.blockID);
		var1.setBlock(i + 3, j + 14, k + 16, Block.stoneBrick.blockID);
		var1.setBlock(i + 3, j + 14, k + 17, Block.stoneBrick.blockID);
		var1.setBlock(i + 3, j + 14, k + 18, Block.stoneBrick.blockID);
		var1.setBlock(i + 3, j + 14, k + 19, Block.stoneBrick.blockID);
		var1.setBlock(i + 3, j + 14, k + 24, Block.brick.blockID);
		var1.setBlock(i + 3, j + 14, k + 25, Block.brick.blockID);
		var1.setBlock(i + 3, j + 15, k + 4, Block.stoneBrick.blockID);
		var1.setBlock(i + 3, j + 15, k + 15, Block.stoneBrick.blockID);
		var1.setBlock(i + 3, j + 15, k + 16, Block.stoneBrick.blockID);
		var1.setBlock(i + 3, j + 15, k + 17, Block.stoneBrick.blockID);
		var1.setBlock(i + 3, j + 15, k + 18, Block.stoneBrick.blockID);
		var1.setBlock(i + 3, j + 15, k + 19, Block.stoneBrick.blockID);
		var1.setBlock(i + 3, j + 15, k + 20, Block.stoneBrick.blockID);
		var1.setBlock(i + 3, j + 15, k + 21, Block.stoneBrick.blockID);
		var1.setBlock(i + 3, j + 15, k + 24, Block.stoneBrick.blockID);
		var1.setBlock(i + 3, j + 15, k + 25, Block.stoneBrick.blockID);
		var1.setBlock(i + 3, j + 16, k + 15, Block.stoneBrick.blockID);
		var1.setBlockAndMetadata(i + 3, j + 16, k + 16, Block.bed.blockID, 9);
		var1.setBlock(i + 3, j + 16, k + 21, Block.stoneBrick.blockID);
		var1.setBlockAndMetadata(i + 3, j + 16, k + 24, Block.stoneBrick.blockID, 2);
		var1.setBlock(i + 3, j + 16, k + 25, Block.stoneBrick.blockID);
		var1.setBlock(i + 3, j + 17, k + 15, Block.stoneBrick.blockID);
		var1.setBlock(i + 3, j + 17, k + 21, Block.stoneBrick.blockID);
		var1.setBlock(i + 3, j + 17, k + 22, Block.stoneBrick.blockID);
		var1.setBlock(i + 3, j + 17, k + 23, Block.stoneBrick.blockID);
		var1.setBlock(i + 3, j + 17, k + 24, Block.stoneBrick.blockID);
		var1.setBlock(i + 3, j + 17, k + 25, Block.stoneBrick.blockID);
		var1.setBlock(i + 3, j + 18, k + 15, Block.stoneBrick.blockID);
		var1.setBlock(i + 3, j + 18, k + 18, Block.glowStone.blockID);
		var1.setBlock(i + 3, j + 18, k + 21, Block.stoneBrick.blockID);
		var1.setBlock(i + 3, j + 18, k + 22, Block.stoneBrick.blockID);
		var1.setBlock(i + 3, j + 18, k + 23, Block.stoneBrick.blockID);
		var1.setBlock(i + 3, j + 18, k + 24, Block.stoneBrick.blockID);
		var1.setBlock(i + 3, j + 18, k + 25, Block.stoneBrick.blockID);
		var1.setBlock(i + 3, j + 19, k + 15, Block.stoneBrick.blockID);
		var1.setBlock(i + 3, j + 19, k + 16, Block.stoneBrick.blockID);
		var1.setBlock(i + 3, j + 19, k + 17, Block.stoneBrick.blockID);
		var1.setBlock(i + 3, j + 19, k + 18, Block.stoneBrick.blockID);
		var1.setBlock(i + 3, j + 19, k + 19, Block.stoneBrick.blockID);
		var1.setBlock(i + 3, j + 19, k + 20, Block.stoneBrick.blockID);
		var1.setBlock(i + 3, j + 19, k + 21, Block.stoneBrick.blockID);
		var1.setBlock(i + 4, j + 0, k + 0, Block.dirt.blockID);
		var1.setBlock(i + 4, j + 0, k + 1, Block.dirt.blockID);
		var1.setBlock(i + 4, j + 0, k + 2, Block.dirt.blockID);
		var1.setBlock(i + 4, j + 0, k + 3, Block.dirt.blockID);
		var1.setBlock(i + 4, j + 0, k + 4, Block.dirt.blockID);
		var1.setBlock(i + 4, j + 0, k + 5, Block.dirt.blockID);
		var1.setBlock(i + 4, j + 0, k + 6, Block.dirt.blockID);
		var1.setBlock(i + 4, j + 0, k + 7, Block.dirt.blockID);
		var1.setBlock(i + 4, j + 0, k + 8, Block.dirt.blockID);
		var1.setBlock(i + 4, j + 0, k + 9, Block.dirt.blockID);
		var1.setBlock(i + 4, j + 0, k + 10, Block.dirt.blockID);
		var1.setBlock(i + 4, j + 0, k + 11, Block.dirt.blockID);
		var1.setBlock(i + 4, j + 0, k + 12, Block.dirt.blockID);
		var1.setBlock(i + 4, j + 0, k + 13, Block.dirt.blockID);
		var1.setBlock(i + 4, j + 0, k + 14, Block.dirt.blockID);
		var1.setBlock(i + 4, j + 0, k + 15, Block.dirt.blockID);
		var1.setBlock(i + 4, j + 0, k + 16, Block.dirt.blockID);
		var1.setBlock(i + 4, j + 0, k + 17, Block.dirt.blockID);
		var1.setBlock(i + 4, j + 0, k + 18, Block.dirt.blockID);
		var1.setBlock(i + 4, j + 0, k + 19, Block.dirt.blockID);
		var1.setBlock(i + 4, j + 0, k + 20, Block.dirt.blockID);
		var1.setBlock(i + 4, j + 0, k + 21, Block.dirt.blockID);
		var1.setBlock(i + 4, j + 0, k + 22, Block.dirt.blockID);
		var1.setBlock(i + 4, j + 0, k + 23, Block.dirt.blockID);
		var1.setBlock(i + 4, j + 0, k + 24, Block.dirt.blockID);
		var1.setBlock(i + 4, j + 0, k + 25, Block.dirt.blockID);
		var1.setBlock(i + 4, j + 0, k + 26, Block.dirt.blockID);
		var1.setBlock(i + 4, j + 1, k + 0, Block.dirt.blockID);
		var1.setBlock(i + 4, j + 1, k + 1, Block.dirt.blockID);
		var1.setBlock(i + 4, j + 1, k + 2, Block.dirt.blockID);
		var1.setBlock(i + 4, j + 1, k + 3, Block.dirt.blockID);
		var1.setBlock(i + 4, j + 1, k + 4, Block.dirt.blockID);
		var1.setBlock(i + 4, j + 1, k + 5, Block.dirt.blockID);
		var1.setBlock(i + 4, j + 1, k + 6, Block.dirt.blockID);
		var1.setBlock(i + 4, j + 1, k + 7, Block.dirt.blockID);
		var1.setBlock(i + 4, j + 1, k + 8, Block.dirt.blockID);
		var1.setBlock(i + 4, j + 1, k + 9, Block.dirt.blockID);
		var1.setBlock(i + 4, j + 1, k + 10, Block.dirt.blockID);
		var1.setBlock(i + 4, j + 1, k + 11, Block.dirt.blockID);
		var1.setBlock(i + 4, j + 1, k + 12, Block.dirt.blockID);
		var1.setBlock(i + 4, j + 1, k + 13, Block.dirt.blockID);
		var1.setBlock(i + 4, j + 1, k + 14, Block.dirt.blockID);
		var1.setBlock(i + 4, j + 1, k + 15, Block.dirt.blockID);
		var1.setBlock(i + 4, j + 1, k + 16, Block.dirt.blockID);
		var1.setBlock(i + 4, j + 1, k + 17, Block.dirt.blockID);
		var1.setBlock(i + 4, j + 1, k + 18, Block.dirt.blockID);
		var1.setBlock(i + 4, j + 1, k + 19, Block.dirt.blockID);
		var1.setBlock(i + 4, j + 1, k + 20, Block.dirt.blockID);
		var1.setBlock(i + 4, j + 1, k + 21, Block.dirt.blockID);
		var1.setBlock(i + 4, j + 1, k + 22, Block.dirt.blockID);
		var1.setBlock(i + 4, j + 1, k + 23, Block.dirt.blockID);
		var1.setBlock(i + 4, j + 1, k + 24, Block.dirt.blockID);
		var1.setBlock(i + 4, j + 1, k + 25, Block.dirt.blockID);
		var1.setBlock(i + 4, j + 1, k + 26, Block.dirt.blockID);
		var1.setBlock(i + 4, j + 2, k + 0, Block.grass.blockID);
		var1.setBlock(i + 4, j + 2, k + 1, Block.grass.blockID);
		var1.setBlock(i + 4, j + 2, k + 2, Block.grass.blockID);
		var1.setBlock(i + 4, j + 2, k + 3, Block.grass.blockID);
		var1.setBlock(i + 4, j + 2, k + 4, Block.grass.blockID);
		var1.setBlock(i + 4, j + 2, k + 5, Block.stoneBrick.blockID);
		var1.setBlock(i + 4, j + 2, k + 6, Block.stoneBrick.blockID);
		var1.setBlock(i + 4, j + 2, k + 7, Block.stoneBrick.blockID);
		var1.setBlock(i + 4, j + 2, k + 8, Block.stoneBrick.blockID);
		var1.setBlock(i + 4, j + 2, k + 9, Block.stoneBrick.blockID);
		var1.setBlock(i + 4, j + 2, k + 10, Block.stoneBrick.blockID);
		var1.setBlock(i + 4, j + 2, k + 11, Block.stoneBrick.blockID);
		var1.setBlock(i + 4, j + 2, k + 12, Block.stoneBrick.blockID);
		var1.setBlockAndMetadata(i + 4, j + 2, k + 13, Block.stoneBrick.blockID, 2);
		var1.setBlock(i + 4, j + 2, k + 14, Block.stoneBrick.blockID);
		var1.setBlock(i + 4, j + 2, k + 15, Block.stoneBrick.blockID);
		var1.setBlock(i + 4, j + 2, k + 16, Block.stoneBrick.blockID);
		var1.setBlock(i + 4, j + 2, k + 17, Block.stoneBrick.blockID);
		var1.setBlock(i + 4, j + 2, k + 18, Block.stoneBrick.blockID);
		var1.setBlock(i + 4, j + 2, k + 19, Block.stoneBrick.blockID);
		var1.setBlock(i + 4, j + 2, k + 20, Block.stoneBrick.blockID);
		var1.setBlockAndMetadata(i + 4, j + 2, k + 21, Block.stoneBrick.blockID, 2);
		var1.setBlock(i + 4, j + 2, k + 22, Block.stoneBrick.blockID);
		var1.setBlock(i + 4, j + 2, k + 23, Block.stoneBrick.blockID);
		var1.setBlock(i + 4, j + 2, k + 24, Block.stoneBrick.blockID);
		var1.setBlock(i + 4, j + 2, k + 25, Block.grass.blockID);
		var1.setBlock(i + 4, j + 2, k + 26, Block.grass.blockID);
		var1.setBlock(i + 4, j + 3, k + 5, Block.stoneBrick.blockID);
		var1.setBlockAndMetadata(i + 4, j + 3, k + 15, Block.stoneSingleSlab.blockID, 5);
		var1.setBlock(i + 4, j + 3, k + 16, Block.stoneBrick.blockID);
		var1.setBlock(i + 4, j + 3, k + 17, Block.stoneBrick.blockID);
		var1.setBlock(i + 4, j + 3, k + 18, Block.stoneBrick.blockID);
		var1.setBlock(i + 4, j + 3, k + 19, Block.stoneBrick.blockID);
		var1.setBlock(i + 4, j + 3, k + 20, Block.stoneBrick.blockID);
		var1.setBlock(i + 4, j + 3, k + 24, Block.stoneBrick.blockID);
		var1.setBlock(i + 4, j + 4, k + 5, Block.thinGlass.blockID);
		var1.setBlockAndMetadata(i + 4, j + 4, k + 17, Block.stoneSingleSlab.blockID, 5);
		var1.setBlock(i + 4, j + 4, k + 18, Block.stoneBrick.blockID);
		var1.setBlock(i + 4, j + 4, k + 19, Block.stoneBrick.blockID);
		var1.setBlock(i + 4, j + 4, k + 20, Block.stoneBrick.blockID);
		var1.setBlock(i + 4, j + 4, k + 24, Block.stoneBrick.blockID);
		var1.setBlock(i + 4, j + 5, k + 5, Block.thinGlass.blockID);
		var1.setBlockAndMetadata(i + 4, j + 5, k + 19, Block.stoneSingleSlab.blockID, 5);
		var1.setBlock(i + 4, j + 5, k + 20, Block.stoneBrick.blockID);
		var1.setBlock(i + 4, j + 5, k + 24, Block.stoneBrick.blockID);
		var1.setBlock(i + 4, j + 6, k + 4, Block.brick.blockID);
		var1.setBlock(i + 4, j + 6, k + 5, Block.brick.blockID);
		var1.setBlockAndMetadata(i + 4, j + 6, k + 21, Block.stoneSingleSlab.blockID, 5);
		var1.setBlock(i + 4, j + 6, k + 22, Block.stoneBrick.blockID);
		var1.setBlock(i + 4, j + 6, k + 23, Block.stoneBrick.blockID);
		var1.setBlock(i + 4, j + 6, k + 24, Block.stoneBrick.blockID);
		var1.setBlock(i + 4, j + 6, k + 25, Block.stoneBrick.blockID);
		var1.setBlock(i + 4, j + 7, k + 4, Block.brick.blockID);
		var1.setBlock(i + 4, j + 7, k + 5, Block.brick.blockID);
		var1.setBlock(i + 4, j + 7, k + 6, Block.web.blockID);
		var1.setBlock(i + 4, j + 7, k + 25, Block.stoneBrick.blockID);
		var1.setBlock(i + 4, j + 8, k + 5, Block.stoneBrick.blockID);
		var1.setBlock(i + 4, j + 8, k + 25, Block.thinGlass.blockID);
		var1.setBlock(i + 4, j + 9, k + 5, Block.stoneBrick.blockID);
		var1.setBlock(i + 4, j + 9, k + 6, Block.stoneBrick.blockID);
		var1.setBlock(i + 4, j + 9, k + 7, Block.stoneBrick.blockID);
		var1.setBlock(i + 4, j + 9, k + 8, Block.stoneBrick.blockID);
		var1.setBlock(i + 4, j + 9, k + 9, Block.stoneBrick.blockID);
		var1.setBlock(i + 4, j + 9, k + 10, Block.stoneBrick.blockID);
		var1.setBlock(i + 4, j + 9, k + 11, Block.stoneBrick.blockID);
		var1.setBlock(i + 4, j + 9, k + 12, Block.stoneBrick.blockID);
		var1.setBlock(i + 4, j + 9, k + 13, Block.stoneBrick.blockID);
		var1.setBlock(i + 4, j + 9, k + 14, Block.brick.blockID);
		var1.setBlock(i + 4, j + 9, k + 15, Block.brick.blockID);
		var1.setBlock(i + 4, j + 9, k + 16, Block.stoneBrick.blockID);
		var1.setBlockAndMetadata(i + 4, j + 9, k + 17, Block.stoneBrick.blockID, 2);
		var1.setBlock(i + 4, j + 9, k + 18, Block.stoneBrick.blockID);
		var1.setBlock(i + 4, j + 9, k + 19, Block.stoneBrick.blockID);
		var1.setBlock(i + 4, j + 9, k + 20, Block.stoneBrick.blockID);
		var1.setBlock(i + 4, j + 9, k + 25, Block.thinGlass.blockID);
		var1.setBlock(i + 4, j + 10, k + 5, Block.stoneBrick.blockID);
		var1.setBlock(i + 4, j + 10, k + 8, Block.enchantmentTable.blockID);
		var1.setBlock(i + 4, j + 10, k + 16, Block.stoneBrick.blockID);
		var1.setBlock(i + 4, j + 10, k + 17, Block.stoneBrick.blockID);
		var1.setBlock(i + 4, j + 10, k + 18, Block.stoneBrick.blockID);
		var1.setBlock(i + 4, j + 10, k + 19, Block.stoneBrick.blockID);
		var1.setBlock(i + 4, j + 10, k + 20, Block.stoneBrick.blockID);
		var1.setBlock(i + 4, j + 10, k + 21, Block.stoneBrick.blockID);
		var1.setBlock(i + 4, j + 10, k + 22, Block.stoneBrick.blockID);
		var1.setBlock(i + 4, j + 10, k + 23, Block.stoneBrick.blockID);
		var1.setBlock(i + 4, j + 10, k + 24, Block.brick.blockID);
		var1.setBlock(i + 4, j + 10, k + 25, Block.brick.blockID);
		var1.setBlock(i + 4, j + 11, k + 5, Block.thinGlass.blockID);
		var1.setBlock(i + 4, j + 11, k + 16, Block.stoneBrick.blockID);
		var1.setBlock(i + 4, j + 11, k + 17, Block.stoneBrick.blockID);
		var1.setBlock(i + 4, j + 11, k + 18, Block.stoneBrick.blockID);
		var1.setBlockAndMetadata(i + 4, j + 11, k + 19, Block.stoneBrick.blockID, 2);
		var1.setBlock(i + 4, j + 11, k + 20, Block.stoneBrick.blockID);
		var1.setBlock(i + 4, j + 11, k + 21, Block.stoneBrick.blockID);
		var1.setBlock(i + 4, j + 11, k + 22, Block.stoneBrick.blockID);
		var1.setBlock(i + 4, j + 11, k + 23, Block.stoneBrick.blockID);
		var1.setBlock(i + 4, j + 11, k + 24, Block.brick.blockID);
		var1.setBlock(i + 4, j + 11, k + 25, Block.brick.blockID);
		var1.setBlock(i + 4, j + 12, k + 5, Block.thinGlass.blockID);
		var1.setBlock(i + 4, j + 12, k + 15, Block.glowStone.blockID);
		var1.setBlock(i + 4, j + 12, k + 16, Block.stoneBrick.blockID);
		var1.setBlock(i + 4, j + 12, k + 17, Block.stoneBrick.blockID);
		var1.setBlock(i + 4, j + 12, k + 18, Block.stoneBrick.blockID);
		var1.setBlock(i + 4, j + 12, k + 19, Block.stoneBrick.blockID);
		var1.setBlock(i + 4, j + 12, k + 20, Block.stoneBrick.blockID);
		var1.setBlock(i + 4, j + 12, k + 21, Block.stoneBrick.blockID);
		var1.setBlock(i + 4, j + 12, k + 22, Block.stoneBrick.blockID);
		var1.setBlock(i + 4, j + 12, k + 23, Block.stoneBrick.blockID);
		var1.setBlock(i + 4, j + 12, k + 24, Block.brick.blockID);
		var1.setBlock(i + 4, j + 12, k + 25, Block.brick.blockID);
		var1.setBlock(i + 4, j + 13, k + 5, Block.stoneBrick.blockID);
		var1.setBlock(i + 4, j + 13, k + 6, Block.web.blockID);
		var1.setBlock(i + 4, j + 13, k + 15, Block.stoneBrick.blockID);
		var1.setBlock(i + 4, j + 13, k + 16, Block.stoneBrick.blockID);
		var1.setBlock(i + 4, j + 13, k + 17, Block.stoneBrick.blockID);
		var1.setBlock(i + 4, j + 13, k + 18, Block.stoneBrick.blockID);
		var1.setBlock(i + 4, j + 13, k + 19, Block.stoneBrick.blockID);
		var1.setBlock(i + 4, j + 13, k + 20, Block.stoneBrick.blockID);
		var1.setBlock(i + 4, j + 13, k + 21, Block.stoneBrick.blockID);
		var1.setBlockAndMetadata(i + 4, j + 13, k + 22, Block.stoneSingleSlab.blockID, 5);
		var1.setBlockAndMetadata(i + 4, j + 13, k + 23, Block.stoneSingleSlab.blockID, 5);
		var1.setBlock(i + 4, j + 13, k + 24, Block.stoneBrick.blockID);
		var1.setBlock(i + 4, j + 13, k + 25, Block.stoneBrick.blockID);
		var1.setBlock(i + 4, j + 14, k + 4, Block.stoneBrick.blockID);
		var1.setBlock(i + 4, j + 14, k + 5, Block.stoneBrick.blockID);
		var1.setBlock(i + 4, j + 14, k + 6, Block.stoneBrick.blockID);
		var1.setBlock(i + 4, j + 14, k + 7, Block.stoneBrick.blockID);
		var1.setBlock(i + 4, j + 14, k + 8, Block.stoneBrick.blockID);
		var1.setBlock(i + 4, j + 14, k + 9, Block.stoneBrick.blockID);
		var1.setBlock(i + 4, j + 14, k + 10, Block.stoneBrick.blockID);
		var1.setBlock(i + 4, j + 14, k + 11, Block.stoneBrick.blockID);
		var1.setBlock(i + 4, j + 14, k + 12, Block.stoneBrick.blockID);
		var1.setBlock(i + 4, j + 14, k + 13, Block.stoneBrick.blockID);
		var1.setBlock(i + 4, j + 14, k + 14, Block.stoneBrick.blockID);
		var1.setBlock(i + 4, j + 14, k + 15, Block.stoneBrick.blockID);
		var1.setBlock(i + 4, j + 14, k + 16, Block.stoneBrick.blockID);
		var1.setBlock(i + 4, j + 14, k + 17, Block.stoneBrick.blockID);
		var1.setBlock(i + 4, j + 14, k + 18, Block.stoneBrick.blockID);
		var1.setBlock(i + 4, j + 14, k + 19, Block.stoneBrick.blockID);
		var1.setBlock(i + 4, j + 14, k + 20, Block.stoneBrick.blockID);
		var1.setBlock(i + 4, j + 14, k + 21, Block.stoneBrick.blockID);
		var1.setBlock(i + 4, j + 14, k + 24, Block.stoneBrick.blockID);
		var1.setBlock(i + 4, j + 14, k + 25, Block.stoneBrick.blockID);
		var1.setBlock(i + 4, j + 15, k + 4, Block.stoneBrick.blockID);
		var1.setBlock(i + 4, j + 15, k + 15, Block.stoneBrick.blockID);
		var1.setBlock(i + 4, j + 15, k + 16, Block.stoneBrick.blockID);
		var1.setBlock(i + 4, j + 15, k + 17, Block.stoneBrick.blockID);
		var1.setBlock(i + 4, j + 15, k + 18, Block.stoneBrick.blockID);
		var1.setBlock(i + 4, j + 15, k + 19, Block.stoneBrick.blockID);
		var1.setBlock(i + 4, j + 15, k + 20, Block.stoneBrick.blockID);
		var1.setBlock(i + 4, j + 15, k + 21, Block.stoneBrick.blockID);
		var1.setBlock(i + 4, j + 15, k + 24, Block.stoneBrick.blockID);
		var1.setBlock(i + 4, j + 15, k + 25, Block.stoneBrick.blockID);
		var1.setBlock(i + 4, j + 16, k + 15, Block.stoneBrick.blockID);
		var1.setBlockAndMetadata(i + 4, j + 16, k + 16, Block.bed.blockID, 1);
		var1.setBlock(i + 4, j + 16, k + 19, Block.bed.blockID);
		var1.setBlockAndMetadata(i + 4, j + 16, k + 20, Block.bed.blockID, 8);
		var1.setBlock(i + 4, j + 16, k + 21, Block.stoneBrick.blockID);
		var1.setBlock(i + 4, j + 16, k + 24, Block.stoneBrick.blockID);
		var1.setBlock(i + 4, j + 16, k + 25, Block.stoneBrick.blockID);
		var1.setBlock(i + 4, j + 17, k + 15, Block.thinGlass.blockID);
		var1.setBlock(i + 4, j + 17, k + 21, Block.stoneBrick.blockID);
		var1.setBlock(i + 4, j + 17, k + 24, Block.stoneBrick.blockID);
		var1.setBlock(i + 4, j + 17, k + 25, Block.stoneBrick.blockID);
		var1.setBlock(i + 4, j + 18, k + 15, Block.thinGlass.blockID);
		var1.setBlock(i + 4, j + 18, k + 21, Block.stoneBrick.blockID);
		var1.setBlock(i + 4, j + 18, k + 22, Block.stoneBrick.blockID);
		var1.setBlock(i + 4, j + 18, k + 23, Block.stoneBrick.blockID);
		var1.setBlock(i + 4, j + 18, k + 24, Block.stoneBrick.blockID);
		var1.setBlock(i + 4, j + 18, k + 25, Block.stoneBrick.blockID);
		var1.setBlock(i + 4, j + 19, k + 15, Block.stoneBrick.blockID);
		var1.setBlock(i + 4, j + 19, k + 16, Block.stoneBrick.blockID);
		var1.setBlock(i + 4, j + 19, k + 17, Block.stoneBrick.blockID);
		var1.setBlock(i + 4, j + 19, k + 18, Block.stoneBrick.blockID);
		var1.setBlock(i + 4, j + 19, k + 19, Block.stoneBrick.blockID);
		var1.setBlock(i + 4, j + 19, k + 20, Block.stoneBrick.blockID);
		var1.setBlock(i + 4, j + 19, k + 21, Block.stoneBrick.blockID);
		var1.setBlock(i + 4, j + 19, k + 22, Block.stoneBrick.blockID);
		var1.setBlock(i + 4, j + 19, k + 23, Block.stoneBrick.blockID);
		var1.setBlock(i + 4, j + 19, k + 24, Block.stoneBrick.blockID);
		var1.setBlock(i + 4, j + 19, k + 25, Block.stoneBrick.blockID);
		var1.setBlock(i + 5, j + 0, k + 0, Block.dirt.blockID);
		var1.setBlock(i + 5, j + 0, k + 1, Block.dirt.blockID);
		var1.setBlock(i + 5, j + 0, k + 2, Block.dirt.blockID);
		var1.setBlock(i + 5, j + 0, k + 3, Block.dirt.blockID);
		var1.setBlock(i + 5, j + 0, k + 4, Block.dirt.blockID);
		var1.setBlock(i + 5, j + 0, k + 5, Block.dirt.blockID);
		var1.setBlock(i + 5, j + 0, k + 6, Block.dirt.blockID);
		var1.setBlock(i + 5, j + 0, k + 7, Block.dirt.blockID);
		var1.setBlock(i + 5, j + 0, k + 8, Block.dirt.blockID);
		var1.setBlock(i + 5, j + 0, k + 9, Block.dirt.blockID);
		var1.setBlock(i + 5, j + 0, k + 10, Block.dirt.blockID);
		var1.setBlock(i + 5, j + 0, k + 11, Block.dirt.blockID);
		var1.setBlock(i + 5, j + 0, k + 12, Block.dirt.blockID);
		var1.setBlock(i + 5, j + 0, k + 13, Block.dirt.blockID);
		var1.setBlock(i + 5, j + 0, k + 14, Block.dirt.blockID);
		var1.setBlock(i + 5, j + 0, k + 15, Block.dirt.blockID);
		var1.setBlock(i + 5, j + 0, k + 16, Block.dirt.blockID);
		var1.setBlock(i + 5, j + 0, k + 17, Block.dirt.blockID);
		var1.setBlock(i + 5, j + 0, k + 18, Block.dirt.blockID);
		var1.setBlock(i + 5, j + 0, k + 19, Block.dirt.blockID);
		var1.setBlock(i + 5, j + 0, k + 20, Block.dirt.blockID);
		var1.setBlock(i + 5, j + 0, k + 21, Block.dirt.blockID);
		var1.setBlock(i + 5, j + 0, k + 22, Block.dirt.blockID);
		var1.setBlock(i + 5, j + 0, k + 23, Block.dirt.blockID);
		var1.setBlock(i + 5, j + 0, k + 24, Block.dirt.blockID);
		var1.setBlock(i + 5, j + 0, k + 25, Block.dirt.blockID);
		var1.setBlock(i + 5, j + 0, k + 26, Block.dirt.blockID);
		var1.setBlock(i + 5, j + 1, k + 0, Block.dirt.blockID);
		var1.setBlock(i + 5, j + 1, k + 1, Block.dirt.blockID);
		var1.setBlock(i + 5, j + 1, k + 2, Block.dirt.blockID);
		var1.setBlock(i + 5, j + 1, k + 3, Block.dirt.blockID);
		var1.setBlock(i + 5, j + 1, k + 4, Block.dirt.blockID);
		var1.setBlock(i + 5, j + 1, k + 5, Block.dirt.blockID);
		var1.setBlock(i + 5, j + 1, k + 6, Block.dirt.blockID);
		var1.setBlock(i + 5, j + 1, k + 7, Block.dirt.blockID);
		var1.setBlock(i + 5, j + 1, k + 8, Block.dirt.blockID);
		var1.setBlock(i + 5, j + 1, k + 9, Block.dirt.blockID);
		var1.setBlock(i + 5, j + 1, k + 10, Block.dirt.blockID);
		var1.setBlock(i + 5, j + 1, k + 11, Block.dirt.blockID);
		var1.setBlock(i + 5, j + 1, k + 12, Block.dirt.blockID);
		var1.setBlock(i + 5, j + 1, k + 13, Block.dirt.blockID);
		var1.setBlock(i + 5, j + 1, k + 14, Block.dirt.blockID);
		var1.setBlock(i + 5, j + 1, k + 15, Block.dirt.blockID);
		var1.setBlock(i + 5, j + 1, k + 16, Block.dirt.blockID);
		var1.setBlock(i + 5, j + 1, k + 17, Block.dirt.blockID);
		var1.setBlock(i + 5, j + 1, k + 18, Block.dirt.blockID);
		var1.setBlock(i + 5, j + 1, k + 19, Block.dirt.blockID);
		var1.setBlock(i + 5, j + 1, k + 20, Block.dirt.blockID);
		var1.setBlock(i + 5, j + 1, k + 21, Block.dirt.blockID);
		var1.setBlock(i + 5, j + 1, k + 22, Block.dirt.blockID);
		var1.setBlock(i + 5, j + 1, k + 23, Block.dirt.blockID);
		var1.setBlock(i + 5, j + 1, k + 24, Block.dirt.blockID);
		var1.setBlock(i + 5, j + 1, k + 25, Block.dirt.blockID);
		var1.setBlock(i + 5, j + 1, k + 26, Block.dirt.blockID);
		var1.setBlock(i + 5, j + 2, k + 0, Block.grass.blockID);
		var1.setBlock(i + 5, j + 2, k + 1, Block.grass.blockID);
		var1.setBlock(i + 5, j + 2, k + 2, Block.grass.blockID);
		var1.setBlock(i + 5, j + 2, k + 3, Block.grass.blockID);
		var1.setBlock(i + 5, j + 2, k + 4, Block.dirt.blockID);
		var1.setBlock(i + 5, j + 2, k + 5, Block.stoneBrick.blockID);
		var1.setBlock(i + 5, j + 2, k + 6, Block.stoneBrick.blockID);
		var1.setBlock(i + 5, j + 2, k + 7, Block.stoneBrick.blockID);
		var1.setBlock(i + 5, j + 2, k + 8, Block.stoneDoubleSlab.blockID);
		var1.setBlock(i + 5, j + 2, k + 9, Block.stoneDoubleSlab.blockID);
		var1.setBlock(i + 5, j + 2, k + 10, Block.stoneDoubleSlab.blockID);
		var1.setBlock(i + 5, j + 2, k + 11, Block.stoneDoubleSlab.blockID);
		var1.setBlock(i + 5, j + 2, k + 12, Block.stoneDoubleSlab.blockID);
		var1.setBlock(i + 5, j + 2, k + 13, Block.stoneDoubleSlab.blockID);
		var1.setBlock(i + 5, j + 2, k + 14, Block.brick.blockID);
		var1.setBlock(i + 5, j + 2, k + 15, Block.brick.blockID);
		var1.setBlock(i + 5, j + 2, k + 16, Block.stoneBrick.blockID);
		var1.setBlock(i + 5, j + 2, k + 17, Block.stoneBrick.blockID);
		var1.setBlock(i + 5, j + 2, k + 18, Block.stoneBrick.blockID);
		var1.setBlock(i + 5, j + 2, k + 19, Block.brick.blockID);
		var1.setBlock(i + 5, j + 2, k + 20, Block.stoneBrick.blockID);
		var1.setBlock(i + 5, j + 2, k + 21, Block.stoneBrick.blockID);
		var1.setBlock(i + 5, j + 2, k + 22, Block.stoneBrick.blockID);
		var1.setBlock(i + 5, j + 2, k + 23, Block.stoneBrick.blockID);
		var1.setBlock(i + 5, j + 2, k + 24, Block.stoneBrick.blockID);
		var1.setBlock(i + 5, j + 2, k + 25, Block.grass.blockID);
		var1.setBlock(i + 5, j + 2, k + 26, Block.grass.blockID);
		var1.setBlock(i + 5, j + 3, k + 4, Block.brick.blockID);
		var1.setBlock(i + 5, j + 3, k + 5, Block.brick.blockID);
		var1.setBlock(i + 5, j + 3, k + 6, Block.brick.blockID);
		var1.setBlock(i + 5, j + 3, k + 14, Block.brick.blockID);
		var1.setBlock(i + 5, j + 3, k + 15, Block.brick.blockID);
		var1.setBlock(i + 5, j + 3, k + 16, Block.stoneBrick.blockID);
		var1.setBlock(i + 5, j + 3, k + 17, Block.stoneBrick.blockID);
		var1.setBlock(i + 5, j + 3, k + 18, Block.stoneBrick.blockID);
		var1.setBlock(i + 5, j + 3, k + 19, Block.brick.blockID);
		var1.setBlock(i + 5, j + 3, k + 20, Block.brick.blockID);
		var1.setBlockAndMetadata(i + 5, j + 3, k + 23, Block.chest.blockID, 2);
		var1.setBlock(i + 5, j + 3, k + 24, Block.stoneBrick.blockID);
		var1.setBlock(i + 5, j + 4, k + 4, Block.brick.blockID);
		var1.setBlock(i + 5, j + 4, k + 5, Block.brick.blockID);
		var1.setBlock(i + 5, j + 4, k + 6, Block.brick.blockID);
		var1.setBlock(i + 5, j + 4, k + 14, Block.brick.blockID);
		var1.setBlock(i + 5, j + 4, k + 15, Block.brick.blockID);
		var1.setBlock(i + 5, j + 4, k + 16, Block.stoneBrick.blockID);
		var1.setBlock(i + 5, j + 4, k + 17, Block.stoneBrick.blockID);
		var1.setBlock(i + 5, j + 4, k + 18, Block.stoneBrick.blockID);
		var1.setBlock(i + 5, j + 4, k + 19, Block.brick.blockID);
		var1.setBlock(i + 5, j + 4, k + 20, Block.blockClay.blockID);
		var1.setBlockAndMetadata(i + 5, j + 4, k + 23, Block.chest.blockID, 2);
		var1.setBlock(i + 5, j + 4, k + 24, Block.stoneBrick.blockID);
		var1.setBlock(i + 5, j + 5, k + 4, Block.brick.blockID);
		var1.setBlock(i + 5, j + 5, k + 5, Block.brick.blockID);
		var1.setBlock(i + 5, j + 5, k + 6, Block.brick.blockID);
		var1.setBlock(i + 5, j + 5, k + 14, Block.brick.blockID);
		var1.setBlock(i + 5, j + 5, k + 15, Block.brick.blockID);
		var1.setBlock(i + 5, j + 5, k + 16, Block.stoneBrick.blockID);
		var1.setBlock(i + 5, j + 5, k + 17, Block.stoneBrick.blockID);
		var1.setBlock(i + 5, j + 5, k + 18, Block.stoneBrick.blockID);
		var1.setBlock(i + 5, j + 5, k + 19, Block.brick.blockID);
		var1.setBlock(i + 5, j + 5, k + 20, Block.glowStone.blockID);
		var1.setBlock(i + 5, j + 5, k + 24, Block.stoneBrick.blockID);
		var1.setBlock(i + 5, j + 6, k + 4, Block.brick.blockID);
		var1.setBlock(i + 5, j + 6, k + 5, Block.brick.blockID);
		var1.setBlock(i + 5, j + 6, k + 6, Block.brick.blockID);
		var1.setBlock(i + 5, j + 6, k + 14, Block.brick.blockID);
		var1.setBlock(i + 5, j + 6, k + 15, Block.brick.blockID);
		var1.setBlock(i + 5, j + 6, k + 16, Block.stoneBrick.blockID);
		var1.setBlock(i + 5, j + 6, k + 17, Block.stoneBrick.blockID);
		var1.setBlockAndMetadata(i + 5, j + 6, k + 18, Block.stoneBrick.blockID, 2);
		var1.setBlock(i + 5, j + 6, k + 19, Block.brick.blockID);
		var1.setBlock(i + 5, j + 6, k + 20, Block.brick.blockID);
		var1.setBlock(i + 5, j + 6, k + 21, Block.stoneBrick.blockID);
		var1.setBlock(i + 5, j + 6, k + 22, Block.stoneBrick.blockID);
		var1.setBlock(i + 5, j + 6, k + 23, Block.stoneBrick.blockID);
		var1.setBlock(i + 5, j + 6, k + 24, Block.stoneBrick.blockID);
		var1.setBlock(i + 5, j + 6, k + 25, Block.stoneBrick.blockID);
		var1.setBlock(i + 5, j + 7, k + 4, Block.brick.blockID);
		var1.setBlock(i + 5, j + 7, k + 5, Block.brick.blockID);
		var1.setBlock(i + 5, j + 7, k + 6, Block.brick.blockID);
		var1.setBlock(i + 5, j + 7, k + 14, Block.netherrack.blockID);
		var1.setBlock(i + 5, j + 7, k + 15, Block.brick.blockID);
		var1.setBlock(i + 5, j + 7, k + 16, Block.stoneBrick.blockID);
		var1.setBlock(i + 5, j + 7, k + 17, Block.stoneBrick.blockID);
		var1.setBlock(i + 5, j + 7, k + 18, Block.stoneBrick.blockID);
		var1.setBlock(i + 5, j + 7, k + 19, Block.stoneBrick.blockID);
		var1.setBlock(i + 5, j + 7, k + 20, Block.stoneBrick.blockID);
		var1.setBlockAndMetadata(i + 5, j + 7, k + 21, Block.stoneSingleSlab.blockID, 5);
		var1.setBlock(i + 5, j + 7, k + 25, Block.stoneBrick.blockID);
		var1.setBlock(i + 5, j + 8, k + 4, Block.brick.blockID);
		var1.setBlock(i + 5, j + 8, k + 5, Block.brick.blockID);
		var1.setBlock(i + 5, j + 8, k + 6, Block.brick.blockID);
		var1.setBlock(i + 5, j + 8, k + 14, Block.brick.blockID);
		var1.setBlock(i + 5, j + 8, k + 15, Block.brick.blockID);
		var1.setBlock(i + 5, j + 8, k + 16, Block.brick.blockID);
		var1.setBlock(i + 5, j + 8, k + 17, Block.brick.blockID);
		var1.setBlock(i + 5, j + 8, k + 18, Block.stoneBrick.blockID);
		var1.setBlockAndMetadata(i + 5, j + 8, k + 19, Block.stoneSingleSlab.blockID, 5);
		var1.setBlock(i + 5, j + 8, k + 25, Block.thinGlass.blockID);
		var1.setBlock(i + 5, j + 9, k + 4, Block.brick.blockID);
		var1.setBlock(i + 5, j + 9, k + 5, Block.brick.blockID);
		var1.setBlock(i + 5, j + 9, k + 6, Block.brick.blockID);
		var1.setBlock(i + 5, j + 9, k + 7, Block.brick.blockID);
		var1.setBlock(i + 5, j + 9, k + 8, Block.brick.blockID);
		var1.setBlock(i + 5, j + 9, k + 9, Block.brick.blockID);
		var1.setBlock(i + 5, j + 9, k + 10, Block.brick.blockID);
		var1.setBlock(i + 5, j + 9, k + 11, Block.brick.blockID);
		var1.setBlock(i + 5, j + 9, k + 12, Block.brick.blockID);
		var1.setBlock(i + 5, j + 9, k + 13, Block.brick.blockID);
		var1.setBlock(i + 5, j + 9, k + 14, Block.brick.blockID);
		var1.setBlock(i + 5, j + 9, k + 15, Block.brick.blockID);
		var1.setBlock(i + 5, j + 9, k + 16, Block.stoneBrick.blockID);
		var1.setBlockAndMetadata(i + 5, j + 9, k + 17, Block.stoneSingleSlab.blockID, 5);
		var1.setBlock(i + 5, j + 9, k + 25, Block.thinGlass.blockID);
		var1.setBlock(i + 5, j + 10, k + 4, Block.stoneBrick.blockID);
		var1.setBlockAndMetadata(i + 5, j + 10, k + 5, Block.stoneBrick.blockID, 2);
		var1.setBlock(i + 5, j + 10, k + 8, Block.stoneBrick.blockID);
		var1.setBlock(i + 5, j + 10, k + 11, Block.stoneBrick.blockID);
		var1.setBlock(i + 5, j + 10, k + 24, Block.brick.blockID);
		var1.setBlock(i + 5, j + 10, k + 25, Block.brick.blockID);
		var1.setBlockAndMetadata(i + 5, j + 11, k + 4, Block.stoneBrick.blockID, 2);
		var1.setBlock(i + 5, j + 11, k + 5, Block.stoneBrick.blockID);
		var1.setBlock(i + 5, j + 11, k + 22, Block.glowStone.blockID);
		var1.setBlock(i + 5, j + 11, k + 23, Block.stoneBrick.blockID);
		var1.setBlock(i + 5, j + 11, k + 24, Block.brick.blockID);
		var1.setBlock(i + 5, j + 11, k + 25, Block.brick.blockID);
		var1.setBlock(i + 5, j + 12, k + 4, Block.stoneBrick.blockID);
		var1.setBlock(i + 5, j + 12, k + 5, Block.stoneBrick.blockID);
		var1.setBlock(i + 5, j + 12, k + 16, Block.stoneBrick.blockID);
		var1.setBlock(i + 5, j + 12, k + 22, Block.fence.blockID);
		var1.setBlock(i + 5, j + 12, k + 23, Block.stoneBrick.blockID);
		var1.setBlock(i + 5, j + 12, k + 24, Block.brick.blockID);
		var1.setBlock(i + 5, j + 12, k + 25, Block.brick.blockID);
		var1.setBlock(i + 5, j + 13, k + 4, Block.stoneBrick.blockID);
		var1.setBlock(i + 5, j + 13, k + 5, Block.stoneBrick.blockID);
		var1.setBlockAndMetadata(i + 5, j + 13, k + 15, Block.stoneBrick.blockID, 2);
		var1.setBlock(i + 5, j + 13, k + 16, Block.stoneBrick.blockID);
		var1.setBlock(i + 5, j + 13, k + 17, Block.stoneBrick.blockID);
		var1.setBlock(i + 5, j + 13, k + 18, Block.stoneBrick.blockID);
		var1.setBlock(i + 5, j + 13, k + 19, Block.stoneBrick.blockID);
		var1.setBlock(i + 5, j + 13, k + 20, Block.stoneBrick.blockID);
		var1.setBlock(i + 5, j + 13, k + 21, Block.stoneBrick.blockID);
		var1.setBlock(i + 5, j + 13, k + 22, Block.stoneBrick.blockID);
		var1.setBlock(i + 5, j + 13, k + 23, Block.stoneBrick.blockID);
		var1.setBlock(i + 5, j + 13, k + 24, Block.stoneBrick.blockID);
		var1.setBlock(i + 5, j + 13, k + 25, Block.stoneBrick.blockID);
		var1.setBlock(i + 5, j + 14, k + 4, Block.stoneBrick.blockID);
		var1.setBlock(i + 5, j + 14, k + 5, Block.stoneBrick.blockID);
		var1.setBlock(i + 5, j + 14, k + 6, Block.stoneBrick.blockID);
		var1.setBlock(i + 5, j + 14, k + 7, Block.stoneBrick.blockID);
		var1.setBlock(i + 5, j + 14, k + 8, Block.stoneBrick.blockID);
		var1.setBlock(i + 5, j + 14, k + 9, Block.stoneBrick.blockID);
		var1.setBlock(i + 5, j + 14, k + 10, Block.stoneBrick.blockID);
		var1.setBlock(i + 5, j + 14, k + 11, Block.stoneBrick.blockID);
		var1.setBlock(i + 5, j + 14, k + 12, Block.stoneBrick.blockID);
		var1.setBlock(i + 5, j + 14, k + 13, Block.stoneBrick.blockID);
		var1.setBlock(i + 5, j + 14, k + 14, Block.stoneBrick.blockID);
		var1.setBlock(i + 5, j + 14, k + 15, Block.stoneBrick.blockID);
		var1.setBlock(i + 5, j + 14, k + 16, Block.stoneBrick.blockID);
		var1.setBlock(i + 5, j + 14, k + 17, Block.stoneBrick.blockID);
		var1.setBlock(i + 5, j + 14, k + 18, Block.stoneBrick.blockID);
		var1.setBlock(i + 5, j + 14, k + 19, Block.stoneBrick.blockID);
		var1.setBlock(i + 5, j + 14, k + 20, Block.stoneBrick.blockID);
		var1.setBlock(i + 5, j + 14, k + 21, Block.stoneBrick.blockID);
		var1.setBlock(i + 5, j + 14, k + 24, Block.stoneBrick.blockID);
		var1.setBlock(i + 5, j + 14, k + 25, Block.stoneBrick.blockID);
		var1.setBlock(i + 5, j + 15, k + 4, Block.stoneBrick.blockID);
		var1.setBlock(i + 5, j + 15, k + 15, Block.stoneBrick.blockID);
		var1.setBlock(i + 5, j + 15, k + 16, Block.stoneBrick.blockID);
		var1.setBlock(i + 5, j + 15, k + 17, Block.stoneBrick.blockID);
		var1.setBlock(i + 5, j + 15, k + 18, Block.stoneBrick.blockID);
		var1.setBlock(i + 5, j + 15, k + 19, Block.stoneBrick.blockID);
		var1.setBlock(i + 5, j + 15, k + 20, Block.stoneBrick.blockID);
		var1.setBlock(i + 5, j + 15, k + 21, Block.stoneBrick.blockID);
		var1.setBlock(i + 5, j + 15, k + 25, Block.stoneBrick.blockID);
		var1.setBlock(i + 5, j + 16, k + 15, Block.stoneBrick.blockID);
		var1.setBlock(i + 5, j + 16, k + 21, Block.stoneBrick.blockID);
		var1.setBlock(i + 5, j + 16, k + 24, Block.stoneBrick.blockID);
		var1.setBlock(i + 5, j + 16, k + 25, Block.stoneBrick.blockID);
		var1.setBlock(i + 5, j + 17, k + 15, Block.stoneBrick.blockID);
		var1.setBlock(i + 5, j + 17, k + 21, Block.stoneBrick.blockID);
		var1.setBlock(i + 5, j + 17, k + 24, Block.stoneBrick.blockID);
		var1.setBlock(i + 5, j + 17, k + 25, Block.stoneBrick.blockID);
		var1.setBlock(i + 5, j + 18, k + 15, Block.stoneBrick.blockID);
		var1.setBlock(i + 5, j + 18, k + 21, Block.stoneBrick.blockID);
		var1.setBlock(i + 5, j + 18, k + 24, Block.stoneBrick.blockID);
		var1.setBlock(i + 5, j + 18, k + 25, Block.stoneBrick.blockID);
		var1.setBlock(i + 5, j + 19, k + 15, Block.stoneBrick.blockID);
		var1.setBlock(i + 5, j + 19, k + 16, Block.stoneBrick.blockID);
		var1.setBlock(i + 5, j + 19, k + 17, Block.stoneBrick.blockID);
		var1.setBlock(i + 5, j + 19, k + 18, Block.stoneBrick.blockID);
		var1.setBlock(i + 5, j + 19, k + 19, Block.stoneBrick.blockID);
		var1.setBlock(i + 5, j + 19, k + 20, Block.stoneBrick.blockID);
		var1.setBlock(i + 5, j + 19, k + 21, Block.stoneBrick.blockID);
		var1.setBlock(i + 5, j + 19, k + 22, Block.stoneBrick.blockID);
		var1.setBlock(i + 5, j + 19, k + 23, Block.stoneBrick.blockID);
		var1.setBlock(i + 5, j + 19, k + 24, Block.stoneBrick.blockID);
		var1.setBlock(i + 5, j + 19, k + 25, Block.stoneBrick.blockID);
		var1.setBlock(i + 6, j + 0, k + 0, Block.dirt.blockID);
		var1.setBlock(i + 6, j + 0, k + 1, Block.dirt.blockID);
		var1.setBlock(i + 6, j + 0, k + 2, Block.dirt.blockID);
		var1.setBlock(i + 6, j + 0, k + 3, Block.dirt.blockID);
		var1.setBlock(i + 6, j + 0, k + 4, Block.dirt.blockID);
		var1.setBlock(i + 6, j + 0, k + 5, Block.dirt.blockID);
		var1.setBlock(i + 6, j + 0, k + 6, Block.dirt.blockID);
		var1.setBlock(i + 6, j + 0, k + 7, Block.dirt.blockID);
		var1.setBlock(i + 6, j + 0, k + 8, Block.dirt.blockID);
		var1.setBlock(i + 6, j + 0, k + 9, Block.dirt.blockID);
		var1.setBlock(i + 6, j + 0, k + 10, Block.dirt.blockID);
		var1.setBlock(i + 6, j + 0, k + 11, Block.dirt.blockID);
		var1.setBlock(i + 6, j + 0, k + 12, Block.dirt.blockID);
		var1.setBlock(i + 6, j + 0, k + 13, Block.dirt.blockID);
		var1.setBlock(i + 6, j + 0, k + 14, Block.dirt.blockID);
		var1.setBlock(i + 6, j + 0, k + 15, Block.dirt.blockID);
		var1.setBlock(i + 6, j + 0, k + 16, Block.dirt.blockID);
		var1.setBlock(i + 6, j + 0, k + 17, Block.dirt.blockID);
		var1.setBlock(i + 6, j + 0, k + 18, Block.dirt.blockID);
		var1.setBlock(i + 6, j + 0, k + 19, Block.dirt.blockID);
		var1.setBlock(i + 6, j + 0, k + 20, Block.dirt.blockID);
		var1.setBlock(i + 6, j + 0, k + 21, Block.dirt.blockID);
		var1.setBlock(i + 6, j + 0, k + 22, Block.dirt.blockID);
		var1.setBlock(i + 6, j + 0, k + 23, Block.dirt.blockID);
		var1.setBlock(i + 6, j + 0, k + 24, Block.dirt.blockID);
		var1.setBlock(i + 6, j + 0, k + 25, Block.dirt.blockID);
		var1.setBlock(i + 6, j + 0, k + 26, Block.dirt.blockID);
		var1.setBlock(i + 6, j + 1, k + 0, Block.dirt.blockID);
		var1.setBlock(i + 6, j + 1, k + 1, Block.dirt.blockID);
		var1.setBlock(i + 6, j + 1, k + 2, Block.dirt.blockID);
		var1.setBlock(i + 6, j + 1, k + 3, Block.dirt.blockID);
		var1.setBlock(i + 6, j + 1, k + 4, Block.dirt.blockID);

		generate2(var1, var2, i, j, k);
		return true;
	}

	public boolean generate2(World var1, Random rand, int i, int j, int k) {
		var1.setBlock(i + 6, j + 1, k + 5, Block.dirt.blockID);
		var1.setBlock(i + 6, j + 1, k + 6, Block.dirt.blockID);
		var1.setBlock(i + 6, j + 1, k + 7, Block.dirt.blockID);
		var1.setBlock(i + 6, j + 1, k + 8, Block.dirt.blockID);
		var1.setBlock(i + 6, j + 1, k + 9, Block.dirt.blockID);
		var1.setBlock(i + 6, j + 1, k + 10, Block.dirt.blockID);
		var1.setBlock(i + 6, j + 1, k + 11, Block.dirt.blockID);
		var1.setBlock(i + 6, j + 1, k + 12, Block.dirt.blockID);
		var1.setBlock(i + 6, j + 1, k + 13, Block.dirt.blockID);
		var1.setBlock(i + 6, j + 1, k + 14, Block.dirt.blockID);
		var1.setBlock(i + 6, j + 1, k + 15, Block.dirt.blockID);
		var1.setBlock(i + 6, j + 1, k + 16, Block.dirt.blockID);
		var1.setBlock(i + 6, j + 1, k + 17, Block.dirt.blockID);
		var1.setBlock(i + 6, j + 1, k + 18, Block.dirt.blockID);
		var1.setBlock(i + 6, j + 1, k + 19, Block.dirt.blockID);
		var1.setBlock(i + 6, j + 1, k + 20, Block.dirt.blockID);
		var1.setBlock(i + 6, j + 1, k + 21, Block.dirt.blockID);
		var1.setBlock(i + 6, j + 1, k + 22, Block.dirt.blockID);
		var1.setBlock(i + 6, j + 1, k + 23, Block.dirt.blockID);
		var1.setBlock(i + 6, j + 1, k + 24, Block.dirt.blockID);
		var1.setBlock(i + 6, j + 1, k + 25, Block.dirt.blockID);
		var1.setBlock(i + 6, j + 1, k + 26, Block.dirt.blockID);
		var1.setBlock(i + 6, j + 2, k + 0, Block.grass.blockID);
		var1.setBlock(i + 6, j + 2, k + 1, Block.grass.blockID);
		var1.setBlock(i + 6, j + 2, k + 2, Block.grass.blockID);
		var1.setBlock(i + 6, j + 2, k + 3, Block.grass.blockID);
		var1.setBlock(i + 6, j + 2, k + 4, Block.dirt.blockID);
		var1.setBlock(i + 6, j + 2, k + 5, Block.stoneBrick.blockID);
		var1.setBlock(i + 6, j + 2, k + 6, Block.stoneBrick.blockID);
		var1.setBlock(i + 6, j + 2, k + 7, Block.stoneBrick.blockID);
		var1.setBlock(i + 6, j + 2, k + 8, Block.stoneDoubleSlab.blockID);
		var1.setBlock(i + 6, j + 2, k + 9, Block.stoneDoubleSlab.blockID);
		var1.setBlock(i + 6, j + 2, k + 10, Block.stoneDoubleSlab.blockID);
		var1.setBlock(i + 6, j + 2, k + 11, Block.stoneDoubleSlab.blockID);
		var1.setBlock(i + 6, j + 2, k + 12, Block.stoneDoubleSlab.blockID);
		var1.setBlock(i + 6, j + 2, k + 13, Block.stoneDoubleSlab.blockID);
		var1.setBlock(i + 6, j + 2, k + 14, Block.brick.blockID);
		var1.setBlock(i + 6, j + 2, k + 15, Block.brick.blockID);
		var1.setBlock(i + 6, j + 2, k + 16, Block.stoneBrick.blockID);
		var1.setBlock(i + 6, j + 2, k + 17, Block.stoneBrick.blockID);
		var1.setBlock(i + 6, j + 2, k + 18, Block.stoneBrick.blockID);
		var1.setBlock(i + 6, j + 2, k + 19, Block.brick.blockID);
		var1.setBlock(i + 6, j + 2, k + 20, Block.brick.blockID);
		var1.setBlock(i + 6, j + 2, k + 21, Block.stoneBrick.blockID);
		var1.setBlockAndMetadata(i + 6, j + 2, k + 22, Block.stoneBrick.blockID, 2);
		var1.setBlock(i + 6, j + 2, k + 23, Block.stoneBrick.blockID);
		var1.setBlock(i + 6, j + 2, k + 24, Block.stoneBrick.blockID);
		var1.setBlock(i + 6, j + 2, k + 25, Block.grass.blockID);
		var1.setBlock(i + 6, j + 2, k + 26, Block.grass.blockID);
		var1.setBlock(i + 6, j + 3, k + 4, Block.brick.blockID);
		var1.setBlock(i + 6, j + 3, k + 5, Block.brick.blockID);
		var1.setBlock(i + 6, j + 3, k + 6, Block.brick.blockID);
		var1.setBlock(i + 6, j + 3, k + 14, Block.brick.blockID);
		var1.setBlock(i + 6, j + 3, k + 15, Block.brick.blockID);
		var1.setBlock(i + 6, j + 3, k + 19, Block.brick.blockID);
		var1.setBlock(i + 6, j + 3, k + 20, Block.brick.blockID);
		var1.setBlockAndMetadata(i + 6, j + 3, k + 23, Block.chest.blockID, 2);
		var1.setBlock(i + 6, j + 3, k + 24, Block.stoneBrick.blockID);
		var1.setBlock(i + 6, j + 4, k + 4, Block.brick.blockID);
		var1.setBlock(i + 6, j + 4, k + 5, Block.brick.blockID);
		var1.setBlock(i + 6, j + 4, k + 6, Block.brick.blockID);
		var1.setBlock(i + 6, j + 4, k + 14, Block.brick.blockID);
		var1.setBlock(i + 6, j + 4, k + 15, Block.brick.blockID);
		var1.setBlock(i + 6, j + 4, k + 19, Block.brick.blockID);
		var1.setBlock(i + 6, j + 4, k + 20, Block.brick.blockID);
		var1.setBlockAndMetadata(i + 6, j + 4, k + 23, Block.chest.blockID, 2);
		var1.setBlock(i + 6, j + 4, k + 24, Block.stoneBrick.blockID);
		var1.setBlock(i + 6, j + 5, k + 4, Block.brick.blockID);
		var1.setBlock(i + 6, j + 5, k + 5, Block.brick.blockID);
		var1.setBlock(i + 6, j + 5, k + 6, Block.brick.blockID);
		var1.setBlock(i + 6, j + 5, k + 14, Block.brick.blockID);
		var1.setBlock(i + 6, j + 5, k + 15, Block.brick.blockID);
		var1.setBlock(i + 6, j + 5, k + 19, Block.brick.blockID);
		var1.setBlock(i + 6, j + 5, k + 20, Block.brick.blockID);
		var1.setBlock(i + 6, j + 5, k + 24, Block.stoneBrick.blockID);
		var1.setBlock(i + 6, j + 6, k + 4, Block.brick.blockID);
		var1.setBlock(i + 6, j + 6, k + 5, Block.brick.blockID);
		var1.setBlock(i + 6, j + 6, k + 6, Block.brick.blockID);
		var1.setBlock(i + 6, j + 6, k + 7, Block.glowStone.blockID);
		var1.setBlock(i + 6, j + 6, k + 14, Block.netherrack.blockID);
		var1.setBlock(i + 6, j + 6, k + 15, Block.brick.blockID);
		var1.setBlock(i + 6, j + 6, k + 19, Block.brick.blockID);
		var1.setBlock(i + 6, j + 6, k + 20, Block.brick.blockID);
		var1.setBlock(i + 6, j + 6, k + 21, Block.stoneBrick.blockID);
		var1.setBlock(i + 6, j + 6, k + 22, Block.stoneBrick.blockID);
		var1.setBlock(i + 6, j + 6, k + 23, Block.stoneBrick.blockID);
		var1.setBlock(i + 6, j + 6, k + 24, Block.stoneBrick.blockID);
		var1.setBlock(i + 6, j + 6, k + 25, Block.stoneBrick.blockID);
		var1.setBlock(i + 6, j + 7, k + 4, Block.brick.blockID);
		var1.setBlock(i + 6, j + 7, k + 5, Block.brick.blockID);
		var1.setBlock(i + 6, j + 7, k + 6, Block.brick.blockID);
