package fossil.gens;

import java.util.Random;

import net.minecraft.block.Block;
import net.minecraft.item.Item;
import net.minecraft.item.ItemStack;
import net.minecraft.tileentity.TileEntityChest;
import net.minecraft.world.World;
import net.minecraft.world.gen.feature.WorldGenerator;

public class WorldGeneratorBigShip extends WorldGenerator
{
	/*protected int[] GetValidSpawnBlocks()
	{
		return new int[] 
		{
				Block.waterStill.blockID,
				Block.sand.blockID
		};
	}

	public boolean LocationIsValidSpawn(World world, int i, int j, int k)
	{
	int distanceToAir = 0;
	int checkID = world.getBlockId(i, j, k);

	while (checkID != 0)
	{
	distanceToAir++;
	checkID = world.getBlockId(i, j + distanceToAir, k);
	}

	if (distanceToAir > 0)
	{
	return false;
	}
	j += distanceToAir - 1;

	int blockID = world.getBlockId(i, j, k);
	int blockIDAbove = world.getBlockId(i, j + 1, k);
	int blockIDBelow = world.getBlockId(i, j - 1, k);
	for (int x : GetValidSpawnBlocks())
	{
	if (blockIDAbove != 0)
	{
	return false;
	}
	if (blockID == x)
	{
	return true;
	} else if (blockID == Block.snow.blockID && blockIDBelow == x)
	{
	return true;
	}
	}
	return false;
	}

	public WorldGeneratorBigShip()
	{
	}*/

	public boolean generate(World world, Random rand, int i, int j, int k) 
	{
		
		 // check that each corner is one of the valid spawn blocks
		//if (!LocationIsValidSpawn(world, i, j, k) || !LocationIsValidSpawn(world, i + 4, j, k) || !LocationIsValidSpawn(world, i + 4, j, k + 4) || !LocationIsValidSpawn(world, i, j, k + 4))
		//{
		//return false;
		//}
		
		System.out.println("Generating Big Ship");
		
		world.setBlockAndMetadata(i + 4, j + 9, k + 22, Block.stoneSingleSlab.blockID, 2);
		world.setBlockAndMetadata(i + 4, j + 9, k + 36, Block.stoneSingleSlab.blockID, 2);
		world.setBlockAndMetadata(i + 5, j + 9, k + 22, Block.stoneSingleSlab.blockID, 2);
		world.setBlockAndMetadata(i + 5, j + 9, k + 36, Block.stoneSingleSlab.blockID, 2);
		world.setBlock(i + 5, j + 10, k + 4, Block.planks.blockID);
		world.setBlock(i + 5, j + 10, k + 5, Block.planks.blockID);
		world.setBlock(i + 5, j + 10, k + 6, Block.planks.blockID);
		world.setBlock(i + 5, j + 10, k + 7, Block.planks.blockID);
		world.setBlock(i + 5, j + 10, k + 8, Block.planks.blockID);
		world.setBlock(i + 5, j + 10, k + 9, Block.planks.blockID);
		world.setBlock(i + 5, j + 10, k + 10, Block.planks.blockID);
		world.setBlock(i + 5, j + 11, k + 4, Block.planks.blockID);
		world.setBlock(i + 5, j + 11, k + 5, Block.glass.blockID);
		world.setBlock(i + 5, j + 11, k + 6, Block.glass.blockID);
		world.setBlock(i + 5, j + 11, k + 7, Block.glass.blockID);
		world.setBlock(i + 5, j + 11, k + 8, Block.glass.blockID);
		world.setBlock(i + 5, j + 11, k + 9, Block.planks.blockID);
		world.setBlock(i + 5, j + 11, k + 10, Block.planks.blockID);
		world.setBlock(i + 5, j + 12, k + 4, Block.planks.blockID);
		world.setBlock(i + 5, j + 12, k + 5, Block.planks.blockID);
		world.setBlock(i + 5, j + 12, k + 6, Block.planks.blockID);
		world.setBlock(i + 5, j + 12, k + 7, Block.planks.blockID);
		world.setBlock(i + 5, j + 12, k + 8, Block.planks.blockID);
		world.setBlock(i + 5, j + 12, k + 9, Block.planks.blockID);
		world.setBlock(i + 5, j + 12, k + 10, Block.planks.blockID);
		world.setBlock(i + 5, j + 13, k + 4, Block.planks.blockID);
		world.setBlock(i + 5, j + 13, k + 5, Block.planks.blockID);
		world.setBlock(i + 5, j + 13, k + 6, Block.planks.blockID);
		world.setBlock(i + 5, j + 13, k + 7, Block.planks.blockID);
		world.setBlock(i + 5, j + 13, k + 8, Block.planks.blockID);
		world.setBlock(i + 5, j + 13, k + 9, Block.planks.blockID);
		world.setBlock(i + 5, j + 13, k + 10, Block.planks.blockID);
		world.setBlock(i + 5, j + 14, k + 4, Block.fence.blockID);
		world.setBlock(i + 5, j + 14, k + 5, Block.fence.blockID);
		world.setBlock(i + 5, j + 14, k + 6, Block.fence.blockID);
		world.setBlock(i + 5, j + 14, k + 7, Block.fence.blockID);
		world.setBlock(i + 5, j + 14, k + 8, Block.fence.blockID);
		world.setBlock(i + 5, j + 14, k + 9, Block.fence.blockID);
		world.setBlock(i + 5, j + 14, k + 10, Block.fence.blockID);
		world.setBlock(i + 5, j + 15, k + 22, Block.cloth.blockID);
		world.setBlock(i + 5, j + 15, k + 36, Block.cloth.blockID);
		world.setBlock(i + 5, j + 16, k + 22, Block.cloth.blockID);
		world.setBlock(i + 5, j + 16, k + 36, Block.cloth.blockID);
		world.setBlock(i + 5, j + 17, k + 22, Block.cloth.blockID);
		world.setBlock(i + 5, j + 17, k + 36, Block.cloth.blockID);
		world.setBlock(i + 5, j + 18, k + 22, Block.cloth.blockID);
		world.setBlock(i + 5, j + 18, k + 36, Block.cloth.blockID);
		world.setBlock(i + 5, j + 19, k + 22, Block.cloth.blockID);
		world.setBlock(i + 5, j + 19, k + 35, Block.cloth.blockID);
		world.setBlock(i + 5, j + 20, k + 21, Block.cloth.blockID);
		world.setBlock(i + 5, j + 20, k + 34, Block.planks.blockID);
		world.setBlock(i + 5, j + 21, k + 20, Block.planks.blockID);
		world.setBlock(i + 5, j + 21, k + 36, Block.cloth.blockID);
		world.setBlock(i + 5, j + 22, k + 36, Block.cloth.blockID);
		world.setBlock(i + 5, j + 23, k + 22, Block.cloth.blockID);
		world.setBlock(i + 5, j + 23, k + 36, Block.cloth.blockID);
		world.setBlock(i + 5, j + 24, k + 22, Block.cloth.blockID);
		world.setBlock(i + 5, j + 24, k + 36, Block.cloth.blockID);
		world.setBlock(i + 5, j + 25, k + 22, Block.cloth.blockID);
		world.setBlock(i + 5, j + 25, k + 35, Block.cloth.blockID);
		world.setBlock(i + 5, j + 26, k + 22, Block.cloth.blockID);
		world.setBlock(i + 5, j + 26, k + 34, Block.planks.blockID);
		world.setBlock(i + 5, j + 27, k + 21, Block.cloth.blockID);
		world.setBlock(i + 5, j + 28, k + 20, Block.planks.blockID);
		world.setBlock(i + 6, j + 4, k + 4, Block.planks.blockID);
		world.setBlock(i + 6, j + 4, k + 5, Block.planks.blockID);
		world.setBlock(i + 6, j + 4, k + 6, Block.planks.blockID);
		world.setBlock(i + 6, j + 4, k + 7, Block.planks.blockID);
		world.setBlock(i + 6, j + 4, k + 8, Block.planks.blockID);
		world.setBlock(i + 6, j + 4, k + 9, Block.planks.blockID);
		world.setBlock(i + 6, j + 4, k + 10, Block.planks.blockID);
		world.setBlock(i + 6, j + 4, k + 11, Block.planks.blockID);
		world.setBlock(i + 6, j + 4, k + 12, Block.planks.blockID);
		world.setBlock(i + 6, j + 4, k + 13, Block.planks.blockID);
		world.setBlock(i + 6, j + 4, k + 14, Block.planks.blockID);
		world.setBlock(i + 6, j + 4, k + 15, Block.planks.blockID);
		world.setBlock(i + 6, j + 4, k + 16, Block.planks.blockID);
		world.setBlock(i + 6, j + 4, k + 17, Block.planks.blockID);
		world.setBlock(i + 6, j + 4, k + 18, Block.planks.blockID);
		world.setBlock(i + 6, j + 4, k + 19, Block.planks.blockID);
		world.setBlock(i + 6, j + 4, k + 20, Block.planks.blockID);
		world.setBlock(i + 6, j + 4, k + 21, Block.planks.blockID);
		world.setBlock(i + 6, j + 4, k + 22, Block.planks.blockID);
		world.setBlock(i + 6, j + 4, k + 23, Block.planks.blockID);
		world.setBlock(i + 6, j + 4, k + 24, Block.planks.blockID);
		world.setBlock(i + 6, j + 4, k + 25, Block.planks.blockID);
		world.setBlock(i + 6, j + 4, k + 26, Block.planks.blockID);
		world.setBlock(i + 6, j + 4, k + 27, Block.planks.blockID);
		world.setBlock(i + 6, j + 4, k + 28, Block.planks.blockID);
		world.setBlock(i + 6, j + 4, k + 29, Block.planks.blockID);
		world.setBlock(i + 6, j + 4, k + 30, Block.planks.blockID);
		world.setBlock(i + 6, j + 4, k + 31, Block.planks.blockID);
		world.setBlock(i + 6, j + 4, k + 32, Block.planks.blockID);
		world.setBlock(i + 6, j + 4, k + 33, Block.planks.blockID);
		world.setBlock(i + 6, j + 4, k + 34, Block.planks.blockID);
		world.setBlock(i + 6, j + 4, k + 35, Block.planks.blockID);
		world.setBlock(i + 6, j + 4, k + 36, Block.planks.blockID);
		world.setBlock(i + 6, j + 4, k + 37, Block.planks.blockID);
		world.setBlock(i + 6, j + 4, k + 38, Block.planks.blockID);
		world.setBlock(i + 6, j + 4, k + 39, Block.planks.blockID);
		world.setBlock(i + 6, j + 4, k + 40, Block.planks.blockID);
		world.setBlock(i + 6, j + 5, k + 4, Block.planks.blockID);
		world.setBlock(i + 6, j + 5, k + 5, Block.planks.blockID);
		world.setBlock(i + 6, j + 5, k + 6, Block.planks.blockID);
		world.setBlock(i + 6, j + 5, k + 7, Block.planks.blockID);
		world.setBlock(i + 6, j + 5, k + 8, Block.planks.blockID);
		world.setBlock(i + 6, j + 5, k + 9, Block.planks.blockID);
		world.setBlock(i + 6, j + 5, k + 10, Block.planks.blockID);
		world.setBlock(i + 6, j + 5, k + 11, Block.planks.blockID);
		world.setBlock(i + 6, j + 5, k + 12, Block.glass.blockID);
		world.setBlock(i + 6, j + 5, k + 13, Block.planks.blockID);
		world.setBlock(i + 6, j + 5, k + 14, Block.planks.blockID);
		world.setBlock(i + 6, j + 5, k + 15, Block.planks.blockID);
		world.setBlock(i + 6, j + 5, k + 16, Block.planks.blockID);
		world.setBlock(i + 6, j + 5, k + 17, Block.glass.blockID);
		world.setBlock(i + 6, j + 5, k + 18, Block.planks.blockID);
		world.setBlock(i + 6, j + 5, k + 19, Block.planks.blockID);
		world.setBlock(i + 6, j + 5, k + 20, Block.planks.blockID);
		world.setBlock(i + 6, j + 5, k + 21, Block.glass.blockID);
		world.setBlock(i + 6, j + 5, k + 22, Block.planks.blockID);
		world.setBlock(i + 6, j + 5, k + 23, Block.planks.blockID);
		world.setBlock(i + 6, j + 5, k + 24, Block.planks.blockID);
		world.setBlock(i + 6, j + 5, k + 25, Block.planks.blockID);
		world.setBlock(i + 6, j + 5, k + 26, Block.planks.blockID);
		world.setBlock(i + 6, j + 5, k + 27, Block.glass.blockID);
		world.setBlock(i + 6, j + 5, k + 28, Block.planks.blockID);
		world.setBlock(i + 6, j + 5, k + 29, Block.planks.blockID);
		world.setBlock(i + 6, j + 5, k + 30, Block.planks.blockID);
		world.setBlock(i + 6, j + 5, k + 31, Block.planks.blockID);
		world.setBlock(i + 6, j + 5, k + 32, Block.glass.blockID);
		world.setBlock(i + 6, j + 5, k + 33, Block.planks.blockID);
		world.setBlock(i + 6, j + 5, k + 34, Block.planks.blockID);
		world.setBlock(i + 6, j + 5, k + 35, Block.planks.blockID);
		world.setBlock(i + 6, j + 5, k + 36, Block.planks.blockID);
		world.setBlock(i + 6, j + 5, k + 37, Block.planks.blockID);
		world.setBlock(i + 6, j + 5, k + 38, Block.planks.blockID);
		world.setBlock(i + 6, j + 5, k + 39, Block.planks.blockID);
		world.setBlock(i + 6, j + 5, k + 40, Block.planks.blockID);
		world.setBlock(i + 6, j + 6, k + 4, Block.planks.blockID);
		world.setBlock(i + 6, j + 6, k + 5, Block.planks.blockID);
		world.setBlock(i + 6, j + 6, k + 6, Block.planks.blockID);
		world.setBlock(i + 6, j + 6, k + 7, Block.planks.blockID);
		world.setBlock(i + 6, j + 6, k + 8, Block.planks.blockID);
		world.setBlock(i + 6, j + 6, k + 9, Block.planks.blockID);
		world.setBlock(i + 6, j + 6, k + 10, Block.planks.blockID);
		world.setBlock(i + 6, j + 6, k + 11, Block.planks.blockID);
		world.setBlock(i + 6, j + 6, k + 12, Block.planks.blockID);
		world.setBlock(i + 6, j + 6, k + 13, Block.planks.blockID);
		world.setBlock(i + 6, j + 6, k + 14, Block.planks.blockID);
		world.setBlock(i + 6, j + 6, k + 15, Block.planks.blockID);
		world.setBlock(i + 6, j + 6, k + 16, Block.planks.blockID);
		world.setBlock(i + 6, j + 6, k + 17, Block.planks.blockID);
		world.setBlock(i + 6, j + 6, k + 18, Block.planks.blockID);
		world.setBlock(i + 6, j + 6, k + 19, Block.planks.blockID);
		world.setBlock(i + 6, j + 6, k + 20, Block.planks.blockID);
		world.setBlock(i + 6, j + 6, k + 21, Block.planks.blockID);
		world.setBlock(i + 6, j + 6, k + 22, Block.planks.blockID);
		world.setBlock(i + 6, j + 6, k + 23, Block.planks.blockID);
		world.setBlock(i + 6, j + 6, k + 24, Block.planks.blockID);
		world.setBlock(i + 6, j + 6, k + 25, Block.planks.blockID);
		world.setBlock(i + 6, j + 6, k + 26, Block.planks.blockID);
		world.setBlock(i + 6, j + 6, k + 27, Block.planks.blockID);
		world.setBlock(i + 6, j + 6, k + 28, Block.planks.blockID);
		world.setBlock(i + 6, j + 6, k + 29, Block.planks.blockID);
		world.setBlock(i + 6, j + 6, k + 30, Block.planks.blockID);
		world.setBlock(i + 6, j + 6, k + 31, Block.planks.blockID);
		world.setBlock(i + 6, j + 6, k + 32, Block.planks.blockID);
		world.setBlock(i + 6, j + 6, k + 33, Block.planks.blockID);
		world.setBlock(i + 6, j + 6, k + 34, Block.planks.blockID);
		world.setBlock(i + 6, j + 6, k + 35, Block.planks.blockID);
		world.setBlock(i + 6, j + 6, k + 36, Block.planks.blockID);
		world.setBlock(i + 6, j + 6, k + 37, Block.planks.blockID);
		world.setBlock(i + 6, j + 6, k + 38, Block.planks.blockID);
		world.setBlock(i + 6, j + 6, k + 39, Block.planks.blockID);
		world.setBlock(i + 6, j + 6, k + 40, Block.planks.blockID);
		world.setBlock(i + 6, j + 7, k + 4, Block.planks.blockID);
		world.setBlock(i + 6, j + 7, k + 5, Block.planks.blockID);
		world.setBlock(i + 6, j + 7, k + 7, Block.planks.blockID);
		world.setBlock(i + 6, j + 7, k + 8, Block.planks.blockID);
		world.setBlock(i + 6, j + 7, k + 10, Block.planks.blockID);
		world.setBlock(i + 6, j + 7, k + 11, Block.planks.blockID);
		world.setBlock(i + 6, j + 7, k + 13, Block.planks.blockID);
		world.setBlock(i + 6, j + 7, k + 14, Block.planks.blockID);
		world.setBlock(i + 6, j + 7, k + 16, Block.planks.blockID);
		world.setBlock(i + 6, j + 7, k + 17, Block.planks.blockID);
		world.setBlock(i + 6, j + 7, k + 19, Block.planks.blockID);
		world.setBlock(i + 6, j + 7, k + 20, Block.planks.blockID);
		world.setBlock(i + 6, j + 7, k + 21, Block.planks.blockID);
		world.setBlock(i + 6, j + 7, k + 22, Block.planks.blockID);
		world.setBlock(i + 6, j + 7, k + 23, Block.planks.blockID);
		world.setBlock(i + 6, j + 7, k + 24, Block.planks.blockID);
		world.setBlock(i + 6, j + 7, k + 25, Block.planks.blockID);
		world.setBlock(i + 6, j + 7, k + 27, Block.planks.blockID);
		world.setBlock(i + 6, j + 7, k + 28, Block.planks.blockID);
		world.setBlockAndMetadata(i + 6, j + 7, k + 29, Block.dispenser.blockID, 4);
		world.setBlock(i + 6, j + 7, k + 30, Block.planks.blockID);
		world.setBlock(i + 6, j + 7, k + 31, Block.planks.blockID);
		world.setBlockAndMetadata(i + 6, j + 7, k + 32, Block.dispenser.blockID, 4);
		world.setBlock(i + 6, j + 7, k + 33, Block.planks.blockID);
		world.setBlock(i + 6, j + 7, k + 34, Block.planks.blockID);
		world.setBlockAndMetadata(i + 6, j + 7, k + 35, Block.dispenser.blockID, 4);
		world.setBlock(i + 6, j + 7, k + 36, Block.planks.blockID);
		world.setBlock(i + 6, j + 7, k + 37, Block.planks.blockID);
		world.setBlockAndMetadata(i + 6, j + 7, k + 38, Block.dispenser.blockID, 4);
		world.setBlock(i + 6, j + 7, k + 39, Block.planks.blockID);
		world.setBlock(i + 6, j + 7, k + 40, Block.planks.blockID);
		world.setBlock(i + 6, j + 7, k + 41, Block.planks.blockID);
		world.setBlock(i + 6, j + 7, k + 42, Block.planks.blockID);
		world.setBlock(i + 6, j + 7, k + 43, Block.planks.blockID);
		world.setBlock(i + 6, j + 8, k + 4, Block.planks.blockID);
		world.setBlock(i + 6, j + 8, k + 5, Block.planks.blockID);
		world.setBlock(i + 6, j + 8, k + 7, Block.planks.blockID);
		world.setBlock(i + 6, j + 8, k + 8, Block.planks.blockID);
		world.setBlock(i + 6, j + 8, k + 10, Block.planks.blockID);
		world.setBlock(i + 6, j + 8, k + 11, Block.planks.blockID);
		world.setBlock(i + 6, j + 8, k + 13, Block.planks.blockID);
		world.setBlock(i + 6, j + 8, k + 14, Block.planks.blockID);
		world.setBlock(i + 6, j + 8, k + 16, Block.planks.blockID);
		world.setBlock(i + 6, j + 8, k + 17, Block.planks.blockID);
		world.setBlock(i + 6, j + 8, k + 19, Block.planks.blockID);
		world.setBlock(i + 6, j + 8, k + 20, Block.planks.blockID);
		world.setBlock(i + 6, j + 8, k + 21, Block.planks.blockID);
		world.setBlock(i + 6, j + 8, k + 22, Block.planks.blockID);
		world.setBlock(i + 6, j + 8, k + 23, Block.planks.blockID);
		world.setBlock(i + 6, j + 8, k + 24, Block.planks.blockID);
		world.setBlock(i + 6, j + 8, k + 25, Block.planks.blockID);
		world.setBlock(i + 6, j + 8, k + 27, Block.planks.blockID);
		world.setBlock(i + 6, j + 8, k + 28, Block.planks.blockID);
		world.setBlock(i + 6, j + 8, k + 30, Block.planks.blockID);
		world.setBlock(i + 6, j + 8, k + 31, Block.planks.blockID);
		world.setBlock(i + 6, j + 8, k + 33, Block.planks.blockID);
		world.setBlock(i + 6, j + 8, k + 34, Block.planks.blockID);
		world.setBlock(i + 6, j + 8, k + 36, Block.planks.blockID);
		world.setBlock(i + 6, j + 8, k + 37, Block.planks.blockID);
		world.setBlock(i + 6, j + 8, k + 39, Block.planks.blockID);
		world.setBlock(i + 6, j + 8, k + 40, Block.planks.blockID);
		world.setBlock(i + 6, j + 8, k + 41, Block.planks.blockID);
		world.setBlock(i + 6, j + 8, k + 42, Block.planks.blockID);
		world.setBlock(i + 6, j + 8, k + 43, Block.planks.blockID);
		world.setBlock(i + 6, j + 8, k + 44, Block.planks.blockID);
		world.setBlock(i + 6, j + 8, k + 45, Block.planks.blockID);
		world.setBlock(i + 6, j + 8, k + 46, Block.planks.blockID);
		world.setBlockAndMetadata(i + 6, j + 9, k + 4, Block.cloth.blockID, 14);
		world.setBlockAndMetadata(i + 6, j + 9, k + 5, Block.cloth.blockID, 14);
		world.setBlockAndMetadata(i + 6, j + 9, k + 6, Block.cloth.blockID, 14);
		world.setBlockAndMetadata(i + 6, j + 9, k + 7, Block.cloth.blockID, 14);
		world.setBlockAndMetadata(i + 6, j + 9, k + 8, Block.cloth.blockID, 14);
		world.setBlockAndMetadata(i + 6, j + 9, k + 9, Block.cloth.blockID, 14);
		world.setBlock(i + 6, j + 9, k + 10, Block.planks.blockID);
		world.setBlock(i + 6, j + 9, k + 11, Block.planks.blockID);
		world.setBlock(i + 6, j + 9, k + 12, Block.planks.blockID);
		world.setBlock(i + 6, j + 9, k + 13, Block.planks.blockID);
		world.setBlock(i + 6, j + 9, k + 14, Block.planks.blockID);
		world.setBlock(i + 6, j + 9, k + 15, Block.planks.blockID);
		world.setBlock(i + 6, j + 9, k + 16, Block.planks.blockID);
		world.setBlock(i + 6, j + 9, k + 17, Block.planks.blockID);
		world.setBlock(i + 6, j + 9, k + 18, Block.planks.blockID);
		world.setBlock(i + 6, j + 9, k + 19, Block.planks.blockID);
		world.setBlock(i + 6, j + 9, k + 20, Block.planks.blockID);
		world.setBlock(i + 6, j + 9, k + 21, Block.planks.blockID);
		world.setBlock(i + 6, j + 9, k + 22, Block.planks.blockID);
		world.setBlock(i + 6, j + 9, k + 23, Block.planks.blockID);
		world.setBlock(i + 6, j + 9, k + 24, Block.planks.blockID);
		world.setBlock(i + 6, j + 9, k + 25, Block.planks.blockID);
		world.setBlock(i + 6, j + 9, k + 26, Block.planks.blockID);
		world.setBlock(i + 6, j + 9, k + 27, Block.planks.blockID);
		world.setBlock(i + 6, j + 9, k + 28, Block.planks.blockID);
		world.setBlock(i + 6, j + 9, k + 29, Block.planks.blockID);
		world.setBlock(i + 6, j + 9, k + 30, Block.planks.blockID);
		world.setBlock(i + 6, j + 9, k + 31, Block.planks.blockID);
		world.setBlock(i + 6, j + 9, k + 32, Block.planks.blockID);
		world.setBlock(i + 6, j + 9, k + 33, Block.planks.blockID);
		world.setBlock(i + 6, j + 9, k + 34, Block.planks.blockID);
		world.setBlock(i + 6, j + 9, k + 35, Block.planks.blockID);
		world.setBlock(i + 6, j + 9, k + 36, Block.planks.blockID);
		world.setBlock(i + 6, j + 9, k + 37, Block.planks.blockID);
		world.setBlock(i + 6, j + 9, k + 38, Block.planks.blockID);
		world.setBlock(i + 6, j + 9, k + 39, Block.planks.blockID);
		world.setBlock(i + 6, j + 9, k + 40, Block.planks.blockID);
		world.setBlock(i + 6, j + 9, k + 41, Block.planks.blockID);
		world.setBlock(i + 6, j + 9, k + 42, Block.planks.blockID);
		world.setBlock(i + 6, j + 9, k + 43, Block.planks.blockID);
		world.setBlock(i + 6, j + 9, k + 44, Block.planks.blockID);
		world.setBlock(i + 6, j + 9, k + 45, Block.planks.blockID);
		world.setBlock(i + 6, j + 9, k + 46, Block.planks.blockID);
		world.setBlock(i + 6, j + 10, k + 3, Block.planks.blockID);
		world.setBlock(i + 6, j + 10, k + 10, Block.planks.blockID);
		world.setBlock(i + 6, j + 10, k + 12, Block.fence.blockID);
		world.setBlock(i + 6, j + 10, k + 13, Block.fence.blockID);
		world.setBlock(i + 6, j + 10, k + 14, Block.fence.blockID);
		world.setBlock(i + 6, j + 10, k + 15, Block.fence.blockID);
		world.setBlock(i + 6, j + 10, k + 16, Block.fence.blockID);
		world.setBlock(i + 6, j + 10, k + 17, Block.fence.blockID);
		world.setBlock(i + 6, j + 10, k + 18, Block.fence.blockID);
		world.setBlock(i + 6, j + 10, k + 19, Block.fence.blockID);
		world.setBlock(i + 6, j + 10, k + 20, Block.fence.blockID);
		world.setBlock(i + 6, j + 10, k + 21, Block.fence.blockID);
		world.setBlock(i + 6, j + 10, k + 23, Block.fence.blockID);
		world.setBlock(i + 6, j + 10, k + 24, Block.fence.blockID);
		world.setBlock(i + 6, j + 10, k + 25, Block.fence.blockID);
		world.setBlock(i + 6, j + 10, k + 26, Block.fence.blockID);
		world.setBlock(i + 6, j + 10, k + 27, Block.fence.blockID);
		world.setBlock(i + 6, j + 10, k + 28, Block.fence.blockID);
		world.setBlock(i + 6, j + 10, k + 29, Block.fence.blockID);
		world.setBlock(i + 6, j + 10, k + 30, Block.fence.blockID);
		world.setBlock(i + 6, j + 10, k + 31, Block.fence.blockID);
		world.setBlock(i + 6, j + 10, k + 32, Block.fence.blockID);
		world.setBlock(i + 6, j + 10, k + 33, Block.fence.blockID);
		world.setBlock(i + 6, j + 10, k + 34, Block.fence.blockID);
		world.setBlock(i + 6, j + 10, k + 35, Block.fence.blockID);
		world.setBlock(i + 6, j + 10, k + 38, Block.planks.blockID);
		world.setBlock(i + 6, j + 10, k + 39, Block.planks.blockID);
		world.setBlock(i + 6, j + 10, k + 40, Block.planks.blockID);
		world.setBlock(i + 6, j + 10, k + 41, Block.planks.blockID);
		world.setBlock(i + 6, j + 10, k + 42, Block.planks.blockID);
		world.setBlock(i + 6, j + 10, k + 43, Block.planks.blockID);
		world.setBlock(i + 6, j + 10, k + 44, Block.planks.blockID);
		world.setBlock(i + 6, j + 10, k + 45, Block.planks.blockID);
		world.setBlock(i + 6, j + 10, k + 46, Block.planks.blockID);
		world.setBlock(i + 6, j + 11, k + 3, Block.planks.blockID);
		world.setBlock(i + 6, j + 11, k + 10, Block.planks.blockID);
		world.setBlock(i + 6, j + 11, k + 38, Block.fence.blockID);
		world.setBlock(i + 6, j + 11, k + 39, Block.fence.blockID);
		world.setBlock(i + 6, j + 11, k + 40, Block.fence.blockID);
		world.setBlock(i + 6, j + 11, k + 41, Block.fence.blockID);
		world.setBlock(i + 6, j + 11, k + 42, Block.fence.blockID);
		world.setBlock(i + 6, j + 11, k + 43, Block.fence.blockID);
		world.setBlock(i + 6, j + 11, k + 44, Block.fence.blockID);
		world.setBlock(i + 6, j + 11, k + 45, Block.fence.blockID);
		world.setBlock(i + 6, j + 11, k + 46, Block.fence.blockID);
		world.setBlock(i + 6, j + 12, k + 3, Block.planks.blockID);
		world.setBlock(i + 6, j + 12, k + 10, Block.planks.blockID);
		world.setBlock(i + 6, j + 13, k + 3, Block.planks.blockID);
		world.setBlock(i + 6, j + 13, k + 4, Block.planks.blockID);
		world.setBlock(i + 6, j + 13, k + 5, Block.planks.blockID);
		world.setBlock(i + 6, j + 13, k + 6, Block.planks.blockID);
		world.setBlock(i + 6, j + 13, k + 7, Block.planks.blockID);
		world.setBlock(i + 6, j + 13, k + 8, Block.planks.blockID);
		world.setBlock(i + 6, j + 13, k + 9, Block.planks.blockID);
		world.setBlock(i + 6, j + 13, k + 10, Block.planks.blockID);
		world.setBlock(i + 6, j + 14, k + 3, Block.fence.blockID);
		world.setBlock(i + 6, j + 14, k + 4, Block.fence.blockID);
		world.setBlock(i + 6, j + 15, k + 22, Block.cloth.blockID);
		world.setBlock(i + 6, j + 15, k + 36, Block.cloth.blockID);
		world.setBlock(i + 6, j + 16, k + 22, Block.cloth.blockID);
		world.setBlock(i + 6, j + 16, k + 36, Block.cloth.blockID);
		world.setBlock(i + 6, j + 17, k + 22, Block.cloth.blockID);
		world.setBlock(i + 6, j + 17, k + 36, Block.cloth.blockID);
		world.setBlock(i + 6, j + 18, k + 22, Block.cloth.blockID);
		world.setBlock(i + 6, j + 18, k + 36, Block.cloth.blockID);
		world.setBlock(i + 6, j + 19, k + 22, Block.cloth.blockID);
		world.setBlock(i + 6, j + 19, k + 35, Block.cloth.blockID);
		world.setBlock(i + 6, j + 20, k + 21, Block.cloth.blockID);
		world.setBlock(i + 6, j + 20, k + 34, Block.planks.blockID);
		world.setBlock(i + 6, j + 21, k + 20, Block.planks.blockID);
		world.setBlock(i + 6, j + 21, k + 36, Block.cloth.blockID);
		world.setBlock(i + 6, j + 22, k + 36, Block.cloth.blockID);
		world.setBlock(i + 6, j + 23, k + 22, Block.cloth.blockID);
		world.setBlock(i + 6, j + 23, k + 36, Block.cloth.blockID);
		world.setBlock(i + 6, j + 24, k + 22, Block.cloth.blockID);
		world.setBlock(i + 6, j + 24, k + 36, Block.cloth.blockID);
		world.setBlock(i + 6, j + 25, k + 22, Block.cloth.blockID);
		world.setBlock(i + 6, j + 25, k + 35, Block.cloth.blockID);
		world.setBlock(i + 6, j + 26, k + 22, Block.cloth.blockID);
		world.setBlock(i + 6, j + 26, k + 34, Block.planks.blockID);
		world.setBlock(i + 6, j + 27, k + 21, Block.cloth.blockID);
		world.setBlock(i + 6, j + 28, k + 20, Block.planks.blockID);
		world.setBlock(i + 7, j + 3, k + 4, Block.planks.blockID);
		world.setBlock(i + 7, j + 3, k + 5, Block.planks.blockID);
		world.setBlock(i + 7, j + 3, k + 6, Block.planks.blockID);
		world.setBlock(i + 7, j + 3, k + 7, Block.planks.blockID);
		world.setBlock(i + 7, j + 3, k + 8, Block.planks.blockID);
		world.setBlock(i + 7, j + 3, k + 9, Block.planks.blockID);
		world.setBlock(i + 7, j + 3, k + 10, Block.planks.blockID);
		world.setBlock(i + 7, j + 3, k + 11, Block.planks.blockID);
		world.setBlock(i + 7, j + 3, k + 12, Block.planks.blockID);
		world.setBlock(i + 7, j + 3, k + 13, Block.planks.blockID);
		world.setBlock(i + 7, j + 3, k + 14, Block.planks.blockID);
		world.setBlock(i + 7, j + 3, k + 15, Block.planks.blockID);
		world.setBlock(i + 7, j + 3, k + 16, Block.planks.blockID);
		world.setBlock(i + 7, j + 3, k + 17, Block.planks.blockID);
		world.setBlock(i + 7, j + 3, k + 18, Block.planks.blockID);
		world.setBlock(i + 7, j + 3, k + 19, Block.planks.blockID);
		world.setBlock(i + 7, j + 3, k + 20, Block.planks.blockID);
		world.setBlock(i + 7, j + 3, k + 21, Block.planks.blockID);
		world.setBlock(i + 7, j + 3, k + 22, Block.planks.blockID);
		world.setBlock(i + 7, j + 3, k + 23, Block.planks.blockID);
		world.setBlock(i + 7, j + 3, k + 24, Block.planks.blockID);
		world.setBlock(i + 7, j + 3, k + 25, Block.planks.blockID);
		world.setBlock(i + 7, j + 3, k + 26, Block.planks.blockID);
		world.setBlock(i + 7, j + 3, k + 27, Block.planks.blockID);
		world.setBlock(i + 7, j + 3, k + 28, Block.planks.blockID);
		world.setBlock(i + 7, j + 3, k + 29, Block.planks.blockID);
		world.setBlock(i + 7, j + 3, k + 30, Block.planks.blockID);
		world.setBlock(i + 7, j + 3, k + 31, Block.planks.blockID);
		world.setBlock(i + 7, j + 3, k + 32, Block.planks.blockID);
		world.setBlock(i + 7, j + 3, k + 33, Block.planks.blockID);
		world.setBlock(i + 7, j + 3, k + 34, Block.planks.blockID);
		world.setBlock(i + 7, j + 3, k + 35, Block.planks.blockID);
		world.setBlock(i + 7, j + 3, k + 36, Block.planks.blockID);
		world.setBlock(i + 7, j + 3, k + 37, Block.planks.blockID);
		world.setBlock(i + 7, j + 3, k + 38, Block.planks.blockID);
		world.setBlock(i + 7, j + 3, k + 39, Block.planks.blockID);
		world.setBlock(i + 7, j + 4, k + 3, Block.planks.blockID);
		world.setBlock(i + 7, j + 4, k + 4, Block.planks.blockID);
		world.setBlock(i + 7, j + 4, k + 40, Block.planks.blockID);
		world.setBlock(i + 7, j + 4, k + 41, Block.planks.blockID);
		world.setBlock(i + 7, j + 4, k + 42, Block.planks.blockID);
		world.setBlock(i + 7, j + 5, k + 3, Block.planks.blockID);
		world.setBlock(i + 7, j + 5, k + 4, Block.planks.blockID);
		world.setBlock(i + 7, j + 5, k + 40, Block.planks.blockID);
		world.setBlock(i + 7, j + 5, k + 41, Block.planks.blockID);
		world.setBlock(i + 7, j + 5, k + 42, Block.planks.blockID);
		world.setBlock(i + 7, j + 6, k + 3, Block.planks.blockID);
		world.setBlock(i + 7, j + 6, k + 4, Block.planks.blockID);
		world.setBlock(i + 7, j + 6, k + 5, Block.planks.blockID);
		world.setBlock(i + 7, j + 6, k + 6, Block.planks.blockID);
		world.setBlock(i + 7, j + 6, k + 7, Block.planks.blockID);
		world.setBlock(i + 7, j + 6, k + 8, Block.planks.blockID);
		world.setBlock(i + 7, j + 6, k + 9, Block.planks.blockID);
		world.setBlock(i + 7, j + 6, k + 10, Block.planks.blockID);
		world.setBlock(i + 7, j + 6, k + 11, Block.planks.blockID);
		world.setBlock(i + 7, j + 6, k + 12, Block.planks.blockID);
		world.setBlock(i + 7, j + 6, k + 13, Block.planks.blockID);
		world.setBlock(i + 7, j + 6, k + 14, Block.planks.blockID);
		world.setBlock(i + 7, j + 6, k + 15, Block.planks.blockID);
		world.setBlock(i + 7, j + 6, k + 16, Block.planks.blockID);
		world.setBlock(i + 7, j + 6, k + 17, Block.planks.blockID);
		world.setBlock(i + 7, j + 6, k + 18, Block.planks.blockID);
		world.setBlock(i + 7, j + 6, k + 19, Block.planks.blockID);
		world.setBlock(i + 7, j + 6, k + 20, Block.planks.blockID);
		world.setBlock(i + 7, j + 6, k + 21, Block.planks.blockID);
		world.setBlock(i + 7, j + 6, k + 22, Block.planks.blockID);
		world.setBlock(i + 7, j + 6, k + 23, Block.planks.blockID);
		world.setBlock(i + 7, j + 6, k + 24, Block.planks.blockID);
		world.setBlock(i + 7, j + 6, k + 25, Block.planks.blockID);
		world.setBlock(i + 7, j + 6, k + 26, Block.planks.blockID);
		world.setBlock(i + 7, j + 6, k + 27, Block.planks.blockID);
		world.setBlock(i + 7, j + 6, k + 28, Block.planks.blockID);
		world.setBlock(i + 7, j + 6, k + 29, Block.planks.blockID);
		world.setBlock(i + 7, j + 6, k + 30, Block.planks.blockID);
		world.setBlock(i + 7, j + 6, k + 31, Block.planks.blockID);
		world.setBlock(i + 7, j + 6, k + 32, Block.planks.blockID);
		world.setBlock(i + 7, j + 6, k + 33, Block.planks.blockID);
		world.setBlock(i + 7, j + 6, k + 34, Block.planks.blockID);
		world.setBlock(i + 7, j + 6, k + 35, Block.planks.blockID);
		world.setBlock(i + 7, j + 6, k + 36, Block.planks.blockID);
		world.setBlock(i + 7, j + 6, k + 37, Block.planks.blockID);
		world.setBlock(i + 7, j + 6, k + 38, Block.planks.blockID);
		world.setBlock(i + 7, j + 6, k + 39, Block.planks.blockID);
		world.setBlock(i + 7, j + 6, k + 40, Block.planks.blockID);
		world.setBlock(i + 7, j + 6, k + 41, Block.planks.blockID);
		world.setBlock(i + 7, j + 6, k + 42, Block.planks.blockID);
		world.setBlock(i + 7, j + 7, k + 3, Block.planks.blockID);
		world.setBlock(i + 7, j + 7, k + 4, Block.planks.blockID);
		world.setBlock(i + 7, j + 7, k + 41, Block.planks.blockID);
		world.setBlock(i + 7, j + 7, k + 43, Block.planks.blockID);
		world.setBlock(i + 7, j + 7, k + 44, Block.planks.blockID);
		world.setBlock(i + 7, j + 7, k + 45, Block.planks.blockID);
		world.setBlock(i + 7, j + 8, k + 3, Block.planks.blockID);
		world.setBlock(i + 7, j + 8, k + 4, Block.planks.blockID);
		world.setBlock(i + 7, j + 8, k + 41, Block.planks.blockID);
		world.setBlockAndMetadata(i + 7, j + 8, k + 45, Block.thinGlass.blockID, 3);
		world.setBlock(i + 7, j + 8, k + 46, Block.planks.blockID);
		world.setBlock(i + 7, j + 8, k + 47, Block.planks.blockID);
		world.setBlockAndMetadata(i + 7, j + 9, k + 3, Block.cloth.blockID, 14);
		world.setBlockAndMetadata(i + 7, j + 9, k + 4, Block.cloth.blockID, 14);
		world.setBlockAndMetadata(i + 7, j + 9, k + 5, Block.cloth.blockID, 14);
		world.setBlockAndMetadata(i + 7, j + 9, k + 6, Block.cloth.blockID, 14);
		world.setBlockAndMetadata(i + 7, j + 9, k + 7, Block.cloth.blockID, 14);
		world.setBlockAndMetadata(i + 7, j + 9, k + 8, Block.cloth.blockID, 14);
		world.setBlockAndMetadata(i + 7, j + 9, k + 9, Block.cloth.blockID, 14);
		world.setBlock(i + 7, j + 9, k + 10, Block.planks.blockID);
		world.setBlock(i + 7, j + 9, k + 11, Block.planks.blockID);
		world.setBlock(i + 7, j + 9, k + 12, Block.planks.blockID);
		world.setBlock(i + 7, j + 9, k + 13, Block.planks.blockID);
		world.setBlock(i + 7, j + 9, k + 14, Block.planks.blockID);
		world.setBlock(i + 7, j + 9, k + 15, Block.planks.blockID);
		world.setBlock(i + 7, j + 9, k + 16, Block.planks.blockID);
		world.setBlock(i + 7, j + 9, k + 17, Block.planks.blockID);
		world.setBlock(i + 7, j + 9, k + 18, Block.planks.blockID);
		world.setBlock(i + 7, j + 9, k + 19, Block.planks.blockID);
		world.setBlock(i + 7, j + 9, k + 20, Block.planks.blockID);
		world.setBlock(i + 7, j + 9, k + 21, Block.planks.blockID);
		world.setBlock(i + 7, j + 9, k + 22, Block.planks.blockID);
		world.setBlock(i + 7, j + 9, k + 23, Block.planks.blockID);
		world.setBlock(i + 7, j + 9, k + 24, Block.planks.blockID);
		world.setBlock(i + 7, j + 9, k + 25, Block.planks.blockID);
		world.setBlock(i + 7, j + 9, k + 26, Block.planks.blockID);
		world.setBlock(i + 7, j + 9, k + 27, Block.planks.blockID);
		world.setBlock(i + 7, j + 9, k + 28, Block.planks.blockID);
		world.setBlock(i + 7, j + 9, k + 29, Block.planks.blockID);
		world.setBlock(i + 7, j + 9, k + 30, Block.planks.blockID);
		world.setBlock(i + 7, j + 9, k + 31, Block.planks.blockID);
		world.setBlock(i + 7, j + 9, k + 32, Block.planks.blockID);
		world.setBlock(i + 7, j + 9, k + 33, Block.planks.blockID);
		world.setBlock(i + 7, j + 9, k + 34, Block.planks.blockID);
		world.setBlock(i + 7, j + 9, k + 35, Block.planks.blockID);
		world.setBlock(i + 7, j + 9, k + 36, Block.planks.blockID);
		world.setBlock(i + 7, j + 9, k + 37, Block.planks.blockID);
		world.setBlock(i + 7, j + 9, k + 38, Block.planks.blockID);
		world.setBlock(i + 7, j + 9, k + 39, Block.planks.blockID);
		world.setBlock(i + 7, j + 9, k + 40, Block.planks.blockID);
		world.setBlock(i + 7, j + 9, k + 41, Block.planks.blockID);
		world.setBlock(i + 7, j + 9, k + 42, Block.planks.blockID);
		world.setBlock(i + 7, j + 9, k + 43, Block.planks.blockID);
		world.setBlock(i + 7, j + 9, k + 44, Block.planks.blockID);
		world.setBlock(i + 7, j + 9, k + 45, Block.planks.blockID);
		world.setBlock(i + 7, j + 9, k + 46, Block.planks.blockID);
		world.setBlock(i + 7, j + 9, k + 47, Block.planks.blockID);
		world.setBlock(i + 7, j + 10, k + 2, Block.planks.blockID);
		world.setBlock(i + 7, j + 10, k + 10, Block.planks.blockID);
		world.setBlock(i + 7, j + 10, k + 11, Block.planks.blockID);
		world.setBlock(i + 7, j + 10, k + 12, Block.planks.blockID);
		world.setBlock(i + 7, j + 10, k + 13, Block.planks.blockID);
		world.setBlockAndMetadata(i + 7, j + 10, k + 14, Block.stairCompactPlanks.blockID, 3);
		world.setBlock(i + 7, j + 10, k + 47, Block.planks.blockID);
		world.setBlock(i + 7, j + 11, k + 2, Block.planks.blockID);
		world.setBlock(i + 7, j + 11, k + 10, Block.planks.blockID);
		world.setBlock(i + 7, j + 11, k + 11, Block.planks.blockID);
		world.setBlock(i + 7, j + 11, k + 12, Block.planks.blockID);
		world.setBlockAndMetadata(i + 7, j + 11, k + 13, Block.stairCompactPlanks.blockID, 3);
		world.setBlock(i + 7, j + 12, k + 2, Block.planks.blockID);
		world.setBlock(i + 7, j + 12, k + 10, Block.planks.blockID);
		world.setBlock(i + 7, j + 12, k + 11, Block.planks.blockID);
		world.setBlockAndMetadata(i + 7, j + 12, k + 12, Block.stairCompactPlanks.blockID, 3);
		world.setBlock(i + 7, j + 13, k + 2, Block.planks.blockID);
		world.setBlock(i + 7, j + 13, k + 3, Block.planks.blockID);
		world.setBlock(i + 7, j + 13, k + 4, Block.planks.blockID);
		world.setBlock(i + 7, j + 13, k + 5, Block.planks.blockID);
		world.setBlock(i + 7, j + 13, k + 6, Block.planks.blockID);
		world.setBlock(i + 7, j + 13, k + 7, Block.planks.blockID);
		world.setBlock(i + 7, j + 13, k + 8, Block.planks.blockID);
		world.setBlock(i + 7, j + 13, k + 9, Block.planks.blockID);
		world.setBlock(i + 7, j + 13, k + 10, Block.planks.blockID);
		world.setBlockAndMetadata(i + 7, j + 13, k + 11, Block.stairCompactPlanks.blockID, 3);
		world.setBlock(i + 7, j + 14, k + 2, Block.fence.blockID);
		world.setBlock(i + 7, j + 14, k + 3, Block.fence.blockID);
		world.setBlock(i + 7, j + 15, k + 22, Block.cloth.blockID);
		world.setBlock(i + 7, j + 15, k + 36, Block.cloth.blockID);
		world.setBlock(i + 7, j + 16, k + 22, Block.cloth.blockID);
		world.setBlock(i + 7, j + 16, k + 36, Block.cloth.blockID);
		world.setBlock(i + 7, j + 17, k + 22, Block.cloth.blockID);
		world.setBlock(i + 7, j + 17, k + 36, Block.cloth.blockID);
		world.setBlock(i + 7, j + 18, k + 22, Block.cloth.blockID);
		world.setBlock(i + 7, j + 18, k + 36, Block.cloth.blockID);
		world.setBlock(i + 7, j + 19, k + 22, Block.cloth.blockID);
		world.setBlock(i + 7, j + 19, k + 35, Block.cloth.blockID);
		world.setBlock(i + 7, j + 20, k + 21, Block.cloth.blockID);
		world.setBlock(i + 7, j + 20, k + 34, Block.planks.blockID);
		world.setBlock(i + 7, j + 21, k + 20, Block.planks.blockID);
		world.setBlock(i + 7, j + 21, k + 36, Block.cloth.blockID);
		world.setBlock(i + 7, j + 22, k + 36, Block.cloth.blockID);
		world.setBlock(i + 7, j + 23, k + 22, Block.cloth.blockID);
		world.setBlock(i + 7, j + 23, k + 36, Block.cloth.blockID);
		world.setBlock(i + 7, j + 24, k + 22, Block.cloth.blockID);
		world.setBlock(i + 7, j + 24, k + 36, Block.cloth.blockID);
		world.setBlock(i + 7, j + 25, k + 22, Block.cloth.blockID);
		world.setBlock(i + 7, j + 25, k + 35, Block.cloth.blockID);
		world.setBlock(i + 7, j + 26, k + 22, Block.cloth.blockID);
		world.setBlock(i + 7, j + 26, k + 34, Block.planks.blockID);
		world.setBlock(i + 7, j + 27, k + 21, Block.cloth.blockID);
		world.setBlock(i + 7, j + 28, k + 20, Block.planks.blockID);
		world.setBlock(i + 8, j + 2, k + 5, Block.planks.blockID);
		world.setBlock(i + 8, j + 2, k + 6, Block.planks.blockID);
		world.setBlock(i + 8, j + 2, k + 7, Block.planks.blockID);
		world.setBlock(i + 8, j + 2, k + 8, Block.planks.blockID);
		world.setBlock(i + 8, j + 2, k + 9, Block.planks.blockID);
		world.setBlock(i + 8, j + 2, k + 10, Block.planks.blockID);
		world.setBlock(i + 8, j + 2, k + 11, Block.planks.blockID);
		world.setBlock(i + 8, j + 2, k + 12, Block.planks.blockID);
		world.setBlock(i + 8, j + 2, k + 13, Block.planks.blockID);
		world.setBlock(i + 8, j + 2, k + 14, Block.planks.blockID);
		world.setBlock(i + 8, j + 2, k + 15, Block.planks.blockID);
		world.setBlock(i + 8, j + 2, k + 16, Block.planks.blockID);
		world.setBlock(i + 8, j + 2, k + 17, Block.planks.blockID);
		world.setBlock(i + 8, j + 2, k + 18, Block.planks.blockID);
		world.setBlock(i + 8, j + 2, k + 19, Block.planks.blockID);
		world.setBlock(i + 8, j + 2, k + 20, Block.planks.blockID);
		world.setBlock(i + 8, j + 2, k + 21, Block.planks.blockID);
		world.setBlock(i + 8, j + 2, k + 22, Block.planks.blockID);
		world.setBlock(i + 8, j + 2, k + 23, Block.planks.blockID);
		world.setBlock(i + 8, j + 2, k + 24, Block.planks.blockID);
		world.setBlock(i + 8, j + 2, k + 25, Block.planks.blockID);
		world.setBlock(i + 8, j + 2, k + 26, Block.planks.blockID);
		world.setBlock(i + 8, j + 2, k + 27, Block.planks.blockID);
		world.setBlock(i + 8, j + 2, k + 28, Block.planks.blockID);
		world.setBlock(i + 8, j + 2, k + 29, Block.planks.blockID);
		world.setBlock(i + 8, j + 2, k + 30, Block.planks.blockID);
		world.setBlock(i + 8, j + 2, k + 31, Block.planks.blockID);
		world.setBlock(i + 8, j + 2, k + 32, Block.planks.blockID);
		world.setBlock(i + 8, j + 2, k + 33, Block.planks.blockID);
		world.setBlock(i + 8, j + 2, k + 34, Block.planks.blockID);
		world.setBlock(i + 8, j + 2, k + 35, Block.planks.blockID);
		world.setBlock(i + 8, j + 2, k + 36, Block.planks.blockID);
		world.setBlock(i + 8, j + 2, k + 37, Block.planks.blockID);
		world.setBlock(i + 8, j + 2, k + 38, Block.planks.blockID);
		world.setBlock(i + 8, j + 2, k + 39, Block.planks.blockID);
		world.setBlock(i + 8, j + 3, k + 3, Block.planks.blockID);
		world.setBlock(i + 8, j + 3, k + 4, Block.planks.blockID);
		world.setBlock(i + 8, j + 3, k + 5, Block.planks.blockID);
		world.setBlock(i + 8, j + 3, k + 6, Block.planks.blockID);
		world.setBlock(i + 8, j + 3, k + 7, Block.planks.blockID);
		world.setBlock(i + 8, j + 3, k + 8, Block.planks.blockID);
		world.setBlock(i + 8, j + 3, k + 9, Block.planks.blockID);
		world.setBlock(i + 8, j + 3, k + 10, Block.planks.blockID);
		world.setBlock(i + 8, j + 3, k + 11, Block.planks.blockID);
		world.setBlock(i + 8, j + 3, k + 12, Block.planks.blockID);
		world.setBlock(i + 8, j + 3, k + 13, Block.planks.blockID);
		world.setBlock(i + 8, j + 3, k + 14, Block.planks.blockID);
		world.setBlock(i + 8, j + 3, k + 15, Block.planks.blockID);
		world.setBlock(i + 8, j + 3, k + 16, Block.planks.blockID);
		world.setBlock(i + 8, j + 3, k + 17, Block.planks.blockID);
		world.setBlock(i + 8, j + 3, k + 18, Block.planks.blockID);
		world.setBlock(i + 8, j + 3, k + 19, Block.planks.blockID);
		world.setBlock(i + 8, j + 3, k + 20, Block.planks.blockID);
		world.setBlock(i + 8, j + 3, k + 21, Block.planks.blockID);
		world.setBlock(i + 8, j + 3, k + 22, Block.planks.blockID);
		world.setBlock(i + 8, j + 3, k + 23, Block.planks.blockID);
		world.setBlock(i + 8, j + 3, k + 24, Block.planks.blockID);
		world.setBlock(i + 8, j + 3, k + 25, Block.planks.blockID);
		world.setBlock(i + 8, j + 3, k + 26, Block.planks.blockID);
		world.setBlock(i + 8, j + 3, k + 27, Block.planks.blockID);
		world.setBlock(i + 8, j + 3, k + 28, Block.planks.blockID);
		world.setBlock(i + 8, j + 3, k + 29, Block.planks.blockID);
		world.setBlock(i + 8, j + 3, k + 30, Block.planks.blockID);
		world.setBlock(i + 8, j + 3, k + 31, Block.planks.blockID);
		world.setBlock(i + 8, j + 3, k + 32, Block.planks.blockID);
		world.setBlock(i + 8, j + 3, k + 33, Block.planks.blockID);
		world.setBlock(i + 8, j + 3, k + 34, Block.planks.blockID);
		world.setBlock(i + 8, j + 3, k + 35, Block.planks.blockID);
		world.setBlock(i + 8, j + 3, k + 36, Block.planks.blockID);
		world.setBlock(i + 8, j + 3, k + 37, Block.planks.blockID);
		world.setBlock(i + 8, j + 3, k + 38, Block.planks.blockID);
		world.setBlock(i + 8, j + 3, k + 39, Block.planks.blockID);
		world.setBlock(i + 8, j + 3, k + 40, Block.planks.blockID);
		world.setBlock(i + 8, j + 3, k + 41, Block.planks.blockID);
		world.setBlock(i + 8, j + 3, k + 42, Block.planks.blockID);
		world.setBlock(i + 8, j + 3, k + 43, Block.planks.blockID);
		world.setBlock(i + 8, j + 4, k + 2, Block.planks.blockID);
		world.setBlock(i + 8, j + 4, k + 3, Block.planks.blockID);
		world.setBlock(i + 8, j + 4, k + 40, Block.planks.blockID);
		world.setBlock(i + 8, j + 4, k + 42, Block.planks.blockID);
		world.setBlock(i + 8, j + 4, k + 43, Block.planks.blockID);
		world.setBlock(i + 8, j + 4, k + 44, Block.planks.blockID);
		world.setBlock(i + 8, j + 5, k + 2, Block.planks.blockID);
		world.setBlock(i + 8, j + 5, k + 3, Block.planks.blockID);
		world.setBlock(i + 8, j + 5, k + 40, Block.planks.blockID);
		world.setBlock(i + 8, j + 5, k + 42, Block.planks.blockID);
		world.setBlock(i + 8, j + 5, k + 43, Block.planks.blockID);
		world.setBlock(i + 8, j + 5, k + 44, Block.planks.blockID);
		world.setBlock(i + 8, j + 6, k + 2, Block.planks.blockID);
		world.setBlock(i + 8, j + 6, k + 3, Block.planks.blockID);
		world.setBlock(i + 8, j + 6, k + 4, Block.planks.blockID);
		world.setBlock(i + 8, j + 6, k + 5, Block.planks.blockID);
		world.setBlock(i + 8, j + 6, k + 6, Block.planks.blockID);
		world.setBlock(i + 8, j + 6, k + 7, Block.planks.blockID);
		world.setBlock(i + 8, j + 6, k + 8, Block.planks.blockID);
		world.setBlock(i + 8, j + 6, k + 9, Block.planks.blockID);
		world.setBlock(i + 8, j + 6, k + 10, Block.planks.blockID);
		world.setBlock(i + 8, j + 6, k + 11, Block.planks.blockID);
		world.setBlock(i + 8, j + 6, k + 12, Block.planks.blockID);
		world.setBlock(i + 8, j + 6, k + 13, Block.planks.blockID);
		world.setBlock(i + 8, j + 6, k + 14, Block.planks.blockID);
		world.setBlock(i + 8, j + 6, k + 15, Block.planks.blockID);
		world.setBlock(i + 8, j + 6, k + 16, Block.planks.blockID);
		world.setBlock(i + 8, j + 6, k + 17, Block.planks.blockID);
		world.setBlock(i + 8, j + 6, k + 18, Block.planks.blockID);
		world.setBlock(i + 8, j + 6, k + 19, Block.planks.blockID);
		world.setBlock(i + 8, j + 6, k + 20, Block.planks.blockID);
		world.setBlock(i + 8, j + 6, k + 21, Block.planks.blockID);
		world.setBlock(i + 8, j + 6, k + 22, Block.planks.blockID);
		world.setBlock(i + 8, j + 6, k + 23, Block.planks.blockID);
		world.setBlock(i + 8, j + 6, k + 24, Block.planks.blockID);
		world.setBlock(i + 8, j + 6, k + 25, Block.planks.blockID);
		world.setBlock(i + 8, j + 6, k + 26, Block.planks.blockID);
		world.setBlock(i + 8, j + 6, k + 27, Block.planks.blockID);
		world.setBlock(i + 8, j + 6, k + 28, Block.planks.blockID);
		world.setBlock(i + 8, j + 6, k + 29, Block.planks.blockID);
		world.setBlock(i + 8, j + 6, k + 30, Block.planks.blockID);
		world.setBlock(i + 8, j + 6, k + 31, Block.planks.blockID);
		world.setBlock(i + 8, j + 6, k + 32, Block.planks.blockID);
		world.setBlock(i + 8, j + 6, k + 33, Block.planks.blockID);
		world.setBlock(i + 8, j + 6, k + 34, Block.planks.blockID);
		world.setBlock(i + 8, j + 6, k + 35, Block.planks.blockID);
		world.setBlock(i + 8, j + 6, k + 36, Block.planks.blockID);
		world.setBlock(i + 8, j + 6, k + 37, Block.planks.blockID);
		world.setBlock(i + 8, j + 6, k + 38, Block.planks.blockID);
		world.setBlock(i + 8, j + 6, k + 39, Block.planks.blockID);
		world.setBlock(i + 8, j + 6, k + 40, Block.planks.blockID);
		world.setBlock(i + 8, j + 6, k + 41, Block.planks.blockID);
		world.setBlock(i + 8, j + 6, k + 42, Block.planks.blockID);
		world.setBlock(i + 8, j + 6, k + 43, Block.planks.blockID);
		world.setBlock(i + 8, j + 6, k + 44, Block.planks.blockID);
		world.setBlock(i + 8, j + 7, k + 2, Block.planks.blockID);
		world.setBlock(i + 8, j + 7, k + 3, Block.planks.blockID);
		world.setBlock(i + 8, j + 7, k + 41, Block.planks.blockID);
		world.setBlock(i + 8, j + 7, k + 45, Block.planks.blockID);
		world.setBlock(i + 8, j + 7, k + 46, Block.planks.blockID);
		world.setBlock(i + 8, j + 7, k + 47, Block.planks.blockID);
		world.setBlock(i + 8, j + 8, k + 2, Block.planks.blockID);
		world.setBlock(i + 8, j + 8, k + 3, Block.planks.blockID);
		world.setBlock(i + 8, j + 8, k + 41, Block.planks.blockID);
		world.setBlockAndMetadata(i + 8, j + 8, k + 46, Block.thinGlass.blockID, 1);
		world.setBlock(i + 8, j + 8, k + 47, Block.planks.blockID);
		world.setBlockAndMetadata(i + 8, j + 9, k + 2, Block.cloth.blockID, 14);
		world.setBlockAndMetadata(i + 8, j + 9, k + 3, Block.cloth.blockID, 14);
		world.setBlockAndMetadata(i + 8, j + 9, k + 4, Block.cloth.blockID, 14);
		world.setBlockAndMetadata(i + 8, j + 9, k + 5, Block.cloth.blockID, 14);
		world.setBlockAndMetadata(i + 8, j + 9, k + 6, Block.cloth.blockID, 14);
		world.setBlockAndMetadata(i + 8, j + 9, k + 7, Block.cloth.blockID, 14);
		world.setBlockAndMetadata(i + 8, j + 9, k + 8, Block.cloth.blockID, 14);
		world.setBlockAndMetadata(i + 8, j + 9, k + 9, Block.cloth.blockID, 14);
		world.setBlock(i + 8, j + 9, k + 10, Block.planks.blockID);
		world.setBlock(i + 8, j + 9, k + 11, Block.planks.blockID);
		world.setBlock(i + 8, j + 9, k + 12, Block.planks.blockID);
		world.setBlock(i + 8, j + 9, k + 13, Block.planks.blockID);
		world.setBlock(i + 8, j + 9, k + 14, Block.planks.blockID);
		world.setBlock(i + 8, j + 9, k + 15, Block.planks.blockID);
		world.setBlock(i + 8, j + 9, k + 16, Block.planks.blockID);
		world.setBlock(i + 8, j + 9, k + 17, Block.planks.blockID);
		world.setBlock(i + 8, j + 9, k + 18, Block.planks.blockID);
		world.setBlock(i + 8, j + 9, k + 19, Block.planks.blockID);
		world.setBlock(i + 8, j + 9, k + 20, Block.planks.blockID);
		world.setBlock(i + 8, j + 9, k + 21, Block.planks.blockID);
		world.setBlock(i + 8, j + 9, k + 22, Block.planks.blockID);
		world.setBlock(i + 8, j + 9, k + 23, Block.planks.blockID);
		world.setBlock(i + 8, j + 9, k + 24, Block.planks.blockID);
		world.setBlock(i + 8, j + 9, k + 25, Block.planks.blockID);
		world.setBlock(i + 8, j + 9, k + 26, Block.planks.blockID);
		world.setBlock(i + 8, j + 9, k + 27, Block.planks.blockID);
		world.setBlock(i + 8, j + 9, k + 28, Block.planks.blockID);
		world.setBlock(i + 8, j + 9, k + 29, Block.planks.blockID);
		world.setBlock(i + 8, j + 9, k + 30, Block.planks.blockID);
		world.setBlock(i + 8, j + 9, k + 31, Block.planks.blockID);
		world.setBlock(i + 8, j + 9, k + 32, Block.planks.blockID);
		world.setBlock(i + 8, j + 9, k + 33, Block.planks.blockID);
		world.setBlock(i + 8, j + 9, k + 34, Block.planks.blockID);
		world.setBlock(i + 8, j + 9, k + 35, Block.planks.blockID);
		world.setBlock(i + 8, j + 9, k + 36, Block.planks.blockID);
		world.setBlock(i + 8, j + 9, k + 37, Block.planks.blockID);
		world.setBlock(i + 8, j + 9, k + 38, Block.planks.blockID);
		world.setBlock(i + 8, j + 9, k + 39, Block.planks.blockID);
		world.setBlock(i + 8, j + 9, k + 40, Block.planks.blockID);
		world.setBlock(i + 8, j + 9, k + 41, Block.planks.blockID);
		world.setBlock(i + 8, j + 9, k + 42, Block.planks.blockID);
		world.setBlock(i + 8, j + 9, k + 43, Block.planks.blockID);
		world.setBlock(i + 8, j + 9, k + 44, Block.planks.blockID);
		world.setBlock(i + 8, j + 9, k + 45, Block.planks.blockID);
		world.setBlock(i + 8, j + 9, k + 46, Block.planks.blockID);
		world.setBlock(i + 8, j + 9, k + 47, Block.planks.blockID);
		world.setBlock(i + 8, j + 10, k + 1, Block.planks.blockID);
		world.setBlock(i + 8, j + 10, k + 10, Block.planks.blockID);
		world.setBlock(i + 8, j + 10, k + 11, Block.planks.blockID);
		world.setBlock(i + 8, j + 10, k + 12, Block.planks.blockID);
		world.setBlock(i + 8, j + 10, k + 13, Block.planks.blockID);
		world.setBlockAndMetadata(i + 8, j + 10, k + 14, Block.stairCompactPlanks.blockID, 3);
		world.setBlock(i + 8, j + 10, k + 47, Block.planks.blockID);
		world.setBlock(i + 8, j + 11, k + 1, Block.planks.blockID);
		world.setBlock(i + 8, j + 11, k + 10, Block.planks.blockID);
		world.setBlock(i + 8, j + 11, k + 11, Block.planks.blockID);
		world.setBlock(i + 8, j + 11, k + 12, Block.planks.blockID);
		world.setBlockAndMetadata(i + 8, j + 11, k + 13, Block.stairCompactPlanks.blockID, 3);
		world.setBlock(i + 8, j + 11, k + 47, Block.planks.blockID);
		world.setBlock(i + 8, j + 11, k + 48, Block.planks.blockID);
		world.setBlock(i + 8, j + 12, k + 1, Block.planks.blockID);
		world.setBlock(i + 8, j + 12, k + 10, Block.planks.blockID);
		world.setBlock(i + 8, j + 12, k + 11, Block.planks.blockID);
		world.setBlockAndMetadata(i + 8, j + 12, k + 12, Block.stairCompactPlanks.blockID, 3);
		world.setBlock(i + 8, j + 12, k + 47, Block.planks.blockID);
		world.setBlock(i + 8, j + 12, k + 48, Block.planks.blockID);
		world.setBlock(i + 8, j + 13, k + 1, Block.planks.blockID);
		world.setBlock(i + 8, j + 13, k + 2, Block.planks.blockID);
		world.setBlock(i + 8, j + 13, k + 3, Block.planks.blockID);
		world.setBlock(i + 8, j + 13, k + 4, Block.planks.blockID);
		world.setBlock(i + 8, j + 13, k + 5, Block.planks.blockID);
		world.setBlock(i + 8, j + 13, k + 6, Block.planks.blockID);
		world.setBlock(i + 8, j + 13, k + 7, Block.planks.blockID);
		world.setBlock(i + 8, j + 13, k + 8, Block.planks.blockID);
		world.setBlock(i + 8, j + 13, k + 9, Block.planks.blockID);
		world.setBlock(i + 8, j + 13, k + 10, Block.planks.blockID);
		world.setBlockAndMetadata(i + 8, j + 13, k + 11, Block.stairCompactPlanks.blockID, 3);
		world.setBlock(i + 8, j + 13, k + 47, Block.fence.blockID);
		world.setBlock(i + 8, j + 13, k + 48, Block.fence.blockID);
		world.setBlock(i + 8, j + 14, k + 1, Block.fence.blockID);
		world.setBlock(i + 8, j + 14, k + 2, Block.fence.blockID);
		world.setBlock(i + 8, j + 15, k + 22, Block.cloth.blockID);
		world.setBlock(i + 8, j + 15, k + 36, Block.cloth.blockID);
		world.setBlock(i + 8, j + 16, k + 22, Block.cloth.blockID);
		world.setBlock(i + 8, j + 16, k + 36, Block.cloth.blockID);
		world.setBlock(i + 8, j + 17, k + 22, Block.cloth.blockID);
		world.setBlock(i + 8, j + 17, k + 36, Block.cloth.blockID);
		world.setBlock(i + 8, j + 18, k + 22, Block.cloth.blockID);
		world.setBlock(i + 8, j + 18, k + 36, Block.cloth.blockID);
		world.setBlock(i + 8, j + 19, k + 22, Block.cloth.blockID);
		world.setBlock(i + 8, j + 19, k + 35, Block.cloth.blockID);
		world.setBlock(i + 8, j + 20, k + 21, Block.cloth.blockID);
		world.setBlock(i + 8, j + 20, k + 34, Block.planks.blockID);
		world.setBlock(i + 8, j + 21, k + 20, Block.planks.blockID);
		world.setBlock(i + 8, j + 21, k + 36, Block.cloth.blockID);
		world.setBlock(i + 8, j + 22, k + 36, Block.cloth.blockID);
		world.setBlock(i + 8, j + 23, k + 22, Block.cloth.blockID);
		world.setBlock(i + 8, j + 23, k + 36, Block.cloth.blockID);
		world.setBlock(i + 8, j + 24, k + 22, Block.cloth.blockID);
		world.setBlock(i + 8, j + 24, k + 36, Block.cloth.blockID);
		world.setBlock(i + 8, j + 25, k + 22, Block.cloth.blockID);
		world.setBlock(i + 8, j + 25, k + 35, Block.cloth.blockID);
		world.setBlock(i + 8, j + 26, k + 22, Block.cloth.blockID);
		world.setBlock(i + 8, j + 26, k + 34, Block.planks.blockID);
		world.setBlock(i + 8, j + 27, k + 21, Block.cloth.blockID);
		world.setBlock(i + 8, j + 28, k + 20, Block.planks.blockID);
		world.setBlock(i + 8, j + 31, k + 16, Block.planks.blockID);
		world.setBlock(i + 8, j + 31, k + 17, Block.planks.blockID);
		world.setBlock(i + 8, j + 31, k + 18, Block.planks.blockID);
		world.setBlock(i + 8, j + 31, k + 19, Block.planks.blockID);
		world.setBlock(i + 8, j + 31, k + 20, Block.planks.blockID);
		world.setBlock(i + 8, j + 31, k + 21, Block.planks.blockID);
		world.setBlock(i + 8, j + 32, k + 16, Block.fence.blockID);
		world.setBlock(i + 8, j + 32, k + 17, Block.fence.blockID);
		world.setBlock(i + 8, j + 32, k + 18, Block.fence.blockID);
		world.setBlock(i + 8, j + 32, k + 19, Block.fence.blockID);
		world.setBlock(i + 8, j + 32, k + 20, Block.fence.blockID);
		world.setBlock(i + 8, j + 32, k + 21, Block.fence.blockID);
		world.setBlock(i + 9, j + 1, k + 6, Block.planks.blockID);
		world.setBlock(i + 9, j + 1, k + 7, Block.planks.blockID);
		world.setBlock(i + 9, j + 1, k + 8, Block.planks.blockID);
		world.setBlock(i + 9, j + 1, k + 9, Block.planks.blockID);
		world.setBlock(i + 9, j + 1, k + 10, Block.planks.blockID);
		world.setBlock(i + 9, j + 1, k + 11, Block.planks.blockID);
		world.setBlock(i + 9, j + 1, k + 12, Block.planks.blockID);
		world.setBlock(i + 9, j + 1, k + 13, Block.planks.blockID);
		world.setBlock(i + 9, j + 1, k + 14, Block.planks.blockID);
		world.setBlock(i + 9, j + 1, k + 15, Block.planks.blockID);
		world.setBlock(i + 9, j + 1, k + 16, Block.planks.blockID);
		world.setBlock(i + 9, j + 1, k + 17, Block.planks.blockID);
		world.setBlock(i + 9, j + 1, k + 18, Block.planks.blockID);
		world.setBlock(i + 9, j + 1, k + 19, Block.planks.blockID);
		world.setBlock(i + 9, j + 1, k + 20, Block.planks.blockID);
		world.setBlock(i + 9, j + 1, k + 21, Block.planks.blockID);
		world.setBlock(i + 9, j + 1, k + 22, Block.planks.blockID);
		world.setBlock(i + 9, j + 1, k + 23, Block.planks.blockID);
		world.setBlock(i + 9, j + 1, k + 24, Block.planks.blockID);
		world.setBlock(i + 9, j + 1, k + 25, Block.planks.blockID);
		world.setBlock(i + 9, j + 1, k + 26, Block.planks.blockID);
		world.setBlock(i + 9, j + 1, k + 27, Block.planks.blockID);
		world.setBlock(i + 9, j + 1, k + 28, Block.planks.blockID);
		world.setBlock(i + 9, j + 1, k + 29, Block.planks.blockID);
		world.setBlock(i + 9, j + 1, k + 30, Block.planks.blockID);
		world.setBlock(i + 9, j + 1, k + 31, Block.planks.blockID);
		world.setBlock(i + 9, j + 1, k + 32, Block.planks.blockID);
		world.setBlock(i + 9, j + 1, k + 33, Block.planks.blockID);
		world.setBlock(i + 9, j + 1, k + 34, Block.planks.blockID);
		world.setBlock(i + 9, j + 1, k + 35, Block.planks.blockID);
		world.setBlock(i + 9, j + 1, k + 36, Block.planks.blockID);
		world.setBlock(i + 9, j + 1, k + 37, Block.planks.blockID);
		world.setBlock(i + 9, j + 1, k + 38, Block.planks.blockID);
		world.setBlock(i + 9, j + 1, k + 39, Block.planks.blockID);
		world.setBlock(i + 9, j + 2, k + 4, Block.planks.blockID);
		world.setBlock(i + 9, j + 2, k + 5, Block.planks.blockID);
		world.setBlock(i + 9, j + 2, k + 6, Block.planks.blockID);
		world.setBlock(i + 9, j + 2, k + 27, Block.planks.blockID);
		world.setBlock(i + 9, j + 2, k + 39, Block.planks.blockID);
		world.setBlock(i + 9, j + 2, k + 40, Block.planks.blockID);
		world.setBlock(i + 9, j + 2, k + 41, Block.planks.blockID);
		world.setBlock(i + 9, j + 3, k + 3, Block.planks.blockID);
		world.setBlock(i + 9, j + 3, k + 4, Block.planks.blockID);
		world.setBlock(i + 9, j + 3, k + 5, Block.planks.blockID);
		world.setBlock(i + 9, j + 3, k + 6, Block.planks.blockID);
		world.setBlock(i + 9, j + 3, k + 7, Block.planks.blockID);
		world.setBlock(i + 9, j + 3, k + 8, Block.planks.blockID);
		world.setBlock(i + 9, j + 3, k + 9, Block.planks.blockID);
		world.setBlock(i + 9, j + 3, k + 10, Block.planks.blockID);
		world.setBlock(i + 9, j + 3, k + 11, Block.planks.blockID);
		world.setBlock(i + 9, j + 3, k + 12, Block.planks.blockID);
		world.setBlock(i + 9, j + 3, k + 13, Block.planks.blockID);
		world.setBlock(i + 9, j + 3, k + 14, Block.planks.blockID);
		world.setBlock(i + 9, j + 3, k + 15, Block.planks.blockID);
		world.setBlock(i + 9, j + 3, k + 16, Block.planks.blockID);
		world.setBlock(i + 9, j + 3, k + 17, Block.planks.blockID);
		world.setBlock(i + 9, j + 3, k + 18, Block.planks.blockID);
		world.setBlock(i + 9, j + 3, k + 19, Block.planks.blockID);
		world.setBlock(i + 9, j + 3, k + 20, Block.planks.blockID);
		world.setBlock(i + 9, j + 3, k + 21, Block.planks.blockID);
		world.setBlock(i + 9, j + 3, k + 22, Block.planks.blockID);
		world.setBlock(i + 9, j + 3, k + 23, Block.planks.blockID);
		world.setBlock(i + 9, j + 3, k + 24, Block.planks.blockID);
		world.setBlock(i + 9, j + 3, k + 25, Block.planks.blockID);
		world.setBlock(i + 9, j + 3, k + 26, Block.planks.blockID);
		world.setBlock(i + 9, j + 3, k + 27, Block.planks.blockID);
		world.setBlock(i + 9, j + 3, k + 28, Block.planks.blockID);
		world.setBlock(i + 9, j + 3, k + 29, Block.planks.blockID);
		world.setBlock(i + 9, j + 3, k + 30, Block.planks.blockID);
		world.setBlock(i + 9, j + 3, k + 31, Block.planks.blockID);
		world.setBlock(i + 9, j + 3, k + 32, Block.planks.blockID);
		world.setBlock(i + 9, j + 3, k + 33, Block.planks.blockID);
		world.setBlock(i + 9, j + 3, k + 34, Block.planks.blockID);
		world.setBlock(i + 9, j + 3, k + 35, Block.planks.blockID);
		world.setBlock(i + 9, j + 3, k + 36, Block.planks.blockID);
		world.setBlock(i + 9, j + 3, k + 37, Block.planks.blockID);
		world.setBlock(i + 9, j + 3, k + 38, Block.planks.blockID);
		world.setBlock(i + 9, j + 3, k + 39, Block.planks.blockID);
		world.setBlock(i + 9, j + 3, k + 40, Block.planks.blockID);
		world.setBlock(i + 9, j + 3, k + 41, Block.planks.blockID);
		world.setBlock(i + 9, j + 3, k + 42, Block.planks.blockID);
		world.setBlock(i + 9, j + 3, k + 43, Block.planks.blockID);
		world.setBlock(i + 9, j + 4, k + 2, Block.planks.blockID);
		world.setBlockAndMetadata(i + 9, j + 4, k + 42, Block.thinGlass.blockID, 3);
		world.setBlockAndMetadata(i + 9, j + 4, k + 43, Block.thinGlass.blockID, 3);
		world.setBlock(i + 9, j + 4, k + 44, Block.planks.blockID);
		world.setBlock(i + 9, j + 4, k + 45, Block.planks.blockID);
		world.setBlock(i + 9, j + 5, k + 2, Block.planks.blockID);
		world.setBlock(i + 9, j + 5, k + 44, Block.planks.blockID);
		world.setBlock(i + 9, j + 5, k + 45, Block.planks.blockID);
		world.setBlock(i + 9, j + 5, k + 46, Block.planks.blockID);
		world.setBlock(i + 9, j + 6, k + 2, Block.planks.blockID);
		world.setBlock(i + 9, j + 6, k + 3, Block.planks.blockID);
		world.setBlock(i + 9, j + 6, k + 4, Block.planks.blockID);
		world.setBlock(i + 9, j + 6, k + 5, Block.planks.blockID);
		world.setBlock(i + 9, j + 6, k + 6, Block.planks.blockID);
		world.setBlock(i + 9, j + 6, k + 7, Block.planks.blockID);
		world.setBlock(i + 9, j + 6, k + 8, Block.planks.blockID);
		world.setBlock(i + 9, j + 6, k + 9, Block.planks.blockID);
		world.setBlock(i + 9, j + 6, k + 10, Block.planks.blockID);
		world.setBlock(i + 9, j + 6, k + 11, Block.planks.blockID);
		world.setBlock(i + 9, j + 6, k + 12, Block.planks.blockID);
		world.setBlock(i + 9, j + 6, k + 13, Block.planks.blockID);
		world.setBlock(i + 9, j + 6, k + 14, Block.planks.blockID);
		world.setBlock(i + 9, j + 6, k + 15, Block.planks.blockID);
		world.setBlock(i + 9, j + 6, k + 16, Block.planks.blockID);
		world.setBlock(i + 9, j + 6, k + 17, Block.planks.blockID);
		world.setBlock(i + 9, j + 6, k + 18, Block.planks.blockID);
		world.setBlock(i + 9, j + 6, k + 19, Block.planks.blockID);
		world.setBlock(i + 9, j + 6, k + 20, Block.planks.blockID);
		world.setBlock(i + 9, j + 6, k + 21, Block.planks.blockID);
		world.setBlock(i + 9, j + 6, k + 22, Block.planks.blockID);
		world.setBlock(i + 9, j + 6, k + 23, Block.planks.blockID);
		world.setBlock(i + 9, j + 6, k + 24, Block.planks.blockID);
		world.setBlock(i + 9, j + 6, k + 25, Block.planks.blockID);
		world.setBlock(i + 9, j + 6, k + 26, Block.planks.blockID);
		world.setBlock(i + 9, j + 6, k + 27, Block.planks.blockID);
		world.setBlock(i + 9, j + 6, k + 28, Block.planks.blockID);
		world.setBlock(i + 9, j + 6, k + 29, Block.planks.blockID);
		world.setBlock(i + 9, j + 6, k + 30, Block.planks.blockID);
		world.setBlock(i + 9, j + 6, k + 31, Block.planks.blockID);
		world.setBlock(i + 9, j + 6, k + 32, Block.planks.blockID);
		world.setBlock(i + 9, j + 6, k + 33, Block.planks.blockID);
		world.setBlock(i + 9, j + 6, k + 34, Block.planks.blockID);
		world.setBlock(i + 9, j + 6, k + 35, Block.planks.blockID);
		world.setBlock(i + 9, j + 6, k + 36, Block.planks.blockID);
		world.setBlock(i + 9, j + 6, k + 37, Block.planks.blockID);
		world.setBlock(i + 9, j + 6, k + 38, Block.planks.blockID);
		world.setBlock(i + 9, j + 6, k + 39, Block.planks.blockID);
		world.setBlock(i + 9, j + 6, k + 40, Block.planks.blockID);
		world.setBlock(i + 9, j + 6, k + 41, Block.planks.blockID);
		world.setBlock(i + 9, j + 6, k + 42, Block.planks.blockID);
		world.setBlock(i + 9, j + 6, k + 43, Block.planks.blockID);
		world.setBlock(i + 9, j + 6, k + 44, Block.planks.blockID);
		world.setBlock(i + 9, j + 6, k + 45, Block.planks.blockID);
		world.setBlock(i + 9, j + 6, k + 46, Block.planks.blockID);
		world.setBlock(i + 9, j + 7, k + 2, Block.planks.blockID);
		world.setBlock(i + 9, j + 7, k + 5, Block.fence.blockID);
		world.setBlock(i + 9, j + 7, k + 6, Block.fence.blockID);
		world.setBlock(i + 9, j + 7, k + 7, Block.fence.blockID);
		world.setBlock(i + 9, j + 7, k + 8, Block.fence.blockID);
		world.setBlock(i + 9, j + 7, k + 9, Block.fence.blockID);
		world.setBlock(i + 9, j + 7, k + 41, Block.planks.blockID);
		world.setBlock(i + 9, j + 7, k + 46, Block.workbench.blockID);
		world.setBlock(i + 9, j + 7, k + 47, Block.planks.blockID);
		world.setBlock(i + 9, j + 8, k + 2, Block.planks.blockID);
		world.setBlock(i + 9, j + 8, k + 41, Block.planks.blockID);
		world.setBlock(i + 9, j + 8, k + 47, Block.planks.blockID);
		world.setBlock(i + 9, j + 8, k + 48, Block.planks.blockID);
		world.setBlockAndMetadata(i + 9, j + 9, k + 2, Block.cloth.blockID, 14);
		world.setBlockAndMetadata(i + 9, j + 9, k + 3, Block.cloth.blockID, 14);
		world.setBlockAndMetadata(i + 9, j + 9, k + 4, Block.cloth.blockID, 14);
		world.setBlockAndMetadata(i + 9, j + 9, k + 5, Block.cloth.blockID, 14);
		world.setBlockAndMetadata(i + 9, j + 9, k + 6, Block.cloth.blockID, 14);
		world.setBlockAndMetadata(i + 9, j + 9, k + 7, Block.cloth.blockID, 14);
		world.setBlockAndMetadata(i + 9, j + 9, k + 8, Block.cloth.blockID, 14);
		world.setBlockAndMetadata(i + 9, j + 9, k + 9, Block.cloth.blockID, 14);
		world.setBlock(i + 9, j + 9, k + 10, Block.planks.blockID);
		world.setBlock(i + 9, j + 9, k + 11, Block.planks.blockID);
		world.setBlock(i + 9, j + 9, k + 12, Block.planks.blockID);
		world.setBlock(i + 9, j + 9, k + 13, Block.planks.blockID);
		world.setBlock(i + 9, j + 9, k + 14, Block.planks.blockID);
		world.setBlock(i + 9, j + 9, k + 15, Block.planks.blockID);
		world.setBlock(i + 9, j + 9, k + 16, Block.planks.blockID);
		world.setBlock(i + 9, j + 9, k + 17, Block.planks.blockID);
		world.setBlock(i + 9, j + 9, k + 18, Block.planks.blockID);
		world.setBlock(i + 9, j + 9, k + 19, Block.planks.blockID);
		world.setBlock(i + 9, j + 9, k + 20, Block.planks.blockID);
		world.setBlock(i + 9, j + 9, k + 21, Block.planks.blockID);
		world.setBlock(i + 9, j + 9, k + 22, Block.planks.blockID);
		world.setBlock(i + 9, j + 9, k + 23, Block.planks.blockID);
		world.setBlock(i + 9, j + 9, k + 24, Block.planks.blockID);
		world.setBlock(i + 9, j + 9, k + 25, Block.planks.blockID);
		world.setBlock(i + 9, j + 9, k + 26, Block.planks.blockID);
		world.setBlock(i + 9, j + 9, k + 27, Block.planks.blockID);
		world.setBlock(i + 9, j + 9, k + 28, Block.planks.blockID);
		world.setBlock(i + 9, j + 9, k + 29, Block.planks.blockID);
		world.setBlock(i + 9, j + 9, k + 30, Block.planks.blockID);
		world.setBlock(i + 9, j + 9, k + 31, Block.planks.blockID);
		world.setBlock(i + 9, j + 9, k + 32, Block.planks.blockID);
		world.setBlock(i + 9, j + 9, k + 33, Block.planks.blockID);
		world.setBlock(i + 9, j + 9, k + 34, Block.planks.blockID);
		world.setBlock(i + 9, j + 9, k + 35, Block.planks.blockID);
		world.setBlock(i + 9, j + 9, k + 36, Block.planks.blockID);
		world.setBlock(i + 9, j + 9, k + 37, Block.planks.blockID);
		world.setBlock(i + 9, j + 9, k + 38, Block.planks.blockID);
		world.setBlock(i + 9, j + 9, k + 39, Block.planks.blockID);
		world.setBlock(i + 9, j + 9, k + 40, Block.planks.blockID);
		world.setBlock(i + 9, j + 9, k + 41, Block.planks.blockID);
		world.setBlock(i + 9, j + 9, k + 42, Block.planks.blockID);
		world.setBlock(i + 9, j + 9, k + 43, Block.planks.blockID);
		world.setBlock(i + 9, j + 9, k + 44, Block.planks.blockID);
		world.setBlock(i + 9, j + 9, k + 45, Block.planks.blockID);
		world.setBlock(i + 9, j + 9, k + 46, Block.planks.blockID);
		world.setBlock(i + 9, j + 9, k + 47, Block.planks.blockID);
		world.setBlock(i + 9, j + 9, k + 48, Block.planks.blockID);
		world.setBlock(i + 9, j + 10, k + 1, Block.planks.blockID);
		world.setBlock(i + 9, j + 10, k + 10, Block.planks.blockID);
		world.setBlock(i + 9, j + 10, k + 24, Block.fence.blockID);
		world.setBlock(i + 9, j + 10, k + 25, Block.fence.blockID);
		world.setBlock(i + 9, j + 10, k + 26, Block.fence.blockID);
		world.setBlock(i + 9, j + 10, k + 27, Block.fence.blockID);
		world.setBlock(i + 9, j + 10, k + 28, Block.fence.blockID);
		world.setBlock(i + 9, j + 10, k + 47, Block.planks.blockID);
		world.setBlock(i + 9, j + 10, k + 48, Block.planks.blockID);
		world.setBlock(i + 9, j + 11, k + 1, Block.glass.blockID);
		world.setBlock(i + 9, j + 11, k + 10, Block.planks.blockID);
		world.setBlock(i + 9, j + 11, k + 47, Block.planks.blockID);
		world.setBlock(i + 9, j + 11, k + 48, Block.planks.blockID);
		world.setBlock(i + 9, j + 11, k + 49, Block.planks.blockID);
		world.setBlock(i + 9, j + 12, k + 1, Block.planks.blockID);
		world.setBlock(i + 9, j + 12, k + 10, Block.planks.blockID);
		world.setBlock(i + 9, j + 12, k + 47, Block.planks.blockID);
		world.setBlock(i + 9, j + 12, k + 48, Block.planks.blockID);
		world.setBlock(i + 9, j + 12, k + 49, Block.planks.blockID);
		world.setBlock(i + 9, j + 13, k + 1, Block.planks.blockID);
		world.setBlock(i + 9, j + 13, k + 2, Block.planks.blockID);
		world.setBlock(i + 9, j + 13, k + 3, Block.planks.blockID);
		world.setBlock(i + 9, j + 13, k + 4, Block.planks.blockID);
		world.setBlock(i + 9, j + 13, k + 5, Block.planks.blockID);
		world.setBlock(i + 9, j + 13, k + 6, Block.planks.blockID);
		world.setBlock(i + 9, j + 13, k + 7, Block.planks.blockID);
		world.setBlock(i + 9, j + 13, k + 8, Block.planks.blockID);
		world.setBlock(i + 9, j + 13, k + 9, Block.planks.blockID);
		world.setBlock(i + 9, j + 13, k + 10, Block.planks.blockID);
		world.setBlock(i + 9, j + 13, k + 48, Block.fence.blockID);
		world.setBlock(i + 9, j + 13, k + 49, Block.fence.blockID);
		world.setBlock(i + 9, j + 14, k + 1, Block.fence.blockID);
		world.setBlock(i + 9, j + 15, k + 22, Block.cloth.blockID);
		world.setBlock(i + 9, j + 15, k + 36, Block.cloth.blockID);
		world.setBlock(i + 9, j + 16, k + 22, Block.cloth.blockID);
		world.setBlock(i + 9, j + 16, k + 36, Block.cloth.blockID);
		world.setBlock(i + 9, j + 17, k + 22, Block.cloth.blockID);
		world.setBlock(i + 9, j + 17, k + 36, Block.cloth.blockID);
		world.setBlock(i + 9, j + 18, k + 22, Block.cloth.blockID);
		world.setBlock(i + 9, j + 18, k + 36, Block.cloth.blockID);
		world.setBlock(i + 9, j + 19, k + 22, Block.cloth.blockID);
		world.setBlock(i + 9, j + 19, k + 35, Block.cloth.blockID);
		world.setBlock(i + 9, j + 20, k + 21, Block.cloth.blockID);
		world.setBlock(i + 9, j + 20, k + 34, Block.planks.blockID);
		world.setBlock(i + 9, j + 21, k + 20, Block.planks.blockID);
		world.setBlock(i + 9, j + 21, k + 36, Block.cloth.blockID);
		world.setBlock(i + 9, j + 22, k + 36, Block.cloth.blockID);
		world.setBlock(i + 9, j + 23, k + 22, Block.cloth.blockID);
		world.setBlock(i + 9, j + 23, k + 36, Block.cloth.blockID);
		world.setBlock(i + 9, j + 24, k + 22, Block.cloth.blockID);
		world.setBlock(i + 9, j + 24, k + 36, Block.cloth.blockID);
		world.setBlock(i + 9, j + 25, k + 22, Block.cloth.blockID);
		world.setBlock(i + 9, j + 25, k + 35, Block.cloth.blockID);
		world.setBlock(i + 9, j + 26, k + 22, Block.cloth.blockID);
		world.setBlock(i + 9, j + 26, k + 34, Block.planks.blockID);
		world.setBlock(i + 9, j + 27, k + 21, Block.cloth.blockID);
		world.setBlock(i + 9, j + 28, k + 20, Block.planks.blockID);
		world.setBlock(i + 9, j + 31, k + 16, Block.planks.blockID);
		world.setBlock(i + 9, j + 31, k + 17, Block.planks.blockID);
		world.setBlock(i + 9, j + 31, k + 18, Block.planks.blockID);
		world.setBlock(i + 9, j + 31, k + 19, Block.planks.blockID);
		world.setBlock(i + 9, j + 31, k + 20, Block.planks.blockID);
		world.setBlock(i + 9, j + 31, k + 21, Block.planks.blockID);
		world.setBlock(i + 9, j + 32, k + 16, Block.fence.blockID);
		world.setBlock(i + 9, j + 32, k + 21, Block.fence.blockID);
		world.setBlock(i + 10, j + 1, k + 5, Block.planks.blockID);
		world.setBlock(i + 10, j + 1, k + 6, Block.planks.blockID);
		world.setBlock(i + 10, j + 1, k + 7, Block.planks.blockID);
		world.setBlock(i + 10, j + 1, k + 8, Block.planks.blockID);
		world.setBlock(i + 10, j + 1, k + 9, Block.planks.blockID);
		world.setBlock(i + 10, j + 1, k + 10, Block.planks.blockID);
		world.setBlock(i + 10, j + 1, k + 11, Block.planks.blockID);
		world.setBlock(i + 10, j + 1, k + 12, Block.planks.blockID);
		world.setBlock(i + 10, j + 1, k + 13, Block.planks.blockID);
		world.setBlock(i + 10, j + 1, k + 14, Block.planks.blockID);
		world.setBlock(i + 10, j + 1, k + 15, Block.planks.blockID);
		world.setBlock(i + 10, j + 1, k + 16, Block.planks.blockID);
		world.setBlock(i + 10, j + 1, k + 17, Block.planks.blockID);
		world.setBlock(i + 10, j + 1, k + 18, Block.planks.blockID);
		world.setBlock(i + 10, j + 1, k + 19, Block.planks.blockID);
		world.setBlock(i + 10, j + 1, k + 20, Block.planks.blockID);
		world.setBlock(i + 10, j + 1, k + 21, Block.planks.blockID);
		world.setBlock(i + 10, j + 1, k + 22, Block.planks.blockID);
		world.setBlock(i + 10, j + 1, k + 23, Block.planks.blockID);
		world.setBlock(i + 10, j + 1, k + 24, Block.planks.blockID);
		world.setBlock(i + 10, j + 1, k + 25, Block.planks.blockID);
		world.setBlock(i + 10, j + 1, k + 26, Block.planks.blockID);
		world.setBlock(i + 10, j + 1, k + 27, Block.planks.blockID);
		world.setBlock(i + 10, j + 1, k + 28, Block.planks.blockID);
		world.setBlock(i + 10, j + 1, k + 29, Block.planks.blockID);
		world.setBlock(i + 10, j + 1, k + 30, Block.planks.blockID);
		world.setBlock(i + 10, j + 1, k + 31, Block.planks.blockID);
		world.setBlock(i + 10, j + 1, k + 32, Block.planks.blockID);
		world.setBlock(i + 10, j + 1, k + 33, Block.planks.blockID);
		world.setBlock(i + 10, j + 1, k + 34, Block.planks.blockID);
		world.setBlock(i + 10, j + 1, k + 35, Block.planks.blockID);
		world.setBlock(i + 10, j + 1, k + 36, Block.planks.blockID);
		world.setBlock(i + 10, j + 1, k + 37, Block.planks.blockID);
		world.setBlock(i + 10, j + 1, k + 38, Block.planks.blockID);
		world.setBlock(i + 10, j + 1, k + 39, Block.planks.blockID);
		world.setBlock(i + 10, j + 1, k + 40, Block.planks.blockID);
		world.setBlock(i + 10, j + 1, k + 41, Block.planks.blockID);
		world.setBlock(i + 10, j + 1, k + 42, Block.planks.blockID);
		world.setBlock(i + 10, j + 2, k + 4, Block.planks.blockID);
		world.setBlock(i + 10, j + 2, k + 5, Block.planks.blockID);
		world.setBlock(i + 10, j + 2, k + 42, Block.planks.blockID);
		world.setBlock(i + 10, j + 2, k + 43, Block.planks.blockID);
		world.setBlock(i + 10, j + 3, k + 3, Block.planks.blockID);
		world.setBlock(i + 10, j + 3, k + 4, Block.planks.blockID);
		world.setBlock(i + 10, j + 3, k + 5, Block.planks.blockID);
		world.setBlock(i + 10, j + 3, k + 6, Block.planks.blockID);
		world.setBlock(i + 10, j + 3, k + 8, Block.planks.blockID);
		world.setBlock(i + 10, j + 3, k + 9, Block.planks.blockID);
		world.setBlock(i + 10, j + 3, k + 10, Block.planks.blockID);
		world.setBlock(i + 10, j + 3, k + 11, Block.planks.blockID);
		world.setBlock(i + 10, j + 3, k + 12, Block.planks.blockID);
		world.setBlock(i + 10, j + 3, k + 13, Block.planks.blockID);
		world.setBlock(i + 10, j + 3, k + 14, Block.planks.blockID);
		world.setBlock(i + 10, j + 3, k + 15, Block.planks.blockID);
		world.setBlock(i + 10, j + 3, k + 16, Block.planks.blockID);
		world.setBlock(i + 10, j + 3, k + 17, Block.planks.blockID);
		world.setBlock(i + 10, j + 3, k + 18, Block.planks.blockID);
		world.setBlock(i + 10, j + 3, k + 19, Block.planks.blockID);
		world.setBlock(i + 10, j + 3, k + 20, Block.planks.blockID);
		world.setBlock(i + 10, j + 3, k + 21, Block.planks.blockID);
		world.setBlock(i + 10, j + 3, k + 22, Block.planks.blockID);
		world.setBlock(i + 10, j + 3, k + 23, Block.planks.blockID);
		world.setBlock(i + 10, j + 3, k + 24, Block.planks.blockID);
		world.setBlock(i + 10, j + 3, k + 25, Block.planks.blockID);
		world.setBlock(i + 10, j + 3, k + 26, Block.planks.blockID);
		world.setBlock(i + 10, j + 3, k + 27, Block.planks.blockID);
		world.setBlock(i + 10, j + 3, k + 28, Block.planks.blockID);
		world.setBlock(i + 10, j + 3, k + 29, Block.planks.blockID);
		world.setBlock(i + 10, j + 3, k + 30, Block.planks.blockID);
		world.setBlock(i + 10, j + 3, k + 31, Block.planks.blockID);
		world.setBlock(i + 10, j + 3, k + 32, Block.planks.blockID);
		world.setBlock(i + 10, j + 3, k + 33, Block.planks.blockID);
		world.setBlock(i + 10, j + 3, k + 34, Block.planks.blockID);
		world.setBlock(i + 10, j + 3, k + 35, Block.planks.blockID);
		world.setBlock(i + 10, j + 3, k + 36, Block.planks.blockID);
		world.setBlock(i + 10, j + 3, k + 37, Block.planks.blockID);
		world.setBlock(i + 10, j + 3, k + 38, Block.planks.blockID);
		world.setBlock(i + 10, j + 3, k + 39, Block.planks.blockID);
		world.setBlock(i + 10, j + 3, k + 40, Block.planks.blockID);
		world.setBlock(i + 10, j + 3, k + 41, Block.planks.blockID);
		world.setBlock(i + 10, j + 3, k + 42, Block.planks.blockID);
		world.setBlock(i + 10, j + 3, k + 43, Block.planks.blockID);
		world.setBlock(i + 10, j + 3, k + 44, Block.planks.blockID);
		world.setBlock(i + 10, j + 4, k + 2, Block.planks.blockID);
		world.setBlockAndMetadata(i + 10, j + 4, k + 7, Block.stairCompactPlanks.blockID, 3);
		world.setBlock(i + 10, j + 4, k + 10, Block.planks.blockID);
		world.setBlock(i + 10, j + 4, k + 11, Block.planks.blockID);
		world.setBlock(i + 10, j + 4, k + 13, Block.planks.blockID);
		world.setBlock(i + 10, j + 4, k + 14, Block.planks.blockID);
		world.setBlock(i + 10, j + 4, k + 15, Block.planks.blockID);
		world.setBlock(i + 10, j + 4, k + 16, Block.planks.blockID);
		world.setBlock(i + 10, j + 4, k + 17, Block.planks.blockID);
		world.setBlock(i + 10, j + 4, k + 19, Block.planks.blockID);
		world.setBlock(i + 10, j + 4, k + 20, Block.planks.blockID);
		world.setBlock(i + 10, j + 4, k + 21, Block.planks.blockID);
		world.setBlock(i + 10, j + 4, k + 22, Block.planks.blockID);
		world.setBlock(i + 10, j + 4, k + 23, Block.planks.blockID);
		world.setBlock(i + 10, j + 4, k + 25, Block.planks.blockID);
		world.setBlock(i + 10, j + 4, k + 26, Block.planks.blockID);
		world.setBlock(i + 10, j + 4, k + 27, Block.planks.blockID);
		world.setBlock(i + 10, j + 4, k + 28, Block.planks.blockID);
		world.setBlock(i + 10, j + 4, k + 29, Block.planks.blockID);
		world.setBlock(i + 10, j + 4, k + 31, Block.planks.blockID);
		world.setBlock(i + 10, j + 4, k + 32, Block.planks.blockID);
		world.setBlock(i + 10, j + 4, k + 33, Block.planks.blockID);
		world.setBlock(i + 10, j + 4, k + 34, Block.planks.blockID);
		world.setBlock(i + 10, j + 4, k + 35, Block.planks.blockID);
		world.setBlock(i + 10, j + 4, k + 37, Block.planks.blockID);
		world.setBlock(i + 10, j + 4, k + 38, Block.planks.blockID);
		world.setBlock(i + 10, j + 4, k + 39, Block.planks.blockID);
		world.setBlock(i + 10, j + 4, k + 40, Block.planks.blockID);
		world.setBlockAndMetadata(i + 10, j + 4, k + 44, Block.stoneOvenIdle.blockID, 2);
		world.setBlock(i + 10, j + 4, k + 45, Block.planks.blockID);
		world.setBlock(i + 10, j + 5, k + 2, Block.planks.blockID);
		world.setBlockAndMetadata(i + 10, j + 5, k + 6, Block.stairCompactPlanks.blockID, 3);
		world.setBlock(i + 10, j + 5, k + 10, Block.planks.blockID);
		world.setBlock(i + 10, j + 5, k + 11, Block.planks.blockID);
		world.setBlock(i + 10, j + 5, k + 13, Block.planks.blockID);
		world.setBlock(i + 10, j + 5, k + 14, Block.planks.blockID);
		world.setBlock(i + 10, j + 5, k + 15, Block.planks.blockID);
		world.setBlock(i + 10, j + 5, k + 16, Block.planks.blockID);
		world.setBlock(i + 10, j + 5, k + 17, Block.planks.blockID);
		world.setBlock(i + 10, j + 5, k + 19, Block.planks.blockID);
		world.setBlock(i + 10, j + 5, k + 20, Block.planks.blockID);
		world.setBlock(i + 10, j + 5, k + 21, Block.planks.blockID);
		world.setBlock(i + 10, j + 5, k + 22, Block.planks.blockID);
		world.setBlock(i + 10, j + 5, k + 23, Block.planks.blockID);
		world.setBlock(i + 10, j + 5, k + 25, Block.planks.blockID);
		world.setBlock(i + 10, j + 5, k + 26, Block.planks.blockID);
		world.setBlock(i + 10, j + 5, k + 27, Block.planks.blockID);
		world.setBlock(i + 10, j + 5, k + 28, Block.planks.blockID);
		world.setBlock(i + 10, j + 5, k + 29, Block.planks.blockID);
		world.setBlock(i + 10, j + 5, k + 31, Block.planks.blockID);
		world.setBlock(i + 10, j + 5, k + 32, Block.planks.blockID);
		world.setBlock(i + 10, j + 5, k + 33, Block.planks.blockID);
		world.setBlock(i + 10, j + 5, k + 34, Block.planks.blockID);
		world.setBlock(i + 10, j + 5, k + 35, Block.planks.blockID);
		world.setBlock(i + 10, j + 5, k + 37, Block.planks.blockID);
		world.setBlock(i + 10, j + 5, k + 38, Block.planks.blockID);
		world.setBlock(i + 10, j + 5, k + 39, Block.planks.blockID);
		world.setBlock(i + 10, j + 5, k + 40, Block.planks.blockID);
		world.setBlockAndMetadata(i + 10, j + 5, k + 45, Block.stoneOvenIdle.blockID, 2);
		world.setBlock(i + 10, j + 5, k + 46, Block.planks.blockID);
		world.setBlock(i + 10, j + 6, k + 2, Block.planks.blockID);
		world.setBlock(i + 10, j + 6, k + 3, Block.planks.blockID);
		world.setBlock(i + 10, j + 6, k + 4, Block.planks.blockID);
		world.setBlockAndMetadata(i + 10, j + 6, k + 5, Block.stairCompactPlanks.blockID, 3);
		world.setBlock(i + 10, j + 6, k + 9, Block.planks.blockID);
		world.setBlock(i + 10, j + 6, k + 10, Block.planks.blockID);
		world.setBlock(i + 10, j + 6, k + 11, Block.planks.blockID);
		world.setBlock(i + 10, j + 6, k + 12, Block.planks.blockID);
		world.setBlock(i + 10, j + 6, k + 13, Block.planks.blockID);
		world.setBlock(i + 10, j + 6, k + 14, Block.planks.blockID);
		world.setBlock(i + 10, j + 6, k + 15, Block.planks.blockID);
		world.setBlock(i + 10, j + 6, k + 16, Block.planks.blockID);
		world.setBlock(i + 10, j + 6, k + 17, Block.planks.blockID);
		world.setBlock(i + 10, j + 6, k + 18, Block.planks.blockID);
		world.setBlock(i + 10, j + 6, k + 19, Block.planks.blockID);
		world.setBlock(i + 10, j + 6, k + 20, Block.planks.blockID);
		world.setBlock(i + 10, j + 6, k + 21, Block.planks.blockID);
		world.setBlock(i + 10, j + 6, k + 22, Block.planks.blockID);
		world.setBlock(i + 10, j + 6, k + 23, Block.planks.blockID);
		world.setBlock(i + 10, j + 6, k + 24, Block.planks.blockID);
		world.setBlock(i + 10, j + 6, k + 25, Block.planks.blockID);
		world.setBlock(i + 10, j + 6, k + 26, Block.planks.blockID);
		world.setBlock(i + 10, j + 6, k + 27, Block.planks.blockID);
		world.setBlock(i + 10, j + 6, k + 28, Block.planks.blockID);
		world.setBlock(i + 10, j + 6, k + 29, Block.planks.blockID);
		world.setBlock(i + 10, j + 6, k + 30, Block.planks.blockID);
		world.setBlock(i + 10, j + 6, k + 31, Block.planks.blockID);
		world.setBlock(i + 10, j + 6, k + 32, Block.planks.blockID);
		world.setBlock(i + 10, j + 6, k + 33, Block.planks.blockID);
		world.setBlock(i + 10, j + 6, k + 34, Block.planks.blockID);
		world.setBlock(i + 10, j + 6, k + 35, Block.planks.blockID);
		world.setBlock(i + 10, j + 6, k + 36, Block.planks.blockID);
		world.setBlock(i + 10, j + 6, k + 37, Block.planks.blockID);
		world.setBlock(i + 10, j + 6, k + 38, Block.planks.blockID);
		world.setBlock(i + 10, j + 6, k + 39, Block.planks.blockID);
		world.setBlock(i + 10, j + 6, k + 40, Block.planks.blockID);
		world.setBlock(i + 10, j + 6, k + 41, Block.planks.blockID);
		world.setBlock(i + 10, j + 6, k + 42, Block.planks.blockID);
		world.setBlock(i + 10, j + 6, k + 43, Block.planks.blockID);
		world.setBlock(i + 10, j + 6, k + 44, Block.planks.blockID);
		world.setBlock(i + 10, j + 6, k + 45, Block.planks.blockID);
		world.setBlock(i + 10, j + 6, k + 46, Block.planks.blockID);
		world.setBlock(i + 10, j + 6, k + 47, Block.planks.blockID);
		world.setBlock(i + 10, j + 7, k + 2, Block.planks.blockID);
		world.setBlock(i + 10, j + 7, k + 9, Block.fence.blockID);
		world.setBlockAndMetadata(i + 10, j + 7, k + 26, Block.stairCompactPlanks.blockID, 2);
		world.setBlockAndMetadata(i + 10, j + 7, k + 29, Block.thinGlass.blockID, 2);
		world.setBlockAndMetadata(i + 10, j + 7, k + 30, Block.thinGlass.blockID, 2);
		world.setBlockAndMetadata(i + 10, j + 7, k + 31, Block.thinGlass.blockID, 2);
		world.setBlockAndMetadata(i + 10, j + 7, k + 32, Block.thinGlass.blockID, 2);
		world.setBlockAndMetadata(i + 10, j + 7, k + 33, Block.thinGlass.blockID, 2);
		world.setBlockAndMetadata(i + 10, j + 7, k + 34, Block.thinGlass.blockID, 2);
		world.setBlockAndMetadata(i + 10, j + 7, k + 35, Block.thinGlass.blockID, 2);
		world.setBlockAndMetadata(i + 10, j + 7, k + 36, Block.thinGlass.blockID, 2);
		world.setBlockAndMetadata(i + 10, j + 7, k + 37, Block.thinGlass.blockID, 2);
		world.setBlockAndMetadata(i + 10, j + 7, k + 38, Block.thinGlass.blockID, 2);
		world.setBlock(i + 10, j + 7, k + 41, Block.planks.blockID);
		world.setBlockAndMetadata(i + 10, j + 7, k + 46, Block.stoneOvenIdle.blockID, 2);
		world.setBlock(i + 10, j + 7, k + 47, Block.planks.blockID);
		world.setBlock(i + 10, j + 7, k + 48, Block.planks.blockID);
		world.setBlock(i + 10, j + 8, k + 2, Block.planks.blockID);
		world.setBlockAndMetadata(i + 10, j + 8, k + 27, Block.stairCompactPlanks.blockID, 2);
		world.setBlock(i + 10, j + 8, k + 41, Block.planks.blockID);
		world.setBlockAndMetadata(i + 10, j + 8, k + 47, Block.stoneOvenIdle.blockID, 2);
		world.setBlock(i + 10, j + 8, k + 48, Block.planks.blockID);
		world.setBlockAndMetadata(i + 10, j + 9, k + 2, Block.cloth.blockID, 14);
		world.setBlockAndMetadata(i + 10, j + 9, k + 3, Block.cloth.blockID, 14);
		world.setBlockAndMetadata(i + 10, j + 9, k + 4, Block.cloth.blockID, 14);
		world.setBlockAndMetadata(i + 10, j + 9, k + 5, Block.cloth.blockID, 14);
		world.setBlockAndMetadata(i + 10, j + 9, k + 6, Block.cloth.blockID, 14);
		world.setBlockAndMetadata(i + 10, j + 9, k + 7, Block.cloth.blockID, 14);
		world.setBlockAndMetadata(i + 10, j + 9, k + 8, Block.cloth.blockID, 14);
		world.setBlockAndMetadata(i + 10, j + 9, k + 9, Block.cloth.blockID, 14);
		world.setBlock(i + 10, j + 9, k + 10, Block.planks.blockID);
		world.setBlock(i + 10, j + 9, k + 11, Block.planks.blockID);
		world.setBlock(i + 10, j + 9, k + 12, Block.planks.blockID);
		world.setBlock(i + 10, j + 9, k + 13, Block.planks.blockID);
		world.setBlock(i + 10, j + 9, k + 14, Block.planks.blockID);
		world.setBlock(i + 10, j + 9, k + 15, Block.planks.blockID);
		world.setBlock(i + 10, j + 9, k + 16, Block.planks.blockID);
		world.setBlock(i + 10, j + 9, k + 17, Block.planks.blockID);
		world.setBlock(i + 10, j + 9, k + 18, Block.planks.blockID);
		world.setBlock(i + 10, j + 9, k + 19, Block.planks.blockID);
		world.setBlock(i + 10, j + 9, k + 20, Block.planks.blockID);
		world.setBlock(i + 10, j + 9, k + 21, Block.planks.blockID);
		world.setBlock(i + 10, j + 9, k + 22, Block.planks.blockID);
		world.setBlock(i + 10, j + 9, k + 23, Block.planks.blockID);
		world.setBlock(i + 10, j + 9, k + 24, Block.planks.blockID);
		world.setBlockAndMetadata(i + 10, j + 9, k + 28, Block.stairCompactPlanks.blockID, 2);
		world.setBlock(i + 10, j + 9, k + 29, Block.planks.blockID);
		world.setBlock(i + 10, j + 9, k + 30, Block.planks.blockID);
		world.setBlock(i + 10, j + 9, k + 31, Block.planks.blockID);
		world.setBlock(i + 10, j + 9, k + 32, Block.planks.blockID);
		world.setBlock(i + 10, j + 9, k + 33, Block.planks.blockID);
		world.setBlock(i + 10, j + 9, k + 34, Block.planks.blockID);
		world.setBlock(i + 10, j + 9, k + 35, Block.planks.blockID);
		world.setBlock(i + 10, j + 9, k + 36, Block.planks.blockID);
		world.setBlock(i + 10, j + 9, k + 37, Block.planks.blockID);
		world.setBlock(i + 10, j + 9, k + 38, Block.planks.blockID);
		world.setBlock(i + 10, j + 9, k + 39, Block.planks.blockID);
		world.setBlock(i + 10, j + 9, k + 40, Block.planks.blockID);
		world.setBlock(i + 10, j + 9, k + 41, Block.planks.blockID);
		world.setBlock(i + 10, j + 9, k + 42, Block.planks.blockID);
		world.setBlock(i + 10, j + 9, k + 43, Block.planks.blockID);
		world.setBlock(i + 10, j + 9, k + 44, Block.planks.blockID);
		world.setBlock(i + 10, j + 9, k + 45, Block.planks.blockID);
		world.setBlock(i + 10, j + 9, k + 46, Block.planks.blockID);
		world.setBlock(i + 10, j + 9, k + 47, Block.planks.blockID);
		world.setBlock(i + 10, j + 9, k + 48, Block.planks.blockID);
		world.setBlock(i + 10, j + 9, k + 49, Block.planks.blockID);
		world.setBlock(i + 10, j + 10, k + 1, Block.planks.blockID);
		world.setBlock(i + 10, j + 10, k + 18, Block.wood.blockID);
		world.setBlock(i + 10, j + 10, k + 19, Block.wood.blockID);
		world.setBlock(i + 10, j + 10, k + 24, Block.fence.blockID);
		world.setBlock(i + 10, j + 10, k + 32, Block.wood.blockID);
		world.setBlock(i + 10, j + 10, k + 33, Block.wood.blockID);
		world.setBlockAndMetadata(i + 10, j + 10, k + 44, Block.stairCompactPlanks.blockID, 2);
		world.setBlock(i + 10, j + 10, k + 45, Block.planks.blockID);
		world.setBlock(i + 10, j + 10, k + 46, Block.planks.blockID);
		world.setBlock(i + 10, j + 10, k + 47, Block.planks.blockID);
		world.setBlock(i + 10, j + 10, k + 49, Block.planks.blockID);
		world.setBlock(i + 10, j + 10, k + 50, Block.planks.blockID);
		world.setBlock(i + 10, j + 11, k + 1, Block.glass.blockID);
		world.setBlock(i + 10, j + 11, k + 18, Block.wood.blockID);
		world.setBlock(i + 10, j + 11, k + 19, Block.wood.blockID);
		world.setBlock(i + 10, j + 11, k + 32, Block.wood.blockID);
		world.setBlock(i + 10, j + 11, k + 33, Block.wood.blockID);
		world.setBlockAndMetadata(i + 10, j + 11, k + 45, Block.stairCompactPlanks.blockID, 2);
		world.setBlock(i + 10, j + 11, k + 46, Block.planks.blockID);
		world.setBlock(i + 10, j + 11, k + 47, Block.planks.blockID);
		world.setBlock(i + 10, j + 11, k + 49, Block.planks.blockID);
		world.setBlock(i + 10, j + 11, k + 50, Block.planks.blockID);
		world.setBlock(i + 10, j + 12, k + 1, Block.planks.blockID);
		world.setBlock(i + 10, j + 12, k + 10, Block.planks.blockID);
		world.setBlock(i + 10, j + 12, k + 18, Block.wood.blockID);
		world.setBlock(i + 10, j + 12, k + 19, Block.wood.blockID);
		world.setBlock(i + 10, j + 12, k + 32, Block.wood.blockID);
		world.setBlock(i + 10, j + 12, k + 33, Block.wood.blockID);
		world.setBlockAndMetadata(i + 10, j + 12, k + 46, Block.stairCompactPlanks.blockID, 2);
		world.setBlock(i + 10, j + 12, k + 47, Block.planks.blockID);
		world.setBlock(i + 10, j + 12, k + 48, Block.planks.blockID);
		world.setBlock(i + 10, j + 12, k + 49, Block.planks.blockID);
		world.setBlock(i + 10, j + 12, k + 50, Block.planks.blockID);
		world.setBlock(i + 10, j + 13, k + 1, Block.planks.blockID);
		world.setBlock(i + 10, j + 13, k + 2, Block.planks.blockID);
		world.setBlock(i + 10, j + 13, k + 3, Block.planks.blockID);
		world.setBlock(i + 10, j + 13, k + 4, Block.planks.blockID);
		world.setBlock(i + 10, j + 13, k + 5, Block.planks.blockID);
		world.setBlock(i + 10, j + 13, k + 6, Block.planks.blockID);
		world.setBlock(i + 10, j + 13, k + 7, Block.planks.blockID);
		world.setBlock(i + 10, j + 13, k + 8, Block.planks.blockID);
		world.setBlock(i + 10, j + 13, k + 9, Block.planks.blockID);
		world.setBlock(i + 10, j + 13, k + 10, Block.planks.blockID);
		world.setBlock(i + 10, j + 13, k + 18, Block.wood.blockID);
		world.setBlock(i + 10, j + 13, k + 19, Block.wood.blockID);
		world.setBlock(i + 10, j + 13, k + 32, Block.wood.blockID);
		world.setBlock(i + 10, j + 13, k + 33, Block.wood.blockID);
		world.setBlock(i + 10, j + 13, k + 49, Block.fence.blockID);
		world.setBlock(i + 10, j + 13, k + 50, Block.fence.blockID);
		world.setBlock(i + 10, j + 14, k + 1, Block.fence.blockID);
		world.setBlock(i + 10, j + 14, k + 18, Block.wood.blockID);
		world.setBlock(i + 10, j + 14, k + 19, Block.wood.blockID);
		world.setBlock(i + 10, j + 14, k + 32, Block.wood.blockID);
		world.setBlock(i + 10, j + 14, k + 33, Block.wood.blockID);
		world.setBlock(i + 10, j + 15, k + 18, Block.wood.blockID);
		world.setBlock(i + 10, j + 15, k + 19, Block.wood.blockID);
		world.setBlock(i + 10, j + 15, k + 22, Block.cloth.blockID);
		world.setBlock(i + 10, j + 15, k + 32, Block.wood.blockID);
		world.setBlock(i + 10, j + 15, k + 33, Block.wood.blockID);
		world.setBlock(i + 10, j + 15, k + 36, Block.cloth.blockID);
		world.setBlock(i + 10, j + 16, k + 18, Block.wood.blockID);
		world.setBlock(i + 10, j + 16, k + 19, Block.wood.blockID);
		world.setBlock(i + 10, j + 16, k + 22, Block.cloth.blockID);
		world.setBlock(i + 10, j + 16, k + 32, Block.wood.blockID);
		world.setBlock(i + 10, j + 16, k + 33, Block.wood.blockID);
		world.setBlock(i + 10, j + 16, k + 36, Block.cloth.blockID);
		world.setBlock(i + 10, j + 17, k + 18, Block.wood.blockID);
		world.setBlock(i + 10, j + 17, k + 19, Block.wood.blockID);
		world.setBlock(i + 10, j + 17, k + 22, Block.cloth.blockID);
		world.setBlock(i + 10, j + 17, k + 32, Block.wood.blockID);
		world.setBlock(i + 10, j + 17, k + 33, Block.wood.blockID);
		world.setBlock(i + 10, j + 17, k + 36, Block.cloth.blockID);
		world.setBlock(i + 10, j + 18, k + 18, Block.wood.blockID);
		world.setBlock(i + 10, j + 18, k + 19, Block.wood.blockID);
		world.setBlock(i + 10, j + 18, k + 22, Block.cloth.blockID);
		world.setBlock(i + 10, j + 18, k + 32, Block.wood.blockID);
		world.setBlock(i + 10, j + 18, k + 33, Block.wood.blockID);
		world.setBlock(i + 10, j + 18, k + 36, Block.cloth.blockID);
		world.setBlock(i + 10, j + 19, k + 18, Block.wood.blockID);
		world.setBlock(i + 10, j + 19, k + 19, Block.wood.blockID);
		world.setBlock(i + 10, j + 19, k + 22, Block.cloth.blockID);
		world.setBlock(i + 10, j + 19, k + 32, Block.wood.blockID);
		world.setBlock(i + 10, j + 19, k + 33, Block.wood.blockID);
		world.setBlock(i + 10, j + 19, k + 35, Block.cloth.blockID);
		world.setBlock(i + 10, j + 20, k + 18, Block.wood.blockID);
		world.setBlock(i + 10, j + 20, k + 19, Block.wood.blockID);
		world.setBlock(i + 10, j + 20, k + 21, Block.cloth.blockID);
		world.setBlock(i + 10, j + 20, k + 32, Block.wood.blockID);
		world.setBlock(i + 10, j + 20, k + 33, Block.wood.blockID);
		world.setBlock(i + 10, j + 20, k + 34, Block.planks.blockID);
		world.setBlock(i + 10, j + 21, k + 18, Block.wood.blockID);
		world.setBlock(i + 10, j + 21, k + 19, Block.wood.blockID);
		world.setBlock(i + 10, j + 21, k + 20, Block.planks.blockID);
		world.setBlock(i + 10, j + 21, k + 32, Block.wood.blockID);
		world.setBlock(i + 10, j + 21, k + 33, Block.wood.blockID);
		world.setBlock(i + 10, j + 21, k + 36, Block.cloth.blockID);
		world.setBlock(i + 10, j + 22, k + 18, Block.wood.blockID);
		world.setBlock(i + 10, j + 22, k + 19, Block.wood.blockID);
		world.setBlock(i + 10, j + 22, k + 32, Block.wood.blockID);
		world.setBlock(i + 10, j + 22, k + 33, Block.wood.blockID);
		world.setBlock(i + 10, j + 22, k + 36, Block.cloth.blockID);
		world.setBlock(i + 10, j + 23, k + 18, Block.wood.blockID);
		world.setBlock(i + 10, j + 23, k + 19, Block.wood.blockID);
		world.setBlock(i + 10, j + 23, k + 22, Block.cloth.blockID);
		world.setBlock(i + 10, j + 23, k + 32, Block.wood.blockID);
		world.setBlock(i + 10, j + 23, k + 33, Block.wood.blockID);
		world.setBlock(i + 10, j + 23, k + 36, Block.cloth.blockID);
		world.setBlock(i + 10, j + 24, k + 18, Block.wood.blockID);
		world.setBlock(i + 10, j + 24, k + 19, Block.wood.blockID);
		world.setBlock(i + 10, j + 24, k + 22, Block.cloth.blockID);
		world.setBlock(i + 10, j + 24, k + 32, Block.wood.blockID);
		world.setBlock(i + 10, j + 24, k + 33, Block.wood.blockID);
		world.setBlock(i + 10, j + 24, k + 36, Block.cloth.blockID);
		world.setBlock(i + 10, j + 25, k + 18, Block.wood.blockID);
		world.setBlock(i + 10, j + 25, k + 19, Block.wood.blockID);
		world.setBlock(i + 10, j + 25, k + 22, Block.cloth.blockID);
		world.setBlock(i + 10, j + 25, k + 32, Block.wood.blockID);
		world.setBlock(i + 10, j + 25, k + 33, Block.wood.blockID);
		world.setBlock(i + 10, j + 25, k + 35, Block.cloth.blockID);
		world.setBlock(i + 10, j + 26, k + 18, Block.wood.blockID);
		world.setBlock(i + 10, j + 26, k + 19, Block.wood.blockID);
		world.setBlock(i + 10, j + 26, k + 22, Block.cloth.blockID);
		world.setBlock(i + 10, j + 26, k + 32, Block.wood.blockID);
		world.setBlock(i + 10, j + 26, k + 33, Block.wood.blockID);
		world.setBlock(i + 10, j + 26, k + 34, Block.planks.blockID);
		world.setBlock(i + 10, j + 27, k + 18, Block.wood.blockID);
		world.setBlock(i + 10, j + 27, k + 19, Block.wood.blockID);
		world.setBlock(i + 10, j + 27, k + 21, Block.cloth.blockID);
		world.setBlock(i + 10, j + 27, k + 32, Block.wood.blockID);
		world.setBlock(i + 10, j + 27, k + 33, Block.wood.blockID);
		world.setBlock(i + 10, j + 28, k + 18, Block.wood.blockID);
		world.setBlock(i + 10, j + 28, k + 19, Block.wood.blockID);
		world.setBlock(i + 10, j + 28, k + 20, Block.planks.blockID);
		world.setBlock(i + 10, j + 28, k + 32, Block.wood.blockID);
		world.setBlock(i + 10, j + 28, k + 33, Block.wood.blockID);
		world.setBlock(i + 10, j + 29, k + 18, Block.wood.blockID);
		world.setBlock(i + 10, j + 29, k + 19, Block.wood.blockID);
		world.setBlock(i + 10, j + 29, k + 32, Block.wood.blockID);
		world.setBlock(i + 10, j + 29, k + 33, Block.wood.blockID);
		world.setBlock(i + 10, j + 30, k + 18, Block.wood.blockID);
		world.setBlock(i + 10, j + 30, k + 19, Block.wood.blockID);
		world.setBlock(i + 10, j + 31, k + 16, Block.planks.blockID);
		world.setBlock(i + 10, j + 31, k + 18, Block.wood.blockID);
		world.setBlock(i + 10, j + 31, k + 19, Block.wood.blockID);
		world.setBlock(i + 10, j + 31, k + 20, Block.planks.blockID);
		world.setBlock(i + 10, j + 31, k + 21, Block.planks.blockID);
		world.setBlock(i + 10, j + 32, k + 16, Block.fence.blockID);
		world.setBlock(i + 10, j + 32, k + 18, Block.wood.blockID);
		world.setBlock(i + 10, j + 32, k + 19, Block.wood.blockID);
		world.setBlock(i + 10, j + 32, k + 21, Block.fence.blockID);
		world.setBlock(i + 10, j + 33, k + 18, Block.wood.blockID);
		world.setBlock(i + 10, j + 33, k + 19, Block.wood.blockID);
		world.setBlock(i + 10, j + 34, k + 18, Block.wood.blockID);
		world.setBlock(i + 10, j + 34, k + 19, Block.wood.blockID);
		world.setBlock(i + 11, j + 1, k + 6, Block.planks.blockID);
		world.setBlock(i + 11, j + 1, k + 7, Block.planks.blockID);
		world.setBlock(i + 11, j + 1, k + 8, Block.planks.blockID);
		world.setBlock(i + 11, j + 1, k + 9, Block.planks.blockID);
		world.setBlock(i + 11, j + 1, k + 10, Block.planks.blockID);
		world.setBlock(i + 11, j + 1, k + 11, Block.planks.blockID);
		world.setBlock(i + 11, j + 1, k + 12, Block.planks.blockID);
		world.setBlock(i + 11, j + 1, k + 13, Block.planks.blockID);
		world.setBlock(i + 11, j + 1, k + 14, Block.planks.blockID);

		generate2(world, rand, i, j, k);
		return true;
	}

	public boolean generate2(World world, Random rand, int i, int j, int k) 
	{
		world.setBlock(i + 11, j + 1, k + 15, Block.planks.blockID);
		world.setBlock(i + 11, j + 1, k + 16, Block.planks.blockID);
		world.setBlock(i + 11, j + 1, k + 17, Block.planks.blockID);
		world.setBlock(i + 11, j + 1, k + 18, Block.planks.blockID);
		world.setBlock(i + 11, j + 1, k + 19, Block.planks.blockID);
		world.setBlock(i + 11, j + 1, k + 20, Block.planks.blockID);
		world.setBlock(i + 11, j + 1, k + 21, Block.planks.blockID);
		world.setBlock(i + 11, j + 1, k + 22, Block.planks.blockID);
		world.setBlock(i + 11, j + 1, k + 23, Block.planks.blockID);
		world.setBlock(i + 11, j + 1, k + 24, Block.planks.blockID);
		world.setBlock(i + 11, j + 1, k + 25, Block.planks.blockID);
		world.setBlock(i + 11, j + 1, k + 26, Block.planks.blockID);
		world.setBlock(i + 11, j + 1, k + 27, Block.planks.blockID);
		world.setBlock(i + 11, j + 1, k + 28, Block.planks.blockID);
		world.setBlock(i + 11, j + 1, k + 29, Block.planks.blockID);
		world.setBlock(i + 11, j + 1, k + 30, Block.planks.blockID);
		world.setBlock(i + 11, j + 1, k + 31, Block.planks.blockID);
		world.setBlock(i + 11, j + 1, k + 32, Block.planks.blockID);
		world.setBlock(i + 11, j + 1, k + 33, Block.planks.blockID);
		world.setBlock(i + 11, j + 1, k + 34, Block.planks.blockID);
		world.setBlock(i + 11, j + 1, k + 35, Block.planks.blockID);
		world.setBlock(i + 11, j + 1, k + 36, Block.planks.blockID);
		world.setBlock(i + 11, j + 1, k + 37, Block.planks.blockID);
		world.setBlock(i + 11, j + 1, k + 38, Block.planks.blockID);
		world.setBlock(i + 11, j + 1, k + 39, Block.planks.blockID);
		world.setBlock(i + 11, j + 1, k + 40, Block.planks.blockID);
		world.setBlock(i + 11, j + 1, k + 41, Block.planks.blockID);
		world.setBlock(i + 11, j + 1, k + 42, Block.planks.blockID);
		world.setBlock(i + 11, j + 2, k + 4, Block.planks.blockID);
		world.setBlock(i + 11, j + 2, k + 5, Block.planks.blockID);
		world.setBlock(i + 11, j + 2, k + 42, Block.planks.blockID);
		world.setBlock(i + 11, j + 2, k + 43, Block.planks.blockID);
		world.setBlock(i + 11, j + 3, k + 3, Block.planks.blockID);
		world.setBlock(i + 11, j + 3, k + 4, Block.planks.blockID);
		world.setBlock(i + 11, j + 3, k + 5, Block.planks.blockID);
		world.setBlock(i + 11, j + 3, k + 6, Block.planks.blockID);
		world.setBlock(i + 11, j + 3, k + 8, Block.planks.blockID);
		world.setBlock(i + 11, j + 3, k + 9, Block.planks.blockID);
		world.setBlock(i + 11, j + 3, k + 10, Block.planks.blockID);
		world.setBlock(i + 11, j + 3, k + 11, Block.planks.blockID);
		world.setBlock(i + 11, j + 3, k + 12, Block.planks.blockID);
		world.setBlock(i + 11, j + 3, k + 13, Block.planks.blockID);
		world.setBlock(i + 11, j + 3, k + 14, Block.planks.blockID);
		world.setBlock(i + 11, j + 3, k + 15, Block.planks.blockID);
		world.setBlock(i + 11, j + 3, k + 16, Block.planks.blockID);
		world.setBlock(i + 11, j + 3, k + 17, Block.planks.blockID);
		world.setBlock(i + 11, j + 3, k + 18, Block.planks.blockID);
		world.setBlock(i + 11, j + 3, k + 19, Block.planks.blockID);
		world.setBlock(i + 11, j + 3, k + 20, Block.planks.blockID);
		world.setBlock(i + 11, j + 3, k + 21, Block.planks.blockID);
		world.setBlock(i + 11, j + 3, k + 22, Block.planks.blockID);
		world.setBlock(i + 11, j + 3, k + 23, Block.planks.blockID);
		world.setBlock(i + 11, j + 3, k + 24, Block.planks.blockID);
		world.setBlock(i + 11, j + 3, k + 25, Block.planks.blockID);
		world.setBlock(i + 11, j + 3, k + 26, Block.planks.blockID);
		world.setBlock(i + 11, j + 3, k + 27, Block.planks.blockID);
