package fossil.gens;

import java.util.Random;

import net.minecraft.block.Block;
import net.minecraft.world.World;
import net.minecraft.world.gen.feature.WorldGenerator;

public class WorldGeneratorDukeWreck extends WorldGenerator
{
	
	public boolean generate(World world, Random rand, int i, int j, int k)
	{
		System.out.println("Generating DukeWreck");
		world.setBlockAndMetadata(i + 0, j + 22, k + 11, Block.wood.blockID, 1);
		world.setBlockAndMetadata(i + 1, j + 22, k + 11, Block.wood.blockID, 1);
		world.setBlockAndMetadata(i + 2, j + 22, k + 11, Block.wood.blockID, 1);
		world.setBlockAndMetadata(i + 3, j + 21, k + 11, Block.wood.blockID, 1);
		world.setBlockAndMetadata(i + 4, j + 20, k + 11, Block.stairsBrick.blockID, 6);
		world.setBlockAndMetadata(i + 4, j + 21, k + 11, Block.wood.blockID, 1);
		world.setBlockAndMetadata(i + 5, j + 14, k + 5, Block.stairsBrick.blockID, 4);
		world.setBlockAndMetadata(i + 5, j + 14, k + 9, Block.stairsBrick.blockID, 4);
		world.setBlockAndMetadata(i + 5, j + 14, k + 13, Block.stairsBrick.blockID, 4);
		world.setBlockAndMetadata(i + 5, j + 14, k + 17, Block.stairsBrick.blockID, 4);
		world.setBlockAndMetadata(i + 5, j + 15, k + 5, Block.cloth.blockID, 15);
		world.setBlockAndMetadata(i + 5, j + 15, k + 6, Block.cloth.blockID, 15);
		world.setBlockAndMetadata(i + 5, j + 15, k + 7, Block.cloth.blockID, 15);
		world.setBlockAndMetadata(i + 5, j + 15, k + 8, Block.cloth.blockID, 15);
		world.setBlockAndMetadata(i + 5, j + 15, k + 9, Block.cloth.blockID, 15);
		world.setBlockAndMetadata(i + 5, j + 15, k + 10, Block.cloth.blockID, 15);
		world.setBlockAndMetadata(i + 5, j + 15, k + 11, Block.cloth.blockID, 15);
		world.setBlockAndMetadata(i + 5, j + 15, k + 12, Block.cloth.blockID, 15);
		world.setBlockAndMetadata(i + 5, j + 15, k + 13, Block.cloth.blockID, 15);
		world.setBlockAndMetadata(i + 5, j + 15, k + 14, Block.cloth.blockID, 15);
		world.setBlockAndMetadata(i + 5, j + 15, k + 15, Block.cloth.blockID, 15);
		world.setBlockAndMetadata(i + 5, j + 15, k + 16, Block.cloth.blockID, 15);
		world.setBlockAndMetadata(i + 5, j + 15, k + 17, Block.cloth.blockID, 15);
		world.setBlockAndMetadata(i + 5, j + 16, k + 4, Block.cloth.blockID, 15);
		world.setBlockAndMetadata(i + 5, j + 16, k + 18, Block.cloth.blockID, 15);
		world.setBlockAndMetadata(i + 5, j + 17, k + 4, Block.cloth.blockID, 15);
		world.setBlockAndMetadata(i + 5, j + 17, k + 5, Block.cloth.blockID, 15);
		world.setBlockAndMetadata(i + 5, j + 17, k + 6, Block.cloth.blockID, 15);
		world.setBlockAndMetadata(i + 5, j + 17, k + 7, Block.cloth.blockID, 15);
		world.setBlockAndMetadata(i + 5, j + 17, k + 8, Block.cloth.blockID, 15);
		world.setBlockAndMetadata(i + 5, j + 17, k + 9, Block.cloth.blockID, 15);
		world.setBlockAndMetadata(i + 5, j + 17, k + 10, Block.cloth.blockID, 15);
		world.setBlockAndMetadata(i + 5, j + 17, k + 11, Block.cloth.blockID, 15);
		world.setBlockAndMetadata(i + 5, j + 17, k + 12, Block.cloth.blockID, 15);
		world.setBlockAndMetadata(i + 5, j + 17, k + 13, Block.cloth.blockID, 15);
		world.setBlockAndMetadata(i + 5, j + 17, k + 14, Block.cloth.blockID, 15);
		world.setBlockAndMetadata(i + 5, j + 17, k + 15, Block.cloth.blockID, 15);
		world.setBlockAndMetadata(i + 5, j + 17, k + 16, Block.cloth.blockID, 15);
		world.setBlockAndMetadata(i + 5, j + 17, k + 17, Block.cloth.blockID, 15);
		world.setBlockAndMetadata(i + 5, j + 17, k + 18, Block.cloth.blockID, 15);
		world.setBlockAndMetadata(i + 5, j + 18, k + 4, Block.cloth.blockID, 4);
		world.setBlockAndMetadata(i + 5, j + 18, k + 5, Block.cloth.blockID, 4);
		world.setBlockAndMetadata(i + 5, j + 18, k + 6, Block.cloth.blockID, 4);
		world.setBlockAndMetadata(i + 5, j + 18, k + 7, Block.cloth.blockID, 4);
		world.setBlockAndMetadata(i + 5, j + 18, k + 8, Block.cloth.blockID, 4);
		world.setBlockAndMetadata(i + 5, j + 18, k + 9, Block.cloth.blockID, 4);
		world.setBlockAndMetadata(i + 5, j + 18, k + 10, Block.cloth.blockID, 4);
		world.setBlockAndMetadata(i + 5, j + 18, k + 11, Block.cloth.blockID, 4);
		world.setBlockAndMetadata(i + 5, j + 18, k + 12, Block.cloth.blockID, 4);
		world.setBlockAndMetadata(i + 5, j + 18, k + 13, Block.cloth.blockID, 4);
		world.setBlockAndMetadata(i + 5, j + 18, k + 14, Block.cloth.blockID, 4);
		world.setBlockAndMetadata(i + 5, j + 18, k + 15, Block.cloth.blockID, 4);
		world.setBlockAndMetadata(i + 5, j + 18, k + 16, Block.cloth.blockID, 4);
		world.setBlockAndMetadata(i + 5, j + 18, k + 17, Block.cloth.blockID, 4);
		world.setBlockAndMetadata(i + 5, j + 18, k + 18, Block.cloth.blockID, 4);
		world.setBlockAndMetadata(i + 5, j + 19, k + 4, Block.cloth.blockID, 15);
		world.setBlockAndMetadata(i + 5, j + 19, k + 5, Block.cloth.blockID, 15);
		world.setBlockAndMetadata(i + 5, j + 19, k + 6, Block.cloth.blockID, 15);
		world.setBlockAndMetadata(i + 5, j + 19, k + 7, Block.cloth.blockID, 15);
		world.setBlockAndMetadata(i + 5, j + 19, k + 8, Block.cloth.blockID, 15);
		world.setBlockAndMetadata(i + 5, j + 19, k + 9, Block.cloth.blockID, 15);
		world.setBlockAndMetadata(i + 5, j + 19, k + 10, Block.cloth.blockID, 15);
		world.setBlockAndMetadata(i + 5, j + 19, k + 11, Block.cloth.blockID, 15);
		world.setBlockAndMetadata(i + 5, j + 19, k + 12, Block.cloth.blockID, 15);
		world.setBlockAndMetadata(i + 5, j + 19, k + 13, Block.cloth.blockID, 15);
		world.setBlockAndMetadata(i + 5, j + 19, k + 14, Block.cloth.blockID, 15);
		world.setBlockAndMetadata(i + 5, j + 19, k + 15, Block.cloth.blockID, 15);
		world.setBlockAndMetadata(i + 5, j + 19, k + 16, Block.cloth.blockID, 15);
		world.setBlockAndMetadata(i + 5, j + 19, k + 17, Block.cloth.blockID, 15);
		world.setBlockAndMetadata(i + 5, j + 19, k + 18, Block.cloth.blockID, 15);
		world.setBlock(i + 5, j + 20, k + 4, Block.cloth.blockID);
		world.setBlock(i + 5, j + 20, k + 5, Block.cloth.blockID);
		world.setBlock(i + 5, j + 20, k + 6, Block.cloth.blockID);
		world.setBlock(i + 5, j + 20, k + 7, Block.cloth.blockID);
		world.setBlock(i + 5, j + 20, k + 8, Block.cloth.blockID);
		world.setBlock(i + 5, j + 20, k + 9, Block.cloth.blockID);
		world.setBlock(i + 5, j + 20, k + 10, Block.cloth.blockID);
		world.setBlock(i + 5, j + 20, k + 11, Block.cloth.blockID);
		world.setBlock(i + 5, j + 20, k + 12, Block.cloth.blockID);
		world.setBlock(i + 5, j + 20, k + 13, Block.cloth.blockID);
		world.setBlock(i + 5, j + 20, k + 14, Block.cloth.blockID);
		world.setBlock(i + 5, j + 20, k + 15, Block.cloth.blockID);
		world.setBlock(i + 5, j + 20, k + 16, Block.cloth.blockID);
		world.setBlock(i + 5, j + 20, k + 17, Block.cloth.blockID);
		world.setBlock(i + 5, j + 20, k + 18, Block.cloth.blockID);
		world.setBlock(i + 5, j + 21, k + 4, Block.cloth.blockID);
		world.setBlock(i + 5, j + 21, k + 5, Block.netherFence.blockID);
		world.setBlock(i + 5, j + 21, k + 6, Block.netherFence.blockID);
		world.setBlock(i + 5, j + 21, k + 7, Block.netherFence.blockID);
		world.setBlock(i + 5, j + 21, k + 8, Block.cloth.blockID);
		world.setBlock(i + 5, j + 21, k + 9, Block.netherFence.blockID);
		world.setBlock(i + 5, j + 21, k + 10, Block.netherFence.blockID);
		world.setBlockAndMetadata(i + 5, j + 21, k + 11, Block.wood.blockID, 1);
		world.setBlock(i + 5, j + 21, k + 12, Block.netherFence.blockID);
		world.setBlock(i + 5, j + 21, k + 13, Block.netherFence.blockID);
		world.setBlock(i + 5, j + 21, k + 14, Block.cloth.blockID);
		world.setBlock(i + 5, j + 21, k + 15, Block.netherFence.blockID);
		world.setBlock(i + 5, j + 21, k + 16, Block.netherFence.blockID);
		world.setBlock(i + 5, j + 21, k + 17, Block.netherFence.blockID);
		world.setBlock(i + 5, j + 21, k + 18, Block.cloth.blockID);
		world.setBlockAndMetadata(i + 6, j + 13, k + 5, Block.stairsBrick.blockID, 4);
		world.setBlockAndMetadata(i + 6, j + 13, k + 9, Block.stairsBrick.blockID, 4);
		world.setBlockAndMetadata(i + 6, j + 13, k + 13, Block.stairsBrick.blockID, 4);
		world.setBlockAndMetadata(i + 6, j + 13, k + 17, Block.stairsBrick.blockID, 4);
		world.setBlockAndMetadata(i + 6, j + 14, k + 2, Block.cloth.blockID, 15);
		world.setBlockAndMetadata(i + 6, j + 14, k + 3, Block.cloth.blockID, 15);
		world.setBlockAndMetadata(i + 6, j + 14, k + 4, Block.cloth.blockID, 15);
		world.setBlockAndMetadata(i + 6, j + 14, k + 5, Block.cloth.blockID, 15);
		world.setBlockAndMetadata(i + 6, j + 14, k + 6, Block.cloth.blockID, 15);
		world.setBlockAndMetadata(i + 6, j + 14, k + 7, Block.cloth.blockID, 15);
		world.setBlockAndMetadata(i + 6, j + 14, k + 8, Block.cloth.blockID, 15);
		world.setBlockAndMetadata(i + 6, j + 14, k + 9, Block.cloth.blockID, 15);
		world.setBlockAndMetadata(i + 6, j + 14, k + 10, Block.cloth.blockID, 15);
		world.setBlockAndMetadata(i + 6, j + 14, k + 11, Block.cloth.blockID, 15);
		world.setBlockAndMetadata(i + 6, j + 14, k + 12, Block.cloth.blockID, 15);
		world.setBlockAndMetadata(i + 6, j + 14, k + 13, Block.cloth.blockID, 15);
		world.setBlockAndMetadata(i + 6, j + 14, k + 14, Block.cloth.blockID, 15);
		world.setBlockAndMetadata(i + 6, j + 14, k + 15, Block.cloth.blockID, 15);
		world.setBlockAndMetadata(i + 6, j + 14, k + 16, Block.cloth.blockID, 15);
		world.setBlockAndMetadata(i + 6, j + 14, k + 17, Block.cloth.blockID, 15);
		world.setBlockAndMetadata(i + 6, j + 14, k + 18, Block.cloth.blockID, 15);
		world.setBlockAndMetadata(i + 6, j + 14, k + 19, Block.cloth.blockID, 15);
		world.setBlockAndMetadata(i + 6, j + 14, k + 20, Block.cloth.blockID, 15);
		world.setBlockAndMetadata(i + 6, j + 15, k + 1, Block.cloth.blockID, 15);
		world.setBlockAndMetadata(i + 6, j + 15, k + 2, Block.cloth.blockID, 15);
		world.setBlockAndMetadata(i + 6, j + 15, k + 3, Block.cloth.blockID, 15);
		world.setBlockAndMetadata(i + 6, j + 15, k + 4, Block.cloth.blockID, 15);
		world.setBlockAndMetadata(i + 6, j + 15, k + 18, Block.cloth.blockID, 15);
		world.setBlockAndMetadata(i + 6, j + 15, k + 19, Block.cloth.blockID, 15);
		world.setBlockAndMetadata(i + 6, j + 15, k + 20, Block.cloth.blockID, 15);
		world.setBlockAndMetadata(i + 6, j + 15, k + 21, Block.cloth.blockID, 15);
		world.setBlockAndMetadata(i + 6, j + 16, k + 1, Block.cloth.blockID, 4);
		world.setBlockAndMetadata(i + 6, j + 16, k + 2, Block.cloth.blockID, 15);
		world.setBlockAndMetadata(i + 6, j + 16, k + 3, Block.cloth.blockID, 15);
		world.setBlockAndMetadata(i + 6, j + 16, k + 4, Block.cloth.blockID, 15);
		world.setBlockAndMetadata(i + 6, j + 16, k + 18, Block.cloth.blockID, 15);
		world.setBlockAndMetadata(i + 6, j + 16, k + 19, Block.cloth.blockID, 15);
		world.setBlockAndMetadata(i + 6, j + 16, k + 20, Block.cloth.blockID, 15);
		world.setBlockAndMetadata(i + 6, j + 16, k + 21, Block.cloth.blockID, 4);
		world.setBlockAndMetadata(i + 6, j + 17, k + 1, Block.cloth.blockID, 15);
		world.setBlockAndMetadata(i + 6, j + 17, k + 2, Block.cloth.blockID, 4);
		world.setBlockAndMetadata(i + 6, j + 17, k + 3, Block.cloth.blockID, 15);
		world.setBlockAndMetadata(i + 6, j + 17, k + 4, Block.cloth.blockID, 15);
		world.setBlockAndMetadata(i + 6, j + 17, k + 18, Block.cloth.blockID, 15);
		world.setBlockAndMetadata(i + 6, j + 17, k + 19, Block.cloth.blockID, 15);
		world.setBlockAndMetadata(i + 6, j + 17, k + 20, Block.cloth.blockID, 4);
		world.setBlockAndMetadata(i + 6, j + 17, k + 21, Block.cloth.blockID, 15);
		world.setBlockAndMetadata(i + 6, j + 18, k + 1, Block.cloth.blockID, 15);
		world.setBlockAndMetadata(i + 6, j + 18, k + 2, Block.cloth.blockID, 15);
		world.setBlockAndMetadata(i + 6, j + 18, k + 3, Block.cloth.blockID, 4);
		world.setBlockAndMetadata(i + 6, j + 18, k + 4, Block.cloth.blockID, 4);
		world.setBlockAndMetadata(i + 6, j + 18, k + 5, Block.cloth.blockID, 4);
		world.setBlockAndMetadata(i + 6, j + 18, k + 6, Block.cloth.blockID, 4);
		world.setBlockAndMetadata(i + 6, j + 18, k + 7, Block.cloth.blockID, 4);
		world.setBlockAndMetadata(i + 6, j + 18, k + 8, Block.cloth.blockID, 4);
		world.setBlockAndMetadata(i + 6, j + 18, k + 9, Block.cloth.blockID, 4);
		world.setBlockAndMetadata(i + 6, j + 18, k + 10, Block.cloth.blockID, 4);
		world.setBlockAndMetadata(i + 6, j + 18, k + 11, Block.cloth.blockID, 4);
		world.setBlockAndMetadata(i + 6, j + 18, k + 12, Block.cloth.blockID, 4);
		world.setBlockAndMetadata(i + 6, j + 18, k + 13, Block.cloth.blockID, 4);
		world.setBlockAndMetadata(i + 6, j + 18, k + 14, Block.cloth.blockID, 4);
		world.setBlockAndMetadata(i + 6, j + 18, k + 15, Block.cloth.blockID, 4);
		world.setBlockAndMetadata(i + 6, j + 18, k + 16, Block.cloth.blockID, 4);
		world.setBlockAndMetadata(i + 6, j + 18, k + 17, Block.cloth.blockID, 4);
		world.setBlockAndMetadata(i + 6, j + 18, k + 18, Block.cloth.blockID, 4);
		world.setBlockAndMetadata(i + 6, j + 18, k + 19, Block.cloth.blockID, 4);
		world.setBlockAndMetadata(i + 6, j + 18, k + 20, Block.cloth.blockID, 15);
		world.setBlockAndMetadata(i + 6, j + 18, k + 21, Block.cloth.blockID, 15);
		world.setBlockAndMetadata(i + 6, j + 19, k + 1, Block.cloth.blockID, 15);
		world.setBlockAndMetadata(i + 6, j + 19, k + 2, Block.cloth.blockID, 15);
		world.setBlockAndMetadata(i + 6, j + 19, k + 3, Block.cloth.blockID, 15);
		world.setBlockAndMetadata(i + 6, j + 19, k + 4, Block.cloth.blockID, 15);
		world.setBlockAndMetadata(i + 6, j + 19, k + 5, Block.cloth.blockID, 15);
		world.setBlockAndMetadata(i + 6, j + 19, k + 6, Block.cloth.blockID, 15);
		world.setBlockAndMetadata(i + 6, j + 19, k + 7, Block.cloth.blockID, 15);
		world.setBlockAndMetadata(i + 6, j + 19, k + 8, Block.cloth.blockID, 15);
		world.setBlockAndMetadata(i + 6, j + 19, k + 9, Block.cloth.blockID, 15);
		world.setBlockAndMetadata(i + 6, j + 19, k + 10, Block.cloth.blockID, 15);
		world.setBlockAndMetadata(i + 6, j + 19, k + 11, Block.cloth.blockID, 15);
		world.setBlockAndMetadata(i + 6, j + 19, k + 12, Block.cloth.blockID, 15);
		world.setBlockAndMetadata(i + 6, j + 19, k + 13, Block.cloth.blockID, 15);
		world.setBlockAndMetadata(i + 6, j + 19, k + 14, Block.cloth.blockID, 15);
		world.setBlockAndMetadata(i + 6, j + 19, k + 15, Block.cloth.blockID, 15);
		world.setBlockAndMetadata(i + 6, j + 19, k + 16, Block.cloth.blockID, 15);
		world.setBlockAndMetadata(i + 6, j + 19, k + 17, Block.cloth.blockID, 15);
		world.setBlockAndMetadata(i + 6, j + 19, k + 18, Block.cloth.blockID, 15);
		world.setBlockAndMetadata(i + 6, j + 19, k + 19, Block.cloth.blockID, 15);
		world.setBlockAndMetadata(i + 6, j + 19, k + 20, Block.cloth.blockID, 15);
		world.setBlockAndMetadata(i + 6, j + 19, k + 21, Block.cloth.blockID, 15);
		world.setBlock(i + 6, j + 20, k + 1, Block.cloth.blockID);
		world.setBlock(i + 6, j + 20, k + 2, Block.cloth.blockID);
		world.setBlock(i + 6, j + 20, k + 3, Block.cloth.blockID);
		world.setBlockAndMetadata(i + 6, j + 20, k + 4, Block.stoneSingleSlab.blockID, 2);
		world.setBlockAndMetadata(i + 6, j + 20, k + 5, Block.stoneSingleSlab.blockID, 2);
		world.setBlockAndMetadata(i + 6, j + 20, k + 6, Block.stoneSingleSlab.blockID, 2);
		world.setBlockAndMetadata(i + 6, j + 20, k + 7, Block.stoneSingleSlab.blockID, 2);
		world.setBlockAndMetadata(i + 6, j + 20, k + 8, Block.stoneSingleSlab.blockID, 2);
		world.setBlockAndMetadata(i + 6, j + 20, k + 9, Block.stoneSingleSlab.blockID, 2);
		world.setBlockAndMetadata(i + 6, j + 20, k + 10, Block.stoneSingleSlab.blockID, 2);
		world.setBlockAndMetadata(i + 6, j + 20, k + 11, Block.stoneSingleSlab.blockID, 2);
		world.setBlockAndMetadata(i + 6, j + 20, k + 12, Block.stoneSingleSlab.blockID, 2);
		world.setBlockAndMetadata(i + 6, j + 20, k + 13, Block.stoneSingleSlab.blockID, 2);
		world.setBlockAndMetadata(i + 6, j + 20, k + 14, Block.stoneSingleSlab.blockID, 2);
		world.setBlockAndMetadata(i + 6, j + 20, k + 15, Block.stoneSingleSlab.blockID, 2);
		world.setBlockAndMetadata(i + 6, j + 20, k + 16, Block.stoneSingleSlab.blockID, 2);
		world.setBlockAndMetadata(i + 6, j + 20, k + 17, Block.stoneSingleSlab.blockID, 2);
		world.setBlockAndMetadata(i + 6, j + 20, k + 18, Block.stoneSingleSlab.blockID, 2);
		world.setBlock(i + 6, j + 20, k + 19, Block.cloth.blockID);
		world.setBlock(i + 6, j + 20, k + 20, Block.cloth.blockID);
		world.setBlock(i + 6, j + 20, k + 21, Block.cloth.blockID);
		world.setBlock(i + 6, j + 21, k + 1, Block.cloth.blockID);
		world.setBlock(i + 6, j + 21, k + 2, Block.netherFence.blockID);
		world.setBlock(i + 6, j + 21, k + 3, Block.netherFence.blockID);
		world.setBlock(i + 6, j + 21, k + 19, Block.netherFence.blockID);
		world.setBlock(i + 6, j + 21, k + 20, Block.netherFence.blockID);
		world.setBlock(i + 6, j + 21, k + 21, Block.cloth.blockID);
		world.setBlockAndMetadata(i + 7, j + 11, k + 2, Block.cloth.blockID, 15);
		world.setBlockAndMetadata(i + 7, j + 11, k + 3, Block.cloth.blockID, 15);
		world.setBlockAndMetadata(i + 7, j + 11, k + 4, Block.cloth.blockID, 15);
		world.setBlockAndMetadata(i + 7, j + 11, k + 5, Block.cloth.blockID, 15);
		world.setBlockAndMetadata(i + 7, j + 11, k + 6, Block.cloth.blockID, 15);
		world.setBlockAndMetadata(i + 7, j + 11, k + 7, Block.cloth.blockID, 15);
		world.setBlockAndMetadata(i + 7, j + 11, k + 8, Block.cloth.blockID, 15);
		world.setBlockAndMetadata(i + 7, j + 11, k + 9, Block.cloth.blockID, 15);
		world.setBlockAndMetadata(i + 7, j + 11, k + 10, Block.cloth.blockID, 15);
		world.setBlockAndMetadata(i + 7, j + 11, k + 11, Block.cloth.blockID, 15);
		world.setBlockAndMetadata(i + 7, j + 11, k + 12, Block.cloth.blockID, 15);
		world.setBlockAndMetadata(i + 7, j + 11, k + 13, Block.cloth.blockID, 15);
		world.setBlockAndMetadata(i + 7, j + 11, k + 14, Block.cloth.blockID, 15);
		world.setBlockAndMetadata(i + 7, j + 11, k + 15, Block.cloth.blockID, 15);
		world.setBlockAndMetadata(i + 7, j + 11, k + 16, Block.cloth.blockID, 15);
		world.setBlockAndMetadata(i + 7, j + 11, k + 17, Block.cloth.blockID, 15);
		world.setBlockAndMetadata(i + 7, j + 11, k + 18, Block.cloth.blockID, 15);
		world.setBlockAndMetadata(i + 7, j + 11, k + 19, Block.cloth.blockID, 15);
		world.setBlockAndMetadata(i + 7, j + 11, k + 20, Block.cloth.blockID, 15);
		world.setBlockAndMetadata(i + 7, j + 12, k + 1, Block.cloth.blockID, 15);
		world.setBlockAndMetadata(i + 7, j + 12, k + 2, Block.cloth.blockID, 15);
		world.setBlockAndMetadata(i + 7, j + 12, k + 3, Block.cloth.blockID, 15);
		world.setBlockAndMetadata(i + 7, j + 12, k + 4, Block.cloth.blockID, 15);
		world.setBlockAndMetadata(i + 7, j + 12, k + 5, Block.cloth.blockID, 15);
		world.setBlockAndMetadata(i + 7, j + 12, k + 6, Block.cloth.blockID, 15);
		world.setBlockAndMetadata(i + 7, j + 12, k + 7, Block.cloth.blockID, 15);
		world.setBlockAndMetadata(i + 7, j + 12, k + 8, Block.cloth.blockID, 15);
		world.setBlockAndMetadata(i + 7, j + 12, k + 9, Block.cloth.blockID, 15);
		world.setBlockAndMetadata(i + 7, j + 12, k + 10, Block.cloth.blockID, 15);
		world.setBlockAndMetadata(i + 7, j + 12, k + 11, Block.cloth.blockID, 15);
		world.setBlockAndMetadata(i + 7, j + 12, k + 12, Block.cloth.blockID, 15);
		world.setBlockAndMetadata(i + 7, j + 12, k + 13, Block.cloth.blockID, 15);
		world.setBlockAndMetadata(i + 7, j + 12, k + 14, Block.cloth.blockID, 15);
		world.setBlockAndMetadata(i + 7, j + 12, k + 15, Block.cloth.blockID, 15);
		world.setBlockAndMetadata(i + 7, j + 12, k + 16, Block.cloth.blockID, 15);
		world.setBlockAndMetadata(i + 7, j + 12, k + 17, Block.cloth.blockID, 15);
		world.setBlockAndMetadata(i + 7, j + 12, k + 18, Block.cloth.blockID, 15);
		world.setBlockAndMetadata(i + 7, j + 12, k + 19, Block.cloth.blockID, 15);
		world.setBlockAndMetadata(i + 7, j + 12, k + 20, Block.cloth.blockID, 15);
		world.setBlockAndMetadata(i + 7, j + 12, k + 21, Block.cloth.blockID, 15);
		world.setBlockAndMetadata(i + 7, j + 13, k + 1, Block.cloth.blockID, 15);
		world.setBlockAndMetadata(i + 7, j + 13, k + 2, Block.cloth.blockID, 15);
		world.setBlockAndMetadata(i + 7, j + 13, k + 3, Block.cloth.blockID, 15);
		world.setBlockAndMetadata(i + 7, j + 13, k + 4, Block.cloth.blockID, 15);
		world.setBlockAndMetadata(i + 7, j + 13, k + 5, Block.cloth.blockID, 15);
		world.setBlockAndMetadata(i + 7, j + 13, k + 9, Block.cloth.blockID, 15);
		world.setBlockAndMetadata(i + 7, j + 13, k + 13, Block.cloth.blockID, 15);
		world.setBlockAndMetadata(i + 7, j + 13, k + 17, Block.cloth.blockID, 15);
		world.setBlockAndMetadata(i + 7, j + 13, k + 18, Block.cloth.blockID, 15);
		world.setBlockAndMetadata(i + 7, j + 13, k + 19, Block.cloth.blockID, 15);
		world.setBlockAndMetadata(i + 7, j + 13, k + 20, Block.cloth.blockID, 15);
		world.setBlockAndMetadata(i + 7, j + 13, k + 21, Block.cloth.blockID, 15);
		world.setBlockAndMetadata(i + 7, j + 14, k + 1, Block.cloth.blockID, 15);
		world.setBlock(i + 7, j + 14, k + 2, Block.planks.blockID);
		world.setBlock(i + 7, j + 14, k + 3, Block.planks.blockID);
		world.setBlock(i + 7, j + 14, k + 4, Block.planks.blockID);
		world.setBlock(i + 7, j + 14, k + 5, Block.planks.blockID);
		world.setBlock(i + 7, j + 14, k + 6, Block.planks.blockID);
		world.setBlock(i + 7, j + 14, k + 7, Block.planks.blockID);
		world.setBlock(i + 7, j + 14, k + 8, Block.planks.blockID);
		world.setBlock(i + 7, j + 14, k + 9, Block.planks.blockID);
		world.setBlock(i + 7, j + 14, k + 10, Block.planks.blockID);
		world.setBlock(i + 7, j + 14, k + 11, Block.planks.blockID);
		world.setBlock(i + 7, j + 14, k + 12, Block.planks.blockID);
		world.setBlock(i + 7, j + 14, k + 13, Block.planks.blockID);
		world.setBlock(i + 7, j + 14, k + 14, Block.planks.blockID);
		world.setBlock(i + 7, j + 14, k + 15, Block.planks.blockID);
		world.setBlock(i + 7, j + 14, k + 16, Block.planks.blockID);
		world.setBlock(i + 7, j + 14, k + 17, Block.planks.blockID);
		world.setBlock(i + 7, j + 14, k + 18, Block.planks.blockID);
		world.setBlock(i + 7, j + 14, k + 19, Block.planks.blockID);
		world.setBlock(i + 7, j + 14, k + 20, Block.planks.blockID);
		world.setBlockAndMetadata(i + 7, j + 14, k + 21, Block.cloth.blockID, 15);
		world.setBlockAndMetadata(i + 7, j + 15, k + 1, Block.cloth.blockID, 15);
		world.setBlock(i + 7, j + 15, k + 2, Block.bookShelf.blockID);
		world.setBlock(i + 7, j + 15, k + 3, Block.bookShelf.blockID);
		world.setBlock(i + 7, j + 15, k + 4, Block.bookShelf.blockID);
		world.setBlock(i + 7, j + 15, k + 18, Block.workbench.blockID);
		world.setBlockAndMetadata(i + 7, j + 15, k + 20, Block.wood.blockID, 1);
		world.setBlockAndMetadata(i + 7, j + 15, k + 21, Block.cloth.blockID, 15);
		world.setBlockAndMetadata(i + 7, j + 16, k + 1, Block.cloth.blockID, 4);
		world.setBlock(i + 7, j + 16, k + 2, Block.bookShelf.blockID);
		world.setBlock(i + 7, j + 16, k + 3, Block.bookShelf.blockID);
		world.setBlock(i + 7, j + 16, k + 4, Block.bookShelf.blockID);
		world.setBlockAndMetadata(i + 7, j + 16, k + 20, Block.wood.blockID, 1);
		world.setBlockAndMetadata(i + 7, j + 16, k + 21, Block.cloth.blockID, 4);
		world.setBlockAndMetadata(i + 7, j + 17, k + 1, Block.cloth.blockID, 15);
		world.setBlockAndMetadata(i + 7, j + 17, k + 20, Block.stoneSingleSlab.blockID, 2);
		world.setBlockAndMetadata(i + 7, j + 17, k + 21, Block.cloth.blockID, 15);
		world.setBlockAndMetadata(i + 7, j + 18, k + 1, Block.cloth.blockID, 15);
		world.setBlockAndMetadata(i + 7, j + 18, k + 21, Block.cloth.blockID, 15);
		world.setBlockAndMetadata(i + 7, j + 19, k + 1, Block.cloth.blockID, 15);
		world.setBlockAndMetadata(i + 7, j + 19, k + 21, Block.cloth.blockID, 15);
		world.setBlock(i + 7, j + 20, k + 1, Block.cloth.blockID);
		world.setBlockAndMetadata(i + 7, j + 20, k + 2, Block.stoneSingleSlab.blockID, 2);
		world.setBlockAndMetadata(i + 7, j + 20, k + 3, Block.stoneSingleSlab.blockID, 2);
		world.setBlockAndMetadata(i + 7, j + 20, k + 4, Block.stoneSingleSlab.blockID, 2);
		world.setBlockAndMetadata(i + 7, j + 20, k + 5, Block.stoneSingleSlab.blockID, 2);
		world.setBlockAndMetadata(i + 7, j + 20, k + 6, Block.stoneSingleSlab.blockID, 2);
		world.setBlockAndMetadata(i + 7, j + 20, k + 7, Block.stoneSingleSlab.blockID, 2);
		world.setBlockAndMetadata(i + 7, j + 20, k + 8, Block.stoneSingleSlab.blockID, 2);
		world.setBlockAndMetadata(i + 7, j + 20, k + 9, Block.stoneSingleSlab.blockID, 2);
		world.setBlockAndMetadata(i + 7, j + 20, k + 10, Block.stoneSingleSlab.blockID, 2);
		world.setBlockAndMetadata(i + 7, j + 20, k + 11, Block.stoneSingleSlab.blockID, 2);
		world.setBlockAndMetadata(i + 7, j + 20, k + 12, Block.stoneSingleSlab.blockID, 2);
		world.setBlockAndMetadata(i + 7, j + 20, k + 13, Block.stoneSingleSlab.blockID, 2);
		world.setBlockAndMetadata(i + 7, j + 20, k + 14, Block.stoneSingleSlab.blockID, 2);
		world.setBlockAndMetadata(i + 7, j + 20, k + 15, Block.stoneSingleSlab.blockID, 2);
		world.setBlockAndMetadata(i + 7, j + 20, k + 16, Block.stoneSingleSlab.blockID, 2);
		world.setBlockAndMetadata(i + 7, j + 20, k + 17, Block.stoneSingleSlab.blockID, 2);
		world.setBlockAndMetadata(i + 7, j + 20, k + 18, Block.stoneSingleSlab.blockID, 2);
		world.setBlockAndMetadata(i + 7, j + 20, k + 19, Block.stoneSingleSlab.blockID, 2);
		world.setBlockAndMetadata(i + 7, j + 20, k + 20, Block.stoneSingleSlab.blockID, 2);
		world.setBlock(i + 7, j + 20, k + 21, Block.cloth.blockID);
		world.setBlock(i + 7, j + 21, k + 1, Block.netherFence.blockID);
		world.setBlock(i + 7, j + 21, k + 21, Block.netherFence.blockID);
		world.setBlockAndMetadata(i + 8, j + 10, k + 1, Block.cloth.blockID, 15);
		world.setBlockAndMetadata(i + 8, j + 10, k + 2, Block.cloth.blockID, 15);
		world.setBlockAndMetadata(i + 8, j + 10, k + 3, Block.cloth.blockID, 15);
		world.setBlockAndMetadata(i + 8, j + 10, k + 4, Block.cloth.blockID, 15);
		world.setBlockAndMetadata(i + 8, j + 10, k + 5, Block.cloth.blockID, 15);
		world.setBlockAndMetadata(i + 8, j + 10, k + 6, Block.cloth.blockID, 15);
		world.setBlockAndMetadata(i + 8, j + 10, k + 7, Block.cloth.blockID, 15);
		world.setBlockAndMetadata(i + 8, j + 10, k + 8, Block.cloth.blockID, 15);
		world.setBlockAndMetadata(i + 8, j + 10, k + 9, Block.cloth.blockID, 15);
		world.setBlockAndMetadata(i + 8, j + 10, k + 10, Block.cloth.blockID, 15);
		world.setBlockAndMetadata(i + 8, j + 10, k + 11, Block.cloth.blockID, 15);
		world.setBlockAndMetadata(i + 8, j + 10, k + 12, Block.cloth.blockID, 15);
		world.setBlockAndMetadata(i + 8, j + 10, k + 13, Block.cloth.blockID, 15);
		world.setBlockAndMetadata(i + 8, j + 10, k + 14, Block.cloth.blockID, 15);
		world.setBlockAndMetadata(i + 8, j + 10, k + 15, Block.cloth.blockID, 15);
		world.setBlockAndMetadata(i + 8, j + 10, k + 16, Block.cloth.blockID, 15);
		world.setBlockAndMetadata(i + 8, j + 10, k + 17, Block.cloth.blockID, 15);
		world.setBlockAndMetadata(i + 8, j + 10, k + 18, Block.cloth.blockID, 15);
		world.setBlockAndMetadata(i + 8, j + 10, k + 19, Block.cloth.blockID, 15);
		world.setBlockAndMetadata(i + 8, j + 10, k + 20, Block.cloth.blockID, 15);
		world.setBlockAndMetadata(i + 8, j + 10, k + 21, Block.cloth.blockID, 15);
		world.setBlockAndMetadata(i + 8, j + 11, k + 1, Block.cloth.blockID, 15);
		world.setBlock(i + 8, j + 11, k + 2, Block.planks.blockID);
		world.setBlock(i + 8, j + 11, k + 3, Block.planks.blockID);
		world.setBlock(i + 8, j + 11, k + 4, Block.planks.blockID);
		world.setBlock(i + 8, j + 11, k + 5, Block.planks.blockID);
		world.setBlock(i + 8, j + 11, k + 6, Block.planks.blockID);
		world.setBlock(i + 8, j + 11, k + 7, Block.planks.blockID);
		world.setBlock(i + 8, j + 11, k + 8, Block.planks.blockID);
		world.setBlock(i + 8, j + 11, k + 9, Block.planks.blockID);
		world.setBlock(i + 8, j + 11, k + 10, Block.planks.blockID);
		world.setBlock(i + 8, j + 11, k + 11, Block.planks.blockID);
		world.setBlock(i + 8, j + 11, k + 12, Block.planks.blockID);
		world.setBlock(i + 8, j + 11, k + 13, Block.planks.blockID);
		world.setBlock(i + 8, j + 11, k + 14, Block.planks.blockID);
		world.setBlock(i + 8, j + 11, k + 15, Block.planks.blockID);
		world.setBlock(i + 8, j + 11, k + 16, Block.planks.blockID);
		world.setBlock(i + 8, j + 11, k + 17, Block.planks.blockID);
		world.setBlock(i + 8, j + 11, k + 18, Block.planks.blockID);
		world.setBlock(i + 8, j + 11, k + 19, Block.planks.blockID);
		world.setBlock(i + 8, j + 11, k + 20, Block.planks.blockID);
		world.setBlockAndMetadata(i + 8, j + 11, k + 21, Block.cloth.blockID, 15);
		world.setBlockAndMetadata(i + 8, j + 12, k + 1, Block.cloth.blockID, 15);
		world.setBlock(i + 8, j + 12, k + 2, Block.bookShelf.blockID);
		world.setBlock(i + 8, j + 12, k + 3, Block.bookShelf.blockID);
		world.setBlock(i + 8, j + 12, k + 4, Block.bookShelf.blockID);
		world.setBlock(i + 8, j + 12, k + 5, Block.bookShelf.blockID);
		world.setBlock(i + 8, j + 12, k + 17, Block.bookShelf.blockID);
		world.setBlock(i + 8, j + 12, k + 18, Block.bookShelf.blockID);
		world.setBlock(i + 8, j + 12, k + 19, Block.bookShelf.blockID);
		world.setBlock(i + 8, j + 12, k + 20, Block.bookShelf.blockID);
		world.setBlockAndMetadata(i + 8, j + 12, k + 21, Block.cloth.blockID, 15);
		world.setBlockAndMetadata(i + 8, j + 13, k + 1, Block.cloth.blockID, 15);
		world.setBlock(i + 8, j + 13, k + 2, Block.bookShelf.blockID);
		world.setBlock(i + 8, j + 13, k + 3, Block.bookShelf.blockID);
		world.setBlock(i + 8, j + 13, k + 4, Block.bookShelf.blockID);
		world.setBlock(i + 8, j + 13, k + 5, Block.bookShelf.blockID);
		world.setBlock(i + 8, j + 13, k + 17, Block.bookShelf.blockID);
		world.setBlock(i + 8, j + 13, k + 18, Block.bookShelf.blockID);
		world.setBlock(i + 8, j + 13, k + 19, Block.bookShelf.blockID);
		world.setBlock(i + 8, j + 13, k + 20, Block.bookShelf.blockID);
		world.setBlockAndMetadata(i + 8, j + 13, k + 21, Block.cloth.blockID, 15);
		world.setBlockAndMetadata(i + 8, j + 14, k + 1, Block.cloth.blockID, 15);
		world.setBlockAndMetadata(i + 8, j + 14, k + 2, Block.stoneSingleSlab.blockID, 10);
		world.setBlockAndMetadata(i + 8, j + 14, k + 3, Block.stoneSingleSlab.blockID, 10);
		world.setBlockAndMetadata(i + 8, j + 14, k + 4, Block.stoneSingleSlab.blockID, 10);
		world.setBlockAndMetadata(i + 8, j + 14, k + 5, Block.stoneSingleSlab.blockID, 10);
		world.setBlockAndMetadata(i + 8, j + 14, k + 6, Block.stoneSingleSlab.blockID, 10);
		world.setBlockAndMetadata(i + 8, j + 14, k + 7, Block.stoneSingleSlab.blockID, 10);
		world.setBlockAndMetadata(i + 8, j + 14, k + 8, Block.stoneSingleSlab.blockID, 10);
		world.setBlockAndMetadata(i + 8, j + 14, k + 9, Block.stoneSingleSlab.blockID, 10);
		world.setBlockAndMetadata(i + 8, j + 14, k + 10, Block.stoneSingleSlab.blockID, 10);
		world.setBlockAndMetadata(i + 8, j + 14, k + 11, Block.stoneSingleSlab.blockID, 10);
		world.setBlockAndMetadata(i + 8, j + 14, k + 12, Block.stoneSingleSlab.blockID, 10);
		world.setBlockAndMetadata(i + 8, j + 14, k + 13, Block.stoneSingleSlab.blockID, 10);
		world.setBlockAndMetadata(i + 8, j + 14, k + 14, Block.stoneSingleSlab.blockID, 10);
		world.setBlockAndMetadata(i + 8, j + 14, k + 15, Block.stoneSingleSlab.blockID, 10);
		world.setBlockAndMetadata(i + 8, j + 14, k + 16, Block.stoneSingleSlab.blockID, 10);
		world.setBlockAndMetadata(i + 8, j + 14, k + 17, Block.stoneSingleSlab.blockID, 10);
		world.setBlockAndMetadata(i + 8, j + 14, k + 18, Block.stoneSingleSlab.blockID, 10);
		world.setBlock(i + 8, j + 14, k + 19, Block.planks.blockID);
		world.setBlockAndMetadata(i + 8, j + 14, k + 20, Block.stoneSingleSlab.blockID, 10);
		world.setBlockAndMetadata(i + 8, j + 14, k + 21, Block.cloth.blockID, 15);
		world.setBlockAndMetadata(i + 8, j + 15, k + 1, Block.cloth.blockID, 15);
		world.setBlock(i + 8, j + 15, k + 2, Block.bookShelf.blockID);
		world.setBlockAndMetadata(i + 8, j + 15, k + 20, Block.chest.blockID, 2);
		world.setBlockAndMetadata(i + 8, j + 15, k + 21, Block.cloth.blockID, 15);
		world.setBlockAndMetadata(i + 8, j + 16, k + 1, Block.cloth.blockID, 4);
		world.setBlock(i + 8, j + 16, k + 2, Block.bookShelf.blockID);
		world.setBlockAndMetadata(i + 8, j + 16, k + 20, Block.chest.blockID, 2);
		world.setBlockAndMetadata(i + 8, j + 16, k + 21, Block.cloth.blockID, 4);
		world.setBlockAndMetadata(i + 8, j + 17, k + 1, Block.cloth.blockID, 15);
		world.setBlockAndMetadata(i + 8, j + 17, k + 20, Block.stoneSingleSlab.blockID, 2);
		world.setBlockAndMetadata(i + 8, j + 17, k + 21, Block.cloth.blockID, 15);
		world.setBlockAndMetadata(i + 8, j + 18, k + 1, Block.cloth.blockID, 15);
		world.setBlockAndMetadata(i + 8, j + 18, k + 21, Block.cloth.blockID, 15);
		world.setBlockAndMetadata(i + 8, j + 19, k + 1, Block.cloth.blockID, 15);
		world.setBlockAndMetadata(i + 8, j + 19, k + 21, Block.cloth.blockID, 15);
		world.setBlock(i + 8, j + 20, k + 1, Block.cloth.blockID);
		world.setBlockAndMetadata(i + 8, j + 20, k + 2, Block.stoneSingleSlab.blockID, 2);
		world.setBlockAndMetadata(i + 8, j + 20, k + 3, Block.stoneSingleSlab.blockID, 2);
		world.setBlockAndMetadata(i + 8, j + 20, k + 4, Block.stoneSingleSlab.blockID, 2);
		world.setBlockAndMetadata(i + 8, j + 20, k + 5, Block.stoneSingleSlab.blockID, 2);
		world.setBlockAndMetadata(i + 8, j + 20, k + 6, Block.stoneSingleSlab.blockID, 2);
		world.setBlockAndMetadata(i + 8, j + 20, k + 7, Block.stoneSingleSlab.blockID, 2);
		world.setBlockAndMetadata(i + 8, j + 20, k + 8, Block.stoneSingleSlab.blockID, 2);
		world.setBlockAndMetadata(i + 8, j + 20, k + 9, Block.stoneSingleSlab.blockID, 2);
		world.setBlockAndMetadata(i + 8, j + 20, k + 10, Block.stoneSingleSlab.blockID, 2);
		world.setBlockAndMetadata(i + 8, j + 20, k + 11, Block.stoneSingleSlab.blockID, 2);
		world.setBlockAndMetadata(i + 8, j + 20, k + 12, Block.stoneSingleSlab.blockID, 2);
		world.setBlockAndMetadata(i + 8, j + 20, k + 13, Block.stoneSingleSlab.blockID, 2);
		world.setBlockAndMetadata(i + 8, j + 20, k + 14, Block.stoneSingleSlab.blockID, 2);
		world.setBlockAndMetadata(i + 8, j + 20, k + 15, Block.stoneSingleSlab.blockID, 2);
		world.setBlockAndMetadata(i + 8, j + 20, k + 16, Block.stoneSingleSlab.blockID, 2);
		world.setBlockAndMetadata(i + 8, j + 20, k + 17, Block.stoneSingleSlab.blockID, 2);
		world.setBlockAndMetadata(i + 8, j + 20, k + 18, Block.stoneSingleSlab.blockID, 2);
		world.setBlockAndMetadata(i + 8, j + 20, k + 19, Block.stoneSingleSlab.blockID, 2);
		world.setBlockAndMetadata(i + 8, j + 20, k + 20, Block.stoneSingleSlab.blockID, 2);
		world.setBlock(i + 8, j + 20, k + 21, Block.cloth.blockID);
		world.setBlock(i + 8, j + 21, k + 1, Block.netherFence.blockID);
		world.setBlock(i + 8, j + 21, k + 21, Block.netherFence.blockID);
		world.setBlockAndMetadata(i + 9, j + 9, k + 2, Block.cloth.blockID, 15);
		world.setBlockAndMetadata(i + 9, j + 9, k + 3, Block.cloth.blockID, 15);
		world.setBlockAndMetadata(i + 9, j + 9, k + 4, Block.cloth.blockID, 15);
		world.setBlockAndMetadata(i + 9, j + 9, k + 5, Block.cloth.blockID, 15);
		world.setBlockAndMetadata(i + 9, j + 9, k + 6, Block.cloth.blockID, 15);
		world.setBlockAndMetadata(i + 9, j + 9, k + 7, Block.cloth.blockID, 15);
		world.setBlockAndMetadata(i + 9, j + 9, k + 8, Block.cloth.blockID, 15);
		world.setBlockAndMetadata(i + 9, j + 9, k + 9, Block.cloth.blockID, 15);
		world.setBlockAndMetadata(i + 9, j + 9, k + 10, Block.cloth.blockID, 15);
		world.setBlockAndMetadata(i + 9, j + 9, k + 11, Block.cloth.blockID, 15);
		world.setBlockAndMetadata(i + 9, j + 9, k + 12, Block.cloth.blockID, 15);
		world.setBlockAndMetadata(i + 9, j + 9, k + 13, Block.cloth.blockID, 15);
		world.setBlockAndMetadata(i + 9, j + 9, k + 14, Block.cloth.blockID, 15);
		world.setBlockAndMetadata(i + 9, j + 9, k + 15, Block.cloth.blockID, 15);
		world.setBlockAndMetadata(i + 9, j + 9, k + 16, Block.cloth.blockID, 15);
		world.setBlockAndMetadata(i + 9, j + 9, k + 17, Block.cloth.blockID, 15);
		world.setBlockAndMetadata(i + 9, j + 9, k + 18, Block.cloth.blockID, 15);
		world.setBlockAndMetadata(i + 9, j + 9, k + 19, Block.cloth.blockID, 15);
		world.setBlockAndMetadata(i + 9, j + 9, k + 20, Block.cloth.blockID, 15);
		world.setBlockAndMetadata(i + 9, j + 10, k + 1, Block.cloth.blockID, 15);
		world.setBlockAndMetadata(i + 9, j + 10, k + 2, Block.cloth.blockID, 15);
		world.setBlockAndMetadata(i + 9, j + 10, k + 3, Block.cloth.blockID, 15);
		world.setBlockAndMetadata(i + 9, j + 10, k + 4, Block.cloth.blockID, 15);
		world.setBlockAndMetadata(i + 9, j + 10, k + 5, Block.cloth.blockID, 15);
		world.setBlockAndMetadata(i + 9, j + 10, k + 6, Block.cloth.blockID, 15);
		world.setBlockAndMetadata(i + 9, j + 10, k + 7, Block.cloth.blockID, 15);
		world.setBlockAndMetadata(i + 9, j + 10, k + 8, Block.cloth.blockID, 15);
		world.setBlockAndMetadata(i + 9, j + 10, k + 9, Block.cloth.blockID, 15);
		world.setBlockAndMetadata(i + 9, j + 10, k + 10, Block.cloth.blockID, 15);
		world.setBlockAndMetadata(i + 9, j + 10, k + 11, Block.cloth.blockID, 15);
		world.setBlockAndMetadata(i + 9, j + 10, k + 12, Block.cloth.blockID, 15);
		world.setBlockAndMetadata(i + 9, j + 10, k + 13, Block.cloth.blockID, 15);
		world.setBlockAndMetadata(i + 9, j + 10, k + 14, Block.cloth.blockID, 15);
		world.setBlockAndMetadata(i + 9, j + 10, k + 15, Block.cloth.blockID, 15);
		world.setBlockAndMetadata(i + 9, j + 10, k + 16, Block.cloth.blockID, 15);
		world.setBlockAndMetadata(i + 9, j + 10, k + 17, Block.cloth.blockID, 15);
		world.setBlockAndMetadata(i + 9, j + 10, k + 18, Block.cloth.blockID, 15);
		world.setBlockAndMetadata(i + 9, j + 10, k + 19, Block.cloth.blockID, 15);
		world.setBlockAndMetadata(i + 9, j + 10, k + 20, Block.cloth.blockID, 15);
		world.setBlockAndMetadata(i + 9, j + 10, k + 21, Block.cloth.blockID, 15);
		world.setBlockAndMetadata(i + 9, j + 11, k + 1, Block.cloth.blockID, 15);
		world.setBlock(i + 9, j + 11, k + 2, Block.planks.blockID);
		world.setBlock(i + 9, j + 11, k + 3, Block.planks.blockID);
		world.setBlock(i + 9, j + 11, k + 4, Block.planks.blockID);
		world.setBlock(i + 9, j + 11, k + 5, Block.planks.blockID);
		world.setBlock(i + 9, j + 11, k + 6, Block.planks.blockID);
		world.setBlock(i + 9, j + 11, k + 7, Block.planks.blockID);
		world.setBlock(i + 9, j + 11, k + 8, Block.planks.blockID);
		world.setBlock(i + 9, j + 11, k + 9, Block.planks.blockID);
		world.setBlock(i + 9, j + 11, k + 10, Block.planks.blockID);
		world.setBlock(i + 9, j + 11, k + 11, Block.planks.blockID);
		world.setBlock(i + 9, j + 11, k + 12, Block.planks.blockID);
		world.setBlock(i + 9, j + 11, k + 13, Block.planks.blockID);
		world.setBlock(i + 9, j + 11, k + 14, Block.planks.blockID);
		world.setBlock(i + 9, j + 11, k + 15, Block.planks.blockID);
		world.setBlock(i + 9, j + 11, k + 16, Block.planks.blockID);
		world.setBlock(i + 9, j + 11, k + 17, Block.planks.blockID);
		world.setBlock(i + 9, j + 11, k + 18, Block.planks.blockID);
		world.setBlock(i + 9, j + 11, k + 19, Block.planks.blockID);
		world.setBlock(i + 9, j + 11, k + 20, Block.planks.blockID);
		world.setBlockAndMetadata(i + 9, j + 11, k + 21, Block.cloth.blockID, 15);
		world.setBlockAndMetadata(i + 9, j + 12, k + 1, Block.cloth.blockID, 15);
		world.setBlockAndMetadata(i + 9, j + 12, k + 21, Block.cloth.blockID, 15);
		world.setBlockAndMetadata(i + 9, j + 13, k + 1, Block.cloth.blockID, 15);
		world.setBlockAndMetadata(i + 9, j + 13, k + 21, Block.cloth.blockID, 15);
		world.setBlockAndMetadata(i + 9, j + 14, k + 1, Block.cloth.blockID, 15);
		world.setBlockAndMetadata(i + 9, j + 14, k + 2, Block.stoneSingleSlab.blockID, 10);
		world.setBlockAndMetadata(i + 9, j + 14, k + 3, Block.stoneSingleSlab.blockID, 10);
		world.setBlockAndMetadata(i + 9, j + 14, k + 4, Block.stoneSingleSlab.blockID, 10);
		world.setBlockAndMetadata(i + 9, j + 14, k + 5, Block.stoneSingleSlab.blockID, 10);
		world.setBlockAndMetadata(i + 9, j + 14, k + 6, Block.stoneSingleSlab.blockID, 10);
		world.setBlockAndMetadata(i + 9, j + 14, k + 7, Block.stoneSingleSlab.blockID, 10);
		world.setBlockAndMetadata(i + 9, j + 14, k + 8, Block.stoneSingleSlab.blockID, 10);
		world.setBlockAndMetadata(i + 9, j + 14, k + 9, Block.stoneSingleSlab.blockID, 10);
		world.setBlockAndMetadata(i + 9, j + 14, k + 10, Block.stoneSingleSlab.blockID, 10);
		world.setBlockAndMetadata(i + 9, j + 14, k + 11, Block.stoneSingleSlab.blockID, 10);
		world.setBlockAndMetadata(i + 9, j + 14, k + 12, Block.stoneSingleSlab.blockID, 10);
		world.setBlockAndMetadata(i + 9, j + 14, k + 13, Block.stoneSingleSlab.blockID, 10);
		world.setBlockAndMetadata(i + 9, j + 14, k + 14, Block.stoneSingleSlab.blockID, 10);
		world.setBlockAndMetadata(i + 9, j + 14, k + 15, Block.stoneSingleSlab.blockID, 10);
		world.setBlockAndMetadata(i + 9, j + 14, k + 16, Block.stoneSingleSlab.blockID, 10);
		world.setBlockAndMetadata(i + 9, j + 14, k + 17, Block.stoneSingleSlab.blockID, 10);
		world.setBlockAndMetadata(i + 9, j + 14, k + 18, Block.stoneSingleSlab.blockID, 10);
		world.setBlock(i + 9, j + 14, k + 19, Block.planks.blockID);
		world.setBlockAndMetadata(i + 9, j + 14, k + 20, Block.stoneSingleSlab.blockID, 10);
		world.setBlockAndMetadata(i + 9, j + 14, k + 21, Block.cloth.blockID, 15);
		world.setBlockAndMetadata(i + 9, j + 15, k + 1, Block.cloth.blockID, 15);
		world.setBlock(i + 9, j + 15, k + 2, Block.bookShelf.blockID);
		world.setBlockAndMetadata(i + 9, j + 15, k + 9, Block.wood.blockID, 1);
		world.setBlockAndMetadata(i + 9, j + 15, k + 11, Block.stairsNetherBrick.blockID, 1);
		world.setBlockAndMetadata(i + 9, j + 15, k + 13, Block.wood.blockID, 1);
		world.setBlockAndMetadata(i + 9, j + 15, k + 20, Block.chest.blockID, 2);
		world.setBlockAndMetadata(i + 9, j + 15, k + 21, Block.cloth.blockID, 15);
		world.setBlockAndMetadata(i + 9, j + 16, k + 1, Block.cloth.blockID, 4);
		world.setBlock(i + 9, j + 16, k + 2, Block.bookShelf.blockID);
		world.setBlockAndMetadata(i + 9, j + 16, k + 20, Block.chest.blockID, 2);
		world.setBlockAndMetadata(i + 9, j + 16, k + 21, Block.cloth.blockID, 4);
		world.setBlockAndMetadata(i + 9, j + 17, k + 1, Block.cloth.blockID, 15);
		world.setBlockAndMetadata(i + 9, j + 17, k + 20, Block.stoneSingleSlab.blockID, 2);
		world.setBlockAndMetadata(i + 9, j + 17, k + 21, Block.cloth.blockID, 15);
		world.setBlockAndMetadata(i + 9, j + 18, k + 1, Block.cloth.blockID, 15);
		world.setBlockAndMetadata(i + 9, j + 18, k + 21, Block.cloth.blockID, 15);
		world.setBlockAndMetadata(i + 9, j + 19, k + 1, Block.cloth.blockID, 15);
		world.setBlockAndMetadata(i + 9, j + 19, k + 21, Block.cloth.blockID, 15);
		world.setBlock(i + 9, j + 20, k + 1, Block.cloth.blockID);
		world.setBlockAndMetadata(i + 9, j + 20, k + 2, Block.stoneSingleSlab.blockID, 2);
		world.setBlockAndMetadata(i + 9, j + 20, k + 3, Block.stoneSingleSlab.blockID, 2);
		world.setBlockAndMetadata(i + 9, j + 20, k + 4, Block.stoneSingleSlab.blockID, 2);
		world.setBlockAndMetadata(i + 9, j + 20, k + 5, Block.stoneSingleSlab.blockID, 2);
		world.setBlockAndMetadata(i + 9, j + 20, k + 6, Block.stoneSingleSlab.blockID, 2);
		world.setBlockAndMetadata(i + 9, j + 20, k + 7, Block.stoneSingleSlab.blockID, 2);
		world.setBlockAndMetadata(i + 9, j + 20, k + 8, Block.stoneSingleSlab.blockID, 2);
		world.setBlockAndMetadata(i + 9, j + 20, k + 9, Block.stoneSingleSlab.blockID, 2);
		world.setBlockAndMetadata(i + 9, j + 20, k + 10, Block.stoneSingleSlab.blockID, 2);
		world.setBlockAndMetadata(i + 9, j + 20, k + 11, Block.stoneSingleSlab.blockID, 2);
		world.setBlockAndMetadata(i + 9, j + 20, k + 12, Block.stoneSingleSlab.blockID, 2);
		world.setBlockAndMetadata(i + 9, j + 20, k + 13, Block.stoneSingleSlab.blockID, 2);
		world.setBlockAndMetadata(i + 9, j + 20, k + 14, Block.stoneSingleSlab.blockID, 2);
		world.setBlockAndMetadata(i + 9, j + 20, k + 15, Block.stoneSingleSlab.blockID, 2);
		world.setBlockAndMetadata(i + 9, j + 20, k + 16, Block.stoneSingleSlab.blockID, 2);
		world.setBlockAndMetadata(i + 9, j + 20, k + 17, Block.stoneSingleSlab.blockID, 2);
		world.setBlockAndMetadata(i + 9, j + 20, k + 18, Block.stoneSingleSlab.blockID, 2);
		world.setBlockAndMetadata(i + 9, j + 20, k + 19, Block.stoneSingleSlab.blockID, 2);
		world.setBlockAndMetadata(i + 9, j + 20, k + 20, Block.stoneSingleSlab.blockID, 2);
		world.setBlock(i + 9, j + 20, k + 21, Block.cloth.blockID);
		world.setBlock(i + 9, j + 21, k + 1, Block.netherFence.blockID);
		world.setBlock(i + 9, j + 21, k + 21, Block.netherFence.blockID);
		world.setBlockAndMetadata(i + 10, j + 9, k + 2, Block.cloth.blockID, 15);
		world.setBlockAndMetadata(i + 10, j + 9, k + 3, Block.cloth.blockID, 15);
		world.setBlockAndMetadata(i + 10, j + 9, k + 4, Block.cloth.blockID, 15);
		world.setBlockAndMetadata(i + 10, j + 9, k + 5, Block.cloth.blockID, 15);
		world.setBlockAndMetadata(i + 10, j + 9, k + 6, Block.cloth.blockID, 15);
		world.setBlockAndMetadata(i + 10, j + 9, k + 7, Block.cloth.blockID, 15);
		world.setBlockAndMetadata(i + 10, j + 9, k + 8, Block.cloth.blockID, 15);
		world.setBlockAndMetadata(i + 10, j + 9, k + 9, Block.cloth.blockID, 15);
		world.setBlockAndMetadata(i + 10, j + 9, k + 10, Block.cloth.blockID, 15);
		world.setBlockAndMetadata(i + 10, j + 9, k + 11, Block.cloth.blockID, 15);
		world.setBlockAndMetadata(i + 10, j + 9, k + 12, Block.cloth.blockID, 15);
		world.setBlockAndMetadata(i + 10, j + 9, k + 13, Block.cloth.blockID, 15);
		world.setBlockAndMetadata(i + 10, j + 9, k + 14, Block.cloth.blockID, 15);
		world.setBlockAndMetadata(i + 10, j + 9, k + 15, Block.cloth.blockID, 15);
		world.setBlockAndMetadata(i + 10, j + 9, k + 16, Block.cloth.blockID, 15);
		world.setBlockAndMetadata(i + 10, j + 9, k + 17, Block.cloth.blockID, 15);
		world.setBlockAndMetadata(i + 10, j + 9, k + 18, Block.cloth.blockID, 15);
		world.setBlockAndMetadata(i + 10, j + 9, k + 19, Block.cloth.blockID, 15);
		world.setBlockAndMetadata(i + 10, j + 9, k + 20, Block.cloth.blockID, 15);
		world.setBlockAndMetadata(i + 10, j + 10, k + 1, Block.cloth.blockID, 15);
		world.setBlockAndMetadata(i + 10, j + 10, k + 2, Block.cloth.blockID, 15);
		world.setBlockAndMetadata(i + 10, j + 10, k + 3, Block.cloth.blockID, 15);
		world.setBlockAndMetadata(i + 10, j + 10, k + 4, Block.cloth.blockID, 15);
		world.setBlockAndMetadata(i + 10, j + 10, k + 5, Block.cloth.blockID, 15);
		world.setBlockAndMetadata(i + 10, j + 10, k + 6, Block.cloth.blockID, 15);
		world.setBlockAndMetadata(i + 10, j + 10, k + 7, Block.cloth.blockID, 15);
		world.setBlockAndMetadata(i + 10, j + 10, k + 8, Block.cloth.blockID, 15);
		world.setBlockAndMetadata(i + 10, j + 10, k + 9, Block.cloth.blockID, 15);
		world.setBlockAndMetadata(i + 10, j + 10, k + 10, Block.cloth.blockID, 15);
		world.setBlockAndMetadata(i + 10, j + 10, k + 11, Block.cloth.blockID, 15);
		world.setBlockAndMetadata(i + 10, j + 10, k + 12, Block.cloth.blockID, 15);
		world.setBlockAndMetadata(i + 10, j + 10, k + 13, Block.cloth.blockID, 15);
		world.setBlockAndMetadata(i + 10, j + 10, k + 14, Block.cloth.blockID, 15);
		world.setBlockAndMetadata(i + 10, j + 10, k + 15, Block.cloth.blockID, 15);
		world.setBlockAndMetadata(i + 10, j + 10, k + 16, Block.cloth.blockID, 15);
		world.setBlockAndMetadata(i + 10, j + 10, k + 17, Block.cloth.blockID, 15);
		world.setBlockAndMetadata(i + 10, j + 10, k + 18, Block.cloth.blockID, 15);
		world.setBlockAndMetadata(i + 10, j + 10, k + 19, Block.cloth.blockID, 15);
		world.setBlockAndMetadata(i + 10, j + 10, k + 20, Block.cloth.blockID, 15);
		world.setBlockAndMetadata(i + 10, j + 10, k + 21, Block.cloth.blockID, 15);
		world.setBlockAndMetadata(i + 10, j + 11, k + 1, Block.cloth.blockID, 15);
		world.setBlock(i + 10, j + 11, k + 2, Block.planks.blockID);
		world.setBlock(i + 10, j + 11, k + 3, Block.planks.blockID);
		world.setBlock(i + 10, j + 11, k + 4, Block.planks.blockID);
		world.setBlock(i + 10, j + 11, k + 5, Block.planks.blockID);
		world.setBlock(i + 10, j + 11, k + 6, Block.planks.blockID);
		world.setBlock(i + 10, j + 11, k + 7, Block.planks.blockID);
		world.setBlock(i + 10, j + 11, k + 8, Block.planks.blockID);
		world.setBlock(i + 10, j + 11, k + 9, Block.planks.blockID);
		world.setBlock(i + 10, j + 11, k + 10, Block.planks.blockID);
		world.setBlock(i + 10, j + 11, k + 11, Block.planks.blockID);
		world.setBlock(i + 10, j + 11, k + 12, Block.planks.blockID);
		world.setBlock(i + 10, j + 11, k + 13, Block.planks.blockID);
		world.setBlock(i + 10, j + 11, k + 14, Block.planks.blockID);
		world.setBlock(i + 10, j + 11, k + 15, Block.planks.blockID);
		world.setBlock(i + 10, j + 11, k + 16, Block.planks.blockID);
		world.setBlock(i + 10, j + 11, k + 17, Block.planks.blockID);
		world.setBlock(i + 10, j + 11, k + 18, Block.planks.blockID);
		world.setBlock(i + 10, j + 11, k + 19, Block.planks.blockID);
		world.setBlock(i + 10, j + 11, k + 20, Block.planks.blockID);
		world.setBlockAndMetadata(i + 10, j + 11, k + 21, Block.cloth.blockID, 15);
		world.setBlockAndMetadata(i + 10, j + 12, k + 1, Block.cloth.blockID, 15);
		world.setBlockAndMetadata(i + 10, j + 12, k + 9, Block.stairsNetherBrick.blockID, 1);
		world.setBlockAndMetadata(i + 10, j + 12, k + 11, Block.stairsNetherBrick.blockID, 1);
		world.setBlockAndMetadata(i + 10, j + 12, k + 13, Block.stairsNetherBrick.blockID, 1);
		world.setBlockAndMetadata(i + 10, j + 12, k + 21, Block.cloth.blockID, 15);
		world.setBlockAndMetadata(i + 10, j + 13, k + 1, Block.cloth.blockID, 15);
		world.setBlockAndMetadata(i + 10, j + 13, k + 21, Block.cloth.blockID, 15);
		world.setBlockAndMetadata(i + 10, j + 14, k + 1, Block.cloth.blockID, 15);
		world.setBlockAndMetadata(i + 10, j + 14, k + 2, Block.stoneSingleSlab.blockID, 10);
		world.setBlockAndMetadata(i + 10, j + 14, k + 3, Block.stoneSingleSlab.blockID, 10);
		world.setBlockAndMetadata(i + 10, j + 14, k + 4, Block.stoneSingleSlab.blockID, 10);
		world.setBlockAndMetadata(i + 10, j + 14, k + 5, Block.stoneSingleSlab.blockID, 10);
		world.setBlockAndMetadata(i + 10, j + 14, k + 6, Block.stoneSingleSlab.blockID, 10);
		world.setBlockAndMetadata(i + 10, j + 14, k + 7, Block.stoneSingleSlab.blockID, 10);
		world.setBlockAndMetadata(i + 10, j + 14, k + 8, Block.stoneSingleSlab.blockID, 10);
		world.setBlockAndMetadata(i + 10, j + 14, k + 9, Block.stoneSingleSlab.blockID, 10);
		world.setBlockAndMetadata(i + 10, j + 14, k + 10, Block.stoneSingleSlab.blockID, 10);
		world.setBlockAndMetadata(i + 10, j + 14, k + 11, Block.stoneSingleSlab.blockID, 10);
		world.setBlockAndMetadata(i + 10, j + 14, k + 12, Block.stoneSingleSlab.blockID, 10);
		world.setBlockAndMetadata(i + 10, j + 14, k + 13, Block.stoneSingleSlab.blockID, 10);
		world.setBlockAndMetadata(i + 10, j + 14, k + 14, Block.stoneSingleSlab.blockID, 10);
		world.setBlockAndMetadata(i + 10, j + 14, k + 15, Block.stoneSingleSlab.blockID, 10);
		world.setBlockAndMetadata(i + 10, j + 14, k + 16, Block.stoneSingleSlab.blockID, 10);
		world.setBlockAndMetadata(i + 10, j + 14, k + 17, Block.stoneSingleSlab.blockID, 10);
		world.setBlockAndMetadata(i + 10, j + 14, k + 18, Block.stoneSingleSlab.blockID, 10);
		world.setBlockAndMetadata(i + 10, j + 14, k + 19, Block.stoneSingleSlab.blockID, 10);
		world.setBlockAndMetadata(i + 10, j + 14, k + 20, Block.stoneSingleSlab.blockID, 10);
		world.setBlockAndMetadata(i + 10, j + 14, k + 21, Block.cloth.blockID, 15);
		world.setBlockAndMetadata(i + 10, j + 15, k + 1, Block.cloth.blockID, 15);
		world.setBlock(i + 10, j + 15, k + 2, Block.bookShelf.blockID);
		world.setBlock(i + 10, j + 15, k + 3, Block.bookShelf.blockID);
		world.setBlock(i + 10, j + 15, k + 4, Block.bookShelf.blockID);
		world.setBlockAndMetadata(i + 10, j + 15, k + 9, Block.wood.blockID, 1);
		world.setBlockAndMetadata(i + 10, j + 15, k + 10, Block.wood.blockID, 1);
		world.setBlockAndMetadata(i + 10, j + 15, k + 11, Block.wood.blockID, 1);
		world.setBlockAndMetadata(i + 10, j + 15, k + 12, Block.wood.blockID, 1);
		world.setBlockAndMetadata(i + 10, j + 15, k + 13, Block.wood.blockID, 1);
		world.setBlockAndMetadata(i + 10, j + 15, k + 20, Block.wood.blockID, 1);
		world.setBlockAndMetadata(i + 10, j + 15, k + 21, Block.cloth.blockID, 15);
		world.setBlockAndMetadata(i + 10, j + 16, k + 1, Block.cloth.blockID, 4);
		world.setBlock(i + 10, j + 16, k + 2, Block.bookShelf.blockID);
		world.setBlock(i + 10, j + 16, k + 3, Block.bookShelf.blockID);
		world.setBlock(i + 10, j + 16, k + 4, Block.bookShelf.blockID);
		world.setBlockAndMetadata(i + 10, j + 16, k + 20, Block.wood.blockID, 1);
		world.setBlockAndMetadata(i + 10, j + 16, k + 21, Block.cloth.blockID, 4);
		world.setBlockAndMetadata(i + 10, j + 17, k + 1, Block.cloth.blockID, 15);
		world.setBlockAndMetadata(i + 10, j + 17, k + 20, Block.stoneSingleSlab.blockID, 2);
		world.setBlockAndMetadata(i + 10, j + 17, k + 21, Block.cloth.blockID, 15);
		world.setBlockAndMetadata(i + 10, j + 18, k + 1, Block.cloth.blockID, 15);
		world.setBlockAndMetadata(i + 10, j + 18, k + 21, Block.cloth.blockID, 15);
		world.setBlockAndMetadata(i + 10, j + 19, k + 1, Block.cloth.blockID, 15);
		world.setBlockAndMetadata(i + 10, j + 19, k + 21, Block.cloth.blockID, 15);
		world.setBlock(i + 10, j + 20, k + 1, Block.cloth.blockID);
		world.setBlockAndMetadata(i + 10, j + 20, k + 2, Block.stoneSingleSlab.blockID, 2);
		world.setBlockAndMetadata(i + 10, j + 20, k + 3, Block.stoneSingleSlab.blockID, 2);
		world.setBlockAndMetadata(i + 10, j + 20, k + 4, Block.stoneSingleSlab.blockID, 2);
		world.setBlockAndMetadata(i + 10, j + 20, k + 5, Block.stoneSingleSlab.blockID, 2);
		world.setBlockAndMetadata(i + 10, j + 20, k + 6, Block.stoneSingleSlab.blockID, 2);
		world.setBlockAndMetadata(i + 10, j + 20, k + 7, Block.stoneSingleSlab.blockID, 2);
		world.setBlockAndMetadata(i + 10, j + 20, k + 8, Block.stoneSingleSlab.blockID, 2);
		world.setBlockAndMetadata(i + 10, j + 20, k + 9, Block.stoneSingleSlab.blockID, 2);
		world.setBlockAndMetadata(i + 10, j + 20, k + 10, Block.stoneSingleSlab.blockID, 2);
		world.setBlockAndMetadata(i + 10, j + 20, k + 11, Block.stoneSingleSlab.blockID, 2);
		world.setBlockAndMetadata(i + 10, j + 20, k + 12, Block.stoneSingleSlab.blockID, 2);
		world.setBlockAndMetadata(i + 10, j + 20, k + 13, Block.stoneSingleSlab.blockID, 2);
		world.setBlockAndMetadata(i + 10, j + 20, k + 14, Block.stoneSingleSlab.blockID, 2);
		world.setBlockAndMetadata(i + 10, j + 20, k + 15, Block.stoneSingleSlab.blockID, 2);
		world.setBlockAndMetadata(i + 10, j + 20, k + 16, Block.stoneSingleSlab.blockID, 2);
		world.setBlockAndMetadata(i + 10, j + 20, k + 17, Block.stoneSingleSlab.blockID, 2);
		world.setBlockAndMetadata(i + 10, j + 20, k + 18, Block.stoneSingleSlab.blockID, 2);
		world.setBlockAndMetadata(i + 10, j + 20, k + 19, Block.stoneSingleSlab.blockID, 2);
		world.setBlockAndMetadata(i + 10, j + 20, k + 20, Block.stoneSingleSlab.blockID, 2);
		world.setBlock(i + 10, j + 20, k + 21, Block.cloth.blockID);
		world.setBlock(i + 10, j + 21, k + 1, Block.cloth.blockID);
		world.setBlock(i + 10, j + 21, k + 21, Block.cloth.blockID);
		world.setBlockAndMetadata(i + 11, j + 0, k + 11, Block.cloth.blockID, 15);
		world.setBlockAndMetadata(i + 11, j + 1, k + 11, Block.cloth.blockID, 15);
		world.setBlockAndMetadata(i + 11, j + 2, k + 11, Block.cloth.blockID, 15);
		world.setBlockAndMetadata(i + 11, j + 8, k + 2, Block.cloth.blockID, 15);
		world.setBlockAndMetadata(i + 11, j + 8, k + 3, Block.cloth.blockID, 15);
		world.setBlockAndMetadata(i + 11, j + 8, k + 4, Block.cloth.blockID, 15);
		world.setBlockAndMetadata(i + 11, j + 8, k + 5, Block.cloth.blockID, 15);
		world.setBlockAndMetadata(i + 11, j + 8, k + 6, Block.cloth.blockID, 15);
		world.setBlockAndMetadata(i + 11, j + 8, k + 7, Block.cloth.blockID, 15);
		world.setBlockAndMetadata(i + 11, j + 8, k + 8, Block.cloth.blockID, 15);
		world.setBlockAndMetadata(i + 11, j + 8, k + 9, Block.cloth.blockID, 15);
		world.setBlockAndMetadata(i + 11, j + 8, k + 10, Block.cloth.blockID, 15);
		world.setBlockAndMetadata(i + 11, j + 8, k + 11, Block.cloth.blockID, 15);
		world.setBlockAndMetadata(i + 11, j + 8, k + 12, Block.cloth.blockID, 15);
		world.setBlockAndMetadata(i + 11, j + 8, k + 13, Block.cloth.blockID, 15);
		world.setBlockAndMetadata(i + 11, j + 8, k + 14, Block.cloth.blockID, 15);
		world.setBlockAndMetadata(i + 11, j + 8, k + 15, Block.cloth.blockID, 15);
		world.setBlockAndMetadata(i + 11, j + 8, k + 16, Block.cloth.blockID, 15);
		world.setBlockAndMetadata(i + 11, j + 8, k + 17, Block.cloth.blockID, 15);
		world.setBlockAndMetadata(i + 11, j + 8, k + 18, Block.cloth.blockID, 15);
		world.setBlockAndMetadata(i + 11, j + 8, k + 19, Block.cloth.blockID, 15);
		world.setBlockAndMetadata(i + 11, j + 8, k + 20, Block.cloth.blockID, 15);
		world.setBlockAndMetadata(i + 11, j + 9, k + 2, Block.cloth.blockID, 15);
		world.setBlockAndMetadata(i + 11, j + 9, k + 3, Block.cloth.blockID, 15);
		world.setBlockAndMetadata(i + 11, j + 9, k + 4, Block.cloth.blockID, 15);
		world.setBlockAndMetadata(i + 11, j + 9, k + 5, Block.cloth.blockID, 15);
		world.setBlockAndMetadata(i + 11, j + 9, k + 6, Block.cloth.blockID, 15);
		world.setBlockAndMetadata(i + 11, j + 9, k + 7, Block.cloth.blockID, 15);
		world.setBlockAndMetadata(i + 11, j + 9, k + 8, Block.cloth.blockID, 15);
		world.setBlock(i + 11, j + 9, k + 9, Block.planks.blockID);
		world.setBlock(i + 11, j + 9, k + 10, Block.planks.blockID);
		world.setBlock(i + 11, j + 9, k + 11, Block.planks.blockID);
		world.setBlock(i + 11, j + 9, k + 12, Block.planks.blockID);
		world.setBlock(i + 11, j + 9, k + 13, Block.planks.blockID);
		world.setBlockAndMetadata(i + 11, j + 9, k + 14, Block.cloth.blockID, 15);
		world.setBlockAndMetadata(i + 11, j + 9, k + 15, Block.cloth.blockID, 15);
		world.setBlockAndMetadata(i + 11, j + 9, k + 16, Block.cloth.blockID, 15);
		world.setBlockAndMetadata(i + 11, j + 9, k + 17, Block.cloth.blockID, 15);
		world.setBlockAndMetadata(i + 11, j + 9, k + 18, Block.cloth.blockID, 15);
		world.setBlockAndMetadata(i + 11, j + 9, k + 19, Block.cloth.blockID, 15);
		world.setBlockAndMetadata(i + 11, j + 9, k + 20, Block.cloth.blockID, 15);
		world.setBlockAndMetadata(i + 11, j + 10, k + 1, Block.cloth.blockID, 15);
		world.setBlockAndMetadata(i + 11, j + 10, k + 2, Block.cloth.blockID, 15);
		world.setBlockAndMetadata(i + 11, j + 10, k + 3, Block.cloth.blockID, 15);
		world.setBlockAndMetadata(i + 11, j + 10, k + 4, Block.cloth.blockID, 15);
		world.setBlockAndMetadata(i + 11, j + 10, k + 5, Block.cloth.blockID, 15);
		world.setBlockAndMetadata(i + 11, j + 10, k + 6, Block.cloth.blockID, 15);
		world.setBlockAndMetadata(i + 11, j + 10, k + 7, Block.cloth.blockID, 15);
		world.setBlockAndMetadata(i + 11, j + 10, k + 8, Block.cloth.blockID, 15);
		world.setBlockAndMetadata(i + 11, j + 10, k + 14, Block.cloth.blockID, 15);
		world.setBlockAndMetadata(i + 11, j + 10, k + 15, Block.cloth.blockID, 15);
		world.setBlockAndMetadata(i + 11, j + 10, k + 16, Block.cloth.blockID, 15);
		world.setBlockAndMetadata(i + 11, j + 10, k + 17, Block.cloth.blockID, 15);
		world.setBlockAndMetadata(i + 11, j + 10, k + 18, Block.cloth.blockID, 15);
		world.setBlockAndMetadata(i + 11, j + 10, k + 19, Block.cloth.blockID, 15);
		world.setBlockAndMetadata(i + 11, j + 10, k + 20, Block.cloth.blockID, 15);
		world.setBlockAndMetadata(i + 11, j + 10, k + 21, Block.cloth.blockID, 15);
		world.setBlockAndMetadata(i + 11, j + 11, k + 1, Block.cloth.blockID, 15);
		world.setBlock(i + 11, j + 11, k + 2, Block.planks.blockID);
		world.setBlock(i + 11, j + 11, k + 3, Block.planks.blockID);
		world.setBlock(i + 11, j + 11, k + 4, Block.planks.blockID);
		world.setBlock(i + 11, j + 11, k + 5, Block.planks.blockID);
		world.setBlock(i + 11, j + 11, k + 6, Block.planks.blockID);
		world.setBlock(i + 11, j + 11, k + 7, Block.planks.blockID);
		world.setBlock(i + 11, j + 11, k + 8, Block.planks.blockID);
		world.setBlockAndMetadata(i + 11, j + 11, k + 9, Block.pistonBase.blockID, 9);
		world.setBlockAndMetadata(i + 11, j + 11, k + 10, Block.pistonBase.blockID, 9);
		world.setBlockAndMetadata(i + 11, j + 11, k + 11, Block.pistonBase.blockID, 9);
		world.setBlockAndMetadata(i + 11, j + 11, k + 12, Block.pistonBase.blockID, 9);
		world.setBlockAndMetadata(i + 11, j + 11, k + 13, Block.pistonBase.blockID, 9);
		world.setBlock(i + 11, j + 11, k + 14, Block.planks.blockID);
		world.setBlock(i + 11, j + 11, k + 15, Block.planks.blockID);
		world.setBlock(i + 11, j + 11, k + 16, Block.planks.blockID);
		world.setBlock(i + 11, j + 11, k + 17, Block.planks.blockID);
		world.setBlock(i + 11, j + 11, k + 18, Block.planks.blockID);
		world.setBlock(i + 11, j + 11, k + 19, Block.planks.blockID);
		world.setBlock(i + 11, j + 11, k + 20, Block.planks.blockID);
		world.setBlockAndMetadata(i + 11, j + 11, k + 21, Block.cloth.blockID, 15);
		world.setBlockAndMetadata(i + 11, j + 12, k + 1, Block.cloth.blockID, 15);
		world.setBlock(i + 11, j + 12, k + 3, Block.bookShelf.blockID);
		world.setBlock(i + 11, j + 12, k + 4, Block.bookShelf.blockID);
		world.setBlockAndMetadata(i + 11, j + 12, k + 9, Block.pistonExtension.blockID, 1);
		world.setBlockAndMetadata(i + 11, j + 12, k + 10, Block.pistonExtension.blockID, 1);
		world.setBlockAndMetadata(i + 11, j + 12, k + 11, Block.pistonExtension.blockID, 1);
		world.setBlockAndMetadata(i + 11, j + 12, k + 12, Block.pistonExtension.blockID, 1);
		world.setBlockAndMetadata(i + 11, j + 12, k + 13, Block.pistonExtension.blockID, 1);
		world.setBlock(i + 11, j + 12, k + 18, Block.bookShelf.blockID);
		world.setBlock(i + 11, j + 12, k + 19, Block.bookShelf.blockID);
		world.setBlockAndMetadata(i + 11, j + 12, k + 21, Block.cloth.blockID, 15);
		world.setBlock(i + 11, j + 13, k + 3, Block.bookShelf.blockID);
		world.setBlock(i + 11, j + 13, k + 4, Block.bookShelf.blockID);
		world.setBlock(i + 11, j + 13, k + 18, Block.bookShelf.blockID);
		world.setBlock(i + 11, j + 13, k + 19, Block.bookShelf.blockID);
		world.setBlockAndMetadata(i + 11, j + 14, k + 1, Block.cloth.blockID, 15);
		world.setBlockAndMetadata(i + 11, j + 14, k + 2, Block.stoneSingleSlab.blockID, 10);
		world.setBlockAndMetadata(i + 11, j + 14, k + 3, Block.stoneSingleSlab.blockID, 10);
		world.setBlockAndMetadata(i + 11, j + 14, k + 4, Block.stoneSingleSlab.blockID, 10);
		world.setBlockAndMetadata(i + 11, j + 14, k + 5, Block.stoneSingleSlab.blockID, 10);
		world.setBlockAndMetadata(i + 11, j + 14, k + 6, Block.stoneSingleSlab.blockID, 10);
		world.setBlockAndMetadata(i + 11, j + 14, k + 7, Block.stoneSingleSlab.blockID, 10);
		world.setBlockAndMetadata(i + 11, j + 14, k + 8, Block.stoneSingleSlab.blockID, 10);
		world.setBlockAndMetadata(i + 11, j + 14, k + 9, Block.stoneSingleSlab.blockID, 10);
		world.setBlockAndMetadata(i + 11, j + 14, k + 10, Block.stoneSingleSlab.blockID, 10);
		world.setBlockAndMetadata(i + 11, j + 14, k + 11, Block.stoneSingleSlab.blockID, 10);
		world.setBlockAndMetadata(i + 11, j + 14, k + 12, Block.stoneSingleSlab.blockID, 10);
		world.setBlockAndMetadata(i + 11, j + 14, k + 13, Block.stoneSingleSlab.blockID, 10);
		world.setBlockAndMetadata(i + 11, j + 14, k + 14, Block.stoneSingleSlab.blockID, 10);
		world.setBlockAndMetadata(i + 11, j + 14, k + 15, Block.stoneSingleSlab.blockID, 10);
		world.setBlockAndMetadata(i + 11, j + 14, k + 16, Block.stoneSingleSlab.blockID, 10);
		world.setBlockAndMetadata(i + 11, j + 14, k + 17, Block.stoneSingleSlab.blockID, 10);
		world.setBlockAndMetadata(i + 11, j + 14, k + 18, Block.stoneSingleSlab.blockID, 10);
		world.setBlockAndMetadata(i + 11, j + 14, k + 19, Block.stoneSingleSlab.blockID, 10);
		world.setBlockAndMetadata(i + 11, j + 14, k + 20, Block.stoneSingleSlab.blockID, 10);
		world.setBlockAndMetadata(i + 11, j + 14, k + 21, Block.cloth.blockID, 15);
		world.setBlockAndMetadata(i + 11, j + 15, k + 1, Block.cloth.blockID, 15);
		world.setBlock(i + 11, j + 15, k + 2, Block.bookShelf.blockID);
		world.setBlockAndMetadata(i + 11, j + 15, k + 21, Block.cloth.blockID, 15);
		world.setBlockAndMetadata(i + 11, j + 16, k + 1, Block.cloth.blockID, 4);
		world.setBlock(i + 11, j + 16, k + 2, Block.bookShelf.blockID);
		world.setBlockAndMetadata(i + 11, j + 16, k + 21, Block.cloth.blockID, 4);
		world.setBlockAndMetadata(i + 11, j + 17, k + 1, Block.cloth.blockID, 15);
		world.setBlockAndMetadata(i + 11, j + 17, k + 21, Block.cloth.blockID, 15);
		world.setBlockAndMetadata(i + 11, j + 18, k + 1, Block.cloth.blockID, 15);
		world.setBlockAndMetadata(i + 11, j + 18, k + 21, Block.cloth.blockID, 15);
		world.setBlockAndMetadata(i + 11, j + 19, k + 1, Block.cloth.blockID, 15);
		world.setBlockAndMetadata(i + 11, j + 19, k + 21, Block.cloth.blockID, 15);
		world.setBlock(i + 11, j + 20, k + 1, Block.cloth.blockID);
		world.setBlockAndMetadata(i + 11, j + 20, k + 2, Block.stoneSingleSlab.blockID, 2);
		world.setBlockAndMetadata(i + 11, j + 20, k + 3, Block.stoneSingleSlab.blockID, 2);
		world.setBlockAndMetadata(i + 11, j + 20, k + 4, Block.stoneSingleSlab.blockID, 2);
		world.setBlockAndMetadata(i + 11, j + 20, k + 5, Block.stoneSingleSlab.blockID, 2);
		world.setBlockAndMetadata(i + 11, j + 20, k + 6, Block.stoneSingleSlab.blockID, 2);
		world.setBlockAndMetadata(i + 11, j + 20, k + 7, Block.stoneSingleSlab.blockID, 2);
		world.setBlockAndMetadata(i + 11, j + 20, k + 8, Block.stoneSingleSlab.blockID, 2);
		world.setBlockAndMetadata(i + 11, j + 20, k + 9, Block.stoneSingleSlab.blockID, 2);
		world.setBlockAndMetadata(i + 11, j + 20, k + 10, Block.stoneSingleSlab.blockID, 2);
		world.setBlockAndMetadata(i + 11, j + 20, k + 11, Block.stoneSingleSlab.blockID, 2);
		world.setBlockAndMetadata(i + 11, j + 20, k + 12, Block.stoneSingleSlab.blockID, 2);
		world.setBlockAndMetadata(i + 11, j + 20, k + 13, Block.stoneSingleSlab.blockID, 2);
		world.setBlockAndMetadata(i + 11, j + 20, k + 14, Block.stoneSingleSlab.blockID, 2);
		world.setBlockAndMetadata(i + 11, j + 20, k + 15, Block.stoneSingleSlab.blockID, 2);
		world.setBlockAndMetadata(i + 11, j + 20, k + 16, Block.stoneSingleSlab.blockID, 2);
		world.setBlockAndMetadata(i + 11, j + 20, k + 17, Block.stoneSingleSlab.blockID, 2);
		world.setBlockAndMetadata(i + 11, j + 20, k + 18, Block.stoneSingleSlab.blockID, 2);
		world.setBlockAndMetadata(i + 11, j + 20, k + 19, Block.stoneSingleSlab.blockID, 2);
		world.setBlockAndMetadata(i + 11, j + 20, k + 20, Block.stoneSingleSlab.blockID, 2);
		world.setBlock(i + 11, j + 20, k + 21, Block.cloth.blockID);
		world.setBlock(i + 11, j + 21, k + 1, Block.netherFence.blockID);
		world.setBlock(i + 11, j + 21, k + 21, Block.netherFence.blockID);
		world.setBlockAndMetadata(i + 12, j + 0, k + 11, Block.cloth.blockID, 15);
		world.setBlockAndMetadata(i + 12, j + 1, k + 11, Block.cloth.blockID, 15);
		world.setBlockAndMetadata(i + 12, j + 2, k + 11, Block.cloth.blockID, 15);
		world.setBlockAndMetadata(i + 12, j + 3, k + 11, Block.cloth.blockID, 15);
		world.setBlockAndMetadata(i + 12, j + 4, k + 11, Block.cloth.blockID, 15);
		world.setBlockAndMetadata(i + 12, j + 5, k + 11, Block.cloth.blockID, 15);
		world.setBlockAndMetadata(i + 12, j + 6, k + 11, Block.cloth.blockID, 15);
		world.setBlockAndMetadata(i + 12, j + 7, k + 11, Block.cloth.blockID, 15);
		world.setBlockAndMetadata(i + 12, j + 8, k + 2, Block.cloth.blockID, 15);
		world.setBlockAndMetadata(i + 12, j + 8, k + 3, Block.cloth.blockID, 15);
		world.setBlockAndMetadata(i + 12, j + 8, k + 4, Block.cloth.blockID, 15);
		world.setBlockAndMetadata(i + 12, j + 8, k + 5, Block.cloth.blockID, 15);
		world.setBlockAndMetadata(i + 12, j + 8, k + 6, Block.cloth.blockID, 15);
		world.setBlockAndMetadata(i + 12, j + 8, k + 7, Block.cloth.blockID, 15);
		world.setBlockAndMetadata(i + 12, j + 8, k + 8, Block.cloth.blockID, 15);
		world.setBlockAndMetadata(i + 12, j + 8, k + 9, Block.cloth.blockID, 15);
		world.setBlockAndMetadata(i + 12, j + 8, k + 10, Block.cloth.blockID, 15);
		world.setBlockAndMetadata(i + 12, j + 8, k + 11, Block.cloth.blockID, 15);
		world.setBlockAndMetadata(i + 12, j + 8, k + 12, Block.cloth.blockID, 15);
		world.setBlockAndMetadata(i + 12, j + 8, k + 13, Block.cloth.blockID, 15);
		world.setBlockAndMetadata(i + 12, j + 8, k + 14, Block.cloth.blockID, 15);
		world.setBlockAndMetadata(i + 12, j + 8, k + 15, Block.cloth.blockID, 15);
		world.setBlockAndMetadata(i + 12, j + 8, k + 16, Block.cloth.blockID, 15);
		world.setBlockAndMetadata(i + 12, j + 8, k + 17, Block.cloth.blockID, 15);
		world.setBlockAndMetadata(i + 12, j + 8, k + 18, Block.cloth.blockID, 15);
		world.setBlockAndMetadata(i + 12, j + 8, k + 19, Block.cloth.blockID, 15);
		world.setBlockAndMetadata(i + 12, j + 8, k + 20, Block.cloth.blockID, 15);
		world.setBlockAndMetadata(i + 12, j + 9, k + 2, Block.cloth.blockID, 15);
		world.setBlockAndMetadata(i + 12, j + 9, k + 3, Block.cloth.blockID, 15);
		world.setBlockAndMetadata(i + 12, j + 9, k + 4, Block.cloth.blockID, 15);
		world.setBlockAndMetadata(i + 12, j + 9, k + 5, Block.cloth.blockID, 15);
		world.setBlockAndMetadata(i + 12, j + 9, k + 6, Block.cloth.blockID, 15);
		world.setBlockAndMetadata(i + 12, j + 9, k + 7, Block.cloth.blockID, 15);
		world.setBlockAndMetadata(i + 12, j + 9, k + 8, Block.cloth.blockID, 15);
		world.setBlock(i + 12, j + 9, k + 9, Block.planks.blockID);
		world.setBlock(i + 12, j + 9, k + 10, Block.planks.blockID);
		world.setBlock(i + 12, j + 9, k + 11, Block.planks.blockID);
		world.setBlock(i + 12, j + 9, k + 12, Block.planks.blockID);
		world.setBlock(i + 12, j + 9, k + 13, Block.planks.blockID);
		world.setBlockAndMetadata(i + 12, j + 9, k + 14, Block.cloth.blockID, 15);
		world.setBlockAndMetadata(i + 12, j + 9, k + 15, Block.cloth.blockID, 15);
		world.setBlockAndMetadata(i + 12, j + 9, k + 16, Block.cloth.blockID, 15);
		world.setBlockAndMetadata(i + 12, j + 9, k + 17, Block.cloth.blockID, 15);
		world.setBlockAndMetadata(i + 12, j + 9, k + 18, Block.cloth.blockID, 15);
		world.setBlockAndMetadata(i + 12, j + 9, k + 19, Block.cloth.blockID, 15);
		world.setBlockAndMetadata(i + 12, j + 9, k + 20, Block.cloth.blockID, 15);
		world.setBlockAndMetadata(i + 12, j + 10, k + 1, Block.cloth.blockID, 15);
		world.setBlockAndMetadata(i + 12, j + 10, k + 2, Block.cloth.blockID, 15);
		world.setBlockAndMetadata(i + 12, j + 10, k + 3, Block.cloth.blockID, 15);
		world.setBlockAndMetadata(i + 12, j + 10, k + 4, Block.cloth.blockID, 15);
		world.setBlockAndMetadata(i + 12, j + 10, k + 5, Block.cloth.blockID, 15);
		world.setBlockAndMetadata(i + 12, j + 10, k + 6, Block.cloth.blockID, 15);
		world.setBlockAndMetadata(i + 12, j + 10, k + 7, Block.cloth.blockID, 15);
		world.setBlockAndMetadata(i + 12, j + 10, k + 8, Block.cloth.blockID, 15);
		world.setBlockAndMetadata(i + 12, j + 10, k + 14, Block.cloth.blockID, 15);
		world.setBlockAndMetadata(i + 12, j + 10, k + 15, Block.cloth.blockID, 15);
		world.setBlockAndMetadata(i + 12, j + 10, k + 16, Block.cloth.blockID, 15);
		world.setBlockAndMetadata(i + 12, j + 10, k + 17, Block.cloth.blockID, 15);
		world.setBlockAndMetadata(i + 12, j + 10, k + 18, Block.cloth.blockID, 15);
		world.setBlockAndMetadata(i + 12, j + 10, k + 19, Block.cloth.blockID, 15);
		world.setBlockAndMetadata(i + 12, j + 10, k + 20, Block.cloth.blockID, 15);
		world.setBlockAndMetadata(i + 12, j + 10, k + 21, Block.cloth.blockID, 15);
		world.setBlockAndMetadata(i + 12, j + 11, k + 1, Block.cloth.blockID, 15);
		world.setBlock(i + 12, j + 11, k + 2, Block.planks.blockID);
		world.setBlock(i + 12, j + 11, k + 3, Block.planks.blockID);
		world.setBlock(i + 12, j + 11, k + 4, Block.planks.blockID);
		world.setBlock(i + 12, j + 11, k + 5, Block.planks.blockID);
		world.setBlock(i + 12, j + 11, k + 6, Block.planks.blockID);
		world.setBlock(i + 12, j + 11, k + 7, Block.planks.blockID);
		world.setBlock(i + 12, j + 11, k + 8, Block.planks.blockID);
		world.setBlockAndMetadata(i + 12, j + 11, k + 9, Block.pistonBase.blockID, 9);
		world.setBlockAndMetadata(i + 12, j + 11, k + 10, Block.pistonBase.blockID, 9);
		world.setBlockAndMetadata(i + 12, j + 11, k + 11, Block.pistonBase.blockID, 9);
		world.setBlockAndMetadata(i + 12, j + 11, k + 12, Block.pistonBase.blockID, 9);
		world.setBlockAndMetadata(i + 12, j + 11, k + 13, Block.pistonBase.blockID, 9);
		world.setBlock(i + 12, j + 11, k + 14, Block.planks.blockID);
		world.setBlock(i + 12, j + 11, k + 15, Block.planks.blockID);
		world.setBlock(i + 12, j + 11, k + 16, Block.planks.blockID);
		world.setBlock(i + 12, j + 11, k + 17, Block.planks.blockID);
		world.setBlock(i + 12, j + 11, k + 18, Block.planks.blockID);
		world.setBlock(i + 12, j + 11, k + 19, Block.planks.blockID);
		world.setBlock(i + 12, j + 11, k + 20, Block.planks.blockID);
		world.setBlockAndMetadata(i + 12, j + 11, k + 21, Block.cloth.blockID, 15);
		world.setBlockAndMetadata(i + 12, j + 12, k + 1, Block.cloth.blockID, 15);
		world.setBlockAndMetadata(i + 12, j + 12, k + 8, Block.stairsNetherBrick.blockID, 3);
		world.setBlockAndMetadata(i + 12, j + 12, k + 9, Block.pistonExtension.blockID, 1);
		world.setBlockAndMetadata(i + 12, j + 12, k + 10, Block.pistonExtension.blockID, 1);
		world.setBlockAndMetadata(i + 12, j + 12, k + 11, Block.pistonExtension.blockID, 1);
		world.setBlockAndMetadata(i + 12, j + 12, k + 12, Block.pistonExtension.blockID, 1);
		world.setBlockAndMetadata(i + 12, j + 12, k + 13, Block.pistonExtension.blockID, 1);
		world.setBlockAndMetadata(i + 12, j + 12, k + 14, Block.stairsNetherBrick.blockID, 2);
		world.setBlockAndMetadata(i + 12, j + 12, k + 21, Block.cloth.blockID, 15);
		world.setBlockAndMetadata(i + 12, j + 14, k + 1, Block.cloth.blockID, 15);
		world.setBlockAndMetadata(i + 12, j + 14, k + 2, Block.stoneSingleSlab.blockID, 10);
		world.setBlockAndMetadata(i + 12, j + 14, k + 3, Block.stoneSingleSlab.blockID, 10);
		world.setBlockAndMetadata(i + 12, j + 14, k + 4, Block.stoneSingleSlab.blockID, 10);
		world.setBlockAndMetadata(i + 12, j + 14, k + 5, Block.stoneSingleSlab.blockID, 10);
		world.setBlockAndMetadata(i + 12, j + 14, k + 6, Block.stoneSingleSlab.blockID, 10);
		world.setBlockAndMetadata(i + 12, j + 14, k + 7, Block.stoneSingleSlab.blockID, 10);
		world.setBlockAndMetadata(i + 12, j + 14, k + 8, Block.stoneSingleSlab.blockID, 10);
		world.setBlockAndMetadata(i + 12, j + 14, k + 9, Block.stoneSingleSlab.blockID, 10);
		world.setBlockAndMetadata(i + 12, j + 14, k + 10, Block.stoneSingleSlab.blockID, 10);
		world.setBlockAndMetadata(i + 12, j + 14, k + 11, Block.stoneSingleSlab.blockID, 10);
		world.setBlockAndMetadata(i + 12, j + 14, k + 12, Block.stoneSingleSlab.blockID, 10);
		world.setBlockAndMetadata(i + 12, j + 14, k + 13, Block.stoneSingleSlab.blockID, 10);
		world.setBlockAndMetadata(i + 12, j + 14, k + 14, Block.stoneSingleSlab.blockID, 10);
		world.setBlockAndMetadata(i + 12, j + 14, k + 15, Block.stoneSingleSlab.blockID, 10);
		world.setBlockAndMetadata(i + 12, j + 14, k + 16, Block.stoneSingleSlab.blockID, 10);
		world.setBlockAndMetadata(i + 12, j + 14, k + 17, Block.stoneSingleSlab.blockID, 10);
		world.setBlockAndMetadata(i + 12, j + 14, k + 18, Block.stoneSingleSlab.blockID, 10);
		world.setBlockAndMetadata(i + 12, j + 14, k + 19, Block.stoneSingleSlab.blockID, 10);
		world.setBlockAndMetadata(i + 12, j + 14, k + 20, Block.stoneSingleSlab.blockID, 10);
		world.setBlockAndMetadata(i + 12, j + 14, k + 21, Block.cloth.blockID, 15);
		world.setBlockAndMetadata(i + 12, j + 15, k + 1, Block.cloth.blockID, 15);
		world.setBlock(i + 12, j + 15, k + 2, Block.bookShelf.blockID);
		world.setBlock(i + 12, j + 15, k + 4, Block.enchantmentTable.blockID);
		world.setBlockAndMetadata(i + 12, j + 15, k + 20, Block.chest.blockID, 2);
		world.setBlockAndMetadata(i + 12, j + 15, k + 21, Block.cloth.blockID, 15);
		world.setBlockAndMetadata(i + 12, j + 16, k + 1, Block.cloth.blockID, 4);
		world.setBlock(i + 12, j + 16, k + 2, Block.bookShelf.blockID);
		world.setBlockAndMetadata(i + 12, j + 16, k + 21, Block.cloth.blockID, 4);
		world.setBlockAndMetadata(i + 12, j + 17, k + 1, Block.cloth.blockID, 15);
		world.setBlockAndMetadata(i + 12, j + 17, k + 21, Block.cloth.blockID, 15);
		world.setBlockAndMetadata(i + 12, j + 18, k + 1, Block.cloth.blockID, 15);
		world.setBlockAndMetadata(i + 12, j + 18, k + 21, Block.cloth.blockID, 15);
		world.setBlockAndMetadata(i + 12, j + 19, k + 1, Block.cloth.blockID, 15);
		world.setBlockAndMetadata(i + 12, j + 19, k + 21, Block.cloth.blockID, 15);
		world.setBlock(i + 12, j + 20, k + 1, Block.cloth.blockID);
		world.setBlockAndMetadata(i + 12, j + 20, k + 2, Block.stoneSingleSlab.blockID, 2);
		world.setBlockAndMetadata(i + 12, j + 20, k + 3, Block.stoneSingleSlab.blockID, 2);
		world.setBlockAndMetadata(i + 12, j + 20, k + 4, Block.stoneSingleSlab.blockID, 2);
		world.setBlockAndMetadata(i + 12, j + 20, k + 5, Block.stoneSingleSlab.blockID, 2);
		world.setBlockAndMetadata(i + 12, j + 20, k + 6, Block.stoneSingleSlab.blockID, 2);
		world.setBlockAndMetadata(i + 12, j + 20, k + 7, Block.stoneSingleSlab.blockID, 2);
		world.setBlockAndMetadata(i + 12, j + 20, k + 8, Block.stoneSingleSlab.blockID, 2);
		world.setBlockAndMetadata(i + 12, j + 20, k + 9, Block.stoneSingleSlab.blockID, 2);
		world.setBlockAndMetadata(i + 12, j + 20, k + 10, Block.stoneSingleSlab.blockID, 2);
		world.setBlockAndMetadata(i + 12, j + 20, k + 11, Block.stoneSingleSlab.blockID, 2);
		world.setBlockAndMetadata(i + 12, j + 20, k + 12, Block.stoneSingleSlab.blockID, 2);
		world.setBlockAndMetadata(i + 12, j + 20, k + 13, Block.stoneSingleSlab.blockID, 2);
		world.setBlockAndMetadata(i + 12, j + 20, k + 14, Block.stoneSingleSlab.blockID, 2);
		world.setBlockAndMetadata(i + 12, j + 20, k + 15, Block.stoneSingleSlab.blockID, 2);
		world.setBlockAndMetadata(i + 12, j + 20, k + 16, Block.stoneSingleSlab.blockID, 2);
		world.setBlockAndMetadata(i + 12, j + 20, k + 17, Block.stoneSingleSlab.blockID, 2);
		world.setBlockAndMetadata(i + 12, j + 20, k + 18, Block.stoneSingleSlab.blockID, 2);
		world.setBlockAndMetadata(i + 12, j + 20, k + 19, Block.stoneSingleSlab.blockID, 2);
		world.setBlockAndMetadata(i + 12, j + 20, k + 20, Block.stoneSingleSlab.blockID, 2);
		world.setBlock(i + 12, j + 20, k + 21, Block.cloth.blockID);
		world.setBlock(i + 12, j + 21, k + 1, Block.netherFence.blockID);
		world.setBlock(i + 12, j + 21, k + 21, Block.netherFence.blockID);
		world.setBlockAndMetadata(i + 13, j + 0, k + 11, Block.cloth.blockID, 15);
		world.setBlockAndMetadata(i + 13, j + 1, k + 11, Block.cloth.blockID, 15);
		world.setBlockAndMetadata(i + 13, j + 2, k + 11, Block.cloth.blockID, 15);
		world.setBlockAndMetadata(i + 13, j + 3, k + 11, Block.cloth.blockID, 15);
		world.setBlockAndMetadata(i + 13, j + 4, k + 11, Block.cloth.blockID, 15);
		world.setBlockAndMetadata(i + 13, j + 5, k + 11, Block.cloth.blockID, 15);
		world.setBlockAndMetadata(i + 13, j + 6, k + 11, Block.cloth.blockID, 15);
		world.setBlockAndMetadata(i + 13, j + 7, k + 3, Block.cloth.blockID, 15);
		world.setBlockAndMetadata(i + 13, j + 7, k + 4, Block.cloth.blockID, 15);
		world.setBlockAndMetadata(i + 13, j + 7, k + 5, Block.cloth.blockID, 15);
		world.setBlockAndMetadata(i + 13, j + 7, k + 6, Block.cloth.blockID, 15);
		world.setBlockAndMetadata(i + 13, j + 7, k + 7, Block.cloth.blockID, 15);
		world.setBlockAndMetadata(i + 13, j + 7, k + 8, Block.cloth.blockID, 15);
		world.setBlockAndMetadata(i + 13, j + 7, k + 9, Block.cloth.blockID, 15);
		world.setBlockAndMetadata(i + 13, j + 7, k + 10, Block.cloth.blockID, 15);
		world.setBlockAndMetadata(i + 13, j + 7, k + 11, Block.cloth.blockID, 15);
		world.setBlockAndMetadata(i + 13, j + 7, k + 12, Block.cloth.blockID, 15);
		world.setBlockAndMetadata(i + 13, j + 7, k + 13, Block.cloth.blockID, 15);
		world.setBlockAndMetadata(i + 13, j + 7, k + 14, Block.cloth.blockID, 15);
		world.setBlockAndMetadata(i + 13, j + 7, k + 15, Block.cloth.blockID, 15);
		world.setBlockAndMetadata(i + 13, j + 7, k + 16, Block.cloth.blockID, 15);
		world.setBlockAndMetadata(i + 13, j + 7, k + 17, Block.cloth.blockID, 15);
		world.setBlockAndMetadata(i + 13, j + 7, k + 18, Block.cloth.blockID, 15);
		world.setBlockAndMetadata(i + 13, j + 7, k + 19, Block.cloth.blockID, 15);
		world.setBlockAndMetadata(i + 13, j + 8, k + 2, Block.cloth.blockID, 15);
		world.setBlockAndMetadata(i + 13, j + 8, k + 3, Block.cloth.blockID, 15);
		world.setBlockAndMetadata(i + 13, j + 8, k + 4, Block.cloth.blockID, 15);
		world.setBlockAndMetadata(i + 13, j + 8, k + 5, Block.cloth.blockID, 15);
		world.setBlockAndMetadata(i + 13, j + 8, k + 6, Block.cloth.blockID, 15);
		world.setBlockAndMetadata(i + 13, j + 8, k + 7, Block.cloth.blockID, 15);
		world.setBlockAndMetadata(i + 13, j + 8, k + 8, Block.cloth.blockID, 15);
		world.setBlockAndMetadata(i + 13, j + 8, k + 9, Block.cloth.blockID, 15);
		world.setBlockAndMetadata(i + 13, j + 8, k + 10, Block.cloth.blockID, 15);
		world.setBlockAndMetadata(i + 13, j + 8, k + 11, Block.cloth.blockID, 15);
		world.setBlockAndMetadata(i + 13, j + 8, k + 12, Block.cloth.blockID, 15);
		world.setBlockAndMetadata(i + 13, j + 8, k + 13, Block.cloth.blockID, 15);
		world.setBlockAndMetadata(i + 13, j + 8, k + 14, Block.cloth.blockID, 15);
		world.setBlockAndMetadata(i + 13, j + 8, k + 15, Block.cloth.blockID, 15);
		world.setBlockAndMetadata(i + 13, j + 8, k + 16, Block.cloth.blockID, 15);
		world.setBlockAndMetadata(i + 13, j + 8, k + 17, Block.cloth.blockID, 15);
		world.setBlockAndMetadata(i + 13, j + 8, k + 18, Block.cloth.blockID, 15);
		world.setBlockAndMetadata(i + 13, j + 8, k + 19, Block.cloth.blockID, 15);
		world.setBlockAndMetadata(i + 13, j + 8, k + 20, Block.cloth.blockID, 15);
		world.setBlockAndMetadata(i + 13, j + 9, k + 2, Block.cloth.blockID, 15);
		world.setBlockAndMetadata(i + 13, j + 9, k + 3, Block.cloth.blockID, 15);
		world.setBlockAndMetadata(i + 13, j + 9, k + 4, Block.cloth.blockID, 15);
		world.setBlockAndMetadata(i + 13, j + 9, k + 5, Block.cloth.blockID, 15);
		world.setBlockAndMetadata(i + 13, j + 9, k + 6, Block.cloth.blockID, 15);
		world.setBlockAndMetadata(i + 13, j + 9, k + 7, Block.cloth.blockID, 15);
		world.setBlockAndMetadata(i + 13, j + 9, k + 8, Block.cloth.blockID, 15);
		world.setBlockAndMetadata(i + 13, j + 9, k + 9, Block.cloth.blockID, 15);
		world.setBlockAndMetadata(i + 13, j + 9, k + 10, Block.cloth.blockID, 15);
		world.setBlockAndMetadata(i + 13, j + 9, k + 11, Block.cloth.blockID, 15);
		world.setBlockAndMetadata(i + 13, j + 9, k + 12, Block.cloth.blockID, 15);
		world.setBlockAndMetadata(i + 13, j + 9, k + 13, Block.cloth.blockID, 15);
		world.setBlockAndMetadata(i + 13, j + 9, k + 14, Block.cloth.blockID, 15);
		world.setBlockAndMetadata(i + 13, j + 9, k + 15, Block.cloth.blockID, 15);
		world.setBlockAndMetadata(i + 13, j + 9, k + 16, Block.cloth.blockID, 15);
		world.setBlockAndMetadata(i + 13, j + 9, k + 17, Block.cloth.blockID, 15);
		world.setBlockAndMetadata(i + 13, j + 9, k + 18, Block.cloth.blockID, 15);
		world.setBlockAndMetadata(i + 13, j + 9, k + 19, Block.cloth.blockID, 15);
		world.setBlockAndMetadata(i + 13, j + 9, k + 20, Block.cloth.blockID, 15);
		world.setBlockAndMetadata(i + 13, j + 10, k + 1, Block.cloth.blockID, 15);
		world.setBlockAndMetadata(i + 13, j + 10, k + 2, Block.cloth.blockID, 15);
		world.setBlockAndMetadata(i + 13, j + 10, k + 3, Block.cloth.blockID, 15);
		world.setBlockAndMetadata(i + 13, j + 10, k + 4, Block.cloth.blockID, 15);
		world.setBlockAndMetadata(i + 13, j + 10, k + 5, Block.cloth.blockID, 15);
		world.setBlockAndMetadata(i + 13, j + 10, k + 6, Block.cloth.blockID, 15);
		world.setBlockAndMetadata(i + 13, j + 10, k + 7, Block.cloth.blockID, 15);
		world.setBlockAndMetadata(i + 13, j + 10, k + 8, Block.cloth.blockID, 15);
		world.setBlockAndMetadata(i + 13, j + 10, k + 14, Block.cloth.blockID, 15);
		world.setBlockAndMetadata(i + 13, j + 10, k + 15, Block.cloth.blockID, 15);
		world.setBlockAndMetadata(i + 13, j + 10, k + 16, Block.cloth.blockID, 15);
		world.setBlockAndMetadata(i + 13, j + 10, k + 17, Block.cloth.blockID, 15);
		world.setBlockAndMetadata(i + 13, j + 10, k + 18, Block.cloth.blockID, 15);
		world.setBlockAndMetadata(i + 13, j + 10, k + 19, Block.cloth.blockID, 15);
		world.setBlockAndMetadata(i + 13, j + 10, k + 20, Block.cloth.blockID, 15);
		world.setBlockAndMetadata(i + 13, j + 10, k + 21, Block.cloth.blockID, 15);
		world.setBlockAndMetadata(i + 13, j + 11, k + 1, Block.cloth.blockID, 15);
		world.setBlock(i + 13, j + 11, k + 2, Block.planks.blockID);
		world.setBlock(i + 13, j + 11, k + 3, Block.planks.blockID);
		world.setBlock(i + 13, j + 11, k + 4, Block.planks.blockID);
		world.setBlock(i + 13, j + 11, k + 5, Block.planks.blockID);
		world.setBlock(i + 13, j + 11, k + 6, Block.planks.blockID);
		world.setBlock(i + 13, j + 11, k + 7, Block.planks.blockID);
		world.setBlock(i + 13, j + 11, k + 8, Block.planks.blockID);
		world.setBlockAndMetadata(i + 13, j + 11, k + 9, Block.pistonBase.blockID, 9);
		world.setBlockAndMetadata(i + 13, j + 11, k + 10, Block.pistonBase.blockID, 9);
		world.setBlockAndMetadata(i + 13, j + 11, k + 11, Block.pistonBase.blockID, 9);
		world.setBlockAndMetadata(i + 13, j + 11, k + 12, Block.pistonBase.blockID, 9);
		world.setBlockAndMetadata(i + 13, j + 11, k + 13, Block.pistonBase.blockID, 9);
		world.setBlock(i + 13, j + 11, k + 14, Block.planks.blockID);
		world.setBlock(i + 13, j + 11, k + 15, Block.planks.blockID);
		world.setBlock(i + 13, j + 11, k + 16, Block.planks.blockID);
		world.setBlock(i + 13, j + 11, k + 17, Block.planks.blockID);
		world.setBlock(i + 13, j + 11, k + 18, Block.planks.blockID);
		world.setBlock(i + 13, j + 11, k + 19, Block.planks.blockID);
		world.setBlock(i + 13, j + 11, k + 20, Block.planks.blockID);
		world.setBlockAndMetadata(i + 13, j + 11, k + 21, Block.cloth.blockID, 15);
		world.setBlockAndMetadata(i + 13, j + 12, k + 1, Block.cloth.blockID, 15);
		world.setBlockAndMetadata(i + 13, j + 12, k + 9, Block.pistonExtension.blockID, 1);
		world.setBlockAndMetadata(i + 13, j + 12, k + 10, Block.pistonExtension.blockID, 1);
		world.setBlockAndMetadata(i + 13, j + 12, k + 11, Block.pistonExtension.blockID, 1);
		world.setBlockAndMetadata(i + 13, j + 12, k + 12, Block.pistonExtension.blockID, 1);
		world.setBlockAndMetadata(i + 13, j + 12, k + 13, Block.pistonExtension.blockID, 1);
		world.setBlockAndMetadata(i + 13, j + 12, k + 21, Block.cloth.blockID, 15);
		world.setBlockAndMetadata(i + 13, j + 14, k + 1, Block.cloth.blockID, 15);
		world.setBlockAndMetadata(i + 13, j + 14, k + 2, Block.stoneSingleSlab.blockID, 10);
		world.setBlockAndMetadata(i + 13, j + 14, k + 3, Block.stoneSingleSlab.blockID, 10);
		world.setBlockAndMetadata(i + 13, j + 14, k + 4, Block.stoneSingleSlab.blockID, 10);
		world.setBlockAndMetadata(i + 13, j + 14, k + 5, Block.stoneSingleSlab.blockID, 10);
		world.setBlockAndMetadata(i + 13, j + 14, k + 6, Block.stoneSingleSlab.blockID, 10);
		world.setBlockAndMetadata(i + 13, j + 14, k + 7, Block.stoneSingleSlab.blockID, 10);
		world.setBlockAndMetadata(i + 13, j + 14, k + 8, Block.stoneSingleSlab.blockID, 10);
		world.setBlockAndMetadata(i + 13, j + 14, k + 9, Block.stoneSingleSlab.blockID, 10);
		world.setBlockAndMetadata(i + 13, j + 14, k + 10, Block.stoneSingleSlab.blockID, 10);
		world.setBlockAndMetadata(i + 13, j + 14, k + 11, Block.stoneSingleSlab.blockID, 10);
		world.setBlockAndMetadata(i + 13, j + 14, k + 12, Block.stoneSingleSlab.blockID, 10);
		world.setBlockAndMetadata(i + 13, j + 14, k + 13, Block.stoneSingleSlab.blockID, 10);
		world.setBlockAndMetadata(i + 13, j + 14, k + 14, Block.stoneSingleSlab.blockID, 10);
		world.setBlockAndMetadata(i + 13, j + 14, k + 15, Block.stoneSingleSlab.blockID, 10);
		world.setBlockAndMetadata(i + 13, j + 14, k + 16, Block.stoneSingleSlab.blockID, 10);
		world.setBlockAndMetadata(i + 13, j + 14, k + 17, Block.stoneSingleSlab.blockID, 10);
		world.setBlockAndMetadata(i + 13, j + 14, k + 18, Block.stoneSingleSlab.blockID, 10);
		world.setBlockAndMetadata(i + 13, j + 14, k + 19, Block.stoneSingleSlab.blockID, 10);
		world.setBlockAndMetadata(i + 13, j + 14, k + 20, Block.stoneSingleSlab.blockID, 10);
		world.setBlockAndMetadata(i + 13, j + 14, k + 21, Block.cloth.blockID, 15);
		world.setBlockAndMetadata(i + 13, j + 15, k + 1, Block.cloth.blockID, 15);
		world.setBlock(i + 13, j + 15, k + 2, Block.bookShelf.blockID);
		world.setBlock(i + 13, j + 15, k + 20, Block.jukebox.blockID);
		world.setBlockAndMetadata(i + 13, j + 15, k + 21, Block.cloth.blockID, 15);
		world.setBlockAndMetadata(i + 13, j + 16, k + 1, Block.cloth.blockID, 4);
		world.setBlock(i + 13, j + 16, k + 2, Block.bookShelf.blockID);
		world.setBlockAndMetadata(i + 13, j + 16, k + 21, Block.cloth.blockID, 4);
		world.setBlockAndMetadata(i + 13, j + 17, k + 1, Block.cloth.blockID, 15);
		world.setBlockAndMetadata(i + 13, j + 17, k + 21, Block.cloth.blockID, 15);
		world.setBlockAndMetadata(i + 13, j + 18, k + 1, Block.cloth.blockID, 15);
		world.setBlockAndMetadata(i + 13, j + 18, k + 21, Block.cloth.blockID, 15);
		world.setBlockAndMetadata(i + 13, j + 19, k + 1, Block.cloth.blockID, 15);
		world.setBlockAndMetadata(i + 13, j + 19, k + 21, Block.cloth.blockID, 15);
		world.setBlock(i + 13, j + 20, k + 1, Block.cloth.blockID);
		world.setBlockAndMetadata(i + 13, j + 20, k + 2, Block.stoneSingleSlab.blockID, 2);
		world.setBlockAndMetadata(i + 13, j + 20, k + 3, Block.stoneSingleSlab.blockID, 2);
		world.setBlockAndMetadata(i + 13, j + 20, k + 4, Block.stoneSingleSlab.blockID, 2);
		world.setBlockAndMetadata(i + 13, j + 20, k + 5, Block.stoneSingleSlab.blockID, 2);
		world.setBlockAndMetadata(i + 13, j + 20, k + 6, Block.stoneSingleSlab.blockID, 2);
		world.setBlockAndMetadata(i + 13, j + 20, k + 7, Block.stoneSingleSlab.blockID, 2);
		world.setBlockAndMetadata(i + 13, j + 20, k + 8, Block.stoneSingleSlab.blockID, 2);
		world.setBlockAndMetadata(i + 13, j + 20, k + 9, Block.stoneSingleSlab.blockID, 2);
		world.setBlockAndMetadata(i + 13, j + 20, k + 10, Block.stoneSingleSlab.blockID, 2);
		world.setBlockAndMetadata(i + 13, j + 20, k + 11, Block.stoneSingleSlab.blockID, 2);
		world.setBlockAndMetadata(i + 13, j + 20, k + 12, Block.stoneSingleSlab.blockID, 2);
		world.setBlockAndMetadata(i + 13, j + 20, k + 13, Block.stoneSingleSlab.blockID, 2);
		world.setBlockAndMetadata(i + 13, j + 20, k + 14, Block.stoneSingleSlab.blockID, 2);
		world.setBlockAndMetadata(i + 13, j + 20, k + 15, Block.stoneSingleSlab.blockID, 2);
		world.setBlockAndMetadata(i + 13, j + 20, k + 16, Block.stoneSingleSlab.blockID, 2);
		world.setBlockAndMetadata(i + 13, j + 20, k + 17, Block.stoneSingleSlab.blockID, 2);
		world.setBlockAndMetadata(i + 13, j + 20, k + 18, Block.stoneSingleSlab.blockID, 2);
		world.setBlockAndMetadata(i + 13, j + 20, k + 19, Block.stoneSingleSlab.blockID, 2);
		world.setBlockAndMetadata(i + 13, j + 20, k + 20, Block.stoneSingleSlab.blockID, 2);
		world.setBlock(i + 13, j + 20, k + 21, Block.cloth.blockID);
		world.setBlock(i + 13, j + 21, k + 1, Block.netherFence.blockID);
		world.setBlock(i + 13, j + 21, k + 21, Block.netherFence.blockID);
		world.setBlockAndMetadata(i + 14, j + 0, k + 11, Block.cloth.blockID, 14);
		world.setBlockAndMetadata(i + 14, j + 1, k + 11, Block.cloth.blockID, 15);
		world.setBlockAndMetadata(i + 14, j + 2, k + 11, Block.cloth.blockID, 15);
		world.setBlockAndMetadata(i + 14, j + 3, k + 11, Block.cloth.blockID, 15);
		world.setBlockAndMetadata(i + 14, j + 4, k + 11, Block.cloth.blockID, 15);
		world.setBlockAndMetadata(i + 14, j + 5, k + 11, Block.cloth.blockID, 15);
		world.setBlockAndMetadata(i + 14, j + 6, k + 3, Block.cloth.blockID, 15);
		world.setBlockAndMetadata(i + 14, j + 6, k + 4, Block.cloth.blockID, 15);
		world.setBlockAndMetadata(i + 14, j + 6, k + 5, Block.cloth.blockID, 15);
		world.setBlockAndMetadata(i + 14, j + 6, k + 6, Block.cloth.blockID, 15);
		world.setBlockAndMetadata(i + 14, j + 6, k + 7, Block.cloth.blockID, 15);
		world.setBlockAndMetadata(i + 14, j + 6, k + 8, Block.cloth.blockID, 15);
		world.setBlockAndMetadata(i + 14, j + 6, k + 9, Block.cloth.blockID, 15);
		world.setBlockAndMetadata(i + 14, j + 6, k + 10, Block.cloth.blockID, 15);
		world.setBlockAndMetadata(i + 14, j + 6, k + 11, Block.cloth.blockID, 15);
		world.setBlockAndMetadata(i + 14, j + 6, k + 12, Block.cloth.blockID, 15);
		world.setBlockAndMetadata(i + 14, j + 6, k + 13, Block.cloth.blockID, 15);
		world.setBlockAndMetadata(i + 14, j + 6, k + 14, Block.cloth.blockID, 15);
		world.setBlockAndMetadata(i + 14, j + 6, k + 15, Block.cloth.blockID, 15);
		world.setBlockAndMetadata(i + 14, j + 6, k + 16, Block.cloth.blockID, 15);
		world.setBlockAndMetadata(i + 14, j + 6, k + 17, Block.cloth.blockID, 15);
		world.setBlockAndMetadata(i + 14, j + 6, k + 18, Block.cloth.blockID, 15);
		world.setBlockAndMetadata(i + 14, j + 6, k + 19, Block.cloth.blockID, 15);
		world.setBlockAndMetadata(i + 14, j + 7, k + 3, Block.cloth.blockID, 15);
		world.setBlockAndMetadata(i + 14, j + 7, k + 4, Block.cloth.blockID, 15);
		world.setBlockAndMetadata(i + 14, j + 7, k + 5, Block.cloth.blockID, 15);
		world.setBlockAndMetadata(i + 14, j + 7, k + 6, Block.cloth.blockID, 15);
		world.setBlockAndMetadata(i + 14, j + 7, k + 7, Block.cloth.blockID, 15);
		world.setBlockAndMetadata(i + 14, j + 7, k + 8, Block.cloth.blockID, 15);
		world.setBlockAndMetadata(i + 14, j + 7, k + 9, Block.cloth.blockID, 15);
		world.setBlockAndMetadata(i + 14, j + 7, k + 10, Block.cloth.blockID, 15);
		world.setBlockAndMetadata(i + 14, j + 7, k + 11, Block.cloth.blockID, 15);
		world.setBlockAndMetadata(i + 14, j + 7, k + 12, Block.cloth.blockID, 15);
		world.setBlockAndMetadata(i + 14, j + 7, k + 13, Block.cloth.blockID, 15);
		world.setBlockAndMetadata(i + 14, j + 7, k + 14, Block.cloth.blockID, 15);
		world.setBlockAndMetadata(i + 14, j + 7, k + 15, Block.cloth.blockID, 15);
		world.setBlockAndMetadata(i + 14, j + 7, k + 16, Block.cloth.blockID, 15);
		world.setBlockAndMetadata(i + 14, j + 7, k + 17, Block.cloth.blockID, 15);
		world.setBlockAndMetadata(i + 14, j + 7, k + 18, Block.cloth.blockID, 15);
		world.setBlockAndMetadata(i + 14, j + 7, k + 19, Block.cloth.blockID, 15);
		world.setBlockAndMetadata(i + 14, j + 8, k + 2, Block.cloth.blockID, 15);
		world.setBlockAndMetadata(i + 14, j + 8, k + 3, Block.cloth.blockID, 15);
		world.setBlockAndMetadata(i + 14, j + 8, k + 4, Block.cloth.blockID, 15);
		world.setBlockAndMetadata(i + 14, j + 8, k + 5, Block.cloth.blockID, 15);
		world.setBlockAndMetadata(i + 14, j + 8, k + 6, Block.cloth.blockID, 15);
		world.setBlockAndMetadata(i + 14, j + 8, k + 7, Block.cloth.blockID, 15);
		world.setBlockAndMetadata(i + 14, j + 8, k + 8, Block.cloth.blockID, 15);
		world.setBlockAndMetadata(i + 14, j + 8, k + 9, Block.cloth.blockID, 15);
		world.setBlockAndMetadata(i + 14, j + 8, k + 10, Block.cloth.blockID, 15);
		world.setBlockAndMetadata(i + 14, j + 8, k + 11, Block.cloth.blockID, 15);
		world.setBlockAndMetadata(i + 14, j + 8, k + 12, Block.cloth.blockID, 15);
		world.setBlockAndMetadata(i + 14, j + 8, k + 13, Block.cloth.blockID, 15);
		world.setBlockAndMetadata(i + 14, j + 8, k + 14, Block.cloth.blockID, 15);
		world.setBlockAndMetadata(i + 14, j + 8, k + 15, Block.cloth.blockID, 15);
		world.setBlockAndMetadata(i + 14, j + 8, k + 16, Block.cloth.blockID, 15);
		world.setBlockAndMetadata(i + 14, j + 8, k + 17, Block.cloth.blockID, 15);
		world.setBlockAndMetadata(i + 14, j + 8, k + 18, Block.cloth.blockID, 15);
		world.setBlockAndMetadata(i + 14, j + 8, k + 19, Block.cloth.blockID, 15);
		world.setBlockAndMetadata(i + 14, j + 8, k + 20, Block.cloth.blockID, 15);
		world.setBlockAndMetadata(i + 14, j + 9, k + 2, Block.cloth.blockID, 15);
		world.setBlockAndMetadata(i + 14, j + 9, k + 3, Block.cloth.blockID, 15);
		world.setBlockAndMetadata(i + 14, j + 9, k + 4, Block.cloth.blockID, 15);
		world.setBlockAndMetadata(i + 14, j + 9, k + 5, Block.cloth.blockID, 15);
		world.setBlockAndMetadata(i + 14, j + 9, k + 6, Block.cloth.blockID, 15);
		world.setBlockAndMetadata(i + 14, j + 9, k + 7, Block.cloth.blockID, 15);
		world.setBlockAndMetadata(i + 14, j + 9, k + 8, Block.cloth.blockID, 15);
		world.setBlockAndMetadata(i + 14, j + 9, k + 9, Block.cloth.blockID, 15);
		world.setBlockAndMetadata(i + 14, j + 9, k + 10, Block.cloth.blockID, 15);
		world.setBlockAndMetadata(i + 14, j + 9, k + 11, Block.cloth.blockID, 15);
		world.setBlockAndMetadata(i + 14, j + 9, k + 12, Block.cloth.blockID, 15);
		world.setBlockAndMetadata(i + 14, j + 9, k + 13, Block.cloth.blockID, 15);
		world.setBlockAndMetadata(i + 14, j + 9, k + 14, Block.cloth.blockID, 15);
		world.setBlockAndMetadata(i + 14, j + 9, k + 15, Block.cloth.blockID, 15);
		world.setBlockAndMetadata(i + 14, j + 9, k + 16, Block.cloth.blockID, 15);
		world.setBlockAndMetadata(i + 14, j + 9, k + 17, Block.cloth.blockID, 15);
		world.setBlockAndMetadata(i + 14, j + 9, k + 18, Block.cloth.blockID, 15);
		world.setBlockAndMetadata(i + 14, j + 9, k + 19, Block.cloth.blockID, 15);
		world.setBlockAndMetadata(i + 14, j + 9, k + 20, Block.cloth.blockID, 15);
		world.setBlockAndMetadata(i + 14, j + 10, k + 1, Block.cloth.blockID, 15);
		world.setBlockAndMetadata(i + 14, j + 10, k + 2, Block.cloth.blockID, 15);
		world.setBlockAndMetadata(i + 14, j + 10, k + 3, Block.cloth.blockID, 15);
		world.setBlockAndMetadata(i + 14, j + 10, k + 4, Block.cloth.blockID, 15);
		world.setBlockAndMetadata(i + 14, j + 10, k + 5, Block.cloth.blockID, 15);
		world.setBlockAndMetadata(i + 14, j + 10, k + 6, Block.cloth.blockID, 15);
		world.setBlockAndMetadata(i + 14, j + 10, k + 7, Block.cloth.blockID, 15);
		world.setBlockAndMetadata(i + 14, j + 10, k + 8, Block.cloth.blockID, 15);
		world.setBlockAndMetadata(i + 14, j + 10, k + 9, Block.cloth.blockID, 15);
		world.setBlockAndMetadata(i + 14, j + 10, k + 10, Block.cloth.blockID, 15);
		world.setBlockAndMetadata(i + 14, j + 10, k + 11, Block.cloth.blockID, 15);
		world.setBlockAndMetadata(i + 14, j + 10, k + 12, Block.cloth.blockID, 15);
		world.setBlockAndMetadata(i + 14, j + 10, k + 13, Block.cloth.blockID, 15);
		world.setBlockAndMetadata(i + 14, j + 10, k + 14, Block.cloth.blockID, 15);
		world.setBlockAndMetadata(i + 14, j + 10, k + 15, Block.cloth.blockID, 15);
		world.setBlockAndMetadata(i + 14, j + 10, k + 16, Block.cloth.blockID, 15);
		world.setBlockAndMetadata(i + 14, j + 10, k + 17, Block.cloth.blockID, 15);
		world.setBlockAndMetadata(i + 14, j + 10, k + 18, Block.cloth.blockID, 15);
		world.setBlockAndMetadata(i + 14, j + 10, k + 19, Block.cloth.blockID, 15);
		world.setBlockAndMetadata(i + 14, j + 10, k + 20, Block.cloth.blockID, 15);
		world.setBlockAndMetadata(i + 14, j + 10, k + 21, Block.cloth.blockID, 15);
		world.setBlockAndMetadata(i + 14, j + 11, k + 1, Block.cloth.blockID, 15);
		world.setBlock(i + 14, j + 11, k + 2, Block.planks.blockID);
		world.setBlock(i + 14, j + 11, k + 3, Block.planks.blockID);
		world.setBlock(i + 14, j + 11, k + 4, Block.planks.blockID);
		world.setBlock(i + 14, j + 11, k + 5, Block.planks.blockID);
		world.setBlock(i + 14, j + 11, k + 6, Block.planks.blockID);
		world.setBlock(i + 14, j + 11, k + 7, Block.planks.blockID);
		world.setBlock(i + 14, j + 11, k + 8, Block.planks.blockID);
		world.setBlock(i + 14, j + 11, k + 9, Block.planks.blockID);
		world.setBlock(i + 14, j + 11, k + 10, Block.planks.blockID);
		world.setBlock(i + 14, j + 11, k + 11, Block.planks.blockID);
		world.setBlock(i + 14, j + 11, k + 12, Block.planks.blockID);
		world.setBlock(i + 14, j + 11, k + 13, Block.planks.blockID);
		world.setBlock(i + 14, j + 11, k + 14, Block.planks.blockID);
		world.setBlock(i + 14, j + 11, k + 15, Block.planks.blockID);
		world.setBlock(i + 14, j + 11, k + 16, Block.planks.blockID);
		world.setBlock(i + 14, j + 11, k + 17, Block.planks.blockID);
		world.setBlock(i + 14, j + 11, k + 18, Block.planks.blockID);
		world.setBlock(i + 14, j + 11, k + 19, Block.planks.blockID);
		world.setBlock(i + 14, j + 11, k + 20, Block.planks.blockID);
		world.setBlockAndMetadata(i + 14, j + 11, k + 21, Block.cloth.blockID, 15);
		world.setBlockAndMetadata(i + 14, j + 12, k + 1, Block.cloth.blockID, 15);
		world.setBlock(i + 14, j + 12, k + 3, Block.bookShelf.blockID);
		world.setBlock(i + 14, j + 12, k + 4, Block.bookShelf.blockID);
		world.setBlock(i + 14, j + 12, k + 9, Block.stairsNetherBrick.blockID);
		world.setBlock(i + 14, j + 12, k + 11, Block.stairsNetherBrick.blockID);
		world.setBlock(i + 14, j + 12, k + 13, Block.stairsNetherBrick.blockID);
		world.setBlock(i + 14, j + 12, k + 18, Block.bookShelf.blockID);
		world.setBlock(i + 14, j + 12, k + 19, Block.bookShelf.blockID);
