package fossil.gens;

import java.util.Random;

import net.minecraft.block.Block;
import net.minecraft.item.Item;
import net.minecraft.item.ItemStack;
import net.minecraft.tileentity.TileEntityChest;
import net.minecraft.world.World;
import net.minecraft.world.gen.feature.WorldGenerator;

public class WorldGeneratorShipWreck270 extends WorldGenerator
{
	
	public boolean generate(World world, Random rand, int i, int j, int k)
	{
		System.out.println("Generating ShipWreck270");
		world.setBlock(i + 0, j + 13, k + 6, Block.planks.blockID);
		world.setBlock(i + 1, j + 12, k + 6, Block.planks.blockID);
		world.setBlock(i + 1, j + 13, k + 6, Block.planks.blockID);
		world.setBlock(i + 2, j + 10, k + 6, Block.planks.blockID);
		world.setBlock(i + 2, j + 11, k + 6, Block.planks.blockID);
		world.setBlock(i + 2, j + 12, k + 6, Block.planks.blockID);
		world.setBlock(i + 3, j + 9, k + 5, Block.planks.blockID);
		world.setBlock(i + 3, j + 9, k + 6, Block.planks.blockID);
		world.setBlock(i + 3, j + 10, k + 5, Block.planks.blockID);
		world.setBlock(i + 3, j + 10, k + 6, Block.planks.blockID);
		world.setBlock(i + 3, j + 10, k + 7, Block.planks.blockID);
		world.setBlock(i + 3, j + 11, k + 5, Block.planks.blockID);
		world.setBlock(i + 3, j + 11, k + 6, Block.planks.blockID);
		world.setBlock(i + 3, j + 11, k + 7, Block.planks.blockID);
		world.setBlock(i + 3, j + 12, k + 5, Block.fence.blockID);
		world.setBlock(i + 3, j + 12, k + 7, Block.fence.blockID);
		world.setBlock(i + 4, j + 8, k + 5, Block.planks.blockID);
		world.setBlock(i + 4, j + 8, k + 6, Block.planks.blockID);
		world.setBlock(i + 4, j + 9, k + 5, Block.planks.blockID);
		world.setBlock(i + 4, j + 9, k + 6, Block.planks.blockID);
		world.setBlock(i + 4, j + 9, k + 7, Block.planks.blockID);
		world.setBlock(i + 4, j + 10, k + 4, Block.planks.blockID);
		world.setBlock(i + 4, j + 10, k + 5, Block.planks.blockID);
		world.setBlock(i + 4, j + 10, k + 7, Block.planks.blockID);
		world.setBlock(i + 4, j + 10, k + 8, Block.planks.blockID);
		world.setBlock(i + 4, j + 11, k + 4, Block.planks.blockID);
		world.setBlock(i + 4, j + 11, k + 5, Block.planks.blockID);
		world.setBlock(i + 4, j + 11, k + 6, Block.planks.blockID);
		world.setBlock(i + 4, j + 11, k + 7, Block.planks.blockID);
		world.setBlock(i + 4, j + 11, k + 8, Block.planks.blockID);
		world.setBlock(i + 4, j + 12, k + 4, Block.fence.blockID);
		world.setBlock(i + 4, j + 12, k + 5, Block.fence.blockID);
		world.setBlock(i + 4, j + 12, k + 7, Block.fence.blockID);
		world.setBlock(i + 4, j + 12, k + 8, Block.fence.blockID);
		world.setBlock(i + 5, j + 6, k + 5, Block.planks.blockID);
		world.setBlock(i + 5, j + 6, k + 6, Block.planks.blockID);
		world.setBlock(i + 5, j + 7, k + 4, Block.planks.blockID);
		world.setBlock(i + 5, j + 7, k + 5, Block.planks.blockID);
		world.setBlock(i + 5, j + 7, k + 6, Block.planks.blockID);
		world.setBlock(i + 5, j + 7, k + 7, Block.planks.blockID);
		world.setBlock(i + 5, j + 8, k + 4, Block.planks.blockID);
		world.setBlock(i + 5, j + 8, k + 5, Block.planks.blockID);
		world.setBlock(i + 5, j + 8, k + 6, Block.planks.blockID);
		world.setBlock(i + 5, j + 8, k + 7, Block.planks.blockID);
		world.setBlock(i + 5, j + 9, k + 4, Block.planks.blockID);
		world.setBlock(i + 5, j + 9, k + 8, Block.planks.blockID);
		world.setBlock(i + 5, j + 10, k + 3, Block.planks.blockID);
		world.setBlock(i + 5, j + 10, k + 4, Block.planks.blockID);
		world.setBlock(i + 5, j + 10, k + 8, Block.planks.blockID);
		world.setBlock(i + 5, j + 10, k + 9, Block.planks.blockID);
		world.setBlock(i + 5, j + 11, k + 3, Block.planks.blockID);
		world.setBlock(i + 5, j + 11, k + 4, Block.planks.blockID);
		world.setBlock(i + 5, j + 11, k + 5, Block.planks.blockID);
		world.setBlock(i + 5, j + 11, k + 6, Block.planks.blockID);
		world.setBlock(i + 5, j + 11, k + 7, Block.planks.blockID);
		world.setBlock(i + 5, j + 11, k + 8, Block.planks.blockID);
		world.setBlock(i + 5, j + 11, k + 9, Block.planks.blockID);
		world.setBlock(i + 5, j + 12, k + 3, Block.fence.blockID);
		world.setBlock(i + 5, j + 12, k + 4, Block.fence.blockID);
		world.setBlock(i + 5, j + 12, k + 8, Block.fence.blockID);
		world.setBlock(i + 5, j + 12, k + 9, Block.fence.blockID);
		world.setBlock(i + 6, j + 5, k + 5, Block.planks.blockID);
		world.setBlock(i + 6, j + 5, k + 6, Block.planks.blockID);
		world.setBlock(i + 6, j + 6, k + 3, Block.planks.blockID);
		world.setBlock(i + 6, j + 6, k + 4, Block.planks.blockID);
		world.setBlock(i + 6, j + 6, k + 5, Block.planks.blockID);
		world.setBlock(i + 6, j + 6, k + 6, Block.planks.blockID);
		world.setBlock(i + 6, j + 6, k + 7, Block.planks.blockID);
		world.setBlock(i + 6, j + 7, k + 2, Block.planks.blockID);
		world.setBlock(i + 6, j + 7, k + 3, Block.planks.blockID);
		world.setBlock(i + 6, j + 7, k + 4, Block.planks.blockID);
		world.setBlockAndMetadata(i + 6, j + 7, k + 5, Block.stoneOvenIdle.blockID, 5);
		world.setBlockAndMetadata(i + 6, j + 7, k + 6, Block.stoneOvenIdle.blockID, 5);
		world.setBlock(i + 6, j + 7, k + 7, Block.planks.blockID);
		world.setBlock(i + 6, j + 7, k + 8, Block.planks.blockID);
		world.setBlock(i + 6, j + 7, k + 9, Block.planks.blockID);
		world.setBlock(i + 6, j + 8, k + 2, Block.planks.blockID);
		world.setBlock(i + 6, j + 8, k + 3, Block.planks.blockID);
		world.setBlock(i + 6, j + 8, k + 4, Block.planks.blockID);
		world.setBlock(i + 6, j + 8, k + 5, Block.planks.blockID);
		world.setBlock(i + 6, j + 8, k + 6, Block.planks.blockID);
		world.setBlock(i + 6, j + 8, k + 7, Block.planks.blockID);
		world.setBlock(i + 6, j + 8, k + 8, Block.planks.blockID);
		world.setBlock(i + 6, j + 8, k + 9, Block.planks.blockID);
		world.setBlock(i + 6, j + 9, k + 2, Block.planks.blockID);
		world.setBlock(i + 6, j + 9, k + 3, Block.planks.blockID);
		world.setBlock(i + 6, j + 9, k + 4, Block.planks.blockID);
		world.setBlock(i + 6, j + 9, k + 5, Block.planks.blockID);
		world.setBlock(i + 6, j + 9, k + 6, Block.planks.blockID);
		world.setBlock(i + 6, j + 9, k + 7, Block.planks.blockID);
		world.setBlock(i + 6, j + 9, k + 8, Block.planks.blockID);
		world.setBlock(i + 6, j + 9, k + 9, Block.planks.blockID);
		world.setBlock(i + 6, j + 10, k + 3, Block.planks.blockID);
		world.setBlock(i + 6, j + 10, k + 4, Block.planks.blockID);
		world.setBlock(i + 6, j + 10, k + 5, Block.planks.blockID);
		world.setBlock(i + 6, j + 10, k + 6, Block.planks.blockID);
		world.setBlock(i + 6, j + 10, k + 7, Block.planks.blockID);
		world.setBlock(i + 6, j + 10, k + 8, Block.planks.blockID);
		world.setBlock(i + 6, j + 10, k + 9, Block.planks.blockID);
		world.setBlock(i + 6, j + 11, k + 3, Block.planks.blockID);
		world.setBlock(i + 6, j + 11, k + 4, Block.planks.blockID);
		world.setBlock(i + 6, j + 11, k + 5, Block.planks.blockID);
		world.setBlock(i + 6, j + 11, k + 6, Block.planks.blockID);
		world.setBlock(i + 6, j + 11, k + 7, Block.planks.blockID);
		world.setBlock(i + 6, j + 11, k + 8, Block.planks.blockID);
		world.setBlock(i + 6, j + 11, k + 9, Block.planks.blockID);
		world.setBlock(i + 6, j + 12, k + 3, Block.fence.blockID);
		world.setBlock(i + 6, j + 12, k + 9, Block.fence.blockID);
		world.setBlock(i + 7, j + 3, k + 7, Block.planks.blockID);
		world.setBlock(i + 7, j + 4, k + 4, Block.planks.blockID);
		world.setBlock(i + 7, j + 4, k + 5, Block.planks.blockID);
		world.setBlock(i + 7, j + 4, k + 6, Block.planks.blockID);
		world.setBlock(i + 7, j + 4, k + 7, Block.planks.blockID);
		world.setBlock(i + 7, j + 5, k + 4, Block.planks.blockID);
		world.setBlock(i + 7, j + 5, k + 5, Block.planks.blockID);
		world.setBlock(i + 7, j + 5, k + 6, Block.planks.blockID);
		world.setBlock(i + 7, j + 5, k + 7, Block.planks.blockID);
		world.setBlock(i + 7, j + 6, k + 3, Block.planks.blockID);
		world.setBlock(i + 7, j + 6, k + 4, Block.workbench.blockID);
		world.setBlockAndMetadata(i + 7, j + 6, k + 5, Block.stoneOvenIdle.blockID, 5);
		world.setBlockAndMetadata(i + 7, j + 6, k + 6, Block.stoneOvenIdle.blockID, 5);
		world.setBlock(i + 7, j + 6, k + 7, Block.planks.blockID);
		world.setBlock(i + 7, j + 6, k + 8, Block.planks.blockID);
		world.setBlock(i + 7, j + 7, k + 1, Block.planks.blockID);
		world.setBlock(i + 7, j + 7, k + 2, Block.planks.blockID);
		world.setBlockAndMetadata(i + 7, j + 7, k + 3, Block.chest.blockID, 3);
		world.setBlock(i + 7, j + 7, k + 9, Block.planks.blockID);
		world.setBlock(i + 7, j + 7, k + 10, Block.planks.blockID);
		world.setBlock(i + 7, j + 8, k + 1, Block.planks.blockID);
		world.setBlock(i + 7, j + 8, k + 2, Block.planks.blockID);
		world.setBlock(i + 7, j + 8, k + 3, Block.planks.blockID);
		world.setBlock(i + 7, j + 8, k + 4, Block.planks.blockID);
		world.setBlock(i + 7, j + 8, k + 5, Block.planks.blockID);
		world.setBlock(i + 7, j + 8, k + 6, Block.planks.blockID);
		world.setBlock(i + 7, j + 8, k + 7, Block.planks.blockID);
		world.setBlock(i + 7, j + 8, k + 8, Block.planks.blockID);
		world.setBlock(i + 7, j + 8, k + 9, Block.planks.blockID);
		world.setBlock(i + 7, j + 8, k + 10, Block.planks.blockID);
		world.setBlock(i + 7, j + 9, k + 1, Block.planks.blockID);
		world.setBlock(i + 7, j + 9, k + 5, Block.planks.blockID);
		world.setBlock(i + 7, j + 9, k + 6, Block.planks.blockID);
		world.setBlock(i + 7, j + 9, k + 10, Block.planks.blockID);
		world.setBlock(i + 7, j + 10, k + 1, Block.fence.blockID);
		world.setBlock(i + 7, j + 10, k + 5, Block.planks.blockID);
		world.setBlock(i + 7, j + 10, k + 6, Block.planks.blockID);
		world.setBlock(i + 7, j + 10, k + 10, Block.fence.blockID);
		world.setBlockAndMetadata(i + 7, j + 11, k + 5, Block.stairCompactPlanks.blockID, 1);
		world.setBlockAndMetadata(i + 7, j + 11, k + 6, Block.stairCompactPlanks.blockID, 1);
		world.setBlock(i + 8, j + 3, k + 4, Block.planks.blockID);
		world.setBlock(i + 8, j + 3, k + 5, Block.planks.blockID);
		world.setBlock(i + 8, j + 3, k + 6, Block.planks.blockID);
		world.setBlock(i + 8, j + 3, k + 7, Block.planks.blockID);
		world.setBlock(i + 8, j + 4, k + 4, Block.planks.blockID);
		world.setBlockAndMetadata(i + 8, j + 4, k + 5, Block.stoneOvenIdle.blockID, 5);
		world.setBlockAndMetadata(i + 8, j + 4, k + 6, Block.stoneOvenIdle.blockID, 5);
		world.setBlock(i + 8, j + 4, k + 7, Block.planks.blockID);
		world.setBlock(i + 8, j + 5, k + 4, Block.planks.blockID);
		world.setBlock(i + 8, j + 5, k + 5, Block.planks.blockID);
		world.setBlock(i + 8, j + 5, k + 6, Block.planks.blockID);
		world.setBlock(i + 8, j + 5, k + 7, Block.planks.blockID);
		world.setBlock(i + 8, j + 6, k + 2, Block.planks.blockID);
		world.setBlock(i + 8, j + 6, k + 3, Block.planks.blockID);
		world.setBlockAndMetadata(i + 8, j + 6, k + 7, Block.chest.blockID, 2);
		world.setBlock(i + 8, j + 6, k + 8, Block.planks.blockID);
		world.setBlock(i + 8, j + 6, k + 9, Block.planks.blockID);
		world.setBlock(i + 8, j + 7, k + 1, Block.planks.blockID);
		world.setBlockAndMetadata(i + 8, j + 7, k + 2, Block.chest.blockID, 3);
		world.setBlockAndMetadata(i + 8, j + 7, k + 9, Block.chest.blockID, 2);
		TileEntityChest var9 = (TileEntityChest)world.getBlockTileEntity(i + 8, j + 7, k + 9);
        int var10;

        if (var9 != null)
        {
            for (var10 = 0; var10 < 8; ++var10)
            {
                ItemStack var11 = this.pickCheckLootItem(rand);

                if (var11 != null)
                {
                    var9.setInventorySlotContents(rand.nextInt(var9.getSizeInventory()), var11);
                }
            }
        }
		world.setBlock(i + 8, j + 7, k + 10, Block.planks.blockID);
		world.setBlock(i + 8, j + 8, k + 1, Block.planks.blockID);
		world.setBlock(i + 8, j + 8, k + 2, Block.planks.blockID);
		world.setBlock(i + 8, j + 8, k + 3, Block.planks.blockID);
		world.setBlock(i + 8, j + 8, k + 4, Block.planks.blockID);
		world.setBlock(i + 8, j + 8, k + 5, Block.planks.blockID);
		world.setBlock(i + 8, j + 8, k + 6, Block.planks.blockID);
		world.setBlock(i + 8, j + 8, k + 7, Block.planks.blockID);
		world.setBlock(i + 8, j + 8, k + 8, Block.planks.blockID);
		world.setBlock(i + 8, j + 8, k + 9, Block.planks.blockID);
		world.setBlock(i + 8, j + 8, k + 10, Block.planks.blockID);
		world.setBlock(i + 8, j + 9, k + 1, Block.planks.blockID);
		world.setBlock(i + 8, j + 9, k + 5, Block.planks.blockID);
		world.setBlock(i + 8, j + 9, k + 6, Block.planks.blockID);
		world.setBlock(i + 8, j + 9, k + 10, Block.planks.blockID);
		world.setBlock(i + 8, j + 10, k + 1, Block.fence.blockID);
		world.setBlockAndMetadata(i + 8, j + 10, k + 5, Block.stairCompactPlanks.blockID, 1);
		world.setBlockAndMetadata(i + 8, j + 10, k + 6, Block.stairCompactPlanks.blockID, 1);
		world.setBlock(i + 8, j + 10, k + 10, Block.fence.blockID);
		world.setBlock(i + 9, j + 2, k + 5, Block.planks.blockID);
		world.setBlock(i + 9, j + 2, k + 6, Block.planks.blockID);
		world.setBlock(i + 9, j + 3, k + 3, Block.planks.blockID);
		world.setBlock(i + 9, j + 3, k + 4, Block.planks.blockID);
		world.setBlockAndMetadata(i + 9, j + 3, k + 5, Block.stoneOvenIdle.blockID, 5);
		world.setBlockAndMetadata(i + 9, j + 3, k + 6, Block.stoneOvenIdle.blockID, 5);
		world.setBlock(i + 9, j + 3, k + 7, Block.planks.blockID);
		world.setBlock(i + 9, j + 3, k + 8, Block.planks.blockID);
		world.setBlock(i + 9, j + 4, k + 3, Block.planks.blockID);
		world.setBlock(i + 9, j + 4, k + 4, Block.planks.blockID);
		world.setBlock(i + 9, j + 4, k + 7, Block.planks.blockID);
		world.setBlock(i + 9, j + 4, k + 8, Block.planks.blockID);
		world.setBlock(i + 9, j + 5, k + 3, Block.planks.blockID);
		world.setBlock(i + 9, j + 5, k + 4, Block.planks.blockID);
		world.setBlock(i + 9, j + 5, k + 5, Block.planks.blockID);
		world.setBlock(i + 9, j + 5, k + 6, Block.planks.blockID);
		world.setBlock(i + 9, j + 5, k + 7, Block.planks.blockID);
		world.setBlock(i + 9, j + 5, k + 8, Block.planks.blockID);
		world.setBlock(i + 9, j + 6, k + 2, Block.planks.blockID);
		world.setBlockAndMetadata(i + 9, j + 6, k + 8, Block.chest.blockID, 2);
		world.setBlock(i + 9, j + 6, k + 9, Block.planks.blockID);
		world.setBlock(i + 9, j + 7, k + 1, Block.planks.blockID);
		world.setBlockAndMetadata(i + 9, j + 7, k + 9, Block.chest.blockID, 2);
		TileEntityChest var12 = (TileEntityChest)world.getBlockTileEntity(i + 9, j + 7, k + 9);
        int var13;

        if (var12 != null)
        {
            for (var13 = 0; var13 < 8; ++var13)
            {
                ItemStack var11 = this.pickCheckLootItem(rand);

                if (var11 != null)
                {
                    var12.setInventorySlotContents(rand.nextInt(var12.getSizeInventory()), var11);
                }
            }
        }
		world.setBlock(i + 9, j + 7, k + 10, Block.planks.blockID);
		world.setBlock(i + 9, j + 8, k + 1, Block.planks.blockID);
		world.setBlock(i + 9, j + 8, k + 2, Block.planks.blockID);
		world.setBlock(i + 9, j + 8, k + 3, Block.planks.blockID);
		world.setBlock(i + 9, j + 8, k + 4, Block.planks.blockID);
		world.setBlock(i + 9, j + 8, k + 5, Block.planks.blockID);
		world.setBlock(i + 9, j + 8, k + 6, Block.planks.blockID);
		world.setBlock(i + 9, j + 8, k + 7, Block.planks.blockID);
		world.setBlock(i + 9, j + 8, k + 8, Block.planks.blockID);
		world.setBlock(i + 9, j + 8, k + 9, Block.planks.blockID);
		world.setBlock(i + 9, j + 8, k + 10, Block.planks.blockID);
		world.setBlock(i + 9, j + 9, k + 1, Block.planks.blockID);
		world.setBlockAndMetadata(i + 9, j + 9, k + 5, Block.stairCompactPlanks.blockID, 1);
		world.setBlockAndMetadata(i + 9, j + 9, k + 6, Block.stairCompactPlanks.blockID, 1);
		world.setBlock(i + 9, j + 9, k + 10, Block.planks.blockID);
		world.setBlock(i + 9, j + 10, k + 1, Block.fence.blockID);
		world.setBlock(i + 9, j + 10, k + 10, Block.fence.blockID);
		world.setBlock(i + 10, j + 1, k + 5, Block.planks.blockID);
		world.setBlock(i + 10, j + 1, k + 6, Block.planks.blockID);
		world.setBlock(i + 10, j + 2, k + 3, Block.planks.blockID);
		world.setBlock(i + 10, j + 2, k + 4, Block.planks.blockID);
		world.setBlock(i + 10, j + 2, k + 5, Block.planks.blockID);
		world.setBlock(i + 10, j + 2, k + 6, Block.planks.blockID);
		world.setBlock(i + 10, j + 2, k + 7, Block.planks.blockID);
		world.setBlock(i + 10, j + 3, k + 3, Block.planks.blockID);
		world.setBlockAndMetadata(i + 10, j + 3, k + 4, Block.chest.blockID, 3);
		world.setBlockAndMetadata(i + 10, j + 3, k + 7, Block.chest.blockID, 2);
		world.setBlock(i + 10, j + 3, k + 8, Block.planks.blockID);
		world.setBlock(i + 10, j + 4, k + 3, Block.planks.blockID);
		world.setBlock(i + 10, j + 4, k + 8, Block.planks.blockID);
		world.setBlock(i + 10, j + 5, k + 3, Block.planks.blockID);
		world.setBlock(i + 10, j + 5, k + 4, Block.planks.blockID);
		world.setBlock(i + 10, j + 5, k + 5, Block.planks.blockID);
		world.setBlock(i + 10, j + 5, k + 6, Block.planks.blockID);
		world.setBlock(i + 10, j + 5, k + 7, Block.planks.blockID);
		world.setBlock(i + 10, j + 5, k + 8, Block.planks.blockID);
		world.setBlock(i + 10, j + 6, k + 1, Block.planks.blockID);
		world.setBlock(i + 10, j + 6, k + 2, Block.planks.blockID);
		world.setBlockAndMetadata(i + 10, j + 6, k + 8, Block.chest.blockID, 2);
		TileEntityChest var14 = (TileEntityChest)world.getBlockTileEntity(i + 10, j + 6, k + 8);
        int var15;

        if (var14 != null)
        {
            for (var15 = 0; var15 < 8; ++var15)
            {
                ItemStack var11 = this.pickCheckLootItem(rand);

                if (var11 != null)
                {
                    var14.setInventorySlotContents(rand.nextInt(var14.getSizeInventory()), var11);
                }
            }
        }
		world.setBlock(i + 10, j + 6, k + 9, Block.planks.blockID);
		world.setBlock(i + 10, j + 7, k + 1, Block.planks.blockID);
		world.setBlockAndMetadata(i + 10, j + 7, k + 9, Block.chest.blockID, 2);
		world.setBlock(i + 10, j + 7, k + 10, Block.planks.blockID);
		world.setBlock(i + 10, j + 8, k + 1, Block.planks.blockID);
		world.setBlock(i + 10, j + 8, k + 2, Block.planks.blockID);
		world.setBlock(i + 10, j + 8, k + 3, Block.planks.blockID);
		world.setBlock(i + 10, j + 8, k + 4, Block.planks.blockID);
		world.setBlock(i + 10, j + 8, k + 5, Block.planks.blockID);
		world.setBlock(i + 10, j + 8, k + 6, Block.planks.blockID);
		world.setBlock(i + 10, j + 8, k + 7, Block.planks.blockID);
		world.setBlock(i + 10, j + 8, k + 8, Block.planks.blockID);
		world.setBlock(i + 10, j + 8, k + 9, Block.planks.blockID);
		world.setBlock(i + 10, j + 8, k + 10, Block.planks.blockID);
		world.setBlock(i + 10, j + 9, k + 1, Block.planks.blockID);
		world.setBlock(i + 10, j + 9, k + 10, Block.planks.blockID);
		world.setBlock(i + 10, j + 10, k + 1, Block.fence.blockID);
		world.setBlock(i + 10, j + 10, k + 10, Block.fence.blockID);
		world.setBlock(i + 11, j + 0, k + 5, Block.planks.blockID);
		world.setBlock(i + 11, j + 0, k + 6, Block.planks.blockID);
		world.setBlock(i + 11, j + 1, k + 5, Block.planks.blockID);
		world.setBlock(i + 11, j + 1, k + 6, Block.planks.blockID);
		world.setBlock(i + 11, j + 2, k + 3, Block.planks.blockID);
		world.setBlock(i + 11, j + 2, k + 4, Block.planks.blockID);
		world.setBlock(i + 11, j + 2, k + 5, Block.planks.blockID);
		world.setBlock(i + 11, j + 2, k + 6, Block.planks.blockID);
		world.setBlock(i + 11, j + 2, k + 7, Block.planks.blockID);
		world.setBlock(i + 11, j + 3, k + 2, Block.planks.blockID);
		world.setBlock(i + 11, j + 3, k + 3, Block.planks.blockID);
		world.setBlockAndMetadata(i + 11, j + 3, k + 4, Block.chest.blockID, 3);
		world.setBlock(i + 11, j + 3, k + 8, Block.planks.blockID);
		world.setBlock(i + 11, j + 3, k + 9, Block.planks.blockID);
		world.setBlock(i + 11, j + 4, k + 2, Block.planks.blockID);
		world.setBlock(i + 11, j + 4, k + 3, Block.planks.blockID);
		world.setBlock(i + 11, j + 4, k + 8, Block.planks.blockID);
		world.setBlock(i + 11, j + 4, k + 9, Block.planks.blockID);
		world.setBlock(i + 11, j + 5, k + 2, Block.planks.blockID);
		world.setBlock(i + 11, j + 5, k + 3, Block.planks.blockID);
		world.setBlock(i + 11, j + 5, k + 4, Block.planks.blockID);
		world.setBlock(i + 11, j + 5, k + 5, Block.planks.blockID);
		world.setBlock(i + 11, j + 5, k + 6, Block.planks.blockID);
		world.setBlock(i + 11, j + 5, k + 7, Block.planks.blockID);
		world.setBlock(i + 11, j + 5, k + 8, Block.planks.blockID);
		world.setBlock(i + 11, j + 5, k + 9, Block.planks.blockID);
		world.setBlock(i + 11, j + 6, k + 1, Block.planks.blockID);
		world.setBlock(i + 11, j + 6, k + 9, Block.planks.blockID);
		world.setBlock(i + 11, j + 7, k + 1, Block.planks.blockID);
		world.setBlockAndMetadata(i + 11, j + 7, k + 9, Block.chest.blockID, 2);
		world.setBlock(i + 11, j + 7, k + 10, Block.planks.blockID);
		world.setBlock(i + 11, j + 8, k + 1, Block.planks.blockID);
		world.setBlock(i + 11, j + 8, k + 2, Block.planks.blockID);
		world.setBlock(i + 11, j + 8, k + 3, Block.planks.blockID);
		world.setBlock(i + 11, j + 8, k + 4, Block.planks.blockID);
		world.setBlock(i + 11, j + 8, k + 5, Block.planks.blockID);
		world.setBlock(i + 11, j + 8, k + 6, Block.planks.blockID);
		world.setBlock(i + 11, j + 8, k + 7, Block.planks.blockID);
		world.setBlock(i + 11, j + 8, k + 8, Block.planks.blockID);
		world.setBlock(i + 11, j + 8, k + 9, Block.planks.blockID);
		world.setBlock(i + 11, j + 8, k + 10, Block.planks.blockID);
		world.setBlock(i + 11, j + 9, k + 1, Block.planks.blockID);
		world.setBlock(i + 11, j + 9, k + 10, Block.planks.blockID);
		world.setBlock(i + 11, j + 10, k + 1, Block.fence.blockID);
		world.setBlock(i + 11, j + 10, k + 10, Block.fence.blockID);
		world.setBlock(i + 12, j + 0, k + 5, Block.planks.blockID);
		world.setBlock(i + 12, j + 0, k + 6, Block.planks.blockID);
		world.setBlock(i + 12, j + 1, k + 4, Block.planks.blockID);
		world.setBlock(i + 12, j + 1, k + 7, Block.planks.blockID);
		world.setBlock(i + 12, j + 2, k + 3, Block.planks.blockID);
		world.setBlock(i + 12, j + 2, k + 4, Block.planks.blockID);
		world.setBlock(i + 12, j + 2, k + 5, Block.planks.blockID);
		world.setBlock(i + 12, j + 2, k + 6, Block.planks.blockID);
		world.setBlock(i + 12, j + 2, k + 7, Block.planks.blockID);
		world.setBlock(i + 12, j + 2, k + 8, Block.planks.blockID);
		world.setBlock(i + 12, j + 3, k + 2, Block.planks.blockID);
		world.setBlock(i + 12, j + 3, k + 9, Block.planks.blockID);
		world.setBlock(i + 12, j + 4, k + 2, Block.planks.blockID);
		world.setBlock(i + 12, j + 4, k + 9, Block.planks.blockID);
		world.setBlock(i + 12, j + 5, k + 2, Block.planks.blockID);
		world.setBlock(i + 12, j + 5, k + 3, Block.planks.blockID);
		world.setBlock(i + 12, j + 5, k + 4, Block.planks.blockID);
		world.setBlock(i + 12, j + 5, k + 5, Block.planks.blockID);
		world.setBlock(i + 12, j + 5, k + 6, Block.planks.blockID);
		world.setBlock(i + 12, j + 5, k + 7, Block.planks.blockID);
		world.setBlock(i + 12, j + 5, k + 8, Block.planks.blockID);
		world.setBlock(i + 12, j + 5, k + 9, Block.planks.blockID);
		world.setBlock(i + 12, j + 6, k + 1, Block.planks.blockID);
		world.setBlock(i + 12, j + 6, k + 2, Block.planks.blockID);
		world.setBlock(i + 12, j + 6, k + 3, Block.planks.blockID);
		world.setBlock(i + 12, j + 6, k + 4, Block.planks.blockID);
		world.setBlock(i + 12, j + 6, k + 5, Block.planks.blockID);
		world.setBlock(i + 12, j + 6, k + 6, Block.planks.blockID);
		world.setBlock(i + 12, j + 6, k + 7, Block.planks.blockID);
		world.setBlock(i + 12, j + 6, k + 9, Block.planks.blockID);
		world.setBlock(i + 12, j + 6, k + 10, Block.planks.blockID);
		world.setBlock(i + 12, j + 7, k + 1, Block.planks.blockID);
		world.setBlock(i + 12, j + 7, k + 2, Block.planks.blockID);
		world.setBlock(i + 12, j + 7, k + 3, Block.planks.blockID);
		world.setBlock(i + 12, j + 7, k + 4, Block.planks.blockID);
		world.setBlock(i + 12, j + 7, k + 5, Block.planks.blockID);
		world.setBlock(i + 12, j + 7, k + 6, Block.planks.blockID);
		world.setBlock(i + 12, j + 7, k + 7, Block.planks.blockID);
		world.setBlock(i + 12, j + 7, k + 9, Block.planks.blockID);
		world.setBlock(i + 12, j + 7, k + 10, Block.planks.blockID);
		world.setBlock(i + 12, j + 8, k + 1, Block.planks.blockID);
		world.setBlock(i + 12, j + 8, k + 2, Block.planks.blockID);
		world.setBlock(i + 12, j + 8, k + 3, Block.planks.blockID);
		world.setBlock(i + 12, j + 8, k + 4, Block.planks.blockID);
		world.setBlock(i + 12, j + 8, k + 5, Block.planks.blockID);
		world.setBlock(i + 12, j + 8, k + 6, Block.planks.blockID);
		world.setBlock(i + 12, j + 8, k + 7, Block.planks.blockID);
		world.setBlock(i + 12, j + 8, k + 8, Block.planks.blockID);
		world.setBlock(i + 12, j + 8, k + 9, Block.planks.blockID);
		world.setBlock(i + 12, j + 8, k + 10, Block.planks.blockID);
		world.setBlock(i + 12, j + 9, k + 1, Block.planks.blockID);
		world.setBlock(i + 12, j + 9, k + 10, Block.planks.blockID);
		world.setBlock(i + 12, j + 10, k + 1, Block.fence.blockID);
		world.setBlock(i + 12, j + 10, k + 10, Block.fence.blockID);
		world.setBlock(i + 13, j + 0, k + 5, Block.planks.blockID);
		world.setBlock(i + 13, j + 0, k + 6, Block.planks.blockID);
		world.setBlock(i + 13, j + 1, k + 4, Block.planks.blockID);
		world.setBlock(i + 13, j + 1, k + 7, Block.planks.blockID);
		world.setBlock(i + 13, j + 2, k + 3, Block.planks.blockID);
		world.setBlock(i + 13, j + 2, k + 4, Block.planks.blockID);
		world.setBlock(i + 13, j + 2, k + 5, Block.planks.blockID);
		world.setBlock(i + 13, j + 2, k + 6, Block.planks.blockID);
		world.setBlock(i + 13, j + 2, k + 7, Block.planks.blockID);
		world.setBlock(i + 13, j + 2, k + 8, Block.planks.blockID);
		world.setBlock(i + 13, j + 2, k + 9, Block.planks.blockID);
		world.setBlock(i + 13, j + 3, k + 1, Block.planks.blockID);
		world.setBlock(i + 13, j + 3, k + 2, Block.planks.blockID);
		world.setBlock(i + 13, j + 3, k + 3, Block.planks.blockID);
		world.setBlock(i + 13, j + 3, k + 5, Block.planks.blockID);
		world.setBlock(i + 13, j + 3, k + 6, Block.planks.blockID);
		world.setBlock(i + 13, j + 3, k + 7, Block.planks.blockID);
		world.setBlock(i + 13, j + 3, k + 8, Block.planks.blockID);
		world.setBlock(i + 13, j + 3, k + 9, Block.planks.blockID);
		world.setBlock(i + 13, j + 3, k + 10, Block.planks.blockID);
		world.setBlock(i + 13, j + 4, k + 1, Block.planks.blockID);
		world.setBlock(i + 13, j + 4, k + 2, Block.planks.blockID);
		world.setBlock(i + 13, j + 4, k + 3, Block.planks.blockID);
		world.setBlock(i + 13, j + 4, k + 5, Block.planks.blockID);
		world.setBlock(i + 13, j + 4, k + 6, Block.planks.blockID);
		world.setBlock(i + 13, j + 4, k + 7, Block.planks.blockID);
		world.setBlock(i + 13, j + 4, k + 8, Block.planks.blockID);
		world.setBlock(i + 13, j + 4, k + 9, Block.planks.blockID);
		world.setBlock(i + 13, j + 4, k + 10, Block.planks.blockID);
		world.setBlock(i + 13, j + 5, k + 1, Block.planks.blockID);
		world.setBlock(i + 13, j + 5, k + 2, Block.planks.blockID);
		world.setBlock(i + 13, j + 5, k + 3, Block.planks.blockID);
		world.setBlock(i + 13, j + 5, k + 4, Block.planks.blockID);
		world.setBlock(i + 13, j + 5, k + 5, Block.planks.blockID);
		world.setBlock(i + 13, j + 5, k + 6, Block.planks.blockID);
		world.setBlock(i + 13, j + 5, k + 7, Block.planks.blockID);
		world.setBlock(i + 13, j + 5, k + 8, Block.planks.blockID);
		world.setBlock(i + 13, j + 5, k + 9, Block.planks.blockID);
		world.setBlock(i + 13, j + 5, k + 10, Block.planks.blockID);
		world.setBlock(i + 13, j + 6, k + 1, Block.planks.blockID);
		world.setBlock(i + 13, j + 6, k + 10, Block.planks.blockID);
		world.setBlock(i + 13, j + 7, k + 1, Block.planks.blockID);
		world.setBlock(i + 13, j + 7, k + 10, Block.planks.blockID);
		world.setBlock(i + 13, j + 8, k + 1, Block.planks.blockID);
		world.setBlock(i + 13, j + 8, k + 2, Block.planks.blockID);
		world.setBlock(i + 13, j + 8, k + 3, Block.planks.blockID);
		world.setBlock(i + 13, j + 8, k + 4, Block.planks.blockID);
		world.setBlock(i + 13, j + 8, k + 5, Block.planks.blockID);
		world.setBlock(i + 13, j + 8, k + 6, Block.planks.blockID);
		world.setBlock(i + 13, j + 8, k + 7, Block.planks.blockID);
		world.setBlock(i + 13, j + 8, k + 8, Block.planks.blockID);
		world.setBlock(i + 13, j + 8, k + 9, Block.planks.blockID);
		world.setBlock(i + 13, j + 8, k + 10, Block.planks.blockID);
		world.setBlock(i + 13, j + 9, k + 1, Block.planks.blockID);
		world.setBlock(i + 13, j + 9, k + 10, Block.planks.blockID);
		world.setBlock(i + 13, j + 10, k + 1, Block.fence.blockID);
		world.setBlock(i + 13, j + 10, k + 10, Block.fence.blockID);
		world.setBlock(i + 14, j + 0, k + 4, Block.planks.blockID);
		world.setBlock(i + 14, j + 0, k + 5, Block.planks.blockID);
		world.setBlock(i + 14, j + 0, k + 6, Block.planks.blockID);
		world.setBlock(i + 14, j + 0, k + 7, Block.planks.blockID);
		world.setBlock(i + 14, j + 1, k + 3, Block.planks.blockID);
		world.setBlock(i + 14, j + 1, k + 4, Block.planks.blockID);
		world.setBlock(i + 14, j + 1, k + 7, Block.planks.blockID);
		world.setBlock(i + 14, j + 1, k + 8, Block.planks.blockID);
		world.setBlock(i + 14, j + 2, k + 2, Block.planks.blockID);
		world.setBlock(i + 14, j + 2, k + 3, Block.planks.blockID);
		world.setBlock(i + 14, j + 2, k + 4, Block.planks.blockID);
		world.setBlock(i + 14, j + 2, k + 5, Block.planks.blockID);
		world.setBlock(i + 14, j + 2, k + 6, Block.planks.blockID);
		world.setBlock(i + 14, j + 2, k + 7, Block.planks.blockID);
		world.setBlock(i + 14, j + 2, k + 8, Block.planks.blockID);
		world.setBlock(i + 14, j + 2, k + 9, Block.planks.blockID);
		world.setBlock(i + 14, j + 3, k + 1, Block.planks.blockID);
		world.setBlock(i + 14, j + 3, k + 5, Block.planks.blockID);
		world.setBlock(i + 14, j + 3, k + 8, Block.bed.blockID);
		world.setBlockAndMetadata(i + 14, j + 3, k + 9, Block.bed.blockID, 8);
		world.setBlock(i + 14, j + 3, k + 10, Block.planks.blockID);
		world.setBlock(i + 14, j + 4, k + 1, Block.planks.blockID);
		world.setBlock(i + 14, j + 4, k + 5, Block.planks.blockID);
		world.setBlock(i + 14, j + 4, k + 10, Block.planks.blockID);
		world.setBlock(i + 14, j + 5, k + 1, Block.planks.blockID);
		world.setBlock(i + 14, j + 5, k + 2, Block.planks.blockID);
		world.setBlock(i + 14, j + 5, k + 3, Block.planks.blockID);
		world.setBlock(i + 14, j + 5, k + 4, Block.planks.blockID);
		world.setBlock(i + 14, j + 5, k + 5, Block.planks.blockID);
		world.setBlock(i + 14, j + 5, k + 6, Block.planks.blockID);
		world.setBlock(i + 14, j + 5, k + 7, Block.planks.blockID);
		world.setBlock(i + 14, j + 5, k + 8, Block.planks.blockID);
		world.setBlock(i + 14, j + 5, k + 9, Block.planks.blockID);
		world.setBlock(i + 14, j + 5, k + 10, Block.planks.blockID);
		world.setBlock(i + 14, j + 6, k + 1, Block.planks.blockID);
		world.setBlock(i + 14, j + 6, k + 10, Block.planks.blockID);
		world.setBlock(i + 14, j + 7, k + 1, Block.planks.blockID);
		world.setBlock(i + 14, j + 7, k + 10, Block.planks.blockID);
		world.setBlock(i + 14, j + 8, k + 1, Block.planks.blockID);
		world.setBlock(i + 14, j + 8, k + 2, Block.planks.blockID);
		world.setBlock(i + 14, j + 8, k + 3, Block.planks.blockID);
		world.setBlock(i + 14, j + 8, k + 4, Block.planks.blockID);
		world.setBlock(i + 14, j + 8, k + 5, Block.planks.blockID);
		world.setBlock(i + 14, j + 8, k + 6, Block.planks.blockID);
		world.setBlock(i + 14, j + 8, k + 7, Block.planks.blockID);
		world.setBlock(i + 14, j + 8, k + 8, Block.planks.blockID);
		world.setBlock(i + 14, j + 8, k + 9, Block.planks.blockID);
		world.setBlock(i + 14, j + 8, k + 10, Block.planks.blockID);
		world.setBlock(i + 14, j + 9, k + 1, Block.planks.blockID);
		world.setBlock(i + 14, j + 9, k + 10, Block.planks.blockID);
		world.setBlock(i + 14, j + 10, k + 1, Block.fence.blockID);
		world.setBlock(i + 14, j + 10, k + 10, Block.fence.blockID);
		world.setBlock(i + 15, j + 0, k + 4, Block.planks.blockID);
		world.setBlock(i + 15, j + 0, k + 5, Block.planks.blockID);
		world.setBlock(i + 15, j + 0, k + 6, Block.planks.blockID);
		world.setBlock(i + 15, j + 0, k + 7, Block.planks.blockID);
		world.setBlock(i + 15, j + 1, k + 3, Block.planks.blockID);
		world.setBlock(i + 15, j + 1, k + 8, Block.planks.blockID);
		world.setBlock(i + 15, j + 2, k + 2, Block.planks.blockID);
		world.setBlock(i + 15, j + 2, k + 3, Block.planks.blockID);
		world.setBlock(i + 15, j + 2, k + 4, Block.planks.blockID);
		world.setBlock(i + 15, j + 2, k + 5, Block.planks.blockID);
		world.setBlock(i + 15, j + 2, k + 6, Block.planks.blockID);
		world.setBlock(i + 15, j + 2, k + 7, Block.planks.blockID);
		world.setBlock(i + 15, j + 2, k + 8, Block.planks.blockID);
		world.setBlock(i + 15, j + 2, k + 9, Block.planks.blockID);
		world.setBlock(i + 15, j + 3, k + 1, Block.planks.blockID);
		world.setBlock(i + 15, j + 3, k + 5, Block.planks.blockID);
		world.setBlock(i + 15, j + 3, k + 10, Block.planks.blockID);
		world.setBlock(i + 15, j + 4, k + 1, Block.planks.blockID);
		world.setBlock(i + 15, j + 4, k + 5, Block.planks.blockID);
		world.setBlock(i + 15, j + 4, k + 10, Block.planks.blockID);
		world.setBlock(i + 15, j + 5, k + 1, Block.planks.blockID);
		world.setBlock(i + 15, j + 5, k + 2, Block.planks.blockID);
		world.setBlock(i + 15, j + 5, k + 3, Block.planks.blockID);
		world.setBlock(i + 15, j + 5, k + 4, Block.planks.blockID);
		world.setBlock(i + 15, j + 5, k + 5, Block.planks.blockID);
		world.setBlock(i + 15, j + 5, k + 6, Block.planks.blockID);
		world.setBlock(i + 15, j + 5, k + 7, Block.planks.blockID);
		world.setBlock(i + 15, j + 5, k + 8, Block.planks.blockID);
		world.setBlock(i + 15, j + 5, k + 9, Block.planks.blockID);
		world.setBlock(i + 15, j + 5, k + 10, Block.planks.blockID);
		world.setBlockAndMetadata(i + 15, j + 6, k + 1, Block.dispenser.blockID, 2);
		world.setBlock(i + 15, j + 8, k + 1, Block.planks.blockID);
		world.setBlock(i + 15, j + 8, k + 2, Block.planks.blockID);
		world.setBlock(i + 15, j + 8, k + 3, Block.planks.blockID);
		world.setBlock(i + 15, j + 8, k + 4, Block.planks.blockID);
		world.setBlock(i + 15, j + 8, k + 5, Block.planks.blockID);
		world.setBlock(i + 15, j + 8, k + 6, Block.planks.blockID);
		world.setBlock(i + 15, j + 8, k + 7, Block.planks.blockID);
		world.setBlock(i + 15, j + 8, k + 8, Block.planks.blockID);
		world.setBlock(i + 15, j + 8, k + 9, Block.planks.blockID);
		world.setBlock(i + 15, j + 8, k + 10, Block.planks.blockID);
		world.setBlock(i + 15, j + 9, k + 1, Block.planks.blockID);
		world.setBlock(i + 15, j + 9, k + 10, Block.planks.blockID);
		world.setBlock(i + 15, j + 10, k + 1, Block.fence.blockID);
		world.setBlock(i + 15, j + 10, k + 10, Block.fence.blockID);
		world.setBlock(i + 16, j + 0, k + 4, Block.planks.blockID);
		world.setBlock(i + 16, j + 0, k + 5, Block.planks.blockID);
		world.setBlock(i + 16, j + 0, k + 6, Block.planks.blockID);
		world.setBlock(i + 16, j + 0, k + 7, Block.planks.blockID);
		world.setBlock(i + 16, j + 1, k + 3, Block.planks.blockID);
		world.setBlock(i + 16, j + 1, k + 8, Block.planks.blockID);
		world.setBlock(i + 16, j + 2, k + 2, Block.planks.blockID);
		world.setBlock(i + 16, j + 2, k + 3, Block.planks.blockID);
		world.setBlock(i + 16, j + 2, k + 4, Block.planks.blockID);
		world.setBlock(i + 16, j + 2, k + 5, Block.planks.blockID);
		world.setBlock(i + 16, j + 2, k + 6, Block.planks.blockID);
		world.setBlock(i + 16, j + 2, k + 7, Block.planks.blockID);
		world.setBlock(i + 16, j + 2, k + 8, Block.planks.blockID);
		world.setBlock(i + 16, j + 2, k + 9, Block.planks.blockID);
		world.setBlock(i + 16, j + 3, k + 1, Block.planks.blockID);
		world.setBlock(i + 16, j + 3, k + 5, Block.planks.blockID);
		world.setBlock(i + 16, j + 3, k + 10, Block.planks.blockID);
		world.setBlock(i + 16, j + 4, k + 1, Block.planks.blockID);
		world.setBlock(i + 16, j + 4, k + 5, Block.planks.blockID);
		world.setBlock(i + 16, j + 4, k + 10, Block.planks.blockID);
		world.setBlock(i + 16, j + 5, k + 1, Block.planks.blockID);
		world.setBlock(i + 16, j + 5, k + 2, Block.planks.blockID);
		world.setBlock(i + 16, j + 5, k + 3, Block.planks.blockID);
		world.setBlock(i + 16, j + 5, k + 4, Block.planks.blockID);
		world.setBlock(i + 16, j + 5, k + 5, Block.planks.blockID);
		world.setBlock(i + 16, j + 5, k + 6, Block.planks.blockID);
		world.setBlock(i + 16, j + 5, k + 7, Block.planks.blockID);
		world.setBlock(i + 16, j + 5, k + 8, Block.planks.blockID);
		world.setBlock(i + 16, j + 5, k + 9, Block.planks.blockID);
		world.setBlock(i + 16, j + 5, k + 10, Block.planks.blockID);
		world.setBlock(i + 16, j + 6, k + 1, Block.planks.blockID);
		world.setBlockAndMetadata(i + 16, j + 6, k + 5, Block.chest.blockID, 4);
		world.setBlockAndMetadata(i + 16, j + 6, k + 6, Block.chest.blockID, 4);
		world.setBlock(i + 16, j + 6, k + 10, Block.planks.blockID);
		world.setBlock(i + 16, j + 7, k + 1, Block.planks.blockID);
		world.setBlock(i + 16, j + 7, k + 10, Block.planks.blockID);
		world.setBlock(i + 16, j + 8, k + 1, Block.planks.blockID);
		world.setBlock(i + 16, j + 8, k + 2, Block.planks.blockID);
		world.setBlock(i + 16, j + 8, k + 3, Block.planks.blockID);
		world.setBlock(i + 16, j + 8, k + 4, Block.planks.blockID);
		world.setBlock(i + 16, j + 8, k + 5, Block.planks.blockID);
		world.setBlock(i + 16, j + 8, k + 6, Block.planks.blockID);
		world.setBlock(i + 16, j + 8, k + 7, Block.planks.blockID);
		world.setBlock(i + 16, j + 8, k + 8, Block.planks.blockID);
		world.setBlock(i + 16, j + 8, k + 9, Block.planks.blockID);
		world.setBlock(i + 16, j + 8, k + 10, Block.planks.blockID);
		world.setBlock(i + 17, j + 0, k + 4, Block.planks.blockID);
		world.setBlock(i + 17, j + 0, k + 5, Block.planks.blockID);
		world.setBlock(i + 17, j + 0, k + 6, Block.planks.blockID);
		world.setBlock(i + 17, j + 0, k + 7, Block.planks.blockID);
		world.setBlock(i + 17, j + 1, k + 3, Block.planks.blockID);
		world.setBlock(i + 17, j + 1, k + 8, Block.planks.blockID);
		world.setBlock(i + 17, j + 2, k + 2, Block.planks.blockID);
		world.setBlock(i + 17, j + 2, k + 3, Block.planks.blockID);
		world.setBlock(i + 17, j + 2, k + 4, Block.planks.blockID);
		world.setBlock(i + 17, j + 2, k + 5, Block.planks.blockID);
		world.setBlock(i + 17, j + 2, k + 6, Block.planks.blockID);
		world.setBlock(i + 17, j + 2, k + 7, Block.planks.blockID);
		world.setBlock(i + 17, j + 2, k + 8, Block.planks.blockID);
		world.setBlock(i + 17, j + 2, k + 9, Block.planks.blockID);
		world.setBlock(i + 17, j + 3, k + 1, Block.planks.blockID);
		world.setBlock(i + 17, j + 3, k + 10, Block.planks.blockID);
		world.setBlock(i + 17, j + 4, k + 1, Block.planks.blockID);
		world.setBlock(i + 17, j + 4, k + 10, Block.glass.blockID);
		world.setBlock(i + 17, j + 5, k + 1, Block.planks.blockID);
		world.setBlock(i + 17, j + 5, k + 2, Block.planks.blockID);
		world.setBlock(i + 17, j + 5, k + 3, Block.planks.blockID);
		world.setBlock(i + 17, j + 5, k + 4, Block.planks.blockID);
		world.setBlock(i + 17, j + 5, k + 5, Block.planks.blockID);
		world.setBlock(i + 17, j + 5, k + 6, Block.planks.blockID);
		world.setBlock(i + 17, j + 5, k + 7, Block.planks.blockID);
		world.setBlock(i + 17, j + 5, k + 8, Block.planks.blockID);
		world.setBlock(i + 17, j + 5, k + 9, Block.planks.blockID);
		world.setBlock(i + 17, j + 5, k + 10, Block.planks.blockID);
		world.setBlock(i + 17, j + 6, k + 1, Block.planks.blockID);
		world.setBlock(i + 17, j + 6, k + 10, Block.planks.blockID);
		world.setBlock(i + 17, j + 7, k + 1, Block.planks.blockID);
		world.setBlock(i + 17, j + 7, k + 10, Block.planks.blockID);
		world.setBlockAndMetadata(i + 17, j + 8, k + 0, Block.stoneSingleSlab.blockID, 2);
		world.setBlock(i + 17, j + 8, k + 1, Block.planks.blockID);
		world.setBlock(i + 17, j + 8, k + 2, Block.planks.blockID);
		world.setBlock(i + 17, j + 8, k + 3, Block.planks.blockID);
		world.setBlock(i + 17, j + 8, k + 4, Block.planks.blockID);
		world.setBlock(i + 17, j + 8, k + 5, Block.planks.blockID);
		world.setBlock(i + 17, j + 8, k + 6, Block.planks.blockID);
		world.setBlock(i + 17, j + 8, k + 7, Block.planks.blockID);
		world.setBlock(i + 17, j + 8, k + 8, Block.planks.blockID);
		world.setBlock(i + 17, j + 8, k + 9, Block.planks.blockID);
		world.setBlock(i + 17, j + 8, k + 10, Block.planks.blockID);
		world.setBlock(i + 17, j + 9, k + 10, Block.fence.blockID);
		world.setBlock(i + 18, j + 0, k + 4, Block.planks.blockID);
		world.setBlock(i + 18, j + 0, k + 5, Block.planks.blockID);
		world.setBlock(i + 18, j + 0, k + 6, Block.planks.blockID);
		world.setBlock(i + 18, j + 0, k + 7, Block.planks.blockID);
		world.setBlock(i + 18, j + 1, k + 3, Block.planks.blockID);
		world.setBlock(i + 18, j + 1, k + 8, Block.planks.blockID);
		world.setBlock(i + 18, j + 2, k + 2, Block.planks.blockID);
		world.setBlock(i + 18, j + 2, k + 3, Block.planks.blockID);
		world.setBlock(i + 18, j + 2, k + 4, Block.planks.blockID);
		world.setBlock(i + 18, j + 2, k + 5, Block.planks.blockID);
		world.setBlock(i + 18, j + 2, k + 6, Block.planks.blockID);
		world.setBlock(i + 18, j + 2, k + 7, Block.planks.blockID);
		world.setBlock(i + 18, j + 2, k + 8, Block.planks.blockID);
		world.setBlock(i + 18, j + 2, k + 9, Block.planks.blockID);
		world.setBlock(i + 18, j + 3, k + 1, Block.planks.blockID);
		world.setBlock(i + 18, j + 3, k + 5, Block.planks.blockID);
		world.setBlock(i + 18, j + 3, k + 10, Block.planks.blockID);
		world.setBlock(i + 18, j + 4, k + 1, Block.planks.blockID);
		world.setBlock(i + 18, j + 4, k + 5, Block.planks.blockID);
		world.setBlock(i + 18, j + 4, k + 10, Block.planks.blockID);
		world.setBlock(i + 18, j + 5, k + 1, Block.planks.blockID);
		world.setBlock(i + 18, j + 5, k + 2, Block.planks.blockID);
		world.setBlock(i + 18, j + 5, k + 3, Block.planks.blockID);
		world.setBlock(i + 18, j + 5, k + 4, Block.planks.blockID);
		world.setBlock(i + 18, j + 5, k + 5, Block.planks.blockID);
		world.setBlock(i + 18, j + 5, k + 6, Block.planks.blockID);
		world.setBlock(i + 18, j + 5, k + 7, Block.planks.blockID);
		world.setBlock(i + 18, j + 5, k + 8, Block.planks.blockID);
		world.setBlock(i + 18, j + 5, k + 9, Block.planks.blockID);
		world.setBlock(i + 18, j + 5, k + 10, Block.planks.blockID);
		world.setBlockAndMetadata(i + 18, j + 6, k + 1, Block.dispenser.blockID, 2);
		world.setBlockAndMetadata(i + 18, j + 6, k + 5, Block.chest.blockID, 4);
		world.setBlockAndMetadata(i + 18, j + 6, k + 6, Block.chest.blockID, 4);
		world.setBlock(i + 18, j + 8, k + 1, Block.planks.blockID);
		world.setBlock(i + 18, j + 8, k + 2, Block.planks.blockID);
		world.setBlock(i + 18, j + 8, k + 3, Block.planks.blockID);
		world.setBlock(i + 18, j + 8, k + 4, Block.planks.blockID);
		world.setBlock(i + 18, j + 8, k + 5, Block.planks.blockID);
		world.setBlock(i + 18, j + 8, k + 6, Block.planks.blockID);
		world.setBlock(i + 18, j + 8, k + 7, Block.planks.blockID);
		world.setBlock(i + 18, j + 8, k + 8, Block.planks.blockID);
		world.setBlock(i + 18, j + 8, k + 9, Block.planks.blockID);
		world.setBlock(i + 18, j + 8, k + 10, Block.planks.blockID);
		world.setBlock(i + 18, j + 9, k + 1, Block.fence.blockID);
		world.setBlock(i + 18, j + 9, k + 10, Block.fence.blockID);
		world.setBlock(i + 19, j + 0, k + 4, Block.planks.blockID);
		world.setBlock(i + 19, j + 0, k + 5, Block.planks.blockID);
		world.setBlock(i + 19, j + 0, k + 6, Block.planks.blockID);
		world.setBlock(i + 19, j + 0, k + 7, Block.planks.blockID);
		world.setBlock(i + 19, j + 1, k + 3, Block.planks.blockID);
		world.setBlock(i + 19, j + 1, k + 8, Block.planks.blockID);
		world.setBlock(i + 19, j + 2, k + 2, Block.planks.blockID);
		world.setBlock(i + 19, j + 2, k + 3, Block.planks.blockID);
		world.setBlock(i + 19, j + 2, k + 4, Block.planks.blockID);
		world.setBlock(i + 19, j + 2, k + 5, Block.planks.blockID);
		world.setBlock(i + 19, j + 2, k + 6, Block.planks.blockID);
		world.setBlock(i + 19, j + 2, k + 7, Block.planks.blockID);
		world.setBlock(i + 19, j + 2, k + 8, Block.planks.blockID);
		world.setBlock(i + 19, j + 2, k + 9, Block.planks.blockID);
		world.setBlock(i + 19, j + 3, k + 1, Block.planks.blockID);
		world.setBlock(i + 19, j + 3, k + 5, Block.planks.blockID);
		world.setBlock(i + 19, j + 3, k + 6, Block.planks.blockID);
		world.setBlock(i + 19, j + 3, k + 7, Block.planks.blockID);
		world.setBlock(i + 19, j + 3, k + 8, Block.planks.blockID);
		world.setBlock(i + 19, j + 3, k + 9, Block.planks.blockID);
		world.setBlock(i + 19, j + 3, k + 10, Block.planks.blockID);
		world.setBlock(i + 19, j + 4, k + 1, Block.planks.blockID);
		world.setBlock(i + 19, j + 4, k + 5, Block.planks.blockID);
		world.setBlock(i + 19, j + 4, k + 6, Block.planks.blockID);
		world.setBlock(i + 19, j + 4, k + 7, Block.planks.blockID);
		world.setBlock(i + 19, j + 4, k + 8, Block.planks.blockID);
		world.setBlock(i + 19, j + 4, k + 9, Block.planks.blockID);
		world.setBlock(i + 19, j + 4, k + 10, Block.planks.blockID);
		world.setBlock(i + 19, j + 5, k + 1, Block.planks.blockID);
		world.setBlock(i + 19, j + 5, k + 2, Block.planks.blockID);
		world.setBlock(i + 19, j + 5, k + 3, Block.planks.blockID);
		world.setBlock(i + 19, j + 5, k + 4, Block.planks.blockID);
		world.setBlock(i + 19, j + 5, k + 5, Block.planks.blockID);
		world.setBlock(i + 19, j + 5, k + 6, Block.planks.blockID);
		world.setBlock(i + 19, j + 5, k + 7, Block.planks.blockID);
		world.setBlock(i + 19, j + 5, k + 8, Block.planks.blockID);
		world.setBlock(i + 19, j + 5, k + 9, Block.planks.blockID);
		world.setBlock(i + 19, j + 5, k + 10, Block.planks.blockID);
		world.setBlock(i + 19, j + 6, k + 1, Block.planks.blockID);
		world.setBlock(i + 19, j + 6, k + 10, Block.planks.blockID);
		world.setBlock(i + 19, j + 7, k + 1, Block.planks.blockID);
		world.setBlock(i + 19, j + 7, k + 10, Block.planks.blockID);
		world.setBlock(i + 19, j + 8, k + 1, Block.planks.blockID);
		world.setBlock(i + 19, j + 8, k + 2, Block.planks.blockID);
		world.setBlock(i + 19, j + 8, k + 3, Block.planks.blockID);
		world.setBlock(i + 19, j + 8, k + 4, Block.planks.blockID);
		world.setBlock(i + 19, j + 8, k + 5, Block.planks.blockID);
		world.setBlock(i + 19, j + 8, k + 6, Block.planks.blockID);
		world.setBlock(i + 19, j + 8, k + 7, Block.planks.blockID);
		world.setBlock(i + 19, j + 8, k + 8, Block.planks.blockID);
		world.setBlock(i + 19, j + 8, k + 9, Block.planks.blockID);
		world.setBlock(i + 19, j + 8, k + 10, Block.planks.blockID);
		world.setBlock(i + 19, j + 9, k + 1, Block.fence.blockID);
		world.setBlock(i + 19, j + 9, k + 10, Block.fence.blockID);
		world.setBlock(i + 20, j + 0, k + 4, Block.planks.blockID);
		world.setBlock(i + 20, j + 0, k + 5, Block.planks.blockID);
		world.setBlock(i + 20, j + 0, k + 6, Block.planks.blockID);
		world.setBlock(i + 20, j + 0, k + 7, Block.planks.blockID);
		world.setBlock(i + 20, j + 1, k + 3, Block.planks.blockID);
		world.setBlock(i + 20, j + 1, k + 8, Block.planks.blockID);
		world.setBlock(i + 20, j + 2, k + 2, Block.planks.blockID);
		world.setBlock(i + 20, j + 2, k + 3, Block.planks.blockID);
		world.setBlock(i + 20, j + 2, k + 4, Block.planks.blockID);
		world.setBlock(i + 20, j + 2, k + 5, Block.planks.blockID);
		world.setBlock(i + 20, j + 2, k + 6, Block.planks.blockID);
		world.setBlock(i + 20, j + 2, k + 7, Block.planks.blockID);
		world.setBlock(i + 20, j + 2, k + 8, Block.planks.blockID);
		world.setBlock(i + 20, j + 2, k + 9, Block.planks.blockID);
		world.setBlock(i + 20, j + 3, k + 1, Block.planks.blockID);
		world.setBlock(i + 20, j + 3, k + 5, Block.planks.blockID);
		world.setBlock(i + 20, j + 3, k + 8, Block.bed.blockID);
		world.setBlockAndMetadata(i + 20, j + 3, k + 9, Block.bed.blockID, 8);
		world.setBlock(i + 20, j + 3, k + 10, Block.planks.blockID);
		world.setBlock(i + 20, j + 4, k + 1, Block.planks.blockID);
		world.setBlock(i + 20, j + 4, k + 5, Block.planks.blockID);
		world.setBlock(i + 20, j + 4, k + 10, Block.planks.blockID);
		world.setBlock(i + 20, j + 5, k + 1, Block.planks.blockID);
		world.setBlock(i + 20, j + 5, k + 2, Block.planks.blockID);
		world.setBlock(i + 20, j + 5, k + 3, Block.planks.blockID);
		world.setBlock(i + 20, j + 5, k + 4, Block.planks.blockID);
		world.setBlock(i + 20, j + 5, k + 5, Block.planks.blockID);
		world.setBlock(i + 20, j + 5, k + 6, Block.planks.blockID);
		world.setBlock(i + 20, j + 5, k + 7, Block.planks.blockID);
		world.setBlock(i + 20, j + 5, k + 8, Block.planks.blockID);
		world.setBlock(i + 20, j + 5, k + 9, Block.planks.blockID);
		world.setBlock(i + 20, j + 5, k + 10, Block.planks.blockID);
		world.setBlock(i + 20, j + 6, k + 1, Block.planks.blockID);
		world.setBlockAndMetadata(i + 20, j + 6, k + 5, Block.chest.blockID, 4);
		world.setBlockAndMetadata(i + 20, j + 6, k + 6, Block.chest.blockID, 4);
		TileEntityChest var16 = (TileEntityChest)world.getBlockTileEntity(i + 20, j + 6, k + 6);
        int var17;

        if (var16 != null)
        {
            for (var17 = 0; var17 < 8; ++var17)
            {
                ItemStack var11 = this.pickCheckLootItem(rand);

                if (var11 != null)
                {
                    var16.setInventorySlotContents(rand.nextInt(var16.getSizeInventory()), var11);
                }
            }
        }
		world.setBlock(i + 20, j + 6, k + 10, Block.planks.blockID);
		world.setBlock(i + 20, j + 7, k + 1, Block.planks.blockID);
		world.setBlock(i + 20, j + 7, k + 10, Block.planks.blockID);
		world.setBlock(i + 20, j + 8, k + 1, Block.planks.blockID);
		world.setBlock(i + 20, j + 8, k + 2, Block.planks.blockID);
		world.setBlock(i + 20, j + 8, k + 3, Block.planks.blockID);
		world.setBlock(i + 20, j + 8, k + 4, Block.planks.blockID);
		world.setBlock(i + 20, j + 8, k + 5, Block.planks.blockID);
		world.setBlock(i + 20, j + 8, k + 6, Block.planks.blockID);
		world.setBlock(i + 20, j + 8, k + 7, Block.planks.blockID);
		world.setBlock(i + 20, j + 8, k + 8, Block.planks.blockID);
		world.setBlock(i + 20, j + 8, k + 9, Block.planks.blockID);
		world.setBlock(i + 20, j + 8, k + 10, Block.planks.blockID);
		world.setBlock(i + 20, j + 9, k + 1, Block.fence.blockID);
		world.setBlock(i + 20, j + 9, k + 5, Block.wood.blockID);
		world.setBlock(i + 20, j + 9, k + 6, Block.wood.blockID);
		world.setBlock(i + 20, j + 9, k + 10, Block.fence.blockID);
		world.setBlock(i + 20, j + 10, k + 5, Block.wood.blockID);
		world.setBlock(i + 20, j + 10, k + 6, Block.wood.blockID);
		world.setBlock(i + 20, j + 11, k + 5, Block.wood.blockID);
		world.setBlock(i + 20, j + 11, k + 6, Block.wood.blockID);
		world.setBlock(i + 20, j + 12, k + 5, Block.wood.blockID);
		world.setBlock(i + 20, j + 12, k + 6, Block.wood.blockID);
		world.setBlock(i + 20, j + 13, k + 5, Block.wood.blockID);
		world.setBlock(i + 20, j + 13, k + 6, Block.wood.blockID);
		world.setBlock(i + 21, j + 0, k + 4, Block.planks.blockID);
		world.setBlock(i + 21, j + 0, k + 5, Block.planks.blockID);
		world.setBlock(i + 21, j + 0, k + 6, Block.planks.blockID);
		world.setBlock(i + 21, j + 0, k + 7, Block.planks.blockID);
		world.setBlock(i + 21, j + 1, k + 3, Block.planks.blockID);
		world.setBlock(i + 21, j + 1, k + 8, Block.planks.blockID);
		world.setBlock(i + 21, j + 2, k + 2, Block.planks.blockID);
		world.setBlock(i + 21, j + 2, k + 3, Block.planks.blockID);
		world.setBlock(i + 21, j + 2, k + 4, Block.planks.blockID);
		world.setBlock(i + 21, j + 2, k + 5, Block.planks.blockID);
		world.setBlock(i + 21, j + 2, k + 6, Block.planks.blockID);
		world.setBlock(i + 21, j + 2, k + 7, Block.planks.blockID);
		world.setBlock(i + 21, j + 2, k + 8, Block.planks.blockID);
		world.setBlock(i + 21, j + 2, k + 9, Block.planks.blockID);
		world.setBlock(i + 21, j + 3, k + 1, Block.planks.blockID);
		world.setBlock(i + 21, j + 3, k + 5, Block.planks.blockID);
		world.setBlock(i + 21, j + 3, k + 10, Block.planks.blockID);
		world.setBlock(i + 21, j + 4, k + 1, Block.glass.blockID);
		world.setBlock(i + 21, j + 4, k + 5, Block.planks.blockID);
		world.setBlock(i + 21, j + 4, k + 10, Block.planks.blockID);
		world.setBlock(i + 21, j + 5, k + 1, Block.planks.blockID);
		world.setBlock(i + 21, j + 5, k + 2, Block.planks.blockID);
		world.setBlock(i + 21, j + 5, k + 3, Block.planks.blockID);
		world.setBlock(i + 21, j + 5, k + 4, Block.planks.blockID);
		world.setBlock(i + 21, j + 5, k + 5, Block.planks.blockID);
		world.setBlock(i + 21, j + 5, k + 6, Block.planks.blockID);
		world.setBlock(i + 21, j + 5, k + 7, Block.planks.blockID);
		world.setBlock(i + 21, j + 5, k + 8, Block.planks.blockID);
		world.setBlock(i + 21, j + 5, k + 9, Block.planks.blockID);
		world.setBlock(i + 21, j + 5, k + 10, Block.planks.blockID);
		world.setBlockAndMetadata(i + 21, j + 6, k + 1, Block.dispenser.blockID, 2);
		world.setBlock(i + 21, j + 8, k + 1, Block.planks.blockID);
		world.setBlock(i + 21, j + 8, k + 2, Block.planks.blockID);
		world.setBlock(i + 21, j + 8, k + 3, Block.planks.blockID);
		world.setBlock(i + 21, j + 8, k + 4, Block.planks.blockID);
		world.setBlock(i + 21, j + 8, k + 5, Block.planks.blockID);
		world.setBlock(i + 21, j + 8, k + 6, Block.planks.blockID);
		world.setBlock(i + 21, j + 8, k + 7, Block.planks.blockID);
		world.setBlock(i + 21, j + 8, k + 8, Block.planks.blockID);
		world.setBlock(i + 21, j + 8, k + 9, Block.planks.blockID);
		world.setBlock(i + 21, j + 8, k + 10, Block.planks.blockID);
		world.setBlock(i + 21, j + 9, k + 1, Block.fence.blockID);
		world.setBlock(i + 21, j + 9, k + 5, Block.wood.blockID);
		world.setBlock(i + 21, j + 9, k + 6, Block.wood.blockID);
		world.setBlock(i + 21, j + 9, k + 10, Block.fence.blockID);
		world.setBlock(i + 21, j + 10, k + 5, Block.wood.blockID);
		world.setBlock(i + 21, j + 10, k + 6, Block.wood.blockID);
		world.setBlock(i + 21, j + 11, k + 5, Block.wood.blockID);
		world.setBlock(i + 21, j + 11, k + 6, Block.wood.blockID);
		world.setBlock(i + 21, j + 12, k + 5, Block.wood.blockID);
		world.setBlock(i + 21, j + 12, k + 6, Block.wood.blockID);
		world.setBlock(i + 21, j + 13, k + 5, Block.wood.blockID);
		world.setBlock(i + 21, j + 13, k + 6, Block.wood.blockID);
		world.setBlock(i + 22, j + 0, k + 4, Block.planks.blockID);
		world.setBlock(i + 22, j + 0, k + 5, Block.planks.blockID);
		world.setBlock(i + 22, j + 0, k + 6, Block.planks.blockID);
		world.setBlock(i + 22, j + 0, k + 7, Block.planks.blockID);
		world.setBlock(i + 22, j + 1, k + 3, Block.planks.blockID);
		world.setBlock(i + 22, j + 1, k + 8, Block.planks.blockID);
		world.setBlock(i + 22, j + 2, k + 2, Block.planks.blockID);
		world.setBlock(i + 22, j + 2, k + 3, Block.planks.blockID);
		world.setBlock(i + 22, j + 2, k + 4, Block.planks.blockID);
		world.setBlock(i + 22, j + 2, k + 5, Block.planks.blockID);
		world.setBlock(i + 22, j + 2, k + 6, Block.planks.blockID);
		world.setBlock(i + 22, j + 2, k + 7, Block.planks.blockID);
		world.setBlock(i + 22, j + 2, k + 8, Block.planks.blockID);
		world.setBlock(i + 22, j + 2, k + 9, Block.planks.blockID);
		world.setBlock(i + 22, j + 3, k + 1, Block.planks.blockID);
		world.setBlock(i + 22, j + 3, k + 5, Block.planks.blockID);
		world.setBlock(i + 22, j + 3, k + 10, Block.planks.blockID);
		world.setBlock(i + 22, j + 4, k + 1, Block.planks.blockID);
		world.setBlock(i + 22, j + 4, k + 5, Block.planks.blockID);
		world.setBlock(i + 22, j + 4, k + 10, Block.planks.blockID);
		world.setBlock(i + 22, j + 5, k + 1, Block.planks.blockID);
		world.setBlock(i + 22, j + 5, k + 2, Block.planks.blockID);
		world.setBlock(i + 22, j + 5, k + 3, Block.planks.blockID);
		world.setBlock(i + 22, j + 5, k + 4, Block.planks.blockID);
		world.setBlock(i + 22, j + 5, k + 5, Block.planks.blockID);
		world.setBlock(i + 22, j + 5, k + 6, Block.planks.blockID);
		world.setBlock(i + 22, j + 5, k + 7, Block.planks.blockID);
		world.setBlock(i + 22, j + 5, k + 8, Block.planks.blockID);
		world.setBlock(i + 22, j + 5, k + 9, Block.planks.blockID);
		world.setBlock(i + 22, j + 5, k + 10, Block.planks.blockID);
		world.setBlock(i + 22, j + 6, k + 1, Block.planks.blockID);
		world.setBlockAndMetadata(i + 22, j + 6, k + 5, Block.chest.blockID, 4);
		world.setBlockAndMetadata(i + 22, j + 6, k + 6, Block.chest.blockID, 4);
		world.setBlock(i + 22, j + 6, k + 10, Block.planks.blockID);
		world.setBlock(i + 22, j + 7, k + 1, Block.planks.blockID);
		world.setBlock(i + 22, j + 7, k + 10, Block.planks.blockID);
		world.setBlock(i + 22, j + 8, k + 1, Block.planks.blockID);
		world.setBlock(i + 22, j + 8, k + 2, Block.planks.blockID);
		world.setBlock(i + 22, j + 8, k + 3, Block.planks.blockID);
		world.setBlock(i + 22, j + 8, k + 4, Block.planks.blockID);
		world.setBlock(i + 22, j + 8, k + 5, Block.planks.blockID);
		world.setBlock(i + 22, j + 8, k + 6, Block.planks.blockID);
		world.setBlock(i + 22, j + 8, k + 7, Block.planks.blockID);
		world.setBlock(i + 22, j + 8, k + 8, Block.planks.blockID);
		world.setBlock(i + 22, j + 8, k + 9, Block.planks.blockID);
		world.setBlock(i + 22, j + 8, k + 10, Block.planks.blockID);
		world.setBlock(i + 22, j + 9, k + 1, Block.fence.blockID);
		world.setBlock(i + 22, j + 9, k + 10, Block.fence.blockID);
		world.setBlock(i + 23, j + 0, k + 4, Block.planks.blockID);
		world.setBlock(i + 23, j + 0, k + 5, Block.planks.blockID);
		world.setBlock(i + 23, j + 0, k + 6, Block.planks.blockID);
		world.setBlock(i + 23, j + 0, k + 7, Block.planks.blockID);
		world.setBlock(i + 23, j + 1, k + 3, Block.planks.blockID);
		world.setBlock(i + 23, j + 1, k + 8, Block.planks.blockID);
		world.setBlock(i + 23, j + 2, k + 2, Block.planks.blockID);
		world.setBlock(i + 23, j + 2, k + 3, Block.planks.blockID);
		world.setBlock(i + 23, j + 2, k + 4, Block.planks.blockID);
		world.setBlock(i + 23, j + 2, k + 5, Block.planks.blockID);
		world.setBlock(i + 23, j + 2, k + 6, Block.planks.blockID);
		world.setBlock(i + 23, j + 2, k + 7, Block.planks.blockID);
		world.setBlock(i + 23, j + 2, k + 8, Block.planks.blockID);
		world.setBlock(i + 23, j + 2, k + 9, Block.planks.blockID);
		world.setBlock(i + 23, j + 3, k + 1, Block.planks.blockID);
		world.setBlock(i + 23, j + 3, k + 10, Block.planks.blockID);
		world.setBlock(i + 23, j + 4, k + 1, Block.planks.blockID);
		world.setBlock(i + 23, j + 4, k + 10, Block.glass.blockID);
		world.setBlock(i + 23, j + 5, k + 1, Block.planks.blockID);
		world.setBlock(i + 23, j + 5, k + 2, Block.planks.blockID);
		world.setBlock(i + 23, j + 5, k + 3, Block.planks.blockID);
		world.setBlock(i + 23, j + 5, k + 4, Block.planks.blockID);
		world.setBlock(i + 23, j + 5, k + 5, Block.planks.blockID);
		world.setBlock(i + 23, j + 5, k + 6, Block.planks.blockID);
		world.setBlock(i + 23, j + 5, k + 7, Block.planks.blockID);
		world.setBlock(i + 23, j + 5, k + 8, Block.planks.blockID);
		world.setBlock(i + 23, j + 5, k + 9, Block.planks.blockID);
		world.setBlock(i + 23, j + 5, k + 10, Block.planks.blockID);
		world.setBlock(i + 23, j + 6, k + 1, Block.planks.blockID);
		world.setBlock(i + 23, j + 6, k + 10, Block.planks.blockID);
		world.setBlock(i + 23, j + 7, k + 1, Block.planks.blockID);
		world.setBlock(i + 23, j + 7, k + 10, Block.planks.blockID);
		world.setBlock(i + 23, j + 8, k + 1, Block.planks.blockID);
		world.setBlock(i + 23, j + 8, k + 2, Block.planks.blockID);
		world.setBlock(i + 23, j + 8, k + 3, Block.planks.blockID);
		world.setBlock(i + 23, j + 8, k + 4, Block.planks.blockID);
		world.setBlock(i + 23, j + 8, k + 5, Block.planks.blockID);
		world.setBlock(i + 23, j + 8, k + 6, Block.planks.blockID);
		world.setBlock(i + 23, j + 8, k + 7, Block.planks.blockID);
		world.setBlock(i + 23, j + 8, k + 8, Block.planks.blockID);
		world.setBlock(i + 23, j + 8, k + 9, Block.planks.blockID);
		world.setBlock(i + 23, j + 8, k + 10, Block.planks.blockID);
		world.setBlock(i + 23, j + 9, k + 1, Block.fence.blockID);
		world.setBlock(i + 23, j + 9, k + 10, Block.fence.blockID);
		world.setBlock(i + 24, j + 0, k + 4, Block.planks.blockID);
		world.setBlock(i + 24, j + 0, k + 5, Block.planks.blockID);
		world.setBlock(i + 24, j + 0, k + 6, Block.planks.blockID);
		world.setBlock(i + 24, j + 0, k + 7, Block.planks.blockID);
		world.setBlock(i + 24, j + 1, k + 3, Block.planks.blockID);
		world.setBlock(i + 24, j + 1, k + 8, Block.planks.blockID);
		world.setBlock(i + 24, j + 2, k + 2, Block.planks.blockID);
		world.setBlock(i + 24, j + 2, k + 3, Block.planks.blockID);
		world.setBlock(i + 24, j + 2, k + 4, Block.planks.blockID);
		world.setBlock(i + 24, j + 2, k + 5, Block.planks.blockID);
		world.setBlock(i + 24, j + 2, k + 6, Block.planks.blockID);
		world.setBlock(i + 24, j + 2, k + 7, Block.planks.blockID);
		world.setBlock(i + 24, j + 2, k + 8, Block.planks.blockID);
		world.setBlock(i + 24, j + 2, k + 9, Block.planks.blockID);
		world.setBlock(i + 24, j + 3, k + 1, Block.planks.blockID);
		world.setBlock(i + 24, j + 3, k + 5, Block.planks.blockID);
		world.setBlock(i + 24, j + 3, k + 10, Block.planks.blockID);
		world.setBlock(i + 24, j + 4, k + 1, Block.planks.blockID);
		world.setBlock(i + 24, j + 4, k + 5, Block.planks.blockID);
		world.setBlock(i + 24, j + 4, k + 10, Block.planks.blockID);
		world.setBlock(i + 24, j + 5, k + 1, Block.planks.blockID);
		world.setBlock(i + 24, j + 5, k + 2, Block.planks.blockID);
		world.setBlock(i + 24, j + 5, k + 3, Block.planks.blockID);
		world.setBlock(i + 24, j + 5, k + 4, Block.planks.blockID);
		world.setBlock(i + 24, j + 5, k + 5, Block.planks.blockID);
		world.setBlock(i + 24, j + 5, k + 6, Block.planks.blockID);
		world.setBlock(i + 24, j + 5, k + 7, Block.planks.blockID);
		world.setBlock(i + 24, j + 5, k + 8, Block.planks.blockID);
		world.setBlock(i + 24, j + 5, k + 9, Block.planks.blockID);
		world.setBlock(i + 24, j + 5, k + 10, Block.planks.blockID);
		world.setBlockAndMetadata(i + 24, j + 6, k + 1, Block.dispenser.blockID, 2);
		world.setBlockAndMetadata(i + 24, j + 6, k + 5, Block.chest.blockID, 4);
		world.setBlockAndMetadata(i + 24, j + 6, k + 6, Block.chest.blockID, 4);
		world.setBlock(i + 24, j + 8, k + 1, Block.planks.blockID);
		world.setBlock(i + 24, j + 8, k + 2, Block.planks.blockID);
		world.setBlock(i + 24, j + 8, k + 3, Block.planks.blockID);
		world.setBlock(i + 24, j + 8, k + 4, Block.planks.blockID);
		world.setBlock(i + 24, j + 8, k + 5, Block.planks.blockID);
		world.setBlock(i + 24, j + 8, k + 6, Block.planks.blockID);
		world.setBlock(i + 24, j + 8, k + 7, Block.planks.blockID);
		world.setBlock(i + 24, j + 8, k + 8, Block.planks.blockID);
		world.setBlock(i + 24, j + 8, k + 9, Block.planks.blockID);
		world.setBlock(i + 24, j + 8, k + 10, Block.planks.blockID);
		world.setBlock(i + 24, j + 9, k + 1, Block.fence.blockID);
		world.setBlock(i + 24, j + 9, k + 10, Block.fence.blockID);
		world.setBlock(i + 25, j + 0, k + 4, Block.planks.blockID);
		world.setBlock(i + 25, j + 0, k + 5, Block.planks.blockID);
		world.setBlock(i + 25, j + 0, k + 6, Block.planks.blockID);
		world.setBlock(i + 25, j + 0, k + 7, Block.planks.blockID);
		world.setBlock(i + 25, j + 1, k + 3, Block.planks.blockID);
		world.setBlock(i + 25, j + 1, k + 8, Block.planks.blockID);
		world.setBlock(i + 25, j + 2, k + 2, Block.planks.blockID);
		world.setBlock(i + 25, j + 2, k + 3, Block.planks.blockID);
		world.setBlock(i + 25, j + 2, k + 4, Block.planks.blockID);
		world.setBlock(i + 25, j + 2, k + 5, Block.planks.blockID);
		world.setBlock(i + 25, j + 2, k + 6, Block.planks.blockID);
		world.setBlock(i + 25, j + 2, k + 7, Block.planks.blockID);
		world.setBlock(i + 25, j + 2, k + 8, Block.planks.blockID);
		world.setBlock(i + 25, j + 2, k + 9, Block.planks.blockID);
		world.setBlock(i + 25, j + 3, k + 1, Block.planks.blockID);
		world.setBlock(i + 25, j + 3, k + 5, Block.planks.blockID);
		world.setBlock(i + 25, j + 3, k + 6, Block.planks.blockID);
		world.setBlock(i + 25, j + 3, k + 7, Block.planks.blockID);
		world.setBlock(i + 25, j + 3, k + 8, Block.planks.blockID);
		world.setBlock(i + 25, j + 3, k + 9, Block.planks.blockID);
		world.setBlock(i + 25, j + 3, k + 10, Block.planks.blockID);
		world.setBlock(i + 25, j + 4, k + 1, Block.planks.blockID);
		world.setBlock(i + 25, j + 4, k + 5, Block.planks.blockID);
		world.setBlock(i + 25, j + 4, k + 6, Block.planks.blockID);
		world.setBlock(i + 25, j + 4, k + 7, Block.planks.blockID);
		world.setBlock(i + 25, j + 4, k + 8, Block.planks.blockID);
		world.setBlock(i + 25, j + 4, k + 9, Block.planks.blockID);
		world.setBlock(i + 25, j + 4, k + 10, Block.planks.blockID);
		world.setBlock(i + 25, j + 5, k + 1, Block.planks.blockID);
		world.setBlock(i + 25, j + 5, k + 2, Block.planks.blockID);
		world.setBlock(i + 25, j + 5, k + 3, Block.planks.blockID);
		world.setBlock(i + 25, j + 5, k + 4, Block.planks.blockID);
		world.setBlock(i + 25, j + 5, k + 5, Block.planks.blockID);
		world.setBlock(i + 25, j + 5, k + 6, Block.planks.blockID);
		world.setBlock(i + 25, j + 5, k + 7, Block.planks.blockID);
		world.setBlock(i + 25, j + 5, k + 8, Block.planks.blockID);
		world.setBlock(i + 25, j + 5, k + 9, Block.planks.blockID);
		world.setBlock(i + 25, j + 5, k + 10, Block.planks.blockID);
		world.setBlock(i + 25, j + 6, k + 1, Block.planks.blockID);
		world.setBlock(i + 25, j + 6, k + 10, Block.planks.blockID);
		world.setBlock(i + 25, j + 7, k + 1, Block.planks.blockID);
		world.setBlock(i + 25, j + 7, k + 10, Block.planks.blockID);
		world.setBlock(i + 25, j + 8, k + 1, Block.planks.blockID);
		world.setBlock(i + 25, j + 8, k + 2, Block.planks.blockID);
		world.setBlock(i + 25, j + 8, k + 3, Block.planks.blockID);
		world.setBlock(i + 25, j + 8, k + 4, Block.planks.blockID);
		world.setBlockAndMetadata(i + 25, j + 8, k + 5, Block.stairCompactPlanks.blockID, 1);
		world.setBlockAndMetadata(i + 25, j + 8, k + 6, Block.stairCompactPlanks.blockID, 1);
		world.setBlock(i + 25, j + 8, k + 7, Block.planks.blockID);
		world.setBlock(i + 25, j + 8, k + 8, Block.planks.blockID);
		world.setBlock(i + 25, j + 8, k + 9, Block.planks.blockID);
		world.setBlock(i + 25, j + 8, k + 10, Block.planks.blockID);
		world.setBlock(i + 25, j + 9, k + 1, Block.fence.blockID);
		world.setBlock(i + 25, j + 9, k + 4, Block.fence.blockID);
		world.setBlock(i + 25, j + 9, k + 7, Block.fence.blockID);
		world.setBlock(i + 25, j + 9, k + 10, Block.fence.blockID);
		world.setBlock(i + 26, j + 0, k + 4, Block.planks.blockID);
		world.setBlock(i + 26, j + 0, k + 5, Block.planks.blockID);
		world.setBlock(i + 26, j + 0, k + 6, Block.planks.blockID);
		world.setBlock(i + 26, j + 0, k + 7, Block.planks.blockID);
		world.setBlock(i + 26, j + 1, k + 3, Block.planks.blockID);
		world.setBlock(i + 26, j + 1, k + 4, Block.planks.blockID);
		world.setBlock(i + 26, j + 1, k + 8, Block.planks.blockID);
		world.setBlock(i + 26, j + 2, k + 2, Block.planks.blockID);
		world.setBlock(i + 26, j + 2, k + 3, Block.planks.blockID);
		world.setBlock(i + 26, j + 2, k + 4, Block.planks.blockID);
		world.setBlock(i + 26, j + 2, k + 5, Block.planks.blockID);
		world.setBlock(i + 26, j + 2, k + 6, Block.planks.blockID);
		world.setBlock(i + 26, j + 2, k + 7, Block.planks.blockID);
		world.setBlock(i + 26, j + 2, k + 8, Block.planks.blockID);
		world.setBlock(i + 26, j + 2, k + 9, Block.planks.blockID);
		world.setBlock(i + 26, j + 3, k + 1, Block.planks.blockID);
		world.setBlock(i + 26, j + 3, k + 5, Block.planks.blockID);
		world.setBlock(i + 26, j + 3, k + 8, Block.bed.blockID);
		world.setBlockAndMetadata(i + 26, j + 3, k + 9, Block.bed.blockID, 8);
		world.setBlock(i + 26, j + 3, k + 10, Block.planks.blockID);
		world.setBlock(i + 26, j + 4, k + 1, Block.glass.blockID);
		world.setBlock(i + 26, j + 4, k + 5, Block.planks.blockID);
		world.setBlock(i + 26, j + 4, k + 10, Block.planks.blockID);
		world.setBlock(i + 26, j + 5, k + 1, Block.planks.blockID);
		world.setBlock(i + 26, j + 5, k + 2, Block.planks.blockID);
		world.setBlock(i + 26, j + 5, k + 3, Block.planks.blockID);
		world.setBlock(i + 26, j + 5, k + 4, Block.planks.blockID);
		world.setBlock(i + 26, j + 5, k + 5, Block.planks.blockID);
		world.setBlock(i + 26, j + 5, k + 6, Block.planks.blockID);
		world.setBlock(i + 26, j + 5, k + 7, Block.planks.blockID);
		world.setBlock(i + 26, j + 5, k + 8, Block.planks.blockID);
		world.setBlock(i + 26, j + 5, k + 9, Block.planks.blockID);
		world.setBlock(i + 26, j + 5, k + 10, Block.planks.blockID);
		world.setBlock(i + 26, j + 6, k + 1, Block.planks.blockID);
		world.setBlock(i + 26, j + 6, k + 10, Block.planks.blockID);
		world.setBlock(i + 26, j + 7, k + 1, Block.planks.blockID);
		world.setBlockAndMetadata(i + 26, j + 7, k + 5, Block.stairCompactPlanks.blockID, 1);
		world.setBlockAndMetadata(i + 26, j + 7, k + 6, Block.stairCompactPlanks.blockID, 1);
		world.setBlock(i + 26, j + 7, k + 10, Block.planks.blockID);
		world.setBlock(i + 26, j + 8, k + 1, Block.planks.blockID);
		world.setBlock(i + 26, j + 8, k + 2, Block.planks.blockID);
		world.setBlock(i + 26, j + 8, k + 3, Block.planks.blockID);
		world.setBlock(i + 26, j + 8, k + 4, Block.planks.blockID);
		world.setBlock(i + 26, j + 8, k + 7, Block.planks.blockID);
		world.setBlock(i + 26, j + 8, k + 8, Block.planks.blockID);
		world.setBlock(i + 26, j + 8, k + 9, Block.planks.blockID);
		world.setBlock(i + 26, j + 8, k + 10, Block.planks.blockID);
		world.setBlock(i + 26, j + 9, k + 1, Block.fence.blockID);
		world.setBlock(i + 26, j + 9, k + 4, Block.fence.blockID);
		world.setBlock(i + 26, j + 9, k + 7, Block.fence.blockID);
		world.setBlock(i + 26, j + 9, k + 10, Block.fence.blockID);
		world.setBlock(i + 27, j + 0, k + 4, Block.planks.blockID);
		world.setBlock(i + 27, j + 0, k + 5, Block.planks.blockID);
		world.setBlock(i + 27, j + 0, k + 6, Block.planks.blockID);
		world.setBlock(i + 27, j + 0, k + 7, Block.planks.blockID);
		world.setBlock(i + 27, j + 1, k + 3, Block.planks.blockID);
		world.setBlock(i + 27, j + 1, k + 8, Block.planks.blockID);
		world.setBlock(i + 27, j + 2, k + 2, Block.planks.blockID);
		world.setBlock(i + 27, j + 2, k + 3, Block.planks.blockID);
		world.setBlock(i + 27, j + 2, k + 4, Block.planks.blockID);
		world.setBlock(i + 27, j + 2, k + 5, Block.planks.blockID);
		world.setBlock(i + 27, j + 2, k + 6, Block.planks.blockID);
		world.setBlock(i + 27, j + 2, k + 7, Block.planks.blockID);
		world.setBlock(i + 27, j + 2, k + 8, Block.planks.blockID);
		world.setBlock(i + 27, j + 2, k + 9, Block.planks.blockID);
		world.setBlock(i + 27, j + 3, k + 1, Block.planks.blockID);
		world.setBlock(i + 27, j + 3, k + 5, Block.planks.blockID);
		world.setBlock(i + 27, j + 3, k + 10, Block.planks.blockID);
		world.setBlock(i + 27, j + 4, k + 1, Block.planks.blockID);
		world.setBlock(i + 27, j + 4, k + 5, Block.planks.blockID);
		world.setBlock(i + 27, j + 4, k + 10, Block.planks.blockID);
		world.setBlock(i + 27, j + 5, k + 1, Block.planks.blockID);
		world.setBlock(i + 27, j + 5, k + 2, Block.planks.blockID);
		world.setBlock(i + 27, j + 5, k + 3, Block.planks.blockID);
		world.setBlock(i + 27, j + 5, k + 4, Block.planks.blockID);
		world.setBlock(i + 27, j + 5, k + 5, Block.planks.blockID);
		world.setBlock(i + 27, j + 5, k + 6, Block.planks.blockID);
		world.setBlock(i + 27, j + 5, k + 7, Block.planks.blockID);
		world.setBlock(i + 27, j + 5, k + 8, Block.planks.blockID);
		world.setBlock(i + 27, j + 5, k + 9, Block.planks.blockID);
		world.setBlock(i + 27, j + 5, k + 10, Block.planks.blockID);
		world.setBlockAndMetadata(i + 27, j + 6, k + 5, Block.stairCompactPlanks.blockID, 1);
		world.setBlockAndMetadata(i + 27, j + 6, k + 6, Block.stairCompactPlanks.blockID, 1);
		world.setBlock(i + 27, j + 8, k + 1, Block.planks.blockID);
		world.setBlock(i + 27, j + 8, k + 2, Block.planks.blockID);
		world.setBlock(i + 27, j + 8, k + 3, Block.planks.blockID);
		world.setBlock(i + 27, j + 8, k + 4, Block.planks.blockID);
		world.setBlock(i + 27, j + 8, k + 7, Block.planks.blockID);
		world.setBlock(i + 27, j + 8, k + 8, Block.planks.blockID);
		world.setBlock(i + 27, j + 8, k + 9, Block.planks.blockID);
		world.setBlock(i + 27, j + 8, k + 10, Block.planks.blockID);
		world.setBlock(i + 27, j + 9, k + 1, Block.fence.blockID);
		world.setBlock(i + 27, j + 9, k + 4, Block.fence.blockID);
		world.setBlock(i + 27, j + 9, k + 7, Block.fence.blockID);
		world.setBlock(i + 27, j + 9, k + 10, Block.fence.blockID);
		world.setBlock(i + 28, j + 0, k + 4, Block.planks.blockID);
		world.setBlock(i + 28, j + 0, k + 5, Block.planks.blockID);
		world.setBlock(i + 28, j + 0, k + 6, Block.planks.blockID);
		world.setBlock(i + 28, j + 0, k + 7, Block.planks.blockID);
		world.setBlock(i + 28, j + 1, k + 3, Block.planks.blockID);
		world.setBlock(i + 28, j + 1, k + 8, Block.planks.blockID);
		world.setBlock(i + 28, j + 2, k + 2, Block.planks.blockID);
		world.setBlock(i + 28, j + 2, k + 3, Block.planks.blockID);
		world.setBlock(i + 28, j + 2, k + 4, Block.planks.blockID);
		world.setBlock(i + 28, j + 2, k + 5, Block.planks.blockID);
		world.setBlock(i + 28, j + 2, k + 6, Block.planks.blockID);
		world.setBlock(i + 28, j + 2, k + 7, Block.planks.blockID);
		world.setBlock(i + 28, j + 2, k + 8, Block.planks.blockID);
		world.setBlock(i + 28, j + 2, k + 9, Block.planks.blockID);
		world.setBlock(i + 28, j + 3, k + 1, Block.planks.blockID);
		world.setBlock(i + 28, j + 3, k + 5, Block.planks.blockID);
		world.setBlock(i + 28, j + 3, k + 10, Block.planks.blockID);
		world.setBlock(i + 28, j + 4, k + 1, Block.planks.blockID);
		world.setBlock(i + 28, j + 4, k + 5, Block.planks.blockID);
		world.setBlock(i + 28, j + 4, k + 10, Block.planks.blockID);
		world.setBlock(i + 28, j + 5, k + 1, Block.planks.blockID);
		world.setBlock(i + 28, j + 5, k + 2, Block.planks.blockID);
		world.setBlock(i + 28, j + 5, k + 3, Block.planks.blockID);
		world.setBlock(i + 28, j + 5, k + 4, Block.planks.blockID);
		world.setBlock(i + 28, j + 5, k + 5, Block.planks.blockID);
		world.setBlock(i + 28, j + 5, k + 6, Block.planks.blockID);
		world.setBlock(i + 28, j + 5, k + 7, Block.planks.blockID);
		world.setBlock(i + 28, j + 5, k + 8, Block.planks.blockID);
		world.setBlock(i + 28, j + 5, k + 9, Block.planks.blockID);
		world.setBlock(i + 28, j + 5, k + 10, Block.planks.blockID);
		world.setBlock(i + 28, j + 6, k + 1, Block.planks.blockID);
		world.setBlock(i + 28, j + 6, k + 10, Block.planks.blockID);
		world.setBlock(i + 28, j + 7, k + 1, Block.planks.blockID);
		world.setBlock(i + 28, j + 7, k + 10, Block.planks.blockID);
		world.setBlock(i + 28, j + 8, k + 1, Block.planks.blockID);
		world.setBlock(i + 28, j + 8, k + 2, Block.planks.blockID);
		world.setBlock(i + 28, j + 8, k + 3, Block.planks.blockID);
		world.setBlock(i + 28, j + 8, k + 4, Block.planks.blockID);
		world.setBlock(i + 28, j + 8, k + 7, Block.planks.blockID);
		world.setBlock(i + 28, j + 8, k + 8, Block.planks.blockID);
		world.setBlock(i + 28, j + 8, k + 9, Block.planks.blockID);
		world.setBlock(i + 28, j + 8, k + 10, Block.planks.blockID);
		world.setBlock(i + 28, j + 9, k + 1, Block.fence.blockID);
		world.setBlock(i + 28, j + 9, k + 4, Block.fence.blockID);
		world.setBlock(i + 28, j + 9, k + 7, Block.fence.blockID);
		world.setBlock(i + 28, j + 9, k + 10, Block.fence.blockID);
		world.setBlock(i + 29, j + 0, k + 4, Block.planks.blockID);
		world.setBlock(i + 29, j + 0, k + 5, Block.planks.blockID);
		world.setBlock(i + 29, j + 0, k + 6, Block.planks.blockID);
		world.setBlock(i + 29, j + 0, k + 7, Block.planks.blockID);
		world.setBlock(i + 29, j + 1, k + 3, Block.planks.blockID);
		world.setBlock(i + 29, j + 1, k + 8, Block.planks.blockID);
		world.setBlock(i + 29, j + 2, k + 2, Block.planks.blockID);
		world.setBlock(i + 29, j + 2, k + 3, Block.planks.blockID);
		world.setBlock(i + 29, j + 2, k + 4, Block.planks.blockID);
		world.setBlock(i + 29, j + 2, k + 5, Block.planks.blockID);
		world.setBlock(i + 29, j + 2, k + 6, Block.planks.blockID);
		world.setBlock(i + 29, j + 2, k + 7, Block.planks.blockID);
		world.setBlock(i + 29, j + 2, k + 8, Block.planks.blockID);
		world.setBlock(i + 29, j + 2, k + 9, Block.planks.blockID);
		world.setBlock(i + 29, j + 3, k + 1, Block.planks.blockID);
		world.setBlock(i + 29, j + 3, k + 10, Block.planks.blockID);
		world.setBlock(i + 29, j + 4, k + 1, Block.planks.blockID);
		world.setBlock(i + 29, j + 4, k + 10, Block.glass.blockID);
		world.setBlock(i + 29, j + 5, k + 1, Block.planks.blockID);
		world.setBlock(i + 29, j + 5, k + 2, Block.planks.blockID);
		world.setBlock(i + 29, j + 5, k + 3, Block.planks.blockID);
		world.setBlock(i + 29, j + 5, k + 4, Block.planks.blockID);
		world.setBlock(i + 29, j + 5, k + 5, Block.planks.blockID);
		world.setBlock(i + 29, j + 5, k + 6, Block.planks.blockID);
		world.setBlock(i + 29, j + 5, k + 7, Block.planks.blockID);
		world.setBlock(i + 29, j + 5, k + 8, Block.planks.blockID);
		world.setBlock(i + 29, j + 5, k + 9, Block.planks.blockID);
		world.setBlock(i + 29, j + 5, k + 10, Block.planks.blockID);
		world.setBlock(i + 29, j + 6, k + 1, Block.planks.blockID);
		world.setBlock(i + 29, j + 6, k + 10, Block.planks.blockID);
		world.setBlock(i + 29, j + 7, k + 1, Block.planks.blockID);
		world.setBlock(i + 29, j + 7, k + 10, Block.planks.blockID);
		world.setBlock(i + 29, j + 8, k + 1, Block.planks.blockID);
		world.setBlock(i + 29, j + 8, k + 2, Block.planks.blockID);
		world.setBlock(i + 29, j + 8, k + 3, Block.planks.blockID);
		world.setBlock(i + 29, j + 8, k + 4, Block.planks.blockID);
		world.setBlock(i + 29, j + 8, k + 5, Block.planks.blockID);
		world.setBlock(i + 29, j + 8, k + 6, Block.planks.blockID);
		world.setBlock(i + 29, j + 8, k + 7, Block.planks.blockID);
		world.setBlock(i + 29, j + 8, k + 8, Block.planks.blockID);
		world.setBlock(i + 29, j + 8, k + 9, Block.planks.blockID);
		world.setBlock(i + 29, j + 8, k + 10, Block.planks.blockID);
		world.setBlock(i + 29, j + 9, k + 1, Block.fence.blockID);
		world.setBlock(i + 29, j + 9, k + 4, Block.fence.blockID);
		world.setBlock(i + 29, j + 9, k + 5, Block.fence.blockID);
		world.setBlock(i + 29, j + 9, k + 6, Block.fence.blockID);
		world.setBlock(i + 29, j + 9, k + 7, Block.fence.blockID);
		world.setBlock(i + 29, j + 9, k + 10, Block.fence.blockID);
		world.setBlock(i + 30, j + 0, k + 4, Block.planks.blockID);
		world.setBlock(i + 30, j + 0, k + 5, Block.planks.blockID);
		world.setBlock(i + 30, j + 0, k + 6, Block.planks.blockID);
		world.setBlock(i + 30, j + 0, k + 7, Block.planks.blockID);
		world.setBlock(i + 30, j + 1, k + 3, Block.planks.blockID);
		world.setBlock(i + 30, j + 1, k + 8, Block.planks.blockID);
		world.setBlock(i + 30, j + 2, k + 2, Block.planks.blockID);
		world.setBlock(i + 30, j + 2, k + 3, Block.planks.blockID);
		world.setBlock(i + 30, j + 2, k + 4, Block.planks.blockID);
		world.setBlock(i + 30, j + 2, k + 5, Block.planks.blockID);
		world.setBlock(i + 30, j + 2, k + 6, Block.planks.blockID);
		world.setBlock(i + 30, j + 2, k + 7, Block.planks.blockID);
		world.setBlock(i + 30, j + 2, k + 8, Block.planks.blockID);
		world.setBlock(i + 30, j + 2, k + 9, Block.planks.blockID);
		world.setBlock(i + 30, j + 3, k + 1, Block.planks.blockID);
		world.setBlock(i + 30, j + 3, k + 5, Block.planks.blockID);
		world.setBlock(i + 30, j + 3, k + 10, Block.planks.blockID);
		world.setBlock(i + 30, j + 4, k + 1, Block.planks.blockID);
		world.setBlock(i + 30, j + 4, k + 5, Block.planks.blockID);
		world.setBlock(i + 30, j + 4, k + 10, Block.planks.blockID);
		world.setBlock(i + 30, j + 5, k + 1, Block.planks.blockID);
		world.setBlock(i + 30, j + 5, k + 2, Block.planks.blockID);
		world.setBlock(i + 30, j + 5, k + 3, Block.planks.blockID);
		world.setBlock(i + 30, j + 5, k + 4, Block.planks.blockID);
		world.setBlock(i + 30, j + 5, k + 5, Block.planks.blockID);
		world.setBlock(i + 30, j + 5, k + 6, Block.planks.blockID);
		world.setBlock(i + 30, j + 5, k + 7, Block.planks.blockID);
		world.setBlock(i + 30, j + 5, k + 8, Block.planks.blockID);
		world.setBlock(i + 30, j + 5, k + 9, Block.planks.blockID);
		world.setBlock(i + 30, j + 5, k + 10, Block.planks.blockID);
		world.setBlock(i + 30, j + 6, k + 1, Block.planks.blockID);
		world.setBlockAndMetadata(i + 30, j + 6, k + 5, Block.chest.blockID, 4);
		world.setBlockAndMetadata(i + 30, j + 6, k + 6, Block.chest.blockID, 4);
		TileEntityChest var18 = (TileEntityChest)world.getBlockTileEntity(i + 30, j + 6, k + 6);
        int var19;

        if (var18 != null)
        {
            for (var19 = 0; var19 < 8; ++var19)
            {
                ItemStack var11 = this.pickCheckLootItem(rand);

                if (var11 != null)
                {
                    var18.setInventorySlotContents(rand.nextInt(var18.getSizeInventory()), var11);
                }
            }
        }
		world.setBlock(i + 30, j + 6, k + 10, Block.planks.blockID);
		world.setBlock(i + 30, j + 7, k + 1, Block.planks.blockID);
		world.setBlock(i + 30, j + 7, k + 10, Block.planks.blockID);
		world.setBlock(i + 30, j + 8, k + 1, Block.planks.blockID);
		world.setBlock(i + 30, j + 8, k + 2, Block.planks.blockID);
		world.setBlock(i + 30, j + 8, k + 3, Block.planks.blockID);
		world.setBlock(i + 30, j + 8, k + 4, Block.planks.blockID);
		world.setBlock(i + 30, j + 8, k + 5, Block.planks.blockID);
		world.setBlock(i + 30, j + 8, k + 6, Block.planks.blockID);
		world.setBlock(i + 30, j + 8, k + 7, Block.planks.blockID);
		world.setBlock(i + 30, j + 8, k + 8, Block.planks.blockID);
		world.setBlock(i + 30, j + 8, k + 9, Block.planks.blockID);
		world.setBlock(i + 30, j + 8, k + 10, Block.planks.blockID);
		world.setBlock(i + 30, j + 9, k + 1, Block.fence.blockID);
		world.setBlock(i + 30, j + 9, k + 10, Block.fence.blockID);
		world.setBlock(i + 31, j + 0, k + 4, Block.planks.blockID);
		world.setBlock(i + 31, j + 0, k + 5, Block.planks.blockID);
		world.setBlock(i + 31, j + 0, k + 6, Block.planks.blockID);
		world.setBlock(i + 31, j + 0, k + 7, Block.planks.blockID);
		world.setBlock(i + 31, j + 1, k + 3, Block.planks.blockID);
		world.setBlock(i + 31, j + 1, k + 8, Block.planks.blockID);
		world.setBlock(i + 31, j + 2, k + 2, Block.planks.blockID);
		world.setBlock(i + 31, j + 2, k + 3, Block.planks.blockID);
		world.setBlock(i + 31, j + 2, k + 4, Block.planks.blockID);
		world.setBlock(i + 31, j + 2, k + 5, Block.planks.blockID);
		world.setBlock(i + 31, j + 2, k + 6, Block.planks.blockID);
		world.setBlock(i + 31, j + 2, k + 7, Block.planks.blockID);
		world.setBlock(i + 31, j + 2, k + 8, Block.planks.blockID);
		world.setBlock(i + 31, j + 2, k + 9, Block.planks.blockID);
		world.setBlock(i + 31, j + 3, k + 1, Block.planks.blockID);
		world.setBlock(i + 31, j + 3, k + 5, Block.planks.blockID);
		world.setBlock(i + 31, j + 3, k + 6, Block.planks.blockID);
		world.setBlock(i + 31, j + 3, k + 7, Block.planks.blockID);
		world.setBlock(i + 31, j + 3, k + 8, Block.planks.blockID);
		world.setBlock(i + 31, j + 3, k + 9, Block.planks.blockID);
		world.setBlock(i + 31, j + 3, k + 10, Block.planks.blockID);
		world.setBlock(i + 31, j + 4, k + 1, Block.planks.blockID);
		world.setBlock(i + 31, j + 4, k + 5, Block.planks.blockID);
		world.setBlock(i + 31, j + 4, k + 6, Block.planks.blockID);
		world.setBlock(i + 31, j + 4, k + 7, Block.planks.blockID);
		world.setBlock(i + 31, j + 4, k + 8, Block.planks.blockID);
		world.setBlock(i + 31, j + 4, k + 9, Block.planks.blockID);
		world.setBlock(i + 31, j + 4, k + 10, Block.planks.blockID);
		world.setBlock(i + 31, j + 5, k + 1, Block.planks.blockID);
		world.setBlock(i + 31, j + 5, k + 2, Block.planks.blockID);
		world.setBlock(i + 31, j + 5, k + 3, Block.planks.blockID);
		world.setBlock(i + 31, j + 5, k + 4, Block.planks.blockID);
		world.setBlock(i + 31, j + 5, k + 5, Block.planks.blockID);
		world.setBlock(i + 31, j + 5, k + 6, Block.planks.blockID);
		world.setBlock(i + 31, j + 5, k + 7, Block.planks.blockID);
		world.setBlock(i + 31, j + 5, k + 8, Block.planks.blockID);
		world.setBlock(i + 31, j + 5, k + 9, Block.planks.blockID);
		world.setBlock(i + 31, j + 5, k + 10, Block.planks.blockID);
		world.setBlock(i + 31, j + 6, k + 1, Block.planks.blockID);
		world.setBlock(i + 31, j + 6, k + 10, Block.planks.blockID);
		world.setBlock(i + 31, j + 7, k + 1, Block.planks.blockID);
		world.setBlock(i + 31, j + 7, k + 10, Block.planks.blockID);
		world.setBlockAndMetadata(i + 31, j + 8, k + 0, Block.stoneSingleSlab.blockID, 2);
		world.setBlock(i + 31, j + 8, k + 1, Block.planks.blockID);
		world.setBlock(i + 31, j + 8, k + 2, Block.planks.blockID);
		world.setBlock(i + 31, j + 8, k + 3, Block.planks.blockID);
		world.setBlock(i + 31, j + 8, k + 4, Block.planks.blockID);
		world.setBlock(i + 31, j + 8, k + 5, Block.planks.blockID);
		world.setBlock(i + 31, j + 8, k + 6, Block.planks.blockID);
		world.setBlock(i + 31, j + 8, k + 7, Block.planks.blockID);
		world.setBlock(i + 31, j + 8, k + 8, Block.planks.blockID);
		world.setBlock(i + 31, j + 8, k + 9, Block.planks.blockID);
		world.setBlock(i + 31, j + 8, k + 10, Block.planks.blockID);
		world.setBlockAndMetadata(i + 31, j + 8, k + 11, Block.stoneSingleSlab.blockID, 2);
		world.setBlock(i + 32, j + 0, k + 4, Block.planks.blockID);
		world.setBlock(i + 32, j + 0, k + 5, Block.planks.blockID);
		world.setBlock(i + 32, j + 0, k + 6, Block.planks.blockID);
		world.setBlock(i + 32, j + 0, k + 7, Block.planks.blockID);
		world.setBlock(i + 32, j + 1, k + 3, Block.planks.blockID);
		world.setBlock(i + 32, j + 1, k + 8, Block.planks.blockID);
		world.setBlock(i + 32, j + 2, k + 2, Block.planks.blockID);
		world.setBlock(i + 32, j + 2, k + 3, Block.planks.blockID);
		world.setBlock(i + 32, j + 2, k + 4, Block.planks.blockID);
		world.setBlock(i + 32, j + 2, k + 5, Block.planks.blockID);
		world.setBlock(i + 32, j + 2, k + 6, Block.planks.blockID);
		world.setBlock(i + 32, j + 2, k + 7, Block.planks.blockID);
		world.setBlock(i + 32, j + 2, k + 8, Block.planks.blockID);
		world.setBlock(i + 32, j + 2, k + 9, Block.planks.blockID);
		world.setBlock(i + 32, j + 3, k + 1, Block.planks.blockID);
		world.setBlock(i + 32, j + 3, k + 5, Block.planks.blockID);
		world.setBlock(i + 32, j + 3, k + 8, Block.bed.blockID);
		world.setBlockAndMetadata(i + 32, j + 3, k + 9, Block.bed.blockID, 8);
		world.setBlock(i + 32, j + 3, k + 10, Block.planks.blockID);
		world.setBlock(i + 32, j + 4, k + 1, Block.glass.blockID);
		world.setBlock(i + 32, j + 4, k + 5, Block.planks.blockID);
		world.setBlock(i + 32, j + 4, k + 10, Block.planks.blockID);
		world.setBlock(i + 32, j + 5, k + 1, Block.planks.blockID);
		world.setBlock(i + 32, j + 5, k + 2, Block.planks.blockID);
		world.setBlock(i + 32, j + 5, k + 3, Block.planks.blockID);
		world.setBlock(i + 32, j + 5, k + 4, Block.planks.blockID);
		world.setBlock(i + 32, j + 5, k + 5, Block.planks.blockID);
		world.setBlock(i + 32, j + 5, k + 6, Block.planks.blockID);
		world.setBlock(i + 32, j + 5, k + 7, Block.planks.blockID);
		world.setBlock(i + 32, j + 5, k + 8, Block.planks.blockID);
		world.setBlock(i + 32, j + 5, k + 9, Block.planks.blockID);
		world.setBlock(i + 32, j + 5, k + 10, Block.planks.blockID);
		world.setBlock(i + 32, j + 6, k + 1, Block.planks.blockID);
		world.setBlock(i + 32, j + 6, k + 10, Block.planks.blockID);
		world.setBlock(i + 32, j + 7, k + 1, Block.planks.blockID);
		world.setBlock(i + 32, j + 7, k + 10, Block.planks.blockID);
		world.setBlock(i + 32, j + 8, k + 1, Block.planks.blockID);
		world.setBlock(i + 32, j + 8, k + 2, Block.planks.blockID);
		world.setBlock(i + 32, j + 8, k + 3, Block.planks.blockID);
		world.setBlock(i + 32, j + 8, k + 4, Block.planks.blockID);
		world.setBlock(i + 32, j + 8, k + 5, Block.planks.blockID);
		world.setBlock(i + 32, j + 8, k + 6, Block.planks.blockID);
		world.setBlock(i + 32, j + 8, k + 7, Block.planks.blockID);
		world.setBlock(i + 32, j + 8, k + 8, Block.planks.blockID);
		world.setBlock(i + 32, j + 8, k + 9, Block.planks.blockID);
		world.setBlock(i + 32, j + 8, k + 10, Block.planks.blockID);
		world.setBlock(i + 32, j + 9, k + 1, Block.fence.blockID);
		world.setBlock(i + 32, j + 9, k + 10, Block.fence.blockID);
		world.setBlock(i + 33, j + 0, k + 4, Block.planks.blockID);
		world.setBlock(i + 33, j + 0, k + 5, Block.planks.blockID);
		world.setBlock(i + 33, j + 0, k + 6, Block.planks.blockID);
		world.setBlock(i + 33, j + 0, k + 7, Block.planks.blockID);
		world.setBlock(i + 33, j + 1, k + 3, Block.planks.blockID);
		world.setBlock(i + 33, j + 1, k + 8, Block.planks.blockID);
		world.setBlock(i + 33, j + 2, k + 2, Block.planks.blockID);
		world.setBlock(i + 33, j + 2, k + 3, Block.planks.blockID);
		world.setBlock(i + 33, j + 2, k + 4, Block.planks.blockID);
		world.setBlock(i + 33, j + 2, k + 5, Block.planks.blockID);
		world.setBlock(i + 33, j + 2, k + 6, Block.planks.blockID);
		world.setBlock(i + 33, j + 2, k + 7, Block.planks.blockID);
		world.setBlock(i + 33, j + 2, k + 8, Block.planks.blockID);
		world.setBlock(i + 33, j + 2, k + 9, Block.planks.blockID);
		world.setBlock(i + 33, j + 3, k + 1, Block.planks.blockID);
		world.setBlock(i + 33, j + 3, k + 5, Block.planks.blockID);
		world.setBlock(i + 33, j + 3, k + 10, Block.planks.blockID);
		world.setBlock(i + 33, j + 4, k + 1, Block.planks.blockID);
		world.setBlock(i + 33, j + 4, k + 5, Block.planks.blockID);
		world.setBlock(i + 33, j + 4, k + 10, Block.planks.blockID);
		world.setBlock(i + 33, j + 5, k + 1, Block.planks.blockID);
		world.setBlock(i + 33, j + 5, k + 2, Block.planks.blockID);
		world.setBlock(i + 33, j + 5, k + 3, Block.planks.blockID);
		world.setBlock(i + 33, j + 5, k + 4, Block.planks.blockID);
		world.setBlock(i + 33, j + 5, k + 5, Block.planks.blockID);
		world.setBlock(i + 33, j + 5, k + 6, Block.planks.blockID);
		world.setBlock(i + 33, j + 5, k + 7, Block.planks.blockID);
		world.setBlock(i + 33, j + 5, k + 8, Block.planks.blockID);
		world.setBlock(i + 33, j + 5, k + 9, Block.planks.blockID);
		world.setBlock(i + 33, j + 5, k + 10, Block.planks.blockID);
		world.setBlock(i + 33, j + 6, k + 1, Block.planks.blockID);
		world.setBlock(i + 33, j + 6, k + 3, Block.cloth.blockID);
		world.setBlock(i + 33, j + 6, k + 4, Block.cloth.blockID);
		world.setBlock(i + 33, j + 6, k + 5, Block.cloth.blockID);
		world.setBlock(i + 33, j + 6, k + 6, Block.cloth.blockID);
		world.setBlock(i + 33, j + 6, k + 7, Block.cloth.blockID);
		world.setBlock(i + 33, j + 6, k + 8, Block.cloth.blockID);
		world.setBlock(i + 33, j + 6, k + 10, Block.planks.blockID);
		world.setBlock(i + 33, j + 7, k + 1, Block.planks.blockID);
		world.setBlock(i + 33, j + 7, k + 10, Block.planks.blockID);
		world.setBlock(i + 33, j + 8, k + 1, Block.planks.blockID);
		world.setBlock(i + 33, j + 8, k + 2, Block.planks.blockID);
		world.setBlock(i + 33, j + 8, k + 3, Block.planks.blockID);
		world.setBlock(i + 33, j + 8, k + 4, Block.planks.blockID);
		world.setBlock(i + 33, j + 8, k + 5, Block.planks.blockID);
		world.setBlock(i + 33, j + 8, k + 6, Block.planks.blockID);
		world.setBlock(i + 33, j + 8, k + 7, Block.planks.blockID);
		world.setBlock(i + 33, j + 8, k + 8, Block.planks.blockID);
		world.setBlock(i + 33, j + 8, k + 9, Block.planks.blockID);
		world.setBlock(i + 33, j + 8, k + 10, Block.planks.blockID);
		world.setBlock(i + 33, j + 9, k + 1, Block.fence.blockID);
		world.setBlock(i + 33, j + 9, k + 10, Block.fence.blockID);
		world.setBlock(i + 34, j + 0, k + 4, Block.planks.blockID);
		world.setBlock(i + 34, j + 0, k + 5, Block.planks.blockID);
		world.setBlock(i + 34, j + 0, k + 6, Block.planks.blockID);
		world.setBlock(i + 34, j + 0, k + 7, Block.planks.blockID);
		world.setBlock(i + 34, j + 1, k + 3, Block.planks.blockID);
		world.setBlock(i + 34, j + 1, k + 8, Block.planks.blockID);
		world.setBlock(i + 34, j + 2, k + 2, Block.planks.blockID);
		world.setBlock(i + 34, j + 2, k + 3, Block.planks.blockID);
		world.setBlock(i + 34, j + 2, k + 4, Block.planks.blockID);
		world.setBlock(i + 34, j + 2, k + 5, Block.planks.blockID);
		world.setBlock(i + 34, j + 2, k + 6, Block.planks.blockID);
		world.setBlock(i + 34, j + 2, k + 7, Block.planks.blockID);
		world.setBlock(i + 34, j + 2, k + 8, Block.planks.blockID);
		world.setBlock(i + 34, j + 2, k + 9, Block.planks.blockID);
		world.setBlock(i + 34, j + 3, k + 1, Block.planks.blockID);
		world.setBlock(i + 34, j + 3, k + 5, Block.planks.blockID);
		world.setBlock(i + 34, j + 3, k + 10, Block.planks.blockID);
		world.setBlock(i + 34, j + 4, k + 1, Block.planks.blockID);
		world.setBlock(i + 34, j + 4, k + 5, Block.planks.blockID);
		world.setBlock(i + 34, j + 4, k + 10, Block.planks.blockID);
		world.setBlock(i + 34, j + 5, k + 1, Block.planks.blockID);
		world.setBlock(i + 34, j + 5, k + 2, Block.planks.blockID);
		world.setBlock(i + 34, j + 5, k + 3, Block.planks.blockID);
		world.setBlock(i + 34, j + 5, k + 4, Block.planks.blockID);
		world.setBlock(i + 34, j + 5, k + 5, Block.planks.blockID);
		world.setBlock(i + 34, j + 5, k + 6, Block.planks.blockID);
		world.setBlock(i + 34, j + 5, k + 7, Block.planks.blockID);
		world.setBlock(i + 34, j + 5, k + 8, Block.planks.blockID);
		world.setBlock(i + 34, j + 5, k + 9, Block.planks.blockID);
		world.setBlock(i + 34, j + 5, k + 10, Block.planks.blockID);
		world.setBlock(i + 34, j + 6, k + 1, Block.planks.blockID);
		world.setBlock(i + 34, j + 6, k + 3, Block.cloth.blockID);
		world.setBlock(i + 34, j + 6, k + 4, Block.cloth.blockID);
		world.setBlock(i + 34, j + 6, k + 5, Block.cloth.blockID);
		world.setBlock(i + 34, j + 6, k + 6, Block.cloth.blockID);
		world.setBlock(i + 34, j + 6, k + 7, Block.cloth.blockID);
		world.setBlock(i + 34, j + 6, k + 8, Block.cloth.blockID);
		world.setBlock(i + 34, j + 6, k + 10, Block.planks.blockID);
		world.setBlock(i + 34, j + 7, k + 1, Block.planks.blockID);
		world.setBlock(i + 34, j + 7, k + 3, Block.cloth.blockID);
		world.setBlock(i + 34, j + 7, k + 4, Block.cloth.blockID);
		world.setBlock(i + 34, j + 7, k + 5, Block.cloth.blockID);
		world.setBlock(i + 34, j + 7, k + 6, Block.cloth.blockID);
		world.setBlock(i + 34, j + 7, k + 7, Block.cloth.blockID);
		world.setBlock(i + 34, j + 7, k + 8, Block.cloth.blockID);
		world.setBlock(i + 34, j + 7, k + 10, Block.planks.blockID);
		world.setBlock(i + 34, j + 8, k + 1, Block.planks.blockID);
		world.setBlock(i + 34, j + 8, k + 2, Block.planks.blockID);
		world.setBlock(i + 34, j + 8, k + 3, Block.planks.blockID);
		world.setBlock(i + 34, j + 8, k + 4, Block.planks.blockID);
		world.setBlock(i + 34, j + 8, k + 5, Block.planks.blockID);
		world.setBlock(i + 34, j + 8, k + 6, Block.planks.blockID);
		world.setBlock(i + 34, j + 8, k + 7, Block.planks.blockID);
		world.setBlock(i + 34, j + 8, k + 8, Block.planks.blockID);
		world.setBlock(i + 34, j + 8, k + 9, Block.planks.blockID);
		world.setBlock(i + 34, j + 8, k + 10, Block.planks.blockID);
		world.setBlock(i + 34, j + 9, k + 1, Block.fence.blockID);
		world.setBlock(i + 34, j + 9, k + 5, Block.wood.blockID);
		world.setBlock(i + 34, j + 9, k + 6, Block.wood.blockID);
		world.setBlock(i + 34, j + 9, k + 10, Block.fence.blockID);
		world.setBlock(i + 34, j + 10, k + 5, Block.wood.blockID);
		world.setBlock(i + 34, j + 10, k + 6, Block.wood.blockID);
		world.setBlock(i + 34, j + 11, k + 5, Block.wood.blockID);
		world.setBlock(i + 34, j + 11, k + 6, Block.wood.blockID);
		world.setBlock(i + 34, j + 12, k + 5, Block.wood.blockID);
		world.setBlock(i + 34, j + 12, k + 6, Block.wood.blockID);
		world.setBlock(i + 34, j + 13, k + 5, Block.wood.blockID);
		world.setBlock(i + 34, j + 13, k + 6, Block.wood.blockID);
		world.setBlock(i + 35, j + 0, k + 4, Block.planks.blockID);
		world.setBlock(i + 35, j + 0, k + 5, Block.planks.blockID);
		world.setBlock(i + 35, j + 0, k + 6, Block.planks.blockID);
		world.setBlock(i + 35, j + 0, k + 7, Block.planks.blockID);
		world.setBlock(i + 35, j + 1, k + 3, Block.planks.blockID);
		world.setBlock(i + 35, j + 1, k + 8, Block.planks.blockID);
		world.setBlock(i + 35, j + 2, k + 2, Block.planks.blockID);
		world.setBlock(i + 35, j + 2, k + 3, Block.planks.blockID);
		world.setBlock(i + 35, j + 2, k + 4, Block.planks.blockID);
		world.setBlock(i + 35, j + 2, k + 5, Block.planks.blockID);
		world.setBlock(i + 35, j + 2, k + 6, Block.planks.blockID);
		world.setBlock(i + 35, j + 2, k + 7, Block.planks.blockID);
		world.setBlock(i + 35, j + 2, k + 8, Block.planks.blockID);
		world.setBlock(i + 35, j + 2, k + 9, Block.planks.blockID);
		world.setBlock(i + 35, j + 3, k + 1, Block.planks.blockID);
		world.setBlock(i + 35, j + 3, k + 10, Block.planks.blockID);
		world.setBlock(i + 35, j + 4, k + 1, Block.planks.blockID);
		world.setBlock(i + 35, j + 4, k + 10, Block.glass.blockID);
		world.setBlock(i + 35, j + 5, k + 1, Block.planks.blockID);
		world.setBlock(i + 35, j + 5, k + 2, Block.planks.blockID);
		world.setBlock(i + 35, j + 5, k + 3, Block.planks.blockID);
		world.setBlock(i + 35, j + 5, k + 4, Block.planks.blockID);
		world.setBlock(i + 35, j + 5, k + 5, Block.planks.blockID);
		world.setBlock(i + 35, j + 5, k + 6, Block.planks.blockID);
		world.setBlock(i + 35, j + 5, k + 7, Block.planks.blockID);
		world.setBlock(i + 35, j + 5, k + 8, Block.planks.blockID);

		generate2(world, rand, i, j, k);
		return true;
	}

	public boolean generate2(World world, Random rand, int i, int j, int k) {
		world.setBlock(i + 35, j + 5, k + 9, Block.planks.blockID);
		world.setBlock(i + 35, j + 5, k + 10, Block.planks.blockID);
		world.setBlock(i + 35, j + 6, k + 3, Block.cloth.blockID);
		world.setBlock(i + 35, j + 6, k + 4, Block.cloth.blockID);
		world.setBlock(i + 35, j + 6, k + 5, Block.cloth.blockID);
		world.setBlock(i + 35, j + 6, k + 6, Block.cloth.blockID);
		world.setBlock(i + 35, j + 6, k + 7, Block.cloth.blockID);
		world.setBlock(i + 35, j + 6, k + 8, Block.cloth.blockID);
		world.setBlock(i + 35, j + 7, k + 3, Block.cloth.blockID);
		world.setBlock(i + 35, j + 7, k + 4, Block.cloth.blockID);
		world.setBlock(i + 35, j + 7, k + 5, Block.cloth.blockID);
		world.setBlock(i + 35, j + 7, k + 6, Block.cloth.blockID);
		world.setBlock(i + 35, j + 7, k + 7, Block.cloth.blockID);
		world.setBlock(i + 35, j + 7, k + 8, Block.cloth.blockID);
		world.setBlock(i + 35, j + 8, k + 1, Block.planks.blockID);
		world.setBlock(i + 35, j + 8, k + 2, Block.planks.blockID);
		world.setBlock(i + 35, j + 8, k + 3, Block.planks.blockID);
		world.setBlock(i + 35, j + 8, k + 4, Block.planks.blockID);
		world.setBlock(i + 35, j + 8, k + 5, Block.planks.blockID);
		world.setBlock(i + 35, j + 8, k + 6, Block.planks.blockID);
		world.setBlock(i + 35, j + 8, k + 7, Block.planks.blockID);
		world.setBlock(i + 35, j + 8, k + 8, Block.planks.blockID);
		world.setBlock(i + 35, j + 8, k + 9, Block.planks.blockID);
		world.setBlock(i + 35, j + 8, k + 10, Block.planks.blockID);
		world.setBlock(i + 35, j + 9, k + 1, Block.fence.blockID);
		world.setBlock(i + 35, j + 9, k + 5, Block.wood.blockID);
		world.setBlock(i + 35, j + 9, k + 6, Block.wood.blockID);
		world.setBlock(i + 35, j + 9, k + 10, Block.fence.blockID);
		world.setBlock(i + 35, j + 10, k + 5, Block.wood.blockID);
		world.setBlock(i + 35, j + 10, k + 6, Block.wood.blockID);
		world.setBlock(i + 35, j + 11, k + 5, Block.wood.blockID);
		world.setBlock(i + 35, j + 11, k + 6, Block.wood.blockID);
		world.setBlock(i + 35, j + 12, k + 5, Block.wood.blockID);
		world.setBlock(i + 35, j + 12, k + 6, Block.wood.blockID);
		world.setBlock(i + 35, j + 13, k + 5, Block.wood.blockID);
		world.setBlock(i + 35, j + 13, k + 6, Block.wood.blockID);
		world.setBlock(i + 36, j + 0, k + 4, Block.planks.blockID);
		world.setBlock(i + 36, j + 0, k + 5, Block.planks.blockID);
		world.setBlock(i + 36, j + 0, k + 6, Block.planks.blockID);
		world.setBlock(i + 36, j + 0, k + 7, Block.planks.blockID);
		world.setBlock(i + 36, j + 1, k + 3, Block.planks.blockID);
		world.setBlock(i + 36, j + 1, k + 8, Block.planks.blockID);
		world.setBlock(i + 36, j + 2, k + 2, Block.planks.blockID);
		world.setBlock(i + 36, j + 2, k + 3, Block.planks.blockID);
		world.setBlock(i + 36, j + 2, k + 4, Block.planks.blockID);
		world.setBlock(i + 36, j + 2, k + 5, Block.planks.blockID);
		world.setBlock(i + 36, j + 2, k + 6, Block.planks.blockID);
		world.setBlock(i + 36, j + 2, k + 7, Block.planks.blockID);
		world.setBlock(i + 36, j + 2, k + 8, Block.planks.blockID);
		world.setBlock(i + 36, j + 2, k + 9, Block.planks.blockID);
		world.setBlock(i + 36, j + 3, k + 1, Block.planks.blockID);
