package fossil.gens;

import java.util.Random;

import fossil.Fossil;

import net.minecraft.block.Block;
import net.minecraft.item.Item;
import net.minecraft.item.ItemStack;
import net.minecraft.tileentity.TileEntityChest;
import net.minecraft.world.World;
import net.minecraft.world.gen.feature.WorldGenerator;

public class WorldGeneratorBigShip extends WorldGenerator
{

/*protected int[] GetValidSpawnBlocks()
	{
		return new int[] 
		{
				Block.waterStill.blockID,
				Block.sand.blockID
		};
	}

	public boolean LocationIsValidSpawn(World world, int i, int j, int k)
	{
	int distanceToAir = 0;
	int checkID = world.getBlockId(i, j, k);

	while (checkID != 0)
	{
	distanceToAir++;
	checkID = world.getBlockId(i, j + distanceToAir, k);
	}

	if (distanceToAir > 0)
	{
	return false;
	}
	j += distanceToAir - 1;

	int blockID = world.getBlockId(i, j, k);
	int blockIDAbove = world.getBlockId(i, j + 1, k);
	int blockIDBelow = world.getBlockId(i, j - 1, k);
	for (int x : GetValidSpawnBlocks())
	{
	if (blockIDAbove != 0)
	{
	return false;
	}
	if (blockID == x)
	{
	return true;
	} else if (blockID == Block.snow.blockID && blockIDBelow == x)
	{
	return true;
	}
	}
	return false;
	}

	public WorldGeneratorBigShip()
	{
	}*/

	
	public boolean generate(World world, Random rand, int i, int j, int k) 
	{
		 // check that each corner is one of the valid spawn blocks
		//if (!LocationIsValidSpawn(world, i, j, k) || !LocationIsValidSpawn(world, i + 4, j, k) || !LocationIsValidSpawn(world, i + 4, j, k + 4) || !LocationIsValidSpawn(world, i, j, k + 4))
		//{
		//return false;
		//}
		
		System.out.println("Generating Big Ship");
		
		world.setBlock(i + 9, j - 1, k + 6, Block.planks.blockID);
		world.setBlock(i + 9, j - 1, k + 7, Block.planks.blockID);
		world.setBlock(i + 9, j - 1, k + 8, Block.planks.blockID);
		world.setBlock(i + 9, j - 1, k + 9, Block.planks.blockID);
		world.setBlock(i + 9, j - 1, k + 10, Block.planks.blockID);
		world.setBlock(i + 9, j - 1, k + 11, Block.planks.blockID);
		world.setBlock(i + 9, j - 1, k + 12, Block.planks.blockID);
		world.setBlock(i + 9, j - 1, k + 13, Block.planks.blockID);
		world.setBlock(i + 9, j - 1, k + 14, Block.planks.blockID);
		world.setBlock(i + 9, j - 1, k + 15, Block.planks.blockID);
		world.setBlock(i + 9, j - 1, k + 16, Block.planks.blockID);
		world.setBlock(i + 9, j - 1, k + 17, Block.planks.blockID);
		world.setBlock(i + 9, j - 1, k + 18, Block.planks.blockID);
		world.setBlock(i + 9, j - 1, k + 19, Block.planks.blockID);
		world.setBlock(i + 9, j - 1, k + 20, Block.planks.blockID);
		world.setBlock(i + 9, j - 1, k + 21, Block.planks.blockID);
		world.setBlock(i + 9, j - 1, k + 22, Block.planks.blockID);
		world.setBlock(i + 9, j - 1, k + 23, Block.planks.blockID);
		world.setBlock(i + 9, j - 1, k + 24, Block.planks.blockID);
		world.setBlock(i + 9, j - 1, k + 25, Block.planks.blockID);
		world.setBlock(i + 9, j - 1, k + 26, Block.planks.blockID);
		world.setBlock(i + 9, j - 1, k + 27, Block.planks.blockID);
		world.setBlock(i + 9, j - 1, k + 28, Block.planks.blockID);
		world.setBlock(i + 9, j - 1, k + 29, Block.planks.blockID);
		world.setBlock(i + 9, j - 1, k + 30, Block.planks.blockID);
		world.setBlock(i + 9, j - 1, k + 31, Block.planks.blockID);
		world.setBlock(i + 9, j - 1, k + 32, Block.planks.blockID);
		world.setBlock(i + 9, j - 1, k + 33, Block.planks.blockID);
		world.setBlock(i + 9, j - 1, k + 34, Block.planks.blockID);
		world.setBlock(i + 9, j - 1, k + 35, Block.planks.blockID);
		world.setBlock(i + 9, j - 1, k + 36, Block.planks.blockID);
		world.setBlock(i + 9, j - 1, k + 37, Block.planks.blockID);
		world.setBlock(i + 9, j - 1, k + 38, Block.planks.blockID);
		world.setBlock(i + 9, j - 1, k + 39, Block.planks.blockID);
		world.setBlock(i + 10, j - 1, k + 5, Block.planks.blockID);
		world.setBlock(i + 10, j - 1, k + 6, Block.planks.blockID);
		world.setBlock(i + 10, j - 1, k + 7, Block.planks.blockID);
		world.setBlock(i + 10, j - 1, k + 8, Block.planks.blockID);
		world.setBlock(i + 10, j - 1, k + 9, Block.planks.blockID);
		world.setBlock(i + 10, j - 1, k + 10, Block.planks.blockID);
		world.setBlock(i + 10, j - 1, k + 11, Block.planks.blockID);
		world.setBlock(i + 10, j - 1, k + 12, Block.planks.blockID);
		world.setBlock(i + 10, j - 1, k + 13, Block.planks.blockID);
		world.setBlock(i + 10, j - 1, k + 14, Block.planks.blockID);
		world.setBlock(i + 10, j - 1, k + 15, Block.planks.blockID);
		world.setBlock(i + 10, j - 1, k + 16, Block.planks.blockID);
		world.setBlock(i + 10, j - 1, k + 17, Block.planks.blockID);
		world.setBlock(i + 10, j - 1, k + 18, Block.planks.blockID);
		world.setBlock(i + 10, j - 1, k + 19, Block.planks.blockID);
		world.setBlock(i + 10, j - 1, k + 20, Block.planks.blockID);
		world.setBlock(i + 10, j - 1, k + 21, Block.planks.blockID);
		world.setBlock(i + 10, j - 1, k + 22, Block.planks.blockID);
		world.setBlock(i + 10, j - 1, k + 23, Block.planks.blockID);
		world.setBlock(i + 10, j - 1, k + 24, Block.planks.blockID);
		world.setBlock(i + 10, j - 1, k + 25, Block.planks.blockID);
		world.setBlock(i + 10, j - 1, k + 26, Block.planks.blockID);
		world.setBlock(i + 10, j - 1, k + 27, Block.planks.blockID);
		world.setBlock(i + 10, j - 1, k + 28, Block.planks.blockID);
		world.setBlock(i + 10, j - 1, k + 29, Block.planks.blockID);
		world.setBlock(i + 10, j - 1, k + 30, Block.planks.blockID);
		world.setBlock(i + 10, j - 1, k + 31, Block.planks.blockID);
		world.setBlock(i + 10, j - 1, k + 32, Block.planks.blockID);
		world.setBlock(i + 10, j - 1, k + 33, Block.planks.blockID);
		world.setBlock(i + 10, j - 1, k + 34, Block.planks.blockID);
		world.setBlock(i + 10, j - 1, k + 35, Block.planks.blockID);
		world.setBlock(i + 10, j - 1, k + 36, Block.planks.blockID);
		world.setBlock(i + 10, j - 1, k + 37, Block.planks.blockID);
		world.setBlock(i + 10, j - 1, k + 38, Block.planks.blockID);
		world.setBlock(i + 10, j - 1, k + 39, Block.planks.blockID);
		world.setBlock(i + 10, j - 1, k + 40, Block.planks.blockID);
		world.setBlock(i + 10, j - 1, k + 41, Block.planks.blockID);
		world.setBlock(i + 10, j - 1, k + 42, Block.planks.blockID);
		world.setBlock(i + 11, j - 1, k + 6, Block.planks.blockID);
		world.setBlock(i + 11, j - 1, k + 7, Block.planks.blockID);
		world.setBlock(i + 11, j - 1, k + 8, Block.planks.blockID);
		world.setBlock(i + 11, j - 1, k + 9, Block.planks.blockID);
		world.setBlock(i + 11, j - 1, k + 10, Block.planks.blockID);
		world.setBlock(i + 11, j - 1, k + 11, Block.planks.blockID);
		world.setBlock(i + 11, j - 1, k + 12, Block.planks.blockID);
		world.setBlock(i + 11, j - 1, k + 13, Block.planks.blockID);
		world.setBlock(i + 11, j - 1, k + 14, Block.planks.blockID);
		world.setBlock(i + 11, j - 1, k + 15, Block.planks.blockID);
		world.setBlock(i + 11, j - 1, k + 16, Block.planks.blockID);
		world.setBlock(i + 11, j - 1, k + 17, Block.planks.blockID);
		world.setBlock(i + 11, j - 1, k + 18, Block.planks.blockID);
		world.setBlock(i + 11, j - 1, k + 19, Block.planks.blockID);
		world.setBlock(i + 11, j - 1, k + 20, Block.planks.blockID);
		world.setBlock(i + 11, j - 1, k + 21, Block.planks.blockID);
		world.setBlock(i + 11, j - 1, k + 22, Block.planks.blockID);
		world.setBlock(i + 11, j - 1, k + 23, Block.planks.blockID);
		world.setBlock(i + 11, j - 1, k + 24, Block.planks.blockID);
		world.setBlock(i + 11, j - 1, k + 25, Block.planks.blockID);
		world.setBlock(i + 11, j - 1, k + 26, Block.planks.blockID);
		world.setBlock(i + 11, j - 1, k + 27, Block.planks.blockID);
		world.setBlock(i + 11, j - 1, k + 28, Block.planks.blockID);
		world.setBlock(i + 11, j - 1, k + 29, Block.planks.blockID);
		world.setBlock(i + 11, j - 1, k + 30, Block.planks.blockID);
		world.setBlock(i + 11, j - 1, k + 31, Block.planks.blockID);
		world.setBlock(i + 11, j - 1, k + 32, Block.planks.blockID);
		world.setBlock(i + 11, j - 1, k + 33, Block.planks.blockID);
		world.setBlock(i + 11, j - 1, k + 34, Block.planks.blockID);
		world.setBlock(i + 11, j - 1, k + 35, Block.planks.blockID);
		world.setBlock(i + 11, j - 1, k + 36, Block.planks.blockID);
		world.setBlock(i + 11, j - 1, k + 37, Block.planks.blockID);
		world.setBlock(i + 11, j - 1, k + 38, Block.planks.blockID);
		world.setBlock(i + 11, j - 1, k + 39, Block.planks.blockID);
		world.setBlock(i + 11, j - 1, k + 40, Block.planks.blockID);
		world.setBlock(i + 11, j - 1, k + 41, Block.planks.blockID);
		world.setBlock(i + 11, j - 1, k + 42, Block.planks.blockID);
		world.setBlock(i + 12, j - 1, k + 7, Block.planks.blockID);
		world.setBlock(i + 12, j - 1, k + 8, Block.planks.blockID);
		world.setBlock(i + 12, j - 1, k + 9, Block.planks.blockID);
		world.setBlock(i + 12, j - 1, k + 10, Block.planks.blockID);
		world.setBlock(i + 12, j - 1, k + 11, Block.planks.blockID);
		world.setBlock(i + 12, j - 1, k + 12, Block.planks.blockID);
		world.setBlock(i + 12, j - 1, k + 13, Block.planks.blockID);
		world.setBlock(i + 12, j - 1, k + 14, Block.planks.blockID);
		world.setBlock(i + 12, j - 1, k + 15, Block.planks.blockID);
		world.setBlock(i + 12, j - 1, k + 16, Block.planks.blockID);
		world.setBlock(i + 12, j - 1, k + 17, Block.planks.blockID);
		world.setBlock(i + 12, j - 1, k + 18, Block.planks.blockID);
		world.setBlock(i + 12, j - 1, k + 19, Block.planks.blockID);
		world.setBlock(i + 12, j - 1, k + 20, Block.planks.blockID);
		world.setBlock(i + 12, j - 1, k + 21, Block.planks.blockID);
		world.setBlock(i + 12, j - 1, k + 22, Block.planks.blockID);
		world.setBlock(i + 12, j - 1, k + 23, Block.planks.blockID);
		world.setBlock(i + 12, j - 1, k + 24, Block.planks.blockID);
		world.setBlock(i + 12, j - 1, k + 25, Block.planks.blockID);
		world.setBlock(i + 12, j - 1, k + 26, Block.planks.blockID);
		world.setBlock(i + 12, j - 1, k + 27, Block.planks.blockID);
		world.setBlock(i + 12, j - 1, k + 28, Block.planks.blockID);
		world.setBlock(i + 12, j - 1, k + 29, Block.planks.blockID);
		world.setBlock(i + 12, j - 1, k + 30, Block.planks.blockID);
		world.setBlock(i + 12, j - 1, k + 31, Block.planks.blockID);
		world.setBlock(i + 12, j - 1, k + 32, Block.planks.blockID);
		world.setBlock(i + 12, j - 1, k + 33, Block.planks.blockID);
		world.setBlock(i + 12, j - 1, k + 34, Block.planks.blockID);
		world.setBlock(i + 12, j - 1, k + 35, Block.planks.blockID);
		world.setBlock(i + 12, j - 1, k + 36, Block.planks.blockID);
		world.setBlock(i + 12, j - 1, k + 37, Block.planks.blockID);
		world.setBlock(i + 12, j - 1, k + 38, Block.planks.blockID);
		world.setBlock(i + 12, j - 1, k + 39, Block.planks.blockID);

		generate2(world, rand, i, j, k);
		return true;
	}
	
	public boolean generate2(World world, Random rand, int i, int j, int k) 
	{
	
		world.setBlock(i + 8, j + 0, k + 5, Block.planks.blockID);
		world.setBlock(i + 8, j + 0, k + 6, Block.planks.blockID);
		world.setBlock(i + 8, j + 0, k + 7, Block.planks.blockID);
		world.setBlock(i + 8, j + 0, k + 8, Block.planks.blockID);
		world.setBlock(i + 8, j + 0, k + 9, Block.planks.blockID);
		world.setBlock(i + 8, j + 0, k + 10, Block.planks.blockID);
		world.setBlock(i + 8, j + 0, k + 11, Block.planks.blockID);
		world.setBlock(i + 8, j + 0, k + 12, Block.planks.blockID);
		world.setBlock(i + 8, j + 0, k + 13, Block.planks.blockID);
		world.setBlock(i + 8, j + 0, k + 14, Block.planks.blockID);
		world.setBlock(i + 8, j + 0, k + 15, Block.planks.blockID);
		world.setBlock(i + 8, j + 0, k + 16, Block.planks.blockID);
		world.setBlock(i + 8, j + 0, k + 17, Block.planks.blockID);
		world.setBlock(i + 8, j + 0, k + 18, Block.planks.blockID);
		world.setBlock(i + 8, j + 0, k + 19, Block.planks.blockID);
		world.setBlock(i + 8, j + 0, k + 20, Block.planks.blockID);
		world.setBlock(i + 8, j + 0, k + 21, Block.planks.blockID);
		world.setBlock(i + 8, j + 0, k + 22, Block.planks.blockID);
		world.setBlock(i + 8, j + 0, k + 23, Block.planks.blockID);
		world.setBlock(i + 8, j + 0, k + 24, Block.planks.blockID);
		world.setBlock(i + 8, j + 0, k + 25, Block.planks.blockID);
		world.setBlock(i + 8, j + 0, k + 26, Block.planks.blockID);
		world.setBlock(i + 8, j + 0, k + 27, Block.planks.blockID);
		world.setBlock(i + 8, j + 0, k + 28, Block.planks.blockID);
		world.setBlock(i + 8, j + 0, k + 29, Block.planks.blockID);
		world.setBlock(i + 8, j + 0, k + 30, Block.planks.blockID);
		world.setBlock(i + 8, j + 0, k + 31, Block.planks.blockID);
		world.setBlock(i + 8, j + 0, k + 32, Block.planks.blockID);
		world.setBlock(i + 8, j + 0, k + 33, Block.planks.blockID);
		world.setBlock(i + 8, j + 0, k + 34, Block.planks.blockID);
		world.setBlock(i + 8, j + 0, k + 35, Block.planks.blockID);
		world.setBlock(i + 8, j + 0, k + 36, Block.planks.blockID);
		world.setBlock(i + 8, j + 0, k + 37, Block.planks.blockID);
		world.setBlock(i + 8, j + 0, k + 38, Block.planks.blockID);
		world.setBlock(i + 8, j + 0, k + 39, Block.planks.blockID);
		world.setBlock(i + 9, j + 0, k + 4, Block.planks.blockID);
		world.setBlock(i + 9, j + 0, k + 5, Block.planks.blockID);
		world.setBlock(i + 9, j + 0, k + 6, Block.planks.blockID);
		world.setBlock(i + 9, j + 0, k + 27, Block.planks.blockID);
		world.setBlock(i + 9, j + 0, k + 39, Block.planks.blockID);
		world.setBlock(i + 9, j + 0, k + 40, Block.planks.blockID);
		world.setBlock(i + 9, j + 0, k + 41, Block.planks.blockID);
		world.setBlock(i + 10, j + 0, k + 4, Block.planks.blockID);
		world.setBlock(i + 10, j + 0, k + 5, Block.planks.blockID);
		world.setBlock(i + 10, j + 0, k + 42, Block.planks.blockID);
		world.setBlock(i + 10, j + 0, k + 43, Block.planks.blockID);
		world.setBlock(i + 11, j + 0, k + 4, Block.planks.blockID);
		world.setBlock(i + 11, j + 0, k + 5, Block.planks.blockID);
		world.setBlock(i + 11, j + 0, k + 42, Block.planks.blockID);
		world.setBlock(i + 11, j + 0, k + 43, Block.planks.blockID);
		world.setBlock(i + 12, j + 0, k + 5, Block.planks.blockID);
		world.setBlock(i + 12, j + 0, k + 6, Block.planks.blockID);
		world.setBlock(i + 12, j + 0, k + 39, Block.planks.blockID);
		world.setBlock(i + 12, j + 0, k + 40, Block.planks.blockID);
		world.setBlock(i + 12, j + 0, k + 41, Block.planks.blockID);
		world.setBlock(i + 13, j + 0, k + 6, Block.planks.blockID);
		world.setBlock(i + 13, j + 0, k + 7, Block.planks.blockID);
		world.setBlock(i + 13, j + 0, k + 8, Block.planks.blockID);
		world.setBlock(i + 13, j + 0, k + 9, Block.planks.blockID);
		world.setBlock(i + 13, j + 0, k + 10, Block.planks.blockID);
		world.setBlock(i + 13, j + 0, k + 11, Block.planks.blockID);
		world.setBlock(i + 13, j + 0, k + 12, Block.planks.blockID);
		world.setBlock(i + 13, j + 0, k + 13, Block.planks.blockID);
		world.setBlock(i + 13, j + 0, k + 14, Block.planks.blockID);
		world.setBlock(i + 13, j + 0, k + 15, Block.planks.blockID);
		world.setBlock(i + 13, j + 0, k + 16, Block.planks.blockID);
		world.setBlock(i + 13, j + 0, k + 17, Block.planks.blockID);
		world.setBlock(i + 13, j + 0, k + 18, Block.planks.blockID);
		world.setBlock(i + 13, j + 0, k + 19, Block.planks.blockID);
		world.setBlock(i + 13, j + 0, k + 20, Block.planks.blockID);
		world.setBlock(i + 13, j + 0, k + 21, Block.planks.blockID);
		world.setBlock(i + 13, j + 0, k + 22, Block.planks.blockID);
		world.setBlock(i + 13, j + 0, k + 23, Block.planks.blockID);
		world.setBlock(i + 13, j + 0, k + 24, Block.planks.blockID);
		world.setBlock(i + 13, j + 0, k + 25, Block.planks.blockID);
		world.setBlock(i + 13, j + 0, k + 26, Block.planks.blockID);
		world.setBlock(i + 13, j + 0, k + 27, Block.planks.blockID);
		world.setBlock(i + 13, j + 0, k + 28, Block.planks.blockID);
		world.setBlock(i + 13, j + 0, k + 29, Block.planks.blockID);
		world.setBlock(i + 13, j + 0, k + 30, Block.planks.blockID);
		world.setBlock(i + 13, j + 0, k + 31, Block.planks.blockID);
		world.setBlock(i + 13, j + 0, k + 32, Block.planks.blockID);
		world.setBlock(i + 13, j + 0, k + 33, Block.planks.blockID);
		world.setBlock(i + 13, j + 0, k + 34, Block.planks.blockID);
		world.setBlock(i + 13, j + 0, k + 35, Block.planks.blockID);
		world.setBlock(i + 13, j + 0, k + 36, Block.planks.blockID);
		world.setBlock(i + 13, j + 0, k + 37, Block.planks.blockID);
		world.setBlock(i + 13, j + 0, k + 38, Block.planks.blockID);
		world.setBlock(i + 13, j + 0, k + 39, Block.planks.blockID);
	
		generate3(world, rand, i, j, k);
		return true;
	}
	
	public boolean generate3(World world, Random rand, int i, int j, int k) 
	{
	
		world.setBlock(i + 7, j + 1, k + 4, Block.planks.blockID);
		world.setBlock(i + 7, j + 1, k + 5, Block.planks.blockID);
		world.setBlock(i + 7, j + 1, k + 6, Block.planks.blockID);
		world.setBlock(i + 7, j + 1, k + 7, Block.planks.blockID);
		world.setBlock(i + 7, j + 1, k + 8, Block.planks.blockID);
		world.setBlock(i + 7, j + 1, k + 9, Block.planks.blockID);
		world.setBlock(i + 7, j + 1, k + 10, Block.planks.blockID);
		world.setBlock(i + 7, j + 1, k + 11, Block.planks.blockID);
		world.setBlock(i + 7, j + 1, k + 12, Block.planks.blockID);
		world.setBlock(i + 7, j + 1, k + 13, Block.planks.blockID);
		world.setBlock(i + 7, j + 1, k + 14, Block.planks.blockID);
		world.setBlock(i + 7, j + 1, k + 15, Block.planks.blockID);
		world.setBlock(i + 7, j + 1, k + 16, Block.planks.blockID);
		world.setBlock(i + 7, j + 1, k + 17, Block.planks.blockID);
		world.setBlock(i + 7, j + 1, k + 18, Block.planks.blockID);
		world.setBlock(i + 7, j + 1, k + 19, Block.planks.blockID);
		world.setBlock(i + 7, j + 1, k + 20, Block.planks.blockID);
		world.setBlock(i + 7, j + 1, k + 21, Block.planks.blockID);
		world.setBlock(i + 7, j + 1, k + 22, Block.planks.blockID);
		world.setBlock(i + 7, j + 1, k + 23, Block.planks.blockID);
		world.setBlock(i + 7, j + 1, k + 24, Block.planks.blockID);
		world.setBlock(i + 7, j + 1, k + 25, Block.planks.blockID);
		world.setBlock(i + 7, j + 1, k + 26, Block.planks.blockID);
		world.setBlock(i + 7, j + 1, k + 27, Block.planks.blockID);
		world.setBlock(i + 7, j + 1, k + 28, Block.planks.blockID);
		world.setBlock(i + 7, j + 1, k + 29, Block.planks.blockID);
		world.setBlock(i + 7, j + 1, k + 30, Block.planks.blockID);
		world.setBlock(i + 7, j + 1, k + 31, Block.planks.blockID);
		world.setBlock(i + 7, j + 1, k + 32, Block.planks.blockID);
		world.setBlock(i + 7, j + 1, k + 33, Block.planks.blockID);
		world.setBlock(i + 7, j + 1, k + 34, Block.planks.blockID);
		world.setBlock(i + 7, j + 1, k + 35, Block.planks.blockID);
		world.setBlock(i + 7, j + 1, k + 36, Block.planks.blockID);
		world.setBlock(i + 7, j + 1, k + 37, Block.planks.blockID);
		world.setBlock(i + 7, j + 1, k + 38, Block.planks.blockID);
		world.setBlock(i + 7, j + 1, k + 39, Block.planks.blockID);
		world.setBlock(i + 8, j + 1, k + 3, Block.planks.blockID);
		world.setBlock(i + 8, j + 1, k + 4, Block.planks.blockID);
		world.setBlock(i + 8, j + 1, k + 5, Block.planks.blockID);
		world.setBlock(i + 8, j + 1, k + 6, Block.planks.blockID);
		world.setBlock(i + 8, j + 1, k + 7, Block.planks.blockID);
		world.setBlock(i + 8, j + 1, k + 8, Block.planks.blockID);
		world.setBlock(i + 8, j + 1, k + 9, Block.planks.blockID);
		world.setBlock(i + 8, j + 1, k + 10, Block.planks.blockID);
		world.setBlock(i + 8, j + 1, k + 11, Block.planks.blockID);
		world.setBlock(i + 8, j + 1, k + 12, Block.planks.blockID);
		world.setBlock(i + 8, j + 1, k + 13, Block.planks.blockID);
		world.setBlock(i + 8, j + 1, k + 14, Block.planks.blockID);
		world.setBlock(i + 8, j + 1, k + 15, Block.planks.blockID);
		world.setBlock(i + 8, j + 1, k + 16, Block.planks.blockID);
		world.setBlock(i + 8, j + 1, k + 17, Block.planks.blockID);
		world.setBlock(i + 8, j + 1, k + 18, Block.planks.blockID);
		world.setBlock(i + 8, j + 1, k + 19, Block.planks.blockID);
		world.setBlock(i + 8, j + 1, k + 20, Block.planks.blockID);
		world.setBlock(i + 8, j + 1, k + 21, Block.planks.blockID);
		world.setBlock(i + 8, j + 1, k + 22, Block.planks.blockID);
		world.setBlock(i + 8, j + 1, k + 23, Block.planks.blockID);
		world.setBlock(i + 8, j + 1, k + 24, Block.planks.blockID);
		world.setBlock(i + 8, j + 1, k + 25, Block.planks.blockID);
		world.setBlock(i + 8, j + 1, k + 26, Block.planks.blockID);
		world.setBlock(i + 8, j + 1, k + 27, Block.planks.blockID);
		world.setBlock(i + 8, j + 1, k + 28, Block.planks.blockID);
		world.setBlock(i + 8, j + 1, k + 29, Block.planks.blockID);
		world.setBlock(i + 8, j + 1, k + 30, Block.planks.blockID);
		world.setBlock(i + 8, j + 1, k + 31, Block.planks.blockID);
		world.setBlock(i + 8, j + 1, k + 32, Block.planks.blockID);
		world.setBlock(i + 8, j + 1, k + 33, Block.planks.blockID);
		world.setBlock(i + 8, j + 1, k + 34, Block.planks.blockID);
		world.setBlock(i + 8, j + 1, k + 35, Block.planks.blockID);
		world.setBlock(i + 8, j + 1, k + 36, Block.planks.blockID);
		world.setBlock(i + 8, j + 1, k + 37, Block.planks.blockID);
		world.setBlock(i + 8, j + 1, k + 38, Block.planks.blockID);
		world.setBlock(i + 8, j + 1, k + 39, Block.planks.blockID);
		world.setBlock(i + 8, j + 1, k + 40, Block.planks.blockID);
		world.setBlock(i + 8, j + 1, k + 41, Block.planks.blockID);
		world.setBlock(i + 8, j + 1, k + 42, Block.planks.blockID);
		world.setBlock(i + 8, j + 1, k + 43, Block.planks.blockID);
		world.setBlock(i + 9, j + 1, k + 3, Block.planks.blockID);
		world.setBlock(i + 9, j + 1, k + 4, Block.planks.blockID);
		world.setBlock(i + 9, j + 1, k + 5, Block.planks.blockID);
		world.setBlock(i + 9, j + 1, k + 6, Block.planks.blockID);
		world.setBlock(i + 9, j + 1, k + 7, Block.planks.blockID);
		world.setBlock(i + 9, j + 1, k + 8, Block.planks.blockID);
		world.setBlock(i + 9, j + 1, k + 9, Block.planks.blockID);
		world.setBlock(i + 9, j + 1, k + 10, Block.planks.blockID);
		world.setBlock(i + 9, j + 1, k + 11, Block.planks.blockID);
		world.setBlock(i + 9, j + 1, k + 12, Block.planks.blockID);
		world.setBlock(i + 9, j + 1, k + 13, Block.planks.blockID);
		world.setBlock(i + 9, j + 1, k + 14, Block.planks.blockID);
		world.setBlock(i + 9, j + 1, k + 15, Block.planks.blockID);
		world.setBlock(i + 9, j + 1, k + 16, Block.planks.blockID);
		world.setBlock(i + 9, j + 1, k + 17, Block.planks.blockID);
		world.setBlock(i + 9, j + 1, k + 18, Block.planks.blockID);
		world.setBlock(i + 9, j + 1, k + 19, Block.planks.blockID);
		world.setBlock(i + 9, j + 1, k + 20, Block.planks.blockID);
		world.setBlock(i + 9, j + 1, k + 21, Block.planks.blockID);
		world.setBlock(i + 9, j + 1, k + 22, Block.planks.blockID);
		world.setBlock(i + 9, j + 1, k + 23, Block.planks.blockID);
		world.setBlock(i + 9, j + 1, k + 24, Block.planks.blockID);
		world.setBlock(i + 9, j + 1, k + 25, Block.planks.blockID);
		world.setBlock(i + 9, j + 1, k + 26, Block.planks.blockID);
		world.setBlock(i + 9, j + 1, k + 27, Block.planks.blockID);
		world.setBlock(i + 9, j + 1, k + 28, Block.planks.blockID);
		world.setBlock(i + 9, j + 1, k + 29, Block.planks.blockID);
		world.setBlock(i + 9, j + 1, k + 30, Block.planks.blockID);
		world.setBlock(i + 9, j + 1, k + 31, Block.planks.blockID);
		world.setBlock(i + 9, j + 1, k + 32, Block.planks.blockID);
		world.setBlock(i + 9, j + 1, k + 33, Block.planks.blockID);
		world.setBlock(i + 9, j + 1, k + 34, Block.planks.blockID);
		world.setBlock(i + 9, j + 1, k + 35, Block.planks.blockID);
		world.setBlock(i + 9, j + 1, k + 36, Block.planks.blockID);
		world.setBlock(i + 9, j + 1, k + 37, Block.planks.blockID);
		world.setBlock(i + 9, j + 1, k + 38, Block.planks.blockID);
		world.setBlock(i + 9, j + 1, k + 39, Block.planks.blockID);
		world.setBlock(i + 9, j + 1, k + 40, Block.planks.blockID);
		world.setBlock(i + 9, j + 1, k + 41, Block.planks.blockID);
		world.setBlock(i + 9, j + 1, k + 42, Block.planks.blockID);
		world.setBlock(i + 9, j + 1, k + 43, Block.planks.blockID);
		world.setBlock(i + 10, j + 1, k + 3, Block.planks.blockID);
		world.setBlock(i + 10, j + 1, k + 4, Block.planks.blockID);
		world.setBlock(i + 10, j + 1, k + 5, Block.planks.blockID);
		world.setBlock(i + 10, j + 1, k + 6, Block.planks.blockID);
		world.setBlock(i + 10, j + 1, k + 8, Block.planks.blockID);
		world.setBlock(i + 10, j + 1, k + 9, Block.planks.blockID);
		world.setBlock(i + 10, j + 1, k + 10, Block.planks.blockID);
		world.setBlock(i + 10, j + 1, k + 11, Block.planks.blockID);
		world.setBlock(i + 10, j + 1, k + 12, Block.planks.blockID);
		world.setBlock(i + 10, j + 1, k + 13, Block.planks.blockID);
		world.setBlock(i + 10, j + 1, k + 14, Block.planks.blockID);
		world.setBlock(i + 10, j + 1, k + 15, Block.planks.blockID);
		world.setBlock(i + 10, j + 1, k + 16, Block.planks.blockID);
		world.setBlock(i + 10, j + 1, k + 17, Block.planks.blockID);
		world.setBlock(i + 10, j + 1, k + 18, Block.planks.blockID);
		world.setBlock(i + 10, j + 1, k + 19, Block.planks.blockID);
		world.setBlock(i + 10, j + 1, k + 20, Block.planks.blockID);
		world.setBlock(i + 10, j + 1, k + 21, Block.planks.blockID);
		world.setBlock(i + 10, j + 1, k + 22, Block.planks.blockID);
		world.setBlock(i + 10, j + 1, k + 23, Block.planks.blockID);
		world.setBlock(i + 10, j + 1, k + 24, Block.planks.blockID);
		world.setBlock(i + 10, j + 1, k + 25, Block.planks.blockID);
		world.setBlock(i + 10, j + 1, k + 26, Block.planks.blockID);
		world.setBlock(i + 10, j + 1, k + 27, Block.planks.blockID);
		world.setBlock(i + 10, j + 1, k + 28, Block.planks.blockID);
		world.setBlock(i + 10, j + 1, k + 29, Block.planks.blockID);
		world.setBlock(i + 10, j + 1, k + 30, Block.planks.blockID);
		world.setBlock(i + 10, j + 1, k + 31, Block.planks.blockID);
		world.setBlock(i + 10, j + 1, k + 32, Block.planks.blockID);
		world.setBlock(i + 10, j + 1, k + 33, Block.planks.blockID);
		world.setBlock(i + 10, j + 1, k + 34, Block.planks.blockID);
		world.setBlock(i + 10, j + 1, k + 35, Block.planks.blockID);
		world.setBlock(i + 10, j + 1, k + 36, Block.planks.blockID);
		world.setBlock(i + 10, j + 1, k + 37, Block.planks.blockID);
		world.setBlock(i + 10, j + 1, k + 38, Block.planks.blockID);
		world.setBlock(i + 10, j + 1, k + 39, Block.planks.blockID);
		world.setBlock(i + 10, j + 1, k + 40, Block.planks.blockID);
		world.setBlock(i + 10, j + 1, k + 41, Block.planks.blockID);
		world.setBlock(i + 10, j + 1, k + 42, Block.planks.blockID);
		world.setBlock(i + 10, j + 1, k + 43, Block.planks.blockID);
		world.setBlock(i + 10, j + 1, k + 44, Block.planks.blockID);
		world.setBlock(i + 11, j + 1, k + 3, Block.planks.blockID);
		world.setBlock(i + 11, j + 1, k + 4, Block.planks.blockID);
		world.setBlock(i + 11, j + 1, k + 5, Block.planks.blockID);
		world.setBlock(i + 11, j + 1, k + 6, Block.planks.blockID);
		world.setBlock(i + 11, j + 1, k + 8, Block.planks.blockID);
		world.setBlock(i + 11, j + 1, k + 9, Block.planks.blockID);
		world.setBlock(i + 11, j + 1, k + 10, Block.planks.blockID);
		world.setBlock(i + 11, j + 1, k + 11, Block.planks.blockID);
		world.setBlock(i + 11, j + 1, k + 12, Block.planks.blockID);
		world.setBlock(i + 11, j + 1, k + 13, Block.planks.blockID);
		world.setBlock(i + 11, j + 1, k + 14, Block.planks.blockID);
		world.setBlock(i + 11, j + 1, k + 15, Block.planks.blockID);
		world.setBlock(i + 11, j + 1, k + 16, Block.planks.blockID);
		world.setBlock(i + 11, j + 1, k + 17, Block.planks.blockID);
		world.setBlock(i + 11, j + 1, k + 18, Block.planks.blockID);
		world.setBlock(i + 11, j + 1, k + 19, Block.planks.blockID);
		world.setBlock(i + 11, j + 1, k + 20, Block.planks.blockID);
		world.setBlock(i + 11, j + 1, k + 21, Block.planks.blockID);
		world.setBlock(i + 11, j + 1, k + 22, Block.planks.blockID);
		world.setBlock(i + 11, j + 1, k + 23, Block.planks.blockID);
		world.setBlock(i + 11, j + 1, k + 24, Block.planks.blockID);
		world.setBlock(i + 11, j + 1, k + 25, Block.planks.blockID);
		world.setBlock(i + 11, j + 1, k + 26, Block.planks.blockID);
		world.setBlock(i + 11, j + 1, k + 27, Block.planks.blockID);
		world.setBlock(i + 11, j + 1, k + 28, Block.planks.blockID);
		world.setBlock(i + 11, j + 1, k + 29, Block.planks.blockID);
		world.setBlock(i + 11, j + 1, k + 30, Block.planks.blockID);
		world.setBlock(i + 11, j + 1, k + 31, Block.planks.blockID);
		world.setBlock(i + 11, j + 1, k + 32, Block.planks.blockID);
		world.setBlock(i + 11, j + 1, k + 33, Block.planks.blockID);
		world.setBlock(i + 11, j + 1, k + 34, Block.planks.blockID);
		world.setBlock(i + 11, j + 1, k + 35, Block.planks.blockID);
		world.setBlock(i + 11, j + 1, k + 36, Block.planks.blockID);
		world.setBlock(i + 11, j + 1, k + 37, Block.planks.blockID);
		world.setBlock(i + 11, j + 1, k + 38, Block.planks.blockID);
		world.setBlock(i + 11, j + 1, k + 39, Block.planks.blockID);
		world.setBlock(i + 11, j + 1, k + 40, Block.planks.blockID);
		world.setBlock(i + 11, j + 1, k + 41, Block.planks.blockID);
		world.setBlock(i + 11, j + 1, k + 42, Block.planks.blockID);
		world.setBlock(i + 11, j + 1, k + 43, Block.planks.blockID);
		world.setBlock(i + 11, j + 1, k + 44, Block.planks.blockID);
		world.setBlock(i + 12, j + 1, k + 3, Block.planks.blockID);
		world.setBlock(i + 12, j + 1, k + 4, Block.planks.blockID);
		world.setBlock(i + 12, j + 1, k + 5, Block.planks.blockID);
		world.setBlock(i + 12, j + 1, k + 6, Block.planks.blockID);
		world.setBlock(i + 12, j + 1, k + 7, Block.planks.blockID);
		world.setBlock(i + 12, j + 1, k + 8, Block.planks.blockID);
		world.setBlock(i + 12, j + 1, k + 9, Block.planks.blockID);
		world.setBlock(i + 12, j + 1, k + 10, Block.planks.blockID);
		world.setBlock(i + 12, j + 1, k + 11, Block.planks.blockID);
		world.setBlock(i + 12, j + 1, k + 12, Block.planks.blockID);
		world.setBlock(i + 12, j + 1, k + 13, Block.planks.blockID);
		world.setBlock(i + 12, j + 1, k + 14, Block.planks.blockID);
		world.setBlock(i + 12, j + 1, k + 15, Block.planks.blockID);
		world.setBlock(i + 12, j + 1, k + 16, Block.planks.blockID);
		world.setBlock(i + 12, j + 1, k + 17, Block.planks.blockID);
		world.setBlock(i + 12, j + 1, k + 18, Block.planks.blockID);
		world.setBlock(i + 12, j + 1, k + 19, Block.planks.blockID);
		world.setBlock(i + 12, j + 1, k + 20, Block.planks.blockID);
		world.setBlock(i + 12, j + 1, k + 21, Block.planks.blockID);
		world.setBlock(i + 12, j + 1, k + 22, Block.planks.blockID);
		world.setBlock(i + 12, j + 1, k + 23, Block.planks.blockID);
		world.setBlock(i + 12, j + 1, k + 24, Block.planks.blockID);
		world.setBlock(i + 12, j + 1, k + 25, Block.planks.blockID);
		world.setBlock(i + 12, j + 1, k + 26, Block.planks.blockID);
		world.setBlock(i + 12, j + 1, k + 27, Block.planks.blockID);
		world.setBlock(i + 12, j + 1, k + 28, Block.planks.blockID);
		world.setBlock(i + 12, j + 1, k + 29, Block.planks.blockID);
		world.setBlock(i + 12, j + 1, k + 30, Block.planks.blockID);
		world.setBlock(i + 12, j + 1, k + 31, Block.planks.blockID);
		world.setBlock(i + 12, j + 1, k + 32, Block.planks.blockID);
		world.setBlock(i + 12, j + 1, k + 33, Block.planks.blockID);
		world.setBlock(i + 12, j + 1, k + 34, Block.planks.blockID);
		world.setBlock(i + 12, j + 1, k + 35, Block.planks.blockID);
		world.setBlock(i + 12, j + 1, k + 36, Block.planks.blockID);
		world.setBlock(i + 12, j + 1, k + 37, Block.planks.blockID);
		world.setBlock(i + 12, j + 1, k + 38, Block.planks.blockID);
		world.setBlock(i + 12, j + 1, k + 39, Block.planks.blockID);
		world.setBlock(i + 12, j + 1, k + 40, Block.planks.blockID);
		world.setBlock(i + 12, j + 1, k + 41, Block.planks.blockID);
		world.setBlock(i + 12, j + 1, k + 42, Block.planks.blockID);
		world.setBlock(i + 12, j + 1, k + 43, Block.planks.blockID);
		world.setBlock(i + 13, j + 1, k + 4, Block.planks.blockID);
		world.setBlock(i + 13, j + 1, k + 5, Block.planks.blockID);
		world.setBlock(i + 13, j + 1, k + 6, Block.planks.blockID);
		world.setBlock(i + 13, j + 1, k + 7, Block.planks.blockID);
		world.setBlock(i + 13, j + 1, k + 8, Block.planks.blockID);
		world.setBlock(i + 13, j + 1, k + 9, Block.planks.blockID);
		world.setBlock(i + 13, j + 1, k + 10, Block.planks.blockID);
		world.setBlock(i + 13, j + 1, k + 11, Block.planks.blockID);
		world.setBlock(i + 13, j + 1, k + 12, Block.planks.blockID);
		world.setBlock(i + 13, j + 1, k + 13, Block.planks.blockID);
		world.setBlock(i + 13, j + 1, k + 14, Block.planks.blockID);
		world.setBlock(i + 13, j + 1, k + 15, Block.planks.blockID);
		world.setBlock(i + 13, j + 1, k + 16, Block.planks.blockID);
		world.setBlock(i + 13, j + 1, k + 17, Block.planks.blockID);
		world.setBlock(i + 13, j + 1, k + 18, Block.planks.blockID);
		world.setBlock(i + 13, j + 1, k + 19, Block.planks.blockID);
		world.setBlock(i + 13, j + 1, k + 20, Block.planks.blockID);
		world.setBlock(i + 13, j + 1, k + 21, Block.planks.blockID);
		world.setBlock(i + 13, j + 1, k + 22, Block.planks.blockID);
		world.setBlock(i + 13, j + 1, k + 23, Block.planks.blockID);
		world.setBlock(i + 13, j + 1, k + 24, Block.planks.blockID);
		world.setBlock(i + 13, j + 1, k + 25, Block.planks.blockID);
		world.setBlock(i + 13, j + 1, k + 26, Block.planks.blockID);
		world.setBlock(i + 13, j + 1, k + 27, Block.planks.blockID);
		world.setBlock(i + 13, j + 1, k + 28, Block.planks.blockID);
		world.setBlock(i + 13, j + 1, k + 29, Block.planks.blockID);
		world.setBlock(i + 13, j + 1, k + 30, Block.planks.blockID);
		world.setBlock(i + 13, j + 1, k + 31, Block.planks.blockID);
		world.setBlock(i + 13, j + 1, k + 32, Block.planks.blockID);
		world.setBlock(i + 13, j + 1, k + 33, Block.planks.blockID);
		world.setBlock(i + 13, j + 1, k + 34, Block.planks.blockID);
		world.setBlock(i + 13, j + 1, k + 35, Block.planks.blockID);
		world.setBlock(i + 13, j + 1, k + 36, Block.planks.blockID);
		world.setBlock(i + 13, j + 1, k + 37, Block.planks.blockID);
		world.setBlock(i + 13, j + 1, k + 38, Block.planks.blockID);
		world.setBlock(i + 13, j + 1, k + 39, Block.planks.blockID);
		world.setBlock(i + 13, j + 1, k + 40, Block.planks.blockID);
		world.setBlock(i + 13, j + 1, k + 41, Block.planks.blockID);
		world.setBlock(i + 14, j + 1, k + 5, Block.planks.blockID);
		world.setBlock(i + 14, j + 1, k + 6, Block.planks.blockID);
		world.setBlock(i + 14, j + 1, k + 7, Block.planks.blockID);
		world.setBlock(i + 14, j + 1, k + 8, Block.planks.blockID);
		world.setBlock(i + 14, j + 1, k + 9, Block.planks.blockID);
		world.setBlock(i + 14, j + 1, k + 10, Block.planks.blockID);
		world.setBlock(i + 14, j + 1, k + 11, Block.planks.blockID);
		world.setBlock(i + 14, j + 1, k + 12, Block.planks.blockID);
		world.setBlock(i + 14, j + 1, k + 13, Block.planks.blockID);
		world.setBlock(i + 14, j + 1, k + 14, Block.planks.blockID);
		world.setBlock(i + 14, j + 1, k + 15, Block.planks.blockID);
		world.setBlock(i + 14, j + 1, k + 16, Block.planks.blockID);
		world.setBlock(i + 14, j + 1, k + 17, Block.planks.blockID);
		world.setBlock(i + 14, j + 1, k + 18, Block.planks.blockID);
		world.setBlock(i + 14, j + 1, k + 19, Block.planks.blockID);
		world.setBlock(i + 14, j + 1, k + 20, Block.planks.blockID);
		world.setBlock(i + 14, j + 1, k + 21, Block.planks.blockID);
		world.setBlock(i + 14, j + 1, k + 22, Block.planks.blockID);
		world.setBlock(i + 14, j + 1, k + 23, Block.planks.blockID);
		world.setBlock(i + 14, j + 1, k + 24, Block.planks.blockID);
		world.setBlock(i + 14, j + 1, k + 25, Block.planks.blockID);
		world.setBlock(i + 14, j + 1, k + 26, Block.planks.blockID);
		world.setBlock(i + 14, j + 1, k + 27, Block.planks.blockID);
		world.setBlock(i + 14, j + 1, k + 28, Block.planks.blockID);
		world.setBlock(i + 14, j + 1, k + 29, Block.planks.blockID);
		world.setBlock(i + 14, j + 1, k + 30, Block.planks.blockID);
		world.setBlock(i + 14, j + 1, k + 31, Block.planks.blockID);
		world.setBlock(i + 14, j + 1, k + 32, Block.planks.blockID);
		world.setBlock(i + 14, j + 1, k + 33, Block.planks.blockID);
		world.setBlock(i + 14, j + 1, k + 34, Block.planks.blockID);
		world.setBlock(i + 14, j + 1, k + 35, Block.planks.blockID);
		world.setBlock(i + 14, j + 1, k + 36, Block.planks.blockID);
		world.setBlock(i + 14, j + 1, k + 37, Block.planks.blockID);
		world.setBlock(i + 14, j + 1, k + 38, Block.planks.blockID);
		world.setBlock(i + 14, j + 1, k + 39, Block.planks.blockID);
		world.setBlock(i + 14, j + 1, k + 40, Block.planks.blockID);
	
		generate4(world, rand, i, j, k);
		return true;
	}
	
	public boolean generate4(World world, Random rand, int i, int j, int k) 
	{
	
		world.setBlock(i + 6, j + 2, k + 4, Block.planks.blockID);
		world.setBlock(i + 6, j + 2, k + 5, Block.planks.blockID);
		world.setBlock(i + 6, j + 2, k + 6, Block.planks.blockID);
		world.setBlock(i + 6, j + 2, k + 7, Block.planks.blockID);
		world.setBlock(i + 6, j + 2, k + 8, Block.planks.blockID);
		world.setBlock(i + 6, j + 2, k + 9, Block.planks.blockID);
		world.setBlock(i + 6, j + 2, k + 10, Block.planks.blockID);
		world.setBlock(i + 6, j + 2, k + 11, Block.planks.blockID);
		world.setBlock(i + 6, j + 2, k + 12, Block.planks.blockID);
		world.setBlock(i + 6, j + 2, k + 13, Block.planks.blockID);
		world.setBlock(i + 6, j + 2, k + 14, Block.planks.blockID);
		world.setBlock(i + 6, j + 2, k + 15, Block.planks.blockID);
		world.setBlock(i + 6, j + 2, k + 16, Block.planks.blockID);
		world.setBlock(i + 6, j + 2, k + 17, Block.planks.blockID);
		world.setBlock(i + 6, j + 2, k + 18, Block.planks.blockID);
		world.setBlock(i + 6, j + 2, k + 19, Block.planks.blockID);
		world.setBlock(i + 6, j + 2, k + 20, Block.planks.blockID);
		world.setBlock(i + 6, j + 2, k + 21, Block.planks.blockID);
		world.setBlock(i + 6, j + 2, k + 22, Block.planks.blockID);
		world.setBlock(i + 6, j + 2, k + 23, Block.planks.blockID);
		world.setBlock(i + 6, j + 2, k + 24, Block.planks.blockID);
		world.setBlock(i + 6, j + 2, k + 25, Block.planks.blockID);
		world.setBlock(i + 6, j + 2, k + 26, Block.planks.blockID);
		world.setBlock(i + 6, j + 2, k + 27, Block.planks.blockID);
		world.setBlock(i + 6, j + 2, k + 28, Block.planks.blockID);
		world.setBlock(i + 6, j + 2, k + 29, Block.planks.blockID);
		world.setBlock(i + 6, j + 2, k + 30, Block.planks.blockID);
		world.setBlock(i + 6, j + 2, k + 31, Block.planks.blockID);
		world.setBlock(i + 6, j + 2, k + 32, Block.planks.blockID);
		world.setBlock(i + 6, j + 2, k + 33, Block.planks.blockID);
		world.setBlock(i + 6, j + 2, k + 34, Block.planks.blockID);
		world.setBlock(i + 6, j + 2, k + 35, Block.planks.blockID);
		world.setBlock(i + 6, j + 2, k + 36, Block.planks.blockID);
		world.setBlock(i + 6, j + 2, k + 37, Block.planks.blockID);
		world.setBlock(i + 6, j + 2, k + 38, Block.planks.blockID);
		world.setBlock(i + 6, j + 2, k + 39, Block.planks.blockID);
		world.setBlock(i + 6, j + 2, k + 40, Block.planks.blockID);
		world.setBlock(i + 7, j + 2, k + 3, Block.planks.blockID);
		world.setBlock(i + 7, j + 2, k + 4, Block.planks.blockID);
		world.setBlock(i + 7, j + 2, k + 40, Block.planks.blockID);
		world.setBlock(i + 7, j + 2, k + 41, Block.planks.blockID);
		world.setBlock(i + 7, j + 2, k + 42, Block.planks.blockID);
		world.setBlock(i + 8, j + 2, k + 2, Block.planks.blockID);
		world.setBlock(i + 8, j + 2, k + 3, Block.planks.blockID);
		world.setBlock(i + 8, j + 2, k + 40, Block.planks.blockID);
		world.setBlock(i + 8, j + 2, k + 42, Block.planks.blockID);
		world.setBlock(i + 8, j + 2, k + 43, Block.planks.blockID);
		world.setBlock(i + 8, j + 2, k + 44, Block.planks.blockID);
		world.setBlock(i + 9, j + 2, k + 2, Block.planks.blockID);
		world.setBlockAndMetadata(i + 9, j + 2, k + 42, Block.thinGlass.blockID, 3);
		world.setBlockAndMetadata(i + 9, j + 2, k + 43, Block.thinGlass.blockID, 3);
		world.setBlock(i + 9, j + 2, k + 44, Block.planks.blockID);
		world.setBlock(i + 9, j + 2, k + 45, Block.planks.blockID);
		world.setBlock(i + 10, j + 2, k + 2, Block.planks.blockID);
		world.setBlockAndMetadata(i + 10, j + 2, k + 7, Block.stairCompactPlanks.blockID, 3);
		world.setBlock(i + 10, j + 2, k + 10, Block.planks.blockID);
		world.setBlock(i + 10, j + 2, k + 11, Block.planks.blockID);
		world.setBlock(i + 10, j + 2, k + 13, Block.planks.blockID);
		world.setBlock(i + 10, j + 2, k + 14, Block.planks.blockID);
		world.setBlock(i + 10, j + 2, k + 15, Block.planks.blockID);
		world.setBlock(i + 10, j + 2, k + 16, Block.planks.blockID);
		world.setBlock(i + 10, j + 2, k + 17, Block.planks.blockID);
		world.setBlock(i + 10, j + 2, k + 19, Block.planks.blockID);
		world.setBlock(i + 10, j + 2, k + 20, Block.planks.blockID);
		world.setBlock(i + 10, j + 2, k + 21, Block.planks.blockID);
		world.setBlock(i + 10, j + 2, k + 22, Block.planks.blockID);
		world.setBlock(i + 10, j + 2, k + 23, Block.planks.blockID);
		world.setBlock(i + 10, j + 2, k + 25, Block.planks.blockID);
		world.setBlock(i + 10, j + 2, k + 26, Block.planks.blockID);
		world.setBlock(i + 10, j + 2, k + 27, Block.planks.blockID);
		world.setBlock(i + 10, j + 2, k + 28, Block.planks.blockID);
		world.setBlock(i + 10, j + 2, k + 29, Block.planks.blockID);
		world.setBlock(i + 10, j + 2, k + 31, Block.planks.blockID);
		world.setBlock(i + 10, j + 2, k + 32, Block.planks.blockID);
		world.setBlock(i + 10, j + 2, k + 33, Block.planks.blockID);
		world.setBlock(i + 10, j + 2, k + 34, Block.planks.blockID);
		world.setBlock(i + 10, j + 2, k + 35, Block.planks.blockID);
		world.setBlock(i + 10, j + 2, k + 37, Block.planks.blockID);
		world.setBlock(i + 10, j + 2, k + 38, Block.planks.blockID);
		world.setBlock(i + 10, j + 2, k + 39, Block.planks.blockID);
		world.setBlock(i + 10, j + 2, k + 40, Block.planks.blockID);
		world.setBlockAndMetadata(i + 10, j + 2, k + 44, Block.stoneOvenIdle.blockID, 2);
		world.setBlock(i + 10, j + 2, k + 45, Block.planks.blockID);
		world.setBlock(i + 11, j + 2, k + 2, Block.planks.blockID);
		world.setBlockAndMetadata(i + 11, j + 2, k + 7, Block.stairCompactPlanks.blockID, 3);
		world.setBlock(i + 11, j + 2, k + 10, Block.planks.blockID);
		world.setBlock(i + 11, j + 2, k + 16, Block.planks.blockID);
		world.setBlock(i + 11, j + 2, k + 22, Block.planks.blockID);
		world.setBlock(i + 11, j + 2, k + 28, Block.planks.blockID);
		world.setBlock(i + 11, j + 2, k + 34, Block.planks.blockID);
		world.setBlock(i + 11, j + 2, k + 40, Block.planks.blockID);
		world.setBlockAndMetadata(i + 11, j + 2, k + 44, Block.stoneOvenIdle.blockID, 2);
		world.setBlock(i + 11, j + 2, k + 45, Block.planks.blockID);
		world.setBlock(i + 12, j + 2, k + 2, Block.planks.blockID);
		world.setBlock(i + 12, j + 2, k + 10, Block.planks.blockID);
		world.setBlock(i + 12, j + 2, k + 16, Block.planks.blockID);
		world.setBlock(i + 12, j + 2, k + 22, Block.planks.blockID);
		world.setBlock(i + 12, j + 2, k + 28, Block.planks.blockID);
		world.setBlock(i + 12, j + 2, k + 34, Block.planks.blockID);
		world.setBlock(i + 12, j + 2, k + 40, Block.planks.blockID);
		world.setBlockAndMetadata(i + 12, j + 2, k + 43, Block.thinGlass.blockID, 2);
		world.setBlock(i + 12, j + 2, k + 44, Block.planks.blockID);
		world.setBlock(i + 12, j + 2, k + 45, Block.planks.blockID);
		world.setBlock(i + 12, j + 2, k + 46, Block.planks.blockID);
		world.setBlock(i + 13, j + 2, k + 2, Block.planks.blockID);
		world.setBlock(i + 13, j + 2, k + 3, Block.planks.blockID);
		world.setBlock(i + 13, j + 2, k + 10, Block.planks.blockID);
		world.setBlock(i + 13, j + 2, k + 15, Block.bed.blockID);
		world.setBlock(i + 13, j + 2, k + 16, Block.planks.blockID);
		world.setBlock(i + 13, j + 2, k + 21, Block.bed.blockID);
		world.setBlock(i + 13, j + 2, k + 22, Block.planks.blockID);
		world.setBlock(i + 13, j + 2, k + 27, Block.bed.blockID);
		world.setBlock(i + 13, j + 2, k + 28, Block.planks.blockID);
		world.setBlock(i + 13, j + 2, k + 33, Block.bed.blockID);
		world.setBlock(i + 13, j + 2, k + 34, Block.planks.blockID);
		world.setBlock(i + 13, j + 2, k + 39, Block.bed.blockID);
		world.setBlock(i + 13, j + 2, k + 40, Block.planks.blockID);
		world.setBlock(i + 13, j + 2, k + 42, Block.planks.blockID);
		world.setBlock(i + 13, j + 2, k + 43, Block.planks.blockID);
		world.setBlock(i + 13, j + 2, k + 44, Block.planks.blockID);
		world.setBlock(i + 14, j + 2, k + 3, Block.planks.blockID);
		world.setBlock(i + 14, j + 2, k + 4, Block.planks.blockID);
		world.setBlock(i + 14, j + 2, k + 10, Block.planks.blockID);
		world.setBlockAndMetadata(i + 14, j + 2, k + 15, Block.bed.blockID, 8);
		world.setBlock(i + 14, j + 2, k + 16, Block.planks.blockID);
		world.setBlockAndMetadata(i + 14, j + 2, k + 21, Block.bed.blockID, 8);
		world.setBlock(i + 14, j + 2, k + 22, Block.planks.blockID);
		world.setBlockAndMetadata(i + 14, j + 2, k + 27, Block.bed.blockID, 8);
		world.setBlock(i + 14, j + 2, k + 28, Block.planks.blockID);
		world.setBlockAndMetadata(i + 14, j + 2, k + 33, Block.bed.blockID, 8);
		world.setBlock(i + 14, j + 2, k + 34, Block.planks.blockID);
		world.setBlockAndMetadata(i + 14, j + 2, k + 39, Block.bed.blockID, 8);
		world.setBlock(i + 14, j + 2, k + 40, Block.planks.blockID);
		world.setBlock(i + 14, j + 2, k + 41, Block.planks.blockID);
		world.setBlock(i + 14, j + 2, k + 42, Block.planks.blockID);
		world.setBlock(i + 15, j + 2, k + 4, Block.planks.blockID);
		world.setBlock(i + 15, j + 2, k + 5, Block.planks.blockID);
		world.setBlock(i + 15, j + 2, k + 6, Block.planks.blockID);
		world.setBlock(i + 15, j + 2, k + 7, Block.planks.blockID);
		world.setBlock(i + 15, j + 2, k + 8, Block.planks.blockID);
		world.setBlock(i + 15, j + 2, k + 9, Block.planks.blockID);
		world.setBlock(i + 15, j + 2, k + 10, Block.planks.blockID);
		world.setBlock(i + 15, j + 2, k + 11, Block.planks.blockID);
		world.setBlock(i + 15, j + 2, k + 12, Block.planks.blockID);
		world.setBlock(i + 15, j + 2, k + 13, Block.planks.blockID);
		world.setBlock(i + 15, j + 2, k + 14, Block.planks.blockID);
		world.setBlock(i + 15, j + 2, k + 15, Block.planks.blockID);
		world.setBlock(i + 15, j + 2, k + 16, Block.planks.blockID);
		world.setBlock(i + 15, j + 2, k + 17, Block.planks.blockID);
		world.setBlock(i + 15, j + 2, k + 18, Block.planks.blockID);
		world.setBlock(i + 15, j + 2, k + 19, Block.planks.blockID);
		world.setBlock(i + 15, j + 2, k + 20, Block.planks.blockID);
		world.setBlock(i + 15, j + 2, k + 21, Block.planks.blockID);
		world.setBlock(i + 15, j + 2, k + 22, Block.planks.blockID);
		world.setBlock(i + 15, j + 2, k + 23, Block.planks.blockID);
		world.setBlock(i + 15, j + 2, k + 24, Block.planks.blockID);
		world.setBlock(i + 15, j + 2, k + 25, Block.planks.blockID);
		world.setBlock(i + 15, j + 2, k + 26, Block.planks.blockID);
		world.setBlock(i + 15, j + 2, k + 27, Block.planks.blockID);
		world.setBlock(i + 15, j + 2, k + 28, Block.planks.blockID);
		world.setBlock(i + 15, j + 2, k + 29, Block.planks.blockID);
		world.setBlock(i + 15, j + 2, k + 30, Block.planks.blockID);
		world.setBlock(i + 15, j + 2, k + 31, Block.planks.blockID);
		world.setBlock(i + 15, j + 2, k + 32, Block.planks.blockID);
		world.setBlock(i + 15, j + 2, k + 33, Block.planks.blockID);
		world.setBlock(i + 15, j + 2, k + 34, Block.planks.blockID);
		world.setBlock(i + 15, j + 2, k + 35, Block.planks.blockID);
		world.setBlock(i + 15, j + 2, k + 36, Block.planks.blockID);
		world.setBlock(i + 15, j + 2, k + 37, Block.planks.blockID);
		world.setBlock(i + 15, j + 2, k + 38, Block.planks.blockID);
		world.setBlock(i + 15, j + 2, k + 39, Block.planks.blockID);
		world.setBlock(i + 15, j + 2, k + 40, Block.planks.blockID);
		world.setBlockAndMetadataWithNotify(i + 9, j + 2, k + 40, Block.doorWood.blockID, 1);
		world.setBlockWithNotify(i + 9, j + 2, k + 41, Block.pressurePlatePlanks.blockID);
		world.setBlockWithNotify(i + 10, j + 2, k + 12, Block.doorWood.blockID);
		world.setBlockWithNotify(i + 10, j + 2, k + 18, Block.doorWood.blockID);
		world.setBlockWithNotify(i + 10, j + 2, k + 24, Block.doorWood.blockID);
		world.setBlockWithNotify(i + 10, j + 2, k + 30, Block.doorWood.blockID);
		world.setBlockWithNotify(i + 10, j + 2, k + 36, Block.doorWood.blockID);
		world.setBlockWithNotify(i + 11, j + 2, k + 12, Block.pressurePlatePlanks.blockID);
		world.setBlockWithNotify(i + 11, j + 2, k + 18, Block.pressurePlatePlanks.blockID);
		world.setBlockWithNotify(i + 11, j + 2, k + 24, Block.pressurePlatePlanks.blockID);
		world.setBlockWithNotify(i + 11, j + 2, k + 30, Block.pressurePlatePlanks.blockID);
		world.setBlockWithNotify(i + 11, j + 2, k + 36, Block.pressurePlatePlanks.blockID);
	
		generate5(world, rand, i, j, k);
		return true;
	}
	
	public boolean generate5(World world, Random rand, int i, int j, int k) 
	{
	
		world.setBlock(i + 6, j + 3, k + 4, Block.planks.blockID);
		world.setBlock(i + 6, j + 3, k + 5, Block.planks.blockID);
		world.setBlock(i + 6, j + 3, k + 6, Block.planks.blockID);
		world.setBlock(i + 6, j + 3, k + 7, Block.planks.blockID);
		world.setBlock(i + 6, j + 3, k + 8, Block.planks.blockID);
		world.setBlock(i + 6, j + 3, k + 9, Block.planks.blockID);
		world.setBlock(i + 6, j + 3, k + 10, Block.planks.blockID);
		world.setBlock(i + 6, j + 3, k + 11, Block.planks.blockID);
		world.setBlock(i + 6, j + 3, k + 12, Block.glass.blockID);
		world.setBlock(i + 6, j + 3, k + 13, Block.planks.blockID);
		world.setBlock(i + 6, j + 3, k + 14, Block.planks.blockID);
		world.setBlock(i + 6, j + 3, k + 15, Block.planks.blockID);
		world.setBlock(i + 6, j + 3, k + 16, Block.planks.blockID);
		world.setBlock(i + 6, j + 3, k + 17, Block.glass.blockID);
		world.setBlock(i + 6, j + 3, k + 18, Block.planks.blockID);
		world.setBlock(i + 6, j + 3, k + 19, Block.planks.blockID);
		world.setBlock(i + 6, j + 3, k + 20, Block.planks.blockID);
		world.setBlock(i + 6, j + 3, k + 21, Block.glass.blockID);
		world.setBlock(i + 6, j + 3, k + 22, Block.planks.blockID);
		world.setBlock(i + 6, j + 3, k + 23, Block.planks.blockID);
		world.setBlock(i + 6, j + 3, k + 24, Block.planks.blockID);
		world.setBlock(i + 6, j + 3, k + 25, Block.planks.blockID);
		world.setBlock(i + 6, j + 3, k + 26, Block.planks.blockID);
		world.setBlock(i + 6, j + 3, k + 27, Block.glass.blockID);
		world.setBlock(i + 6, j + 3, k + 28, Block.planks.blockID);
		world.setBlock(i + 6, j + 3, k + 29, Block.planks.blockID);
		world.setBlock(i + 6, j + 3, k + 30, Block.planks.blockID);
		world.setBlock(i + 6, j + 3, k + 31, Block.planks.blockID);
		world.setBlock(i + 6, j + 3, k + 32, Block.glass.blockID);
		world.setBlock(i + 6, j + 3, k + 33, Block.planks.blockID);
		world.setBlock(i + 6, j + 3, k + 34, Block.planks.blockID);
		world.setBlock(i + 6, j + 3, k + 35, Block.planks.blockID);
		world.setBlock(i + 6, j + 3, k + 36, Block.planks.blockID);
		world.setBlock(i + 6, j + 3, k + 37, Block.planks.blockID);
		world.setBlock(i + 6, j + 3, k + 38, Block.planks.blockID);
		world.setBlock(i + 6, j + 3, k + 39, Block.planks.blockID);
		world.setBlock(i + 6, j + 3, k + 40, Block.planks.blockID);
		world.setBlock(i + 7, j + 3, k + 3, Block.planks.blockID);
		world.setBlock(i + 7, j + 3, k + 4, Block.planks.blockID);
		world.setBlock(i + 7, j + 3, k + 40, Block.planks.blockID);
		world.setBlock(i + 7, j + 3, k + 41, Block.planks.blockID);
		world.setBlock(i + 7, j + 3, k + 42, Block.planks.blockID);
		world.setBlock(i + 8, j + 3, k + 2, Block.planks.blockID);
		world.setBlock(i + 8, j + 3, k + 3, Block.planks.blockID);
		world.setBlock(i + 8, j + 3, k + 40, Block.planks.blockID);
		world.setBlock(i + 8, j + 3, k + 42, Block.planks.blockID);
		world.setBlock(i + 8, j + 3, k + 43, Block.planks.blockID);
		world.setBlock(i + 8, j + 3, k + 44, Block.planks.blockID);
		world.setBlock(i + 9, j + 3, k + 2, Block.planks.blockID);
		world.setBlock(i + 9, j + 3, k + 44, Block.planks.blockID);
		world.setBlock(i + 9, j + 3, k + 45, Block.planks.blockID);
		world.setBlock(i + 9, j + 3, k + 46, Block.planks.blockID);
		world.setBlock(i + 10, j + 3, k + 2, Block.planks.blockID);
		world.setBlockAndMetadata(i + 10, j + 3, k + 6, Block.stairCompactPlanks.blockID, 3);
		world.setBlock(i + 10, j + 3, k + 10, Block.planks.blockID);
		world.setBlock(i + 10, j + 3, k + 11, Block.planks.blockID);
		world.setBlock(i + 10, j + 3, k + 13, Block.planks.blockID);
		world.setBlock(i + 10, j + 3, k + 14, Block.planks.blockID);
		world.setBlock(i + 10, j + 3, k + 15, Block.planks.blockID);
		world.setBlock(i + 10, j + 3, k + 16, Block.planks.blockID);
		world.setBlock(i + 10, j + 3, k + 17, Block.planks.blockID);
		world.setBlock(i + 10, j + 3, k + 19, Block.planks.blockID);
		world.setBlock(i + 10, j + 3, k + 20, Block.planks.blockID);
		world.setBlock(i + 10, j + 3, k + 21, Block.planks.blockID);
		world.setBlock(i + 10, j + 3, k + 22, Block.planks.blockID);
		world.setBlock(i + 10, j + 3, k + 23, Block.planks.blockID);
		world.setBlock(i + 10, j + 3, k + 25, Block.planks.blockID);
		world.setBlock(i + 10, j + 3, k + 26, Block.planks.blockID);
		world.setBlock(i + 10, j + 3, k + 27, Block.planks.blockID);
		world.setBlock(i + 10, j + 3, k + 28, Block.planks.blockID);
		world.setBlock(i + 10, j + 3, k + 29, Block.planks.blockID);
		world.setBlock(i + 10, j + 3, k + 31, Block.planks.blockID);
		world.setBlock(i + 10, j + 3, k + 32, Block.planks.blockID);
		world.setBlock(i + 10, j + 3, k + 33, Block.planks.blockID);
		world.setBlock(i + 10, j + 3, k + 34, Block.planks.blockID);
		world.setBlock(i + 10, j + 3, k + 35, Block.planks.blockID);
		world.setBlock(i + 10, j + 3, k + 37, Block.planks.blockID);
		world.setBlock(i + 10, j + 3, k + 38, Block.planks.blockID);
		world.setBlock(i + 10, j + 3, k + 39, Block.planks.blockID);
		world.setBlock(i + 10, j + 3, k + 40, Block.planks.blockID);
		world.setBlockAndMetadata(i + 10, j + 3, k + 45, Block.stoneOvenIdle.blockID, 2);
		world.setBlock(i + 10, j + 3, k + 46, Block.planks.blockID);
		world.setBlock(i + 11, j + 3, k + 2, Block.planks.blockID);
		world.setBlockAndMetadata(i + 11, j + 3, k + 6, Block.stairCompactPlanks.blockID, 3);
		world.setBlock(i + 11, j + 3, k + 10, Block.planks.blockID);
		world.setBlock(i + 11, j + 3, k + 16, Block.planks.blockID);
		world.setBlock(i + 11, j + 3, k + 22, Block.planks.blockID);
		world.setBlock(i + 11, j + 3, k + 28, Block.planks.blockID);
		world.setBlock(i + 11, j + 3, k + 34, Block.planks.blockID);
		world.setBlock(i + 11, j + 3, k + 40, Block.planks.blockID);
		world.setBlockAndMetadata(i + 11, j + 3, k + 45, Block.stoneOvenIdle.blockID, 2);
		world.setBlock(i + 11, j + 3, k + 46, Block.planks.blockID);
		world.setBlock(i + 12, j + 3, k + 2, Block.planks.blockID);
		world.setBlock(i + 12, j + 3, k + 10, Block.planks.blockID);
		world.setBlock(i + 12, j + 3, k + 16, Block.planks.blockID);
		world.setBlock(i + 12, j + 3, k + 22, Block.planks.blockID);
		world.setBlock(i + 12, j + 3, k + 28, Block.planks.blockID);
		world.setBlock(i + 12, j + 3, k + 34, Block.planks.blockID);
		world.setBlock(i + 12, j + 3, k + 40, Block.planks.blockID);
		world.setBlock(i + 12, j + 3, k + 44, Block.planks.blockID);
		world.setBlock(i + 12, j + 3, k + 45, Block.planks.blockID);
		world.setBlock(i + 12, j + 3, k + 46, Block.planks.blockID);
		world.setBlock(i + 13, j + 3, k + 2, Block.planks.blockID);
		world.setBlock(i + 13, j + 3, k + 3, Block.planks.blockID);
		world.setBlock(i + 13, j + 3, k + 10, Block.planks.blockID);
		world.setBlock(i + 13, j + 3, k + 16, Block.planks.blockID);
		world.setBlock(i + 13, j + 3, k + 22, Block.planks.blockID);
		world.setBlock(i + 13, j + 3, k + 28, Block.planks.blockID);
		world.setBlock(i + 13, j + 3, k + 34, Block.planks.blockID);
		world.setBlock(i + 13, j + 3, k + 40, Block.planks.blockID);
		world.setBlock(i + 13, j + 3, k + 42, Block.planks.blockID);
		world.setBlock(i + 13, j + 3, k + 43, Block.planks.blockID);
		world.setBlock(i + 13, j + 3, k + 44, Block.planks.blockID);
		world.setBlock(i + 14, j + 3, k + 3, Block.planks.blockID);
		world.setBlock(i + 14, j + 3, k + 4, Block.planks.blockID);
		world.setBlock(i + 14, j + 3, k + 10, Block.planks.blockID);
		world.setBlock(i + 14, j + 3, k + 16, Block.planks.blockID);
		world.setBlock(i + 14, j + 3, k + 22, Block.planks.blockID);
		world.setBlock(i + 14, j + 3, k + 28, Block.planks.blockID);
		world.setBlock(i + 14, j + 3, k + 34, Block.planks.blockID);
		world.setBlock(i + 14, j + 3, k + 40, Block.planks.blockID);
		world.setBlock(i + 14, j + 3, k + 41, Block.planks.blockID);
		world.setBlock(i + 14, j + 3, k + 42, Block.planks.blockID);
		world.setBlock(i + 15, j + 3, k + 4, Block.planks.blockID);
		world.setBlock(i + 15, j + 3, k + 5, Block.planks.blockID);
		world.setBlock(i + 15, j + 3, k + 6, Block.planks.blockID);
		world.setBlock(i + 15, j + 3, k + 7, Block.planks.blockID);
		world.setBlock(i + 15, j + 3, k + 8, Block.planks.blockID);
		world.setBlock(i + 15, j + 3, k + 9, Block.planks.blockID);
		world.setBlock(i + 15, j + 3, k + 10, Block.planks.blockID);
		world.setBlock(i + 15, j + 3, k + 11, Block.planks.blockID);
		world.setBlock(i + 15, j + 3, k + 12, Block.glass.blockID);
		world.setBlock(i + 15, j + 3, k + 13, Block.planks.blockID);
		world.setBlock(i + 15, j + 3, k + 14, Block.planks.blockID);
		world.setBlock(i + 15, j + 3, k + 15, Block.planks.blockID);
		world.setBlock(i + 15, j + 3, k + 16, Block.planks.blockID);
		world.setBlock(i + 15, j + 3, k + 17, Block.planks.blockID);
		world.setBlock(i + 15, j + 3, k + 18, Block.glass.blockID);
		world.setBlock(i + 15, j + 3, k + 19, Block.planks.blockID);
		world.setBlock(i + 15, j + 3, k + 20, Block.planks.blockID);
		world.setBlock(i + 15, j + 3, k + 21, Block.planks.blockID);
		world.setBlock(i + 15, j + 3, k + 22, Block.planks.blockID);
		world.setBlock(i + 15, j + 3, k + 23, Block.planks.blockID);
		world.setBlock(i + 15, j + 3, k + 24, Block.glass.blockID);
		world.setBlock(i + 15, j + 3, k + 25, Block.planks.blockID);
		world.setBlock(i + 15, j + 3, k + 26, Block.planks.blockID);
		world.setBlock(i + 15, j + 3, k + 27, Block.planks.blockID);
		world.setBlock(i + 15, j + 3, k + 28, Block.planks.blockID);
		world.setBlock(i + 15, j + 3, k + 29, Block.planks.blockID);
		world.setBlock(i + 15, j + 3, k + 30, Block.glass.blockID);
		world.setBlock(i + 15, j + 3, k + 31, Block.planks.blockID);
		world.setBlock(i + 15, j + 3, k + 32, Block.planks.blockID);
		world.setBlock(i + 15, j + 3, k + 33, Block.planks.blockID);
		world.setBlock(i + 15, j + 3, k + 34, Block.planks.blockID);
		world.setBlock(i + 15, j + 3, k + 35, Block.planks.blockID);
		world.setBlock(i + 15, j + 3, k + 36, Block.glass.blockID);
		world.setBlock(i + 15, j + 3, k + 37, Block.planks.blockID);
		world.setBlock(i + 15, j + 3, k + 38, Block.planks.blockID);
		world.setBlock(i + 15, j + 3, k + 39, Block.planks.blockID);
		world.setBlock(i + 15, j + 3, k + 40, Block.planks.blockID);
		world.setBlockAndMetadataWithNotify(i + 7, j + 3, k + 7, Block.torchWood.blockID, 1);
		world.setBlockAndMetadataWithNotify(i + 7, j + 3, k + 10, Block.torchWood.blockID, 1);
		world.setBlockAndMetadataWithNotify(i + 7, j + 3, k + 13, Block.torchWood.blockID, 1);
		world.setBlockAndMetadataWithNotify(i + 7, j + 3, k + 16, Block.torchWood.blockID, 1);
		world.setBlockAndMetadataWithNotify(i + 7, j + 3, k + 19, Block.torchWood.blockID, 1);
		world.setBlockAndMetadataWithNotify(i + 7, j + 3, k + 22, Block.torchWood.blockID, 1);
		world.setBlockAndMetadataWithNotify(i + 7, j + 3, k + 25, Block.torchWood.blockID, 1);
		world.setBlockAndMetadataWithNotify(i + 7, j + 3, k + 28, Block.torchWood.blockID, 1);
		world.setBlockAndMetadataWithNotify(i + 7, j + 3, k + 31, Block.torchWood.blockID, 1);
		world.setBlockAndMetadataWithNotify(i + 7, j + 3, k + 34, Block.torchWood.blockID, 1);
		world.setBlockAndMetadataWithNotify(i + 7, j + 3, k + 37, Block.torchWood.blockID, 1);
		world.setBlockAndMetadataWithNotify(i + 7, j + 3, k + 39, Block.torchWood.blockID, 4);
		world.setBlockAndMetadataWithNotify(i + 8, j + 3, k + 39, Block.signWall.blockID, 2);
		world.setBlockAndMetadataWithNotify(i + 8, j + 3, k + 41, Block.torchWood.blockID, 1);
		world.setBlockAndMetadataWithNotify(i + 9, j + 3, k + 3, Block.torchWood.blockID, 3);
		world.setBlockAndMetadataWithNotify(i + 9, j + 3, k + 40, Block.doorWood.blockID, 9);
		world.setBlockAndMetadataWithNotify(i + 9, j + 3, k + 43, Block.torchWood.blockID, 4);
		world.setBlockAndMetadataWithNotify(i + 10, j + 3, k + 12, Block.doorWood.blockID, 8);
		world.setBlockAndMetadataWithNotify(i + 10, j + 3, k + 18, Block.doorWood.blockID, 8);
		world.setBlockAndMetadataWithNotify(i + 10, j + 3, k + 24, Block.doorWood.blockID, 8);
		world.setBlockAndMetadataWithNotify(i + 10, j + 3, k + 30, Block.doorWood.blockID, 8);
		world.setBlockAndMetadataWithNotify(i + 10, j + 3, k + 36, Block.doorWood.blockID, 8);
		world.setBlockAndMetadataWithNotify(i + 12, j + 3, k + 3, Block.torchWood.blockID, 3);
		world.setBlockAndMetadataWithNotify(i + 12, j + 3, k + 43, Block.torchWood.blockID, 4);
		world.setBlockAndMetadataWithNotify(i + 13, j + 3, k + 9, Block.torchWood.blockID, 4);
		world.setBlockAndMetadataWithNotify(i + 13, j + 3, k + 11, Block.torchWood.blockID, 3);
		world.setBlockAndMetadataWithNotify(i + 13, j + 3, k + 41, Block.torchWood.blockID, 2);
		world.setBlockAndMetadataWithNotify(i + 14, j + 3, k + 14, Block.torchWood.blockID, 2);
		world.setBlockAndMetadataWithNotify(i + 14, j + 3, k + 33, Block.torchWood.blockID, 2);
	
		generate6(world, rand, i, j, k);
		return true;
	}
	
	public boolean generate6(World world, Random rand, int i, int j, int k) 
	{
	
		world.setBlock(i + 6, j + 4, k + 4, Block.planks.blockID);
		world.setBlock(i + 6, j + 4, k + 5, Block.planks.blockID);
		world.setBlock(i + 6, j + 4, k + 6, Block.planks.blockID);
		world.setBlock(i + 6, j + 4, k + 7, Block.planks.blockID);
		world.setBlock(i + 6, j + 4, k + 8, Block.planks.blockID);
		world.setBlock(i + 6, j + 4, k + 9, Block.planks.blockID);
		world.setBlock(i + 6, j + 4, k + 10, Block.planks.blockID);
		world.setBlock(i + 6, j + 4, k + 11, Block.planks.blockID);
		world.setBlock(i + 6, j + 4, k + 12, Block.planks.blockID);
		world.setBlock(i + 6, j + 4, k + 13, Block.planks.blockID);
		world.setBlock(i + 6, j + 4, k + 14, Block.planks.blockID);
		world.setBlock(i + 6, j + 4, k + 15, Block.planks.blockID);
		world.setBlock(i + 6, j + 4, k + 16, Block.planks.blockID);
		world.setBlock(i + 6, j + 4, k + 17, Block.planks.blockID);
		world.setBlock(i + 6, j + 4, k + 18, Block.planks.blockID);
		world.setBlock(i + 6, j + 4, k + 19, Block.planks.blockID);
		world.setBlock(i + 6, j + 4, k + 20, Block.planks.blockID);
		world.setBlock(i + 6, j + 4, k + 21, Block.planks.blockID);
		world.setBlock(i + 6, j + 4, k + 22, Block.planks.blockID);
		world.setBlock(i + 6, j + 4, k + 23, Block.planks.blockID);
		world.setBlock(i + 6, j + 4, k + 24, Block.planks.blockID);
		world.setBlock(i + 6, j + 4, k + 25, Block.planks.blockID);
		world.setBlock(i + 6, j + 4, k + 26, Block.planks.blockID);
		world.setBlock(i + 6, j + 4, k + 27, Block.planks.blockID);
		world.setBlock(i + 6, j + 4, k + 28, Block.planks.blockID);
		world.setBlock(i + 6, j + 4, k + 29, Block.planks.blockID);
		world.setBlock(i + 6, j + 4, k + 30, Block.planks.blockID);
		world.setBlock(i + 6, j + 4, k + 31, Block.planks.blockID);
		world.setBlock(i + 6, j + 4, k + 32, Block.planks.blockID);
		world.setBlock(i + 6, j + 4, k + 33, Block.planks.blockID);
		world.setBlock(i + 6, j + 4, k + 34, Block.planks.blockID);
		world.setBlock(i + 6, j + 4, k + 35, Block.planks.blockID);
		world.setBlock(i + 6, j + 4, k + 36, Block.planks.blockID);
		world.setBlock(i + 6, j + 4, k + 37, Block.planks.blockID);
		world.setBlock(i + 6, j + 4, k + 38, Block.planks.blockID);
		world.setBlock(i + 6, j + 4, k + 39, Block.planks.blockID);
		world.setBlock(i + 6, j + 4, k + 40, Block.planks.blockID);
		world.setBlock(i + 7, j + 4, k + 3, Block.planks.blockID);
		world.setBlock(i + 7, j + 4, k + 4, Block.planks.blockID);
		world.setBlock(i + 7, j + 4, k + 5, Block.planks.blockID);
		world.setBlock(i + 7, j + 4, k + 6, Block.planks.blockID);
		world.setBlock(i + 7, j + 4, k + 7, Block.planks.blockID);
		world.setBlock(i + 7, j + 4, k + 8, Block.planks.blockID);
		world.setBlock(i + 7, j + 4, k + 9, Block.planks.blockID);
		world.setBlock(i + 7, j + 4, k + 10, Block.planks.blockID);
		world.setBlock(i + 7, j + 4, k + 11, Block.planks.blockID);
		world.setBlock(i + 7, j + 4, k + 12, Block.planks.blockID);
		world.setBlock(i + 7, j + 4, k + 13, Block.planks.blockID);
		world.setBlock(i + 7, j + 4, k + 14, Block.planks.blockID);
		world.setBlock(i + 7, j + 4, k + 15, Block.planks.blockID);
		world.setBlock(i + 7, j + 4, k + 16, Block.planks.blockID);
		world.setBlock(i + 7, j + 4, k + 17, Block.planks.blockID);
		world.setBlock(i + 7, j + 4, k + 18, Block.planks.blockID);
		world.setBlock(i + 7, j + 4, k + 19, Block.planks.blockID);
		world.setBlock(i + 7, j + 4, k + 20, Block.planks.blockID);
		world.setBlock(i + 7, j + 4, k + 21, Block.planks.blockID);
		world.setBlock(i + 7, j + 4, k + 22, Block.planks.blockID);
		world.setBlock(i + 7, j + 4, k + 23, Block.planks.blockID);
		world.setBlock(i + 7, j + 4, k + 24, Block.planks.blockID);
		world.setBlock(i + 7, j + 4, k + 25, Block.planks.blockID);
		world.setBlock(i + 7, j + 4, k + 26, Block.planks.blockID);
		world.setBlock(i + 7, j + 4, k + 27, Block.planks.blockID);
		world.setBlock(i + 7, j + 4, k + 28, Block.planks.blockID);
		world.setBlock(i + 7, j + 4, k + 29, Block.planks.blockID);
		world.setBlock(i + 7, j + 4, k + 30, Block.planks.blockID);
		world.setBlock(i + 7, j + 4, k + 31, Block.planks.blockID);
		world.setBlock(i + 7, j + 4, k + 32, Block.planks.blockID);
		world.setBlock(i + 7, j + 4, k + 33, Block.planks.blockID);
		world.setBlock(i + 7, j + 4, k + 34, Block.planks.blockID);
		world.setBlock(i + 7, j + 4, k + 35, Block.planks.blockID);
		world.setBlock(i + 7, j + 4, k + 36, Block.planks.blockID);
		world.setBlock(i + 7, j + 4, k + 37, Block.planks.blockID);
		world.setBlock(i + 7, j + 4, k + 38, Block.planks.blockID);
		world.setBlock(i + 7, j + 4, k + 39, Block.planks.blockID);
		world.setBlock(i + 7, j + 4, k + 40, Block.planks.blockID);
		world.setBlock(i + 7, j + 4, k + 41, Block.planks.blockID);
		world.setBlock(i + 7, j + 4, k + 42, Block.planks.blockID);
		world.setBlock(i + 8, j + 4, k + 2, Block.planks.blockID);
		world.setBlock(i + 8, j + 4, k + 3, Block.planks.blockID);
		world.setBlock(i + 8, j + 4, k + 4, Block.planks.blockID);
		world.setBlock(i + 8, j + 4, k + 5, Block.planks.blockID);
		world.setBlock(i + 8, j + 4, k + 6, Block.planks.blockID);
		world.setBlock(i + 8, j + 4, k + 7, Block.planks.blockID);
		world.setBlock(i + 8, j + 4, k + 8, Block.planks.blockID);
		world.setBlock(i + 8, j + 4, k + 9, Block.planks.blockID);
		world.setBlock(i + 8, j + 4, k + 10, Block.planks.blockID);
		world.setBlock(i + 8, j + 4, k + 11, Block.planks.blockID);
		world.setBlock(i + 8, j + 4, k + 12, Block.planks.blockID);
		world.setBlock(i + 8, j + 4, k + 13, Block.planks.blockID);
		world.setBlock(i + 8, j + 4, k + 14, Block.planks.blockID);
		world.setBlock(i + 8, j + 4, k + 15, Block.planks.blockID);
		world.setBlock(i + 8, j + 4, k + 16, Block.planks.blockID);
		world.setBlock(i + 8, j + 4, k + 17, Block.planks.blockID);
		world.setBlock(i + 8, j + 4, k + 18, Block.planks.blockID);
		world.setBlock(i + 8, j + 4, k + 19, Block.planks.blockID);
		world.setBlock(i + 8, j + 4, k + 20, Block.planks.blockID);
		world.setBlock(i + 8, j + 4, k + 21, Block.planks.blockID);
		world.setBlock(i + 8, j + 4, k + 22, Block.planks.blockID);
		world.setBlock(i + 8, j + 4, k + 23, Block.planks.blockID);
		world.setBlock(i + 8, j + 4, k + 24, Block.planks.blockID);
		world.setBlock(i + 8, j + 4, k + 25, Block.planks.blockID);
		world.setBlock(i + 8, j + 4, k + 26, Block.planks.blockID);
		world.setBlock(i + 8, j + 4, k + 27, Block.planks.blockID);
		world.setBlock(i + 8, j + 4, k + 28, Block.planks.blockID);
		world.setBlock(i + 8, j + 4, k + 29, Block.planks.blockID);
		world.setBlock(i + 8, j + 4, k + 30, Block.planks.blockID);
		world.setBlock(i + 8, j + 4, k + 31, Block.planks.blockID);
		world.setBlock(i + 8, j + 4, k + 32, Block.planks.blockID);
		world.setBlock(i + 8, j + 4, k + 33, Block.planks.blockID);
		world.setBlock(i + 8, j + 4, k + 34, Block.planks.blockID);
		world.setBlock(i + 8, j + 4, k + 35, Block.planks.blockID);
		world.setBlock(i + 8, j + 4, k + 36, Block.planks.blockID);
		world.setBlock(i + 8, j + 4, k + 37, Block.planks.blockID);
		world.setBlock(i + 8, j + 4, k + 38, Block.planks.blockID);
		world.setBlock(i + 8, j + 4, k + 39, Block.planks.blockID);
		world.setBlock(i + 8, j + 4, k + 40, Block.planks.blockID);
		world.setBlock(i + 8, j + 4, k + 41, Block.planks.blockID);
		world.setBlock(i + 8, j + 4, k + 42, Block.planks.blockID);
		world.setBlock(i + 8, j + 4, k + 43, Block.planks.blockID);
		world.setBlock(i + 8, j + 4, k + 44, Block.planks.blockID);
		world.setBlock(i + 9, j + 4, k + 2, Block.planks.blockID);
		world.setBlock(i + 9, j + 4, k + 3, Block.planks.blockID);
		world.setBlock(i + 9, j + 4, k + 4, Block.planks.blockID);
		world.setBlock(i + 9, j + 4, k + 5, Block.planks.blockID);
		world.setBlock(i + 9, j + 4, k + 6, Block.planks.blockID);
		world.setBlock(i + 9, j + 4, k + 7, Block.planks.blockID);
		world.setBlock(i + 9, j + 4, k + 8, Block.planks.blockID);
		world.setBlock(i + 9, j + 4, k + 9, Block.planks.blockID);
		world.setBlock(i + 9, j + 4, k + 10, Block.planks.blockID);
		world.setBlock(i + 9, j + 4, k + 11, Block.planks.blockID);
		world.setBlock(i + 9, j + 4, k + 12, Block.planks.blockID);
		world.setBlock(i + 9, j + 4, k + 13, Block.planks.blockID);
		world.setBlock(i + 9, j + 4, k + 14, Block.planks.blockID);
		world.setBlock(i + 9, j + 4, k + 15, Block.planks.blockID);
		world.setBlock(i + 9, j + 4, k + 16, Block.planks.blockID);
		world.setBlock(i + 9, j + 4, k + 17, Block.planks.blockID);
		world.setBlock(i + 9, j + 4, k + 18, Block.planks.blockID);
		world.setBlock(i + 9, j + 4, k + 19, Block.planks.blockID);
		world.setBlock(i + 9, j + 4, k + 20, Block.planks.blockID);
		world.setBlock(i + 9, j + 4, k + 21, Block.planks.blockID);
		world.setBlock(i + 9, j + 4, k + 22, Block.planks.blockID);
		world.setBlock(i + 9, j + 4, k + 23, Block.planks.blockID);
		world.setBlock(i + 9, j + 4, k + 24, Block.planks.blockID);
		world.setBlock(i + 9, j + 4, k + 25, Block.planks.blockID);
		world.setBlock(i + 9, j + 4, k + 26, Block.planks.blockID);
		world.setBlock(i + 9, j + 4, k + 27, Block.planks.blockID);
		world.setBlock(i + 9, j + 4, k + 28, Block.planks.blockID);
		world.setBlock(i + 9, j + 4, k + 29, Block.planks.blockID);
		world.setBlock(i + 9, j + 4, k + 30, Block.planks.blockID);
		world.setBlock(i + 9, j + 4, k + 31, Block.planks.blockID);
		world.setBlock(i + 9, j + 4, k + 32, Block.planks.blockID);
		world.setBlock(i + 9, j + 4, k + 33, Block.planks.blockID);
		world.setBlock(i + 9, j + 4, k + 34, Block.planks.blockID);
		world.setBlock(i + 9, j + 4, k + 35, Block.planks.blockID);
		world.setBlock(i + 9, j + 4, k + 36, Block.planks.blockID);
		world.setBlock(i + 9, j + 4, k + 37, Block.planks.blockID);
		world.setBlock(i + 9, j + 4, k + 38, Block.planks.blockID);
		world.setBlock(i + 9, j + 4, k + 39, Block.planks.blockID);
		world.setBlock(i + 9, j + 4, k + 40, Block.planks.blockID);
		world.setBlock(i + 9, j + 4, k + 41, Block.planks.blockID);
		world.setBlock(i + 9, j + 4, k + 42, Block.planks.blockID);
		world.setBlock(i + 9, j + 4, k + 43, Block.planks.blockID);
		world.setBlock(i + 9, j + 4, k + 44, Block.planks.blockID);
		world.setBlock(i + 9, j + 4, k + 45, Block.planks.blockID);
		world.setBlock(i + 9, j + 4, k + 46, Block.planks.blockID);
		world.setBlock(i + 10, j + 4, k + 2, Block.planks.blockID);
		world.setBlock(i + 10, j + 4, k + 3, Block.planks.blockID);
		world.setBlock(i + 10, j + 4, k + 4, Block.planks.blockID);
		world.setBlockAndMetadata(i + 10, j + 4, k + 5, Block.stairCompactPlanks.blockID, 3);
		world.setBlock(i + 10, j + 4, k + 9, Block.planks.blockID);
		world.setBlock(i + 10, j + 4, k + 10, Block.planks.blockID);
		world.setBlock(i + 10, j + 4, k + 11, Block.planks.blockID);
		world.setBlock(i + 10, j + 4, k + 12, Block.planks.blockID);
		world.setBlock(i + 10, j + 4, k + 13, Block.planks.blockID);
		world.setBlock(i + 10, j + 4, k + 14, Block.planks.blockID);
		world.setBlock(i + 10, j + 4, k + 15, Block.planks.blockID);
		world.setBlock(i + 10, j + 4, k + 16, Block.planks.blockID);
		world.setBlock(i + 10, j + 4, k + 17, Block.planks.blockID);
		world.setBlock(i + 10, j + 4, k + 18, Block.planks.blockID);
		world.setBlock(i + 10, j + 4, k + 19, Block.planks.blockID);
		world.setBlock(i + 10, j + 4, k + 20, Block.planks.blockID);
		world.setBlock(i + 10, j + 4, k + 21, Block.planks.blockID);
		world.setBlock(i + 10, j + 4, k + 22, Block.planks.blockID);
		world.setBlock(i + 10, j + 4, k + 23, Block.planks.blockID);
		world.setBlock(i + 10, j + 4, k + 24, Block.planks.blockID);
		world.setBlock(i + 10, j + 4, k + 25, Block.planks.blockID);
		world.setBlock(i + 10, j + 4, k + 26, Block.planks.blockID);
		world.setBlock(i + 10, j + 4, k + 27, Block.planks.blockID);
		world.setBlock(i + 10, j + 4, k + 28, Block.planks.blockID);
		world.setBlock(i + 10, j + 4, k + 29, Block.planks.blockID);
		world.setBlock(i + 10, j + 4, k + 30, Block.planks.blockID);
		world.setBlock(i + 10, j + 4, k + 31, Block.planks.blockID);
		world.setBlock(i + 10, j + 4, k + 32, Block.planks.blockID);
		world.setBlock(i + 10, j + 4, k + 33, Block.planks.blockID);
		world.setBlock(i + 10, j + 4, k + 34, Block.planks.blockID);
		world.setBlock(i + 10, j + 4, k + 35, Block.planks.blockID);
		world.setBlock(i + 10, j + 4, k + 36, Block.planks.blockID);
		world.setBlock(i + 10, j + 4, k + 37, Block.planks.blockID);
		world.setBlock(i + 10, j + 4, k + 38, Block.planks.blockID);
		world.setBlock(i + 10, j + 4, k + 39, Block.planks.blockID);
		world.setBlock(i + 10, j + 4, k + 40, Block.planks.blockID);
		world.setBlock(i + 10, j + 4, k + 41, Block.planks.blockID);
		world.setBlock(i + 10, j + 4, k + 42, Block.planks.blockID);
		world.setBlock(i + 10, j + 4, k + 43, Block.planks.blockID);
		world.setBlock(i + 10, j + 4, k + 44, Block.planks.blockID);
		world.setBlock(i + 10, j + 4, k + 45, Block.planks.blockID);
		world.setBlock(i + 10, j + 4, k + 46, Block.planks.blockID);
		world.setBlock(i + 10, j + 4, k + 47, Block.planks.blockID);
		world.setBlock(i + 11, j + 4, k + 2, Block.planks.blockID);
		world.setBlock(i + 11, j + 4, k + 3, Block.planks.blockID);
		world.setBlock(i + 11, j + 4, k + 4, Block.planks.blockID);
		world.setBlockAndMetadata(i + 11, j + 4, k + 5, Block.stairCompactPlanks.blockID, 3);
		world.setBlock(i + 11, j + 4, k + 9, Block.planks.blockID);
		world.setBlock(i + 11, j + 4, k + 10, Block.planks.blockID);
		world.setBlock(i + 11, j + 4, k + 11, Block.planks.blockID);
		world.setBlock(i + 11, j + 4, k + 12, Block.planks.blockID);
		world.setBlock(i + 11, j + 4, k + 13, Block.planks.blockID);
		world.setBlock(i + 11, j + 4, k + 14, Block.planks.blockID);
		world.setBlock(i + 11, j + 4, k + 15, Block.planks.blockID);
		world.setBlock(i + 11, j + 4, k + 16, Block.planks.blockID);
		world.setBlock(i + 11, j + 4, k + 17, Block.planks.blockID);
		world.setBlock(i + 11, j + 4, k + 18, Block.planks.blockID);
		world.setBlock(i + 11, j + 4, k + 19, Block.planks.blockID);
		world.setBlock(i + 11, j + 4, k + 20, Block.planks.blockID);
		world.setBlock(i + 11, j + 4, k + 21, Block.planks.blockID);
		world.setBlock(i + 11, j + 4, k + 22, Block.planks.blockID);
		world.setBlock(i + 11, j + 4, k + 23, Block.planks.blockID);
		world.setBlock(i + 11, j + 4, k + 24, Block.planks.blockID);
		world.setBlock(i + 11, j + 4, k + 25, Block.planks.blockID);
		world.setBlock(i + 11, j + 4, k + 26, Block.planks.blockID);
		world.setBlock(i + 11, j + 4, k + 27, Block.planks.blockID);
		world.setBlock(i + 11, j + 4, k + 28, Block.planks.blockID);
		world.setBlock(i + 11, j + 4, k + 29, Block.planks.blockID);
		world.setBlock(i + 11, j + 4, k + 30, Block.planks.blockID);
		world.setBlock(i + 11, j + 4, k + 31, Block.planks.blockID);
		world.setBlock(i + 11, j + 4, k + 32, Block.planks.blockID);
		world.setBlock(i + 11, j + 4, k + 33, Block.planks.blockID);
		world.setBlock(i + 11, j + 4, k + 34, Block.planks.blockID);
		world.setBlock(i + 11, j + 4, k + 35, Block.planks.blockID);
		world.setBlock(i + 11, j + 4, k + 36, Block.planks.blockID);
		world.setBlock(i + 11, j + 4, k + 37, Block.planks.blockID);
		world.setBlock(i + 11, j + 4, k + 38, Block.planks.blockID);
		world.setBlock(i + 11, j + 4, k + 39, Block.planks.blockID);
		world.setBlock(i + 11, j + 4, k + 40, Block.planks.blockID);
		world.setBlock(i + 11, j + 4, k + 41, Block.planks.blockID);
		world.setBlock(i + 11, j + 4, k + 42, Block.planks.blockID);
		world.setBlock(i + 11, j + 4, k + 43, Block.planks.blockID);
		world.setBlock(i + 11, j + 4, k + 44, Block.planks.blockID);
		world.setBlock(i + 11, j + 4, k + 45, Block.planks.blockID);
		world.setBlock(i + 11, j + 4, k + 46, Block.planks.blockID);
		world.setBlock(i + 11, j + 4, k + 47, Block.planks.blockID);
		world.setBlock(i + 12, j + 4, k + 2, Block.planks.blockID);
		world.setBlock(i + 12, j + 4, k + 3, Block.planks.blockID);
		world.setBlock(i + 12, j + 4, k + 4, Block.planks.blockID);
		world.setBlock(i + 12, j + 4, k + 5, Block.planks.blockID);
		world.setBlock(i + 12, j + 4, k + 6, Block.planks.blockID);
		world.setBlock(i + 12, j + 4, k + 7, Block.planks.blockID);
		world.setBlock(i + 12, j + 4, k + 8, Block.planks.blockID);
		world.setBlock(i + 12, j + 4, k + 9, Block.planks.blockID);
		world.setBlock(i + 12, j + 4, k + 10, Block.planks.blockID);
		world.setBlock(i + 12, j + 4, k + 11, Block.planks.blockID);
		world.setBlock(i + 12, j + 4, k + 12, Block.planks.blockID);
		world.setBlock(i + 12, j + 4, k + 13, Block.planks.blockID);
		world.setBlock(i + 12, j + 4, k + 14, Block.planks.blockID);
		world.setBlock(i + 12, j + 4, k + 15, Block.planks.blockID);
		world.setBlock(i + 12, j + 4, k + 16, Block.planks.blockID);
		world.setBlock(i + 12, j + 4, k + 17, Block.planks.blockID);
		world.setBlock(i + 12, j + 4, k + 18, Block.planks.blockID);
		world.setBlock(i + 12, j + 4, k + 19, Block.planks.blockID);
		world.setBlock(i + 12, j + 4, k + 20, Block.planks.blockID);
		world.setBlock(i + 12, j + 4, k + 21, Block.planks.blockID);
		world.setBlock(i + 12, j + 4, k + 22, Block.planks.blockID);
		world.setBlock(i + 12, j + 4, k + 23, Block.planks.blockID);
		world.setBlock(i + 12, j + 4, k + 24, Block.planks.blockID);
		world.setBlock(i + 12, j + 4, k + 25, Block.planks.blockID);
		world.setBlock(i + 12, j + 4, k + 26, Block.planks.blockID);
		world.setBlock(i + 12, j + 4, k + 27, Block.planks.blockID);
		world.setBlock(i + 12, j + 4, k + 28, Block.planks.blockID);
		world.setBlock(i + 12, j + 4, k + 29, Block.planks.blockID);
		world.setBlock(i + 12, j + 4, k + 30, Block.planks.blockID);
		world.setBlock(i + 12, j + 4, k + 31, Block.planks.blockID);
		world.setBlock(i + 12, j + 4, k + 32, Block.planks.blockID);
		world.setBlock(i + 12, j + 4, k + 33, Block.planks.blockID);
		world.setBlock(i + 12, j + 4, k + 34, Block.planks.blockID);
		world.setBlock(i + 12, j + 4, k + 35, Block.planks.blockID);
		world.setBlock(i + 12, j + 4, k + 36, Block.planks.blockID);
		world.setBlock(i + 12, j + 4, k + 37, Block.planks.blockID);
		world.setBlock(i + 12, j + 4, k + 38, Block.planks.blockID);
		world.setBlock(i + 12, j + 4, k + 39, Block.planks.blockID);
		world.setBlock(i + 12, j + 4, k + 40, Block.planks.blockID);
		world.setBlock(i + 12, j + 4, k + 41, Block.planks.blockID);
		world.setBlock(i + 12, j + 4, k + 42, Block.planks.blockID);
		world.setBlock(i + 12, j + 4, k + 43, Block.planks.blockID);
		world.setBlock(i + 12, j + 4, k + 44, Block.planks.blockID);
		world.setBlock(i + 12, j + 4, k + 45, Block.planks.blockID);
		world.setBlock(i + 12, j + 4, k + 46, Block.planks.blockID);
		world.setBlock(i + 13, j + 4, k + 2, Block.planks.blockID);
		world.setBlock(i + 13, j + 4, k + 3, Block.planks.blockID);
		world.setBlock(i + 13, j + 4, k + 4, Block.planks.blockID);
		world.setBlock(i + 13, j + 4, k + 5, Block.planks.blockID);
		world.setBlock(i + 13, j + 4, k + 6, Block.planks.blockID);
		world.setBlock(i + 13, j + 4, k + 7, Block.planks.blockID);
		world.setBlock(i + 13, j + 4, k + 8, Block.planks.blockID);
		world.setBlock(i + 13, j + 4, k + 9, Block.planks.blockID);
		world.setBlock(i + 13, j + 4, k + 10, Block.planks.blockID);
		world.setBlock(i + 13, j + 4, k + 11, Block.planks.blockID);
		world.setBlock(i + 13, j + 4, k + 12, Block.planks.blockID);
		world.setBlock(i + 13, j + 4, k + 13, Block.planks.blockID);
		world.setBlock(i + 13, j + 4, k + 14, Block.planks.blockID);
		world.setBlock(i + 13, j + 4, k + 15, Block.planks.blockID);
		world.setBlock(i + 13, j + 4, k + 16, Block.planks.blockID);
		world.setBlock(i + 13, j + 4, k + 17, Block.planks.blockID);
		world.setBlock(i + 13, j + 4, k + 18, Block.planks.blockID);
		world.setBlock(i + 13, j + 4, k + 19, Block.planks.blockID);
		world.setBlock(i + 13, j + 4, k + 20, Block.planks.blockID);
		world.setBlock(i + 13, j + 4, k + 21, Block.planks.blockID);
		world.setBlock(i + 13, j + 4, k + 22, Block.planks.blockID);
		world.setBlock(i + 13, j + 4, k + 23, Block.planks.blockID);
		world.setBlock(i + 13, j + 4, k + 24, Block.planks.blockID);
		world.setBlock(i + 13, j + 4, k + 25, Block.planks.blockID);
		world.setBlock(i + 13, j + 4, k + 26, Block.planks.blockID);
		world.setBlock(i + 13, j + 4, k + 27, Block.planks.blockID);
		world.setBlock(i + 13, j + 4, k + 28, Block.planks.blockID);
		world.setBlock(i + 13, j + 4, k + 29, Block.planks.blockID);
		world.setBlock(i + 13, j + 4, k + 30, Block.planks.blockID);
		world.setBlock(i + 13, j + 4, k + 31, Block.planks.blockID);
		world.setBlock(i + 13, j + 4, k + 32, Block.planks.blockID);
		world.setBlock(i + 13, j + 4, k + 33, Block.planks.blockID);
		world.setBlock(i + 13, j + 4, k + 34, Block.planks.blockID);
		world.setBlock(i + 13, j + 4, k + 35, Block.planks.blockID);
		world.setBlock(i + 13, j + 4, k + 36, Block.planks.blockID);
		world.setBlock(i + 13, j + 4, k + 37, Block.planks.blockID);
		world.setBlock(i + 13, j + 4, k + 38, Block.planks.blockID);
		world.setBlock(i + 13, j + 4, k + 39, Block.planks.blockID);
		world.setBlock(i + 13, j + 4, k + 40, Block.planks.blockID);
		world.setBlock(i + 13, j + 4, k + 41, Block.planks.blockID);
		world.setBlock(i + 13, j + 4, k + 42, Block.planks.blockID);
		world.setBlock(i + 13, j + 4, k + 43, Block.planks.blockID);
		world.setBlock(i + 13, j + 4, k + 44, Block.planks.blockID);
		world.setBlock(i + 14, j + 4, k + 3, Block.planks.blockID);
		world.setBlock(i + 14, j + 4, k + 4, Block.planks.blockID);
		world.setBlock(i + 14, j + 4, k + 5, Block.planks.blockID);
		world.setBlock(i + 14, j + 4, k + 6, Block.planks.blockID);
		world.setBlock(i + 14, j + 4, k + 7, Block.planks.blockID);
		world.setBlock(i + 14, j + 4, k + 8, Block.planks.blockID);
		world.setBlock(i + 14, j + 4, k + 9, Block.planks.blockID);
		world.setBlock(i + 14, j + 4, k + 10, Block.planks.blockID);
		world.setBlock(i + 14, j + 4, k + 11, Block.planks.blockID);
		world.setBlock(i + 14, j + 4, k + 12, Block.planks.blockID);
		world.setBlock(i + 14, j + 4, k + 13, Block.planks.blockID);
		world.setBlock(i + 14, j + 4, k + 14, Block.planks.blockID);
		world.setBlock(i + 14, j + 4, k + 15, Block.planks.blockID);
		world.setBlock(i + 14, j + 4, k + 16, Block.planks.blockID);
		world.setBlock(i + 14, j + 4, k + 17, Block.planks.blockID);
		world.setBlock(i + 14, j + 4, k + 18, Block.planks.blockID);
		world.setBlock(i + 14, j + 4, k + 19, Block.planks.blockID);
		world.setBlock(i + 14, j + 4, k + 20, Block.planks.blockID);
		world.setBlock(i + 14, j + 4, k + 21, Block.planks.blockID);
		world.setBlock(i + 14, j + 4, k + 22, Block.planks.blockID);
		world.setBlock(i + 14, j + 4, k + 23, Block.planks.blockID);
		world.setBlock(i + 14, j + 4, k + 24, Block.planks.blockID);
		world.setBlock(i + 14, j + 4, k + 25, Block.planks.blockID);
		world.setBlock(i + 14, j + 4, k + 26, Block.planks.blockID);
		world.setBlock(i + 14, j + 4, k + 27, Block.planks.blockID);
		world.setBlock(i + 14, j + 4, k + 28, Block.planks.blockID);
		world.setBlock(i + 14, j + 4, k + 29, Block.planks.blockID);
		world.setBlock(i + 14, j + 4, k + 30, Block.planks.blockID);
		world.setBlock(i + 14, j + 4, k + 31, Block.planks.blockID);
		world.setBlock(i + 14, j + 4, k + 32, Block.planks.blockID);
		world.setBlock(i + 14, j + 4, k + 33, Block.planks.blockID);
		world.setBlock(i + 14, j + 4, k + 34, Block.planks.blockID);
		world.setBlock(i + 14, j + 4, k + 35, Block.planks.blockID);
		world.setBlock(i + 14, j + 4, k + 36, Block.planks.blockID);
		world.setBlock(i + 14, j + 4, k + 37, Block.planks.blockID);
		world.setBlock(i + 14, j + 4, k + 38, Block.planks.blockID);
		world.setBlock(i + 14, j + 4, k + 39, Block.planks.blockID);
		world.setBlock(i + 14, j + 4, k + 40, Block.planks.blockID);
		world.setBlock(i + 14, j + 4, k + 41, Block.planks.blockID);
		world.setBlock(i + 14, j + 4, k + 42, Block.planks.blockID);
		world.setBlock(i + 15, j + 4, k + 4, Block.planks.blockID);
		world.setBlock(i + 15, j + 4, k + 5, Block.planks.blockID);
		world.setBlock(i + 15, j + 4, k + 6, Block.planks.blockID);
		world.setBlock(i + 15, j + 4, k + 7, Block.planks.blockID);
		world.setBlock(i + 15, j + 4, k + 8, Block.planks.blockID);
		world.setBlock(i + 15, j + 4, k + 9, Block.planks.blockID);
		world.setBlock(i + 15, j + 4, k + 10, Block.planks.blockID);
		world.setBlock(i + 15, j + 4, k + 11, Block.planks.blockID);
		world.setBlock(i + 15, j + 4, k + 12, Block.planks.blockID);
		world.setBlock(i + 15, j + 4, k + 13, Block.planks.blockID);
		world.setBlock(i + 15, j + 4, k + 14, Block.planks.blockID);
		world.setBlock(i + 15, j + 4, k + 15, Block.planks.blockID);
		world.setBlock(i + 15, j + 4, k + 16, Block.planks.blockID);
		world.setBlock(i + 15, j + 4, k + 17, Block.planks.blockID);
		world.setBlock(i + 15, j + 4, k + 18, Block.planks.blockID);
		world.setBlock(i + 15, j + 4, k + 19, Block.planks.blockID);
		world.setBlock(i + 15, j + 4, k + 20, Block.planks.blockID);
		world.setBlock(i + 15, j + 4, k + 21, Block.planks.blockID);
		world.setBlock(i + 15, j + 4, k + 22, Block.planks.blockID);
		world.setBlock(i + 15, j + 4, k + 23, Block.planks.blockID);
		world.setBlock(i + 15, j + 4, k + 24, Block.planks.blockID);
		world.setBlock(i + 15, j + 4, k + 25, Block.planks.blockID);
		world.setBlock(i + 15, j + 4, k + 26, Block.planks.blockID);
		world.setBlock(i + 15, j + 4, k + 27, Block.planks.blockID);
		world.setBlock(i + 15, j + 4, k + 28, Block.planks.blockID);
		world.setBlock(i + 15, j + 4, k + 29, Block.planks.blockID);
		world.setBlock(i + 15, j + 4, k + 30, Block.planks.blockID);
		world.setBlock(i + 15, j + 4, k + 31, Block.planks.blockID);
		world.setBlock(i + 15, j + 4, k + 32, Block.planks.blockID);
		world.setBlock(i + 15, j + 4, k + 33, Block.planks.blockID);
		world.setBlock(i + 15, j + 4, k + 34, Block.planks.blockID);
		world.setBlock(i + 15, j + 4, k + 35, Block.planks.blockID);
		world.setBlock(i + 15, j + 4, k + 36, Block.planks.blockID);
		world.setBlock(i + 15, j + 4, k + 37, Block.planks.blockID);
		world.setBlock(i + 15, j + 4, k + 38, Block.planks.blockID);
		world.setBlock(i + 15, j + 4, k + 39, Block.planks.blockID);
		world.setBlock(i + 15, j + 4, k + 40, Block.planks.blockID);
	
		generate7(world, rand, i, j, k);
		return true;
	}
	
	public boolean generate7(World world, Random rand, int i, int j, int k) 
	{
	
		world.setBlock(i + 6, j + 5, k + 4, Block.planks.blockID);
		world.setBlock(i + 6, j + 5, k + 5, Block.planks.blockID);
		world.setBlock(i + 6, j + 5, k + 7, Block.planks.blockID);
		world.setBlock(i + 6, j + 5, k + 8, Block.planks.blockID);
		world.setBlock(i + 6, j + 5, k + 10, Block.planks.blockID);
		world.setBlock(i + 6, j + 5, k + 11, Block.planks.blockID);
		world.setBlock(i + 6, j + 5, k + 13, Block.planks.blockID);
		world.setBlock(i + 6, j + 5, k + 14, Block.planks.blockID);
		world.setBlock(i + 6, j + 5, k + 16, Block.planks.blockID);
		world.setBlock(i + 6, j + 5, k + 17, Block.planks.blockID);
		world.setBlock(i + 6, j + 5, k + 19, Block.planks.blockID);
		world.setBlock(i + 6, j + 5, k + 20, Block.planks.blockID);
		world.setBlock(i + 6, j + 5, k + 21, Block.planks.blockID);
		world.setBlock(i + 6, j + 5, k + 22, Block.planks.blockID);
		world.setBlock(i + 6, j + 5, k + 23, Block.planks.blockID);
		world.setBlock(i + 6, j + 5, k + 24, Block.planks.blockID);
		world.setBlock(i + 6, j + 5, k + 25, Block.planks.blockID);
		world.setBlock(i + 6, j + 5, k + 27, Block.planks.blockID);
		world.setBlock(i + 6, j + 5, k + 28, Block.planks.blockID);
		world.setBlockAndMetadata(i + 6, j + 5, k + 29, Block.dispenser.blockID, 4);
		world.setBlock(i + 6, j + 5, k + 30, Block.planks.blockID);
		world.setBlock(i + 6, j + 5, k + 31, Block.planks.blockID);
		world.setBlockAndMetadata(i + 6, j + 5, k + 32, Block.dispenser.blockID, 4);
		world.setBlock(i + 6, j + 5, k + 33, Block.planks.blockID);
		world.setBlock(i + 6, j + 5, k + 34, Block.planks.blockID);
		world.setBlockAndMetadata(i + 6, j + 5, k + 35, Block.dispenser.blockID, 4);
		world.setBlock(i + 6, j + 5, k + 36, Block.planks.blockID);
		world.setBlock(i + 6, j + 5, k + 37, Block.planks.blockID);
		world.setBlockAndMetadata(i + 6, j + 5, k + 38, Block.dispenser.blockID, 4);
		world.setBlock(i + 6, j + 5, k + 39, Block.planks.blockID);
		world.setBlock(i + 6, j + 5, k + 40, Block.planks.blockID);
		world.setBlock(i + 6, j + 5, k + 41, Block.planks.blockID);
		world.setBlock(i + 6, j + 5, k + 42, Block.planks.blockID);
		world.setBlock(i + 6, j + 5, k + 43, Block.planks.blockID);
		world.setBlock(i + 7, j + 5, k + 3, Block.planks.blockID);
		world.setBlock(i + 7, j + 5, k + 4, Block.planks.blockID);
		world.setBlock(i + 7, j + 5, k + 41, Block.planks.blockID);
		world.setBlock(i + 7, j + 5, k + 43, Block.planks.blockID);
		world.setBlock(i + 7, j + 5, k + 44, Block.planks.blockID);
		world.setBlock(i + 7, j + 5, k + 45, Block.planks.blockID);
		world.setBlock(i + 8, j + 5, k + 2, Block.planks.blockID);
		world.setBlock(i + 8, j + 5, k + 3, Block.planks.blockID);
		world.setBlock(i + 8, j + 5, k + 41, Block.planks.blockID);
		world.setBlock(i + 8, j + 5, k + 45, Block.planks.blockID);
		world.setBlock(i + 8, j + 5, k + 46, Block.planks.blockID);
		world.setBlock(i + 8, j + 5, k + 47, Block.planks.blockID);
		world.setBlock(i + 9, j + 5, k + 2, Block.planks.blockID);
		world.setBlock(i + 9, j + 5, k + 5, Block.fence.blockID);
		world.setBlock(i + 9, j + 5, k + 6, Block.fence.blockID);
		world.setBlock(i + 9, j + 5, k + 7, Block.fence.blockID);
		world.setBlock(i + 9, j + 5, k + 8, Block.fence.blockID);
		world.setBlock(i + 9, j + 5, k + 9, Block.fence.blockID);
		world.setBlock(i + 9, j + 5, k + 41, Block.planks.blockID);
		world.setBlock(i + 9, j + 5, k + 46, Block.workbench.blockID);
		world.setBlock(i + 9, j + 5, k + 47, Block.planks.blockID);
		world.setBlock(i + 10, j + 5, k + 2, Block.planks.blockID);
		world.setBlock(i + 10, j + 5, k + 9, Block.fence.blockID);
		world.setBlockAndMetadata(i + 10, j + 5, k + 26, Block.stairCompactPlanks.blockID, 2);
		world.setBlockAndMetadata(i + 10, j + 5, k + 29, Block.thinGlass.blockID, 2);
		world.setBlockAndMetadata(i + 10, j + 5, k + 30, Block.thinGlass.blockID, 2);
		world.setBlockAndMetadata(i + 10, j + 5, k + 31, Block.thinGlass.blockID, 2);
		world.setBlockAndMetadata(i + 10, j + 5, k + 32, Block.thinGlass.blockID, 2);
		world.setBlockAndMetadata(i + 10, j + 5, k + 33, Block.thinGlass.blockID, 2);
		world.setBlockAndMetadata(i + 10, j + 5, k + 34, Block.thinGlass.blockID, 2);
		world.setBlockAndMetadata(i + 10, j + 5, k + 35, Block.thinGlass.blockID, 2);
		world.setBlockAndMetadata(i + 10, j + 5, k + 36, Block.thinGlass.blockID, 2);
		world.setBlockAndMetadata(i + 10, j + 5, k + 37, Block.thinGlass.blockID, 2);
		world.setBlockAndMetadata(i + 10, j + 5, k + 38, Block.thinGlass.blockID, 2);
		world.setBlock(i + 10, j + 5, k + 41, Block.planks.blockID);
		world.setBlockAndMetadata(i + 10, j + 5, k + 46, Block.stoneOvenIdle.blockID, 2);
		world.setBlock(i + 10, j + 5, k + 47, Block.planks.blockID);
		world.setBlock(i + 10, j + 5, k + 48, Block.planks.blockID);
		world.setBlock(i + 11, j + 5, k + 2, Block.planks.blockID);
		world.setBlock(i + 11, j + 5, k + 9, Block.fence.blockID);
		world.setBlockAndMetadata(i + 11, j + 5, k + 26, Block.stairCompactPlanks.blockID, 2);
		world.setBlockAndMetadata(i + 11, j + 5, k + 29, Block.thinGlass.blockID, 3);
		world.setBlockAndMetadata(i + 11, j + 5, k + 30, Block.thinGlass.blockID, 3);
		world.setBlockAndMetadata(i + 11, j + 5, k + 31, Block.thinGlass.blockID, 3);
		world.setBlockAndMetadata(i + 11, j + 5, k + 32, Block.thinGlass.blockID, 3);
		world.setBlockAndMetadata(i + 11, j + 5, k + 33, Block.thinGlass.blockID, 3);
		world.setBlockAndMetadata(i + 11, j + 5, k + 34, Block.thinGlass.blockID, 3);
		world.setBlockAndMetadata(i + 11, j + 5, k + 35, Block.thinGlass.blockID, 3);
		world.setBlockAndMetadata(i + 11, j + 5, k + 36, Block.thinGlass.blockID, 3);
		world.setBlockAndMetadata(i + 11, j + 5, k + 37, Block.thinGlass.blockID, 3);
		world.setBlockAndMetadata(i + 11, j + 5, k + 38, Block.thinGlass.blockID, 3);
		world.setBlock(i + 11, j + 5, k + 41, Block.planks.blockID);
		world.setBlockAndMetadata(i + 11, j + 5, k + 46, Block.stoneOvenIdle.blockID, 2);
		world.setBlock(i + 11, j + 5, k + 47, Block.planks.blockID);
		world.setBlock(i + 11, j + 5, k + 48, Block.planks.blockID);
		world.setBlock(i + 12, j + 5, k + 2, Block.planks.blockID);
		world.setBlock(i + 12, j + 5, k + 5, Block.fence.blockID);
		world.setBlock(i + 12, j + 5, k + 6, Block.fence.blockID);
		world.setBlock(i + 12, j + 5, k + 7, Block.fence.blockID);
		world.setBlock(i + 12, j + 5, k + 8, Block.fence.blockID);
		world.setBlock(i + 12, j + 5, k + 9, Block.fence.blockID);
		world.setBlock(i + 12, j + 5, k + 41, Block.planks.blockID);
		world.setBlockAndMetadata(i + 12, j + 5, k + 45, Block.thinGlass.blockID, 1);
		world.setBlock(i + 12, j + 5, k + 46, Block.planks.blockID);
		world.setBlock(i + 12, j + 5, k + 47, Block.planks.blockID);
		world.setBlock(i + 13, j + 5, k + 2, Block.planks.blockID);
		world.setBlock(i + 13, j + 5, k + 3, Block.planks.blockID);
		world.setBlock(i + 13, j + 5, k + 43, Block.chest.blockID);
		TileEntityChest var9 = (TileEntityChest)world.getBlockTileEntity(i + 13, j + 5, k + 43);
        int var10;

        if (var9 != null)
        {
            for (var10 = 0; var10 < 8; ++var10)
            {
                ItemStack var11 = this.pickCheckLootItem(rand);

                if (var11 != null)
                {
                    var9.setInventorySlotContents(rand.nextInt(var9.getSizeInventory()), var11);
                }
            }
        }
		world.setBlock(i + 13, j + 5, k + 44, Block.chest.blockID);
		world.setBlock(i + 13, j + 5, k + 45, Block.planks.blockID);
		world.setBlock(i + 13, j + 5, k + 46, Block.planks.blockID);
		world.setBlock(i + 14, j + 5, k + 3, Block.planks.blockID);
		world.setBlock(i + 14, j + 5, k + 4, Block.planks.blockID);
		world.setBlock(i + 14, j + 5, k + 41, Block.planks.blockID);
		world.setBlock(i + 14, j + 5, k + 42, Block.planks.blockID);
		world.setBlock(i + 14, j + 5, k + 43, Block.planks.blockID);
		world.setBlock(i + 14, j + 5, k + 44, Block.planks.blockID);
		world.setBlock(i + 14, j + 5, k + 45, Block.planks.blockID);
		world.setBlock(i + 15, j + 5, k + 4, Block.planks.blockID);
		world.setBlock(i + 15, j + 5, k + 5, Block.planks.blockID);
		world.setBlock(i + 15, j + 5, k + 7, Block.planks.blockID);
		world.setBlock(i + 15, j + 5, k + 8, Block.planks.blockID);
		world.setBlock(i + 15, j + 5, k + 10, Block.planks.blockID);
		world.setBlock(i + 15, j + 5, k + 11, Block.planks.blockID);
		world.setBlock(i + 15, j + 5, k + 13, Block.planks.blockID);
		world.setBlock(i + 15, j + 5, k + 14, Block.planks.blockID);
		world.setBlock(i + 15, j + 5, k + 16, Block.planks.blockID);
		world.setBlock(i + 15, j + 5, k + 17, Block.planks.blockID);
		world.setBlock(i + 15, j + 5, k + 19, Block.planks.blockID);
		world.setBlock(i + 15, j + 5, k + 20, Block.planks.blockID);
		world.setBlock(i + 15, j + 5, k + 21, Block.planks.blockID);
		world.setBlock(i + 15, j + 5, k + 22, Block.planks.blockID);
		world.setBlock(i + 15, j + 5, k + 23, Block.planks.blockID);
		world.setBlock(i + 15, j + 5, k + 24, Block.planks.blockID);
		world.setBlock(i + 15, j + 5, k + 25, Block.planks.blockID);
		world.setBlock(i + 15, j + 5, k + 27, Block.planks.blockID);
		world.setBlock(i + 15, j + 5, k + 28, Block.planks.blockID);
		world.setBlock(i + 15, j + 5, k + 30, Block.planks.blockID);
		world.setBlock(i + 15, j + 5, k + 31, Block.planks.blockID);
		world.setBlock(i + 15, j + 5, k + 33, Block.planks.blockID);
		world.setBlock(i + 15, j + 5, k + 34, Block.planks.blockID);
		world.setBlock(i + 15, j + 5, k + 36, Block.planks.blockID);
		world.setBlock(i + 15, j + 5, k + 37, Block.planks.blockID);
		world.setBlock(i + 15, j + 5, k + 39, Block.planks.blockID);
		world.setBlock(i + 15, j + 5, k + 40, Block.planks.blockID);
		world.setBlock(i + 15, j + 5, k + 41, Block.planks.blockID);
		world.setBlockAndMetadataWithNotify(i + 5, j + 5, k + 37, Block.ladder.blockID, 4);
		world.setBlockAndMetadataWithNotify(i + 13, j + 5, k + 41, Block.doorWood.blockID, 1);
		world.setBlockWithNotify(i + 13, j + 5, k + 42, Block.pressurePlatePlanks.blockID);
	
		generate8(world, rand, i, j, k);
		return true;
	}
	
	public boolean generate8(World world, Random rand, int i, int j, int k) 
	{
	
		world.setBlockAndMetadataWithNotify(i + 5, j + 6, k + 37, Block.ladder.blockID, 4);
		world.setBlock(i + 6, j + 6, k + 4, Block.planks.blockID);
		world.setBlock(i + 6, j + 6, k + 5, Block.planks.blockID);
		world.setBlock(i + 6, j + 6, k + 7, Block.planks.blockID);
		world.setBlock(i + 6, j + 6, k + 8, Block.planks.blockID);
		world.setBlock(i + 6, j + 6, k + 10, Block.planks.blockID);
		world.setBlock(i + 6, j + 6, k + 11, Block.planks.blockID);
		world.setBlock(i + 6, j + 6, k + 13, Block.planks.blockID);
		world.setBlock(i + 6, j + 6, k + 14, Block.planks.blockID);
		world.setBlock(i + 6, j + 6, k + 16, Block.planks.blockID);
		world.setBlock(i + 6, j + 6, k + 17, Block.planks.blockID);
		world.setBlock(i + 6, j + 6, k + 19, Block.planks.blockID);
		world.setBlock(i + 6, j + 6, k + 20, Block.planks.blockID);
		world.setBlock(i + 6, j + 6, k + 21, Block.planks.blockID);
		world.setBlock(i + 6, j + 6, k + 22, Block.planks.blockID);
		world.setBlock(i + 6, j + 6, k + 23, Block.planks.blockID);
		world.setBlock(i + 6, j + 6, k + 24, Block.planks.blockID);
		world.setBlock(i + 6, j + 6, k + 25, Block.planks.blockID);
		world.setBlock(i + 6, j + 6, k + 27, Block.planks.blockID);
		world.setBlock(i + 6, j + 6, k + 28, Block.planks.blockID);
		world.setBlock(i + 6, j + 6, k + 30, Block.planks.blockID);
		world.setBlock(i + 6, j + 6, k + 31, Block.planks.blockID);
		world.setBlock(i + 6, j + 6, k + 33, Block.planks.blockID);
		world.setBlock(i + 6, j + 6, k + 34, Block.planks.blockID);
		world.setBlock(i + 6, j + 6, k + 36, Block.planks.blockID);
		world.setBlock(i + 6, j + 6, k + 37, Block.planks.blockID);
		world.setBlock(i + 6, j + 6, k + 39, Block.planks.blockID);
		world.setBlock(i + 6, j + 6, k + 40, Block.planks.blockID);
		world.setBlock(i + 6, j + 6, k + 41, Block.planks.blockID);
		world.setBlock(i + 6, j + 6, k + 42, Block.planks.blockID);
		world.setBlock(i + 6, j + 6, k + 43, Block.planks.blockID);
		world.setBlock(i + 6, j + 6, k + 44, Block.planks.blockID);
		world.setBlock(i + 6, j + 6, k + 45, Block.planks.blockID);
		world.setBlock(i + 6, j + 6, k + 46, Block.planks.blockID);
		world.setBlock(i + 7, j + 6, k + 3, Block.planks.blockID);
		world.setBlock(i + 7, j + 6, k + 4, Block.planks.blockID);
		world.setBlock(i + 7, j + 6, k + 41, Block.planks.blockID);
		world.setBlockAndMetadata(i + 7, j + 6, k + 45, Block.thinGlass.blockID, 3);
		world.setBlock(i + 7, j + 6, k + 46, Block.planks.blockID);
		world.setBlock(i + 7, j + 6, k + 47, Block.planks.blockID);
		world.setBlockAndMetadataWithNotify(i + 7, j + 6, k + 5, Block.torchWood.blockID, 3);
		world.setBlockAndMetadataWithNotify(i + 7, j + 6, k + 7, Block.torchWood.blockID, 1);
